{"type": "orderbook_snapshot", "buy": [[6, 80000], [11, 1767], [12, 8000], [30, 200], [41, 50], [47, 75], [48, 20], [50, 250], [52, 1500], [53, 200], [54, 250], [56, 750], [58, 250], [59, 100], [61, 101]], "sell": [[99, 20], [94, 80000], [90, 200], [89, 8000], [74, 250], [72, 250], [70, 250], [68, 250], [67, 100], [66, 1500], [65, 200], [64, 375], [63, 500]]}
{"type": "orderbook_delta", "seq": 2, "price": 64, "quantity": -175, "ts": 1756428106.431419, "side": "sell"}
{"type": "orderbook_delta", "seq": 3, "price": 63, "quantity": -500, "ts": 1756428106.462184, "side": "sell"}
{"type": "orderbook_delta", "seq": 4, "price": 64, "quantity": 500, "ts": 1756428106.512609, "side": "sell"}
{"type": "orderbook_delta", "seq": 5, "price": 62, "quantity": 175, "ts": 1756428106.647911, "side": "sell"}
{"type": "orderbook_delta", "seq": 6, "price": 64, "quantity": -500, "ts": 1756428106.687298, "side": "sell"}
{"type": "orderbook_delta", "seq": 7, "price": 62, "quantity": 500, "ts": 1756428106.767507, "side": "sell"}
{"type": "orderbook_delta", "seq": 8, "price": 64, "quantity": -200, "ts": 1756428106.914167, "side": "sell"}
{"type": "orderbook_delta", "seq": 9, "price": 66, "quantity": -1250, "ts": 1756428106.914923, "side": "sell"}
{"type": "orderbook_delta", "seq": 10, "price": 53, "quantity": -200, "ts": 1756428106.917639, "side": "buy"}
{"type": "orderbook_delta", "seq": 11, "price": 89, "quantity": -8000, "ts": 1756428106.918731, "side": "sell"}
{"type": "orderbook_delta", "seq": 12, "price": 54, "quantity": 200, "ts": 1756428106.970361, "side": "buy"}
{"type": "orderbook_delta", "seq": 13, "price": 90, "quantity": 8000, "ts": 1756428106.973485, "side": "sell"}
{"type": "orderbook_delta", "seq": 14, "price": 65, "quantity": 200, "ts": 1756428106.97404, "side": "sell"}
{"type": "orderbook_delta", "seq": 15, "price": 67, "quantity": 1250, "ts": 1756428106.976804, "side": "sell"}
{"type": "orderbook_delta", "seq": 16, "price": 62, "quantity": -175, "ts": 1756428107.450495, "side": "sell"}
{"type": "orderbook_delta", "seq": 17, "price": 62, "quantity": -500, "ts": 1756428107.486794, "side": "sell"}
{"type": "orderbook_delta", "seq": 18, "price": 64, "quantity": 500, "ts": 1756428107.522317, "side": "sell"}
{"type": "orderbook_delta", "seq": 19, "price": 11, "quantity": -1767, "ts": 1756428107.728917, "side": "buy"}
{"type": "orderbook_delta", "seq": 20, "price": 7, "quantity": 2777, "ts": 1756428107.728917, "side": "buy"}
{"type": "orderbook_delta", "seq": 21, "price": 12, "quantity": -8000, "ts": 1756428107.775041, "side": "buy"}
{"type": "orderbook_delta", "seq": 22, "price": 8, "quantity": 8000, "ts": 1756428107.821005, "side": "buy"}
{"type": "orderbook_delta", "seq": 23, "price": 61, "quantity": -100, "ts": 1756428107.959007, "side": "buy"}
{"type": "orderbook_delta", "seq": 24, "price": 56, "quantity": -500, "ts": 1756428109.145647, "side": "buy"}
{"type": "orderbook_delta", "seq": 25, "price": 57, "quantity": 500, "ts": 1756428109.181909, "side": "buy"}
{"type": "orderbook_delta", "seq": 26, "price": 61, "quantity": 100, "ts": 1756428109.273699, "side": "buy"}
{"type": "orderbook_delta", "seq": 27, "price": 64, "quantity": 175, "ts": 1756428109.972724, "side": "sell"}
{"type": "orderbook_delta", "seq": 28, "price": 64, "quantity": -500, "ts": 1756428109.996978, "side": "sell"}
{"type": "orderbook_delta", "seq": 29, "price": 63, "quantity": 500, "ts": 1756428110.039484, "side": "sell"}
{"type": "orderbook_delta", "seq": 30, "price": 67, "quantity": -100, "ts": 1756428110.084857, "side": "sell"}
{"type": "orderbook_delta", "seq": 31, "price": 68, "quantity": 100, "ts": 1756428110.084857, "side": "sell"}
{"type": "orderbook_delta", "seq": 32, "price": 7, "quantity": -2777, "ts": 1756428110.685698, "side": "buy"}
{"type": "orderbook_delta", "seq": 33, "price": 9, "quantity": 2160, "ts": 1756428110.685698, "side": "buy"}
{"type": "orderbook_delta", "seq": 34, "price": 8, "quantity": -8000, "ts": 1756428110.744457, "side": "buy"}
{"type": "orderbook_delta", "seq": 35, "price": 10, "quantity": 8000, "ts": 1756428110.780171, "side": "buy"}
{"type": "orderbook_delta", "seq": 36, "price": 98, "quantity": 9720, "ts": 1756428110.825929, "side": "sell"}
{"type": "orderbook_delta", "seq": 37, "price": 97, "quantity": 7000, "ts": 1756428111.423233, "side": "sell"}
{"type": "orderbook_delta", "seq": 38, "price": 52, "quantity": -1250, "ts": 1756428111.614141, "side": "buy"}
{"type": "orderbook_delta", "seq": 39, "price": 53, "quantity": 1250, "ts": 1756428111.6491, "side": "buy"}
{"type": "orderbook_delta", "seq": 40, "price": 9, "quantity": -2160, "ts": 1756428111.899571, "side": "buy"}
{"type": "orderbook_delta", "seq": 41, "price": 11, "quantity": 1767, "ts": 1756428111.899571, "side": "buy"}
{"type": "orderbook_delta", "seq": 42, "price": 10, "quantity": -8000, "ts": 1756428111.987495, "side": "buy"}
{"type": "orderbook_delta", "seq": 43, "price": 53, "quantity": -1250, "ts": 1756428112.006589, "side": "buy"}
{"type": "orderbook_delta", "seq": 44, "price": 12, "quantity": 8000, "ts": 1756428112.03087, "side": "buy"}
{"type": "orderbook_delta", "seq": 45, "price": 52, "quantity": 1250, "ts": 1756428112.051368, "side": "buy"}
{"type": "orderbook_delta", "seq": 46, "price": 64, "quantity": -175, "ts": 1756428112.645715, "side": "sell"}
{"type": "orderbook_delta", "seq": 47, "price": 63, "quantity": -500, "ts": 1756428112.688162, "side": "sell"}
{"type": "orderbook_delta", "seq": 48, "price": 64, "quantity": 500, "ts": 1756428112.735465, "side": "sell"}
{"type": "orderbook_delta", "seq": 49, "price": 11, "quantity": -1767, "ts": 1756428112.809881, "side": "buy"}
{"type": "orderbook_delta", "seq": 50, "price": 12, "quantity": 1620, "ts": 1756428112.809881, "side": "buy"}
{"type": "orderbook_delta", "seq": 51, "price": 12, "quantity": -8000, "ts": 1756428112.843031, "side": "buy"}
{"type": "orderbook_delta", "seq": 52, "price": 62, "quantity": 175, "ts": 1756428112.85782, "side": "sell"}
{"type": "orderbook_delta", "seq": 53, "price": 13, "quantity": 8000, "ts": 1756428112.881382, "side": "buy"}
{"type": "orderbook_delta", "seq": 54, "price": 64, "quantity": -500, "ts": 1756428112.890219, "side": "sell"}
{"type": "orderbook_delta", "seq": 55, "price": 62, "quantity": 500, "ts": 1756428112.931669, "side": "sell"}
{"type": "orderbook_delta", "seq": 56, "price": 57, "quantity": -500, "ts": 1756428113.512247, "side": "buy"}
{"type": "orderbook_delta", "seq": 57, "price": 56, "quantity": 500, "ts": 1756428113.548625, "side": "buy"}
{"type": "orderbook_delta", "seq": 58, "price": 62, "quantity": -175, "ts": 1756428113.568447, "side": "sell"}
{"type": "orderbook_delta", "seq": 59, "price": 62, "quantity": -500, "ts": 1756428113.602355, "side": "sell"}
{"type": "orderbook_delta", "seq": 60, "price": 64, "quantity": 500, "ts": 1756428113.6441, "side": "sell"}
{"type": "orderbook_delta", "seq": 61, "price": 64, "quantity": 175, "ts": 1756428113.757202, "side": "sell"}
{"type": "orderbook_delta", "seq": 62, "price": 12, "quantity": -1620, "ts": 1756428113.762493, "side": "buy"}
{"type": "orderbook_delta", "seq": 63, "price": 7, "quantity": 2777, "ts": 1756428113.762493, "side": "buy"}
{"type": "orderbook_delta", "seq": 64, "price": 64, "quantity": -500, "ts": 1756428113.879159, "side": "sell"}
{"type": "orderbook_delta", "seq": 65, "price": 13, "quantity": -8000, "ts": 1756428113.882142, "side": "buy"}
{"type": "orderbook_delta", "seq": 66, "price": 63, "quantity": 500, "ts": 1756428113.913689, "side": "sell"}
{"type": "orderbook_delta", "seq": 67, "price": 8, "quantity": 8000, "ts": 1756428113.918854, "side": "buy"}
{"type": "orderbook_delta", "seq": 68, "price": 7, "quantity": -2777, "ts": 1756428114.641166, "side": "buy"}
{"type": "orderbook_delta", "seq": 69, "price": 9, "quantity": 2160, "ts": 1756428114.641166, "side": "buy"}
{"type": "orderbook_delta", "seq": 70, "price": 8, "quantity": -8000, "ts": 1756428114.68276, "side": "buy"}
{"type": "orderbook_delta", "seq": 71, "price": 10, "quantity": 8000, "ts": 1756428114.724662, "side": "buy"}
{"type": "orderbook_delta", "seq": 72, "price": 68, "quantity": -100, "ts": 1756428115.085735, "side": "sell"}
{"type": "orderbook_delta", "seq": 73, "price": 65, "quantity": 100, "ts": 1756428115.085735, "side": "sell"}
{"type": "orderbook_delta", "seq": 74, "price": 64, "quantity": -175, "ts": 1756428115.710233, "side": "sell"}
{"type": "orderbook_delta", "seq": 75, "price": 56, "quantity": -500, "ts": 1756428115.729031, "side": "buy"}
{"type": "orderbook_delta", "seq": 76, "price": 57, "quantity": 500, "ts": 1756428115.771842, "side": "buy"}
{"type": "orderbook_delta", "seq": 77, "price": 63, "quantity": -500, "ts": 1756428115.789035, "side": "sell"}
{"type": "orderbook_delta", "seq": 78, "price": 64, "quantity": 500, "ts": 1756428115.853643, "side": "sell"}
{"type": "orderbook_delta", "seq": 79, "price": 62, "quantity": 175, "ts": 1756428115.944499, "side": "sell"}
{"type": "orderbook_delta", "seq": 80, "price": 62, "quantity": -175, "ts": 1756428116.639084, "side": "sell"}
{"type": "orderbook_delta", "seq": 81, "price": 64, "quantity": 175, "ts": 1756428116.878687, "side": "sell"}
{"type": "orderbook_delta", "seq": 82, "price": 64, "quantity": -500, "ts": 1756428116.908705, "side": "sell"}
{"type": "orderbook_delta", "seq": 83, "price": 63, "quantity": 500, "ts": 1756428116.981927, "side": "sell"}
{"type": "orderbook_delta", "seq": 84, "price": 61, "quantity": 0, "ts": 1756428117.341819, "side": "buy"}
{"type": "trade", "seq": 8, "price": 61, "quantity": 1, "ts": 1756428117.341819, "side": "sell"}
{"type": "orderbook_delta", "seq": 85, "price": 61, "quantity": 0, "ts": 1756428117.341819, "side": "buy"}
{"type": "trade", "seq": 9, "price": 61, "quantity": 35, "ts": 1756428117.871338, "side": "sell"}
{"type": "orderbook_delta", "seq": 86, "price": 90, "quantity": -8000, "ts": 1756428117.871338, "side": "sell"}
{"type": "orderbook_delta", "seq": 87, "price": 57, "quantity": -500, "ts": 1756428117.871508, "side": "buy"}
{"type": "orderbook_delta", "seq": 88, "price": 67, "quantity": -1250, "ts": 1756428117.87284, "side": "sell"}
{"type": "orderbook_delta", "seq": 89, "price": 56, "quantity": 500, "ts": 1756428117.910639, "side": "buy"}
{"type": "orderbook_delta", "seq": 90, "price": 66, "quantity": 1250, "ts": 1756428117.910971, "side": "sell"}
{"type": "orderbook_delta", "seq": 91, "price": 89, "quantity": 8000, "ts": 1756428117.916515, "side": "sell"}
{"type": "orderbook_delta", "seq": 92, "price": 58, "quantity": -250, "ts": 1756428117.931467, "side": "buy"}
{"type": "orderbook_delta", "seq": 93, "price": 48, "quantity": 250, "ts": 1756428117.934587, "side": "buy"}
{"type": "orderbook_delta", "seq": 94, "price": 59, "quantity": -100, "ts": 1756428118.06374, "side": "buy"}
{"type": "orderbook_delta", "seq": 95, "price": 57, "quantity": 100, "ts": 1756428118.06374, "side": "buy"}
{"type": "orderbook_delta", "seq": 96, "price": 58, "quantity": 250, "ts": 1756428118.188237, "side": "buy"}
{"type": "orderbook_delta", "seq": 97, "price": 48, "quantity": -250, "ts": 1756428118.188452, "side": "buy"}
{"type": "orderbook_delta", "seq": 98, "price": 64, "quantity": -175, "ts": 1756428118.643023, "side": "sell"}
{"type": "orderbook_delta", "seq": 99, "price": 63, "quantity": -500, "ts": 1756428118.675592, "side": "sell"}
{"type": "orderbook_delta", "seq": 100, "price": 64, "quantity": 500, "ts": 1756428118.742643, "side": "sell"}
{"type": "orderbook_delta", "seq": 101, "price": 57, "quantity": -100, "ts": 1756428118.808209, "side": "buy"}
{"type": "orderbook_delta", "seq": 102, "price": 59, "quantity": 100, "ts": 1756428118.808209, "side": "buy"}
{"type": "orderbook_delta", "seq": 103, "price": 62, "quantity": 175, "ts": 1756428118.826845, "side": "sell"}
{"type": "orderbook_delta", "seq": 104, "price": 64, "quantity": -500, "ts": 1756428118.979957, "side": "sell"}
{"type": "orderbook_delta", "seq": 105, "price": 9, "quantity": -2160, "ts": 1756428118.989683, "side": "buy"}
{"type": "orderbook_delta", "seq": 106, "price": 11, "quantity": 1767, "ts": 1756428118.989683, "side": "buy"}
{"type": "orderbook_delta", "seq": 107, "price": 62, "quantity": 500, "ts": 1756428119.025405, "side": "sell"}
{"type": "orderbook_delta", "seq": 108, "price": 10, "quantity": -8000, "ts": 1756428119.147161, "side": "buy"}
{"type": "orderbook_delta", "seq": 109, "price": 12, "quantity": 8000, "ts": 1756428119.204551, "side": "buy"}
{"type": "orderbook_delta", "seq": 110, "price": 62, "quantity": -175, "ts": 1756428119.712244, "side": "sell"}
{"type": "orderbook_delta", "seq": 111, "price": 62, "quantity": -500, "ts": 1756428119.743407, "side": "sell"}
{"type": "orderbook_delta", "seq": 112, "price": 64, "quantity": 500, "ts": 1756428119.778592, "side": "sell"}
{"type": "orderbook_delta", "seq": 113, "price": 56, "quantity": -500, "ts": 1756428120.141665, "side": "buy"}
{"type": "orderbook_delta", "seq": 114, "price": 89, "quantity": -8000, "ts": 1756428120.148841, "side": "sell"}
{"type": "orderbook_delta", "seq": 115, "price": 66, "quantity": -1250, "ts": 1756428120.149493, "side": "sell"}
{"type": "orderbook_delta", "seq": 116, "price": 67, "quantity": 1250, "ts": 1756428120.206904, "side": "sell"}
{"type": "orderbook_delta", "seq": 117, "price": 90, "quantity": 8000, "ts": 1756428120.211258, "side": "sell"}
{"type": "orderbook_delta", "seq": 118, "price": 57, "quantity": 500, "ts": 1756428120.212611, "side": "buy"}
{"type": "orderbook_delta", "seq": 119, "price": 61, "quantity": -65, "ts": 1756428120.245904, "side": "buy"}
{"type": "orderbook_delta", "seq": 120, "price": 60, "quantity": 100, "ts": 1756428121.220275, "side": "buy"}
{"type": "orderbook_delta", "seq": 121, "price": 54, "quantity": -200, "ts": 1756428121.25686, "side": "buy"}
{"type": "orderbook_delta", "seq": 122, "price": 12, "quantity": -8000, "ts": 1756428121.257471, "side": "buy"}
{"type": "orderbook_delta", "seq": 123, "price": 65, "quantity": -200, "ts": 1756428121.258786, "side": "sell"}
{"type": "orderbook_delta", "seq": 124, "price": 52, "quantity": -1250, "ts": 1756428121.261887, "side": "buy"}
{"type": "orderbook_delta", "seq": 125, "price": 30, "quantity": 8000, "ts": 1756428121.304308, "side": "buy"}
{"type": "orderbook_delta", "seq": 126, "price": 66, "quantity": 200, "ts": 1756428121.30466, "side": "sell"}
{"type": "orderbook_delta", "seq": 127, "price": 55, "quantity": 200, "ts": 1756428121.30597, "side": "buy"}
{"type": "orderbook_delta", "seq": 128, "price": 53, "quantity": 1250, "ts": 1756428121.308448, "side": "buy"}
{"type": "orderbook_delta", "seq": 129, "price": 66, "quantity": -250, "ts": 1756428121.812581, "side": "sell"}
{"type": "orderbook_delta", "seq": 130, "price": 76, "quantity": 250, "ts": 1756428121.819318, "side": "sell"}
{"type": "orderbook_delta", "seq": 131, "price": 57, "quantity": -500, "ts": 1756428121.853734, "side": "buy"}
{"type": "orderbook_delta", "seq": 132, "price": 67, "quantity": -1250, "ts": 1756428121.853913, "side": "sell"}
{"type": "orderbook_delta", "seq": 133, "price": 53, "quantity": -1250, "ts": 1756428121.854119, "side": "buy"}
{"type": "orderbook_delta", "seq": 134, "price": 90, "quantity": -8000, "ts": 1756428121.854175, "side": "sell"}
{"type": "orderbook_delta", "seq": 135, "price": 66, "quantity": -200, "ts": 1756428121.854863, "side": "sell"}
{"type": "orderbook_delta", "seq": 136, "price": 64, "quantity": -500, "ts": 1756428121.85493, "side": "sell"}
{"type": "orderbook_delta", "seq": 137, "price": 30, "quantity": -8000, "ts": 1756428121.889834, "side": "buy"}
{"type": "orderbook_delta", "seq": 138, "price": 65, "quantity": -100, "ts": 1756428121.892036, "side": "sell"}
{"type": "orderbook_delta", "seq": 139, "price": 66, "quantity": 100, "ts": 1756428121.892036, "side": "sell"}
{"type": "orderbook_delta", "seq": 140, "price": 48, "quantity": 250, "ts": 1756428121.893553, "side": "buy"}
{"type": "orderbook_delta", "seq": 141, "price": 58, "quantity": -250, "ts": 1756428121.896532, "side": "buy"}
{"type": "orderbook_delta", "seq": 142, "price": 90, "quantity": -200, "ts": 1756428121.93071, "side": "sell"}
{"type": "orderbook_delta", "seq": 143, "price": 78, "quantity": 250, "ts": 1756428121.934993, "side": "sell"}
{"type": "orderbook_delta", "seq": 144, "price": 63, "quantity": 210, "ts": 1756428121.95136, "side": "sell"}
{"type": "orderbook_delta", "seq": 145, "price": 55, "quantity": -200, "ts": 1756428121.989805, "side": "buy"}
{"type": "orderbook_delta", "seq": 146, "price": 66, "quantity": -100, "ts": 1756428122.001905, "side": "sell"}
{"type": "orderbook_delta", "seq": 147, "price": 67, "quantity": 100, "ts": 1756428122.001905, "side": "sell"}
{"type": "orderbook_delta", "seq": 148, "price": 68, "quantity": -250, "ts": 1756428122.014874, "side": "sell"}
{"type": "orderbook_delta", "seq": 149, "price": 65, "quantity": -200, "ts": 1756428122.017121, "side": "sell"}
{"type": "orderbook_delta", "seq": 150, "price": 66, "quantity": 200, "ts": 1756428122.017121, "side": "sell"}
{"type": "orderbook_delta", "seq": 151, "price": 11, "quantity": -1767, "ts": 1756428122.029937, "side": "buy"}
{"type": "orderbook_delta", "seq": 152, "price": 7, "quantity": 2777, "ts": 1756428122.029937, "side": "buy"}
{"type": "orderbook_delta", "seq": 153, "price": 57, "quantity": 1250, "ts": 1756428122.030664, "side": "buy"}
{"type": "orderbook_delta", "seq": 154, "price": 67, "quantity": 500, "ts": 1756428122.031951, "side": "sell"}
{"type": "orderbook_delta", "seq": 155, "price": 61, "quantity": 500, "ts": 1756428122.035991, "side": "buy"}
{"type": "orderbook_delta", "seq": 156, "price": 57, "quantity": 200, "ts": 1756428122.036509, "side": "buy"}
{"type": "orderbook_delta", "seq": 157, "price": 31, "quantity": 8000, "ts": 1756428122.036843, "side": "buy"}
{"type": "orderbook_delta", "seq": 158, "price": 97, "quantity": 8000, "ts": 1756428122.03896, "side": "sell"}
{"type": "orderbook_delta", "seq": 159, "price": 71, "quantity": 1250, "ts": 1756428122.039978, "side": "sell"}
{"type": "orderbook_delta", "seq": 160, "price": 69, "quantity": 200, "ts": 1756428122.040368, "side": "sell"}
{"type": "orderbook_delta", "seq": 161, "price": 67, "quantity": -100, "ts": 1756428122.051759, "side": "sell"}
{"type": "orderbook_delta", "seq": 162, "price": 68, "quantity": 100, "ts": 1756428122.051759, "side": "sell"}
{"type": "orderbook_delta", "seq": 163, "price": 58, "quantity": 250, "ts": 1756428122.07974, "side": "buy"}
{"type": "orderbook_delta", "seq": 164, "price": 68, "quantity": 250, "ts": 1756428122.095984, "side": "sell"}
{"type": "orderbook_delta", "seq": 165, "price": 59, "quantity": -100, "ts": 1756428122.101875, "side": "buy"}
{"type": "orderbook_delta", "seq": 166, "price": 62, "quantity": 100, "ts": 1756428122.101875, "side": "buy"}
{"type": "orderbook_delta", "seq": 167, "price": 48, "quantity": -250, "ts": 1756428122.106509, "side": "buy"}
{"type": "orderbook_delta", "seq": 168, "price": 66, "quantity": -200, "ts": 1756428122.109307, "side": "sell"}
{"type": "orderbook_delta", "seq": 169, "price": 68, "quantity": 200, "ts": 1756428122.109307, "side": "sell"}
{"type": "orderbook_delta", "seq": 170, "price": 57, "quantity": -200, "ts": 1756428122.111301, "side": "buy"}
{"type": "orderbook_delta", "seq": 171, "price": 78, "quantity": -250, "ts": 1756428122.126766, "side": "sell"}
{"type": "orderbook_delta", "seq": 172, "price": 60, "quantity": 250, "ts": 1756428122.131792, "side": "buy"}
{"type": "orderbook_delta", "seq": 173, "price": 50, "quantity": -250, "ts": 1756428122.146633, "side": "buy"}
{"type": "orderbook_delta", "seq": 174, "price": 58, "quantity": 200, "ts": 1756428122.155529, "side": "buy"}
{"type": "orderbook_delta", "seq": 175, "price": 69, "quantity": -200, "ts": 1756428122.185468, "side": "sell"}
{"type": "orderbook_delta", "seq": 176, "price": 68, "quantity": -200, "ts": 1756428122.186266, "side": "sell"}
{"type": "orderbook_delta", "seq": 177, "price": 70, "quantity": 200, "ts": 1756428122.186266, "side": "sell"}
{"type": "orderbook_delta", "seq": 178, "price": 58, "quantity": -200, "ts": 1756428122.199668, "side": "buy"}
{"type": "orderbook_delta", "seq": 179, "price": 59, "quantity": 200, "ts": 1756428122.240758, "side": "buy"}
{"type": "orderbook_delta", "seq": 180, "price": 70, "quantity": 200, "ts": 1756428122.245091, "side": "sell"}
{"type": "orderbook_delta", "seq": 181, "price": 70, "quantity": -200, "ts": 1756428122.476847, "side": "sell"}
{"type": "orderbook_delta", "seq": 182, "price": 68, "quantity": -250, "ts": 1756428122.477795, "side": "sell"}
{"type": "orderbook_delta", "seq": 183, "price": 78, "quantity": 250, "ts": 1756428122.479405, "side": "sell"}
{"type": "orderbook_delta", "seq": 184, "price": 59, "quantity": -200, "ts": 1756428122.479696, "side": "buy"}
{"type": "orderbook_delta", "seq": 185, "price": 71, "quantity": -1250, "ts": 1756428122.479753, "side": "sell"}
{"type": "orderbook_delta", "seq": 186, "price": 80, "quantity": 250, "ts": 1756428122.484398, "side": "sell"}
{"type": "orderbook_delta", "seq": 187, "price": 57, "quantity": -1250, "ts": 1756428122.485878, "side": "buy"}
{"type": "orderbook_delta", "seq": 188, "price": 61, "quantity": -500, "ts": 1756428122.49078, "side": "buy"}
{"type": "orderbook_delta", "seq": 189, "price": 70, "quantity": -200, "ts": 1756428122.504946, "side": "sell"}
{"type": "orderbook_delta", "seq": 190, "price": 71, "quantity": 200, "ts": 1756428122.504946, "side": "sell"}
{"type": "orderbook_delta", "seq": 191, "price": 70, "quantity": -250, "ts": 1756428122.507121, "side": "sell"}
{"type": "orderbook_delta", "seq": 192, "price": 62, "quantity": 500, "ts": 1756428122.535439, "side": "buy"}
{"type": "orderbook_delta", "seq": 193, "price": 62, "quantity": -100, "ts": 1756428122.546346, "side": "buy"}
{"type": "orderbook_delta", "seq": 194, "price": 61, "quantity": 100, "ts": 1756428122.546346, "side": "buy"}
{"type": "orderbook_delta", "seq": 195, "price": 68, "quantity": -100, "ts": 1756428122.602107, "side": "sell"}
{"type": "orderbook_delta", "seq": 196, "price": 69, "quantity": 100, "ts": 1756428122.602107, "side": "sell"}
{"type": "orderbook_delta", "seq": 197, "price": 57, "quantity": 1250, "ts": 1756428122.615905, "side": "buy"}
{"type": "orderbook_delta", "seq": 198, "price": 72, "quantity": 1250, "ts": 1756428122.616875, "side": "sell"}
{"type": "orderbook_delta", "seq": 199, "price": 59, "quantity": 200, "ts": 1756428122.617454, "side": "buy"}
{"type": "orderbook_delta", "seq": 200, "price": 70, "quantity": 200, "ts": 1756428122.665967, "side": "sell"}
{"type": "orderbook_delta", "seq": 201, "price": 67, "quantity": -500, "ts": 1756428122.687829, "side": "sell"}
{"type": "orderbook_delta", "seq": 202, "price": 57, "quantity": -1250, "ts": 1756428122.717306, "side": "buy"}
{"type": "orderbook_delta", "seq": 203, "price": 59, "quantity": -200, "ts": 1756428122.730769, "side": "buy"}
{"type": "orderbook_delta", "seq": 204, "price": 69, "quantity": -100, "ts": 1756428122.732217, "side": "sell"}
{"type": "orderbook_delta", "seq": 205, "price": 70, "quantity": 100, "ts": 1756428122.732217, "side": "sell"}
{"type": "orderbook_delta", "seq": 206, "price": 68, "quantity": 500, "ts": 1756428122.739512, "side": "sell"}
{"type": "orderbook_delta", "seq": 207, "price": 70, "quantity": -200, "ts": 1756428122.749568, "side": "sell"}
{"type": "orderbook_delta", "seq": 208, "price": 59, "quantity": 1250, "ts": 1756428122.770723, "side": "buy"}
{"type": "orderbook_delta", "seq": 209, "price": 71, "quantity": 200, "ts": 1756428122.782242, "side": "sell"}
{"type": "orderbook_delta", "seq": 210, "price": 60, "quantity": 200, "ts": 1756428122.784393, "side": "buy"}
{"type": "orderbook_delta", "seq": 211, "price": 68, "quantity": -500, "ts": 1756428122.790754, "side": "sell"}
{"type": "orderbook_delta", "seq": 212, "price": 69, "quantity": 500, "ts": 1756428122.866895, "side": "sell"}
{"type": "orderbook_delta", "seq": 213, "price": 98, "quantity": -9720, "ts": 1756428123.035717, "side": "sell"}
{"type": "orderbook_delta", "seq": 214, "price": 97, "quantity": -8000, "ts": 1756428123.073106, "side": "sell"}
{"type": "orderbook_delta", "seq": 215, "price": 97, "quantity": -7000, "ts": 1756428123.075088, "side": "sell"}
{"type": "trade", "seq": 10, "price": 63, "quantity": 210, "ts": 1756428123.177174, "side": "buy"}
{"type": "orderbook_delta", "seq": 216, "price": 98, "quantity": 8000, "ts": 1756428123.177174, "side": "sell"}
{"type": "orderbook_delta", "seq": 217, "price": 63, "quantity": 0, "ts": 1756428123.179115, "side": "sell"}
{"type": "orderbook_delta", "seq": 218, "price": 54, "quantity": -250, "ts": 1756428123.220264, "side": "buy"}
{"type": "orderbook_delta", "seq": 219, "price": 64, "quantity": 250, "ts": 1756428123.233103, "side": "buy"}
{"type": "orderbook_delta", "seq": 220, "price": 62, "quantity": 250, "ts": 1756428123.236411, "side": "buy"}
{"type": "orderbook_delta", "seq": 221, "price": 52, "quantity": -250, "ts": 1756428123.237023, "side": "buy"}
{"type": "orderbook_delta", "seq": 222, "price": 62, "quantity": -500, "ts": 1756428123.285315, "side": "buy"}
{"type": "orderbook_delta", "seq": 223, "price": 69, "quantity": 210, "ts": 1756428123.315888, "side": "sell"}
{"type": "orderbook_delta", "seq": 224, "price": 63, "quantity": 500, "ts": 1756428123.332081, "side": "buy"}
{"type": "orderbook_delta", "seq": 225, "price": 61, "quantity": -100, "ts": 1756428123.370953, "side": "buy"}
{"type": "orderbook_delta", "seq": 226, "price": 65, "quantity": 100, "ts": 1756428123.370953, "side": "buy"}
{"type": "orderbook_delta", "seq": 227, "price": 69, "quantity": -500, "ts": 1756428123.387304, "side": "sell"}
{"type": "orderbook_delta", "seq": 228, "price": 68, "quantity": 500, "ts": 1756428123.43237, "side": "sell"}
{"type": "orderbook_delta", "seq": 229, "price": 60, "quantity": -100, "ts": 1756428124.018509, "side": "buy"}
{"type": "orderbook_delta", "seq": 230, "price": 54, "quantity": 250, "ts": 1756428124.14022, "side": "buy"}
{"type": "orderbook_delta", "seq": 231, "price": 69, "quantity": -210, "ts": 1756428124.184793, "side": "sell"}
{"type": "orderbook_delta", "seq": 232, "price": 64, "quantity": -250, "ts": 1756428124.216666, "side": "buy"}
{"type": "orderbook_delta", "seq": 233, "price": 68, "quantity": 210, "ts": 1756428124.280499, "side": "sell"}
{"type": "orderbook_delta", "seq": 234, "price": 68, "quantity": -500, "ts": 1756428124.294991, "side": "sell"}
{"type": "orderbook_delta", "seq": 235, "price": 69, "quantity": 500, "ts": 1756428124.355531, "side": "sell"}
{"type": "orderbook_delta", "seq": 236, "price": 69, "quantity": -500, "ts": 1756428124.486841, "side": "sell"}
{"type": "orderbook_delta", "seq": 237, "price": 68, "quantity": 500, "ts": 1756428124.530273, "side": "sell"}
{"type": "orderbook_delta", "seq": 238, "price": 71, "quantity": -200, "ts": 1756428124.829962, "side": "sell"}
{"type": "orderbook_delta", "seq": 239, "price": 60, "quantity": -200, "ts": 1756428124.830015, "side": "buy"}
{"type": "orderbook_delta", "seq": 240, "price": 68, "quantity": -500, "ts": 1756428124.830068, "side": "sell"}
{"type": "orderbook_delta", "seq": 241, "price": 72, "quantity": -1250, "ts": 1756428124.83012, "side": "sell"}
{"type": "orderbook_delta", "seq": 242, "price": 59, "quantity": -1250, "ts": 1756428124.830519, "side": "buy"}
{"type": "orderbook_delta", "seq": 243, "price": 72, "quantity": 200, "ts": 1756428124.877258, "side": "sell"}
{"type": "orderbook_delta", "seq": 244, "price": 73, "quantity": 1250, "ts": 1756428124.879087, "side": "sell"}
{"type": "orderbook_delta", "seq": 245, "price": 60, "quantity": 1250, "ts": 1756428124.879367, "side": "buy"}
{"type": "orderbook_delta", "seq": 246, "price": 61, "quantity": 200, "ts": 1756428124.879608, "side": "buy"}
{"type": "orderbook_delta", "seq": 247, "price": 69, "quantity": 500, "ts": 1756428124.882237, "side": "sell"}
{"type": "orderbook_delta", "seq": 248, "price": 60, "quantity": -1250, "ts": 1756428125.249143, "side": "buy"}
{"type": "orderbook_delta", "seq": 249, "price": 59, "quantity": 1250, "ts": 1756428125.324733, "side": "buy"}
{"type": "orderbook_delta", "seq": 250, "price": 65, "quantity": -100, "ts": 1756428125.546496, "side": "buy"}
{"type": "orderbook_delta", "seq": 251, "price": 64, "quantity": 100, "ts": 1756428125.546496, "side": "buy"}
{"type": "orderbook_delta", "seq": 252, "price": 63, "quantity": -500, "ts": 1756428125.581824, "side": "buy"}
{"type": "orderbook_delta", "seq": 253, "price": 64, "quantity": 500, "ts": 1756428125.625415, "side": "buy"}
{"type": "orderbook_delta", "seq": 254, "price": 65, "quantity": 100, "ts": 1756428125.718419, "side": "buy"}
{"type": "orderbook_delta", "seq": 255, "price": 70, "quantity": 10, "ts": 1756428126.036934, "side": "sell"}
{"type": "orderbook_delta", "seq": 256, "price": 68, "quantity": 100, "ts": 1756428126.450576, "side": "sell"}
{"type": "orderbook_delta", "seq": 257, "price": 64, "quantity": -500, "ts": 1756428127.058011, "side": "buy"}
{"type": "orderbook_delta", "seq": 258, "price": 63, "quantity": 500, "ts": 1756428127.134552, "side": "buy"}
{"type": "orderbook_delta", "seq": 259, "price": 64, "quantity": 250, "ts": 1756428128.00286, "side": "buy"}
{"type": "orderbook_delta", "seq": 260, "price": 54, "quantity": -250, "ts": 1756428128.003573, "side": "buy"}
{"type": "orderbook_delta", "seq": 261, "price": 64, "quantity": -100, "ts": 1756428128.055707, "side": "buy"}
{"type": "orderbook_delta", "seq": 262, "price": 65, "quantity": 100, "ts": 1756428128.055707, "side": "buy"}
{"type": "orderbook_delta", "seq": 263, "price": 59, "quantity": -1250, "ts": 1756428129.3597, "side": "buy"}
{"type": "orderbook_delta", "seq": 264, "price": 63, "quantity": -500, "ts": 1756428129.360958, "side": "buy"}
{"type": "orderbook_delta", "seq": 265, "price": 60, "quantity": 1250, "ts": 1756428129.407736, "side": "buy"}
{"type": "orderbook_delta", "seq": 266, "price": 69, "quantity": -500, "ts": 1756428129.470115, "side": "sell"}
{"type": "orderbook_delta", "seq": 267, "price": 73, "quantity": -1250, "ts": 1756428129.474744, "side": "sell"}
{"type": "orderbook_delta", "seq": 268, "price": 74, "quantity": 1250, "ts": 1756428129.506901, "side": "sell"}
{"type": "orderbook_delta", "seq": 269, "price": 70, "quantity": 500, "ts": 1756428129.50823, "side": "sell"}
{"type": "orderbook_delta", "seq": 270, "price": 71, "quantity": -200, "ts": 1756428129.54078, "side": "sell"}
{"type": "orderbook_delta", "seq": 271, "price": 72, "quantity": 200, "ts": 1756428129.54078, "side": "sell"}
{"type": "orderbook_delta", "seq": 272, "price": 70, "quantity": -100, "ts": 1756428129.62236, "side": "sell"}
{"type": "orderbook_delta", "seq": 273, "price": 71, "quantity": 100, "ts": 1756428129.62236, "side": "sell"}
{"type": "orderbook_delta", "seq": 274, "price": 64, "quantity": 500, "ts": 1756428129.674165, "side": "buy"}
{"type": "orderbook_delta", "seq": 275, "price": 65, "quantity": -100, "ts": 1756428129.680278, "side": "buy"}
{"type": "orderbook_delta", "seq": 276, "price": 64, "quantity": 100, "ts": 1756428129.680278, "side": "buy"}
{"type": "orderbook_delta", "seq": 277, "price": 74, "quantity": -1250, "ts": 1756428129.775244, "side": "sell"}
{"type": "orderbook_delta", "seq": 278, "price": 70, "quantity": -500, "ts": 1756428129.775609, "side": "sell"}
{"type": "orderbook_delta", "seq": 279, "price": 72, "quantity": -200, "ts": 1756428129.776733, "side": "sell"}
{"type": "orderbook_delta", "seq": 280, "price": 60, "quantity": -1250, "ts": 1756428129.776808, "side": "buy"}
{"type": "orderbook_delta", "seq": 281, "price": 64, "quantity": -500, "ts": 1756428129.805719, "side": "buy"}
{"type": "orderbook_delta", "seq": 282, "price": 61, "quantity": -200, "ts": 1756428129.821853, "side": "buy"}
{"type": "orderbook_delta", "seq": 283, "price": 71, "quantity": 500, "ts": 1756428129.906127, "side": "sell"}
{"type": "orderbook_delta", "seq": 284, "price": 75, "quantity": 1250, "ts": 1756428129.906594, "side": "sell"}
{"type": "orderbook_delta", "seq": 285, "price": 73, "quantity": 200, "ts": 1756428129.906832, "side": "sell"}
{"type": "orderbook_delta", "seq": 286, "price": 62, "quantity": 200, "ts": 1756428129.907067, "side": "buy"}
{"type": "orderbook_delta", "seq": 287, "price": 61, "quantity": 1250, "ts": 1756428129.907289, "side": "buy"}
{"type": "orderbook_delta", "seq": 288, "price": 65, "quantity": 500, "ts": 1756428129.907502, "side": "buy"}
{"type": "orderbook_delta", "seq": 289, "price": 72, "quantity": -200, "ts": 1756428129.908722, "side": "sell"}
{"type": "orderbook_delta", "seq": 290, "price": 74, "quantity": 200, "ts": 1756428129.908722, "side": "sell"}
{"type": "orderbook_delta", "seq": 291, "price": 71, "quantity": -100, "ts": 1756428129.96105, "side": "sell"}
{"type": "orderbook_delta", "seq": 292, "price": 72, "quantity": 100, "ts": 1756428129.96105, "side": "sell"}
{"type": "orderbook_delta", "seq": 293, "price": 82, "quantity": 250, "ts": 1756428130.130156, "side": "sell"}
{"type": "orderbook_delta", "seq": 294, "price": 68, "quantity": -210, "ts": 1756428130.130993, "side": "sell"}
{"type": "orderbook_delta", "seq": 295, "price": 72, "quantity": -250, "ts": 1756428130.14653, "side": "sell"}
{"type": "orderbook_delta", "seq": 296, "price": 69, "quantity": 210, "ts": 1756428130.191933, "side": "sell"}
{"type": "orderbook_delta", "seq": 297, "price": 69, "quantity": -210, "ts": 1756428130.274394, "side": "sell"}
{"type": "orderbook_delta", "seq": 298, "price": 73, "quantity": -200, "ts": 1756428130.279976, "side": "sell"}
{"type": "orderbook_delta", "seq": 299, "price": 65, "quantity": -500, "ts": 1756428130.280385, "side": "buy"}
{"type": "orderbook_delta", "seq": 300, "price": 71, "quantity": -500, "ts": 1756428130.280626, "side": "sell"}
{"type": "orderbook_delta", "seq": 301, "price": 62, "quantity": -200, "ts": 1756428130.281208, "side": "buy"}
{"type": "orderbook_delta", "seq": 302, "price": 61, "quantity": -1250, "ts": 1756428130.281511, "side": "buy"}
{"type": "orderbook_delta", "seq": 303, "price": 75, "quantity": -1250, "ts": 1756428130.281642, "side": "sell"}
{"type": "orderbook_delta", "seq": 304, "price": 31, "quantity": -8000, "ts": 1756428130.281736, "side": "buy"}
{"type": "orderbook_delta", "seq": 305, "price": 71, "quantity": 210, "ts": 1756428130.336529, "side": "sell"}
{"type": "orderbook_delta", "seq": 306, "price": 76, "quantity": 1250, "ts": 1756428130.351364, "side": "sell"}
{"type": "orderbook_delta", "seq": 307, "price": 63, "quantity": 1250, "ts": 1756428130.351673, "side": "buy"}
{"type": "orderbook_delta", "seq": 308, "price": 64, "quantity": 200, "ts": 1756428130.351972, "side": "buy"}
{"type": "orderbook_delta", "seq": 309, "price": 72, "quantity": 500, "ts": 1756428130.352199, "side": "sell"}
{"type": "orderbook_delta", "seq": 310, "price": 75, "quantity": 200, "ts": 1756428130.352789, "side": "sell"}
{"type": "orderbook_delta", "seq": 311, "price": 42, "quantity": 8000, "ts": 1756428130.353064, "side": "buy"}
{"type": "orderbook_delta", "seq": 312, "price": 66, "quantity": 500, "ts": 1756428130.360776, "side": "buy"}
{"type": "orderbook_delta", "seq": 313, "price": 64, "quantity": -100, "ts": 1756428130.451774, "side": "buy"}
{"type": "orderbook_delta", "seq": 314, "price": 66, "quantity": 100, "ts": 1756428130.451774, "side": "buy"}
{"type": "orderbook_delta", "seq": 315, "price": 66, "quantity": -500, "ts": 1756428130.499764, "side": "buy"}
{"type": "orderbook_delta", "seq": 316, "price": 67, "quantity": 500, "ts": 1756428130.537972, "side": "buy"}
{"type": "orderbook_delta", "seq": 317, "price": 66, "quantity": -100, "ts": 1756428130.547131, "side": "buy"}
{"type": "orderbook_delta", "seq": 318, "price": 65, "quantity": 100, "ts": 1756428130.547131, "side": "buy"}
{"type": "trade", "seq": 11, "price": 68, "quantity": 71, "ts": 1756428130.555257, "side": "buy"}
{"type": "orderbook_delta", "seq": 319, "price": 68, "quantity": 0, "ts": 1756428130.555257, "side": "sell"}
{"type": "orderbook_delta", "seq": 320, "price": 67, "quantity": -500, "ts": 1756428130.586972, "side": "buy"}
{"type": "orderbook_delta", "seq": 321, "price": 66, "quantity": 500, "ts": 1756428130.647341, "side": "buy"}
{"type": "orderbook_delta", "seq": 322, "price": 56, "quantity": -250, "ts": 1756428131.116653, "side": "buy"}
{"type": "orderbook_delta", "seq": 323, "price": 66, "quantity": 250, "ts": 1756428131.11869, "side": "buy"}
{"type": "orderbook_delta", "seq": 324, "price": 66, "quantity": -500, "ts": 1756428131.15165, "side": "buy"}
{"type": "orderbook_delta", "seq": 325, "price": 67, "quantity": 500, "ts": 1756428131.19218, "side": "buy"}
{"type": "orderbook_delta", "seq": 326, "price": 72, "quantity": -100, "ts": 1756428131.472535, "side": "sell"}
{"type": "orderbook_delta", "seq": 327, "price": 71, "quantity": 100, "ts": 1756428131.472535, "side": "sell"}
{"type": "orderbook_delta", "seq": 328, "price": 72, "quantity": -500, "ts": 1756428131.595183, "side": "sell"}
{"type": "orderbook_delta", "seq": 329, "price": 73, "quantity": 500, "ts": 1756428131.634997, "side": "sell"}
{"type": "orderbook_delta", "seq": 330, "price": 65, "quantity": -100, "ts": 1756428132.088283, "side": "buy"}
{"type": "orderbook_delta", "seq": 331, "price": 67, "quantity": 100, "ts": 1756428132.088283, "side": "buy"}
{"type": "orderbook_delta", "seq": 332, "price": 71, "quantity": -210, "ts": 1756428132.11345, "side": "sell"}
{"type": "orderbook_delta", "seq": 333, "price": 71, "quantity": -100, "ts": 1756428132.160589, "side": "sell"}
{"type": "orderbook_delta", "seq": 334, "price": 72, "quantity": 100, "ts": 1756428132.160589, "side": "sell"}
{"type": "orderbook_delta", "seq": 335, "price": 73, "quantity": -500, "ts": 1756428132.192367, "side": "sell"}
{"type": "orderbook_delta", "seq": 336, "price": 70, "quantity": 210, "ts": 1756428132.226792, "side": "sell"}
{"type": "orderbook_delta", "seq": 337, "price": 72, "quantity": 500, "ts": 1756428132.26873, "side": "sell"}
{"type": "orderbook_delta", "seq": 338, "price": 65, "quantity": -100, "ts": 1756428132.576091, "side": "buy"}
{"type": "orderbook_delta", "seq": 339, "price": 68, "quantity": -29, "ts": 1756428132.844298, "side": "sell"}
{"type": "orderbook_delta", "seq": 340, "price": 41, "quantity": -50, "ts": 1756428134.010892, "side": "buy"}
{"type": "orderbook_delta", "seq": 341, "price": 67, "quantity": 100, "ts": 1756428134.035809, "side": "buy"}
{"type": "orderbook_delta", "seq": 342, "price": 42, "quantity": -8000, "ts": 1756428134.10275, "side": "buy"}
{"type": "orderbook_delta", "seq": 343, "price": 31, "quantity": 8000, "ts": 1756428134.133249, "side": "buy"}
{"type": "orderbook_delta", "seq": 344, "price": 66, "quantity": -250, "ts": 1756428134.141167, "side": "buy"}
{"type": "orderbook_delta", "seq": 345, "price": 56, "quantity": 250, "ts": 1756428134.141229, "side": "buy"}
{"type": "orderbook_delta", "seq": 346, "price": 72, "quantity": -500, "ts": 1756428134.430584, "side": "sell"}
{"type": "orderbook_delta", "seq": 347, "price": 76, "quantity": -1250, "ts": 1756428134.431095, "side": "sell"}
{"type": "orderbook_delta", "seq": 348, "price": 67, "quantity": -500, "ts": 1756428134.432468, "side": "buy"}
{"type": "orderbook_delta", "seq": 349, "price": 63, "quantity": -1250, "ts": 1756428134.434512, "side": "buy"}
{"type": "orderbook_delta", "seq": 350, "price": 74, "quantity": -200, "ts": 1756428134.44431, "side": "sell"}
{"type": "orderbook_delta", "seq": 351, "price": 72, "quantity": 200, "ts": 1756428134.44431, "side": "sell"}
{"type": "orderbook_delta", "seq": 352, "price": 75, "quantity": -200, "ts": 1756428134.456749, "side": "sell"}
{"type": "orderbook_delta", "seq": 353, "price": 67, "quantity": -100, "ts": 1756428134.480977, "side": "buy"}
{"type": "orderbook_delta", "seq": 354, "price": 65, "quantity": 100, "ts": 1756428134.480977, "side": "buy"}
{"type": "orderbook_delta", "seq": 355, "price": 64, "quantity": -200, "ts": 1756428134.615955, "side": "buy"}
{"type": "orderbook_delta", "seq": 356, "price": 75, "quantity": 1250, "ts": 1756428134.683775, "side": "sell"}
{"type": "orderbook_delta", "seq": 357, "price": 65, "quantity": 500, "ts": 1756428134.684996, "side": "buy"}
{"type": "orderbook_delta", "seq": 358, "price": 63, "quantity": 200, "ts": 1756428134.686667, "side": "buy"}
{"type": "orderbook_delta", "seq": 359, "price": 74, "quantity": 200, "ts": 1756428134.687192, "side": "sell"}
{"type": "orderbook_delta", "seq": 360, "price": 61, "quantity": 1250, "ts": 1756428134.687796, "side": "buy"}
{"type": "orderbook_delta", "seq": 361, "price": 70, "quantity": 100, "ts": 1756428134.75446, "side": "sell"}
{"type": "orderbook_delta", "seq": 362, "price": 63, "quantity": -200, "ts": 1756428134.796723, "side": "buy"}
{"type": "orderbook_delta", "seq": 363, "price": 65, "quantity": -500, "ts": 1756428134.796852, "side": "buy"}
{"type": "orderbook_delta", "seq": 364, "price": 74, "quantity": -200, "ts": 1756428134.798384, "side": "sell"}
{"type": "orderbook_delta", "seq": 365, "price": 61, "quantity": -1250, "ts": 1756428134.798517, "side": "buy"}
{"type": "orderbook_delta", "seq": 366, "price": 75, "quantity": -1250, "ts": 1756428134.799131, "side": "sell"}
{"type": "orderbook_delta", "seq": 367, "price": 71, "quantity": 500, "ts": 1756428134.898101, "side": "sell"}
{"type": "orderbook_delta", "seq": 368, "price": 62, "quantity": 200, "ts": 1756428134.901865, "side": "buy"}
{"type": "orderbook_delta", "seq": 369, "price": 73, "quantity": 200, "ts": 1756428134.903579, "side": "sell"}
{"type": "orderbook_delta", "seq": 370, "price": 64, "quantity": 500, "ts": 1756428134.904643, "side": "buy"}
{"type": "orderbook_delta", "seq": 371, "price": 74, "quantity": 1250, "ts": 1756428134.910733, "side": "sell"}
{"type": "orderbook_delta", "seq": 372, "price": 60, "quantity": 1250, "ts": 1756428134.911291, "side": "buy"}
{"type": "orderbook_delta", "seq": 373, "price": 64, "quantity": -250, "ts": 1756428134.946423, "side": "buy"}
{"type": "orderbook_delta", "seq": 374, "price": 71, "quantity": -500, "ts": 1756428134.974243, "side": "sell"}
{"type": "orderbook_delta", "seq": 375, "price": 64, "quantity": -500, "ts": 1756428135.007285, "side": "buy"}
{"type": "orderbook_delta", "seq": 376, "price": 54, "quantity": 250, "ts": 1756428135.044257, "side": "buy"}
{"type": "orderbook_delta", "seq": 377, "price": 70, "quantity": 500, "ts": 1756428135.044658, "side": "sell"}
{"type": "orderbook_delta", "seq": 378, "price": 63, "quantity": 500, "ts": 1756428135.095039, "side": "buy"}
{"type": "orderbook_delta", "seq": 379, "price": 70, "quantity": -210, "ts": 1756428135.115698, "side": "sell"}
{"type": "orderbook_delta", "seq": 380, "price": 64, "quantity": 250, "ts": 1756428135.153276, "side": "buy"}
{"type": "orderbook_delta", "seq": 381, "price": 54, "quantity": -250, "ts": 1756428135.209188, "side": "buy"}
{"type": "orderbook_delta", "seq": 382, "price": 72, "quantity": 250, "ts": 1756428135.214433, "side": "sell"}
{"type": "orderbook_delta", "seq": 383, "price": 63, "quantity": -500, "ts": 1756428135.244615, "side": "buy"}
{"type": "orderbook_delta", "seq": 384, "price": 82, "quantity": -250, "ts": 1756428135.250679, "side": "sell"}
{"type": "orderbook_delta", "seq": 385, "price": 64, "quantity": 500, "ts": 1756428135.320779, "side": "buy"}
{"type": "orderbook_delta", "seq": 386, "price": 69, "quantity": 210, "ts": 1756428135.34409, "side": "sell"}
{"type": "orderbook_delta", "seq": 387, "price": 73, "quantity": -200, "ts": 1756428136.275382, "side": "sell"}
{"type": "orderbook_delta", "seq": 388, "price": 62, "quantity": -200, "ts": 1756428136.275435, "side": "buy"}
{"type": "orderbook_delta", "seq": 389, "price": 61, "quantity": 200, "ts": 1756428136.331441, "side": "buy"}
{"type": "orderbook_delta", "seq": 390, "price": 72, "quantity": 200, "ts": 1756428136.335736, "side": "sell"}
{"type": "orderbook_delta", "seq": 391, "price": 67, "quantity": -100, "ts": 1756428136.538641, "side": "buy"}
{"type": "orderbook_delta", "seq": 392, "price": 68, "quantity": 71, "ts": 1756428136.785769, "side": "buy"}
{"type": "orderbook_delta", "seq": 393, "price": 74, "quantity": -1250, "ts": 1756428136.85794, "side": "sell"}
{"type": "orderbook_delta", "seq": 394, "price": 70, "quantity": -500, "ts": 1756428136.863769, "side": "sell"}
{"type": "orderbook_delta", "seq": 395, "price": 69, "quantity": 500, "ts": 1756428136.898288, "side": "sell"}
{"type": "orderbook_delta", "seq": 396, "price": 73, "quantity": 1250, "ts": 1756428137.013674, "side": "sell"}
{"type": "orderbook_delta", "seq": 397, "price": 64, "quantity": -500, "ts": 1756428137.01969, "side": "buy"}
{"type": "orderbook_delta", "seq": 398, "price": 60, "quantity": -1250, "ts": 1756428137.020613, "side": "buy"}
{"type": "orderbook_delta", "seq": 399, "price": 72, "quantity": -200, "ts": 1756428137.029149, "side": "sell"}
{"type": "orderbook_delta", "seq": 400, "price": 61, "quantity": -200, "ts": 1756428137.054145, "side": "buy"}
{"type": "orderbook_delta", "seq": 401, "price": 73, "quantity": -1250, "ts": 1756428137.060217, "side": "sell"}
{"type": "orderbook_delta", "seq": 402, "price": 72, "quantity": -200, "ts": 1756428137.077494, "side": "sell"}
{"type": "orderbook_delta", "seq": 403, "price": 70, "quantity": 200, "ts": 1756428137.077494, "side": "sell"}
{"type": "orderbook_delta", "seq": 404, "price": 65, "quantity": -100, "ts": 1756428137.087172, "side": "buy"}
{"type": "orderbook_delta", "seq": 405, "price": 64, "quantity": 100, "ts": 1756428137.087172, "side": "buy"}
{"type": "orderbook_delta", "seq": 406, "price": 58, "quantity": 1250, "ts": 1756428137.089266, "side": "buy"}
{"type": "orderbook_delta", "seq": 407, "price": 63, "quantity": 500, "ts": 1756428137.090352, "side": "buy"}
{"type": "orderbook_delta", "seq": 408, "price": 71, "quantity": 200, "ts": 1756428137.092147, "side": "sell"}
{"type": "orderbook_delta", "seq": 409, "price": 72, "quantity": 1250, "ts": 1756428137.096281, "side": "sell"}
{"type": "orderbook_delta", "seq": 410, "price": 60, "quantity": 200, "ts": 1756428137.100802, "side": "buy"}
{"type": "orderbook_delta", "seq": 411, "price": 52, "quantity": 250, "ts": 1756428137.128036, "side": "buy"}
{"type": "orderbook_delta", "seq": 412, "price": 62, "quantity": -250, "ts": 1756428137.129287, "side": "buy"}
{"type": "orderbook_delta", "seq": 413, "price": 60, "quantity": -200, "ts": 1756428137.130649, "side": "buy"}
{"type": "orderbook_delta", "seq": 414, "price": 71, "quantity": -200, "ts": 1756428137.132219, "side": "sell"}
{"type": "orderbook_delta", "seq": 415, "price": 54, "quantity": 250, "ts": 1756428137.136621, "side": "buy"}
{"type": "orderbook_delta", "seq": 416, "price": 63, "quantity": -500, "ts": 1756428137.143444, "side": "buy"}
{"type": "orderbook_delta", "seq": 417, "price": 64, "quantity": -250, "ts": 1756428137.169861, "side": "buy"}
{"type": "orderbook_delta", "seq": 418, "price": 70, "quantity": 200, "ts": 1756428137.1816, "side": "sell"}
{"type": "orderbook_delta", "seq": 419, "price": 59, "quantity": 200, "ts": 1756428137.181942, "side": "buy"}
{"type": "orderbook_delta", "seq": 420, "price": 61, "quantity": 500, "ts": 1756428137.188726, "side": "buy"}
{"type": "orderbook_delta", "seq": 421, "price": 64, "quantity": -100, "ts": 1756428137.490426, "side": "buy"}
{"type": "orderbook_delta", "seq": 422, "price": 62, "quantity": 100, "ts": 1756428137.490426, "side": "buy"}
{"type": "orderbook_delta", "seq": 423, "price": 61, "quantity": -500, "ts": 1756428137.522173, "side": "buy"}
{"type": "orderbook_delta", "seq": 424, "price": 70, "quantity": -100, "ts": 1756428137.526274, "side": "sell"}
{"type": "orderbook_delta", "seq": 425, "price": 62, "quantity": 500, "ts": 1756428137.555417, "side": "buy"}
{"type": "orderbook_delta", "seq": 426, "price": 62, "quantity": 250, "ts": 1756428137.942763, "side": "buy"}
{"type": "orderbook_delta", "seq": 427, "price": 52, "quantity": -250, "ts": 1756428137.943039, "side": "buy"}
{"type": "orderbook_delta", "seq": 428, "price": 72, "quantity": -100, "ts": 1756428138.108067, "side": "sell"}
{"type": "orderbook_delta", "seq": 429, "price": 70, "quantity": 100, "ts": 1756428138.108067, "side": "sell"}
{"type": "orderbook_delta", "seq": 430, "price": 70, "quantity": 250, "ts": 1756428138.108907, "side": "sell"}
{"type": "orderbook_delta", "seq": 431, "price": 80, "quantity": -250, "ts": 1756428138.111199, "side": "sell"}
{"type": "orderbook_delta", "seq": 432, "price": 62, "quantity": -100, "ts": 1756428138.250797, "side": "buy"}
{"type": "orderbook_delta", "seq": 433, "price": 63, "quantity": 100, "ts": 1756428138.250797, "side": "buy"}
{"type": "orderbook_delta", "seq": 434, "price": 59, "quantity": -200, "ts": 1756428138.573226, "side": "buy"}
{"type": "orderbook_delta", "seq": 435, "price": 70, "quantity": -200, "ts": 1756428138.577786, "side": "sell"}
{"type": "orderbook_delta", "seq": 436, "price": 71, "quantity": 200, "ts": 1756428138.682571, "side": "sell"}
{"type": "orderbook_delta", "seq": 437, "price": 60, "quantity": 200, "ts": 1756428138.685451, "side": "buy"}
{"type": "orderbook_delta", "seq": 438, "price": 70, "quantity": -100, "ts": 1756428138.879885, "side": "sell"}
{"type": "orderbook_delta", "seq": 439, "price": 69, "quantity": 100, "ts": 1756428138.879885, "side": "sell"}
{"type": "orderbook_delta", "seq": 440, "price": 80, "quantity": 250, "ts": 1756428139.074098, "side": "sell"}
{"type": "orderbook_delta", "seq": 441, "price": 70, "quantity": -250, "ts": 1756428139.0784, "side": "sell"}
{"type": "orderbook_delta", "seq": 442, "price": 72, "quantity": -1250, "ts": 1756428139.079592, "side": "sell"}
{"type": "orderbook_delta", "seq": 443, "price": 58, "quantity": -1250, "ts": 1756428139.079698, "side": "buy"}
{"type": "orderbook_delta", "seq": 444, "price": 62, "quantity": -500, "ts": 1756428139.098412, "side": "buy"}
{"type": "orderbook_delta", "seq": 445, "price": 59, "quantity": 1250, "ts": 1756428139.159591, "side": "buy"}
{"type": "orderbook_delta", "seq": 446, "price": 63, "quantity": 500, "ts": 1756428139.16166, "side": "buy"}
{"type": "orderbook_delta", "seq": 447, "price": 63, "quantity": -100, "ts": 1756428139.207338, "side": "buy"}
{"type": "orderbook_delta", "seq": 448, "price": 64, "quantity": 100, "ts": 1756428139.207338, "side": "buy"}
{"type": "orderbook_delta", "seq": 449, "price": 73, "quantity": 1250, "ts": 1756428139.266251, "side": "sell"}
{"type": "orderbook_delta", "seq": 450, "price": 73, "quantity": -1250, "ts": 1756428140.035959, "side": "sell"}
{"type": "orderbook_delta", "seq": 451, "price": 63, "quantity": -500, "ts": 1756428140.043059, "side": "buy"}
{"type": "orderbook_delta", "seq": 452, "price": 59, "quantity": -1250, "ts": 1756428140.08742, "side": "buy"}
{"type": "orderbook_delta", "seq": 453, "price": 72, "quantity": 1250, "ts": 1756428140.131587, "side": "sell"}
{"type": "orderbook_delta", "seq": 454, "price": 62, "quantity": 500, "ts": 1756428140.132145, "side": "buy"}
{"type": "orderbook_delta", "seq": 455, "price": 58, "quantity": 1250, "ts": 1756428140.132395, "side": "buy"}
{"type": "orderbook_delta", "seq": 456, "price": 64, "quantity": -100, "ts": 1756428140.508708, "side": "buy"}
{"type": "orderbook_delta", "seq": 457, "price": 63, "quantity": 100, "ts": 1756428140.508708, "side": "buy"}
{"type": "orderbook_delta", "seq": 458, "price": 60, "quantity": -200, "ts": 1756428140.885243, "side": "buy"}
{"type": "orderbook_delta", "seq": 459, "price": 71, "quantity": -200, "ts": 1756428140.901743, "side": "sell"}
{"type": "orderbook_delta", "seq": 460, "price": 70, "quantity": 200, "ts": 1756428140.939507, "side": "sell"}
{"type": "orderbook_delta", "seq": 461, "price": 59, "quantity": 200, "ts": 1756428140.941898, "side": "buy"}
{"type": "orderbook_delta", "seq": 462, "price": 70, "quantity": -10, "ts": 1756428141.671076, "side": "sell"}
{"type": "orderbook_delta", "seq": 463, "price": 75, "quantity": 10, "ts": 1756428141.671076, "side": "sell"}
{"type": "orderbook_delta", "seq": 464, "price": 58, "quantity": -1250, "ts": 1756428142.080224, "side": "buy"}
{"type": "orderbook_delta", "seq": 465, "price": 72, "quantity": -1250, "ts": 1756428142.095569, "side": "sell"}
{"type": "orderbook_delta", "seq": 466, "price": 70, "quantity": -200, "ts": 1756428142.096887, "side": "sell"}
{"type": "orderbook_delta", "seq": 467, "price": 59, "quantity": -200, "ts": 1756428142.096984, "side": "buy"}
{"type": "orderbook_delta", "seq": 468, "price": 70, "quantity": 250, "ts": 1756428142.107165, "side": "sell"}
{"type": "orderbook_delta", "seq": 469, "price": 62, "quantity": -500, "ts": 1756428142.119073, "side": "buy"}
{"type": "orderbook_delta", "seq": 470, "price": 69, "quantity": -210, "ts": 1756428142.137487, "side": "sell"}
{"type": "orderbook_delta", "seq": 471, "price": 56, "quantity": 1250, "ts": 1756428142.143524, "side": "buy"}
{"type": "orderbook_delta", "seq": 472, "price": 71, "quantity": 1250, "ts": 1756428142.143819, "side": "sell"}
{"type": "orderbook_delta", "seq": 473, "price": 69, "quantity": 200, "ts": 1756428142.163703, "side": "sell"}
{"type": "orderbook_delta", "seq": 474, "price": 61, "quantity": 500, "ts": 1756428142.165714, "side": "buy"}
{"type": "orderbook_delta", "seq": 475, "price": 58, "quantity": 200, "ts": 1756428142.168877, "side": "buy"}
{"type": "orderbook_delta", "seq": 476, "price": 80, "quantity": -250, "ts": 1756428142.18701, "side": "sell"}
{"type": "orderbook_delta", "seq": 477, "price": 71, "quantity": -1250, "ts": 1756428142.238756, "side": "sell"}
{"type": "orderbook_delta", "seq": 478, "price": 61, "quantity": -500, "ts": 1756428142.24002, "side": "buy"}
{"type": "trade", "seq": 12, "price": 68, "quantity": 71, "ts": 1756428142.24993, "side": "sell"}
{"type": "orderbook_delta", "seq": 479, "price": 68, "quantity": 0, "ts": 1756428142.24993, "side": "buy"}
{"type": "orderbook_delta", "seq": 480, "price": 68, "quantity": 139, "ts": 1756428142.24993, "side": "sell"}
{"type": "orderbook_delta", "seq": 481, "price": 70, "quantity": -200, "ts": 1756428142.265634, "side": "sell"}
{"type": "orderbook_delta", "seq": 482, "price": 69, "quantity": 200, "ts": 1756428142.265634, "side": "sell"}
{"type": "orderbook_delta", "seq": 483, "price": 52, "quantity": 250, "ts": 1756428142.288019, "side": "buy"}
{"type": "orderbook_delta", "seq": 484, "price": 70, "quantity": 1250, "ts": 1756428142.288251, "side": "sell"}
{"type": "orderbook_delta", "seq": 485, "price": 60, "quantity": 500, "ts": 1756428142.288557, "side": "buy"}
{"type": "orderbook_delta", "seq": 486, "price": 68, "quantity": -139, "ts": 1756428142.292152, "side": "sell"}
{"type": "orderbook_delta", "seq": 487, "price": 62, "quantity": -250, "ts": 1756428142.308704, "side": "buy"}
{"type": "orderbook_delta", "seq": 488, "price": 69, "quantity": -500, "ts": 1756428142.312222, "side": "sell"}
{"type": "orderbook_delta", "seq": 489, "price": 67, "quantity": 139, "ts": 1756428142.334579, "side": "sell"}
{"type": "orderbook_delta", "seq": 490, "price": 52, "quantity": -250, "ts": 1756428142.34653, "side": "buy"}
{"type": "orderbook_delta", "seq": 491, "price": 68, "quantity": 500, "ts": 1756428142.376468, "side": "sell"}
{"type": "orderbook_delta", "seq": 492, "price": 68, "quantity": -500, "ts": 1756428142.419132, "side": "sell"}
{"type": "orderbook_delta", "seq": 493, "price": 66, "quantity": 500, "ts": 1756428142.453444, "side": "sell"}
{"type": "orderbook_delta", "seq": 494, "price": 75, "quantity": 0, "ts": 1756428142.724129, "side": "sell"}
{"type": "orderbook_delta", "seq": 495, "price": 67, "quantity": -139, "ts": 1756428143.18536, "side": "sell"}
{"type": "orderbook_delta", "seq": 496, "price": 66, "quantity": -500, "ts": 1756428143.224815, "side": "sell"}
{"type": "orderbook_delta", "seq": 497, "price": 60, "quantity": -500, "ts": 1756428143.257477, "side": "buy"}
{"type": "orderbook_delta", "seq": 498, "price": 66, "quantity": 139, "ts": 1756428143.26718, "side": "sell"}
{"type": "orderbook_delta", "seq": 499, "price": 56, "quantity": -1250, "ts": 1756428143.267653, "side": "buy"}
{"type": "orderbook_delta", "seq": 500, "price": 68, "quantity": 500, "ts": 1756428143.277017, "side": "sell"}
{"type": "orderbook_delta", "seq": 501, "price": 70, "quantity": -1250, "ts": 1756428143.284903, "side": "sell"}
{"type": "orderbook_delta", "seq": 502, "price": 52, "quantity": 250, "ts": 1756428143.310121, "side": "buy"}
{"type": "orderbook_delta", "seq": 503, "price": 68, "quantity": -500, "ts": 1756428143.338666, "side": "sell"}
{"type": "orderbook_delta", "seq": 504, "price": 71, "quantity": 1250, "ts": 1756428143.358078, "side": "sell"}
{"type": "orderbook_delta", "seq": 505, "price": 61, "quantity": 500, "ts": 1756428143.364923, "side": "buy"}
{"type": "orderbook_delta", "seq": 506, "price": 57, "quantity": 1250, "ts": 1756428143.365228, "side": "buy"}
{"type": "orderbook_delta", "seq": 507, "price": 66, "quantity": 500, "ts": 1756428143.374544, "side": "sell"}
{"type": "orderbook_delta", "seq": 508, "price": 63, "quantity": -100, "ts": 1756428143.499915, "side": "buy"}
{"type": "orderbook_delta", "seq": 509, "price": 62, "quantity": 100, "ts": 1756428143.499915, "side": "buy"}
{"type": "orderbook_delta", "seq": 510, "price": 62, "quantity": 250, "ts": 1756428143.539619, "side": "buy"}
{"type": "orderbook_delta", "seq": 511, "price": 66, "quantity": -139, "ts": 1756428143.540102, "side": "sell"}
{"type": "orderbook_delta", "seq": 512, "price": 52, "quantity": -250, "ts": 1756428143.558299, "side": "buy"}
{"type": "orderbook_delta", "seq": 513, "price": 66, "quantity": -500, "ts": 1756428143.576861, "side": "sell"}
{"type": "orderbook_delta", "seq": 514, "price": 66, "quantity": 139, "ts": 1756428143.599685, "side": "sell"}
{"type": "orderbook_delta", "seq": 515, "price": 68, "quantity": 500, "ts": 1756428143.69379, "side": "sell"}
{"type": "orderbook_delta", "seq": 516, "price": 68, "quantity": -500, "ts": 1756428143.727434, "side": "sell"}
{"type": "orderbook_delta", "seq": 517, "price": 66, "quantity": 500, "ts": 1756428143.767715, "side": "sell"}
{"type": "orderbook_delta", "seq": 518, "price": 62, "quantity": -100, "ts": 1756428144.246579, "side": "buy"}
{"type": "orderbook_delta", "seq": 519, "price": 63, "quantity": 100, "ts": 1756428144.246579, "side": "buy"}
{"type": "orderbook_delta", "seq": 520, "price": 62, "quantity": 100, "ts": 1756428144.92252, "side": "buy"}
{"type": "orderbook_delta", "seq": 521, "price": 57, "quantity": -1250, "ts": 1756428145.607216, "side": "buy"}
{"type": "orderbook_delta", "seq": 522, "price": 58, "quantity": -200, "ts": 1756428145.607808, "side": "buy"}
{"type": "orderbook_delta", "seq": 523, "price": 61, "quantity": -500, "ts": 1756428145.607865, "side": "buy"}
{"type": "orderbook_delta", "seq": 524, "price": 69, "quantity": -200, "ts": 1756428145.608542, "side": "sell"}
{"type": "orderbook_delta", "seq": 525, "price": 71, "quantity": -1250, "ts": 1756428145.612338, "side": "sell"}
{"type": "orderbook_delta", "seq": 526, "price": 56, "quantity": 1250, "ts": 1756428145.727031, "side": "buy"}
{"type": "orderbook_delta", "seq": 527, "price": 70, "quantity": 1250, "ts": 1756428145.727295, "side": "sell"}
{"type": "orderbook_delta", "seq": 528, "price": 60, "quantity": 500, "ts": 1756428145.72752, "side": "buy"}
{"type": "orderbook_delta", "seq": 529, "price": 62, "quantity": -100, "ts": 1756428145.728338, "side": "buy"}
{"type": "orderbook_delta", "seq": 530, "price": 68, "quantity": 200, "ts": 1756428145.728359, "side": "sell"}
{"type": "orderbook_delta", "seq": 531, "price": 57, "quantity": 200, "ts": 1756428145.729014, "side": "buy"}
{"type": "orderbook_delta", "seq": 532, "price": 63, "quantity": 100, "ts": 1756428145.942105, "side": "buy"}
{"type": "orderbook_delta", "seq": 533, "price": 52, "quantity": 250, "ts": 1756428146.09789, "side": "buy"}
{"type": "orderbook_delta", "seq": 534, "price": 68, "quantity": 250, "ts": 1756428146.117175, "side": "sell"}
{"type": "orderbook_delta", "seq": 535, "price": 66, "quantity": -139, "ts": 1756428146.120145, "side": "sell"}
{"type": "orderbook_delta", "seq": 536, "price": 62, "quantity": -250, "ts": 1756428146.136564, "side": "buy"}
{"type": "orderbook_delta", "seq": 537, "price": 66, "quantity": -500, "ts": 1756428146.155123, "side": "sell"}
{"type": "orderbook_delta", "seq": 538, "price": 78, "quantity": -250, "ts": 1756428146.156987, "side": "sell"}
{"type": "orderbook_delta", "seq": 539, "price": 67, "quantity": 500, "ts": 1756428146.195495, "side": "sell"}
{"type": "orderbook_delta", "seq": 540, "price": 65, "quantity": 139, "ts": 1756428146.20265, "side": "sell"}
{"type": "orderbook_delta", "seq": 541, "price": 63, "quantity": -100, "ts": 1756428146.500198, "side": "buy"}
{"type": "orderbook_delta", "seq": 542, "price": 61, "quantity": 100, "ts": 1756428146.500198, "side": "buy"}
{"type": "orderbook_delta", "seq": 543, "price": 80, "quantity": 250, "ts": 1756428146.681529, "side": "sell"}
{"type": "orderbook_delta", "seq": 544, "price": 57, "quantity": -200, "ts": 1756428146.684801, "side": "buy"}
{"type": "orderbook_delta", "seq": 545, "price": 70, "quantity": -1250, "ts": 1756428146.68486, "side": "sell"}
{"type": "orderbook_delta", "seq": 546, "price": 68, "quantity": -200, "ts": 1756428146.686382, "side": "sell"}
{"type": "orderbook_delta", "seq": 547, "price": 56, "quantity": -1250, "ts": 1756428146.690229, "side": "buy"}
{"type": "orderbook_delta", "seq": 548, "price": 67, "quantity": -500, "ts": 1756428146.695688, "side": "sell"}
{"type": "orderbook_delta", "seq": 549, "price": 65, "quantity": -139, "ts": 1756428146.707945, "side": "sell"}
{"type": "orderbook_delta", "seq": 550, "price": 78, "quantity": 250, "ts": 1756428146.727763, "side": "sell"}
{"type": "orderbook_delta", "seq": 551, "price": 68, "quantity": -250, "ts": 1756428146.728222, "side": "sell"}
{"type": "orderbook_delta", "seq": 552, "price": 60, "quantity": -500, "ts": 1756428146.746121, "side": "buy"}
{"type": "orderbook_delta", "seq": 553, "price": 68, "quantity": 500, "ts": 1756428146.756102, "side": "sell"}
{"type": "orderbook_delta", "seq": 554, "price": 69, "quantity": -100, "ts": 1756428146.763139, "side": "sell"}
{"type": "orderbook_delta", "seq": 555, "price": 68, "quantity": 100, "ts": 1756428146.763139, "side": "sell"}
{"type": "orderbook_delta", "seq": 556, "price": 69, "quantity": -200, "ts": 1756428146.768548, "side": "sell"}
{"type": "orderbook_delta", "seq": 557, "price": 71, "quantity": 200, "ts": 1756428146.768548, "side": "sell"}
{"type": "orderbook_delta", "seq": 558, "price": 70, "quantity": -250, "ts": 1756428146.785636, "side": "sell"}
{"type": "orderbook_delta", "seq": 559, "price": 50, "quantity": 250, "ts": 1756428146.802535, "side": "buy"}
{"type": "orderbook_delta", "seq": 560, "price": 60, "quantity": -250, "ts": 1756428146.809181, "side": "buy"}
{"type": "orderbook_delta", "seq": 561, "price": 71, "quantity": 200, "ts": 1756428146.819715, "side": "sell"}
{"type": "orderbook_delta", "seq": 562, "price": 62, "quantity": 500, "ts": 1756428146.820225, "side": "buy"}
{"type": "orderbook_delta", "seq": 563, "price": 72, "quantity": 1250, "ts": 1756428146.820492, "side": "sell"}
{"type": "orderbook_delta", "seq": 564, "price": 58, "quantity": 1250, "ts": 1756428146.820857, "side": "buy"}
{"type": "orderbook_delta", "seq": 565, "price": 60, "quantity": 200, "ts": 1756428146.82843, "side": "buy"}
{"type": "orderbook_delta", "seq": 566, "price": 68, "quantity": 139, "ts": 1756428146.84581, "side": "sell"}
{"type": "orderbook_delta", "seq": 567, "price": 60, "quantity": -200, "ts": 1756428146.874993, "side": "buy"}
{"type": "orderbook_delta", "seq": 568, "price": 71, "quantity": -200, "ts": 1756428146.888354, "side": "sell"}
{"type": "orderbook_delta", "seq": 569, "price": 59, "quantity": 200, "ts": 1756428146.913794, "side": "buy"}
{"type": "orderbook_delta", "seq": 570, "price": 70, "quantity": 200, "ts": 1756428146.929559, "side": "sell"}
{"type": "orderbook_delta", "seq": 571, "price": 50, "quantity": -250, "ts": 1756428146.941148, "side": "buy"}
{"type": "orderbook_delta", "seq": 572, "price": 60, "quantity": 250, "ts": 1756428146.946439, "side": "buy"}
{"type": "orderbook_delta", "seq": 573, "price": 58, "quantity": -1250, "ts": 1756428147.096061, "side": "buy"}
{"type": "orderbook_delta", "seq": 574, "price": 72, "quantity": -1250, "ts": 1756428147.097056, "side": "sell"}
{"type": "orderbook_delta", "seq": 575, "price": 68, "quantity": -500, "ts": 1756428147.097878, "side": "sell"}
{"type": "orderbook_delta", "seq": 576, "price": 52, "quantity": -250, "ts": 1756428147.100833, "side": "buy"}
{"type": "orderbook_delta", "seq": 577, "price": 64, "quantity": 250, "ts": 1756428147.101419, "side": "buy"}
{"type": "orderbook_delta", "seq": 578, "price": 54, "quantity": -250, "ts": 1756428147.137702, "side": "buy"}
{"type": "orderbook_delta", "seq": 579, "price": 62, "quantity": 250, "ts": 1756428147.137815, "side": "buy"}
{"type": "orderbook_delta", "seq": 580, "price": 82, "quantity": 250, "ts": 1756428147.142011, "side": "sell"}
{"type": "orderbook_delta", "seq": 581, "price": 72, "quantity": -250, "ts": 1756428147.142279, "side": "sell"}
{"type": "orderbook_delta", "seq": 582, "price": 71, "quantity": 1250, "ts": 1756428147.147605, "side": "sell"}
{"type": "orderbook_delta", "seq": 583, "price": 67, "quantity": 500, "ts": 1756428147.153657, "side": "sell"}
{"type": "orderbook_delta", "seq": 584, "price": 57, "quantity": 1250, "ts": 1756428147.173926, "side": "buy"}
{"type": "orderbook_delta", "seq": 585, "price": 82, "quantity": -250, "ts": 1756428147.184487, "side": "sell"}
{"type": "orderbook_delta", "seq": 586, "price": 72, "quantity": 250, "ts": 1756428147.190341, "side": "sell"}
{"type": "orderbook_delta", "seq": 587, "price": 61, "quantity": -100, "ts": 1756428147.254266, "side": "buy"}
{"type": "orderbook_delta", "seq": 588, "price": 64, "quantity": 100, "ts": 1756428147.254266, "side": "buy"}
{"type": "orderbook_delta", "seq": 589, "price": 66, "quantity": 100, "ts": 1756428147.26341, "side": "sell"}
{"type": "orderbook_delta", "seq": 590, "price": 54, "quantity": 250, "ts": 1756428147.307087, "side": "buy"}
{"type": "orderbook_delta", "seq": 591, "price": 64, "quantity": -250, "ts": 1756428147.307354, "side": "buy"}
{"type": "orderbook_delta", "seq": 592, "price": 57, "quantity": -1250, "ts": 1756428147.929345, "side": "buy"}
{"type": "orderbook_delta", "seq": 593, "price": 67, "quantity": -500, "ts": 1756428147.92955, "side": "sell"}
{"type": "orderbook_delta", "seq": 594, "price": 71, "quantity": -1250, "ts": 1756428147.932444, "side": "sell"}
{"type": "orderbook_delta", "seq": 595, "price": 72, "quantity": 1250, "ts": 1756428147.977952, "side": "sell"}
{"type": "orderbook_delta", "seq": 596, "price": 58, "quantity": 1250, "ts": 1756428147.980319, "side": "buy"}
{"type": "orderbook_delta", "seq": 597, "price": 68, "quantity": 500, "ts": 1756428147.981677, "side": "sell"}
{"type": "orderbook_delta", "seq": 598, "price": 68, "quantity": -500, "ts": 1756428148.016866, "side": "sell"}
{"type": "orderbook_delta", "seq": 599, "price": 67, "quantity": 500, "ts": 1756428148.058019, "side": "sell"}
{"type": "orderbook_delta", "seq": 600, "price": 70, "quantity": 250, "ts": 1756428148.120066, "side": "sell"}
{"type": "orderbook_delta", "seq": 601, "price": 68, "quantity": -139, "ts": 1756428148.136148, "side": "sell"}
{"type": "orderbook_delta", "seq": 602, "price": 80, "quantity": -250, "ts": 1756428148.175814, "side": "sell"}
{"type": "orderbook_delta", "seq": 603, "price": 63, "quantity": -100, "ts": 1756428148.233531, "side": "buy"}
{"type": "orderbook_delta", "seq": 604, "price": 67, "quantity": 139, "ts": 1756428148.247261, "side": "sell"}
{"type": "orderbook_delta", "seq": 605, "price": 64, "quantity": 100, "ts": 1756428148.429787, "side": "buy"}
{"type": "orderbook_delta", "seq": 606, "price": 68, "quantity": -100, "ts": 1756428148.719209, "side": "sell"}
{"type": "orderbook_delta", "seq": 607, "price": 69, "quantity": 100, "ts": 1756428148.719209, "side": "sell"}
{"type": "orderbook_delta", "seq": 608, "price": 71, "quantity": -200, "ts": 1756428148.771604, "side": "sell"}
{"type": "orderbook_delta", "seq": 609, "price": 69, "quantity": 200, "ts": 1756428148.771604, "side": "sell"}
{"type": "orderbook_delta", "seq": 610, "price": 80, "quantity": 250, "ts": 1756428149.146149, "side": "sell"}
{"type": "orderbook_delta", "seq": 611, "price": 70, "quantity": -250, "ts": 1756428149.178763, "side": "sell"}
{"type": "orderbook_delta", "seq": 612, "price": 70, "quantity": -200, "ts": 1756428149.207769, "side": "sell"}
{"type": "orderbook_delta", "seq": 613, "price": 71, "quantity": 200, "ts": 1756428149.264856, "side": "sell"}
{"type": "orderbook_delta", "seq": 614, "price": 64, "quantity": -100, "ts": 1756428149.359728, "side": "buy"}
{"type": "orderbook_delta", "seq": 615, "price": 64, "quantity": -100, "ts": 1756428149.500369, "side": "buy"}
{"type": "orderbook_delta", "seq": 616, "price": 63, "quantity": 100, "ts": 1756428149.500369, "side": "buy"}
{"type": "orderbook_delta", "seq": 617, "price": 66, "quantity": -100, "ts": 1756428149.611226, "side": "sell"}
{"type": "orderbook_delta", "seq": 618, "price": 67, "quantity": -500, "ts": 1756428149.717142, "side": "sell"}
{"type": "orderbook_delta", "seq": 619, "price": 59, "quantity": -200, "ts": 1756428149.719386, "side": "buy"}
{"type": "orderbook_delta", "seq": 620, "price": 68, "quantity": 500, "ts": 1756428149.785817, "side": "sell"}
{"type": "orderbook_delta", "seq": 621, "price": 60, "quantity": 200, "ts": 1756428149.795078, "side": "buy"}
{"type": "orderbook_delta", "seq": 622, "price": 60, "quantity": -200, "ts": 1756428150.059596, "side": "buy"}
{"type": "orderbook_delta", "seq": 623, "price": 68, "quantity": -500, "ts": 1756428150.059758, "side": "sell"}
{"type": "orderbook_delta", "seq": 624, "price": 59, "quantity": 200, "ts": 1756428150.099228, "side": "buy"}
{"type": "orderbook_delta", "seq": 625, "price": 67, "quantity": 500, "ts": 1756428150.122506, "side": "sell"}
{"type": "orderbook_delta", "seq": 626, "price": 70, "quantity": 250, "ts": 1756428150.140936, "side": "sell"}
{"type": "orderbook_delta", "seq": 627, "price": 80, "quantity": -250, "ts": 1756428150.148703, "side": "sell"}
{"type": "orderbook_delta", "seq": 628, "price": 58, "quantity": -1250, "ts": 1756428150.210638, "side": "buy"}
{"type": "orderbook_delta", "seq": 629, "price": 57, "quantity": 1250, "ts": 1756428150.258873, "side": "buy"}
{"type": "orderbook_delta", "seq": 630, "price": 71, "quantity": -200, "ts": 1756428150.291305, "side": "sell"}
{"type": "orderbook_delta", "seq": 631, "price": 70, "quantity": 200, "ts": 1756428150.327379, "side": "sell"}
{"type": "orderbook_delta", "seq": 632, "price": 63, "quantity": 100, "ts": 1756428150.587719, "side": "buy"}
{"type": "orderbook_delta", "seq": 633, "price": 66, "quantity": 100, "ts": 1756428151.353272, "side": "sell"}
{"type": "orderbook_delta", "seq": 634, "price": 70, "quantity": -250, "ts": 1756428152.120118, "side": "sell"}
{"type": "orderbook_delta", "seq": 635, "price": 80, "quantity": 250, "ts": 1756428152.120327, "side": "sell"}
{"type": "orderbook_delta", "seq": 636, "price": 70, "quantity": -200, "ts": 1756428152.16859, "side": "sell"}
{"type": "orderbook_delta", "seq": 637, "price": 71, "quantity": 200, "ts": 1756428152.211749, "side": "sell"}
{"type": "orderbook_delta", "seq": 638, "price": 72, "quantity": -1250, "ts": 1756428152.471002, "side": "sell"}
{"type": "orderbook_delta", "seq": 639, "price": 71, "quantity": 1250, "ts": 1756428152.518474, "side": "sell"}
{"type": "orderbook_delta", "seq": 640, "price": 69, "quantity": -100, "ts": 1756428152.762417, "side": "sell"}
{"type": "orderbook_delta", "seq": 641, "price": 70, "quantity": 100, "ts": 1756428152.762417, "side": "sell"}
{"type": "orderbook_delta", "seq": 642, "price": 67, "quantity": -500, "ts": 1756428152.855175, "side": "sell"}
{"type": "orderbook_delta", "seq": 643, "price": 71, "quantity": -1250, "ts": 1756428152.859103, "side": "sell"}
{"type": "orderbook_delta", "seq": 644, "price": 59, "quantity": -200, "ts": 1756428152.86043, "side": "buy"}
{"type": "orderbook_delta", "seq": 645, "price": 67, "quantity": -139, "ts": 1756428152.869251, "side": "sell"}
{"type": "orderbook_delta", "seq": 646, "price": 69, "quantity": -200, "ts": 1756428152.869298, "side": "sell"}
{"type": "orderbook_delta", "seq": 647, "price": 71, "quantity": 200, "ts": 1756428152.869298, "side": "sell"}
{"type": "orderbook_delta", "seq": 648, "price": 62, "quantity": -500, "ts": 1756428152.869598, "side": "buy"}
{"type": "orderbook_delta", "seq": 649, "price": 57, "quantity": -1250, "ts": 1756428152.87847, "side": "buy"}
{"type": "orderbook_delta", "seq": 650, "price": 68, "quantity": 139, "ts": 1756428152.910409, "side": "sell"}
{"type": "orderbook_delta", "seq": 651, "price": 71, "quantity": -200, "ts": 1756428152.918991, "side": "sell"}
{"type": "orderbook_delta", "seq": 652, "price": 73, "quantity": 200, "ts": 1756428152.918991, "side": "sell"}
{"type": "orderbook_delta", "seq": 653, "price": 60, "quantity": 200, "ts": 1756428152.922537, "side": "buy"}
{"type": "orderbook_delta", "seq": 654, "price": 59, "quantity": 1250, "ts": 1756428152.923708, "side": "buy"}
{"type": "orderbook_delta", "seq": 655, "price": 69, "quantity": 500, "ts": 1756428152.925814, "side": "sell"}
{"type": "orderbook_delta", "seq": 656, "price": 73, "quantity": 1250, "ts": 1756428152.928754, "side": "sell"}
{"type": "orderbook_delta", "seq": 657, "price": 63, "quantity": 500, "ts": 1756428152.929003, "side": "buy"}
{"type": "orderbook_delta", "seq": 658, "price": 70, "quantity": -100, "ts": 1756428152.934802, "side": "sell"}
{"type": "orderbook_delta", "seq": 659, "price": 71, "quantity": 100, "ts": 1756428152.934802, "side": "sell"}
{"type": "orderbook_delta", "seq": 660, "price": 69, "quantity": -500, "ts": 1756428152.977608, "side": "sell"}
{"type": "orderbook_delta", "seq": 661, "price": 68, "quantity": -139, "ts": 1756428152.981639, "side": "sell"}
{"type": "orderbook_delta", "seq": 662, "price": 73, "quantity": -1250, "ts": 1756428152.986881, "side": "sell"}
{"type": "orderbook_delta", "seq": 663, "price": 82, "quantity": 250, "ts": 1756428152.988326, "side": "sell"}
{"type": "orderbook_delta", "seq": 664, "price": 60, "quantity": -200, "ts": 1756428152.989228, "side": "buy"}
{"type": "orderbook_delta", "seq": 665, "price": 63, "quantity": -500, "ts": 1756428152.989314, "side": "buy"}
{"type": "orderbook_delta", "seq": 666, "price": 59, "quantity": -1250, "ts": 1756428152.989974, "side": "buy"}
{"type": "orderbook_delta", "seq": 667, "price": 63, "quantity": -100, "ts": 1756428152.990911, "side": "buy"}
{"type": "orderbook_delta", "seq": 668, "price": 64, "quantity": 100, "ts": 1756428152.990911, "side": "buy"}
{"type": "orderbook_delta", "seq": 669, "price": 71, "quantity": -200, "ts": 1756428152.991151, "side": "sell"}
{"type": "orderbook_delta", "seq": 670, "price": 72, "quantity": -250, "ts": 1756428153.017459, "side": "sell"}
{"type": "orderbook_delta", "seq": 671, "price": 62, "quantity": -250, "ts": 1756428153.039243, "side": "buy"}
{"type": "orderbook_delta", "seq": 672, "price": 52, "quantity": 250, "ts": 1756428153.041891, "side": "buy"}
{"type": "orderbook_delta", "seq": 673, "price": 70, "quantity": 500, "ts": 1756428153.045737, "side": "sell"}
{"type": "orderbook_delta", "seq": 674, "price": 64, "quantity": -100, "ts": 1756428153.049201, "side": "buy"}
{"type": "orderbook_delta", "seq": 675, "price": 63, "quantity": 100, "ts": 1756428153.049201, "side": "buy"}
{"type": "orderbook_delta", "seq": 676, "price": 74, "quantity": 1250, "ts": 1756428153.051758, "side": "sell"}
{"type": "orderbook_delta", "seq": 677, "price": 62, "quantity": 200, "ts": 1756428153.05433, "side": "buy"}
{"type": "orderbook_delta", "seq": 678, "price": 65, "quantity": 500, "ts": 1756428153.056102, "side": "buy"}
{"type": "orderbook_delta", "seq": 679, "price": 74, "quantity": -250, "ts": 1756428153.056561, "side": "sell"}
{"type": "orderbook_delta", "seq": 680, "price": 84, "quantity": 250, "ts": 1756428153.056799, "side": "sell"}
{"type": "orderbook_delta", "seq": 681, "price": 61, "quantity": 1250, "ts": 1756428153.057697, "side": "buy"}
{"type": "orderbook_delta", "seq": 682, "price": 73, "quantity": 200, "ts": 1756428153.065301, "side": "sell"}
{"type": "orderbook_delta", "seq": 683, "price": 69, "quantity": 139, "ts": 1756428153.080683, "side": "sell"}
{"type": "orderbook_delta", "seq": 684, "price": 71, "quantity": -100, "ts": 1756428153.092791, "side": "sell"}
{"type": "orderbook_delta", "seq": 685, "price": 72, "quantity": 100, "ts": 1756428153.092791, "side": "sell"}
{"type": "orderbook_delta", "seq": 686, "price": 64, "quantity": 250, "ts": 1756428153.11369, "side": "buy"}
{"type": "orderbook_delta", "seq": 687, "price": 52, "quantity": -250, "ts": 1756428153.136124, "side": "buy"}
{"type": "orderbook_delta", "seq": 688, "price": 62, "quantity": -200, "ts": 1756428153.188103, "side": "buy"}
{"type": "orderbook_delta", "seq": 689, "price": 74, "quantity": -1250, "ts": 1756428153.188755, "side": "sell"}
{"type": "orderbook_delta", "seq": 690, "price": 65, "quantity": -500, "ts": 1756428153.190418, "side": "buy"}
{"type": "orderbook_delta", "seq": 691, "price": 84, "quantity": -250, "ts": 1756428153.197054, "side": "sell"}
{"type": "orderbook_delta", "seq": 692, "price": 54, "quantity": -250, "ts": 1756428153.282143, "side": "buy"}
{"type": "orderbook_delta", "seq": 693, "price": 69, "quantity": -139, "ts": 1756428153.284486, "side": "sell"}
{"type": "orderbook_delta", "seq": 694, "price": 62, "quantity": 250, "ts": 1756428153.284514, "side": "buy"}
{"type": "orderbook_delta", "seq": 695, "price": 72, "quantity": -100, "ts": 1756428153.285405, "side": "sell"}
{"type": "orderbook_delta", "seq": 696, "price": 73, "quantity": 100, "ts": 1756428153.285405, "side": "sell"}
{"type": "orderbook_delta", "seq": 697, "price": 61, "quantity": 200, "ts": 1756428153.365409, "side": "buy"}
{"type": "orderbook_delta", "seq": 698, "price": 64, "quantity": 500, "ts": 1756428153.36608, "side": "buy"}
{"type": "orderbook_delta", "seq": 699, "price": 75, "quantity": 1250, "ts": 1756428153.366443, "side": "sell"}
{"type": "orderbook_delta", "seq": 700, "price": 64, "quantity": -250, "ts": 1756428153.367888, "side": "buy"}
{"type": "orderbook_delta", "seq": 701, "price": 70, "quantity": -500, "ts": 1756428153.369771, "side": "sell"}
{"type": "orderbook_delta", "seq": 702, "price": 70, "quantity": 139, "ts": 1756428153.41358, "side": "sell"}
{"type": "orderbook_delta", "seq": 703, "price": 61, "quantity": -200, "ts": 1756428153.421318, "side": "buy"}
{"type": "orderbook_delta", "seq": 704, "price": 62, "quantity": 200, "ts": 1756428153.460252, "side": "buy"}
{"type": "orderbook_delta", "seq": 705, "price": 70, "quantity": 500, "ts": 1756428153.485663, "side": "sell"}
{"type": "orderbook_delta", "seq": 706, "price": 70, "quantity": -500, "ts": 1756428153.559706, "side": "sell"}
{"type": "orderbook_delta", "seq": 707, "price": 62, "quantity": -200, "ts": 1756428153.560859, "side": "buy"}
{"type": "orderbook_delta", "seq": 708, "price": 61, "quantity": -1250, "ts": 1756428153.561001, "side": "buy"}
{"type": "orderbook_delta", "seq": 709, "price": 75, "quantity": -1250, "ts": 1756428153.562664, "side": "sell"}
{"type": "orderbook_delta", "seq": 710, "price": 73, "quantity": -200, "ts": 1756428153.562828, "side": "sell"}
{"type": "orderbook_delta", "seq": 711, "price": 64, "quantity": 250, "ts": 1756428153.571215, "side": "buy"}
{"type": "orderbook_delta", "seq": 712, "price": 63, "quantity": 200, "ts": 1756428153.604107, "side": "buy"}
{"type": "orderbook_delta", "seq": 713, "price": 72, "quantity": 500, "ts": 1756428153.604705, "side": "sell"}
{"type": "orderbook_delta", "seq": 714, "price": 75, "quantity": 200, "ts": 1756428153.60615, "side": "sell"}
{"type": "orderbook_delta", "seq": 715, "price": 64, "quantity": -500, "ts": 1756428153.606518, "side": "buy"}
{"type": "orderbook_delta", "seq": 716, "price": 76, "quantity": 1250, "ts": 1756428153.606535, "side": "sell"}
{"type": "orderbook_delta", "seq": 717, "price": 62, "quantity": 1250, "ts": 1756428153.607216, "side": "buy"}
{"type": "orderbook_delta", "seq": 718, "price": 65, "quantity": 500, "ts": 1756428153.644774, "side": "buy"}
{"type": "orderbook_delta", "seq": 719, "price": 63, "quantity": -100, "ts": 1756428153.796336, "side": "buy"}
{"type": "orderbook_delta", "seq": 720, "price": 65, "quantity": 100, "ts": 1756428153.796336, "side": "buy"}
{"type": "orderbook_delta", "seq": 721, "price": 63, "quantity": -100, "ts": 1756428154.073158, "side": "buy"}
{"type": "orderbook_delta", "seq": 722, "price": 70, "quantity": -139, "ts": 1756428154.117377, "side": "sell"}
{"type": "orderbook_delta", "seq": 723, "price": 71, "quantity": 139, "ts": 1756428154.159749, "side": "sell"}
{"type": "orderbook_delta", "seq": 724, "price": 66, "quantity": -100, "ts": 1756428154.306639, "side": "sell"}
{"type": "orderbook_delta", "seq": 725, "price": 65, "quantity": -500, "ts": 1756428154.345879, "side": "buy"}
{"type": "orderbook_delta", "seq": 726, "price": 65, "quantity": -100, "ts": 1756428154.360248, "side": "buy"}
{"type": "orderbook_delta", "seq": 727, "price": 66, "quantity": 100, "ts": 1756428154.360248, "side": "buy"}
{"type": "orderbook_delta", "seq": 728, "price": 66, "quantity": 250, "ts": 1756428154.37566, "side": "buy"}
{"type": "orderbook_delta", "seq": 729, "price": 56, "quantity": -250, "ts": 1756428154.378545, "side": "buy"}
{"type": "orderbook_delta", "seq": 730, "price": 66, "quantity": 500, "ts": 1756428154.385906, "side": "buy"}
{"type": "orderbook_delta", "seq": 731, "price": 72, "quantity": -500, "ts": 1756428154.445962, "side": "sell"}
{"type": "orderbook_delta", "seq": 732, "price": 76, "quantity": -1250, "ts": 1756428154.449839, "side": "sell"}
{"type": "orderbook_delta", "seq": 733, "price": 66, "quantity": -500, "ts": 1756428154.452642, "side": "buy"}
{"type": "orderbook_delta", "seq": 734, "price": 62, "quantity": -1250, "ts": 1756428154.456045, "side": "buy"}
{"type": "orderbook_delta", "seq": 735, "price": 71, "quantity": 500, "ts": 1756428154.489019, "side": "sell"}
{"type": "orderbook_delta", "seq": 736, "price": 75, "quantity": 1250, "ts": 1756428154.48978, "side": "sell"}
{"type": "orderbook_delta", "seq": 737, "price": 65, "quantity": 500, "ts": 1756428154.500205, "side": "buy"}
{"type": "orderbook_delta", "seq": 738, "price": 61, "quantity": 1250, "ts": 1756428154.500523, "side": "buy"}
{"type": "orderbook_delta", "seq": 739, "price": 73, "quantity": -200, "ts": 1756428154.60583, "side": "sell"}
{"type": "orderbook_delta", "seq": 740, "price": 70, "quantity": 200, "ts": 1756428154.60583, "side": "sell"}
{"type": "orderbook_delta", "seq": 741, "price": 66, "quantity": -100, "ts": 1756428154.669938, "side": "buy"}
{"type": "orderbook_delta", "seq": 742, "price": 67, "quantity": 100, "ts": 1756428154.669938, "side": "buy"}
{"type": "orderbook_delta", "seq": 743, "price": 67, "quantity": -100, "ts": 1756428154.721695, "side": "buy"}
{"type": "orderbook_delta", "seq": 744, "price": 64, "quantity": 100, "ts": 1756428154.721695, "side": "buy"}
{"type": "orderbook_delta", "seq": 745, "price": 65, "quantity": -500, "ts": 1756428154.807634, "side": "buy"}
{"type": "orderbook_delta", "seq": 746, "price": 73, "quantity": -100, "ts": 1756428154.807909, "side": "sell"}
{"type": "orderbook_delta", "seq": 747, "price": 74, "quantity": 100, "ts": 1756428154.807909, "side": "sell"}
{"type": "orderbook_delta", "seq": 748, "price": 61, "quantity": -1250, "ts": 1756428154.808282, "side": "buy"}
{"type": "orderbook_delta", "seq": 749, "price": 62, "quantity": 1250, "ts": 1756428154.848556, "side": "buy"}
{"type": "orderbook_delta", "seq": 750, "price": 66, "quantity": 500, "ts": 1756428154.848867, "side": "buy"}
{"type": "orderbook_delta", "seq": 751, "price": 71, "quantity": -139, "ts": 1756428155.172877, "side": "sell"}
{"type": "orderbook_delta", "seq": 752, "price": 71, "quantity": -500, "ts": 1756428155.200931, "side": "sell"}
{"type": "orderbook_delta", "seq": 753, "price": 70, "quantity": 139, "ts": 1756428155.211948, "side": "sell"}
{"type": "orderbook_delta", "seq": 754, "price": 73, "quantity": 500, "ts": 1756428155.246436, "side": "sell"}
{"type": "orderbook_delta", "seq": 755, "price": 56, "quantity": 250, "ts": 1756428155.305912, "side": "buy"}
{"type": "orderbook_delta", "seq": 756, "price": 64, "quantity": -250, "ts": 1756428155.308163, "side": "buy"}
{"type": "orderbook_delta", "seq": 757, "price": 75, "quantity": -200, "ts": 1756428155.32033, "side": "sell"}
{"type": "orderbook_delta", "seq": 758, "price": 66, "quantity": -250, "ts": 1756428155.325622, "side": "buy"}
{"type": "orderbook_delta", "seq": 759, "price": 54, "quantity": 250, "ts": 1756428155.325647, "side": "buy"}
{"type": "orderbook_delta", "seq": 760, "price": 66, "quantity": -500, "ts": 1756428155.325901, "side": "buy"}
{"type": "orderbook_delta", "seq": 761, "price": 73, "quantity": -500, "ts": 1756428155.326586, "side": "sell"}
{"type": "orderbook_delta", "seq": 762, "price": 63, "quantity": -200, "ts": 1756428155.337387, "side": "buy"}
{"type": "orderbook_delta", "seq": 763, "price": 62, "quantity": -1250, "ts": 1756428155.339018, "side": "buy"}
{"type": "orderbook_delta", "seq": 764, "price": 59, "quantity": 200, "ts": 1756428155.373658, "side": "buy"}
{"type": "orderbook_delta", "seq": 765, "price": 70, "quantity": 200, "ts": 1756428155.373889, "side": "sell"}
{"type": "orderbook_delta", "seq": 766, "price": 62, "quantity": 500, "ts": 1756428155.375387, "side": "buy"}
{"type": "orderbook_delta", "seq": 767, "price": 58, "quantity": 1250, "ts": 1756428155.376462, "side": "buy"}
{"type": "orderbook_delta", "seq": 768, "price": 69, "quantity": 500, "ts": 1756428155.37676, "side": "sell"}
{"type": "orderbook_delta", "seq": 769, "price": 62, "quantity": -500, "ts": 1756428155.549611, "side": "buy"}
{"type": "orderbook_delta", "seq": 770, "price": 74, "quantity": -100, "ts": 1756428155.558967, "side": "sell"}
{"type": "orderbook_delta", "seq": 771, "price": 71, "quantity": 100, "ts": 1756428155.558967, "side": "sell"}
{"type": "orderbook_delta", "seq": 772, "price": 58, "quantity": -1250, "ts": 1756428155.563021, "side": "buy"}
{"type": "orderbook_delta", "seq": 773, "price": 57, "quantity": 1250, "ts": 1756428155.613755, "side": "buy"}
{"type": "orderbook_delta", "seq": 774, "price": 61, "quantity": 500, "ts": 1756428155.624393, "side": "buy"}
{"type": "orderbook_delta", "seq": 775, "price": 70, "quantity": -200, "ts": 1756428155.685525, "side": "sell"}
{"type": "orderbook_delta", "seq": 776, "price": 69, "quantity": 200, "ts": 1756428155.685525, "side": "sell"}
{"type": "orderbook_delta", "seq": 777, "price": 59, "quantity": -200, "ts": 1756428155.725972, "side": "buy"}
{"type": "orderbook_delta", "seq": 778, "price": 61, "quantity": -500, "ts": 1756428155.726943, "side": "buy"}
{"type": "orderbook_delta", "seq": 779, "price": 57, "quantity": -1250, "ts": 1756428155.727078, "side": "buy"}
{"type": "orderbook_delta", "seq": 780, "price": 69, "quantity": -500, "ts": 1756428155.727185, "side": "sell"}
{"type": "orderbook_delta", "seq": 781, "price": 70, "quantity": -200, "ts": 1756428155.733205, "side": "sell"}
{"type": "orderbook_delta", "seq": 782, "price": 75, "quantity": -1250, "ts": 1756428155.747048, "side": "sell"}
{"type": "orderbook_delta", "seq": 783, "price": 68, "quantity": 500, "ts": 1756428155.766508, "side": "sell"}
{"type": "orderbook_delta", "seq": 784, "price": 59, "quantity": 500, "ts": 1756428155.766788, "side": "buy"}
{"type": "orderbook_delta", "seq": 785, "price": 57, "quantity": 200, "ts": 1756428155.769734, "side": "buy"}
{"type": "orderbook_delta", "seq": 786, "price": 55, "quantity": 1250, "ts": 1756428155.770994, "side": "buy"}
{"type": "orderbook_delta", "seq": 787, "price": 68, "quantity": 200, "ts": 1756428155.771297, "side": "sell"}
{"type": "orderbook_delta", "seq": 788, "price": 69, "quantity": 1250, "ts": 1756428155.791883, "side": "sell"}
{"type": "orderbook_delta", "seq": 789, "price": 62, "quantity": -250, "ts": 1756428155.812485, "side": "buy"}
{"type": "orderbook_delta", "seq": 790, "price": 52, "quantity": 250, "ts": 1756428155.81597, "side": "buy"}
{"type": "orderbook_delta", "seq": 791, "price": 64, "quantity": -100, "ts": 1756428156.053097, "side": "buy"}
{"type": "orderbook_delta", "seq": 792, "price": 61, "quantity": 100, "ts": 1756428156.053097, "side": "buy"}
{"type": "orderbook_delta", "seq": 793, "price": 72, "quantity": 250, "ts": 1756428156.136739, "side": "sell"}
{"type": "orderbook_delta", "seq": 794, "price": 70, "quantity": -139, "ts": 1756428156.167555, "side": "sell"}
{"type": "orderbook_delta", "seq": 795, "price": 68, "quantity": 250, "ts": 1756428156.167602, "side": "sell"}
{"type": "orderbook_delta", "seq": 796, "price": 80, "quantity": -250, "ts": 1756428156.196347, "side": "sell"}
{"type": "orderbook_delta", "seq": 797, "price": 69, "quantity": -200, "ts": 1756428156.201237, "side": "sell"}
{"type": "orderbook_delta", "seq": 798, "price": 68, "quantity": 200, "ts": 1756428156.201237, "side": "sell"}
{"type": "orderbook_delta", "seq": 799, "price": 68, "quantity": -500, "ts": 1756428156.213298, "side": "sell"}
{"type": "orderbook_delta", "seq": 800, "price": 69, "quantity": -1250, "ts": 1756428156.235512, "side": "sell"}
{"type": "orderbook_delta", "seq": 801, "price": 74, "quantity": 250, "ts": 1756428156.236951, "side": "sell"}
{"type": "orderbook_delta", "seq": 802, "price": 78, "quantity": -250, "ts": 1756428156.256781, "side": "sell"}
{"type": "orderbook_delta", "seq": 803, "price": 67, "quantity": 500, "ts": 1756428156.257414, "side": "sell"}
{"type": "orderbook_delta", "seq": 804, "price": 70, "quantity": 250, "ts": 1756428156.257759, "side": "sell"}
{"type": "orderbook_delta", "seq": 805, "price": 82, "quantity": -250, "ts": 1756428156.276577, "side": "sell"}
{"type": "orderbook_delta", "seq": 806, "price": 71, "quantity": 1250, "ts": 1756428156.287557, "side": "sell"}
{"type": "orderbook_delta", "seq": 807, "price": 71, "quantity": -1250, "ts": 1756428156.328815, "side": "sell"}
{"type": "orderbook_delta", "seq": 808, "price": 65, "quantity": 139, "ts": 1756428156.337672, "side": "sell"}
{"type": "orderbook_delta", "seq": 809, "price": 67, "quantity": -500, "ts": 1756428156.441052, "side": "sell"}
{"type": "orderbook_delta", "seq": 810, "price": 69, "quantity": 1250, "ts": 1756428156.441075, "side": "sell"}
{"type": "trade", "seq": 13, "price": 65, "quantity": 139, "ts": 1756428156.441075, "side": "buy"}
{"type": "trade", "seq": 14, "price": 68, "quantity": 139, "ts": 1756428156.445213, "side": "buy"}
{"type": "orderbook_delta", "seq": 811, "price": 65, "quantity": 0, "ts": 1756428156.445213, "side": "sell"}
{"type": "orderbook_delta", "seq": 812, "price": 68, "quantity": 0, "ts": 1756428156.445213, "side": "sell"}
{"type": "orderbook_delta", "seq": 813, "price": 65, "quantity": 500, "ts": 1756428156.521994, "side": "sell"}
{"type": "orderbook_delta", "seq": 814, "price": 65, "quantity": -500, "ts": 1756428156.559622, "side": "sell"}
{"type": "orderbook_delta", "seq": 815, "price": 67, "quantity": 500, "ts": 1756428156.60396, "side": "sell"}
{"type": "orderbook_delta", "seq": 816, "price": 71, "quantity": -100, "ts": 1756428156.819766, "side": "sell"}
{"type": "orderbook_delta", "seq": 817, "price": 69, "quantity": 100, "ts": 1756428156.819766, "side": "sell"}
{"type": "orderbook_delta", "seq": 818, "price": 64, "quantity": 100, "ts": 1756428156.888203, "side": "buy"}
{"type": "orderbook_delta", "seq": 819, "price": 57, "quantity": -200, "ts": 1756428156.960167, "side": "buy"}
{"type": "orderbook_delta", "seq": 820, "price": 68, "quantity": -61, "ts": 1756428156.964374, "side": "sell"}
{"type": "orderbook_delta", "seq": 821, "price": 56, "quantity": 200, "ts": 1756428156.999879, "side": "buy"}
{"type": "orderbook_delta", "seq": 822, "price": 67, "quantity": 200, "ts": 1756428157.000191, "side": "sell"}
{"type": "orderbook_delta", "seq": 823, "price": 64, "quantity": -100, "ts": 1756428158.374692, "side": "buy"}
{"type": "orderbook_delta", "seq": 824, "price": 62, "quantity": 100, "ts": 1756428158.580041, "side": "buy"}
{"type": "orderbook_delta", "seq": 825, "price": 67, "quantity": -200, "ts": 1756428159.092026, "side": "sell"}
{"type": "orderbook_delta", "seq": 826, "price": 56, "quantity": -200, "ts": 1756428159.094742, "side": "buy"}
{"type": "orderbook_delta", "seq": 827, "price": 57, "quantity": 200, "ts": 1756428159.120238, "side": "buy"}
{"type": "orderbook_delta", "seq": 828, "price": 68, "quantity": 200, "ts": 1756428159.122738, "side": "sell"}
{"type": "orderbook_delta", "seq": 829, "price": 69, "quantity": -1250, "ts": 1756428160.249362, "side": "sell"}
{"type": "orderbook_delta", "seq": 830, "price": 59, "quantity": -500, "ts": 1756428160.252012, "side": "buy"}
{"type": "orderbook_delta", "seq": 831, "price": 70, "quantity": 1250, "ts": 1756428160.292826, "side": "sell"}
{"type": "orderbook_delta", "seq": 832, "price": 60, "quantity": 500, "ts": 1756428160.294486, "side": "buy"}
{"type": "orderbook_delta", "seq": 833, "price": 69, "quantity": -100, "ts": 1756428160.754397, "side": "sell"}
{"type": "orderbook_delta", "seq": 834, "price": 70, "quantity": 100, "ts": 1756428160.754397, "side": "sell"}
{"type": "orderbook_delta", "seq": 835, "price": 62, "quantity": -100, "ts": 1756428160.988772, "side": "buy"}
{"type": "orderbook_delta", "seq": 836, "price": 68, "quantity": -200, "ts": 1756428161.086377, "side": "sell"}
{"type": "orderbook_delta", "seq": 837, "price": 60, "quantity": -500, "ts": 1756428161.087064, "side": "buy"}
{"type": "orderbook_delta", "seq": 838, "price": 70, "quantity": -1250, "ts": 1756428161.087195, "side": "sell"}
{"type": "orderbook_delta", "seq": 839, "price": 57, "quantity": -200, "ts": 1756428161.087287, "side": "buy"}
{"type": "orderbook_delta", "seq": 840, "price": 55, "quantity": -1250, "ts": 1756428161.123966, "side": "buy"}
{"type": "orderbook_delta", "seq": 841, "price": 52, "quantity": -250, "ts": 1756428161.14025, "side": "buy"}
{"type": "orderbook_delta", "seq": 842, "price": 62, "quantity": 250, "ts": 1756428161.147803, "side": "buy"}
{"type": "orderbook_delta", "seq": 843, "price": 78, "quantity": 250, "ts": 1756428161.167026, "side": "sell"}
{"type": "orderbook_delta", "seq": 844, "price": 68, "quantity": -250, "ts": 1756428161.167344, "side": "sell"}
{"type": "orderbook_delta", "seq": 845, "price": 57, "quantity": 1250, "ts": 1756428161.185498, "side": "buy"}
{"type": "orderbook_delta", "seq": 846, "price": 58, "quantity": 200, "ts": 1756428161.185859, "side": "buy"}
{"type": "orderbook_delta", "seq": 847, "price": 69, "quantity": 200, "ts": 1756428161.187087, "side": "sell"}
{"type": "orderbook_delta", "seq": 848, "price": 61, "quantity": 500, "ts": 1756428161.187419, "side": "buy"}
{"type": "orderbook_delta", "seq": 849, "price": 71, "quantity": 1250, "ts": 1756428161.18808, "side": "sell"}
{"type": "orderbook_delta", "seq": 850, "price": 61, "quantity": -100, "ts": 1756428161.207514, "side": "buy"}
{"type": "orderbook_delta", "seq": 851, "price": 63, "quantity": 100, "ts": 1756428161.207514, "side": "buy"}
{"type": "orderbook_delta", "seq": 852, "price": 62, "quantity": -250, "ts": 1756428161.229532, "side": "buy"}
{"type": "orderbook_delta", "seq": 853, "price": 63, "quantity": 100, "ts": 1756428161.255066, "side": "buy"}
{"type": "orderbook_delta", "seq": 854, "price": 63, "quantity": -100, "ts": 1756428161.289019, "side": "buy"}
{"type": "orderbook_delta", "seq": 855, "price": 62, "quantity": 100, "ts": 1756428161.289019, "side": "buy"}
{"type": "orderbook_delta", "seq": 856, "price": 61, "quantity": -500, "ts": 1756428161.329375, "side": "buy"}
{"type": "orderbook_delta", "seq": 857, "price": 57, "quantity": -1250, "ts": 1756428161.329689, "side": "buy"}
{"type": "orderbook_delta", "seq": 858, "price": 71, "quantity": -1250, "ts": 1756428161.351907, "side": "sell"}
{"type": "orderbook_delta", "seq": 859, "price": 56, "quantity": 1250, "ts": 1756428161.398143, "side": "buy"}
{"type": "orderbook_delta", "seq": 860, "price": 70, "quantity": 1250, "ts": 1756428161.41548, "side": "sell"}
{"type": "orderbook_delta", "seq": 861, "price": 60, "quantity": 500, "ts": 1756428161.416327, "side": "buy"}
{"type": "orderbook_delta", "seq": 862, "price": 66, "quantity": 100, "ts": 1756428161.951844, "side": "sell"}
{"type": "orderbook_delta", "seq": 863, "price": 67, "quantity": -500, "ts": 1756428161.994324, "side": "sell"}
{"type": "orderbook_delta", "seq": 864, "price": 66, "quantity": 500, "ts": 1756428162.036026, "side": "sell"}
{"type": "orderbook_delta", "seq": 865, "price": 69, "quantity": -200, "ts": 1756428162.218248, "side": "sell"}
{"type": "orderbook_delta", "seq": 866, "price": 58, "quantity": -200, "ts": 1756428162.218886, "side": "buy"}
{"type": "orderbook_delta", "seq": 867, "price": 68, "quantity": 200, "ts": 1756428162.260632, "side": "sell"}
{"type": "orderbook_delta", "seq": 868, "price": 57, "quantity": 200, "ts": 1756428162.261351, "side": "buy"}
{"type": "orderbook_delta", "seq": 869, "price": 68, "quantity": -200, "ts": 1756428163.273758, "side": "sell"}
{"type": "orderbook_delta", "seq": 870, "price": 57, "quantity": -200, "ts": 1756428163.309803, "side": "buy"}
{"type": "orderbook_delta", "seq": 871, "price": 69, "quantity": 200, "ts": 1756428163.356497, "side": "sell"}
{"type": "orderbook_delta", "seq": 872, "price": 58, "quantity": 200, "ts": 1756428163.466183, "side": "buy"}
{"type": "orderbook_delta", "seq": 873, "price": 70, "quantity": -100, "ts": 1756428164.167932, "side": "sell"}
{"type": "orderbook_delta", "seq": 874, "price": 68, "quantity": 100, "ts": 1756428164.167932, "side": "sell"}
{"type": "orderbook_delta", "seq": 875, "price": 62, "quantity": -100, "ts": 1756428164.292539, "side": "buy"}
{"type": "orderbook_delta", "seq": 876, "price": 61, "quantity": 100, "ts": 1756428164.292539, "side": "buy"}
{"type": "orderbook_delta", "seq": 877, "price": 66, "quantity": 0, "ts": 1756428165.341064, "side": "sell"}
{"type": "trade", "seq": 15, "price": 66, "quantity": 1, "ts": 1756428165.507042, "side": "buy"}
{"type": "orderbook_delta", "seq": 878, "price": 68, "quantity": -200, "ts": 1756428165.507042, "side": "sell"}
{"type": "orderbook_delta", "seq": 879, "price": 69, "quantity": 200, "ts": 1756428165.507042, "side": "sell"}
{"type": "orderbook_delta", "seq": 880, "price": 69, "quantity": -200, "ts": 1756428165.700049, "side": "sell"}
{"type": "orderbook_delta", "seq": 881, "price": 58, "quantity": -200, "ts": 1756428165.700108, "side": "buy"}
{"type": "orderbook_delta", "seq": 882, "price": 68, "quantity": 200, "ts": 1756428165.743349, "side": "sell"}
{"type": "orderbook_delta", "seq": 883, "price": 57, "quantity": 200, "ts": 1756428165.755037, "side": "buy"}
{"type": "orderbook_delta", "seq": 884, "price": 57, "quantity": -200, "ts": 1756428166.520761, "side": "buy"}
{"type": "orderbook_delta", "seq": 885, "price": 68, "quantity": -200, "ts": 1756428166.523421, "side": "sell"}
{"type": "orderbook_delta", "seq": 886, "price": 58, "quantity": 200, "ts": 1756428166.58061, "side": "buy"}
{"type": "orderbook_delta", "seq": 887, "price": 69, "quantity": 200, "ts": 1756428166.584285, "side": "sell"}
{"type": "orderbook_delta", "seq": 888, "price": 58, "quantity": -200, "ts": 1756428166.688014, "side": "buy"}
{"type": "orderbook_delta", "seq": 889, "price": 69, "quantity": -200, "ts": 1756428166.688484, "side": "sell"}
{"type": "orderbook_delta", "seq": 890, "price": 57, "quantity": 200, "ts": 1756428166.722042, "side": "buy"}
{"type": "orderbook_delta", "seq": 891, "price": 68, "quantity": 200, "ts": 1756428166.751773, "side": "sell"}
{"type": "orderbook_delta", "seq": 892, "price": 68, "quantity": -200, "ts": 1756428167.29321, "side": "sell"}
{"type": "orderbook_delta", "seq": 893, "price": 57, "quantity": -200, "ts": 1756428167.296277, "side": "buy"}
{"type": "orderbook_delta", "seq": 894, "price": 58, "quantity": 200, "ts": 1756428167.345498, "side": "buy"}
{"type": "orderbook_delta", "seq": 895, "price": 69, "quantity": 200, "ts": 1756428167.3466, "side": "sell"}
{"type": "orderbook_delta", "seq": 896, "price": 69, "quantity": -200, "ts": 1756428167.497897, "side": "sell"}
{"type": "orderbook_delta", "seq": 897, "price": 58, "quantity": -200, "ts": 1756428167.498911, "side": "buy"}
{"type": "orderbook_delta", "seq": 898, "price": 57, "quantity": 200, "ts": 1756428167.533824, "side": "buy"}
{"type": "orderbook_delta", "seq": 899, "price": 68, "quantity": 200, "ts": 1756428167.534189, "side": "sell"}
{"type": "orderbook_delta", "seq": 900, "price": 57, "quantity": -200, "ts": 1756428167.854942, "side": "buy"}
{"type": "orderbook_delta", "seq": 901, "price": 68, "quantity": -200, "ts": 1756428167.855775, "side": "sell"}
{"type": "orderbook_delta", "seq": 902, "price": 69, "quantity": 200, "ts": 1756428167.898517, "side": "sell"}
{"type": "orderbook_delta", "seq": 903, "price": 58, "quantity": 200, "ts": 1756428167.902981, "side": "buy"}
{"type": "orderbook_delta", "seq": 904, "price": 68, "quantity": -100, "ts": 1756428170.267297, "side": "sell"}
{"type": "orderbook_delta", "seq": 905, "price": 68, "quantity": 100, "ts": 1756428171.780363, "side": "sell"}
{"type": "orderbook_delta", "seq": 906, "price": 60, "quantity": -500, "ts": 1756428172.606083, "side": "buy"}
{"type": "orderbook_delta", "seq": 907, "price": 56, "quantity": -1250, "ts": 1756428172.606254, "side": "buy"}
{"type": "orderbook_delta", "seq": 908, "price": 70, "quantity": -1250, "ts": 1756428172.6074, "side": "sell"}
{"type": "orderbook_delta", "seq": 909, "price": 66, "quantity": -500, "ts": 1756428172.612467, "side": "sell"}
{"type": "orderbook_delta", "seq": 910, "price": 67, "quantity": 500, "ts": 1756428172.654303, "side": "sell"}
{"type": "orderbook_delta", "seq": 911, "price": 71, "quantity": 1250, "ts": 1756428172.655022, "side": "sell"}
{"type": "orderbook_delta", "seq": 912, "price": 61, "quantity": 500, "ts": 1756428172.6555, "side": "buy"}
{"type": "orderbook_delta", "seq": 913, "price": 57, "quantity": 1250, "ts": 1756428172.669894, "side": "buy"}
{"type": "orderbook_delta", "seq": 914, "price": 61, "quantity": -100, "ts": 1756428172.760788, "side": "buy"}
{"type": "orderbook_delta", "seq": 915, "price": 62, "quantity": 100, "ts": 1756428172.760788, "side": "buy"}
{"type": "orderbook_delta", "seq": 916, "price": 58, "quantity": -200, "ts": 1756428173.187507, "side": "buy"}
{"type": "orderbook_delta", "seq": 917, "price": 69, "quantity": -200, "ts": 1756428173.188128, "side": "sell"}
{"type": "orderbook_delta", "seq": 918, "price": 70, "quantity": 200, "ts": 1756428173.227367, "side": "sell"}
{"type": "orderbook_delta", "seq": 919, "price": 59, "quantity": 200, "ts": 1756428173.232194, "side": "buy"}
{"type": "orderbook_delta", "seq": 920, "price": 70, "quantity": -200, "ts": 1756428173.699786, "side": "sell"}
{"type": "orderbook_delta", "seq": 921, "price": 59, "quantity": -200, "ts": 1756428173.700034, "side": "buy"}
{"type": "orderbook_delta", "seq": 922, "price": 69, "quantity": 200, "ts": 1756428173.746645, "side": "sell"}
{"type": "orderbook_delta", "seq": 923, "price": 67, "quantity": -500, "ts": 1756428173.747207, "side": "sell"}
{"type": "orderbook_delta", "seq": 924, "price": 58, "quantity": 200, "ts": 1756428173.747455, "side": "buy"}
{"type": "orderbook_delta", "seq": 925, "price": 66, "quantity": 500, "ts": 1756428173.789975, "side": "sell"}
{"type": "orderbook_delta", "seq": 926, "price": 57, "quantity": -1250, "ts": 1756428174.017012, "side": "buy"}
{"type": "orderbook_delta", "seq": 927, "price": 71, "quantity": -1250, "ts": 1756428174.020816, "side": "sell"}
{"type": "orderbook_delta", "seq": 928, "price": 61, "quantity": -500, "ts": 1756428174.035812, "side": "buy"}
{"type": "orderbook_delta", "seq": 929, "price": 70, "quantity": 1250, "ts": 1756428174.077522, "side": "sell"}
{"type": "orderbook_delta", "seq": 930, "price": 60, "quantity": 500, "ts": 1756428174.080368, "side": "buy"}
{"type": "orderbook_delta", "seq": 931, "price": 62, "quantity": -100, "ts": 1756428174.091597, "side": "buy"}
{"type": "orderbook_delta", "seq": 932, "price": 61, "quantity": 100, "ts": 1756428174.091597, "side": "buy"}
{"type": "orderbook_delta", "seq": 933, "price": 78, "quantity": -250, "ts": 1756428174.116606, "side": "sell"}
{"type": "orderbook_delta", "seq": 934, "price": 52, "quantity": 250, "ts": 1756428174.117542, "side": "buy"}
{"type": "orderbook_delta", "seq": 935, "price": 56, "quantity": 1250, "ts": 1756428174.130351, "side": "buy"}
{"type": "orderbook_delta", "seq": 936, "price": 68, "quantity": 250, "ts": 1756428174.135404, "side": "sell"}
{"type": "orderbook_delta", "seq": 937, "price": 69, "quantity": -200, "ts": 1756428174.237941, "side": "sell"}
{"type": "orderbook_delta", "seq": 938, "price": 58, "quantity": -200, "ts": 1756428174.34864, "side": "buy"}
{"type": "orderbook_delta", "seq": 939, "price": 57, "quantity": 200, "ts": 1756428174.453627, "side": "buy"}
{"type": "orderbook_delta", "seq": 940, "price": 68, "quantity": 200, "ts": 1756428174.453955, "side": "sell"}
{"type": "orderbook_delta", "seq": 941, "price": 68, "quantity": -100, "ts": 1756428174.738485, "side": "sell"}
{"type": "orderbook_delta", "seq": 942, "price": 66, "quantity": 100, "ts": 1756428174.738485, "side": "sell"}
{"type": "orderbook_delta", "seq": 943, "price": 56, "quantity": -1250, "ts": 1756428174.814486, "side": "buy"}
{"type": "orderbook_delta", "seq": 944, "price": 66, "quantity": -500, "ts": 1756428174.816729, "side": "sell"}
{"type": "orderbook_delta", "seq": 945, "price": 65, "quantity": 500, "ts": 1756428174.908003, "side": "sell"}
{"type": "orderbook_delta", "seq": 946, "price": 55, "quantity": 1250, "ts": 1756428174.908331, "side": "buy"}
{"type": "orderbook_delta", "seq": 947, "price": 60, "quantity": -500, "ts": 1756428175.439809, "side": "buy"}
{"type": "orderbook_delta", "seq": 948, "price": 70, "quantity": -1250, "ts": 1756428175.442397, "side": "sell"}
{"type": "orderbook_delta", "seq": 949, "price": 59, "quantity": 500, "ts": 1756428175.506471, "side": "buy"}
{"type": "orderbook_delta", "seq": 950, "price": 69, "quantity": 1250, "ts": 1756428175.509419, "side": "sell"}
{"type": "orderbook_delta", "seq": 951, "price": 69, "quantity": -200, "ts": 1756428175.576826, "side": "sell"}
{"type": "orderbook_delta", "seq": 952, "price": 68, "quantity": 200, "ts": 1756428175.576826, "side": "sell"}
{"type": "orderbook_delta", "seq": 953, "price": 60, "quantity": -250, "ts": 1756428176.118863, "side": "buy"}
{"type": "orderbook_delta", "seq": 954, "price": 50, "quantity": 250, "ts": 1756428176.119563, "side": "buy"}
{"type": "orderbook_delta", "seq": 955, "price": 68, "quantity": -200, "ts": 1756428176.411436, "side": "sell"}
{"type": "orderbook_delta", "seq": 956, "price": 57, "quantity": -200, "ts": 1756428176.412072, "side": "buy"}
{"type": "orderbook_delta", "seq": 957, "price": 55, "quantity": -1250, "ts": 1756428176.414148, "side": "buy"}
{"type": "orderbook_delta", "seq": 958, "price": 63, "quantity": -100, "ts": 1756428176.416652, "side": "buy"}
{"type": "orderbook_delta", "seq": 959, "price": 67, "quantity": 200, "ts": 1756428176.452517, "side": "sell"}
{"type": "orderbook_delta", "seq": 960, "price": 56, "quantity": 200, "ts": 1756428176.454356, "side": "buy"}
{"type": "orderbook_delta", "seq": 961, "price": 54, "quantity": 1250, "ts": 1756428176.454655, "side": "buy"}
{"type": "orderbook_delta", "seq": 962, "price": 64, "quantity": 1, "ts": 1756428176.636032, "side": "buy"}
{"type": "orderbook_delta", "seq": 963, "price": 31, "quantity": -8000, "ts": 1756428176.889238, "side": "buy"}
{"type": "orderbook_delta", "seq": 964, "price": 69, "quantity": -1250, "ts": 1756428176.890058, "side": "sell"}
{"type": "orderbook_delta", "seq": 965, "price": 67, "quantity": -200, "ts": 1756428176.890108, "side": "sell"}
{"type": "orderbook_delta", "seq": 966, "price": 56, "quantity": -200, "ts": 1756428176.890156, "side": "buy"}
{"type": "orderbook_delta", "seq": 967, "price": 59, "quantity": -500, "ts": 1756428176.891567, "side": "buy"}
{"type": "orderbook_delta", "seq": 968, "price": 54, "quantity": -1250, "ts": 1756428176.941675, "side": "buy"}
{"type": "orderbook_delta", "seq": 969, "price": 48, "quantity": 250, "ts": 1756428176.959302, "side": "buy"}
{"type": "orderbook_delta", "seq": 970, "price": 58, "quantity": -250, "ts": 1756428176.978808, "side": "buy"}
{"type": "orderbook_delta", "seq": 971, "price": 66, "quantity": 200, "ts": 1756428176.987073, "side": "sell"}
{"type": "orderbook_delta", "seq": 972, "price": 53, "quantity": 1250, "ts": 1756428176.987415, "side": "buy"}
{"type": "orderbook_delta", "seq": 973, "price": 58, "quantity": 500, "ts": 1756428176.987656, "side": "buy"}
{"type": "orderbook_delta", "seq": 974, "price": 68, "quantity": 1250, "ts": 1756428176.988926, "side": "sell"}
{"type": "orderbook_delta", "seq": 975, "price": 30, "quantity": 8000, "ts": 1756428176.989469, "side": "buy"}
{"type": "orderbook_delta", "seq": 976, "price": 55, "quantity": 200, "ts": 1756428176.995012, "side": "buy"}
{"type": "orderbook_delta", "seq": 977, "price": 58, "quantity": -500, "ts": 1756428177.039926, "side": "buy"}
{"type": "orderbook_delta", "seq": 978, "price": 57, "quantity": 500, "ts": 1756428177.080138, "side": "buy"}
{"type": "orderbook_delta", "seq": 979, "price": 66, "quantity": 250, "ts": 1756428177.10211, "side": "sell"}
{"type": "orderbook_delta", "seq": 980, "price": 76, "quantity": -250, "ts": 1756428177.119094, "side": "sell"}
{"type": "orderbook_delta", "seq": 981, "price": 61, "quantity": -100, "ts": 1756428177.119354, "side": "buy"}
{"type": "orderbook_delta", "seq": 982, "price": 57, "quantity": 100, "ts": 1756428177.119354, "side": "buy"}
{"type": "orderbook_delta", "seq": 983, "price": 57, "quantity": -500, "ts": 1756428177.172002, "side": "buy"}
{"type": "orderbook_delta", "seq": 984, "price": 58, "quantity": 500, "ts": 1756428177.237529, "side": "buy"}
{"type": "orderbook_delta", "seq": 985, "price": 57, "quantity": -100, "ts": 1756428177.880508, "side": "buy"}
{"type": "orderbook_delta", "seq": 986, "price": 59, "quantity": 100, "ts": 1756428177.880508, "side": "buy"}
{"type": "orderbook_delta", "seq": 987, "price": 58, "quantity": -500, "ts": 1756428177.907254, "side": "buy"}
{"type": "orderbook_delta", "seq": 988, "price": 57, "quantity": 500, "ts": 1756428177.945993, "side": "buy"}
{"type": "orderbook_delta", "seq": 989, "price": 48, "quantity": -250, "ts": 1756428178.131194, "side": "buy"}
{"type": "orderbook_delta", "seq": 990, "price": 58, "quantity": 250, "ts": 1756428178.135044, "side": "buy"}
{"type": "orderbook_delta", "seq": 991, "price": 57, "quantity": -500, "ts": 1756428178.171109, "side": "buy"}
{"type": "orderbook_delta", "seq": 992, "price": 58, "quantity": 500, "ts": 1756428178.217847, "side": "buy"}
{"type": "orderbook_delta", "seq": 993, "price": 66, "quantity": -100, "ts": 1756428178.458073, "side": "sell"}
{"type": "orderbook_delta", "seq": 994, "price": 65, "quantity": 100, "ts": 1756428178.458073, "side": "sell"}
{"type": "orderbook_delta", "seq": 995, "price": 65, "quantity": -500, "ts": 1756428178.4945, "side": "sell"}
{"type": "trade", "seq": 16, "price": 64, "quantity": 1, "ts": 1756428178.537405, "side": "sell"}
{"type": "orderbook_delta", "seq": 996, "price": 64, "quantity": 0, "ts": 1756428178.537405, "side": "buy"}
{"type": "orderbook_delta", "seq": 997, "price": 64, "quantity": 499, "ts": 1756428178.537405, "side": "sell"}
{"type": "orderbook_delta", "seq": 998, "price": 65, "quantity": -100, "ts": 1756428178.711712, "side": "sell"}
{"type": "orderbook_delta", "seq": 999, "price": 64, "quantity": 100, "ts": 1756428178.711712, "side": "sell"}
{"type": "orderbook_delta", "seq": 1000, "price": 64, "quantity": -499, "ts": 1756428178.74094, "side": "sell"}
{"type": "orderbook_delta", "seq": 1001, "price": 63, "quantity": 500, "ts": 1756428178.786539, "side": "sell"}
{"type": "orderbook_delta", "seq": 1002, "price": 64, "quantity": -100, "ts": 1756428178.796602, "side": "sell"}
{"type": "orderbook_delta", "seq": 1003, "price": 65, "quantity": 100, "ts": 1756428178.796602, "side": "sell"}
{"type": "orderbook_delta", "seq": 1004, "price": 63, "quantity": -500, "ts": 1756428178.831115, "side": "sell"}
{"type": "orderbook_delta", "seq": 1005, "price": 64, "quantity": 500, "ts": 1756428178.866939, "side": "sell"}
{"type": "orderbook_delta", "seq": 1006, "price": 30, "quantity": -8000, "ts": 1756428179.119465, "side": "buy"}
{"type": "orderbook_delta", "seq": 1007, "price": 53, "quantity": -1250, "ts": 1756428179.119922, "side": "buy"}
{"type": "orderbook_delta", "seq": 1008, "price": 55, "quantity": -200, "ts": 1756428179.121024, "side": "buy"}
{"type": "orderbook_delta", "seq": 1009, "price": 66, "quantity": -200, "ts": 1756428179.123042, "side": "sell"}
{"type": "orderbook_delta", "seq": 1010, "price": 54, "quantity": 1250, "ts": 1756428179.157265, "side": "buy"}
{"type": "orderbook_delta", "seq": 1011, "price": 31, "quantity": 8000, "ts": 1756428179.158685, "side": "buy"}
{"type": "orderbook_delta", "seq": 1012, "price": 56, "quantity": 200, "ts": 1756428179.158974, "side": "buy"}
{"type": "orderbook_delta", "seq": 1013, "price": 67, "quantity": 200, "ts": 1756428179.1596, "side": "sell"}
{"type": "orderbook_delta", "seq": 1014, "price": 65, "quantity": -100, "ts": 1756428180.227192, "side": "sell"}
{"type": "orderbook_delta", "seq": 1015, "price": 64, "quantity": -500, "ts": 1756428180.268608, "side": "sell"}
{"type": "orderbook_delta", "seq": 1016, "price": 65, "quantity": 500, "ts": 1756428180.312018, "side": "sell"}
{"type": "orderbook_delta", "seq": 1017, "price": 54, "quantity": -1250, "ts": 1756428180.486102, "side": "buy"}
{"type": "orderbook_delta", "seq": 1018, "price": 31, "quantity": -8000, "ts": 1756428180.487007, "side": "buy"}
{"type": "orderbook_delta", "seq": 1019, "price": 68, "quantity": -1250, "ts": 1756428180.487193, "side": "sell"}
{"type": "orderbook_delta", "seq": 1020, "price": 56, "quantity": -200, "ts": 1756428180.489026, "side": "buy"}
{"type": "orderbook_delta", "seq": 1021, "price": 58, "quantity": -500, "ts": 1756428180.491734, "side": "buy"}
{"type": "orderbook_delta", "seq": 1022, "price": 67, "quantity": -200, "ts": 1756428180.491893, "side": "sell"}
{"type": "orderbook_delta", "seq": 1023, "price": 68, "quantity": -200, "ts": 1756428180.510571, "side": "sell"}
{"type": "orderbook_delta", "seq": 1024, "price": 66, "quantity": 200, "ts": 1756428180.510571, "side": "sell"}
{"type": "orderbook_delta", "seq": 1025, "price": 67, "quantity": 1250, "ts": 1756428180.534991, "side": "sell"}
{"type": "orderbook_delta", "seq": 1026, "price": 57, "quantity": 500, "ts": 1756428180.535286, "side": "buy"}
{"type": "orderbook_delta", "seq": 1027, "price": 65, "quantity": 200, "ts": 1756428180.535892, "side": "sell"}
{"type": "orderbook_delta", "seq": 1028, "price": 54, "quantity": 200, "ts": 1756428180.536937, "side": "buy"}
{"type": "orderbook_delta", "seq": 1029, "price": 30, "quantity": 8000, "ts": 1756428180.537688, "side": "buy"}
{"type": "orderbook_delta", "seq": 1030, "price": 53, "quantity": 1250, "ts": 1756428180.554371, "side": "buy"}
{"type": "orderbook_delta", "seq": 1031, "price": 66, "quantity": -200, "ts": 1756428180.560333, "side": "sell"}
{"type": "orderbook_delta", "seq": 1032, "price": 65, "quantity": 200, "ts": 1756428180.560333, "side": "sell"}
{"type": "orderbook_delta", "seq": 1033, "price": 65, "quantity": -500, "ts": 1756428180.591692, "side": "sell"}
{"type": "orderbook_delta", "seq": 1034, "price": 64, "quantity": 500, "ts": 1756428180.631204, "side": "sell"}
{"type": "orderbook_delta", "seq": 1035, "price": 48, "quantity": 250, "ts": 1756428180.913025, "side": "buy"}
{"type": "orderbook_delta", "seq": 1036, "price": 58, "quantity": -250, "ts": 1756428180.914627, "side": "buy"}
{"type": "orderbook_delta", "seq": 1037, "price": 54, "quantity": -200, "ts": 1756428180.928961, "side": "buy"}
{"type": "orderbook_delta", "seq": 1038, "price": 57, "quantity": -500, "ts": 1756428180.929707, "side": "buy"}
{"type": "orderbook_delta", "seq": 1039, "price": 30, "quantity": -8000, "ts": 1756428180.929775, "side": "buy"}
{"type": "orderbook_delta", "seq": 1040, "price": 67, "quantity": -1250, "ts": 1756428180.930138, "side": "sell"}
{"type": "orderbook_delta", "seq": 1041, "price": 65, "quantity": -200, "ts": 1756428180.935264, "side": "sell"}
{"type": "orderbook_delta", "seq": 1042, "price": 59, "quantity": -100, "ts": 1756428180.96119, "side": "buy"}
{"type": "orderbook_delta", "seq": 1043, "price": 58, "quantity": 100, "ts": 1756428180.96119, "side": "buy"}
{"type": "orderbook_delta", "seq": 1044, "price": 53, "quantity": -1250, "ts": 1756428180.987027, "side": "buy"}
{"type": "orderbook_delta", "seq": 1045, "price": 46, "quantity": 250, "ts": 1756428181.008887, "side": "buy"}
{"type": "orderbook_delta", "seq": 1046, "price": 56, "quantity": -250, "ts": 1756428181.01097, "side": "buy"}
{"type": "orderbook_delta", "seq": 1047, "price": 64, "quantity": 200, "ts": 1756428181.027406, "side": "sell"}
{"type": "orderbook_delta", "seq": 1048, "price": 8, "quantity": 8000, "ts": 1756428181.029989, "side": "buy"}
{"type": "orderbook_delta", "seq": 1049, "price": 52, "quantity": 1250, "ts": 1756428181.031427, "side": "buy"}
{"type": "orderbook_delta", "seq": 1050, "price": 66, "quantity": 1250, "ts": 1756428181.032825, "side": "sell"}
{"type": "orderbook_delta", "seq": 1051, "price": 56, "quantity": 500, "ts": 1756428181.035606, "side": "buy"}
{"type": "orderbook_delta", "seq": 1052, "price": 53, "quantity": 200, "ts": 1756428181.038221, "side": "buy"}
{"type": "orderbook_delta", "seq": 1053, "price": 56, "quantity": -500, "ts": 1756428181.075303, "side": "buy"}
{"type": "orderbook_delta", "seq": 1054, "price": 55, "quantity": 500, "ts": 1756428181.127081, "side": "buy"}
{"type": "orderbook_delta", "seq": 1055, "price": 74, "quantity": -250, "ts": 1756428181.146884, "side": "sell"}
{"type": "orderbook_delta", "seq": 1056, "price": 64, "quantity": 250, "ts": 1756428181.149074, "side": "sell"}
{"type": "orderbook_delta", "seq": 1057, "price": 64, "quantity": -500, "ts": 1756428181.181374, "side": "sell"}
{"type": "orderbook_delta", "seq": 1058, "price": 63, "quantity": 500, "ts": 1756428181.221797, "side": "sell"}
{"type": "orderbook_delta", "seq": 1059, "price": 64, "quantity": -200, "ts": 1756428181.256622, "side": "sell"}
{"type": "orderbook_delta", "seq": 1060, "price": 66, "quantity": -1250, "ts": 1756428181.256784, "side": "sell"}
{"type": "orderbook_delta", "seq": 1061, "price": 52, "quantity": -1250, "ts": 1756428181.256836, "side": "buy"}
{"type": "orderbook_delta", "seq": 1062, "price": 53, "quantity": -200, "ts": 1756428181.258046, "side": "buy"}
{"type": "orderbook_delta", "seq": 1063, "price": 52, "quantity": 200, "ts": 1756428181.295746, "side": "buy"}
{"type": "orderbook_delta", "seq": 1064, "price": 65, "quantity": 1250, "ts": 1756428181.296998, "side": "sell"}
{"type": "orderbook_delta", "seq": 1065, "price": 63, "quantity": 200, "ts": 1756428181.297265, "side": "sell"}
{"type": "orderbook_delta", "seq": 1066, "price": 50, "quantity": 1250, "ts": 1756428181.29812, "side": "buy"}
{"type": "orderbook_delta", "seq": 1067, "price": 55, "quantity": -500, "ts": 1756428181.356292, "side": "buy"}
{"type": "orderbook_delta", "seq": 1068, "price": 46, "quantity": -250, "ts": 1756428181.374147, "side": "buy"}
{"type": "orderbook_delta", "seq": 1069, "price": 56, "quantity": 250, "ts": 1756428181.374673, "side": "buy"}
{"type": "orderbook_delta", "seq": 1070, "price": 65, "quantity": -1250, "ts": 1756428181.390454, "side": "sell"}
{"type": "orderbook_delta", "seq": 1071, "price": 54, "quantity": 500, "ts": 1756428181.4054, "side": "buy"}
{"type": "orderbook_delta", "seq": 1072, "price": 64, "quantity": 1250, "ts": 1756428181.431028, "side": "sell"}
{"type": "orderbook_delta", "seq": 1073, "price": 90, "quantity": 200, "ts": 1756428181.450395, "side": "sell"}
{"type": "orderbook_delta", "seq": 1074, "price": 52, "quantity": -200, "ts": 1756428181.465056, "side": "buy"}
{"type": "orderbook_delta", "seq": 1075, "price": 50, "quantity": -1250, "ts": 1756428181.467395, "side": "buy"}
{"type": "orderbook_delta", "seq": 1076, "price": 98, "quantity": -8000, "ts": 1756428181.489853, "side": "sell"}
{"type": "orderbook_delta", "seq": 1077, "price": 49, "quantity": 1250, "ts": 1756428181.531301, "side": "buy"}
{"type": "orderbook_delta", "seq": 1078, "price": 51, "quantity": 200, "ts": 1756428181.532795, "side": "buy"}
{"type": "orderbook_delta", "seq": 1079, "price": 89, "quantity": 8000, "ts": 1756428181.535033, "side": "sell"}
{"type": "orderbook_delta", "seq": 1080, "price": 67, "quantity": 100, "ts": 1756428181.731801, "side": "sell"}
{"type": "orderbook_delta", "seq": 1081, "price": 65, "quantity": -200, "ts": 1756428181.91891, "side": "sell"}
{"type": "orderbook_delta", "seq": 1082, "price": 63, "quantity": 200, "ts": 1756428181.91891, "side": "sell"}
{"type": "orderbook_delta", "seq": 1083, "price": 63, "quantity": -500, "ts": 1756428181.967015, "side": "sell"}
{"type": "orderbook_delta", "seq": 1084, "price": 63, "quantity": -200, "ts": 1756428182.022116, "side": "sell"}
{"type": "orderbook_delta", "seq": 1085, "price": 62, "quantity": 200, "ts": 1756428182.083018, "side": "sell"}
{"type": "orderbook_delta", "seq": 1086, "price": 62, "quantity": 500, "ts": 1756428182.084845, "side": "sell"}
{"type": "orderbook_delta", "seq": 1087, "price": 46, "quantity": 250, "ts": 1756428182.139818, "side": "buy"}
{"type": "orderbook_delta", "seq": 1088, "price": 56, "quantity": -250, "ts": 1756428182.142656, "side": "buy"}
{"type": "orderbook_delta", "seq": 1089, "price": 54, "quantity": -500, "ts": 1756428182.596663, "side": "buy"}
{"type": "orderbook_delta", "seq": 1090, "price": 67, "quantity": -100, "ts": 1756428182.605099, "side": "sell"}
{"type": "orderbook_delta", "seq": 1091, "price": 63, "quantity": 100, "ts": 1756428182.605099, "side": "sell"}
{"type": "orderbook_delta", "seq": 1092, "price": 51, "quantity": -200, "ts": 1756428182.64393, "side": "buy"}
{"type": "orderbook_delta", "seq": 1093, "price": 64, "quantity": -1250, "ts": 1756428182.644194, "side": "sell"}
{"type": "orderbook_delta", "seq": 1094, "price": 49, "quantity": -1250, "ts": 1756428182.644314, "side": "buy"}
{"type": "orderbook_delta", "seq": 1095, "price": 52, "quantity": 500, "ts": 1756428182.705802, "side": "buy"}
{"type": "orderbook_delta", "seq": 1096, "price": 48, "quantity": 1250, "ts": 1756428182.715419, "side": "buy"}
{"type": "orderbook_delta", "seq": 1097, "price": 63, "quantity": 1250, "ts": 1756428182.716893, "side": "sell"}
{"type": "orderbook_delta", "seq": 1098, "price": 63, "quantity": -200, "ts": 1756428182.744697, "side": "sell"}
{"type": "orderbook_delta", "seq": 1099, "price": 62, "quantity": 200, "ts": 1756428182.744697, "side": "sell"}
{"type": "orderbook_delta", "seq": 1100, "price": 50, "quantity": 200, "ts": 1756428182.78043, "side": "buy"}
{"type": "orderbook_delta", "seq": 1101, "price": 62, "quantity": -200, "ts": 1756428182.814518, "side": "sell"}
{"type": "orderbook_delta", "seq": 1102, "price": 62, "quantity": -500, "ts": 1756428182.825833, "side": "sell"}
{"type": "orderbook_delta", "seq": 1103, "price": 58, "quantity": -100, "ts": 1756428182.907376, "side": "buy"}
{"type": "orderbook_delta", "seq": 1104, "price": 55, "quantity": 100, "ts": 1756428182.907376, "side": "buy"}
{"type": "orderbook_delta", "seq": 1105, "price": 61, "quantity": 200, "ts": 1756428182.908265, "side": "sell"}
{"type": "orderbook_delta", "seq": 1106, "price": 50, "quantity": -200, "ts": 1756428182.965673, "side": "buy"}
{"type": "orderbook_delta", "seq": 1107, "price": 61, "quantity": 500, "ts": 1756428182.967942, "side": "sell"}
{"type": "orderbook_delta", "seq": 1108, "price": 63, "quantity": -1250, "ts": 1756428182.970391, "side": "sell"}
{"type": "orderbook_delta", "seq": 1109, "price": 62, "quantity": 1250, "ts": 1756428183.014511, "side": "sell"}
{"type": "orderbook_delta", "seq": 1110, "price": 49, "quantity": 200, "ts": 1756428183.018237, "side": "buy"}
{"type": "orderbook_delta", "seq": 1111, "price": 63, "quantity": -100, "ts": 1756428183.068035, "side": "sell"}
{"type": "orderbook_delta", "seq": 1112, "price": 64, "quantity": 100, "ts": 1756428183.068035, "side": "sell"}
{"type": "orderbook_delta", "seq": 1113, "price": 62, "quantity": 250, "ts": 1756428183.144234, "side": "sell"}
{"type": "orderbook_delta", "seq": 1114, "price": 72, "quantity": -250, "ts": 1756428183.25794, "side": "sell"}
{"type": "orderbook_delta", "seq": 1115, "price": 61, "quantity": -200, "ts": 1756428183.39151, "side": "sell"}
{"type": "orderbook_delta", "seq": 1116, "price": 48, "quantity": -1250, "ts": 1756428183.395548, "side": "buy"}
{"type": "orderbook_delta", "seq": 1117, "price": 62, "quantity": -1250, "ts": 1756428183.395823, "side": "sell"}
{"type": "orderbook_delta", "seq": 1118, "price": 52, "quantity": -500, "ts": 1756428183.398644, "side": "buy"}
{"type": "orderbook_delta", "seq": 1119, "price": 49, "quantity": -200, "ts": 1756428183.419766, "side": "buy"}
{"type": "orderbook_delta", "seq": 1120, "price": 49, "quantity": 1250, "ts": 1756428183.52651, "side": "buy"}
{"type": "orderbook_delta", "seq": 1121, "price": 53, "quantity": 500, "ts": 1756428183.527506, "side": "buy"}
{"type": "orderbook_delta", "seq": 1122, "price": 51, "quantity": 200, "ts": 1756428183.52826, "side": "buy"}
{"type": "orderbook_delta", "seq": 1123, "price": 62, "quantity": 200, "ts": 1756428183.528545, "side": "sell"}
{"type": "orderbook_delta", "seq": 1124, "price": 63, "quantity": 1250, "ts": 1756428183.54628, "side": "sell"}
{"type": "orderbook_delta", "seq": 1125, "price": 54, "quantity": -250, "ts": 1756428185.12575, "side": "buy"}
{"type": "orderbook_delta", "seq": 1126, "price": 44, "quantity": 250, "ts": 1756428185.129505, "side": "buy"}
{"type": "orderbook_delta", "seq": 1127, "price": 55, "quantity": -100, "ts": 1756428185.174597, "side": "buy"}
{"type": "orderbook_delta", "seq": 1128, "price": 54, "quantity": 100, "ts": 1756428185.174597, "side": "buy"}
{"type": "orderbook_delta", "seq": 1129, "price": 7, "quantity": -2777, "ts": 1756428185.3949, "side": "buy"}
{"type": "orderbook_delta", "seq": 1130, "price": 9, "quantity": 2160, "ts": 1756428185.3949, "side": "buy"}
{"type": "orderbook_delta", "seq": 1131, "price": 8, "quantity": -8000, "ts": 1756428185.491437, "side": "buy"}
{"type": "orderbook_delta", "seq": 1132, "price": 62, "quantity": -200, "ts": 1756428185.491806, "side": "sell"}
{"type": "orderbook_delta", "seq": 1133, "price": 49, "quantity": -1250, "ts": 1756428185.492099, "side": "buy"}
{"type": "orderbook_delta", "seq": 1134, "price": 10, "quantity": 8000, "ts": 1756428185.528117, "side": "buy"}
{"type": "orderbook_delta", "seq": 1135, "price": 51, "quantity": -200, "ts": 1756428185.532516, "side": "buy"}
{"type": "orderbook_delta", "seq": 1136, "price": 64, "quantity": -100, "ts": 1756428185.553814, "side": "sell"}
{"type": "orderbook_delta", "seq": 1137, "price": 62, "quantity": 100, "ts": 1756428185.553814, "side": "sell"}
{"type": "orderbook_delta", "seq": 1138, "price": 48, "quantity": 1250, "ts": 1756428185.57037, "side": "buy"}
{"type": "orderbook_delta", "seq": 1139, "price": 61, "quantity": 200, "ts": 1756428185.575874, "side": "sell"}
{"type": "orderbook_delta", "seq": 1140, "price": 50, "quantity": 200, "ts": 1756428185.591396, "side": "buy"}
{"type": "orderbook_delta", "seq": 1141, "price": 62, "quantity": -100, "ts": 1756428185.960357, "side": "sell"}
{"type": "orderbook_delta", "seq": 1142, "price": 63, "quantity": 100, "ts": 1756428185.960357, "side": "sell"}
{"type": "orderbook_delta", "seq": 1143, "price": 63, "quantity": -100, "ts": 1756428186.02277, "side": "sell"}
{"type": "orderbook_delta", "seq": 1144, "price": 64, "quantity": 100, "ts": 1756428186.02277, "side": "sell"}
{"type": "orderbook_delta", "seq": 1145, "price": 9, "quantity": -2160, "ts": 1756428187.017105, "side": "buy"}
{"type": "orderbook_delta", "seq": 1146, "price": 10, "quantity": -8000, "ts": 1756428187.055367, "side": "buy"}
{"type": "orderbook_delta", "seq": 1147, "price": 70, "quantity": -250, "ts": 1756428187.116916, "side": "sell"}
{"type": "orderbook_delta", "seq": 1148, "price": 60, "quantity": 250, "ts": 1756428187.119953, "side": "sell"}
{"type": "orderbook_delta", "seq": 1149, "price": 63, "quantity": -1250, "ts": 1756428187.128822, "side": "sell"}
{"type": "orderbook_delta", "seq": 1150, "price": 53, "quantity": -500, "ts": 1756428187.135401, "side": "buy"}
{"type": "orderbook_delta", "seq": 1151, "price": 48, "quantity": -1250, "ts": 1756428187.150575, "side": "buy"}
{"type": "orderbook_delta", "seq": 1152, "price": 61, "quantity": -200, "ts": 1756428187.150788, "side": "sell"}
{"type": "orderbook_delta", "seq": 1153, "price": 50, "quantity": -200, "ts": 1756428187.150928, "side": "buy"}
{"type": "orderbook_delta", "seq": 1154, "price": 61, "quantity": -500, "ts": 1756428187.154637, "side": "sell"}
{"type": "orderbook_delta", "seq": 1155, "price": 61, "quantity": 1250, "ts": 1756428187.169805, "side": "sell"}
{"type": "orderbook_delta", "seq": 1156, "price": 51, "quantity": 500, "ts": 1756428187.171064, "side": "buy"}
{"type": "orderbook_delta", "seq": 1157, "price": 59, "quantity": 200, "ts": 1756428187.190251, "side": "sell"}
{"type": "orderbook_delta", "seq": 1158, "price": 48, "quantity": 200, "ts": 1756428187.190718, "side": "buy"}
{"type": "orderbook_delta", "seq": 1159, "price": 46, "quantity": 1250, "ts": 1756428187.191898, "side": "buy"}
{"type": "orderbook_delta", "seq": 1160, "price": 59, "quantity": 500, "ts": 1756428187.201947, "side": "sell"}
{"type": "orderbook_delta", "seq": 1161, "price": 51, "quantity": -500, "ts": 1756428187.214845, "side": "buy"}
{"type": "orderbook_delta", "seq": 1162, "price": 40, "quantity": 250, "ts": 1756428187.237419, "side": "buy"}
{"type": "orderbook_delta", "seq": 1163, "price": 50, "quantity": -250, "ts": 1756428187.238097, "side": "buy"}
{"type": "orderbook_delta", "seq": 1164, "price": 61, "quantity": -1250, "ts": 1756428187.240071, "side": "sell"}
{"type": "orderbook_delta", "seq": 1165, "price": 48, "quantity": -200, "ts": 1756428187.241437, "side": "buy"}
{"type": "orderbook_delta", "seq": 1166, "price": 46, "quantity": -1250, "ts": 1756428187.252547, "side": "buy"}
{"type": "orderbook_delta", "seq": 1167, "price": 50, "quantity": 500, "ts": 1756428187.256274, "side": "buy"}
{"type": "orderbook_delta", "seq": 1168, "price": 60, "quantity": 1250, "ts": 1756428187.276676, "side": "sell"}
{"type": "orderbook_delta", "seq": 1169, "price": 47, "quantity": 200, "ts": 1756428187.277297, "side": "buy"}
{"type": "orderbook_delta", "seq": 1170, "price": 45, "quantity": 1250, "ts": 1756428187.283849, "side": "buy"}
{"type": "orderbook_delta", "seq": 1171, "price": 42, "quantity": 250, "ts": 1756428187.287238, "side": "buy"}
{"type": "orderbook_delta", "seq": 1172, "price": 52, "quantity": -250, "ts": 1756428187.287455, "side": "buy"}
{"type": "orderbook_delta", "seq": 1173, "price": 62, "quantity": -200, "ts": 1756428187.297952, "side": "sell"}
{"type": "orderbook_delta", "seq": 1174, "price": 59, "quantity": 200, "ts": 1756428187.297952, "side": "sell"}
{"type": "orderbook_delta", "seq": 1175, "price": 54, "quantity": -100, "ts": 1756428187.299529, "side": "buy"}
{"type": "orderbook_delta", "seq": 1176, "price": 52, "quantity": 100, "ts": 1756428187.299529, "side": "buy"}
{"type": "orderbook_delta", "seq": 1177, "price": 50, "quantity": -500, "ts": 1756428187.306759, "side": "buy"}
{"type": "orderbook_delta", "seq": 1178, "price": 40, "quantity": -250, "ts": 1756428187.329121, "side": "buy"}
{"type": "orderbook_delta", "seq": 1179, "price": 64, "quantity": -100, "ts": 1756428187.340171, "side": "sell"}
{"type": "orderbook_delta", "seq": 1180, "price": 65, "quantity": 100, "ts": 1756428187.340171, "side": "sell"}
{"type": "orderbook_delta", "seq": 1181, "price": 49, "quantity": 500, "ts": 1756428187.347621, "side": "buy"}
{"type": "orderbook_delta", "seq": 1182, "price": 59, "quantity": -500, "ts": 1756428187.389129, "side": "sell"}
{"type": "orderbook_delta", "seq": 1183, "price": 59, "quantity": -200, "ts": 1756428187.393038, "side": "sell"}
{"type": "orderbook_delta", "seq": 1184, "price": 58, "quantity": 200, "ts": 1756428187.48156, "side": "sell"}
{"type": "orderbook_delta", "seq": 1185, "price": 58, "quantity": 500, "ts": 1756428187.484348, "side": "sell"}
{"type": "orderbook_delta", "seq": 1186, "price": 59, "quantity": -200, "ts": 1756428187.519056, "side": "sell"}
{"type": "orderbook_delta", "seq": 1187, "price": 58, "quantity": 200, "ts": 1756428187.519056, "side": "sell"}
{"type": "orderbook_delta", "seq": 1188, "price": 58, "quantity": -500, "ts": 1756428187.60554, "side": "sell"}
{"type": "orderbook_delta", "seq": 1189, "price": 57, "quantity": 500, "ts": 1756428187.680471, "side": "sell"}
{"type": "orderbook_delta", "seq": 1190, "price": 58, "quantity": 250, "ts": 1756428188.133343, "side": "sell"}
{"type": "orderbook_delta", "seq": 1191, "price": 68, "quantity": -250, "ts": 1756428188.147536, "side": "sell"}
{"type": "orderbook_delta", "seq": 1192, "price": 52, "quantity": -100, "ts": 1756428188.18424, "side": "buy"}
{"type": "orderbook_delta", "seq": 1193, "price": 50, "quantity": 100, "ts": 1756428188.18424, "side": "buy"}
{"type": "orderbook_delta", "seq": 1194, "price": 40, "quantity": 250, "ts": 1756428188.22863, "side": "buy"}
{"type": "orderbook_delta", "seq": 1195, "price": 47, "quantity": -200, "ts": 1756428188.237961, "side": "buy"}
{"type": "orderbook_delta", "seq": 1196, "price": 60, "quantity": -1250, "ts": 1756428188.239154, "side": "sell"}
{"type": "orderbook_delta", "seq": 1197, "price": 45, "quantity": -1250, "ts": 1756428188.239633, "side": "buy"}
{"type": "orderbook_delta", "seq": 1198, "price": 58, "quantity": -200, "ts": 1756428188.240866, "side": "sell"}
{"type": "orderbook_delta", "seq": 1199, "price": 30, "quantity": -200, "ts": 1756428188.246786, "side": "buy"}
{"type": "orderbook_delta", "seq": 1200, "price": 20, "quantity": 200, "ts": 1756428188.246786, "side": "buy"}
{"type": "orderbook_delta", "seq": 1201, "price": 49, "quantity": -500, "ts": 1756428188.24891, "side": "buy"}
{"type": "orderbook_delta", "seq": 1202, "price": 90, "quantity": -200, "ts": 1756428188.281205, "side": "sell"}
{"type": "orderbook_delta", "seq": 1203, "price": 80, "quantity": 200, "ts": 1756428188.281205, "side": "sell"}
{"type": "orderbook_delta", "seq": 1204, "price": 20, "quantity": 8000, "ts": 1756428188.281951, "side": "buy"}
{"type": "orderbook_delta", "seq": 1205, "price": 89, "quantity": -8000, "ts": 1756428188.318403, "side": "sell"}
{"type": "orderbook_delta", "seq": 1206, "price": 59, "quantity": 1250, "ts": 1756428188.319244, "side": "sell"}
{"type": "orderbook_delta", "seq": 1207, "price": 48, "quantity": 500, "ts": 1756428188.327168, "side": "buy"}
{"type": "orderbook_delta", "seq": 1208, "price": 46, "quantity": 200, "ts": 1756428188.331558, "side": "buy"}
{"type": "orderbook_delta", "seq": 1209, "price": 57, "quantity": 200, "ts": 1756428188.338046, "side": "sell"}
{"type": "orderbook_delta", "seq": 1210, "price": 44, "quantity": 1250, "ts": 1756428188.358945, "side": "buy"}
{"type": "orderbook_delta", "seq": 1211, "price": 98, "quantity": 8000, "ts": 1756428188.373283, "side": "sell"}
{"type": "orderbook_delta", "seq": 1212, "price": 65, "quantity": -100, "ts": 1756428188.60502, "side": "sell"}
{"type": "orderbook_delta", "seq": 1213, "price": 59, "quantity": 100, "ts": 1756428188.60502, "side": "sell"}
{"type": "orderbook_delta", "seq": 1214, "price": 1, "quantity": 19440, "ts": 1756428188.610646, "side": "buy"}
{"type": "orderbook_delta", "seq": 1215, "price": 58, "quantity": -200, "ts": 1756428188.681286, "side": "sell"}
{"type": "orderbook_delta", "seq": 1216, "price": 57, "quantity": 200, "ts": 1756428188.681286, "side": "sell"}
{"type": "orderbook_delta", "seq": 1217, "price": 57, "quantity": -500, "ts": 1756428188.717527, "side": "sell"}
{"type": "orderbook_delta", "seq": 1218, "price": 20, "quantity": -8000, "ts": 1756428188.723179, "side": "buy"}
{"type": "orderbook_delta", "seq": 1219, "price": 57, "quantity": -200, "ts": 1756428188.723924, "side": "sell"}
{"type": "orderbook_delta", "seq": 1220, "price": 46, "quantity": -200, "ts": 1756428188.724021, "side": "buy"}
{"type": "orderbook_delta", "seq": 1221, "price": 48, "quantity": -500, "ts": 1756428188.72548, "side": "buy"}
{"type": "orderbook_delta", "seq": 1222, "price": 44, "quantity": -1250, "ts": 1756428188.727093, "side": "buy"}
{"type": "orderbook_delta", "seq": 1223, "price": 59, "quantity": -1250, "ts": 1756428188.729449, "side": "sell"}
{"type": "orderbook_delta", "seq": 1224, "price": 56, "quantity": 500, "ts": 1756428188.756508, "side": "sell"}
{"type": "orderbook_delta", "seq": 1225, "price": 2, "quantity": 8000, "ts": 1756428188.775411, "side": "buy"}
{"type": "orderbook_delta", "seq": 1226, "price": 58, "quantity": 1250, "ts": 1756428188.775693, "side": "sell"}
{"type": "orderbook_delta", "seq": 1227, "price": 45, "quantity": 200, "ts": 1756428188.776251, "side": "buy"}
{"type": "orderbook_delta", "seq": 1228, "price": 43, "quantity": 1250, "ts": 1756428188.777661, "side": "buy"}
{"type": "orderbook_delta", "seq": 1229, "price": 56, "quantity": 200, "ts": 1756428188.779901, "side": "sell"}
{"type": "orderbook_delta", "seq": 1230, "price": 47, "quantity": 500, "ts": 1756428188.793517, "side": "buy"}
{"type": "orderbook_delta", "seq": 1231, "price": 2, "quantity": 7000, "ts": 1756428188.808593, "side": "buy"}
{"type": "orderbook_delta", "seq": 1232, "price": 48, "quantity": -250, "ts": 1756428188.867768, "side": "buy"}
{"type": "orderbook_delta", "seq": 1233, "price": 38, "quantity": 250, "ts": 1756428188.876272, "side": "buy"}
{"type": "orderbook_delta", "seq": 1234, "price": 38, "quantity": -250, "ts": 1756428188.960259, "side": "buy"}
{"type": "orderbook_delta", "seq": 1235, "price": 48, "quantity": 250, "ts": 1756428188.962795, "side": "buy"}
{"type": "orderbook_delta", "seq": 1236, "price": 59, "quantity": -100, "ts": 1756428189.029307, "side": "sell"}
{"type": "orderbook_delta", "seq": 1237, "price": 60, "quantity": 100, "ts": 1756428189.029307, "side": "sell"}
{"type": "orderbook_delta", "seq": 1238, "price": 66, "quantity": -250, "ts": 1756428189.133462, "side": "sell"}
{"type": "orderbook_delta", "seq": 1239, "price": 56, "quantity": 250, "ts": 1756428189.136711, "side": "sell"}
{"type": "orderbook_delta", "seq": 1240, "price": 56, "quantity": -500, "ts": 1756428189.187576, "side": "sell"}
{"type": "orderbook_delta", "seq": 1241, "price": 55, "quantity": 500, "ts": 1756428189.236909, "side": "sell"}
{"type": "orderbook_delta", "seq": 1242, "price": 1, "quantity": -19440, "ts": 1756428189.479169, "side": "buy"}
{"type": "orderbook_delta", "seq": 1243, "price": 3, "quantity": 6480, "ts": 1756428189.479169, "side": "buy"}
{"type": "orderbook_delta", "seq": 1244, "price": 2, "quantity": -7000, "ts": 1756428189.514873, "side": "buy"}
{"type": "orderbook_delta", "seq": 1245, "price": 2, "quantity": -8000, "ts": 1756428189.515388, "side": "buy"}
{"type": "orderbook_delta", "seq": 1246, "price": 4, "quantity": 7000, "ts": 1756428189.547675, "side": "buy"}
{"type": "orderbook_delta", "seq": 1247, "price": 4, "quantity": 8000, "ts": 1756428189.55183, "side": "buy"}
{"type": "orderbook_delta", "seq": 1248, "price": 57, "quantity": -200, "ts": 1756428190.114347, "side": "sell"}
{"type": "orderbook_delta", "seq": 1249, "price": 56, "quantity": 200, "ts": 1756428190.114347, "side": "sell"}
{"type": "orderbook_delta", "seq": 1250, "price": 45, "quantity": -200, "ts": 1756428190.122956, "side": "buy"}
{"type": "orderbook_delta", "seq": 1251, "price": 56, "quantity": -200, "ts": 1756428190.12735, "side": "sell"}
{"type": "orderbook_delta", "seq": 1252, "price": 43, "quantity": -1250, "ts": 1756428190.127704, "side": "buy"}
{"type": "orderbook_delta", "seq": 1253, "price": 58, "quantity": -1250, "ts": 1756428190.133859, "side": "sell"}
{"type": "orderbook_delta", "seq": 1254, "price": 55, "quantity": 200, "ts": 1756428190.171808, "side": "sell"}
{"type": "orderbook_delta", "seq": 1255, "price": 57, "quantity": 1250, "ts": 1756428190.174215, "side": "sell"}
{"type": "orderbook_delta", "seq": 1256, "price": 42, "quantity": 1250, "ts": 1756428190.174534, "side": "buy"}
{"type": "orderbook_delta", "seq": 1257, "price": 44, "quantity": 200, "ts": 1756428190.175053, "side": "buy"}
{"type": "orderbook_delta", "seq": 1258, "price": 3, "quantity": -6480, "ts": 1756428190.356692, "side": "buy"}
{"type": "orderbook_delta", "seq": 1259, "price": 1, "quantity": 19440, "ts": 1756428190.356692, "side": "buy"}
{"type": "orderbook_delta", "seq": 1260, "price": 4, "quantity": -8000, "ts": 1756428190.397042, "side": "buy"}
{"type": "orderbook_delta", "seq": 1261, "price": 4, "quantity": -7000, "ts": 1756428190.399068, "side": "buy"}
{"type": "orderbook_delta", "seq": 1262, "price": 2, "quantity": 8000, "ts": 1756428190.446941, "side": "buy"}
{"type": "orderbook_delta", "seq": 1263, "price": 2, "quantity": 7000, "ts": 1756428190.447682, "side": "buy"}
{"type": "orderbook_delta", "seq": 1264, "price": 60, "quantity": -100, "ts": 1756428190.54106, "side": "sell"}
{"type": "orderbook_delta", "seq": 1265, "price": 58, "quantity": 100, "ts": 1756428190.54106, "side": "sell"}
{"type": "orderbook_delta", "seq": 1266, "price": 50, "quantity": -100, "ts": 1756428191.187479, "side": "buy"}
{"type": "orderbook_delta", "seq": 1267, "price": 49, "quantity": 100, "ts": 1756428191.187479, "side": "buy"}
{"type": "orderbook_delta", "seq": 1268, "price": 58, "quantity": -100, "ts": 1756428191.273658, "side": "sell"}
{"type": "orderbook_delta", "seq": 1269, "price": 59, "quantity": 100, "ts": 1756428191.273658, "side": "sell"}
{"type": "orderbook_delta", "seq": 1270, "price": 1, "quantity": -19440, "ts": 1756428191.42814, "side": "buy"}
{"type": "orderbook_delta", "seq": 1271, "price": 3, "quantity": 6480, "ts": 1756428191.42814, "side": "buy"}
{"type": "orderbook_delta", "seq": 1272, "price": 2, "quantity": -8000, "ts": 1756428191.460341, "side": "buy"}
{"type": "orderbook_delta", "seq": 1273, "price": 2, "quantity": -7000, "ts": 1756428191.524954, "side": "buy"}
{"type": "orderbook_delta", "seq": 1274, "price": 4, "quantity": 8000, "ts": 1756428191.561027, "side": "buy"}
{"type": "orderbook_delta", "seq": 1275, "price": 4, "quantity": 7000, "ts": 1756428191.571707, "side": "buy"}
{"type": "orderbook_delta", "seq": 1276, "price": 3, "quantity": -6480, "ts": 1756428192.3076, "side": "buy"}
{"type": "orderbook_delta", "seq": 1277, "price": 1, "quantity": 19440, "ts": 1756428192.3076, "side": "buy"}
{"type": "orderbook_delta", "seq": 1278, "price": 4, "quantity": -7000, "ts": 1756428192.344163, "side": "buy"}
{"type": "orderbook_delta", "seq": 1279, "price": 4, "quantity": -8000, "ts": 1756428192.345808, "side": "buy"}
{"type": "orderbook_delta", "seq": 1280, "price": 2, "quantity": 8000, "ts": 1756428192.395998, "side": "buy"}
{"type": "orderbook_delta", "seq": 1281, "price": 2, "quantity": 7000, "ts": 1756428192.398196, "side": "buy"}
{"type": "orderbook_delta", "seq": 1282, "price": 49, "quantity": 0, "ts": 1756428192.579706, "side": "buy"}
{"type": "trade", "seq": 17, "price": 49, "quantity": 100, "ts": 1756428192.579706, "side": "sell"}
{"type": "orderbook_delta", "seq": 1283, "price": 48, "quantity": 0, "ts": 1756428192.579706, "side": "buy"}
{"type": "trade", "seq": 18, "price": 48, "quantity": 20, "ts": 1756428192.579706, "side": "sell"}
{"type": "orderbook_delta", "seq": 1284, "price": 48, "quantity": 0, "ts": 1756428192.579706, "side": "buy"}
{"type": "trade", "seq": 19, "price": 48, "quantity": 67, "ts": 1756428192.671454, "side": "sell"}
{"type": "orderbook_delta", "seq": 1285, "price": 54, "quantity": 67, "ts": 1756428192.671454, "side": "sell"}
{"type": "orderbook_delta", "seq": 1286, "price": 55, "quantity": -500, "ts": 1756428192.709906, "side": "sell"}
{"type": "orderbook_delta", "seq": 1287, "price": 53, "quantity": 500, "ts": 1756428192.870573, "side": "sell"}
{"type": "orderbook_delta", "seq": 1288, "price": 57, "quantity": -1250, "ts": 1756428193.675352, "side": "sell"}
{"type": "orderbook_delta", "seq": 1289, "price": 44, "quantity": -200, "ts": 1756428193.676033, "side": "buy"}
{"type": "orderbook_delta", "seq": 1290, "price": 55, "quantity": -200, "ts": 1756428193.707864, "side": "sell"}
{"type": "orderbook_delta", "seq": 1291, "price": 56, "quantity": -200, "ts": 1756428193.75004, "side": "sell"}
{"type": "orderbook_delta", "seq": 1292, "price": 57, "quantity": 200, "ts": 1756428193.75004, "side": "sell"}
{"type": "orderbook_delta", "seq": 1293, "price": 42, "quantity": -1250, "ts": 1756428193.796164, "side": "buy"}
{"type": "orderbook_delta", "seq": 1294, "price": 56, "quantity": 200, "ts": 1756428193.833348, "side": "sell"}
{"type": "orderbook_delta", "seq": 1295, "price": 58, "quantity": 1250, "ts": 1756428193.834621, "side": "sell"}
{"type": "orderbook_delta", "seq": 1296, "price": 43, "quantity": 1250, "ts": 1756428193.834877, "side": "buy"}
{"type": "orderbook_delta", "seq": 1297, "price": 45, "quantity": 200, "ts": 1756428193.835107, "side": "buy"}
{"type": "orderbook_delta", "seq": 1298, "price": 66, "quantity": 250, "ts": 1756428194.072907, "side": "sell"}
{"type": "orderbook_delta", "seq": 1299, "price": 53, "quantity": -500, "ts": 1756428194.07355, "side": "sell"}
{"type": "orderbook_delta", "seq": 1300, "price": 43, "quantity": -1250, "ts": 1756428194.078592, "side": "buy"}
{"type": "orderbook_delta", "seq": 1301, "price": 2, "quantity": -8000, "ts": 1756428194.079265, "side": "buy"}
{"type": "orderbook_delta", "seq": 1302, "price": 56, "quantity": -200, "ts": 1756428194.07935, "side": "sell"}
{"type": "orderbook_delta", "seq": 1303, "price": 45, "quantity": -200, "ts": 1756428194.079399, "side": "buy"}
{"type": "orderbook_delta", "seq": 1304, "price": 58, "quantity": -1250, "ts": 1756428194.079445, "side": "sell"}
{"type": "orderbook_delta", "seq": 1305, "price": 47, "quantity": -500, "ts": 1756428194.079543, "side": "buy"}
{"type": "orderbook_delta", "seq": 1306, "price": 54, "quantity": -67, "ts": 1756428194.088664, "side": "sell"}
{"type": "orderbook_delta", "seq": 1307, "price": 56, "quantity": -250, "ts": 1756428194.117171, "side": "sell"}
{"type": "orderbook_delta", "seq": 1308, "price": 49, "quantity": 100, "ts": 1756428194.124747, "side": "buy"}
{"type": "orderbook_delta", "seq": 1309, "price": 49, "quantity": 500, "ts": 1756428194.127665, "side": "buy"}
{"type": "orderbook_delta", "seq": 1310, "price": 21, "quantity": 8000, "ts": 1756428194.127967, "side": "buy"}
{"type": "orderbook_delta", "seq": 1311, "price": 47, "quantity": 200, "ts": 1756428194.12879, "side": "buy"}
{"type": "orderbook_delta", "seq": 1312, "price": 58, "quantity": 200, "ts": 1756428194.132058, "side": "sell"}
{"type": "orderbook_delta", "seq": 1313, "price": 56, "quantity": 500, "ts": 1756428194.132514, "side": "sell"}
{"type": "orderbook_delta", "seq": 1314, "price": 60, "quantity": 1250, "ts": 1756428194.133175, "side": "sell"}
{"type": "orderbook_delta", "seq": 1315, "price": 45, "quantity": 1250, "ts": 1756428194.136275, "side": "buy"}
{"type": "orderbook_delta", "seq": 1316, "price": 57, "quantity": -200, "ts": 1756428194.155895, "side": "sell"}
{"type": "orderbook_delta", "seq": 1317, "price": 60, "quantity": 200, "ts": 1756428194.155895, "side": "sell"}
{"type": "orderbook_delta", "seq": 1318, "price": 58, "quantity": -250, "ts": 1756428194.171044, "side": "sell"}
{"type": "orderbook_delta", "seq": 1319, "price": 49, "quantity": -500, "ts": 1756428194.171185, "side": "buy"}
{"type": "orderbook_delta", "seq": 1320, "price": 68, "quantity": 250, "ts": 1756428194.179064, "side": "sell"}
{"type": "orderbook_delta", "seq": 1321, "price": 56, "quantity": 67, "ts": 1756428194.186003, "side": "sell"}
{"type": "orderbook_delta", "seq": 1322, "price": 56, "quantity": -500, "ts": 1756428194.200663, "side": "sell"}
{"type": "orderbook_delta", "seq": 1323, "price": 50, "quantity": 500, "ts": 1756428194.20668, "side": "buy"}
{"type": "orderbook_delta", "seq": 1324, "price": 58, "quantity": -200, "ts": 1756428194.210912, "side": "sell"}
{"type": "orderbook_delta", "seq": 1325, "price": 56, "quantity": 500, "ts": 1756428194.24275, "side": "sell"}
{"type": "orderbook_delta", "seq": 1326, "price": 59, "quantity": -100, "ts": 1756428194.253921, "side": "sell"}
{"type": "orderbook_delta", "seq": 1327, "price": 61, "quantity": 100, "ts": 1756428194.253921, "side": "sell"}
{"type": "orderbook_delta", "seq": 1328, "price": 59, "quantity": 200, "ts": 1756428194.261555, "side": "sell"}
{"type": "orderbook_delta", "seq": 1329, "price": 49, "quantity": -100, "ts": 1756428194.363023, "side": "buy"}
{"type": "orderbook_delta", "seq": 1330, "price": 51, "quantity": 100, "ts": 1756428194.363023, "side": "buy"}
{"type": "orderbook_delta", "seq": 1331, "price": 40, "quantity": -250, "ts": 1756428194.371612, "side": "buy"}
{"type": "orderbook_delta", "seq": 1332, "price": 50, "quantity": 250, "ts": 1756428194.374493, "side": "buy"}
{"type": "orderbook_delta", "seq": 1333, "price": 68, "quantity": -250, "ts": 1756428194.387866, "side": "sell"}
{"type": "orderbook_delta", "seq": 1334, "price": 58, "quantity": 250, "ts": 1756428194.405872, "side": "sell"}
{"type": "orderbook_delta", "seq": 1335, "price": 59, "quantity": -200, "ts": 1756428194.439053, "side": "sell"}
{"type": "orderbook_delta", "seq": 1336, "price": 61, "quantity": -100, "ts": 1756428194.44646, "side": "sell"}
{"type": "orderbook_delta", "seq": 1337, "price": 62, "quantity": 100, "ts": 1756428194.44646, "side": "sell"}
{"type": "orderbook_delta", "seq": 1338, "price": 58, "quantity": 200, "ts": 1756428194.482392, "side": "sell"}
{"type": "orderbook_delta", "seq": 1339, "price": 47, "quantity": -200, "ts": 1756428194.509148, "side": "buy"}
{"type": "orderbook_delta", "seq": 1340, "price": 60, "quantity": -1250, "ts": 1756428194.510418, "side": "sell"}
{"type": "orderbook_delta", "seq": 1341, "price": 45, "quantity": -1250, "ts": 1756428194.5107, "side": "buy"}
{"type": "orderbook_delta", "seq": 1342, "price": 58, "quantity": -200, "ts": 1756428194.516375, "side": "sell"}
{"type": "orderbook_delta", "seq": 1343, "price": 50, "quantity": 100, "ts": 1756428194.556533, "side": "buy"}
{"type": "orderbook_delta", "seq": 1344, "price": 46, "quantity": 1250, "ts": 1756428194.559033, "side": "buy"}
{"type": "orderbook_delta", "seq": 1345, "price": 48, "quantity": 200, "ts": 1756428194.559319, "side": "buy"}
{"type": "orderbook_delta", "seq": 1346, "price": 61, "quantity": 1250, "ts": 1756428194.56131, "side": "sell"}
{"type": "orderbook_delta", "seq": 1347, "price": 59, "quantity": 200, "ts": 1756428194.564956, "side": "sell"}
{"type": "orderbook_delta", "seq": 1348, "price": 75, "quantity": -3, "ts": 1756428194.59244, "side": "sell"}
{"type": "orderbook_delta", "seq": 1349, "price": 60, "quantity": -200, "ts": 1756428194.619641, "side": "sell"}
{"type": "orderbook_delta", "seq": 1350, "price": 58, "quantity": 200, "ts": 1756428194.619641, "side": "sell"}
{"type": "orderbook_delta", "seq": 1351, "price": 58, "quantity": -200, "ts": 1756428195.436636, "side": "sell"}
{"type": "orderbook_delta", "seq": 1352, "price": 56, "quantity": 200, "ts": 1756428195.436636, "side": "sell"}
{"type": "orderbook_delta", "seq": 1353, "price": 40, "quantity": 250, "ts": 1756428195.538789, "side": "buy"}
{"type": "orderbook_delta", "seq": 1354, "price": 50, "quantity": -250, "ts": 1756428195.544287, "side": "buy"}
{"type": "orderbook_delta", "seq": 1355, "price": 61, "quantity": -1250, "ts": 1756428195.552107, "side": "sell"}
{"type": "orderbook_delta", "seq": 1356, "price": 50, "quantity": -500, "ts": 1756428195.552161, "side": "buy"}
{"type": "orderbook_delta", "seq": 1357, "price": 59, "quantity": -200, "ts": 1756428195.552683, "side": "sell"}
{"type": "orderbook_delta", "seq": 1358, "price": 21, "quantity": -8000, "ts": 1756428195.553568, "side": "buy"}
{"type": "orderbook_delta", "seq": 1359, "price": 56, "quantity": -500, "ts": 1756428195.554738, "side": "sell"}
{"type": "orderbook_delta", "seq": 1360, "price": 48, "quantity": -200, "ts": 1756428195.557017, "side": "buy"}
{"type": "orderbook_delta", "seq": 1361, "price": 46, "quantity": -1250, "ts": 1756428195.5574, "side": "buy"}
{"type": "orderbook_delta", "seq": 1362, "price": 54, "quantity": 100, "ts": 1756428195.566261, "side": "sell"}
{"type": "orderbook_delta", "seq": 1363, "price": 51, "quantity": -100, "ts": 1756428195.604381, "side": "buy"}
{"type": "orderbook_delta", "seq": 1364, "price": 49, "quantity": 100, "ts": 1756428195.604381, "side": "buy"}
{"type": "orderbook_delta", "seq": 1365, "price": 38, "quantity": 250, "ts": 1756428195.609479, "side": "buy"}
{"type": "orderbook_delta", "seq": 1366, "price": 48, "quantity": -183, "ts": 1756428195.60979, "side": "buy"}
{"type": "orderbook_delta", "seq": 1367, "price": 2, "quantity": 8000, "ts": 1756428195.621877, "side": "buy"}
{"type": "orderbook_delta", "seq": 1368, "price": 54, "quantity": 500, "ts": 1756428195.622288, "side": "sell"}
{"type": "orderbook_delta", "seq": 1369, "price": 43, "quantity": 1250, "ts": 1756428195.623751, "side": "buy"}
{"type": "orderbook_delta", "seq": 1370, "price": 48, "quantity": 500, "ts": 1756428195.624048, "side": "buy"}
{"type": "orderbook_delta", "seq": 1371, "price": 56, "quantity": 200, "ts": 1756428195.624673, "side": "sell"}
{"type": "orderbook_delta", "seq": 1372, "price": 45, "quantity": 200, "ts": 1756428195.625766, "side": "buy"}
{"type": "orderbook_delta", "seq": 1373, "price": 58, "quantity": 1250, "ts": 1756428195.632538, "side": "sell"}
{"type": "orderbook_delta", "seq": 1374, "price": 58, "quantity": -250, "ts": 1756428195.63681, "side": "sell"}
{"type": "orderbook_delta", "seq": 1375, "price": 68, "quantity": 250, "ts": 1756428195.637102, "side": "sell"}
{"type": "orderbook_delta", "seq": 1376, "price": 48, "quantity": 250, "ts": 1756428195.680299, "side": "buy"}
{"type": "orderbook_delta", "seq": 1377, "price": 58, "quantity": -1250, "ts": 1756428195.682229, "side": "sell"}
{"type": "orderbook_delta", "seq": 1378, "price": 38, "quantity": -250, "ts": 1756428195.68238, "side": "buy"}
{"type": "orderbook_delta", "seq": 1379, "price": 58, "quantity": 250, "ts": 1756428195.706815, "side": "sell"}
{"type": "orderbook_delta", "seq": 1380, "price": 68, "quantity": -250, "ts": 1756428195.707046, "side": "sell"}
{"type": "orderbook_delta", "seq": 1381, "price": 59, "quantity": 1250, "ts": 1756428195.726732, "side": "sell"}
{"type": "orderbook_delta", "seq": 1382, "price": 59, "quantity": -1250, "ts": 1756428195.767411, "side": "sell"}
{"type": "orderbook_delta", "seq": 1383, "price": 2, "quantity": -8000, "ts": 1756428195.799907, "side": "buy"}
{"type": "orderbook_delta", "seq": 1384, "price": 45, "quantity": -200, "ts": 1756428195.801993, "side": "buy"}
{"type": "orderbook_delta", "seq": 1385, "price": 56, "quantity": -200, "ts": 1756428195.802877, "side": "sell"}
{"type": "orderbook_delta", "seq": 1386, "price": 59, "quantity": 1250, "ts": 1756428195.809177, "side": "sell"}
{"type": "orderbook_delta", "seq": 1387, "price": 43, "quantity": -1250, "ts": 1756428195.838605, "side": "buy"}
{"type": "orderbook_delta", "seq": 1388, "price": 75, "quantity": 0, "ts": 1756428195.86978, "side": "sell"}
{"type": "orderbook_delta", "seq": 1389, "price": 62, "quantity": -100, "ts": 1756428195.893245, "side": "sell"}
{"type": "orderbook_delta", "seq": 1390, "price": 59, "quantity": 100, "ts": 1756428195.893245, "side": "sell"}
{"type": "orderbook_delta", "seq": 1391, "price": 44, "quantity": 1250, "ts": 1756428195.89561, "side": "buy"}
{"type": "orderbook_delta", "seq": 1392, "price": 57, "quantity": 200, "ts": 1756428195.896783, "side": "sell"}
{"type": "orderbook_delta", "seq": 1393, "price": 46, "quantity": 200, "ts": 1756428195.89708, "side": "buy"}
{"type": "orderbook_delta", "seq": 1394, "price": 20, "quantity": 8000, "ts": 1756428195.897325, "side": "buy"}
{"type": "orderbook_delta", "seq": 1395, "price": 40, "quantity": -250, "ts": 1756428196.120706, "side": "buy"}
{"type": "orderbook_delta", "seq": 1396, "price": 50, "quantity": 250, "ts": 1756428196.121857, "side": "buy"}
{"type": "orderbook_delta", "seq": 1397, "price": 1, "quantity": -19440, "ts": 1756428196.29748, "side": "buy"}
{"type": "orderbook_delta", "seq": 1398, "price": 3, "quantity": 6480, "ts": 1756428196.29748, "side": "buy"}
{"type": "orderbook_delta", "seq": 1399, "price": 49, "quantity": -100, "ts": 1756428196.34521, "side": "buy"}
{"type": "orderbook_delta", "seq": 1400, "price": 51, "quantity": 100, "ts": 1756428196.34521, "side": "buy"}
{"type": "orderbook_delta", "seq": 1401, "price": 2, "quantity": -7000, "ts": 1756428196.397197, "side": "buy"}
{"type": "orderbook_delta", "seq": 1402, "price": 4, "quantity": 7000, "ts": 1756428196.457535, "side": "buy"}
{"type": "orderbook_delta", "seq": 1403, "price": 44, "quantity": -1250, "ts": 1756428196.737248, "side": "buy"}
{"type": "orderbook_delta", "seq": 1404, "price": 46, "quantity": -200, "ts": 1756428196.740416, "side": "buy"}
{"type": "orderbook_delta", "seq": 1405, "price": 59, "quantity": -1250, "ts": 1756428196.741195, "side": "sell"}
{"type": "orderbook_delta", "seq": 1406, "price": 57, "quantity": -200, "ts": 1756428196.741876, "side": "sell"}
{"type": "orderbook_delta", "seq": 1407, "price": 45, "quantity": 200, "ts": 1756428196.781978, "side": "buy"}
{"type": "orderbook_delta", "seq": 1408, "price": 58, "quantity": 1250, "ts": 1756428196.789045, "side": "sell"}
{"type": "orderbook_delta", "seq": 1409, "price": 56, "quantity": 200, "ts": 1756428196.789561, "side": "sell"}
{"type": "orderbook_delta", "seq": 1410, "price": 43, "quantity": 1250, "ts": 1756428196.850347, "side": "buy"}
{"type": "orderbook_delta", "seq": 1411, "price": 40, "quantity": 250, "ts": 1756428197.343188, "side": "buy"}
{"type": "orderbook_delta", "seq": 1412, "price": 50, "quantity": -250, "ts": 1756428197.344822, "side": "buy"}
{"type": "orderbook_delta", "seq": 1413, "price": 48, "quantity": -500, "ts": 1756428197.350867, "side": "buy"}
{"type": "orderbook_delta", "seq": 1414, "price": 20, "quantity": -8000, "ts": 1756428197.356223, "side": "buy"}
{"type": "orderbook_delta", "seq": 1415, "price": 54, "quantity": -500, "ts": 1756428197.356692, "side": "sell"}
{"type": "orderbook_delta", "seq": 1416, "price": 53, "quantity": 500, "ts": 1756428197.400195, "side": "sell"}
{"type": "orderbook_delta", "seq": 1417, "price": 4, "quantity": 8000, "ts": 1756428197.402528, "side": "buy"}
{"type": "orderbook_delta", "seq": 1418, "price": 47, "quantity": 500, "ts": 1756428197.407133, "side": "buy"}
{"type": "orderbook_delta", "seq": 1419, "price": 38, "quantity": 250, "ts": 1756428197.434898, "side": "buy"}
{"type": "orderbook_delta", "seq": 1420, "price": 48, "quantity": -250, "ts": 1756428197.440371, "side": "buy"}
{"type": "orderbook_delta", "seq": 1421, "price": 48, "quantity": 250, "ts": 1756428197.96877, "side": "buy"}
{"type": "orderbook_delta", "seq": 1422, "price": 38, "quantity": -250, "ts": 1756428197.973586, "side": "buy"}
{"type": "orderbook_delta", "seq": 1423, "price": 4, "quantity": -8000, "ts": 1756428197.997613, "side": "buy"}
{"type": "orderbook_delta", "seq": 1424, "price": 58, "quantity": -1250, "ts": 1756428197.997954, "side": "sell"}
{"type": "orderbook_delta", "seq": 1425, "price": 53, "quantity": -500, "ts": 1756428197.998795, "side": "sell"}
{"type": "orderbook_delta", "seq": 1426, "price": 43, "quantity": -1250, "ts": 1756428197.999459, "side": "buy"}
{"type": "orderbook_delta", "seq": 1427, "price": 47, "quantity": -500, "ts": 1756428197.999664, "side": "buy"}
{"type": "orderbook_delta", "seq": 1428, "price": 56, "quantity": -200, "ts": 1756428197.999866, "side": "sell"}
{"type": "orderbook_delta", "seq": 1429, "price": 45, "quantity": -200, "ts": 1756428198.000169, "side": "buy"}
{"type": "orderbook_delta", "seq": 1430, "price": 46, "quantity": 200, "ts": 1756428198.043059, "side": "buy"}
{"type": "orderbook_delta", "seq": 1431, "price": 38, "quantity": 250, "ts": 1756428198.04339, "side": "buy"}
{"type": "orderbook_delta", "seq": 1432, "price": 57, "quantity": 200, "ts": 1756428198.04362, "side": "sell"}
{"type": "orderbook_delta", "seq": 1433, "price": 54, "quantity": 500, "ts": 1756428198.044354, "side": "sell"}
{"type": "orderbook_delta", "seq": 1434, "price": 44, "quantity": 1250, "ts": 1756428198.044652, "side": "buy"}
{"type": "orderbook_delta", "seq": 1435, "price": 20, "quantity": 8000, "ts": 1756428198.045203, "side": "buy"}
{"type": "orderbook_delta", "seq": 1436, "price": 59, "quantity": 1250, "ts": 1756428198.045513, "side": "sell"}
{"type": "orderbook_delta", "seq": 1437, "price": 48, "quantity": 500, "ts": 1756428198.054061, "side": "buy"}
{"type": "orderbook_delta", "seq": 1438, "price": 48, "quantity": -250, "ts": 1756428198.055062, "side": "buy"}
{"type": "orderbook_delta", "seq": 1439, "price": 68, "quantity": 250, "ts": 1756428198.05656, "side": "sell"}
{"type": "orderbook_delta", "seq": 1440, "price": 58, "quantity": -250, "ts": 1756428198.07692, "side": "sell"}
{"type": "orderbook_delta", "seq": 1441, "price": 56, "quantity": -200, "ts": 1756428198.108283, "side": "sell"}
{"type": "orderbook_delta", "seq": 1442, "price": 58, "quantity": 200, "ts": 1756428198.108283, "side": "sell"}
{"type": "orderbook_delta", "seq": 1443, "price": 56, "quantity": -67, "ts": 1756428198.134718, "side": "sell"}
{"type": "orderbook_delta", "seq": 1444, "price": 48, "quantity": 250, "ts": 1756428198.136784, "side": "buy"}
{"type": "orderbook_delta", "seq": 1445, "price": 66, "quantity": -250, "ts": 1756428198.148008, "side": "sell"}
{"type": "orderbook_delta", "seq": 1446, "price": 56, "quantity": 250, "ts": 1756428198.156748, "side": "sell"}
{"type": "orderbook_delta", "seq": 1447, "price": 38, "quantity": -250, "ts": 1756428198.165524, "side": "buy"}
{"type": "orderbook_delta", "seq": 1448, "price": 58, "quantity": 250, "ts": 1756428198.177154, "side": "sell"}
{"type": "orderbook_delta", "seq": 1449, "price": 68, "quantity": -250, "ts": 1756428198.187069, "side": "sell"}
{"type": "orderbook_delta", "seq": 1450, "price": 54, "quantity": 67, "ts": 1756428198.234635, "side": "sell"}
{"type": "orderbook_delta", "seq": 1451, "price": 51, "quantity": -100, "ts": 1756428198.617035, "side": "buy"}
{"type": "orderbook_delta", "seq": 1452, "price": 49, "quantity": 100, "ts": 1756428198.617035, "side": "buy"}
{"type": "orderbook_delta", "seq": 1453, "price": 44, "quantity": -1250, "ts": 1756428198.978951, "side": "buy"}
{"type": "orderbook_delta", "seq": 1454, "price": 20, "quantity": -8000, "ts": 1756428198.98029, "side": "buy"}
{"type": "orderbook_delta", "seq": 1455, "price": 59, "quantity": -1250, "ts": 1756428198.981965, "side": "sell"}
{"type": "orderbook_delta", "seq": 1456, "price": 46, "quantity": -200, "ts": 1756428198.98204, "side": "buy"}
{"type": "orderbook_delta", "seq": 1457, "price": 57, "quantity": -200, "ts": 1756428198.982094, "side": "sell"}
{"type": "orderbook_delta", "seq": 1458, "price": 58, "quantity": 1250, "ts": 1756428199.018965, "side": "sell"}
{"type": "orderbook_delta", "seq": 1459, "price": 56, "quantity": 200, "ts": 1756428199.019244, "side": "sell"}
{"type": "orderbook_delta", "seq": 1460, "price": 43, "quantity": 1250, "ts": 1756428199.021156, "side": "buy"}
{"type": "orderbook_delta", "seq": 1461, "price": 4, "quantity": 8000, "ts": 1756428199.021456, "side": "buy"}
{"type": "orderbook_delta", "seq": 1462, "price": 45, "quantity": 200, "ts": 1756428199.021728, "side": "buy"}
{"type": "orderbook_delta", "seq": 1463, "price": 58, "quantity": -200, "ts": 1756428199.039069, "side": "sell"}
{"type": "orderbook_delta", "seq": 1464, "price": 57, "quantity": 200, "ts": 1756428199.039069, "side": "sell"}
{"type": "orderbook_delta", "seq": 1465, "price": 57, "quantity": -200, "ts": 1756428199.477737, "side": "sell"}
{"type": "orderbook_delta", "seq": 1466, "price": 58, "quantity": 200, "ts": 1756428199.477737, "side": "sell"}
{"type": "orderbook_delta", "seq": 1467, "price": 66, "quantity": 250, "ts": 1756428199.66293, "side": "sell"}
{"type": "orderbook_delta", "seq": 1468, "price": 43, "quantity": -1250, "ts": 1756428199.671128, "side": "buy"}
{"type": "orderbook_delta", "seq": 1469, "price": 48, "quantity": -500, "ts": 1756428199.671871, "side": "buy"}
{"type": "orderbook_delta", "seq": 1470, "price": 4, "quantity": -8000, "ts": 1756428199.672413, "side": "buy"}
{"type": "orderbook_delta", "seq": 1471, "price": 45, "quantity": -200, "ts": 1756428199.672628, "side": "buy"}
{"type": "orderbook_delta", "seq": 1472, "price": 58, "quantity": -1250, "ts": 1756428199.672853, "side": "sell"}
{"type": "orderbook_delta", "seq": 1473, "price": 54, "quantity": -67, "ts": 1756428199.67329, "side": "sell"}
{"type": "orderbook_delta", "seq": 1474, "price": 54, "quantity": -500, "ts": 1756428199.674167, "side": "sell"}
{"type": "orderbook_delta", "seq": 1475, "price": 56, "quantity": -250, "ts": 1756428199.686488, "side": "sell"}
{"type": "orderbook_delta", "seq": 1476, "price": 56, "quantity": -200, "ts": 1756428199.688022, "side": "sell"}
{"type": "orderbook_delta", "seq": 1477, "price": 58, "quantity": 200, "ts": 1756428199.734722, "side": "sell"}
{"type": "orderbook_delta", "seq": 1478, "price": 49, "quantity": 500, "ts": 1756428199.735501, "side": "buy"}
{"type": "orderbook_delta", "seq": 1479, "price": 21, "quantity": 8000, "ts": 1756428199.736645, "side": "buy"}
{"type": "orderbook_delta", "seq": 1480, "price": 47, "quantity": 200, "ts": 1756428199.737513, "side": "buy"}
{"type": "orderbook_delta", "seq": 1481, "price": 57, "quantity": 500, "ts": 1756428199.737782, "side": "sell"}
{"type": "orderbook_delta", "seq": 1482, "price": 45, "quantity": 1250, "ts": 1756428199.740127, "side": "buy"}
{"type": "orderbook_delta", "seq": 1483, "price": 60, "quantity": 1250, "ts": 1756428199.740418, "side": "sell"}
{"type": "orderbook_delta", "seq": 1484, "price": 55, "quantity": 67, "ts": 1756428199.74068, "side": "sell"}
{"type": "orderbook_delta", "seq": 1485, "price": 49, "quantity": -100, "ts": 1756428199.790671, "side": "buy"}
{"type": "orderbook_delta", "seq": 1486, "price": 50, "quantity": 100, "ts": 1756428199.790671, "side": "buy"}
{"type": "orderbook_delta", "seq": 1487, "price": 55, "quantity": -67, "ts": 1756428199.792246, "side": "sell"}
{"type": "orderbook_delta", "seq": 1488, "price": 49, "quantity": -500, "ts": 1756428199.796837, "side": "buy"}
{"type": "orderbook_delta", "seq": 1489, "price": 68, "quantity": 250, "ts": 1756428199.812224, "side": "sell"}
{"type": "orderbook_delta", "seq": 1490, "price": 58, "quantity": -200, "ts": 1756428199.816939, "side": "sell"}
{"type": "orderbook_delta", "seq": 1491, "price": 59, "quantity": 200, "ts": 1756428199.816939, "side": "sell"}
{"type": "orderbook_delta", "seq": 1492, "price": 45, "quantity": -1250, "ts": 1756428199.836884, "side": "buy"}
{"type": "orderbook_delta", "seq": 1493, "price": 58, "quantity": -200, "ts": 1756428199.837973, "side": "sell"}
{"type": "orderbook_delta", "seq": 1494, "price": 47, "quantity": -200, "ts": 1756428199.839167, "side": "buy"}
{"type": "orderbook_delta", "seq": 1495, "price": 57, "quantity": 67, "ts": 1756428199.839981, "side": "sell"}
{"type": "orderbook_delta", "seq": 1496, "price": 51, "quantity": 500, "ts": 1756428199.844167, "side": "buy"}
{"type": "orderbook_delta", "seq": 1497, "price": 59, "quantity": -200, "ts": 1756428199.866835, "side": "sell"}
{"type": "orderbook_delta", "seq": 1498, "price": 61, "quantity": 200, "ts": 1756428199.866835, "side": "sell"}
{"type": "orderbook_delta", "seq": 1499, "price": 60, "quantity": -1250, "ts": 1756428199.885777, "side": "sell"}
{"type": "orderbook_delta", "seq": 1500, "price": 58, "quantity": -250, "ts": 1756428199.886136, "side": "sell"}
{"type": "orderbook_delta", "seq": 1501, "price": 59, "quantity": -100, "ts": 1756428199.979298, "side": "sell"}
{"type": "orderbook_delta", "seq": 1502, "price": 61, "quantity": 100, "ts": 1756428199.979298, "side": "sell"}
{"type": "orderbook_delta", "seq": 1503, "price": 60, "quantity": 200, "ts": 1756428200.008884, "side": "sell"}
{"type": "orderbook_delta", "seq": 1504, "price": 62, "quantity": 1250, "ts": 1756428200.014179, "side": "sell"}
{"type": "orderbook_delta", "seq": 1505, "price": 47, "quantity": 1250, "ts": 1756428200.021918, "side": "buy"}
{"type": "orderbook_delta", "seq": 1506, "price": 49, "quantity": 200, "ts": 1756428200.029648, "side": "buy"}
{"type": "orderbook_delta", "seq": 1507, "price": 61, "quantity": -100, "ts": 1756428200.042477, "side": "sell"}
{"type": "orderbook_delta", "seq": 1508, "price": 62, "quantity": 100, "ts": 1756428200.042477, "side": "sell"}
{"type": "orderbook_delta", "seq": 1509, "price": 50, "quantity": -100, "ts": 1756428200.090632, "side": "buy"}
{"type": "orderbook_delta", "seq": 1510, "price": 52, "quantity": 100, "ts": 1756428200.090632, "side": "buy"}
{"type": "orderbook_delta", "seq": 1511, "price": 57, "quantity": -500, "ts": 1756428200.105967, "side": "sell"}
{"type": "orderbook_delta", "seq": 1512, "price": 57, "quantity": -67, "ts": 1756428200.121628, "side": "sell"}
{"type": "orderbook_delta", "seq": 1513, "price": 51, "quantity": -500, "ts": 1756428200.122934, "side": "buy"}
{"type": "orderbook_delta", "seq": 1514, "price": 52, "quantity": 250, "ts": 1756428200.137738, "side": "buy"}
{"type": "orderbook_delta", "seq": 1515, "price": 40, "quantity": -250, "ts": 1756428200.15713, "side": "buy"}
{"type": "orderbook_delta", "seq": 1516, "price": 50, "quantity": 250, "ts": 1756428200.157346, "side": "buy"}
{"type": "orderbook_delta", "seq": 1517, "price": 59, "quantity": 500, "ts": 1756428200.163539, "side": "sell"}
{"type": "orderbook_delta", "seq": 1518, "price": 52, "quantity": 500, "ts": 1756428200.163852, "side": "buy"}
{"type": "orderbook_delta", "seq": 1519, "price": 42, "quantity": -250, "ts": 1756428200.176529, "side": "buy"}
{"type": "orderbook_delta", "seq": 1520, "price": 58, "quantity": 67, "ts": 1756428200.227203, "side": "sell"}
{"type": "orderbook_delta", "seq": 1521, "price": 59, "quantity": -500, "ts": 1756428200.262229, "side": "sell"}
{"type": "orderbook_delta", "seq": 1522, "price": 54, "quantity": -100, "ts": 1756428200.268236, "side": "sell"}
{"type": "orderbook_delta", "seq": 1523, "price": 61, "quantity": -200, "ts": 1756428200.27068, "side": "sell"}
{"type": "orderbook_delta", "seq": 1524, "price": 60, "quantity": 200, "ts": 1756428200.27068, "side": "sell"}
{"type": "orderbook_delta", "seq": 1525, "price": 58, "quantity": 500, "ts": 1756428200.308335, "side": "sell"}
{"type": "orderbook_delta", "seq": 1526, "price": 3, "quantity": -6480, "ts": 1756428200.344146, "side": "buy"}
{"type": "orderbook_delta", "seq": 1527, "price": 1, "quantity": 19440, "ts": 1756428200.344146, "side": "buy"}
{"type": "orderbook_delta", "seq": 1528, "price": 4, "quantity": -7000, "ts": 1756428200.444809, "side": "buy"}
{"type": "orderbook_delta", "seq": 1529, "price": 2, "quantity": 7000, "ts": 1756428200.48267, "side": "buy"}
{"type": "orderbook_delta", "seq": 1530, "price": 52, "quantity": -100, "ts": 1756428200.48649, "side": "buy"}
{"type": "orderbook_delta", "seq": 1531, "price": 53, "quantity": 100, "ts": 1756428200.48649, "side": "buy"}
{"type": "orderbook_delta", "seq": 1532, "price": 47, "quantity": -1250, "ts": 1756428200.498718, "side": "buy"}
{"type": "orderbook_delta", "seq": 1533, "price": 58, "quantity": -500, "ts": 1756428200.499612, "side": "sell"}
{"type": "orderbook_delta", "seq": 1534, "price": 52, "quantity": -500, "ts": 1756428200.500314, "side": "buy"}
{"type": "orderbook_delta", "seq": 1535, "price": 60, "quantity": -200, "ts": 1756428200.501725, "side": "sell"}
{"type": "orderbook_delta", "seq": 1536, "price": 21, "quantity": -8000, "ts": 1756428200.502866, "side": "buy"}
{"type": "orderbook_delta", "seq": 1537, "price": 60, "quantity": -200, "ts": 1756428200.506925, "side": "sell"}
{"type": "orderbook_delta", "seq": 1538, "price": 59, "quantity": 200, "ts": 1756428200.506925, "side": "sell"}
{"type": "orderbook_delta", "seq": 1539, "price": 62, "quantity": -1250, "ts": 1756428200.513858, "side": "sell"}
{"type": "orderbook_delta", "seq": 1540, "price": 49, "quantity": -200, "ts": 1756428200.513915, "side": "buy"}
{"type": "orderbook_delta", "seq": 1541, "price": 40, "quantity": 250, "ts": 1756428200.51767, "side": "buy"}
{"type": "orderbook_delta", "seq": 1542, "price": 50, "quantity": -250, "ts": 1756428200.517884, "side": "buy"}
{"type": "orderbook_delta", "seq": 1543, "price": 42, "quantity": 250, "ts": 1756428200.538276, "side": "buy"}
{"type": "orderbook_delta", "seq": 1544, "price": 52, "quantity": -250, "ts": 1756428200.538513, "side": "buy"}
{"type": "orderbook_delta", "seq": 1545, "price": 2, "quantity": -7000, "ts": 1756428200.539389, "side": "buy"}
{"type": "orderbook_delta", "seq": 1546, "price": 98, "quantity": -8000, "ts": 1756428200.561955, "side": "sell"}
{"type": "orderbook_delta", "seq": 1547, "price": 53, "quantity": -100, "ts": 1756428200.562804, "side": "buy"}
{"type": "orderbook_delta", "seq": 1548, "price": 50, "quantity": 100, "ts": 1756428200.562804, "side": "buy"}
{"type": "orderbook_delta", "seq": 1549, "price": 48, "quantity": -250, "ts": 1756428200.567501, "side": "buy"}
{"type": "orderbook_delta", "seq": 1550, "price": 70, "quantity": 250, "ts": 1756428200.568372, "side": "sell"}
{"type": "orderbook_delta", "seq": 1551, "price": 2, "quantity": 8000, "ts": 1756428200.5753, "side": "buy"}
{"type": "orderbook_delta", "seq": 1552, "price": 53, "quantity": 100, "ts": 1756428200.584216, "side": "sell"}
{"type": "orderbook_delta", "seq": 1553, "price": 40, "quantity": -250, "ts": 1756428200.606098, "side": "buy"}
{"type": "orderbook_delta", "seq": 1554, "price": 79, "quantity": 8000, "ts": 1756428200.615359, "side": "sell"}
{"type": "orderbook_delta", "seq": 1555, "price": 50, "quantity": -100, "ts": 1756428200.623117, "side": "buy"}
{"type": "orderbook_delta", "seq": 1556, "price": 42, "quantity": 100, "ts": 1756428200.623117, "side": "buy"}
{"type": "orderbook_delta", "seq": 1557, "price": 42, "quantity": -250, "ts": 1756428200.62551, "side": "buy"}
{"type": "orderbook_delta", "seq": 1558, "price": 46, "quantity": -250, "ts": 1756428200.625776, "side": "buy"}
{"type": "orderbook_delta", "seq": 1559, "price": 60, "quantity": -250, "ts": 1756428200.647153, "side": "sell"}
{"type": "orderbook_delta", "seq": 1560, "price": 6, "quantity": 250, "ts": 1756428200.656909, "side": "buy"}
{"type": "orderbook_delta", "seq": 1561, "price": 44, "quantity": -250, "ts": 1756428200.666473, "side": "buy"}
{"type": "orderbook_delta", "seq": 1562, "price": 12, "quantity": 250, "ts": 1756428200.676125, "side": "buy"}
{"type": "orderbook_delta", "seq": 1563, "price": 2, "quantity": -8000, "ts": 1756428200.694988, "side": "buy"}
{"type": "orderbook_delta", "seq": 1564, "price": 10, "quantity": 250, "ts": 1756428200.696859, "side": "buy"}
{"type": "orderbook_delta", "seq": 1565, "price": 4, "quantity": 250, "ts": 1756428200.716944, "side": "buy"}
{"type": "orderbook_delta", "seq": 1566, "price": 59, "quantity": -200, "ts": 1756428200.721393, "side": "sell"}
{"type": "orderbook_delta", "seq": 1567, "price": 61, "quantity": 200, "ts": 1756428200.721393, "side": "sell"}
{"type": "orderbook_delta", "seq": 1568, "price": 13, "quantity": 8000, "ts": 1756428200.735772, "side": "buy"}
{"type": "orderbook_delta", "seq": 1569, "price": 8, "quantity": 250, "ts": 1756428200.73682, "side": "buy"}
{"type": "orderbook_delta", "seq": 1570, "price": 62, "quantity": -100, "ts": 1756428200.793631, "side": "sell"}
{"type": "orderbook_delta", "seq": 1571, "price": 63, "quantity": 100, "ts": 1756428200.793631, "side": "sell"}
{"type": "orderbook_delta", "seq": 1572, "price": 14, "quantity": 250, "ts": 1756428200.969355, "side": "buy"}
{"type": "orderbook_delta", "seq": 1573, "price": 4, "quantity": -250, "ts": 1756428200.969624, "side": "buy"}
{"type": "orderbook_delta", "seq": 1574, "price": 62, "quantity": -250, "ts": 1756428200.986555, "side": "sell"}
{"type": "orderbook_delta", "seq": 1575, "price": 72, "quantity": 250, "ts": 1756428200.987213, "side": "sell"}
{"type": "orderbook_delta", "seq": 1576, "price": 13, "quantity": -8000, "ts": 1756428201.011469, "side": "buy"}
{"type": "orderbook_delta", "seq": 1577, "price": 42, "quantity": -100, "ts": 1756428201.036925, "side": "buy"}
{"type": "orderbook_delta", "seq": 1578, "price": 41, "quantity": 100, "ts": 1756428201.036925, "side": "buy"}
{"type": "orderbook_delta", "seq": 1579, "price": 15, "quantity": 8000, "ts": 1756428201.057793, "side": "buy"}
{"type": "orderbook_delta", "seq": 1580, "price": 58, "quantity": -67, "ts": 1756428201.146168, "side": "sell"}
{"type": "orderbook_delta", "seq": 1581, "price": 36, "quantity": 250, "ts": 1756428201.175899, "side": "buy"}
{"type": "orderbook_delta", "seq": 1582, "price": 6, "quantity": -250, "ts": 1756428201.186703, "side": "buy"}
{"type": "orderbook_delta", "seq": 1583, "price": 70, "quantity": -250, "ts": 1756428201.205902, "side": "sell"}
{"type": "orderbook_delta", "seq": 1584, "price": 62, "quantity": 250, "ts": 1756428201.216304, "side": "sell"}
{"type": "orderbook_delta", "seq": 1585, "price": 68, "quantity": -250, "ts": 1756428201.227658, "side": "sell"}
{"type": "orderbook_delta", "seq": 1586, "price": 60, "quantity": 250, "ts": 1756428201.255492, "side": "sell"}
{"type": "orderbook_delta", "seq": 1587, "price": 66, "quantity": -250, "ts": 1756428201.266077, "side": "sell"}
{"type": "orderbook_delta", "seq": 1588, "price": 58, "quantity": 250, "ts": 1756428201.274536, "side": "sell"}
{"type": "orderbook_delta", "seq": 1589, "price": 56, "quantity": 250, "ts": 1756428201.285854, "side": "sell"}
{"type": "orderbook_delta", "seq": 1590, "price": 72, "quantity": -250, "ts": 1756428201.286132, "side": "sell"}
{"type": "orderbook_delta", "seq": 1591, "price": 42, "quantity": 250, "ts": 1756428201.305908, "side": "buy"}
{"type": "orderbook_delta", "seq": 1592, "price": 8, "quantity": -250, "ts": 1756428201.306477, "side": "buy"}
{"type": "orderbook_delta", "seq": 1593, "price": 40, "quantity": 250, "ts": 1756428201.326075, "side": "buy"}
{"type": "orderbook_delta", "seq": 1594, "price": 12, "quantity": -250, "ts": 1756428201.327085, "side": "buy"}
{"type": "orderbook_delta", "seq": 1595, "price": 34, "quantity": 250, "ts": 1756428201.346381, "side": "buy"}
{"type": "orderbook_delta", "seq": 1596, "price": 10, "quantity": -250, "ts": 1756428201.347093, "side": "buy"}
{"type": "orderbook_delta", "seq": 1597, "price": 38, "quantity": 250, "ts": 1756428201.366844, "side": "buy"}
{"type": "orderbook_delta", "seq": 1598, "price": 14, "quantity": -250, "ts": 1756428201.407572, "side": "buy"}
{"type": "orderbook_delta", "seq": 1599, "price": 15, "quantity": -8000, "ts": 1756428201.440323, "side": "buy"}
{"type": "orderbook_delta", "seq": 1600, "price": 2, "quantity": 8000, "ts": 1756428201.48258, "side": "buy"}
{"type": "orderbook_delta", "seq": 1601, "price": 40, "quantity": -250, "ts": 1756428201.485016, "side": "buy"}
{"type": "orderbook_delta", "seq": 1602, "price": 36, "quantity": -250, "ts": 1756428201.569178, "side": "buy"}
{"type": "orderbook_delta", "seq": 1603, "price": 42, "quantity": -250, "ts": 1756428201.569431, "side": "buy"}
{"type": "orderbook_delta", "seq": 1604, "price": 50, "quantity": 0, "ts": 1756428201.751037, "side": "buy"}
{"type": "trade", "seq": 20, "price": 50, "quantity": 100, "ts": 1756428201.764504, "side": "sell"}
{"type": "orderbook_delta", "seq": 1605, "price": 63, "quantity": -100, "ts": 1756428201.764504, "side": "sell"}
{"type": "orderbook_delta", "seq": 1606, "price": 55, "quantity": 100, "ts": 1756428201.764504, "side": "sell"}
{"type": "orderbook_delta", "seq": 1607, "price": 20, "quantity": -200, "ts": 1756428201.764807, "side": "buy"}
{"type": "orderbook_delta", "seq": 1608, "price": 10, "quantity": 200, "ts": 1756428201.764807, "side": "buy"}
{"type": "orderbook_delta", "seq": 1609, "price": 61, "quantity": -200, "ts": 1756428201.776285, "side": "sell"}
{"type": "orderbook_delta", "seq": 1610, "price": 55, "quantity": 200, "ts": 1756428201.776285, "side": "sell"}
{"type": "orderbook_delta", "seq": 1611, "price": 38, "quantity": -250, "ts": 1756428201.7886, "side": "buy"}
{"type": "orderbook_delta", "seq": 1612, "price": 50, "quantity": 67, "ts": 1756428201.790425, "side": "sell"}
{"type": "orderbook_delta", "seq": 1613, "price": 35, "quantity": 1250, "ts": 1756428201.814577, "side": "buy"}
{"type": "orderbook_delta", "seq": 1614, "price": 2, "quantity": -8000, "ts": 1756428201.816523, "side": "buy"}
{"type": "orderbook_delta", "seq": 1615, "price": 39, "quantity": 500, "ts": 1756428201.843868, "side": "buy"}
{"type": "orderbook_delta", "seq": 1616, "price": 41, "quantity": -100, "ts": 1756428201.844435, "side": "buy"}
{"type": "orderbook_delta", "seq": 1617, "price": 39, "quantity": 100, "ts": 1756428201.844435, "side": "buy"}
{"type": "orderbook_delta", "seq": 1618, "price": 55, "quantity": -200, "ts": 1756428201.884131, "side": "sell"}
{"type": "orderbook_delta", "seq": 1619, "price": 54, "quantity": 200, "ts": 1756428201.884131, "side": "sell"}
{"type": "orderbook_delta", "seq": 1620, "price": 34, "quantity": -250, "ts": 1756428201.904766, "side": "buy"}
{"type": "orderbook_delta", "seq": 1621, "price": 22, "quantity": 250, "ts": 1756428201.905251, "side": "buy"}
{"type": "orderbook_delta", "seq": 1622, "price": 54, "quantity": 1250, "ts": 1756428201.906799, "side": "sell"}
{"type": "orderbook_delta", "seq": 1623, "price": 49, "quantity": 500, "ts": 1756428201.912583, "side": "sell"}
{"type": "orderbook_delta", "seq": 1624, "price": 54, "quantity": 250, "ts": 1756428201.913045, "side": "sell"}
{"type": "orderbook_delta", "seq": 1625, "price": 54, "quantity": 200, "ts": 1756428201.913379, "side": "sell"}
{"type": "orderbook_delta", "seq": 1626, "price": 35, "quantity": 200, "ts": 1756428201.914539, "side": "buy"}
{"type": "orderbook_delta", "seq": 1627, "price": 11, "quantity": 8000, "ts": 1756428201.917116, "side": "buy"}
{"type": "orderbook_delta", "seq": 1628, "price": 64, "quantity": -250, "ts": 1756428201.917572, "side": "sell"}
{"type": "orderbook_delta", "seq": 1629, "price": 39, "quantity": -500, "ts": 1756428201.945215, "side": "buy"}
{"type": "orderbook_delta", "seq": 1630, "price": 26, "quantity": 250, "ts": 1756428201.957071, "side": "buy"}
{"type": "orderbook_delta", "seq": 1631, "price": 28, "quantity": 250, "ts": 1756428201.970949, "side": "buy"}
{"type": "orderbook_delta", "seq": 1632, "price": 35, "quantity": -1250, "ts": 1756428201.975659, "side": "buy"}
{"type": "orderbook_delta", "seq": 1633, "price": 35, "quantity": -200, "ts": 1756428201.978606, "side": "buy"}
{"type": "orderbook_delta", "seq": 1634, "price": 54, "quantity": -1250, "ts": 1756428201.980553, "side": "sell"}
{"type": "orderbook_delta", "seq": 1635, "price": 54, "quantity": -200, "ts": 1756428201.980801, "side": "sell"}
{"type": "orderbook_delta", "seq": 1636, "price": 54, "quantity": -250, "ts": 1756428201.981798, "side": "sell"}
{"type": "orderbook_delta", "seq": 1637, "price": 54, "quantity": -200, "ts": 1756428201.988332, "side": "sell"}
{"type": "orderbook_delta", "seq": 1638, "price": 48, "quantity": 200, "ts": 1756428201.988332, "side": "sell"}
{"type": "orderbook_delta", "seq": 1639, "price": 20, "quantity": 250, "ts": 1756428201.988617, "side": "buy"}
{"type": "orderbook_delta", "seq": 1640, "price": 40, "quantity": 500, "ts": 1756428202.014494, "side": "buy"}
{"type": "orderbook_delta", "seq": 1641, "price": 24, "quantity": 250, "ts": 1756428202.018642, "side": "buy"}
{"type": "orderbook_delta", "seq": 1642, "price": 28, "quantity": -250, "ts": 1756428202.043974, "side": "buy"}
{"type": "orderbook_delta", "seq": 1643, "price": 49, "quantity": -500, "ts": 1756428202.044202, "side": "sell"}
{"type": "orderbook_delta", "seq": 1644, "price": 55, "quantity": -100, "ts": 1756428202.044248, "side": "sell"}
{"type": "orderbook_delta", "seq": 1645, "price": 51, "quantity": 100, "ts": 1756428202.044248, "side": "sell"}
{"type": "orderbook_delta", "seq": 1646, "price": 29, "quantity": 1250, "ts": 1756428202.045029, "side": "buy"}
{"type": "orderbook_delta", "seq": 1647, "price": 29, "quantity": 200, "ts": 1756428202.045602, "side": "buy"}
{"type": "orderbook_delta", "seq": 1648, "price": 55, "quantity": 1250, "ts": 1756428202.056267, "side": "sell"}
{"type": "orderbook_delta", "seq": 1649, "price": 48, "quantity": 200, "ts": 1756428202.056849, "side": "sell"}
{"type": "orderbook_delta", "seq": 1650, "price": 18, "quantity": 250, "ts": 1756428202.266141, "side": "buy"}
{"type": "orderbook_delta", "seq": 1651, "price": 29, "quantity": -200, "ts": 1756428202.269, "side": "buy"}
{"type": "orderbook_delta", "seq": 1652, "price": 48, "quantity": 500, "ts": 1756428202.271203, "side": "sell"}
{"type": "orderbook_delta", "seq": 1653, "price": 29, "quantity": -1250, "ts": 1756428202.27223, "side": "buy"}
{"type": "orderbook_delta", "seq": 1654, "price": 50, "quantity": -67, "ts": 1756428202.320424, "side": "sell"}
{"type": "orderbook_delta", "seq": 1655, "price": 27, "quantity": 200, "ts": 1756428202.354786, "side": "buy"}
{"type": "orderbook_delta", "seq": 1656, "price": 27, "quantity": 1250, "ts": 1756428202.355312, "side": "buy"}
{"type": "orderbook_delta", "seq": 1657, "price": 62, "quantity": -250, "ts": 1756428202.375776, "side": "sell"}
{"type": "orderbook_delta", "seq": 1658, "price": 36, "quantity": 250, "ts": 1756428202.37581, "side": "buy"}
{"type": "orderbook_delta", "seq": 1659, "price": 27, "quantity": -200, "ts": 1756428202.48594, "side": "buy"}
{"type": "orderbook_delta", "seq": 1660, "price": 34, "quantity": 250, "ts": 1756428202.487125, "side": "buy"}
{"type": "orderbook_delta", "seq": 1661, "price": 54, "quantity": 250, "ts": 1756428202.514301, "side": "sell"}
{"type": "orderbook_delta", "seq": 1662, "price": 27, "quantity": -1250, "ts": 1756428202.545342, "side": "buy"}
{"type": "orderbook_delta", "seq": 1663, "price": 37, "quantity": 200, "ts": 1756428202.545378, "side": "buy"}
{"type": "orderbook_delta", "seq": 1664, "price": 52, "quantity": 250, "ts": 1756428202.567999, "side": "sell"}
{"type": "orderbook_delta", "seq": 1665, "price": 22, "quantity": -250, "ts": 1756428202.568353, "side": "buy"}
{"type": "orderbook_delta", "seq": 1666, "price": 55, "quantity": -1250, "ts": 1756428202.57355, "side": "sell"}
{"type": "orderbook_delta", "seq": 1667, "price": 48, "quantity": 67, "ts": 1756428202.581367, "side": "sell"}
{"type": "orderbook_delta", "seq": 1668, "price": 39, "quantity": -100, "ts": 1756428202.62449, "side": "buy"}
{"type": "orderbook_delta", "seq": 1669, "price": 41, "quantity": 100, "ts": 1756428202.62449, "side": "buy"}
{"type": "orderbook_delta", "seq": 1670, "price": 18, "quantity": -250, "ts": 1756428202.668196, "side": "buy"}
{"type": "orderbook_delta", "seq": 1671, "price": 40, "quantity": 250, "ts": 1756428202.668276, "side": "buy"}
{"type": "orderbook_delta", "seq": 1672, "price": 40, "quantity": -500, "ts": 1756428202.695594, "side": "buy"}
{"type": "orderbook_delta", "seq": 1673, "price": 51, "quantity": 1250, "ts": 1756428202.695709, "side": "sell"}
{"type": "orderbook_delta", "seq": 1674, "price": 35, "quantity": 1250, "ts": 1756428202.696493, "side": "buy"}
{"type": "orderbook_delta", "seq": 1675, "price": 24, "quantity": -250, "ts": 1756428202.747034, "side": "buy"}
{"type": "orderbook_delta", "seq": 1676, "price": 38, "quantity": 250, "ts": 1756428202.783688, "side": "buy"}
{"type": "orderbook_delta", "seq": 1677, "price": 40, "quantity": 500, "ts": 1756428202.78708, "side": "buy"}
{"type": "orderbook_delta", "seq": 1678, "price": 1, "quantity": -19440, "ts": 1756428202.804858, "side": "buy"}
{"type": "orderbook_delta", "seq": 1679, "price": 32, "quantity": 250, "ts": 1756428202.81999, "side": "buy"}
{"type": "orderbook_delta", "seq": 1680, "price": 20, "quantity": -250, "ts": 1756428202.820976, "side": "buy"}
{"type": "orderbook_delta", "seq": 1681, "price": 26, "quantity": -250, "ts": 1756428202.906379, "side": "buy"}
{"type": "orderbook_delta", "seq": 1682, "price": 50, "quantity": 250, "ts": 1756428202.971844, "side": "sell"}
{"type": "orderbook_delta", "seq": 1683, "price": 48, "quantity": -67, "ts": 1756428202.981983, "side": "sell"}
{"type": "orderbook_delta", "seq": 1684, "price": 60, "quantity": -250, "ts": 1756428202.997161, "side": "sell"}
{"type": "orderbook_delta", "seq": 1685, "price": 51, "quantity": -1250, "ts": 1756428203.006669, "side": "sell"}
{"type": "orderbook_delta", "seq": 1686, "price": 51, "quantity": -100, "ts": 1756428203.038285, "side": "sell"}
{"type": "orderbook_delta", "seq": 1687, "price": 48, "quantity": 100, "ts": 1756428203.038285, "side": "sell"}
{"type": "orderbook_delta", "seq": 1688, "price": 48, "quantity": 67, "ts": 1756428203.039356, "side": "sell"}
{"type": "orderbook_delta", "seq": 1689, "price": 50, "quantity": 1250, "ts": 1756428203.060475, "side": "sell"}
{"type": "orderbook_delta", "seq": 1690, "price": 48, "quantity": -100, "ts": 1756428203.949472, "side": "sell"}
{"type": "orderbook_delta", "seq": 1691, "price": 49, "quantity": 100, "ts": 1756428203.949472, "side": "sell"}
{"type": "orderbook_delta", "seq": 1692, "price": 40, "quantity": -500, "ts": 1756428203.959771, "side": "buy"}
{"type": "orderbook_delta", "seq": 1693, "price": 39, "quantity": 500, "ts": 1756428204.025786, "side": "buy"}
{"type": "orderbook_delta", "seq": 1694, "price": 53, "quantity": -100, "ts": 1756428205.53451, "side": "sell"}
{"type": "orderbook_delta", "seq": 1695, "price": 49, "quantity": -100, "ts": 1756428205.580789, "side": "sell"}
{"type": "orderbook_delta", "seq": 1696, "price": 48, "quantity": 100, "ts": 1756428205.580789, "side": "sell"}
{"type": "orderbook_delta", "seq": 1697, "price": 48, "quantity": 250, "ts": 1756428206.132757, "side": "sell"}
{"type": "orderbook_delta", "seq": 1698, "price": 58, "quantity": -250, "ts": 1756428206.134334, "side": "sell"}
{"type": "orderbook_delta", "seq": 1699, "price": 48, "quantity": -100, "ts": 1756428207.484861, "side": "sell"}
{"type": "orderbook_delta", "seq": 1700, "price": 51, "quantity": 100, "ts": 1756428207.484861, "side": "sell"}
{"type": "orderbook_delta", "seq": 1701, "price": 35, "quantity": -1250, "ts": 1756428207.514698, "side": "buy"}
{"type": "orderbook_delta", "seq": 1702, "price": 39, "quantity": -500, "ts": 1756428207.538018, "side": "buy"}
{"type": "orderbook_delta", "seq": 1703, "price": 36, "quantity": 1250, "ts": 1756428207.582047, "side": "buy"}
{"type": "orderbook_delta", "seq": 1704, "price": 40, "quantity": 500, "ts": 1756428207.583116, "side": "buy"}
{"type": "orderbook_delta", "seq": 1705, "price": 47, "quantity": 0, "ts": 1756428207.601905, "side": "buy"}
{"type": "trade", "seq": 21, "price": 47, "quantity": 18, "ts": 1756428207.66131, "side": "sell"}
{"type": "orderbook_delta", "seq": 1706, "price": 36, "quantity": -1250, "ts": 1756428207.66131, "side": "buy"}
{"type": "orderbook_delta", "seq": 1707, "price": 35, "quantity": 1250, "ts": 1756428207.696224, "side": "buy"}
{"type": "orderbook_delta", "seq": 1708, "price": 37, "quantity": -200, "ts": 1756428207.909483, "side": "buy"}
{"type": "orderbook_delta", "seq": 1709, "price": 50, "quantity": -1250, "ts": 1756428207.911983, "side": "sell"}
{"type": "orderbook_delta", "seq": 1710, "price": 35, "quantity": -1250, "ts": 1756428207.914117, "side": "buy"}
{"type": "orderbook_delta", "seq": 1711, "price": 48, "quantity": -200, "ts": 1756428207.957727, "side": "sell"}
{"type": "orderbook_delta", "seq": 1712, "price": 51, "quantity": 1250, "ts": 1756428208.026078, "side": "sell"}
{"type": "orderbook_delta", "seq": 1713, "price": 49, "quantity": 200, "ts": 1756428208.026659, "side": "sell"}
{"type": "orderbook_delta", "seq": 1714, "price": 38, "quantity": 200, "ts": 1756428208.027676, "side": "buy"}
{"type": "orderbook_delta", "seq": 1715, "price": 36, "quantity": 1250, "ts": 1756428208.028406, "side": "buy"}
{"type": "orderbook_delta", "seq": 1716, "price": 42, "quantity": 250, "ts": 1756428208.13766, "side": "buy"}
{"type": "orderbook_delta", "seq": 1717, "price": 32, "quantity": -250, "ts": 1756428208.139333, "side": "buy"}
{"type": "orderbook_delta", "seq": 1718, "price": 58, "quantity": 250, "ts": 1756428208.166749, "side": "sell"}
{"type": "orderbook_delta", "seq": 1719, "price": 48, "quantity": -250, "ts": 1756428208.167054, "side": "sell"}
{"type": "orderbook_delta", "seq": 1720, "price": 41, "quantity": -100, "ts": 1756428208.954822, "side": "buy"}
{"type": "orderbook_delta", "seq": 1721, "price": 43, "quantity": 100, "ts": 1756428208.954822, "side": "buy"}
{"type": "trade", "seq": 22, "price": 47, "quantity": 57, "ts": 1756428210.0, "side": "sell"}
{"type": "orderbook_delta", "seq": 1722, "price": 47, "quantity": 0, "ts": 1756428210.305083, "side": "buy"}
{"type": "orderbook_delta", "seq": 1723, "price": 47, "quantity": 100, "ts": 1756428210.312386, "side": "sell"}
{"type": "orderbook_delta", "seq": 1724, "price": 48, "quantity": -500, "ts": 1756428210.345074, "side": "sell"}
{"type": "orderbook_delta", "seq": 1725, "price": 46, "quantity": 500, "ts": 1756428210.378712, "side": "sell"}
{"type": "orderbook_delta", "seq": 1726, "price": 48, "quantity": -67, "ts": 1756428211.100409, "side": "sell"}
{"type": "orderbook_delta", "seq": 1727, "price": 47, "quantity": 67, "ts": 1756428211.152801, "side": "sell"}
{"type": "orderbook_delta", "seq": 1728, "price": 46, "quantity": -500, "ts": 1756428211.21978, "side": "sell"}
{"type": "orderbook_delta", "seq": 1729, "price": 40, "quantity": -500, "ts": 1756428211.219858, "side": "buy"}
{"type": "orderbook_delta", "seq": 1730, "price": 49, "quantity": -200, "ts": 1756428211.219912, "side": "sell"}
{"type": "orderbook_delta", "seq": 1731, "price": 36, "quantity": -1250, "ts": 1756428211.221239, "side": "buy"}
{"type": "orderbook_delta", "seq": 1732, "price": 38, "quantity": -200, "ts": 1756428211.221749, "side": "buy"}
{"type": "orderbook_delta", "seq": 1733, "price": 51, "quantity": -1250, "ts": 1756428211.231566, "side": "sell"}
{"type": "orderbook_delta", "seq": 1734, "price": 32, "quantity": 250, "ts": 1756428211.260119, "side": "buy"}
{"type": "orderbook_delta", "seq": 1735, "price": 42, "quantity": -250, "ts": 1756428211.260369, "side": "buy"}
{"type": "orderbook_delta", "seq": 1736, "price": 48, "quantity": -200, "ts": 1756428211.26718, "side": "sell"}
{"type": "orderbook_delta", "seq": 1737, "price": 49, "quantity": 200, "ts": 1756428211.26718, "side": "sell"}
{"type": "orderbook_delta", "seq": 1738, "price": 39, "quantity": 200, "ts": 1756428211.270654, "side": "buy"}
{"type": "orderbook_delta", "seq": 1739, "price": 50, "quantity": 200, "ts": 1756428211.271471, "side": "sell"}
{"type": "orderbook_delta", "seq": 1740, "price": 47, "quantity": 500, "ts": 1756428211.273389, "side": "sell"}
{"type": "orderbook_delta", "seq": 1741, "price": 52, "quantity": 1250, "ts": 1756428211.274767, "side": "sell"}
{"type": "orderbook_delta", "seq": 1742, "price": 41, "quantity": 500, "ts": 1756428211.281833, "side": "buy"}
{"type": "orderbook_delta", "seq": 1743, "price": 37, "quantity": 1250, "ts": 1756428211.292229, "side": "buy"}
{"type": "orderbook_delta", "seq": 1744, "price": 43, "quantity": -100, "ts": 1756428211.315627, "side": "buy"}
{"type": "orderbook_delta", "seq": 1745, "price": 41, "quantity": 100, "ts": 1756428211.315627, "side": "buy"}
{"type": "orderbook_delta", "seq": 1746, "price": 32, "quantity": -250, "ts": 1756428211.360327, "side": "buy"}
{"type": "orderbook_delta", "seq": 1747, "price": 42, "quantity": 250, "ts": 1756428211.361051, "side": "buy"}
{"type": "orderbook_delta", "seq": 1748, "price": 51, "quantity": -100, "ts": 1756428211.416552, "side": "sell"}
{"type": "orderbook_delta", "seq": 1749, "price": 52, "quantity": 100, "ts": 1756428211.416552, "side": "sell"}
{"type": "orderbook_delta", "seq": 1750, "price": 52, "quantity": -100, "ts": 1756428211.756697, "side": "sell"}
{"type": "orderbook_delta", "seq": 1751, "price": 53, "quantity": 100, "ts": 1756428211.756697, "side": "sell"}
{"type": "orderbook_delta", "seq": 1752, "price": 47, "quantity": -67, "ts": 1756428211.988238, "side": "sell"}
{"type": "orderbook_delta", "seq": 1753, "price": 39, "quantity": -200, "ts": 1756428211.988375, "side": "buy"}
{"type": "orderbook_delta", "seq": 1754, "price": 47, "quantity": -500, "ts": 1756428211.988499, "side": "sell"}
{"type": "orderbook_delta", "seq": 1755, "price": 41, "quantity": -500, "ts": 1756428211.989527, "side": "buy"}
{"type": "orderbook_delta", "seq": 1756, "price": 37, "quantity": -1250, "ts": 1756428211.989599, "side": "buy"}
{"type": "orderbook_delta", "seq": 1757, "price": 52, "quantity": -1250, "ts": 1756428211.990481, "side": "sell"}
{"type": "orderbook_delta", "seq": 1758, "price": 50, "quantity": -200, "ts": 1756428212.004332, "side": "sell"}
{"type": "orderbook_delta", "seq": 1759, "price": 48, "quantity": 67, "ts": 1756428212.033075, "side": "sell"}
{"type": "orderbook_delta", "seq": 1760, "price": 49, "quantity": -200, "ts": 1756428212.035112, "side": "sell"}
{"type": "orderbook_delta", "seq": 1761, "price": 51, "quantity": 200, "ts": 1756428212.035112, "side": "sell"}
{"type": "orderbook_delta", "seq": 1762, "price": 42, "quantity": 500, "ts": 1756428212.047206, "side": "buy"}
{"type": "orderbook_delta", "seq": 1763, "price": 53, "quantity": 1250, "ts": 1756428212.047752, "side": "sell"}
{"type": "orderbook_delta", "seq": 1764, "price": 40, "quantity": 200, "ts": 1756428212.048134, "side": "buy"}
{"type": "orderbook_delta", "seq": 1765, "price": 48, "quantity": 500, "ts": 1756428212.048425, "side": "sell"}
{"type": "orderbook_delta", "seq": 1766, "price": 51, "quantity": 200, "ts": 1756428212.048752, "side": "sell"}
{"type": "orderbook_delta", "seq": 1767, "price": 38, "quantity": 1250, "ts": 1756428212.05001, "side": "buy"}
{"type": "orderbook_delta", "seq": 1768, "price": 43, "quantity": 100, "ts": 1756428212.071744, "side": "buy"}
{"type": "orderbook_delta", "seq": 1769, "price": 41, "quantity": -100, "ts": 1756428212.074285, "side": "buy"}
{"type": "orderbook_delta", "seq": 1770, "price": 43, "quantity": 100, "ts": 1756428212.074285, "side": "buy"}
{"type": "orderbook_delta", "seq": 1771, "price": 48, "quantity": -67, "ts": 1756428212.122158, "side": "sell"}
{"type": "orderbook_delta", "seq": 1772, "price": 53, "quantity": -100, "ts": 1756428212.122177, "side": "sell"}
{"type": "orderbook_delta", "seq": 1773, "price": 54, "quantity": 100, "ts": 1756428212.122177, "side": "sell"}
{"type": "orderbook_delta", "seq": 1774, "price": 44, "quantity": 250, "ts": 1756428212.135748, "side": "buy"}
{"type": "orderbook_delta", "seq": 1775, "price": 60, "quantity": 250, "ts": 1756428212.1561, "side": "sell"}
{"type": "orderbook_delta", "seq": 1776, "price": 48, "quantity": -500, "ts": 1756428212.177757, "side": "sell"}
{"type": "orderbook_delta", "seq": 1777, "price": 42, "quantity": -500, "ts": 1756428212.178791, "side": "buy"}
{"type": "orderbook_delta", "seq": 1778, "price": 49, "quantity": 500, "ts": 1756428212.220585, "side": "sell"}
{"type": "orderbook_delta", "seq": 1779, "price": 43, "quantity": 500, "ts": 1756428212.220868, "side": "buy"}
