{"type": "orderbook_delta", "seq": 7092, "price": 46, "quantity": -500, "ts": 1756428508.031793, "side": "sell"}
{"type": "orderbook_delta", "seq": 7093, "price": 40, "quantity": -500, "ts": 1756428508.031845, "side": "buy"}
{"type": "orderbook_delta", "seq": 7094, "price": 48, "quantity": -250, "ts": 1756428508.050023, "side": "sell"}
{"type": "orderbook_delta", "seq": 7095, "price": 50, "quantity": -100, "ts": 1756428508.084057, "side": "sell"}
{"type": "orderbook_delta", "seq": 7096, "price": 51, "quantity": 100, "ts": 1756428508.084057, "side": "sell"}
{"type": "orderbook_delta", "seq": 7097, "price": 38, "quantity": 1250, "ts": 1756428508.085881, "side": "buy"}
{"type": "orderbook_delta", "seq": 7098, "price": 39, "quantity": 200, "ts": 1756428508.086124, "side": "buy"}
{"type": "orderbook_delta", "seq": 7099, "price": 48, "quantity": 500, "ts": 1756428508.087178, "side": "sell"}
{"type": "orderbook_delta", "seq": 7100, "price": 53, "quantity": 1250, "ts": 1756428508.087629, "side": "sell"}
{"type": "orderbook_delta", "seq": 7101, "price": 51, "quantity": 200, "ts": 1756428508.088341, "side": "sell"}
{"type": "orderbook_delta", "seq": 7102, "price": 28, "quantity": 250, "ts": 1756428508.088834, "side": "buy"}
{"type": "orderbook_delta", "seq": 7103, "price": 38, "quantity": -250, "ts": 1756428508.094156, "side": "buy"}
{"type": "orderbook_delta", "seq": 7104, "price": 41, "quantity": 500, "ts": 1756428508.127185, "side": "buy"}
{"type": "orderbook_delta", "seq": 7105, "price": 28, "quantity": -250, "ts": 1756428508.128586, "side": "buy"}
{"type": "orderbook_delta", "seq": 7106, "price": 47, "quantity": 969, "ts": 1756428508.129582, "side": "sell"}
{"type": "orderbook_delta", "seq": 7107, "price": 49, "quantity": -200, "ts": 1756428508.163216, "side": "sell"}
{"type": "orderbook_delta", "seq": 7108, "price": 48, "quantity": 200, "ts": 1756428508.163216, "side": "sell"}
{"type": "orderbook_delta", "seq": 7109, "price": 40, "quantity": 250, "ts": 1756428508.169158, "side": "buy"}
{"type": "orderbook_delta", "seq": 7110, "price": 38, "quantity": 250, "ts": 1756428508.186046, "side": "buy"}
{"type": "orderbook_delta", "seq": 7111, "price": 39, "quantity": -200, "ts": 1756428508.190784, "side": "buy"}
{"type": "orderbook_delta", "seq": 7112, "price": 38, "quantity": -1250, "ts": 1756428508.192781, "side": "buy"}
{"type": "orderbook_delta", "seq": 7113, "price": 30, "quantity": -250, "ts": 1756428508.245646, "side": "buy"}
{"type": "orderbook_delta", "seq": 7114, "price": 37, "quantity": 1250, "ts": 1756428508.246576, "side": "buy"}
{"type": "orderbook_delta", "seq": 7115, "price": 37, "quantity": 200, "ts": 1756428508.24837, "side": "buy"}
{"type": "orderbook_delta", "seq": 7116, "price": 37, "quantity": -200, "ts": 1756428508.289924, "side": "buy"}
{"type": "orderbook_delta", "seq": 7117, "price": 37, "quantity": -1250, "ts": 1756428508.293539, "side": "buy"}
{"type": "orderbook_delta", "seq": 7118, "price": 40, "quantity": 200, "ts": 1756428508.321699, "side": "buy"}
{"type": "orderbook_delta", "seq": 7119, "price": 38, "quantity": 1250, "ts": 1756428508.323038, "side": "buy"}
{"type": "orderbook_delta", "seq": 7120, "price": 53, "quantity": -1250, "ts": 1756428508.508315, "side": "sell"}
{"type": "orderbook_delta", "seq": 7121, "price": 38, "quantity": -1250, "ts": 1756428508.508373, "side": "buy"}
{"type": "orderbook_delta", "seq": 7122, "price": 40, "quantity": -200, "ts": 1756428508.509404, "side": "buy"}
{"type": "orderbook_delta", "seq": 7123, "price": 48, "quantity": -500, "ts": 1756428508.509711, "side": "sell"}
{"type": "orderbook_delta", "seq": 7124, "price": 51, "quantity": -200, "ts": 1756428508.510878, "side": "sell"}
{"type": "orderbook_delta", "seq": 7125, "price": 48, "quantity": -200, "ts": 1756428508.53924, "side": "sell"}
{"type": "orderbook_delta", "seq": 7126, "price": 46, "quantity": 200, "ts": 1756428508.53924, "side": "sell"}
{"type": "orderbook_delta", "seq": 7127, "price": 51, "quantity": 1250, "ts": 1756428508.553524, "side": "sell"}
{"type": "orderbook_delta", "seq": 7128, "price": 47, "quantity": 500, "ts": 1756428508.556343, "side": "sell"}
{"type": "orderbook_delta", "seq": 7129, "price": 38, "quantity": 200, "ts": 1756428508.556641, "side": "buy"}
{"type": "orderbook_delta", "seq": 7130, "price": 49, "quantity": 200, "ts": 1756428508.557104, "side": "sell"}
{"type": "orderbook_delta", "seq": 7131, "price": 37, "quantity": 1250, "ts": 1756428508.557916, "side": "buy"}
{"type": "orderbook_delta", "seq": 7132, "price": 39, "quantity": -100, "ts": 1756428508.609595, "side": "buy"}
{"type": "orderbook_delta", "seq": 7133, "price": 42, "quantity": 100, "ts": 1756428508.609595, "side": "buy"}
{"type": "orderbook_delta", "seq": 7134, "price": 47, "quantity": -500, "ts": 1756428508.677014, "side": "sell"}
{"type": "orderbook_delta", "seq": 7135, "price": 41, "quantity": -500, "ts": 1756428508.678816, "side": "buy"}
{"type": "orderbook_delta", "seq": 7136, "price": 51, "quantity": -1250, "ts": 1756428508.678927, "side": "sell"}
{"type": "orderbook_delta", "seq": 7137, "price": 37, "quantity": -1250, "ts": 1756428508.679922, "side": "buy"}
{"type": "orderbook_delta", "seq": 7138, "price": 38, "quantity": -200, "ts": 1756428508.68235, "side": "buy"}
{"type": "orderbook_delta", "seq": 7139, "price": 46, "quantity": 500, "ts": 1756428508.719116, "side": "sell"}
{"type": "orderbook_delta", "seq": 7140, "price": 50, "quantity": 1250, "ts": 1756428508.721165, "side": "sell"}
{"type": "orderbook_delta", "seq": 7141, "price": 36, "quantity": 1250, "ts": 1756428508.721719, "side": "buy"}
{"type": "orderbook_delta", "seq": 7142, "price": 40, "quantity": 500, "ts": 1756428508.730513, "side": "buy"}
{"type": "orderbook_delta", "seq": 7143, "price": 42, "quantity": -100, "ts": 1756428508.730825, "side": "buy"}
{"type": "orderbook_delta", "seq": 7144, "price": 41, "quantity": 100, "ts": 1756428508.730825, "side": "buy"}
{"type": "orderbook_delta", "seq": 7145, "price": 37, "quantity": 200, "ts": 1756428508.748031, "side": "buy"}
{"type": "orderbook_delta", "seq": 7146, "price": 30, "quantity": 250, "ts": 1756428508.848755, "side": "buy"}
{"type": "orderbook_delta", "seq": 7147, "price": 40, "quantity": -250, "ts": 1756428508.848985, "side": "buy"}
{"type": "orderbook_delta", "seq": 7148, "price": 50, "quantity": -1250, "ts": 1756428508.861746, "side": "sell"}
{"type": "orderbook_delta", "seq": 7149, "price": 37, "quantity": -200, "ts": 1756428508.86243, "side": "buy"}
{"type": "orderbook_delta", "seq": 7150, "price": 38, "quantity": 200, "ts": 1756428508.907807, "side": "buy"}
{"type": "orderbook_delta", "seq": 7151, "price": 51, "quantity": 1250, "ts": 1756428508.908848, "side": "sell"}
{"type": "orderbook_delta", "seq": 7152, "price": 38, "quantity": -200, "ts": 1756428508.960121, "side": "buy"}
{"type": "orderbook_delta", "seq": 7153, "price": 51, "quantity": -1250, "ts": 1756428508.963506, "side": "sell"}
{"type": "orderbook_delta", "seq": 7154, "price": 37, "quantity": 200, "ts": 1756428508.991437, "side": "buy"}
{"type": "orderbook_delta", "seq": 7155, "price": 50, "quantity": 1250, "ts": 1756428508.99541, "side": "sell"}
{"type": "orderbook_delta", "seq": 7156, "price": 40, "quantity": 250, "ts": 1756428509.106656, "side": "buy"}
{"type": "orderbook_delta", "seq": 7157, "price": 30, "quantity": -250, "ts": 1756428509.107154, "side": "buy"}
{"type": "orderbook_delta", "seq": 7158, "price": 48, "quantity": 250, "ts": 1756428509.125794, "side": "sell"}
{"type": "orderbook_delta", "seq": 7159, "price": 58, "quantity": -250, "ts": 1756428509.126033, "side": "sell"}
{"type": "orderbook_delta", "seq": 7160, "price": 37, "quantity": -200, "ts": 1756428509.14484, "side": "buy"}
{"type": "orderbook_delta", "seq": 7161, "price": 38, "quantity": 200, "ts": 1756428509.189886, "side": "buy"}
{"type": "orderbook_delta", "seq": 7162, "price": 40, "quantity": -500, "ts": 1756428509.47167, "side": "buy"}
{"type": "orderbook_delta", "seq": 7163, "price": 46, "quantity": -500, "ts": 1756428509.473501, "side": "sell"}
{"type": "orderbook_delta", "seq": 7164, "price": 49, "quantity": -200, "ts": 1756428509.487885, "side": "sell"}
{"type": "orderbook_delta", "seq": 7165, "price": 48, "quantity": -250, "ts": 1756428509.488407, "side": "sell"}
{"type": "orderbook_delta", "seq": 7166, "price": 36, "quantity": -1250, "ts": 1756428509.489331, "side": "buy"}
{"type": "orderbook_delta", "seq": 7167, "price": 38, "quantity": -200, "ts": 1756428509.489902, "side": "buy"}
{"type": "orderbook_delta", "seq": 7168, "price": 58, "quantity": 250, "ts": 1756428509.490558, "side": "sell"}
{"type": "orderbook_delta", "seq": 7169, "price": 50, "quantity": -1250, "ts": 1756428509.521527, "side": "sell"}
{"type": "orderbook_delta", "seq": 7170, "price": 37, "quantity": 1250, "ts": 1756428509.521553, "side": "buy"}
{"type": "orderbook_delta", "seq": 7171, "price": 51, "quantity": -100, "ts": 1756428509.522574, "side": "sell"}
{"type": "orderbook_delta", "seq": 7172, "price": 48, "quantity": 100, "ts": 1756428509.522574, "side": "sell"}
{"type": "orderbook_delta", "seq": 7173, "price": 39, "quantity": 200, "ts": 1756428509.52445, "side": "buy"}
{"type": "orderbook_delta", "seq": 7174, "price": 52, "quantity": 1250, "ts": 1756428509.555079, "side": "sell"}
{"type": "orderbook_delta", "seq": 7175, "price": 41, "quantity": 500, "ts": 1756428509.555917, "side": "buy"}
{"type": "orderbook_delta", "seq": 7176, "price": 47, "quantity": 500, "ts": 1756428509.560371, "side": "sell"}
{"type": "orderbook_delta", "seq": 7177, "price": 48, "quantity": -100, "ts": 1756428509.571254, "side": "sell"}
{"type": "orderbook_delta", "seq": 7178, "price": 50, "quantity": 100, "ts": 1756428509.571254, "side": "sell"}
{"type": "orderbook_delta", "seq": 7179, "price": 50, "quantity": 200, "ts": 1756428509.573697, "side": "sell"}
{"type": "orderbook_delta", "seq": 7180, "price": 46, "quantity": -200, "ts": 1756428509.599225, "side": "sell"}
{"type": "orderbook_delta", "seq": 7181, "price": 48, "quantity": 200, "ts": 1756428509.599225, "side": "sell"}
{"type": "orderbook_delta", "seq": 7182, "price": 41, "quantity": -100, "ts": 1756428509.628339, "side": "buy"}
{"type": "orderbook_delta", "seq": 7183, "price": 42, "quantity": 100, "ts": 1756428509.628339, "side": "buy"}
{"type": "orderbook_delta", "seq": 7184, "price": 42, "quantity": 0, "ts": 1756428509.717457, "side": "buy"}
{"type": "trade", "seq": 67, "price": 42, "quantity": 9, "ts": 1756428510.370595, "side": "sell"}
{"type": "orderbook_delta", "seq": 7185, "price": 52, "quantity": -1250, "ts": 1756428510.370595, "side": "sell"}
{"type": "orderbook_delta", "seq": 7186, "price": 50, "quantity": -200, "ts": 1756428510.374562, "side": "sell"}
{"type": "orderbook_delta", "seq": 7187, "price": 39, "quantity": -200, "ts": 1756428510.375094, "side": "buy"}
{"type": "orderbook_delta", "seq": 7188, "price": 49, "quantity": 200, "ts": 1756428510.419793, "side": "sell"}
{"type": "orderbook_delta", "seq": 7189, "price": 38, "quantity": 200, "ts": 1756428510.420827, "side": "buy"}
{"type": "orderbook_delta", "seq": 7190, "price": 51, "quantity": 1250, "ts": 1756428510.439173, "side": "sell"}
{"type": "orderbook_delta", "seq": 7191, "price": 43, "quantity": -100, "ts": 1756428510.70023, "side": "sell"}
{"type": "orderbook_delta", "seq": 7192, "price": 37, "quantity": -1250, "ts": 1756428510.836942, "side": "buy"}
{"type": "orderbook_delta", "seq": 7193, "price": 47, "quantity": -500, "ts": 1756428510.837815, "side": "sell"}
{"type": "orderbook_delta", "seq": 7194, "price": 41, "quantity": -500, "ts": 1756428510.838003, "side": "buy"}
{"type": "orderbook_delta", "seq": 7195, "price": 51, "quantity": -1250, "ts": 1756428510.86071, "side": "sell"}
{"type": "orderbook_delta", "seq": 7196, "price": 38, "quantity": -200, "ts": 1756428510.861036, "side": "buy"}
{"type": "orderbook_delta", "seq": 7197, "price": 49, "quantity": -200, "ts": 1756428510.862575, "side": "sell"}
{"type": "orderbook_delta", "seq": 7198, "price": 48, "quantity": -200, "ts": 1756428510.894569, "side": "sell"}
{"type": "orderbook_delta", "seq": 7199, "price": 46, "quantity": 200, "ts": 1756428510.894569, "side": "sell"}
{"type": "orderbook_delta", "seq": 7200, "price": 39, "quantity": 500, "ts": 1756428510.895403, "side": "buy"}
{"type": "orderbook_delta", "seq": 7201, "price": 35, "quantity": 1250, "ts": 1756428510.896618, "side": "buy"}
{"type": "orderbook_delta", "seq": 7202, "price": 48, "quantity": 200, "ts": 1756428510.908138, "side": "sell"}
{"type": "orderbook_delta", "seq": 7203, "price": 37, "quantity": 200, "ts": 1756428510.913125, "side": "buy"}
{"type": "orderbook_delta", "seq": 7204, "price": 48, "quantity": -200, "ts": 1756428510.956918, "side": "sell"}
{"type": "orderbook_delta", "seq": 7205, "price": 50, "quantity": 1250, "ts": 1756428510.963237, "side": "sell"}
{"type": "orderbook_delta", "seq": 7206, "price": 46, "quantity": 500, "ts": 1756428510.966598, "side": "sell"}
{"type": "orderbook_delta", "seq": 7207, "price": 49, "quantity": 200, "ts": 1756428510.995848, "side": "sell"}
{"type": "orderbook_delta", "seq": 7208, "price": 46, "quantity": -500, "ts": 1756428511.008971, "side": "sell"}
{"type": "orderbook_delta", "seq": 7209, "price": 50, "quantity": -100, "ts": 1756428511.013524, "side": "sell"}
{"type": "orderbook_delta", "seq": 7210, "price": 48, "quantity": 100, "ts": 1756428511.013524, "side": "sell"}
{"type": "orderbook_delta", "seq": 7211, "price": 45, "quantity": 500, "ts": 1756428511.056058, "side": "sell"}
{"type": "orderbook_delta", "seq": 7212, "price": 42, "quantity": -91, "ts": 1756428511.083568, "side": "buy"}
{"type": "orderbook_delta", "seq": 7213, "price": 40, "quantity": 91, "ts": 1756428511.083568, "side": "buy"}
{"type": "orderbook_delta", "seq": 7214, "price": 40, "quantity": -100, "ts": 1756428511.178165, "side": "buy"}
{"type": "orderbook_delta", "seq": 7215, "price": 40, "quantity": -91, "ts": 1756428511.527022, "side": "buy"}
{"type": "orderbook_delta", "seq": 7216, "price": 39, "quantity": 91, "ts": 1756428511.527022, "side": "buy"}
{"type": "orderbook_delta", "seq": 7217, "price": 42, "quantity": 100, "ts": 1756428511.653965, "side": "sell"}
{"type": "orderbook_delta", "seq": 7218, "price": 39, "quantity": -91, "ts": 1756428511.755764, "side": "buy"}
{"type": "orderbook_delta", "seq": 7219, "price": 38, "quantity": 91, "ts": 1756428511.755764, "side": "buy"}
{"type": "orderbook_delta", "seq": 7220, "price": 39, "quantity": -500, "ts": 1756428511.767344, "side": "buy"}
{"type": "orderbook_delta", "seq": 7221, "price": 40, "quantity": 500, "ts": 1756428511.806175, "side": "buy"}
{"type": "orderbook_delta", "seq": 7222, "price": 47, "quantity": -969, "ts": 1756428512.116239, "side": "sell"}
{"type": "orderbook_delta", "seq": 7223, "price": 40, "quantity": -250, "ts": 1756428512.135726, "side": "buy"}
{"type": "orderbook_delta", "seq": 7224, "price": 30, "quantity": 250, "ts": 1756428512.136259, "side": "buy"}
{"type": "orderbook_delta", "seq": 7225, "price": 58, "quantity": -250, "ts": 1756428512.146491, "side": "sell"}
{"type": "orderbook_delta", "seq": 7226, "price": 40, "quantity": -500, "ts": 1756428512.166063, "side": "buy"}
{"type": "orderbook_delta", "seq": 7227, "price": 48, "quantity": 250, "ts": 1756428512.175511, "side": "sell"}
{"type": "orderbook_delta", "seq": 7228, "price": 49, "quantity": -200, "ts": 1756428512.211113, "side": "sell"}
{"type": "orderbook_delta", "seq": 7229, "price": 39, "quantity": 500, "ts": 1756428512.211149, "side": "buy"}
{"type": "orderbook_delta", "seq": 7230, "price": 48, "quantity": 200, "ts": 1756428512.256423, "side": "sell"}
{"type": "orderbook_delta", "seq": 7231, "price": 45, "quantity": 969, "ts": 1756428512.26479, "side": "sell"}
{"type": "orderbook_delta", "seq": 7232, "price": 48, "quantity": -100, "ts": 1756428512.513668, "side": "sell"}
{"type": "orderbook_delta", "seq": 7233, "price": 44, "quantity": 100, "ts": 1756428512.513668, "side": "sell"}
{"type": "orderbook_delta", "seq": 7234, "price": 44, "quantity": -100, "ts": 1756428512.75208, "side": "sell"}
{"type": "orderbook_delta", "seq": 7235, "price": 43, "quantity": 100, "ts": 1756428512.75208, "side": "sell"}
{"type": "orderbook_delta", "seq": 7236, "price": 43, "quantity": -100, "ts": 1756428513.018268, "side": "sell"}
{"type": "orderbook_delta", "seq": 7237, "price": 44, "quantity": 100, "ts": 1756428513.018268, "side": "sell"}
{"type": "orderbook_delta", "seq": 7238, "price": 38, "quantity": -91, "ts": 1756428513.255951, "side": "buy"}
{"type": "orderbook_delta", "seq": 7239, "price": 39, "quantity": 91, "ts": 1756428513.255951, "side": "buy"}
{"type": "trade", "seq": 68, "price": 42, "quantity": 22, "ts": 1756428513.936229, "side": "buy"}
{"type": "orderbook_delta", "seq": 7240, "price": 42, "quantity": 0, "ts": 1756428513.936229, "side": "sell"}
{"type": "orderbook_delta", "seq": 7241, "price": 37, "quantity": -200, "ts": 1756428514.030992, "side": "buy"}
{"type": "orderbook_delta", "seq": 7242, "price": 38, "quantity": -250, "ts": 1756428514.031141, "side": "buy"}
{"type": "orderbook_delta", "seq": 7243, "price": 50, "quantity": -1250, "ts": 1756428514.031935, "side": "sell"}
{"type": "orderbook_delta", "seq": 7244, "price": 12, "quantity": -8000, "ts": 1756428514.031996, "side": "buy"}
{"type": "orderbook_delta", "seq": 7245, "price": 28, "quantity": 250, "ts": 1756428514.032354, "side": "buy"}
{"type": "orderbook_delta", "seq": 7246, "price": 48, "quantity": -200, "ts": 1756428514.03314, "side": "sell"}
{"type": "orderbook_delta", "seq": 7247, "price": 35, "quantity": -1250, "ts": 1756428514.033698, "side": "buy"}
{"type": "orderbook_delta", "seq": 7248, "price": 46, "quantity": -200, "ts": 1756428514.046381, "side": "sell"}
{"type": "orderbook_delta", "seq": 7249, "price": 45, "quantity": 200, "ts": 1756428514.046381, "side": "sell"}
{"type": "orderbook_delta", "seq": 7250, "price": 36, "quantity": 200, "ts": 1756428514.077358, "side": "buy"}
{"type": "orderbook_delta", "seq": 7251, "price": 47, "quantity": 200, "ts": 1756428514.078351, "side": "sell"}
{"type": "orderbook_delta", "seq": 7252, "price": 49, "quantity": 1250, "ts": 1756428514.080107, "side": "sell"}
{"type": "orderbook_delta", "seq": 7253, "price": 34, "quantity": 1250, "ts": 1756428514.080355, "side": "buy"}
{"type": "orderbook_delta", "seq": 7254, "price": 11, "quantity": 8000, "ts": 1756428514.081934, "side": "buy"}
{"type": "orderbook_delta", "seq": 7255, "price": 45, "quantity": -500, "ts": 1756428514.10301, "side": "sell"}
{"type": "orderbook_delta", "seq": 7256, "price": 39, "quantity": -500, "ts": 1756428514.103947, "side": "buy"}
{"type": "orderbook_delta", "seq": 7257, "price": 49, "quantity": -1250, "ts": 1756428514.115326, "side": "sell"}
{"type": "orderbook_delta", "seq": 7258, "price": 37, "quantity": 500, "ts": 1756428514.138292, "side": "buy"}
{"type": "orderbook_delta", "seq": 7259, "price": 44, "quantity": 500, "ts": 1756428514.141949, "side": "sell"}
{"type": "orderbook_delta", "seq": 7260, "price": 45, "quantity": -969, "ts": 1756428514.145755, "side": "sell"}
{"type": "orderbook_delta", "seq": 7261, "price": 39, "quantity": -91, "ts": 1756428514.156083, "side": "buy"}
{"type": "orderbook_delta", "seq": 7262, "price": 37, "quantity": 91, "ts": 1756428514.156083, "side": "buy"}
{"type": "orderbook_delta", "seq": 7263, "price": 46, "quantity": 250, "ts": 1756428514.156409, "side": "sell"}
{"type": "orderbook_delta", "seq": 7264, "price": 49, "quantity": 1250, "ts": 1756428514.169374, "side": "sell"}
{"type": "orderbook_delta", "seq": 7265, "price": 56, "quantity": -250, "ts": 1756428514.169942, "side": "sell"}
{"type": "orderbook_delta", "seq": 7266, "price": 37, "quantity": -500, "ts": 1756428514.189679, "side": "buy"}
{"type": "orderbook_delta", "seq": 7267, "price": 44, "quantity": -100, "ts": 1756428514.21091, "side": "sell"}
{"type": "orderbook_delta", "seq": 7268, "price": 45, "quantity": 100, "ts": 1756428514.21091, "side": "sell"}
{"type": "orderbook_delta", "seq": 7269, "price": 44, "quantity": 969, "ts": 1756428514.214587, "side": "sell"}
{"type": "orderbook_delta", "seq": 7270, "price": 38, "quantity": 500, "ts": 1756428514.223033, "side": "buy"}
{"type": "orderbook_delta", "seq": 7271, "price": 45, "quantity": -100, "ts": 1756428514.276358, "side": "sell"}
{"type": "orderbook_delta", "seq": 7272, "price": 47, "quantity": 100, "ts": 1756428514.276358, "side": "sell"}
{"type": "orderbook_delta", "seq": 7273, "price": 39, "quantity": 100, "ts": 1756428514.402371, "side": "buy"}
{"type": "orderbook_delta", "seq": 7274, "price": 38, "quantity": -500, "ts": 1756428514.585021, "side": "buy"}
{"type": "orderbook_delta", "seq": 7275, "price": 39, "quantity": 500, "ts": 1756428514.614676, "side": "buy"}
{"type": "orderbook_delta", "seq": 7276, "price": 37, "quantity": -91, "ts": 1756428515.121624, "side": "buy"}
{"type": "orderbook_delta", "seq": 7277, "price": 40, "quantity": 91, "ts": 1756428515.121624, "side": "buy"}
{"type": "orderbook_delta", "seq": 7278, "price": 38, "quantity": 250, "ts": 1756428515.13148, "side": "buy"}
{"type": "orderbook_delta", "seq": 7279, "price": 44, "quantity": -969, "ts": 1756428515.136869, "side": "sell"}
{"type": "orderbook_delta", "seq": 7280, "price": 56, "quantity": 250, "ts": 1756428515.146236, "side": "sell"}
{"type": "orderbook_delta", "seq": 7281, "price": 28, "quantity": -250, "ts": 1756428515.156833, "side": "buy"}
{"type": "orderbook_delta", "seq": 7282, "price": 46, "quantity": -250, "ts": 1756428515.195594, "side": "sell"}
{"type": "orderbook_delta", "seq": 7283, "price": 45, "quantity": 969, "ts": 1756428515.242241, "side": "sell"}
{"type": "orderbook_delta", "seq": 7284, "price": 44, "quantity": -500, "ts": 1756428516.045537, "side": "sell"}
{"type": "orderbook_delta", "seq": 7285, "price": 34, "quantity": -1250, "ts": 1756428516.048311, "side": "buy"}
{"type": "orderbook_delta", "seq": 7286, "price": 45, "quantity": 500, "ts": 1756428516.084863, "side": "sell"}
{"type": "orderbook_delta", "seq": 7287, "price": 35, "quantity": 1250, "ts": 1756428516.085159, "side": "buy"}
{"type": "orderbook_delta", "seq": 7288, "price": 45, "quantity": -969, "ts": 1756428516.11622, "side": "sell"}
{"type": "orderbook_delta", "seq": 7289, "price": 46, "quantity": 969, "ts": 1756428516.159271, "side": "sell"}
{"type": "orderbook_delta", "seq": 7290, "price": 47, "quantity": -100, "ts": 1756428516.241815, "side": "sell"}
{"type": "orderbook_delta", "seq": 7291, "price": 45, "quantity": 100, "ts": 1756428516.241815, "side": "sell"}
{"type": "orderbook_delta", "seq": 7292, "price": 42, "quantity": -78, "ts": 1756428516.502226, "side": "sell"}
{"type": "orderbook_delta", "seq": 7293, "price": 45, "quantity": -200, "ts": 1756428516.714161, "side": "sell"}
{"type": "orderbook_delta", "seq": 7294, "price": 46, "quantity": 200, "ts": 1756428516.714161, "side": "sell"}
{"type": "orderbook_delta", "seq": 7295, "price": 45, "quantity": -100, "ts": 1756428516.756239, "side": "sell"}
{"type": "orderbook_delta", "seq": 7296, "price": 41, "quantity": 100, "ts": 1756428516.782552, "side": "sell"}
{"type": "orderbook_delta", "seq": 7297, "price": 40, "quantity": -91, "ts": 1756428516.806024, "side": "buy"}
{"type": "orderbook_delta", "seq": 7298, "price": 38, "quantity": 91, "ts": 1756428516.806024, "side": "buy"}
{"type": "orderbook_delta", "seq": 7299, "price": 39, "quantity": -500, "ts": 1756428516.825335, "side": "buy"}
{"type": "orderbook_delta", "seq": 7300, "price": 45, "quantity": -500, "ts": 1756428516.82547, "side": "sell"}
{"type": "orderbook_delta", "seq": 7301, "price": 35, "quantity": -1250, "ts": 1756428516.826603, "side": "buy"}
{"type": "orderbook_delta", "seq": 7302, "price": 36, "quantity": -200, "ts": 1756428516.827349, "side": "buy"}
{"type": "orderbook_delta", "seq": 7303, "price": 47, "quantity": -200, "ts": 1756428516.827609, "side": "sell"}
{"type": "orderbook_delta", "seq": 7304, "price": 11, "quantity": -8000, "ts": 1756428516.828515, "side": "buy"}
{"type": "orderbook_delta", "seq": 7305, "price": 49, "quantity": -1250, "ts": 1756428516.844186, "side": "sell"}
{"type": "orderbook_delta", "seq": 7306, "price": 46, "quantity": -200, "ts": 1756428516.844648, "side": "sell"}
{"type": "orderbook_delta", "seq": 7307, "price": 47, "quantity": 200, "ts": 1756428516.844648, "side": "sell"}
{"type": "orderbook_delta", "seq": 7308, "price": 38, "quantity": 200, "ts": 1756428516.88059, "side": "buy"}
{"type": "orderbook_delta", "seq": 7309, "price": 51, "quantity": 1250, "ts": 1756428516.881364, "side": "sell"}
{"type": "orderbook_delta", "seq": 7310, "price": 49, "quantity": 200, "ts": 1756428516.882441, "side": "sell"}
{"type": "orderbook_delta", "seq": 7311, "price": 46, "quantity": 500, "ts": 1756428516.883282, "side": "sell"}
{"type": "orderbook_delta", "seq": 7312, "price": 12, "quantity": 8000, "ts": 1756428516.884257, "side": "buy"}
{"type": "orderbook_delta", "seq": 7313, "price": 47, "quantity": -200, "ts": 1756428516.892173, "side": "sell"}
{"type": "orderbook_delta", "seq": 7314, "price": 48, "quantity": 200, "ts": 1756428516.892173, "side": "sell"}
{"type": "orderbook_delta", "seq": 7315, "price": 40, "quantity": 500, "ts": 1756428516.958915, "side": "buy"}
{"type": "orderbook_delta", "seq": 7316, "price": 36, "quantity": 1250, "ts": 1756428516.959485, "side": "buy"}
{"type": "orderbook_delta", "seq": 7317, "price": 58, "quantity": 250, "ts": 1756428516.984191, "side": "sell"}
{"type": "orderbook_delta", "seq": 7318, "price": 46, "quantity": -969, "ts": 1756428516.985925, "side": "sell"}
{"type": "orderbook_delta", "seq": 7319, "price": 46, "quantity": -500, "ts": 1756428516.986546, "side": "sell"}
{"type": "orderbook_delta", "seq": 7320, "price": 51, "quantity": -1250, "ts": 1756428516.988614, "side": "sell"}
{"type": "orderbook_delta", "seq": 7321, "price": 49, "quantity": -200, "ts": 1756428516.989733, "side": "sell"}
{"type": "orderbook_delta", "seq": 7322, "price": 36, "quantity": -1250, "ts": 1756428517.006465, "side": "buy"}
{"type": "orderbook_delta", "seq": 7323, "price": 48, "quantity": -250, "ts": 1756428517.006511, "side": "sell"}
{"type": "orderbook_delta", "seq": 7324, "price": 47, "quantity": 969, "ts": 1756428517.050225, "side": "sell"}
{"type": "orderbook_delta", "seq": 7325, "price": 48, "quantity": -200, "ts": 1756428517.06032, "side": "sell"}
{"type": "orderbook_delta", "seq": 7326, "price": 50, "quantity": 200, "ts": 1756428517.06032, "side": "sell"}
{"type": "orderbook_delta", "seq": 7327, "price": 38, "quantity": 1250, "ts": 1756428517.061617, "side": "buy"}
{"type": "orderbook_delta", "seq": 7328, "price": 38, "quantity": -200, "ts": 1756428517.063235, "side": "buy"}
{"type": "orderbook_delta", "seq": 7329, "price": 30, "quantity": -250, "ts": 1756428517.106853, "side": "buy"}
{"type": "orderbook_delta", "seq": 7330, "price": 39, "quantity": 200, "ts": 1756428517.109575, "side": "buy"}
{"type": "orderbook_delta", "seq": 7331, "price": 51, "quantity": 200, "ts": 1756428517.110612, "side": "sell"}
{"type": "orderbook_delta", "seq": 7332, "price": 49, "quantity": 500, "ts": 1756428517.110898, "side": "sell"}
{"type": "orderbook_delta", "seq": 7333, "price": 50, "quantity": -200, "ts": 1756428517.11132, "side": "sell"}
{"type": "orderbook_delta", "seq": 7334, "price": 52, "quantity": 200, "ts": 1756428517.11132, "side": "sell"}
{"type": "orderbook_delta", "seq": 7335, "price": 53, "quantity": 1250, "ts": 1756428517.116402, "side": "sell"}
{"type": "orderbook_delta", "seq": 7336, "price": 40, "quantity": 250, "ts": 1756428517.116676, "side": "buy"}
{"type": "orderbook_delta", "seq": 7337, "price": 40, "quantity": 0, "ts": 1756428517.127896, "side": "buy"}
{"type": "trade", "seq": 69, "price": 40, "quantity": 1, "ts": 1756428517.198509, "side": "sell"}
{"type": "orderbook_delta", "seq": 7338, "price": 39, "quantity": -200, "ts": 1756428517.198509, "side": "buy"}
{"type": "orderbook_delta", "seq": 7339, "price": 40, "quantity": 200, "ts": 1756428517.249985, "side": "buy"}
{"type": "orderbook_delta", "seq": 7340, "price": 40, "quantity": -200, "ts": 1756428517.476939, "side": "buy"}
{"type": "orderbook_delta", "seq": 7341, "price": 51, "quantity": -200, "ts": 1756428517.477396, "side": "sell"}
{"type": "orderbook_delta", "seq": 7342, "price": 53, "quantity": -1250, "ts": 1756428517.477602, "side": "sell"}
{"type": "orderbook_delta", "seq": 7343, "price": 41, "quantity": -100, "ts": 1756428517.515985, "side": "sell"}
{"type": "orderbook_delta", "seq": 7344, "price": 47, "quantity": -969, "ts": 1756428517.555037, "side": "sell"}
{"type": "orderbook_delta", "seq": 7345, "price": 54, "quantity": 1250, "ts": 1756428517.56479, "side": "sell"}
{"type": "orderbook_delta", "seq": 7346, "price": 49, "quantity": -500, "ts": 1756428517.565546, "side": "sell"}
{"type": "orderbook_delta", "seq": 7347, "price": 38, "quantity": -1250, "ts": 1756428517.565683, "side": "buy"}
{"type": "orderbook_delta", "seq": 7348, "price": 40, "quantity": -499, "ts": 1756428517.565806, "side": "buy"}
{"type": "orderbook_delta", "seq": 7349, "price": 41, "quantity": 200, "ts": 1756428517.566537, "side": "buy"}
{"type": "orderbook_delta", "seq": 7350, "price": 52, "quantity": 200, "ts": 1756428517.566998, "side": "sell"}
{"type": "orderbook_delta", "seq": 7351, "price": 60, "quantity": 250, "ts": 1756428517.578086, "side": "sell"}
{"type": "orderbook_delta", "seq": 7352, "price": 50, "quantity": -250, "ts": 1756428517.578881, "side": "sell"}
{"type": "orderbook_delta", "seq": 7353, "price": 49, "quantity": 969, "ts": 1756428517.64516, "side": "sell"}
{"type": "orderbook_delta", "seq": 7354, "price": 40, "quantity": 1250, "ts": 1756428517.662473, "side": "buy"}
{"type": "orderbook_delta", "seq": 7355, "price": 51, "quantity": 500, "ts": 1756428517.667461, "side": "sell"}
{"type": "orderbook_delta", "seq": 7356, "price": 41, "quantity": 500, "ts": 1756428517.671706, "side": "buy"}
{"type": "orderbook_delta", "seq": 7357, "price": 39, "quantity": -100, "ts": 1756428517.943877, "side": "buy"}
{"type": "orderbook_delta", "seq": 7358, "price": 52, "quantity": -200, "ts": 1756428518.055951, "side": "sell"}
{"type": "orderbook_delta", "seq": 7359, "price": 50, "quantity": 200, "ts": 1756428518.055951, "side": "sell"}
{"type": "orderbook_delta", "seq": 7360, "price": 51, "quantity": -500, "ts": 1756428518.11881, "side": "sell"}
{"type": "orderbook_delta", "seq": 7361, "price": 49, "quantity": -969, "ts": 1756428518.120206, "side": "sell"}
{"type": "orderbook_delta", "seq": 7362, "price": 42, "quantity": 250, "ts": 1756428518.166186, "side": "buy"}
{"type": "orderbook_delta", "seq": 7363, "price": 40, "quantity": -1250, "ts": 1756428518.182999, "side": "buy"}
{"type": "orderbook_delta", "seq": 7364, "price": 50, "quantity": 500, "ts": 1756428518.194058, "side": "sell"}
{"type": "orderbook_delta", "seq": 7365, "price": 32, "quantity": -250, "ts": 1756428518.200057, "side": "buy"}
{"type": "orderbook_delta", "seq": 7366, "price": 41, "quantity": -500, "ts": 1756428518.225459, "side": "buy"}
{"type": "orderbook_delta", "seq": 7367, "price": 53, "quantity": 100, "ts": 1756428518.264106, "side": "sell"}
{"type": "orderbook_delta", "seq": 7368, "price": 39, "quantity": 1250, "ts": 1756428518.270614, "side": "buy"}
{"type": "orderbook_delta", "seq": 7369, "price": 50, "quantity": 969, "ts": 1756428518.271287, "side": "sell"}
{"type": "orderbook_delta", "seq": 7370, "price": 43, "quantity": 500, "ts": 1756428518.308063, "side": "buy"}
{"type": "orderbook_delta", "seq": 7371, "price": 38, "quantity": -91, "ts": 1756428518.366892, "side": "buy"}
{"type": "orderbook_delta", "seq": 7372, "price": 43, "quantity": 91, "ts": 1756428518.366892, "side": "buy"}
{"type": "orderbook_delta", "seq": 7373, "price": 43, "quantity": -500, "ts": 1756428518.407396, "side": "buy"}
{"type": "orderbook_delta", "seq": 7374, "price": 44, "quantity": 500, "ts": 1756428518.444058, "side": "buy"}
{"type": "orderbook_delta", "seq": 7375, "price": 42, "quantity": 100, "ts": 1756428518.484619, "side": "buy"}
{"type": "orderbook_delta", "seq": 7376, "price": 50, "quantity": -200, "ts": 1756428518.545668, "side": "sell"}
{"type": "orderbook_delta", "seq": 7377, "price": 49, "quantity": 200, "ts": 1756428518.545668, "side": "sell"}
{"type": "orderbook_delta", "seq": 7378, "price": 43, "quantity": -91, "ts": 1756428518.62199, "side": "buy"}
{"type": "orderbook_delta", "seq": 7379, "price": 44, "quantity": 91, "ts": 1756428518.62199, "side": "buy"}
{"type": "orderbook_delta", "seq": 7380, "price": 32, "quantity": 250, "ts": 1756428518.644289, "side": "buy"}
{"type": "orderbook_delta", "seq": 7381, "price": 42, "quantity": -250, "ts": 1756428518.644571, "side": "buy"}
{"type": "orderbook_delta", "seq": 7382, "price": 50, "quantity": -500, "ts": 1756428518.651689, "side": "sell"}
{"type": "orderbook_delta", "seq": 7383, "price": 39, "quantity": -1250, "ts": 1756428518.651819, "side": "buy"}
{"type": "orderbook_delta", "seq": 7384, "price": 44, "quantity": -500, "ts": 1756428518.652917, "side": "buy"}
{"type": "orderbook_delta", "seq": 7385, "price": 54, "quantity": -1250, "ts": 1756428518.653144, "side": "sell"}
{"type": "orderbook_delta", "seq": 7386, "price": 52, "quantity": -200, "ts": 1756428518.653825, "side": "sell"}
{"type": "orderbook_delta", "seq": 7387, "price": 41, "quantity": -200, "ts": 1756428518.665072, "side": "buy"}
{"type": "orderbook_delta", "seq": 7388, "price": 44, "quantity": -91, "ts": 1756428518.706483, "side": "buy"}
{"type": "orderbook_delta", "seq": 7389, "price": 42, "quantity": 91, "ts": 1756428518.706483, "side": "buy"}
{"type": "orderbook_delta", "seq": 7390, "price": 38, "quantity": 1250, "ts": 1756428518.713138, "side": "buy"}
{"type": "orderbook_delta", "seq": 7391, "price": 48, "quantity": 500, "ts": 1756428518.714972, "side": "sell"}
{"type": "orderbook_delta", "seq": 7392, "price": 40, "quantity": 200, "ts": 1756428518.716311, "side": "buy"}
{"type": "orderbook_delta", "seq": 7393, "price": 51, "quantity": 200, "ts": 1756428518.716641, "side": "sell"}
{"type": "orderbook_delta", "seq": 7394, "price": 42, "quantity": 500, "ts": 1756428518.717007, "side": "buy"}
{"type": "orderbook_delta", "seq": 7395, "price": 52, "quantity": 1250, "ts": 1756428518.717372, "side": "sell"}
{"type": "orderbook_delta", "seq": 7396, "price": 99, "quantity": 16200, "ts": 1756428518.864952, "side": "sell"}
{"type": "orderbook_delta", "seq": 7397, "price": 53, "quantity": -100, "ts": 1756428518.882267, "side": "sell"}
{"type": "orderbook_delta", "seq": 7398, "price": 49, "quantity": 100, "ts": 1756428518.882267, "side": "sell"}
{"type": "orderbook_delta", "seq": 7399, "price": 52, "quantity": -1250, "ts": 1756428518.912025, "side": "sell"}
{"type": "orderbook_delta", "seq": 7400, "price": 53, "quantity": 1250, "ts": 1756428518.959865, "side": "sell"}
{"type": "orderbook_delta", "seq": 7401, "price": 98, "quantity": 7000, "ts": 1756428518.982021, "side": "sell"}
{"type": "orderbook_delta", "seq": 7402, "price": 50, "quantity": -969, "ts": 1756428519.125831, "side": "sell"}
{"type": "orderbook_delta", "seq": 7403, "price": 60, "quantity": -250, "ts": 1756428519.16699, "side": "sell"}
{"type": "orderbook_delta", "seq": 7404, "price": 50, "quantity": 250, "ts": 1756428519.168258, "side": "sell"}
{"type": "orderbook_delta", "seq": 7405, "price": 48, "quantity": 969, "ts": 1756428519.210928, "side": "sell"}
{"type": "orderbook_delta", "seq": 7406, "price": 48, "quantity": 100, "ts": 1756428519.283348, "side": "sell"}
{"type": "orderbook_delta", "seq": 7407, "price": 42, "quantity": -91, "ts": 1756428519.458006, "side": "buy"}
{"type": "orderbook_delta", "seq": 7408, "price": 43, "quantity": 91, "ts": 1756428519.458006, "side": "buy"}
{"type": "orderbook_delta", "seq": 7409, "price": 48, "quantity": -500, "ts": 1756428519.807596, "side": "sell"}
{"type": "orderbook_delta", "seq": 7410, "price": 42, "quantity": -500, "ts": 1756428519.843052, "side": "buy"}
{"type": "orderbook_delta", "seq": 7411, "price": 43, "quantity": 500, "ts": 1756428519.874718, "side": "buy"}
{"type": "orderbook_delta", "seq": 7412, "price": 49, "quantity": 500, "ts": 1756428519.87565, "side": "sell"}
{"type": "orderbook_delta", "seq": 7413, "price": 43, "quantity": -91, "ts": 1756428519.918379, "side": "buy"}
{"type": "orderbook_delta", "seq": 7414, "price": 44, "quantity": 91, "ts": 1756428519.918379, "side": "buy"}
{"type": "orderbook_delta", "seq": 7415, "price": 53, "quantity": -1250, "ts": 1756428520.673341, "side": "sell"}
{"type": "orderbook_delta", "seq": 7416, "price": 40, "quantity": -200, "ts": 1756428520.675938, "side": "buy"}
{"type": "orderbook_delta", "seq": 7417, "price": 51, "quantity": -200, "ts": 1756428520.677213, "side": "sell"}
{"type": "orderbook_delta", "seq": 7418, "price": 38, "quantity": -1250, "ts": 1756428520.679774, "side": "buy"}
{"type": "orderbook_delta", "seq": 7419, "price": 49, "quantity": -200, "ts": 1756428520.701113, "side": "sell"}
{"type": "orderbook_delta", "seq": 7420, "price": 50, "quantity": 200, "ts": 1756428520.701113, "side": "sell"}
{"type": "orderbook_delta", "seq": 7421, "price": 39, "quantity": 1250, "ts": 1756428520.714214, "side": "buy"}
{"type": "orderbook_delta", "seq": 7422, "price": 54, "quantity": 1250, "ts": 1756428520.715982, "side": "sell"}
{"type": "orderbook_delta", "seq": 7423, "price": 41, "quantity": 200, "ts": 1756428520.718629, "side": "buy"}
{"type": "orderbook_delta", "seq": 7424, "price": 52, "quantity": 200, "ts": 1756428520.719286, "side": "sell"}
{"type": "orderbook_delta", "seq": 7425, "price": 48, "quantity": -969, "ts": 1756428521.122408, "side": "sell"}
{"type": "orderbook_delta", "seq": 7426, "price": 42, "quantity": 250, "ts": 1756428521.135416, "side": "buy"}
{"type": "orderbook_delta", "seq": 7427, "price": 32, "quantity": -250, "ts": 1756428521.136152, "side": "buy"}
{"type": "orderbook_delta", "seq": 7428, "price": 60, "quantity": 250, "ts": 1756428521.156382, "side": "sell"}
{"type": "orderbook_delta", "seq": 7429, "price": 50, "quantity": -250, "ts": 1756428521.176833, "side": "sell"}
{"type": "orderbook_delta", "seq": 7430, "price": 50, "quantity": -200, "ts": 1756428521.18279, "side": "sell"}
{"type": "orderbook_delta", "seq": 7431, "price": 49, "quantity": 200, "ts": 1756428521.18279, "side": "sell"}
{"type": "orderbook_delta", "seq": 7432, "price": 44, "quantity": -91, "ts": 1756428521.209902, "side": "buy"}
{"type": "orderbook_delta", "seq": 7433, "price": 42, "quantity": 91, "ts": 1756428521.209902, "side": "buy"}
{"type": "orderbook_delta", "seq": 7434, "price": 42, "quantity": -100, "ts": 1756428521.21851, "side": "buy"}
{"type": "orderbook_delta", "seq": 7435, "price": 49, "quantity": 969, "ts": 1756428521.225155, "side": "sell"}
{"type": "orderbook_delta", "seq": 7436, "price": 49, "quantity": -200, "ts": 1756428521.231489, "side": "sell"}
{"type": "orderbook_delta", "seq": 7437, "price": 50, "quantity": 200, "ts": 1756428521.231489, "side": "sell"}
{"type": "orderbook_delta", "seq": 7438, "price": 44, "quantity": 100, "ts": 1756428521.441429, "side": "buy"}
{"type": "orderbook_delta", "seq": 7439, "price": 32, "quantity": 250, "ts": 1756428521.783056, "side": "buy"}
{"type": "orderbook_delta", "seq": 7440, "price": 42, "quantity": -250, "ts": 1756428521.789736, "side": "buy"}
{"type": "orderbook_delta", "seq": 7441, "price": 54, "quantity": -1250, "ts": 1756428521.808817, "side": "sell"}
{"type": "orderbook_delta", "seq": 7442, "price": 39, "quantity": -1250, "ts": 1756428521.808889, "side": "buy"}
{"type": "orderbook_delta", "seq": 7443, "price": 43, "quantity": -500, "ts": 1756428521.809383, "side": "buy"}
{"type": "orderbook_delta", "seq": 7444, "price": 49, "quantity": -500, "ts": 1756428521.809965, "side": "sell"}
{"type": "orderbook_delta", "seq": 7445, "price": 52, "quantity": -200, "ts": 1756428521.810268, "side": "sell"}
{"type": "orderbook_delta", "seq": 7446, "price": 41, "quantity": -200, "ts": 1756428521.815971, "side": "buy"}
{"type": "orderbook_delta", "seq": 7447, "price": 50, "quantity": 200, "ts": 1756428521.853051, "side": "sell"}
{"type": "orderbook_delta", "seq": 7448, "price": 48, "quantity": 500, "ts": 1756428521.855404, "side": "sell"}
{"type": "orderbook_delta", "seq": 7449, "price": 42, "quantity": 500, "ts": 1756428521.855775, "side": "buy"}
{"type": "orderbook_delta", "seq": 7450, "price": 37, "quantity": 1250, "ts": 1756428521.856077, "side": "buy"}
{"type": "orderbook_delta", "seq": 7451, "price": 52, "quantity": 1250, "ts": 1756428521.85691, "side": "sell"}
{"type": "orderbook_delta", "seq": 7452, "price": 39, "quantity": 200, "ts": 1756428521.859455, "side": "buy"}
{"type": "orderbook_delta", "seq": 7453, "price": 42, "quantity": -91, "ts": 1756428521.8698, "side": "buy"}
{"type": "orderbook_delta", "seq": 7454, "price": 41, "quantity": 91, "ts": 1756428521.8698, "side": "buy"}
{"type": "orderbook_delta", "seq": 7455, "price": 49, "quantity": -969, "ts": 1756428522.102374, "side": "sell"}
{"type": "orderbook_delta", "seq": 7456, "price": 50, "quantity": 250, "ts": 1756428522.12606, "side": "sell"}
{"type": "orderbook_delta", "seq": 7457, "price": 60, "quantity": -250, "ts": 1756428522.156725, "side": "sell"}
{"type": "orderbook_delta", "seq": 7458, "price": 48, "quantity": 969, "ts": 1756428522.211877, "side": "sell"}
{"type": "orderbook_delta", "seq": 7459, "price": 41, "quantity": -91, "ts": 1756428522.61213, "side": "buy"}
{"type": "orderbook_delta", "seq": 7460, "price": 42, "quantity": 91, "ts": 1756428522.61213, "side": "buy"}
{"type": "orderbook_delta", "seq": 7461, "price": 42, "quantity": -91, "ts": 1756428522.860601, "side": "buy"}
{"type": "orderbook_delta", "seq": 7462, "price": 43, "quantity": 91, "ts": 1756428522.860601, "side": "buy"}
{"type": "orderbook_delta", "seq": 7463, "price": 42, "quantity": -500, "ts": 1756428522.891968, "side": "buy"}
{"type": "orderbook_delta", "seq": 7464, "price": 41, "quantity": 500, "ts": 1756428522.926736, "side": "buy"}
{"type": "orderbook_delta", "seq": 7465, "price": 48, "quantity": -100, "ts": 1756428523.146583, "side": "sell"}
{"type": "orderbook_delta", "seq": 7466, "price": 49, "quantity": -100, "ts": 1756428523.191081, "side": "sell"}
{"type": "orderbook_delta", "seq": 7467, "price": 50, "quantity": 100, "ts": 1756428523.191081, "side": "sell"}
{"type": "orderbook_delta", "seq": 7468, "price": 39, "quantity": -200, "ts": 1756428523.307231, "side": "buy"}
{"type": "orderbook_delta", "seq": 7469, "price": 48, "quantity": -500, "ts": 1756428523.309174, "side": "sell"}
{"type": "orderbook_delta", "seq": 7470, "price": 41, "quantity": -500, "ts": 1756428523.309416, "side": "buy"}
{"type": "orderbook_delta", "seq": 7471, "price": 37, "quantity": -1250, "ts": 1756428523.324108, "side": "buy"}
{"type": "orderbook_delta", "seq": 7472, "price": 52, "quantity": -1250, "ts": 1756428523.328058, "side": "sell"}
{"type": "orderbook_delta", "seq": 7473, "price": 50, "quantity": -200, "ts": 1756428523.328764, "side": "sell"}
{"type": "orderbook_delta", "seq": 7474, "price": 52, "quantity": 200, "ts": 1756428523.362753, "side": "sell"}
{"type": "orderbook_delta", "seq": 7475, "price": 41, "quantity": 200, "ts": 1756428523.363481, "side": "buy"}
{"type": "orderbook_delta", "seq": 7476, "price": 49, "quantity": 500, "ts": 1756428523.367909, "side": "sell"}
{"type": "orderbook_delta", "seq": 7477, "price": 39, "quantity": 1250, "ts": 1756428523.368197, "side": "buy"}
{"type": "orderbook_delta", "seq": 7478, "price": 47, "quantity": 100, "ts": 1756428523.368775, "side": "sell"}
{"type": "orderbook_delta", "seq": 7479, "price": 53, "quantity": 1250, "ts": 1756428523.371736, "side": "sell"}
{"type": "orderbook_delta", "seq": 7480, "price": 43, "quantity": 500, "ts": 1756428523.372003, "side": "buy"}
{"type": "orderbook_delta", "seq": 7481, "price": 43, "quantity": -91, "ts": 1756428523.429791, "side": "buy"}
{"type": "orderbook_delta", "seq": 7482, "price": 44, "quantity": 91, "ts": 1756428523.429791, "side": "buy"}
{"type": "orderbook_delta", "seq": 7483, "price": 43, "quantity": -500, "ts": 1756428523.469671, "side": "buy"}
{"type": "orderbook_delta", "seq": 7484, "price": 41, "quantity": 500, "ts": 1756428523.511656, "side": "buy"}
{"type": "orderbook_delta", "seq": 7485, "price": 44, "quantity": -91, "ts": 1756428523.581173, "side": "buy"}
{"type": "orderbook_delta", "seq": 7486, "price": 41, "quantity": 91, "ts": 1756428523.581173, "side": "buy"}
{"type": "orderbook_delta", "seq": 7487, "price": 41, "quantity": -500, "ts": 1756428523.620826, "side": "buy"}
{"type": "orderbook_delta", "seq": 7488, "price": 42, "quantity": 500, "ts": 1756428523.65461, "side": "buy"}
{"type": "orderbook_delta", "seq": 7489, "price": 49, "quantity": -500, "ts": 1756428524.856986, "side": "sell"}
{"type": "orderbook_delta", "seq": 7490, "price": 52, "quantity": -200, "ts": 1756428524.85704, "side": "sell"}
{"type": "orderbook_delta", "seq": 7491, "price": 41, "quantity": -200, "ts": 1756428524.857088, "side": "buy"}
{"type": "orderbook_delta", "seq": 7492, "price": 39, "quantity": -1250, "ts": 1756428524.857135, "side": "buy"}
{"type": "orderbook_delta", "seq": 7493, "price": 40, "quantity": 200, "ts": 1756428524.896227, "side": "buy"}
{"type": "orderbook_delta", "seq": 7494, "price": 38, "quantity": 1250, "ts": 1756428524.89676, "side": "buy"}
{"type": "orderbook_delta", "seq": 7495, "price": 48, "quantity": 500, "ts": 1756428524.897903, "side": "sell"}
{"type": "orderbook_delta", "seq": 7496, "price": 51, "quantity": 200, "ts": 1756428524.910894, "side": "sell"}
{"type": "orderbook_delta", "seq": 7497, "price": 41, "quantity": -91, "ts": 1756428524.955797, "side": "buy"}
{"type": "orderbook_delta", "seq": 7498, "price": 42, "quantity": 91, "ts": 1756428524.955797, "side": "buy"}
{"type": "orderbook_delta", "seq": 7499, "price": 42, "quantity": -500, "ts": 1756428524.987798, "side": "buy"}
{"type": "orderbook_delta", "seq": 7500, "price": 43, "quantity": 500, "ts": 1756428525.026466, "side": "buy"}
{"type": "orderbook_delta", "seq": 7501, "price": 42, "quantity": -91, "ts": 1756428525.043992, "side": "buy"}
{"type": "orderbook_delta", "seq": 7502, "price": 41, "quantity": 91, "ts": 1756428525.043992, "side": "buy"}
{"type": "orderbook_delta", "seq": 7503, "price": 43, "quantity": -500, "ts": 1756428525.091391, "side": "buy"}
{"type": "orderbook_delta", "seq": 7504, "price": 42, "quantity": 500, "ts": 1756428525.139257, "side": "buy"}
{"type": "orderbook_delta", "seq": 7505, "price": 41, "quantity": -91, "ts": 1756428525.79952, "side": "buy"}
{"type": "orderbook_delta", "seq": 7506, "price": 42, "quantity": 91, "ts": 1756428525.79952, "side": "buy"}
{"type": "orderbook_delta", "seq": 7507, "price": 42, "quantity": -500, "ts": 1756428525.834998, "side": "buy"}
{"type": "orderbook_delta", "seq": 7508, "price": 43, "quantity": 500, "ts": 1756428525.878172, "side": "buy"}
{"type": "orderbook_delta", "seq": 7509, "price": 51, "quantity": -200, "ts": 1756428526.418056, "side": "sell"}
{"type": "orderbook_delta", "seq": 7510, "price": 43, "quantity": -500, "ts": 1756428526.418459, "side": "buy"}
{"type": "orderbook_delta", "seq": 7511, "price": 53, "quantity": -1250, "ts": 1756428526.418573, "side": "sell"}
{"type": "orderbook_delta", "seq": 7512, "price": 40, "quantity": -200, "ts": 1756428526.418629, "side": "buy"}
{"type": "orderbook_delta", "seq": 7513, "price": 42, "quantity": 500, "ts": 1756428526.459826, "side": "buy"}
{"type": "orderbook_delta", "seq": 7514, "price": 52, "quantity": 1250, "ts": 1756428526.460355, "side": "sell"}
{"type": "orderbook_delta", "seq": 7515, "price": 39, "quantity": 200, "ts": 1756428526.460622, "side": "buy"}
{"type": "orderbook_delta", "seq": 7516, "price": 50, "quantity": 200, "ts": 1756428526.465827, "side": "sell"}
{"type": "orderbook_delta", "seq": 7517, "price": 42, "quantity": -91, "ts": 1756428526.877569, "side": "buy"}
{"type": "orderbook_delta", "seq": 7518, "price": 41, "quantity": 91, "ts": 1756428526.877569, "side": "buy"}
{"type": "orderbook_delta", "seq": 7519, "price": 50, "quantity": -200, "ts": 1756428526.889237, "side": "sell"}
{"type": "orderbook_delta", "seq": 7520, "price": 47, "quantity": 200, "ts": 1756428526.889237, "side": "sell"}
{"type": "orderbook_delta", "seq": 7521, "price": 38, "quantity": -1250, "ts": 1756428526.91086, "side": "buy"}
{"type": "orderbook_delta", "seq": 7522, "price": 41, "quantity": -91, "ts": 1756428526.935906, "side": "buy"}
{"type": "orderbook_delta", "seq": 7523, "price": 39, "quantity": 91, "ts": 1756428526.935906, "side": "buy"}
{"type": "orderbook_delta", "seq": 7524, "price": 37, "quantity": 1250, "ts": 1756428526.945402, "side": "buy"}
{"type": "orderbook_delta", "seq": 7525, "price": 42, "quantity": -500, "ts": 1756428526.984146, "side": "buy"}
{"type": "orderbook_delta", "seq": 7526, "price": 41, "quantity": 500, "ts": 1756428527.023595, "side": "buy"}
{"type": "orderbook_delta", "seq": 7527, "price": 48, "quantity": -969, "ts": 1756428527.092242, "side": "sell"}
{"type": "orderbook_delta", "seq": 7528, "price": 30, "quantity": 250, "ts": 1756428527.094217, "side": "buy"}
{"type": "orderbook_delta", "seq": 7529, "price": 40, "quantity": -250, "ts": 1756428527.105601, "side": "buy"}
{"type": "orderbook_delta", "seq": 7530, "price": 48, "quantity": 250, "ts": 1756428527.105726, "side": "sell"}
{"type": "orderbook_delta", "seq": 7531, "price": 58, "quantity": -250, "ts": 1756428527.125369, "side": "sell"}
{"type": "orderbook_delta", "seq": 7532, "price": 48, "quantity": -500, "ts": 1756428527.128821, "side": "sell"}
{"type": "orderbook_delta", "seq": 7533, "price": 41, "quantity": -500, "ts": 1756428527.139898, "side": "buy"}
{"type": "orderbook_delta", "seq": 7534, "price": 48, "quantity": 500, "ts": 1756428527.166423, "side": "sell"}
{"type": "orderbook_delta", "seq": 7535, "price": 46, "quantity": 969, "ts": 1756428527.180521, "side": "sell"}
{"type": "orderbook_delta", "seq": 7536, "price": 40, "quantity": 500, "ts": 1756428527.180776, "side": "buy"}
{"type": "orderbook_delta", "seq": 7537, "price": 39, "quantity": -91, "ts": 1756428527.541078, "side": "buy"}
{"type": "orderbook_delta", "seq": 7538, "price": 38, "quantity": 91, "ts": 1756428527.541078, "side": "buy"}
{"type": "orderbook_delta", "seq": 7539, "price": 40, "quantity": -500, "ts": 1756428527.579922, "side": "buy"}
{"type": "orderbook_delta", "seq": 7540, "price": 39, "quantity": 500, "ts": 1756428527.618507, "side": "buy"}
{"type": "trade", "seq": 70, "price": 46, "quantity": 20, "ts": 1756428527.681769, "side": "buy"}
{"type": "orderbook_delta", "seq": 7541, "price": 46, "quantity": 0, "ts": 1756428527.681769, "side": "sell"}
{"type": "orderbook_delta", "seq": 7542, "price": 52, "quantity": -1250, "ts": 1756428527.886043, "side": "sell"}
{"type": "orderbook_delta", "seq": 7543, "price": 37, "quantity": -1250, "ts": 1756428527.887478, "side": "buy"}
{"type": "orderbook_delta", "seq": 7544, "price": 50, "quantity": -200, "ts": 1756428527.894292, "side": "sell"}
{"type": "orderbook_delta", "seq": 7545, "price": 51, "quantity": 200, "ts": 1756428527.92442, "side": "sell"}
{"type": "orderbook_delta", "seq": 7546, "price": 53, "quantity": 1250, "ts": 1756428527.928323, "side": "sell"}
{"type": "orderbook_delta", "seq": 7547, "price": 38, "quantity": 1250, "ts": 1756428527.93054, "side": "buy"}
{"type": "orderbook_delta", "seq": 7548, "price": 46, "quantity": -949, "ts": 1756428528.101952, "side": "sell"}
{"type": "orderbook_delta", "seq": 7549, "price": 40, "quantity": 250, "ts": 1756428528.10526, "side": "buy"}
{"type": "orderbook_delta", "seq": 7550, "price": 30, "quantity": -250, "ts": 1756428528.127157, "side": "buy"}
{"type": "orderbook_delta", "seq": 7551, "price": 58, "quantity": 250, "ts": 1756428528.127198, "side": "sell"}
{"type": "orderbook_delta", "seq": 7552, "price": 48, "quantity": -250, "ts": 1756428528.1471, "side": "sell"}
{"type": "orderbook_delta", "seq": 7553, "price": 39, "quantity": -200, "ts": 1756428528.189728, "side": "buy"}
{"type": "orderbook_delta", "seq": 7554, "price": 39, "quantity": -500, "ts": 1756428528.190978, "side": "buy"}
{"type": "orderbook_delta", "seq": 7555, "price": 48, "quantity": -500, "ts": 1756428528.200427, "side": "sell"}
{"type": "orderbook_delta", "seq": 7556, "price": 47, "quantity": 949, "ts": 1756428528.202669, "side": "sell"}
{"type": "orderbook_delta", "seq": 7557, "price": 49, "quantity": 500, "ts": 1756428528.236591, "side": "sell"}
{"type": "orderbook_delta", "seq": 7558, "price": 41, "quantity": 500, "ts": 1756428528.238824, "side": "buy"}
{"type": "orderbook_delta", "seq": 7559, "price": 40, "quantity": 200, "ts": 1756428528.243437, "side": "buy"}
{"type": "orderbook_delta", "seq": 7560, "price": 50, "quantity": -100, "ts": 1756428528.25401, "side": "sell"}
{"type": "orderbook_delta", "seq": 7561, "price": 47, "quantity": 100, "ts": 1756428528.25401, "side": "sell"}
{"type": "orderbook_delta", "seq": 7562, "price": 40, "quantity": -250, "ts": 1756428528.402445, "side": "buy"}
{"type": "orderbook_delta", "seq": 7563, "price": 30, "quantity": 250, "ts": 1756428528.406522, "side": "buy"}
{"type": "orderbook_delta", "seq": 7564, "price": 38, "quantity": -1250, "ts": 1756428528.415252, "side": "buy"}
{"type": "orderbook_delta", "seq": 7565, "price": 40, "quantity": -200, "ts": 1756428528.416048, "side": "buy"}
{"type": "orderbook_delta", "seq": 7566, "price": 51, "quantity": -200, "ts": 1756428528.416397, "side": "sell"}
{"type": "orderbook_delta", "seq": 7567, "price": 41, "quantity": -500, "ts": 1756428528.416572, "side": "buy"}
{"type": "orderbook_delta", "seq": 7568, "price": 49, "quantity": -500, "ts": 1756428528.417445, "side": "sell"}
{"type": "orderbook_delta", "seq": 7569, "price": 53, "quantity": -1250, "ts": 1756428528.425588, "side": "sell"}
{"type": "orderbook_delta", "seq": 7570, "price": 50, "quantity": 1250, "ts": 1756428528.467081, "side": "sell"}
{"type": "orderbook_delta", "seq": 7571, "price": 35, "quantity": 1250, "ts": 1756428528.467887, "side": "buy"}
{"type": "orderbook_delta", "seq": 7572, "price": 49, "quantity": 200, "ts": 1756428528.468179, "side": "sell"}
{"type": "orderbook_delta", "seq": 7573, "price": 37, "quantity": 200, "ts": 1756428528.46923, "side": "buy"}
{"type": "orderbook_delta", "seq": 7574, "price": 39, "quantity": 500, "ts": 1756428528.470374, "side": "buy"}
{"type": "orderbook_delta", "seq": 7575, "price": 46, "quantity": 500, "ts": 1756428528.472467, "side": "sell"}
{"type": "orderbook_delta", "seq": 7576, "price": 99, "quantity": -16200, "ts": 1756428528.776507, "side": "sell"}
{"type": "orderbook_delta", "seq": 7577, "price": 98, "quantity": 8100, "ts": 1756428528.776507, "side": "sell"}
{"type": "orderbook_delta", "seq": 7578, "price": 98, "quantity": -7000, "ts": 1756428528.810282, "side": "sell"}
{"type": "orderbook_delta", "seq": 7579, "price": 98, "quantity": -8000, "ts": 1756428528.811731, "side": "sell"}
{"type": "orderbook_delta", "seq": 7580, "price": 97, "quantity": 7000, "ts": 1756428528.845866, "side": "sell"}
{"type": "orderbook_delta", "seq": 7581, "price": 97, "quantity": 8000, "ts": 1756428528.849633, "side": "sell"}
{"type": "orderbook_delta", "seq": 7582, "price": 47, "quantity": -949, "ts": 1756428529.137882, "side": "sell"}
{"type": "orderbook_delta", "seq": 7583, "price": 48, "quantity": 250, "ts": 1756428529.140203, "side": "sell"}
{"type": "orderbook_delta", "seq": 7584, "price": 58, "quantity": -250, "ts": 1756428529.156202, "side": "sell"}
{"type": "orderbook_delta", "seq": 7585, "price": 35, "quantity": -1250, "ts": 1756428529.178818, "side": "buy"}
{"type": "orderbook_delta", "seq": 7586, "price": 49, "quantity": -200, "ts": 1756428529.179082, "side": "sell"}
{"type": "orderbook_delta", "seq": 7587, "price": 46, "quantity": 949, "ts": 1756428529.204532, "side": "sell"}
{"type": "orderbook_delta", "seq": 7588, "price": 38, "quantity": -91, "ts": 1756428529.226935, "side": "buy"}
{"type": "orderbook_delta", "seq": 7589, "price": 40, "quantity": 91, "ts": 1756428529.226935, "side": "buy"}
{"type": "orderbook_delta", "seq": 7590, "price": 36, "quantity": 1250, "ts": 1756428529.232354, "side": "buy"}
{"type": "orderbook_delta", "seq": 7591, "price": 48, "quantity": 200, "ts": 1756428529.235411, "side": "sell"}
{"type": "orderbook_delta", "seq": 7592, "price": 47, "quantity": -100, "ts": 1756428529.338324, "side": "sell"}
{"type": "orderbook_delta", "seq": 7593, "price": 39, "quantity": -500, "ts": 1756428529.338848, "side": "buy"}
{"type": "orderbook_delta", "seq": 7594, "price": 47, "quantity": -100, "ts": 1756428529.340322, "side": "sell"}
{"type": "orderbook_delta", "seq": 7595, "price": 49, "quantity": 100, "ts": 1756428529.340322, "side": "sell"}
{"type": "orderbook_delta", "seq": 7596, "price": 47, "quantity": -200, "ts": 1756428529.342238, "side": "sell"}
{"type": "orderbook_delta", "seq": 7597, "price": 49, "quantity": 200, "ts": 1756428529.342238, "side": "sell"}
{"type": "orderbook_delta", "seq": 7598, "price": 40, "quantity": 500, "ts": 1756428529.377669, "side": "buy"}
{"type": "orderbook_delta", "seq": 7599, "price": 40, "quantity": -91, "ts": 1756428529.393762, "side": "buy"}
{"type": "orderbook_delta", "seq": 7600, "price": 39, "quantity": 91, "ts": 1756428529.393762, "side": "buy"}
{"type": "orderbook_delta", "seq": 7601, "price": 36, "quantity": -1250, "ts": 1756428529.485186, "side": "buy"}
{"type": "orderbook_delta", "seq": 7602, "price": 35, "quantity": 1250, "ts": 1756428529.511505, "side": "buy"}
{"type": "orderbook_delta", "seq": 7603, "price": 45, "quantity": 78, "ts": 1756428529.543508, "side": "sell"}
{"type": "orderbook_delta", "seq": 7604, "price": 48, "quantity": -200, "ts": 1756428529.637208, "side": "sell"}
{"type": "orderbook_delta", "seq": 7605, "price": 37, "quantity": -200, "ts": 1756428529.639071, "side": "buy"}
{"type": "orderbook_delta", "seq": 7606, "price": 35, "quantity": -1250, "ts": 1756428529.639177, "side": "buy"}
{"type": "orderbook_delta", "seq": 7607, "price": 46, "quantity": -500, "ts": 1756428529.639967, "side": "sell"}
{"type": "orderbook_delta", "seq": 7608, "price": 50, "quantity": -1250, "ts": 1756428529.653312, "side": "sell"}
{"type": "orderbook_delta", "seq": 7609, "price": 50, "quantity": 200, "ts": 1756428529.711546, "side": "sell"}
{"type": "orderbook_delta", "seq": 7610, "price": 37, "quantity": 1250, "ts": 1756428529.715353, "side": "buy"}
{"type": "orderbook_delta", "seq": 7611, "price": 39, "quantity": 200, "ts": 1756428529.7163, "side": "buy"}
{"type": "orderbook_delta", "seq": 7612, "price": 46, "quantity": -949, "ts": 1756428529.719852, "side": "sell"}
{"type": "orderbook_delta", "seq": 7613, "price": 52, "quantity": 1250, "ts": 1756428529.726648, "side": "sell"}
{"type": "orderbook_delta", "seq": 7614, "price": 48, "quantity": 500, "ts": 1756428529.727493, "side": "sell"}
{"type": "orderbook_delta", "seq": 7615, "price": 58, "quantity": 250, "ts": 1756428529.73214, "side": "sell"}
{"type": "orderbook_delta", "seq": 7616, "price": 48, "quantity": -250, "ts": 1756428529.736343, "side": "sell"}
{"type": "orderbook_delta", "seq": 7617, "price": 48, "quantity": 949, "ts": 1756428529.782585, "side": "sell"}
{"type": "orderbook_delta", "seq": 7618, "price": 40, "quantity": 250, "ts": 1756428530.104536, "side": "buy"}
{"type": "orderbook_delta", "seq": 7619, "price": 30, "quantity": -250, "ts": 1756428530.107326, "side": "buy"}
{"type": "orderbook_delta", "seq": 7620, "price": 39, "quantity": -91, "ts": 1756428530.136674, "side": "buy"}
{"type": "orderbook_delta", "seq": 7621, "price": 40, "quantity": 91, "ts": 1756428530.136674, "side": "buy"}
{"type": "orderbook_delta", "seq": 7622, "price": 40, "quantity": -500, "ts": 1756428530.15143, "side": "buy"}
{"type": "orderbook_delta", "seq": 7623, "price": 41, "quantity": 500, "ts": 1756428530.182744, "side": "buy"}
{"type": "orderbook_delta", "seq": 7624, "price": 49, "quantity": -100, "ts": 1756428530.200506, "side": "sell"}
{"type": "orderbook_delta", "seq": 7625, "price": 50, "quantity": 100, "ts": 1756428530.200506, "side": "sell"}
{"type": "orderbook_delta", "seq": 7626, "price": 44, "quantity": -100, "ts": 1756428530.318926, "side": "buy"}
{"type": "orderbook_delta", "seq": 7627, "price": 45, "quantity": -78, "ts": 1756428530.53327, "side": "sell"}
{"type": "orderbook_delta", "seq": 7628, "price": 40, "quantity": -91, "ts": 1756428530.567559, "side": "buy"}
{"type": "orderbook_delta", "seq": 7629, "price": 38, "quantity": 91, "ts": 1756428530.567559, "side": "buy"}
{"type": "orderbook_delta", "seq": 7630, "price": 44, "quantity": 78, "ts": 1756428530.767439, "side": "sell"}
{"type": "orderbook_delta", "seq": 7631, "price": 50, "quantity": -200, "ts": 1756428530.859542, "side": "sell"}
{"type": "orderbook_delta", "seq": 7632, "price": 37, "quantity": -1250, "ts": 1756428530.862656, "side": "buy"}
{"type": "orderbook_delta", "seq": 7633, "price": 39, "quantity": -200, "ts": 1756428530.871077, "side": "buy"}
{"type": "orderbook_delta", "seq": 7634, "price": 52, "quantity": -1250, "ts": 1756428530.878592, "side": "sell"}
{"type": "orderbook_delta", "seq": 7635, "price": 40, "quantity": 200, "ts": 1756428530.913612, "side": "buy"}
{"type": "orderbook_delta", "seq": 7636, "price": 53, "quantity": 1250, "ts": 1756428530.913976, "side": "sell"}
{"type": "orderbook_delta", "seq": 7637, "price": 51, "quantity": 200, "ts": 1756428530.915568, "side": "sell"}
{"type": "orderbook_delta", "seq": 7638, "price": 38, "quantity": 1250, "ts": 1756428530.917413, "side": "buy"}
{"type": "orderbook_delta", "seq": 7639, "price": 48, "quantity": -500, "ts": 1756428531.326809, "side": "sell"}
{"type": "orderbook_delta", "seq": 7640, "price": 53, "quantity": -1250, "ts": 1756428531.326984, "side": "sell"}
{"type": "orderbook_delta", "seq": 7641, "price": 40, "quantity": -200, "ts": 1756428531.327095, "side": "buy"}
{"type": "orderbook_delta", "seq": 7642, "price": 51, "quantity": -200, "ts": 1756428531.333988, "side": "sell"}
{"type": "orderbook_delta", "seq": 7643, "price": 38, "quantity": -1250, "ts": 1756428531.357728, "side": "buy"}
{"type": "orderbook_delta", "seq": 7644, "price": 49, "quantity": -200, "ts": 1756428531.364752, "side": "sell"}
{"type": "orderbook_delta", "seq": 7645, "price": 47, "quantity": 200, "ts": 1756428531.364752, "side": "sell"}
{"type": "orderbook_delta", "seq": 7646, "price": 38, "quantity": 200, "ts": 1756428531.407215, "side": "buy"}
{"type": "orderbook_delta", "seq": 7647, "price": 47, "quantity": 500, "ts": 1756428531.408059, "side": "sell"}
{"type": "orderbook_delta", "seq": 7648, "price": 49, "quantity": 200, "ts": 1756428531.408295, "side": "sell"}
{"type": "orderbook_delta", "seq": 7649, "price": 51, "quantity": 1250, "ts": 1756428531.408509, "side": "sell"}
{"type": "orderbook_delta", "seq": 7650, "price": 36, "quantity": 1250, "ts": 1756428531.414566, "side": "buy"}
{"type": "orderbook_delta", "seq": 7651, "price": 50, "quantity": -100, "ts": 1756428531.762144, "side": "sell"}
{"type": "orderbook_delta", "seq": 7652, "price": 46, "quantity": 100, "ts": 1756428531.762144, "side": "sell"}
{"type": "orderbook_delta", "seq": 7653, "price": 46, "quantity": -100, "ts": 1756428531.966859, "side": "sell"}
{"type": "orderbook_delta", "seq": 7654, "price": 47, "quantity": 100, "ts": 1756428531.966859, "side": "sell"}
{"type": "orderbook_delta", "seq": 7655, "price": 38, "quantity": -91, "ts": 1756428532.070035, "side": "buy"}
{"type": "orderbook_delta", "seq": 7656, "price": 41, "quantity": 91, "ts": 1756428532.070035, "side": "buy"}
{"type": "orderbook_delta", "seq": 7657, "price": 48, "quantity": -949, "ts": 1756428532.106256, "side": "sell"}
{"type": "orderbook_delta", "seq": 7658, "price": 30, "quantity": 250, "ts": 1756428532.106759, "side": "buy"}
{"type": "orderbook_delta", "seq": 7659, "price": 40, "quantity": -250, "ts": 1756428532.127787, "side": "buy"}
{"type": "orderbook_delta", "seq": 7660, "price": 48, "quantity": 250, "ts": 1756428532.128333, "side": "sell"}
{"type": "orderbook_delta", "seq": 7661, "price": 58, "quantity": -250, "ts": 1756428532.147315, "side": "sell"}
{"type": "orderbook_delta", "seq": 7662, "price": 47, "quantity": 949, "ts": 1756428532.191637, "side": "sell"}
{"type": "orderbook_delta", "seq": 7663, "price": 41, "quantity": 100, "ts": 1756428532.428177, "side": "buy"}
{"type": "orderbook_delta", "seq": 7664, "price": 47, "quantity": -100, "ts": 1756428532.447063, "side": "sell"}
{"type": "orderbook_delta", "seq": 7665, "price": 48, "quantity": 100, "ts": 1756428532.447063, "side": "sell"}
{"type": "orderbook_delta", "seq": 7666, "price": 47, "quantity": -500, "ts": 1756428532.532266, "side": "sell"}
{"type": "orderbook_delta", "seq": 7667, "price": 49, "quantity": -200, "ts": 1756428532.532453, "side": "sell"}
{"type": "orderbook_delta", "seq": 7668, "price": 41, "quantity": -500, "ts": 1756428532.536425, "side": "buy"}
{"type": "orderbook_delta", "seq": 7669, "price": 38, "quantity": -200, "ts": 1756428532.536595, "side": "buy"}
{"type": "orderbook_delta", "seq": 7670, "price": 36, "quantity": -1250, "ts": 1756428532.537316, "side": "buy"}
{"type": "orderbook_delta", "seq": 7671, "price": 51, "quantity": -1250, "ts": 1756428532.537931, "side": "sell"}
{"type": "orderbook_delta", "seq": 7672, "price": 37, "quantity": 200, "ts": 1756428532.585194, "side": "buy"}
{"type": "orderbook_delta", "seq": 7673, "price": 39, "quantity": 500, "ts": 1756428532.58548, "side": "buy"}
{"type": "orderbook_delta", "seq": 7674, "price": 46, "quantity": 500, "ts": 1756428532.586587, "side": "sell"}
{"type": "orderbook_delta", "seq": 7675, "price": 35, "quantity": 1250, "ts": 1756428532.588165, "side": "buy"}
{"type": "orderbook_delta", "seq": 7676, "price": 48, "quantity": 200, "ts": 1756428532.589668, "side": "sell"}
{"type": "orderbook_delta", "seq": 7677, "price": 41, "quantity": -91, "ts": 1756428532.58993, "side": "buy"}
{"type": "orderbook_delta", "seq": 7678, "price": 39, "quantity": 91, "ts": 1756428532.58993, "side": "buy"}
{"type": "orderbook_delta", "seq": 7679, "price": 50, "quantity": 1250, "ts": 1756428532.598281, "side": "sell"}
{"type": "orderbook_delta", "seq": 7680, "price": 28, "quantity": 250, "ts": 1756428532.65251, "side": "buy"}
{"type": "orderbook_delta", "seq": 7681, "price": 38, "quantity": -250, "ts": 1756428532.654768, "side": "buy"}
{"type": "orderbook_delta", "seq": 7682, "price": 39, "quantity": -500, "ts": 1756428532.710089, "side": "buy"}
{"type": "orderbook_delta", "seq": 7683, "price": 40, "quantity": 500, "ts": 1756428532.744879, "side": "buy"}
{"type": "orderbook_delta", "seq": 7684, "price": 35, "quantity": -1250, "ts": 1756428533.047032, "side": "buy"}
{"type": "orderbook_delta", "seq": 7685, "price": 48, "quantity": -200, "ts": 1756428533.049661, "side": "sell"}
{"type": "orderbook_delta", "seq": 7686, "price": 49, "quantity": 200, "ts": 1756428533.091144, "side": "sell"}
{"type": "orderbook_delta", "seq": 7687, "price": 36, "quantity": 1250, "ts": 1756428533.094361, "side": "buy"}
{"type": "orderbook_delta", "seq": 7688, "price": 28, "quantity": -250, "ts": 1756428533.099026, "side": "buy"}
{"type": "orderbook_delta", "seq": 7689, "price": 38, "quantity": 250, "ts": 1756428533.099057, "side": "buy"}
{"type": "orderbook_delta", "seq": 7690, "price": 50, "quantity": -1250, "ts": 1756428533.169154, "side": "sell"}
{"type": "orderbook_delta", "seq": 7691, "price": 37, "quantity": -200, "ts": 1756428533.169361, "side": "buy"}
{"type": "orderbook_delta", "seq": 7692, "price": 44, "quantity": -78, "ts": 1756428533.197501, "side": "sell"}
{"type": "orderbook_delta", "seq": 7693, "price": 51, "quantity": 1250, "ts": 1756428533.20698, "side": "sell"}
{"type": "orderbook_delta", "seq": 7694, "price": 38, "quantity": 200, "ts": 1756428533.207818, "side": "buy"}
{"type": "orderbook_delta", "seq": 7695, "price": 39, "quantity": -91, "ts": 1756428533.3567, "side": "buy"}
{"type": "orderbook_delta", "seq": 7696, "price": 41, "quantity": 91, "ts": 1756428533.3567, "side": "buy"}
{"type": "orderbook_delta", "seq": 7697, "price": 51, "quantity": -1250, "ts": 1756428533.390834, "side": "sell"}
{"type": "orderbook_delta", "seq": 7698, "price": 40, "quantity": -500, "ts": 1756428533.392156, "side": "buy"}
{"type": "orderbook_delta", "seq": 7699, "price": 39, "quantity": 500, "ts": 1756428533.446149, "side": "buy"}
{"type": "orderbook_delta", "seq": 7700, "price": 44, "quantity": 100, "ts": 1756428533.451725, "side": "sell"}
{"type": "orderbook_delta", "seq": 7701, "price": 51, "quantity": 1250, "ts": 1756428533.453943, "side": "sell"}
{"type": "orderbook_delta", "seq": 7702, "price": 41, "quantity": -91, "ts": 1756428534.168438, "side": "buy"}
{"type": "orderbook_delta", "seq": 7703, "price": 40, "quantity": 91, "ts": 1756428534.168438, "side": "buy"}
{"type": "orderbook_delta", "seq": 7704, "price": 39, "quantity": -500, "ts": 1756428534.202111, "side": "buy"}
{"type": "orderbook_delta", "seq": 7705, "price": 40, "quantity": 500, "ts": 1756428534.281268, "side": "buy"}
{"type": "orderbook_delta", "seq": 7706, "price": 40, "quantity": -500, "ts": 1756428534.460282, "side": "buy"}
{"type": "orderbook_delta", "seq": 7707, "price": 41, "quantity": 500, "ts": 1756428534.534072, "side": "buy"}
{"type": "orderbook_delta", "seq": 7708, "price": 46, "quantity": -500, "ts": 1756428534.644542, "side": "sell"}
{"type": "orderbook_delta", "seq": 7709, "price": 48, "quantity": -100, "ts": 1756428534.648999, "side": "sell"}
{"type": "orderbook_delta", "seq": 7710, "price": 49, "quantity": 100, "ts": 1756428534.648999, "side": "sell"}
{"type": "orderbook_delta", "seq": 7711, "price": 47, "quantity": 500, "ts": 1756428534.714776, "side": "sell"}
{"type": "orderbook_delta", "seq": 7712, "price": 40, "quantity": 250, "ts": 1756428535.076751, "side": "buy"}
{"type": "orderbook_delta", "seq": 7713, "price": 30, "quantity": -250, "ts": 1756428535.079064, "side": "buy"}
{"type": "orderbook_delta", "seq": 7714, "price": 38, "quantity": -200, "ts": 1756428535.569692, "side": "buy"}
{"type": "orderbook_delta", "seq": 7715, "price": 49, "quantity": -200, "ts": 1756428535.571506, "side": "sell"}
{"type": "orderbook_delta", "seq": 7716, "price": 51, "quantity": -1250, "ts": 1756428535.571746, "side": "sell"}
{"type": "orderbook_delta", "seq": 7717, "price": 36, "quantity": -1250, "ts": 1756428535.571913, "side": "buy"}
{"type": "orderbook_delta", "seq": 7718, "price": 47, "quantity": 1, "ts": 1756428535.593677, "side": "sell"}
{"type": "orderbook_delta", "seq": 7719, "price": 50, "quantity": 200, "ts": 1756428535.645485, "side": "sell"}
{"type": "orderbook_delta", "seq": 7720, "price": 39, "quantity": 200, "ts": 1756428535.646559, "side": "buy"}
{"type": "orderbook_delta", "seq": 7721, "price": 37, "quantity": 1250, "ts": 1756428535.654704, "side": "buy"}
{"type": "orderbook_delta", "seq": 7722, "price": 52, "quantity": 1250, "ts": 1756428535.655864, "side": "sell"}
{"type": "orderbook_delta", "seq": 7723, "price": 40, "quantity": -91, "ts": 1756428535.667606, "side": "buy"}
{"type": "orderbook_delta", "seq": 7724, "price": 42, "quantity": 91, "ts": 1756428535.667606, "side": "buy"}
{"type": "orderbook_delta", "seq": 7725, "price": 52, "quantity": -1250, "ts": 1756428535.928738, "side": "sell"}
{"type": "orderbook_delta", "seq": 7726, "price": 51, "quantity": 1250, "ts": 1756428535.991025, "side": "sell"}
{"type": "orderbook_delta", "seq": 7727, "price": 51, "quantity": -1250, "ts": 1756428536.078078, "side": "sell"}
{"type": "orderbook_delta", "seq": 7728, "price": 52, "quantity": 1250, "ts": 1756428536.120114, "side": "sell"}
{"type": "orderbook_delta", "seq": 7729, "price": 49, "quantity": -100, "ts": 1756428536.303215, "side": "sell"}
{"type": "orderbook_delta", "seq": 7730, "price": 47, "quantity": 100, "ts": 1756428536.303215, "side": "sell"}
{"type": "orderbook_delta", "seq": 7731, "price": 44, "quantity": -100, "ts": 1756428537.005415, "side": "sell"}
{"type": "orderbook_delta", "seq": 7732, "price": 39, "quantity": -200, "ts": 1756428537.057309, "side": "buy"}
{"type": "orderbook_delta", "seq": 7733, "price": 52, "quantity": -1250, "ts": 1756428537.057439, "side": "sell"}
{"type": "orderbook_delta", "seq": 7734, "price": 50, "quantity": -200, "ts": 1756428537.05795, "side": "sell"}
{"type": "orderbook_delta", "seq": 7735, "price": 37, "quantity": -1250, "ts": 1756428537.058557, "side": "buy"}
{"type": "orderbook_delta", "seq": 7736, "price": 41, "quantity": -500, "ts": 1756428537.058988, "side": "buy"}
{"type": "orderbook_delta", "seq": 7737, "price": 47, "quantity": -500, "ts": 1756428537.059493, "side": "sell"}
{"type": "orderbook_delta", "seq": 7738, "price": 36, "quantity": 1250, "ts": 1756428537.098904, "side": "buy"}
{"type": "orderbook_delta", "seq": 7739, "price": 46, "quantity": 500, "ts": 1756428537.100065, "side": "sell"}
{"type": "orderbook_delta", "seq": 7740, "price": 38, "quantity": 200, "ts": 1756428537.100586, "side": "buy"}
{"type": "orderbook_delta", "seq": 7741, "price": 51, "quantity": 1250, "ts": 1756428537.100881, "side": "sell"}
{"type": "orderbook_delta", "seq": 7742, "price": 40, "quantity": 500, "ts": 1756428537.101125, "side": "buy"}
{"type": "orderbook_delta", "seq": 7743, "price": 49, "quantity": 200, "ts": 1756428537.101368, "side": "sell"}
{"type": "orderbook_delta", "seq": 7744, "price": 40, "quantity": -250, "ts": 1756428537.110013, "side": "buy"}
{"type": "orderbook_delta", "seq": 7745, "price": 42, "quantity": -91, "ts": 1756428537.110554, "side": "buy"}
{"type": "orderbook_delta", "seq": 7746, "price": 41, "quantity": 91, "ts": 1756428537.110554, "side": "buy"}
{"type": "orderbook_delta", "seq": 7747, "price": 30, "quantity": 250, "ts": 1756428537.111164, "side": "buy"}
{"type": "orderbook_delta", "seq": 7748, "price": 40, "quantity": -500, "ts": 1756428537.147709, "side": "buy"}
{"type": "orderbook_delta", "seq": 7749, "price": 39, "quantity": 500, "ts": 1756428537.209461, "side": "buy"}
{"type": "orderbook_delta", "seq": 7750, "price": 43, "quantity": 78, "ts": 1756428537.240083, "side": "sell"}
{"type": "orderbook_delta", "seq": 7751, "price": 47, "quantity": -100, "ts": 1756428537.825958, "side": "sell"}
{"type": "orderbook_delta", "seq": 7752, "price": 48, "quantity": 100, "ts": 1756428537.825958, "side": "sell"}
{"type": "orderbook_delta", "seq": 7753, "price": 47, "quantity": -200, "ts": 1756428538.428424, "side": "sell"}
{"type": "orderbook_delta", "seq": 7754, "price": 48, "quantity": 200, "ts": 1756428538.428424, "side": "sell"}
{"type": "orderbook_delta", "seq": 7755, "price": 49, "quantity": -200, "ts": 1756428538.498017, "side": "sell"}
{"type": "orderbook_delta", "seq": 7756, "price": 51, "quantity": -1250, "ts": 1756428538.498715, "side": "sell"}
{"type": "orderbook_delta", "seq": 7757, "price": 36, "quantity": -1250, "ts": 1756428538.498772, "side": "buy"}
{"type": "orderbook_delta", "seq": 7758, "price": 38, "quantity": -200, "ts": 1756428538.499032, "side": "buy"}
{"type": "orderbook_delta", "seq": 7759, "price": 46, "quantity": -500, "ts": 1756428538.499953, "side": "sell"}
{"type": "orderbook_delta", "seq": 7760, "price": 39, "quantity": -500, "ts": 1756428538.618205, "side": "buy"}
{"type": "orderbook_delta", "seq": 7761, "price": 39, "quantity": 200, "ts": 1756428538.659018, "side": "buy"}
{"type": "orderbook_delta", "seq": 7762, "price": 41, "quantity": 500, "ts": 1756428538.659612, "side": "buy"}
{"type": "orderbook_delta", "seq": 7763, "price": 47, "quantity": 500, "ts": 1756428538.661102, "side": "sell"}
{"type": "orderbook_delta", "seq": 7764, "price": 37, "quantity": 1250, "ts": 1756428538.661476, "side": "buy"}
{"type": "orderbook_delta", "seq": 7765, "price": 50, "quantity": 200, "ts": 1756428538.662588, "side": "sell"}
{"type": "orderbook_delta", "seq": 7766, "price": 52, "quantity": 1250, "ts": 1756428538.66339, "side": "sell"}
{"type": "orderbook_delta", "seq": 7767, "price": 41, "quantity": -91, "ts": 1756428538.707989, "side": "buy"}
{"type": "orderbook_delta", "seq": 7768, "price": 42, "quantity": 91, "ts": 1756428538.707989, "side": "buy"}
{"type": "orderbook_delta", "seq": 7769, "price": 42, "quantity": -91, "ts": 1756428538.986014, "side": "buy"}
{"type": "orderbook_delta", "seq": 7770, "price": 40, "quantity": 91, "ts": 1756428538.986014, "side": "buy"}
{"type": "orderbook_delta", "seq": 7771, "price": 40, "quantity": -91, "ts": 1756428539.051944, "side": "buy"}
{"type": "orderbook_delta", "seq": 7772, "price": 39, "quantity": 91, "ts": 1756428539.051944, "side": "buy"}
{"type": "orderbook_delta", "seq": 7773, "price": 52, "quantity": -1250, "ts": 1756428539.072668, "side": "sell"}
{"type": "orderbook_delta", "seq": 7774, "price": 39, "quantity": -200, "ts": 1756428539.072997, "side": "buy"}
{"type": "orderbook_delta", "seq": 7775, "price": 37, "quantity": -1250, "ts": 1756428539.073315, "side": "buy"}
{"type": "orderbook_delta", "seq": 7776, "price": 50, "quantity": -200, "ts": 1756428539.076541, "side": "sell"}
{"type": "orderbook_delta", "seq": 7777, "price": 38, "quantity": 200, "ts": 1756428539.119204, "side": "buy"}
{"type": "orderbook_delta", "seq": 7778, "price": 36, "quantity": 1250, "ts": 1756428539.119928, "side": "buy"}
{"type": "orderbook_delta", "seq": 7779, "price": 49, "quantity": 200, "ts": 1756428539.121774, "side": "sell"}
{"type": "orderbook_delta", "seq": 7780, "price": 51, "quantity": 1250, "ts": 1756428539.122468, "side": "sell"}
{"type": "orderbook_delta", "seq": 7781, "price": 39, "quantity": -91, "ts": 1756428539.14765, "side": "buy"}
{"type": "orderbook_delta", "seq": 7782, "price": 38, "quantity": 91, "ts": 1756428539.14765, "side": "buy"}
{"type": "orderbook_delta", "seq": 7783, "price": 48, "quantity": -200, "ts": 1756428539.183658, "side": "sell"}
{"type": "orderbook_delta", "seq": 7784, "price": 47, "quantity": 200, "ts": 1756428539.183658, "side": "sell"}
{"type": "orderbook_delta", "seq": 7785, "price": 41, "quantity": -500, "ts": 1756428539.220623, "side": "buy"}
{"type": "orderbook_delta", "seq": 7786, "price": 47, "quantity": -500, "ts": 1756428539.224758, "side": "sell"}
{"type": "orderbook_delta", "seq": 7787, "price": 39, "quantity": 500, "ts": 1756428539.280861, "side": "buy"}
{"type": "orderbook_delta", "seq": 7788, "price": 46, "quantity": 500, "ts": 1756428539.282672, "side": "sell"}
{"type": "orderbook_delta", "seq": 7789, "price": 48, "quantity": -100, "ts": 1756428539.351583, "side": "sell"}
{"type": "orderbook_delta", "seq": 7790, "price": 46, "quantity": 100, "ts": 1756428539.351583, "side": "sell"}
{"type": "orderbook_delta", "seq": 7791, "price": 46, "quantity": -100, "ts": 1756428539.606153, "side": "sell"}
{"type": "orderbook_delta", "seq": 7792, "price": 45, "quantity": 100, "ts": 1756428539.606153, "side": "sell"}
{"type": "orderbook_delta", "seq": 7793, "price": 38, "quantity": -91, "ts": 1756428539.659069, "side": "buy"}
{"type": "orderbook_delta", "seq": 7794, "price": 37, "quantity": 91, "ts": 1756428539.659069, "side": "buy"}
{"type": "orderbook_delta", "seq": 7795, "price": 98, "quantity": -8100, "ts": 1756428539.95574, "side": "sell"}
{"type": "orderbook_delta", "seq": 7796, "price": 96, "quantity": 4050, "ts": 1756428539.95574, "side": "sell"}
{"type": "orderbook_delta", "seq": 7797, "price": 97, "quantity": -7000, "ts": 1756428539.992009, "side": "sell"}
{"type": "orderbook_delta", "seq": 7798, "price": 39, "quantity": -500, "ts": 1756428539.992387, "side": "buy"}
{"type": "orderbook_delta", "seq": 7799, "price": 97, "quantity": -8000, "ts": 1756428539.992535, "side": "sell"}
{"type": "orderbook_delta", "seq": 7800, "price": 95, "quantity": 7000, "ts": 1756428540.114522, "side": "sell"}
{"type": "orderbook_delta", "seq": 7801, "price": 95, "quantity": 8000, "ts": 1756428540.115221, "side": "sell"}
{"type": "orderbook_delta", "seq": 7802, "price": 41, "quantity": 500, "ts": 1756428540.115466, "side": "buy"}
{"type": "orderbook_delta", "seq": 7803, "price": 47, "quantity": -949, "ts": 1756428540.116413, "side": "sell"}
{"type": "orderbook_delta", "seq": 7804, "price": 46, "quantity": 949, "ts": 1756428540.163622, "side": "sell"}
{"type": "orderbook_delta", "seq": 7805, "price": 96, "quantity": -4050, "ts": 1756428540.867266, "side": "sell"}
{"type": "orderbook_delta", "seq": 7806, "price": 98, "quantity": 8100, "ts": 1756428540.867266, "side": "sell"}
{"type": "orderbook_delta", "seq": 7807, "price": 45, "quantity": -100, "ts": 1756428540.874742, "side": "sell"}
{"type": "orderbook_delta", "seq": 7808, "price": 47, "quantity": 100, "ts": 1756428540.874742, "side": "sell"}
{"type": "orderbook_delta", "seq": 7809, "price": 95, "quantity": -8000, "ts": 1756428540.917476, "side": "sell"}
{"type": "orderbook_delta", "seq": 7810, "price": 47, "quantity": -100, "ts": 1756428541.037956, "side": "sell"}
{"type": "orderbook_delta", "seq": 7811, "price": 49, "quantity": 100, "ts": 1756428541.037956, "side": "sell"}
{"type": "orderbook_delta", "seq": 7812, "price": 95, "quantity": -7000, "ts": 1756428541.060786, "side": "sell"}
{"type": "orderbook_delta", "seq": 7813, "price": 46, "quantity": -949, "ts": 1756428541.129504, "side": "sell"}
{"type": "orderbook_delta", "seq": 7814, "price": 41, "quantity": -500, "ts": 1756428541.155381, "side": "buy"}
{"type": "orderbook_delta", "seq": 7815, "price": 97, "quantity": 7000, "ts": 1756428541.160424, "side": "sell"}
{"type": "orderbook_delta", "seq": 7816, "price": 45, "quantity": 949, "ts": 1756428541.170332, "side": "sell"}
{"type": "orderbook_delta", "seq": 7817, "price": 97, "quantity": 8000, "ts": 1756428541.175247, "side": "sell"}
{"type": "orderbook_delta", "seq": 7818, "price": 37, "quantity": -91, "ts": 1756428541.179413, "side": "buy"}
{"type": "orderbook_delta", "seq": 7819, "price": 42, "quantity": 91, "ts": 1756428541.179413, "side": "buy"}
{"type": "orderbook_delta", "seq": 7820, "price": 39, "quantity": 500, "ts": 1756428541.198181, "side": "buy"}
{"type": "orderbook_delta", "seq": 7821, "price": 42, "quantity": -91, "ts": 1756428541.230894, "side": "buy"}
{"type": "orderbook_delta", "seq": 7822, "price": 41, "quantity": 91, "ts": 1756428541.230894, "side": "buy"}
{"type": "orderbook_delta", "seq": 7823, "price": 41, "quantity": -91, "ts": 1756428541.283393, "side": "buy"}
{"type": "orderbook_delta", "seq": 7824, "price": 38, "quantity": 91, "ts": 1756428541.283393, "side": "buy"}
{"type": "orderbook_delta", "seq": 7825, "price": 39, "quantity": -500, "ts": 1756428541.472189, "side": "buy"}
{"type": "orderbook_delta", "seq": 7826, "price": 41, "quantity": 500, "ts": 1756428541.503812, "side": "buy"}
{"type": "orderbook_delta", "seq": 7827, "price": 98, "quantity": -8100, "ts": 1756428541.813324, "side": "sell"}
{"type": "orderbook_delta", "seq": 7828, "price": 96, "quantity": 4050, "ts": 1756428541.813324, "side": "sell"}
{"type": "orderbook_delta", "seq": 7829, "price": 97, "quantity": -8000, "ts": 1756428541.838851, "side": "sell"}
{"type": "orderbook_delta", "seq": 7830, "price": 97, "quantity": -7000, "ts": 1756428541.841773, "side": "sell"}
{"type": "orderbook_delta", "seq": 7831, "price": 95, "quantity": 8000, "ts": 1756428541.885729, "side": "sell"}
{"type": "orderbook_delta", "seq": 7832, "price": 95, "quantity": 7000, "ts": 1756428541.88637, "side": "sell"}
{"type": "orderbook_delta", "seq": 7833, "price": 45, "quantity": -949, "ts": 1756428542.037584, "side": "sell"}
{"type": "orderbook_delta", "seq": 7834, "price": 58, "quantity": 250, "ts": 1756428542.045556, "side": "sell"}
{"type": "orderbook_delta", "seq": 7835, "price": 46, "quantity": -500, "ts": 1756428542.054187, "side": "sell"}
{"type": "orderbook_delta", "seq": 7836, "price": 36, "quantity": -1250, "ts": 1756428542.055112, "side": "buy"}
{"type": "orderbook_delta", "seq": 7837, "price": 48, "quantity": -250, "ts": 1756428542.056669, "side": "sell"}
{"type": "orderbook_delta", "seq": 7838, "price": 51, "quantity": -1250, "ts": 1756428542.058065, "side": "sell"}
{"type": "orderbook_delta", "seq": 7839, "price": 41, "quantity": -500, "ts": 1756428542.063332, "side": "buy"}
{"type": "orderbook_delta", "seq": 7840, "price": 49, "quantity": -200, "ts": 1756428542.065798, "side": "sell"}
{"type": "orderbook_delta", "seq": 7841, "price": 38, "quantity": -200, "ts": 1756428542.06591, "side": "buy"}
{"type": "orderbook_delta", "seq": 7842, "price": 47, "quantity": 949, "ts": 1756428542.101516, "side": "sell"}
{"type": "orderbook_delta", "seq": 7843, "price": 42, "quantity": 500, "ts": 1756428542.113379, "side": "buy"}
{"type": "orderbook_delta", "seq": 7844, "price": 48, "quantity": 500, "ts": 1756428542.114795, "side": "sell"}
{"type": "orderbook_delta", "seq": 7845, "price": 50, "quantity": 200, "ts": 1756428542.117462, "side": "sell"}
{"type": "orderbook_delta", "seq": 7846, "price": 39, "quantity": 200, "ts": 1756428542.119118, "side": "buy"}
{"type": "orderbook_delta", "seq": 7847, "price": 52, "quantity": 1250, "ts": 1756428542.135358, "side": "sell"}
{"type": "orderbook_delta", "seq": 7848, "price": 37, "quantity": 1250, "ts": 1756428542.160987, "side": "buy"}
{"type": "orderbook_delta", "seq": 7849, "price": 48, "quantity": -500, "ts": 1756428542.169106, "side": "sell"}
{"type": "orderbook_delta", "seq": 7850, "price": 42, "quantity": -500, "ts": 1756428542.170347, "side": "buy"}
{"type": "orderbook_delta", "seq": 7851, "price": 52, "quantity": -1250, "ts": 1756428542.176527, "side": "sell"}
{"type": "orderbook_delta", "seq": 7852, "price": 41, "quantity": 500, "ts": 1756428542.221702, "side": "buy"}
{"type": "orderbook_delta", "seq": 7853, "price": 51, "quantity": 1250, "ts": 1756428542.225027, "side": "sell"}
{"type": "orderbook_delta", "seq": 7854, "price": 47, "quantity": 500, "ts": 1756428542.227015, "side": "sell"}
{"type": "orderbook_delta", "seq": 7855, "price": 49, "quantity": -100, "ts": 1756428542.597202, "side": "sell"}
{"type": "orderbook_delta", "seq": 7856, "price": 46, "quantity": 100, "ts": 1756428542.597202, "side": "sell"}
{"type": "orderbook_delta", "seq": 7857, "price": 96, "quantity": -4050, "ts": 1756428542.778539, "side": "sell"}
{"type": "orderbook_delta", "seq": 7858, "price": 98, "quantity": 8100, "ts": 1756428542.778539, "side": "sell"}
{"type": "orderbook_delta", "seq": 7859, "price": 43, "quantity": -78, "ts": 1756428542.790081, "side": "sell"}
{"type": "orderbook_delta", "seq": 7860, "price": 38, "quantity": -91, "ts": 1756428542.813191, "side": "buy"}
{"type": "orderbook_delta", "seq": 7861, "price": 41, "quantity": 91, "ts": 1756428542.813191, "side": "buy"}
{"type": "orderbook_delta", "seq": 7862, "price": 95, "quantity": -7000, "ts": 1756428542.819285, "side": "sell"}
{"type": "orderbook_delta", "seq": 7863, "price": 95, "quantity": -8000, "ts": 1756428542.82024, "side": "sell"}
{"type": "orderbook_delta", "seq": 7864, "price": 97, "quantity": 8000, "ts": 1756428542.862777, "side": "sell"}
{"type": "orderbook_delta", "seq": 7865, "price": 97, "quantity": 7000, "ts": 1756428542.863161, "side": "sell"}
{"type": "orderbook_delta", "seq": 7866, "price": 51, "quantity": -1250, "ts": 1756428542.88938, "side": "sell"}
{"type": "orderbook_delta", "seq": 7867, "price": 52, "quantity": 1250, "ts": 1756428542.926121, "side": "sell"}
{"type": "orderbook_delta", "seq": 7868, "price": 41, "quantity": -500, "ts": 1756428542.935256, "side": "buy"}
{"type": "orderbook_delta", "seq": 7869, "price": 37, "quantity": -1250, "ts": 1756428542.936564, "side": "buy"}
{"type": "orderbook_delta", "seq": 7870, "price": 39, "quantity": -200, "ts": 1756428542.937396, "side": "buy"}
{"type": "orderbook_delta", "seq": 7871, "price": 50, "quantity": -200, "ts": 1756428542.93759, "side": "sell"}
{"type": "orderbook_delta", "seq": 7872, "price": 47, "quantity": -500, "ts": 1756428542.951898, "side": "sell"}
{"type": "orderbook_delta", "seq": 7873, "price": 47, "quantity": -200, "ts": 1756428542.952106, "side": "sell"}
{"type": "orderbook_delta", "seq": 7874, "price": 46, "quantity": 200, "ts": 1756428542.952106, "side": "sell"}
{"type": "orderbook_delta", "seq": 7875, "price": 52, "quantity": -1250, "ts": 1756428542.967564, "side": "sell"}
{"type": "orderbook_delta", "seq": 7876, "price": 46, "quantity": 500, "ts": 1756428542.981818, "side": "sell"}
{"type": "orderbook_delta", "seq": 7877, "price": 41, "quantity": -91, "ts": 1756428542.98211, "side": "buy"}
{"type": "orderbook_delta", "seq": 7878, "price": 40, "quantity": 91, "ts": 1756428542.98211, "side": "buy"}
{"type": "orderbook_delta", "seq": 7879, "price": 39, "quantity": 500, "ts": 1756428542.982741, "side": "buy"}
{"type": "orderbook_delta", "seq": 7880, "price": 49, "quantity": 200, "ts": 1756428542.984562, "side": "sell"}
{"type": "orderbook_delta", "seq": 7881, "price": 38, "quantity": 200, "ts": 1756428542.984823, "side": "buy"}
{"type": "orderbook_delta", "seq": 7882, "price": 36, "quantity": 1250, "ts": 1756428542.985569, "side": "buy"}
{"type": "orderbook_delta", "seq": 7883, "price": 50, "quantity": 1250, "ts": 1756428543.022999, "side": "sell"}
{"type": "orderbook_delta", "seq": 7884, "price": 39, "quantity": -500, "ts": 1756428543.02608, "side": "buy"}
{"type": "orderbook_delta", "seq": 7885, "price": 46, "quantity": -100, "ts": 1756428543.028902, "side": "sell"}
{"type": "orderbook_delta", "seq": 7886, "price": 45, "quantity": 100, "ts": 1756428543.028902, "side": "sell"}
{"type": "orderbook_delta", "seq": 7887, "price": 42, "quantity": 78, "ts": 1756428543.062219, "side": "sell"}
{"type": "orderbook_delta", "seq": 7888, "price": 40, "quantity": 500, "ts": 1756428543.070747, "side": "buy"}
{"type": "orderbook_delta", "seq": 7889, "price": 48, "quantity": 250, "ts": 1756428543.102335, "side": "sell"}
{"type": "orderbook_delta", "seq": 7890, "price": 47, "quantity": -949, "ts": 1756428543.103249, "side": "sell"}
{"type": "orderbook_delta", "seq": 7891, "price": 58, "quantity": -250, "ts": 1756428543.104409, "side": "sell"}
{"type": "orderbook_delta", "seq": 7892, "price": 46, "quantity": 949, "ts": 1756428543.152306, "side": "sell"}
{"type": "orderbook_delta", "seq": 7893, "price": 36, "quantity": -1250, "ts": 1756428543.338952, "side": "buy"}
{"type": "orderbook_delta", "seq": 7894, "price": 40, "quantity": -500, "ts": 1756428543.339695, "side": "buy"}
{"type": "orderbook_delta", "seq": 7895, "price": 46, "quantity": -500, "ts": 1756428543.340089, "side": "sell"}
{"type": "orderbook_delta", "seq": 7896, "price": 38, "quantity": -200, "ts": 1756428543.340744, "side": "buy"}
{"type": "orderbook_delta", "seq": 7897, "price": 49, "quantity": -200, "ts": 1756428543.342446, "side": "sell"}
{"type": "orderbook_delta", "seq": 7898, "price": 46, "quantity": -200, "ts": 1756428543.345161, "side": "sell"}
{"type": "orderbook_delta", "seq": 7899, "price": 45, "quantity": 200, "ts": 1756428543.345161, "side": "sell"}
{"type": "orderbook_delta", "seq": 7900, "price": 36, "quantity": 200, "ts": 1756428543.39582, "side": "buy"}
{"type": "orderbook_delta", "seq": 7901, "price": 12, "quantity": -8000, "ts": 1756428543.396089, "side": "buy"}
{"type": "orderbook_delta", "seq": 7902, "price": 44, "quantity": 500, "ts": 1756428543.396315, "side": "sell"}
{"type": "orderbook_delta", "seq": 7903, "price": 38, "quantity": 500, "ts": 1756428543.396545, "side": "buy"}
{"type": "orderbook_delta", "seq": 7904, "price": 45, "quantity": -200, "ts": 1756428543.397361, "side": "sell"}
{"type": "orderbook_delta", "seq": 7905, "price": 46, "quantity": 200, "ts": 1756428543.397361, "side": "sell"}
{"type": "orderbook_delta", "seq": 7906, "price": 47, "quantity": 200, "ts": 1756428543.397647, "side": "sell"}
{"type": "orderbook_delta", "seq": 7907, "price": 34, "quantity": 1250, "ts": 1756428543.397904, "side": "buy"}
{"type": "orderbook_delta", "seq": 7908, "price": 50, "quantity": -1250, "ts": 1756428543.398215, "side": "sell"}
{"type": "orderbook_delta", "seq": 7909, "price": 38, "quantity": -250, "ts": 1756428543.410503, "side": "buy"}
{"type": "orderbook_delta", "seq": 7910, "price": 28, "quantity": 250, "ts": 1756428543.412316, "side": "buy"}
{"type": "orderbook_delta", "seq": 7911, "price": 40, "quantity": -91, "ts": 1756428543.423494, "side": "buy"}
{"type": "orderbook_delta", "seq": 7912, "price": 39, "quantity": 91, "ts": 1756428543.423494, "side": "buy"}
{"type": "orderbook_delta", "seq": 7913, "price": 11, "quantity": 8000, "ts": 1756428543.443612, "side": "buy"}
{"type": "orderbook_delta", "seq": 7914, "price": 36, "quantity": -200, "ts": 1756428543.464675, "side": "buy"}
{"type": "orderbook_delta", "seq": 7915, "price": 39, "quantity": -91, "ts": 1756428543.480272, "side": "buy"}
{"type": "orderbook_delta", "seq": 7916, "price": 36, "quantity": 91, "ts": 1756428543.480272, "side": "buy"}
{"type": "orderbook_delta", "seq": 7917, "price": 38, "quantity": -500, "ts": 1756428543.482119, "side": "buy"}
{"type": "orderbook_delta", "seq": 7918, "price": 47, "quantity": -200, "ts": 1756428543.482919, "side": "sell"}
{"type": "orderbook_delta", "seq": 7919, "price": 49, "quantity": 1250, "ts": 1756428543.485266, "side": "sell"}
{"type": "orderbook_delta", "seq": 7920, "price": 37, "quantity": 500, "ts": 1756428543.511723, "side": "buy"}
{"type": "orderbook_delta", "seq": 7921, "price": 46, "quantity": 200, "ts": 1756428543.530448, "side": "sell"}
{"type": "orderbook_delta", "seq": 7922, "price": 35, "quantity": 200, "ts": 1756428543.531105, "side": "buy"}
{"type": "orderbook_delta", "seq": 7923, "price": 36, "quantity": -91, "ts": 1756428543.531408, "side": "buy"}
{"type": "orderbook_delta", "seq": 7924, "price": 35, "quantity": 91, "ts": 1756428543.531408, "side": "buy"}
{"type": "orderbook_delta", "seq": 7925, "price": 46, "quantity": -200, "ts": 1756428543.581071, "side": "sell"}
{"type": "orderbook_delta", "seq": 7926, "price": 45, "quantity": 200, "ts": 1756428543.581071, "side": "sell"}
{"type": "orderbook_delta", "seq": 7927, "price": 49, "quantity": -1250, "ts": 1756428543.586678, "side": "sell"}
{"type": "orderbook_delta", "seq": 7928, "price": 45, "quantity": -100, "ts": 1756428543.599107, "side": "sell"}
{"type": "orderbook_delta", "seq": 7929, "price": 46, "quantity": 100, "ts": 1756428543.599107, "side": "sell"}
{"type": "orderbook_delta", "seq": 7930, "price": 45, "quantity": -200, "ts": 1756428543.631608, "side": "sell"}
{"type": "orderbook_delta", "seq": 7931, "price": 44, "quantity": 200, "ts": 1756428543.631608, "side": "sell"}
{"type": "orderbook_delta", "seq": 7932, "price": 48, "quantity": 1250, "ts": 1756428543.635796, "side": "sell"}
{"type": "orderbook_delta", "seq": 7933, "price": 46, "quantity": -949, "ts": 1756428544.140767, "side": "sell"}
{"type": "orderbook_delta", "seq": 7934, "price": 56, "quantity": -250, "ts": 1756428544.155986, "side": "sell"}
{"type": "orderbook_delta", "seq": 7935, "price": 11, "quantity": -8000, "ts": 1756428544.164171, "side": "buy"}
{"type": "orderbook_delta", "seq": 7936, "price": 46, "quantity": -200, "ts": 1756428544.166281, "side": "sell"}
{"type": "orderbook_delta", "seq": 7937, "price": 46, "quantity": 250, "ts": 1756428544.166353, "side": "sell"}
{"type": "orderbook_delta", "seq": 7938, "price": 34, "quantity": -1250, "ts": 1756428544.167211, "side": "buy"}
{"type": "orderbook_delta", "seq": 7939, "price": 46, "quantity": 200, "ts": 1756428544.20483, "side": "sell"}
{"type": "orderbook_delta", "seq": 7940, "price": 44, "quantity": 949, "ts": 1756428544.210963, "side": "sell"}
{"type": "orderbook_delta", "seq": 7941, "price": 10, "quantity": 8000, "ts": 1756428544.223554, "side": "buy"}
{"type": "orderbook_delta", "seq": 7942, "price": 33, "quantity": 1250, "ts": 1756428544.225228, "side": "buy"}
{"type": "orderbook_delta", "seq": 7943, "price": 44, "quantity": -500, "ts": 1756428544.300745, "side": "sell"}
{"type": "orderbook_delta", "seq": 7944, "price": 43, "quantity": 500, "ts": 1756428544.357614, "side": "sell"}
{"type": "orderbook_delta", "seq": 7945, "price": 46, "quantity": -100, "ts": 1756428544.718983, "side": "sell"}
{"type": "orderbook_delta", "seq": 7946, "price": 42, "quantity": 100, "ts": 1756428544.718983, "side": "sell"}
{"type": "orderbook_delta", "seq": 7947, "price": 41, "quantity": 0, "ts": 1756428545.080795, "side": "buy"}
{"type": "trade", "seq": 71, "price": 41, "quantity": 82, "ts": 1756428545.138858, "side": "sell"}
{"type": "orderbook_delta", "seq": 7948, "price": 26, "quantity": 250, "ts": 1756428545.138858, "side": "buy"}
{"type": "orderbook_delta", "seq": 7949, "price": 36, "quantity": -250, "ts": 1756428545.141121, "side": "buy"}
{"type": "orderbook_delta", "seq": 7950, "price": 33, "quantity": -1250, "ts": 1756428545.155546, "side": "buy"}
{"type": "orderbook_delta", "seq": 7951, "price": 46, "quantity": -200, "ts": 1756428545.156311, "side": "sell"}
{"type": "orderbook_delta", "seq": 7952, "price": 35, "quantity": -200, "ts": 1756428545.158475, "side": "buy"}
{"type": "orderbook_delta", "seq": 7953, "price": 48, "quantity": -1250, "ts": 1756428545.162403, "side": "sell"}
{"type": "orderbook_delta", "seq": 7954, "price": 43, "quantity": -500, "ts": 1756428545.163521, "side": "sell"}
{"type": "orderbook_delta", "seq": 7955, "price": 97, "quantity": -8000, "ts": 1756428545.163577, "side": "sell"}
{"type": "orderbook_delta", "seq": 7956, "price": 44, "quantity": -200, "ts": 1756428545.166865, "side": "sell"}
{"type": "orderbook_delta", "seq": 7957, "price": 42, "quantity": 200, "ts": 1756428545.166865, "side": "sell"}
{"type": "orderbook_delta", "seq": 7958, "price": 10, "quantity": -8000, "ts": 1756428545.168623, "side": "buy"}
{"type": "orderbook_delta", "seq": 7959, "price": 37, "quantity": -500, "ts": 1756428545.170186, "side": "buy"}
{"type": "orderbook_delta", "seq": 7960, "price": 33, "quantity": 200, "ts": 1756428545.224304, "side": "buy"}
{"type": "orderbook_delta", "seq": 7961, "price": 42, "quantity": 500, "ts": 1756428545.22591, "side": "sell"}
{"type": "orderbook_delta", "seq": 7962, "price": 45, "quantity": 1250, "ts": 1756428545.226263, "side": "sell"}
{"type": "orderbook_delta", "seq": 7963, "price": 35, "quantity": 500, "ts": 1756428545.226548, "side": "buy"}
{"type": "orderbook_delta", "seq": 7964, "price": 68, "quantity": 8000, "ts": 1756428545.226786, "side": "sell"}
{"type": "orderbook_delta", "seq": 7965, "price": 44, "quantity": 200, "ts": 1756428545.22793, "side": "sell"}
{"type": "orderbook_delta", "seq": 7966, "price": 35, "quantity": -91, "ts": 1756428545.235725, "side": "buy"}
{"type": "orderbook_delta", "seq": 7967, "price": 34, "quantity": 91, "ts": 1756428545.235725, "side": "buy"}
{"type": "orderbook_delta", "seq": 7968, "price": 42, "quantity": -200, "ts": 1756428545.237957, "side": "sell"}
{"type": "orderbook_delta", "seq": 7969, "price": 43, "quantity": 200, "ts": 1756428545.237957, "side": "sell"}
{"type": "orderbook_delta", "seq": 7970, "price": 31, "quantity": 1250, "ts": 1756428545.240232, "side": "buy"}
{"type": "orderbook_delta", "seq": 7971, "price": 42, "quantity": -78, "ts": 1756428545.241644, "side": "sell"}
{"type": "orderbook_delta", "seq": 7972, "price": 42, "quantity": -100, "ts": 1756428545.544919, "side": "sell"}
{"type": "orderbook_delta", "seq": 7973, "price": 43, "quantity": 100, "ts": 1756428545.544919, "side": "sell"}
{"type": "orderbook_delta", "seq": 7974, "price": 43, "quantity": -200, "ts": 1756428545.627998, "side": "sell"}
{"type": "orderbook_delta", "seq": 7975, "price": 42, "quantity": 200, "ts": 1756428545.627998, "side": "sell"}
{"type": "orderbook_delta", "seq": 7976, "price": 41, "quantity": -18, "ts": 1756428545.639184, "side": "buy"}
{"type": "orderbook_delta", "seq": 7977, "price": 42, "quantity": -500, "ts": 1756428545.71244, "side": "sell"}
{"type": "orderbook_delta", "seq": 7978, "price": 68, "quantity": -8000, "ts": 1756428545.761327, "side": "sell"}
{"type": "orderbook_delta", "seq": 7979, "price": 45, "quantity": -1250, "ts": 1756428545.766741, "side": "sell"}
{"type": "orderbook_delta", "seq": 7980, "price": 42, "quantity": -200, "ts": 1756428545.770677, "side": "sell"}
{"type": "orderbook_delta", "seq": 7981, "price": 43, "quantity": 200, "ts": 1756428545.770677, "side": "sell"}
{"type": "orderbook_delta", "seq": 7982, "price": 41, "quantity": 500, "ts": 1756428545.773026, "side": "sell"}
{"type": "orderbook_delta", "seq": 7983, "price": 41, "quantity": -500, "ts": 1756428545.831582, "side": "sell"}
{"type": "orderbook_delta", "seq": 7984, "price": 43, "quantity": -200, "ts": 1756428545.83273, "side": "sell"}
{"type": "orderbook_delta", "seq": 7985, "price": 40, "quantity": 200, "ts": 1756428545.83273, "side": "sell"}
{"type": "orderbook_delta", "seq": 7986, "price": 46, "quantity": 1250, "ts": 1756428545.832985, "side": "sell"}
{"type": "orderbook_delta", "seq": 7987, "price": 69, "quantity": 8000, "ts": 1756428545.850639, "side": "sell"}
{"type": "orderbook_delta", "seq": 7988, "price": 42, "quantity": 500, "ts": 1756428545.880272, "side": "sell"}
{"type": "orderbook_delta", "seq": 7989, "price": 44, "quantity": -949, "ts": 1756428546.147183, "side": "sell"}
{"type": "orderbook_delta", "seq": 7990, "price": 44, "quantity": 250, "ts": 1756428546.16658, "side": "sell"}
{"type": "orderbook_delta", "seq": 7991, "price": 44, "quantity": -200, "ts": 1756428546.184146, "side": "sell"}
{"type": "orderbook_delta", "seq": 7992, "price": 54, "quantity": -250, "ts": 1756428546.186022, "side": "sell"}
{"type": "orderbook_delta", "seq": 7993, "price": 34, "quantity": -91, "ts": 1756428546.200115, "side": "buy"}
{"type": "orderbook_delta", "seq": 7994, "price": 33, "quantity": 91, "ts": 1756428546.200115, "side": "buy"}
{"type": "orderbook_delta", "seq": 7995, "price": 44, "quantity": 200, "ts": 1756428546.218926, "side": "sell"}
{"type": "orderbook_delta", "seq": 7996, "price": 42, "quantity": 949, "ts": 1756428546.230275, "side": "sell"}
{"type": "orderbook_delta", "seq": 7997, "price": 42, "quantity": -500, "ts": 1756428546.266612, "side": "sell"}
{"type": "orderbook_delta", "seq": 7998, "price": 44, "quantity": -200, "ts": 1756428546.281309, "side": "sell"}
{"type": "orderbook_delta", "seq": 7999, "price": 33, "quantity": -200, "ts": 1756428546.282548, "side": "buy"}
{"type": "orderbook_delta", "seq": 8000, "price": 31, "quantity": -1250, "ts": 1756428546.286631, "side": "buy"}
{"type": "orderbook_delta", "seq": 8001, "price": 42, "quantity": 500, "ts": 1756428546.324863, "side": "sell"}
{"type": "orderbook_delta", "seq": 8002, "price": 34, "quantity": 200, "ts": 1756428546.347185, "side": "buy"}
{"type": "orderbook_delta", "seq": 8003, "price": 32, "quantity": 1250, "ts": 1756428546.34767, "side": "buy"}
{"type": "orderbook_delta", "seq": 8004, "price": 45, "quantity": 200, "ts": 1756428546.35082, "side": "sell"}
{"type": "orderbook_delta", "seq": 8005, "price": 43, "quantity": -100, "ts": 1756428547.127019, "side": "sell"}
{"type": "orderbook_delta", "seq": 8006, "price": 39, "quantity": 100, "ts": 1756428547.127019, "side": "sell"}
{"type": "orderbook_delta", "seq": 8007, "price": 34, "quantity": -200, "ts": 1756428547.129899, "side": "buy"}
{"type": "orderbook_delta", "seq": 8008, "price": 32, "quantity": -1250, "ts": 1756428547.132284, "side": "buy"}
{"type": "orderbook_delta", "seq": 8009, "price": 42, "quantity": -500, "ts": 1756428547.142432, "side": "sell"}
{"type": "orderbook_delta", "seq": 8010, "price": 69, "quantity": -8000, "ts": 1756428547.163007, "side": "sell"}
{"type": "orderbook_delta", "seq": 8011, "price": 45, "quantity": -200, "ts": 1756428547.17017, "side": "sell"}
{"type": "orderbook_delta", "seq": 8012, "price": 41, "quantity": 500, "ts": 1756428547.221197, "side": "sell"}
{"type": "orderbook_delta", "seq": 8013, "price": 68, "quantity": 8000, "ts": 1756428547.224195, "side": "sell"}
{"type": "orderbook_delta", "seq": 8014, "price": 44, "quantity": 200, "ts": 1756428547.224534, "side": "sell"}
{"type": "orderbook_delta", "seq": 8015, "price": 31, "quantity": 1250, "ts": 1756428547.226857, "side": "buy"}
{"type": "orderbook_delta", "seq": 8016, "price": 33, "quantity": 200, "ts": 1756428547.264607, "side": "buy"}
{"type": "orderbook_delta", "seq": 8017, "price": 39, "quantity": -100, "ts": 1756428547.655235, "side": "sell"}
{"type": "orderbook_delta", "seq": 8018, "price": 41, "quantity": 100, "ts": 1756428547.655235, "side": "sell"}
{"type": "orderbook_delta", "seq": 8019, "price": 41, "quantity": -100, "ts": 1756428548.032461, "side": "sell"}
{"type": "orderbook_delta", "seq": 8020, "price": 43, "quantity": 100, "ts": 1756428548.032461, "side": "sell"}
{"type": "orderbook_delta", "seq": 8021, "price": 34, "quantity": -250, "ts": 1756428548.113197, "side": "buy"}
{"type": "orderbook_delta", "seq": 8022, "price": 24, "quantity": 250, "ts": 1756428548.11626, "side": "buy"}
{"type": "orderbook_delta", "seq": 8023, "price": 41, "quantity": -500, "ts": 1756428548.121205, "side": "sell"}
{"type": "orderbook_delta", "seq": 8024, "price": 44, "quantity": -200, "ts": 1756428548.121339, "side": "sell"}
{"type": "orderbook_delta", "seq": 8025, "price": 31, "quantity": -1250, "ts": 1756428548.122257, "side": "buy"}
{"type": "orderbook_delta", "seq": 8026, "price": 68, "quantity": -8000, "ts": 1756428548.122348, "side": "sell"}
{"type": "orderbook_delta", "seq": 8027, "price": 33, "quantity": -200, "ts": 1756428548.12414, "side": "buy"}
{"type": "orderbook_delta", "seq": 8028, "price": 33, "quantity": 200, "ts": 1756428548.163343, "side": "buy"}
{"type": "orderbook_delta", "seq": 8029, "price": 45, "quantity": 200, "ts": 1756428548.164603, "side": "sell"}
{"type": "orderbook_delta", "seq": 8030, "price": 69, "quantity": 8000, "ts": 1756428548.164877, "side": "sell"}
{"type": "orderbook_delta", "seq": 8031, "price": 42, "quantity": 500, "ts": 1756428548.16546, "side": "sell"}
{"type": "orderbook_delta", "seq": 8032, "price": 32, "quantity": 1250, "ts": 1756428548.165946, "side": "buy"}
{"type": "orderbook_delta", "seq": 8033, "price": 98, "quantity": -8100, "ts": 1756428548.171266, "side": "sell"}
{"type": "orderbook_delta", "seq": 8034, "price": 96, "quantity": 4050, "ts": 1756428548.171266, "side": "sell"}
{"type": "orderbook_delta", "seq": 8035, "price": 54, "quantity": 250, "ts": 1756428548.19811, "side": "sell"}
{"type": "orderbook_delta", "seq": 8036, "price": 42, "quantity": -949, "ts": 1756428548.20075, "side": "sell"}
{"type": "orderbook_delta", "seq": 8037, "price": 44, "quantity": -250, "ts": 1756428548.216802, "side": "sell"}
{"type": "orderbook_delta", "seq": 8038, "price": 40, "quantity": -200, "ts": 1756428548.217579, "side": "sell"}
{"type": "orderbook_delta", "seq": 8039, "price": 41, "quantity": 200, "ts": 1756428548.217579, "side": "sell"}
{"type": "orderbook_delta", "seq": 8040, "price": 97, "quantity": -7000, "ts": 1756428548.218597, "side": "sell"}
{"type": "orderbook_delta", "seq": 8041, "price": 46, "quantity": -1250, "ts": 1756428548.22073, "side": "sell"}
{"type": "orderbook_delta", "seq": 8042, "price": 10, "quantity": 8000, "ts": 1756428548.224695, "side": "buy"}
{"type": "orderbook_delta", "seq": 8043, "price": 69, "quantity": -8000, "ts": 1756428548.235851, "side": "sell"}
{"type": "orderbook_delta", "seq": 8044, "price": 32, "quantity": -1250, "ts": 1756428548.237831, "side": "buy"}
{"type": "orderbook_delta", "seq": 8045, "price": 42, "quantity": -500, "ts": 1756428548.238785, "side": "sell"}
{"type": "orderbook_delta", "seq": 8046, "price": 44, "quantity": 949, "ts": 1756428548.256645, "side": "sell"}
{"type": "orderbook_delta", "seq": 8047, "price": 43, "quantity": -100, "ts": 1756428548.258979, "side": "sell"}
{"type": "orderbook_delta", "seq": 8048, "price": 44, "quantity": 100, "ts": 1756428548.258979, "side": "sell"}
{"type": "orderbook_delta", "seq": 8049, "price": 95, "quantity": 7000, "ts": 1756428548.263547, "side": "sell"}
{"type": "orderbook_delta", "seq": 8050, "price": 41, "quantity": -200, "ts": 1756428548.268593, "side": "sell"}
{"type": "orderbook_delta", "seq": 8051, "price": 43, "quantity": 200, "ts": 1756428548.268593, "side": "sell"}
{"type": "orderbook_delta", "seq": 8052, "price": 45, "quantity": -200, "ts": 1756428548.269271, "side": "sell"}
{"type": "orderbook_delta", "seq": 8053, "price": 48, "quantity": 1250, "ts": 1756428548.269692, "side": "sell"}
{"type": "orderbook_delta", "seq": 8054, "price": 44, "quantity": 500, "ts": 1756428548.325227, "side": "sell"}
{"type": "orderbook_delta", "seq": 8055, "price": 33, "quantity": 1250, "ts": 1756428548.326608, "side": "buy"}
{"type": "orderbook_delta", "seq": 8056, "price": 95, "quantity": 8000, "ts": 1756428548.331054, "side": "sell"}
{"type": "orderbook_delta", "seq": 8057, "price": 46, "quantity": 200, "ts": 1756428548.337902, "side": "sell"}
{"type": "orderbook_delta", "seq": 8058, "price": 44, "quantity": -100, "ts": 1756428548.41416, "side": "sell"}
{"type": "orderbook_delta", "seq": 8059, "price": 45, "quantity": 100, "ts": 1756428548.41416, "side": "sell"}
{"type": "orderbook_delta", "seq": 8060, "price": 10, "quantity": -8000, "ts": 1756428548.52957, "side": "buy"}
{"type": "orderbook_delta", "seq": 8061, "price": 11, "quantity": 8000, "ts": 1756428548.577135, "side": "buy"}
{"type": "orderbook_delta", "seq": 8062, "price": 43, "quantity": -200, "ts": 1756428548.631688, "side": "sell"}
{"type": "orderbook_delta", "seq": 8063, "price": 42, "quantity": 200, "ts": 1756428548.631688, "side": "sell"}
{"type": "orderbook_delta", "seq": 8064, "price": 48, "quantity": -1250, "ts": 1756428548.728128, "side": "sell"}
{"type": "orderbook_delta", "seq": 8065, "price": 46, "quantity": -200, "ts": 1756428548.731772, "side": "sell"}
{"type": "orderbook_delta", "seq": 8066, "price": 49, "quantity": 1250, "ts": 1756428548.766577, "side": "sell"}
{"type": "orderbook_delta", "seq": 8067, "price": 47, "quantity": 200, "ts": 1756428548.77768, "side": "sell"}
{"type": "orderbook_delta", "seq": 8068, "price": 36, "quantity": 100, "ts": 1756428548.974756, "side": "buy"}
{"type": "orderbook_delta", "seq": 8069, "price": 35, "quantity": -500, "ts": 1756428549.003175, "side": "buy"}
{"type": "orderbook_delta", "seq": 8070, "price": 37, "quantity": 500, "ts": 1756428549.038373, "side": "buy"}
{"type": "orderbook_delta", "seq": 8071, "price": 47, "quantity": -200, "ts": 1756428549.11828, "side": "sell"}
{"type": "orderbook_delta", "seq": 8072, "price": 49, "quantity": -1250, "ts": 1756428549.118336, "side": "sell"}
{"type": "orderbook_delta", "seq": 8073, "price": 11, "quantity": -8000, "ts": 1756428549.119215, "side": "buy"}
{"type": "orderbook_delta", "seq": 8074, "price": 44, "quantity": -500, "ts": 1756428549.122164, "side": "sell"}
{"type": "orderbook_delta", "seq": 8075, "price": 34, "quantity": 250, "ts": 1756428549.146632, "side": "buy"}
{"type": "orderbook_delta", "seq": 8076, "price": 24, "quantity": -250, "ts": 1756428549.147402, "side": "buy"}
{"type": "orderbook_delta", "seq": 8077, "price": 36, "quantity": 250, "ts": 1756428549.167036, "side": "buy"}
{"type": "orderbook_delta", "seq": 8078, "price": 10, "quantity": 8000, "ts": 1756428549.169701, "side": "buy"}
{"type": "orderbook_delta", "seq": 8079, "price": 46, "quantity": 200, "ts": 1756428549.17, "side": "sell"}
{"type": "orderbook_delta", "seq": 8080, "price": 48, "quantity": 1250, "ts": 1756428549.172802, "side": "sell"}
{"type": "orderbook_delta", "seq": 8081, "price": 43, "quantity": 500, "ts": 1756428549.17488, "side": "sell"}
{"type": "orderbook_delta", "seq": 8082, "price": 33, "quantity": -200, "ts": 1756428549.181901, "side": "buy"}
{"type": "orderbook_delta", "seq": 8083, "price": 26, "quantity": -250, "ts": 1756428549.186433, "side": "buy"}
{"type": "orderbook_delta", "seq": 8084, "price": 35, "quantity": 200, "ts": 1756428549.254154, "side": "buy"}
{"type": "orderbook_delta", "seq": 8085, "price": 36, "quantity": -250, "ts": 1756428549.40975, "side": "buy"}
{"type": "orderbook_delta", "seq": 8086, "price": 26, "quantity": 250, "ts": 1756428549.40984, "side": "buy"}
{"type": "orderbook_delta", "seq": 8087, "price": 42, "quantity": -200, "ts": 1756428549.583236, "side": "sell"}
{"type": "orderbook_delta", "seq": 8088, "price": 41, "quantity": 200, "ts": 1756428549.583236, "side": "sell"}
{"type": "orderbook_delta", "seq": 8089, "price": 33, "quantity": -91, "ts": 1756428549.593137, "side": "buy"}
{"type": "orderbook_delta", "seq": 8090, "price": 37, "quantity": 91, "ts": 1756428549.593137, "side": "buy"}
{"type": "orderbook_delta", "seq": 8091, "price": 41, "quantity": -200, "ts": 1756428549.628769, "side": "sell"}
{"type": "orderbook_delta", "seq": 8092, "price": 42, "quantity": 200, "ts": 1756428549.628769, "side": "sell"}
{"type": "orderbook_delta", "seq": 8093, "price": 37, "quantity": -91, "ts": 1756428549.743067, "side": "buy"}
{"type": "orderbook_delta", "seq": 8094, "price": 35, "quantity": 91, "ts": 1756428549.743067, "side": "buy"}
{"type": "orderbook_delta", "seq": 8095, "price": 48, "quantity": -1250, "ts": 1756428549.871705, "side": "sell"}
{"type": "orderbook_delta", "seq": 8096, "price": 35, "quantity": -200, "ts": 1756428549.873093, "side": "buy"}
{"type": "orderbook_delta", "seq": 8097, "price": 95, "quantity": -8000, "ts": 1756428549.8758, "side": "sell"}
{"type": "orderbook_delta", "seq": 8098, "price": 46, "quantity": -200, "ts": 1756428549.876144, "side": "sell"}
{"type": "orderbook_delta", "seq": 8099, "price": 33, "quantity": -1250, "ts": 1756428549.876378, "side": "buy"}
{"type": "orderbook_delta", "seq": 8100, "price": 43, "quantity": -500, "ts": 1756428549.87816, "side": "sell"}
{"type": "orderbook_delta", "seq": 8101, "price": 35, "quantity": -91, "ts": 1756428549.879012, "side": "buy"}
{"type": "orderbook_delta", "seq": 8102, "price": 33, "quantity": 91, "ts": 1756428549.879012, "side": "buy"}
{"type": "orderbook_delta", "seq": 8103, "price": 42, "quantity": 500, "ts": 1756428549.925619, "side": "sell"}
{"type": "orderbook_delta", "seq": 8104, "price": 45, "quantity": 200, "ts": 1756428549.925955, "side": "sell"}
{"type": "orderbook_delta", "seq": 8105, "price": 34, "quantity": 200, "ts": 1756428549.926957, "side": "buy"}
{"type": "orderbook_delta", "seq": 8106, "price": 32, "quantity": 1250, "ts": 1756428549.927314, "side": "buy"}
{"type": "orderbook_delta", "seq": 8107, "price": 10, "quantity": -8000, "ts": 1756428549.933007, "side": "buy"}
{"type": "orderbook_delta", "seq": 8108, "price": 37, "quantity": -500, "ts": 1756428549.935207, "side": "buy"}
{"type": "orderbook_delta", "seq": 8109, "price": 47, "quantity": 1250, "ts": 1756428549.935329, "side": "sell"}
{"type": "orderbook_delta", "seq": 8110, "price": 70, "quantity": 8000, "ts": 1756428549.973963, "side": "sell"}
{"type": "orderbook_delta", "seq": 8111, "price": 42, "quantity": -200, "ts": 1756428549.981474, "side": "sell"}
{"type": "orderbook_delta", "seq": 8112, "price": 41, "quantity": 200, "ts": 1756428549.981474, "side": "sell"}
{"type": "orderbook_delta", "seq": 8113, "price": 36, "quantity": 500, "ts": 1756428549.983475, "side": "buy"}
{"type": "orderbook_delta", "seq": 8114, "price": 47, "quantity": -1250, "ts": 1756428549.984102, "side": "sell"}
{"type": "orderbook_delta", "seq": 8115, "price": 45, "quantity": -100, "ts": 1756428550.008113, "side": "sell"}
{"type": "orderbook_delta", "seq": 8116, "price": 41, "quantity": 100, "ts": 1756428550.008113, "side": "sell"}
{"type": "orderbook_delta", "seq": 8117, "price": 46, "quantity": 1250, "ts": 1756428550.016328, "side": "sell"}
{"type": "orderbook_delta", "seq": 8118, "price": 70, "quantity": -8000, "ts": 1756428550.017437, "side": "sell"}
{"type": "orderbook_delta", "seq": 8119, "price": 45, "quantity": -200, "ts": 1756428550.036756, "side": "sell"}
{"type": "orderbook_delta", "seq": 8120, "price": 32, "quantity": -1250, "ts": 1756428550.037235, "side": "buy"}
{"type": "orderbook_delta", "seq": 8121, "price": 34, "quantity": -200, "ts": 1756428550.039259, "side": "buy"}
{"type": "orderbook_delta", "seq": 8122, "price": 42, "quantity": -500, "ts": 1756428550.04719, "side": "sell"}
{"type": "orderbook_delta", "seq": 8123, "price": 33, "quantity": 200, "ts": 1756428550.075832, "side": "buy"}
{"type": "orderbook_delta", "seq": 8124, "price": 44, "quantity": 200, "ts": 1756428550.076174, "side": "sell"}
{"type": "orderbook_delta", "seq": 8125, "price": 31, "quantity": 1250, "ts": 1756428550.076416, "side": "buy"}
{"type": "orderbook_delta", "seq": 8126, "price": 41, "quantity": -100, "ts": 1756428550.166263, "side": "sell"}
{"type": "orderbook_delta", "seq": 8127, "price": 43, "quantity": 100, "ts": 1756428550.166263, "side": "sell"}
{"type": "orderbook_delta", "seq": 8128, "price": 68, "quantity": 8000, "ts": 1756428550.169499, "side": "sell"}
{"type": "orderbook_delta", "seq": 8129, "price": 44, "quantity": -949, "ts": 1756428550.170879, "side": "sell"}
{"type": "orderbook_delta", "seq": 8130, "price": 41, "quantity": 500, "ts": 1756428550.171231, "side": "sell"}
{"type": "orderbook_delta", "seq": 8131, "price": 24, "quantity": 250, "ts": 1756428550.188339, "side": "buy"}
{"type": "orderbook_delta", "seq": 8132, "price": 34, "quantity": -250, "ts": 1756428550.188745, "side": "buy"}
{"type": "orderbook_delta", "seq": 8133, "price": 44, "quantity": -200, "ts": 1756428550.206595, "side": "sell"}
{"type": "orderbook_delta", "seq": 8134, "price": 44, "quantity": 250, "ts": 1756428550.207641, "side": "sell"}
{"type": "orderbook_delta", "seq": 8135, "price": 41, "quantity": -200, "ts": 1756428550.224515, "side": "sell"}
{"type": "orderbook_delta", "seq": 8136, "price": 40, "quantity": 200, "ts": 1756428550.224515, "side": "sell"}
{"type": "orderbook_delta", "seq": 8137, "price": 54, "quantity": -250, "ts": 1756428550.226922, "side": "sell"}
{"type": "orderbook_delta", "seq": 8138, "price": 45, "quantity": 200, "ts": 1756428550.24169, "side": "sell"}
{"type": "orderbook_delta", "seq": 8139, "price": 42, "quantity": 949, "ts": 1756428550.267685, "side": "sell"}
{"type": "orderbook_delta", "seq": 8140, "price": 41, "quantity": -500, "ts": 1756428550.309148, "side": "sell"}
{"type": "orderbook_delta", "seq": 8141, "price": 31, "quantity": -1250, "ts": 1756428550.309306, "side": "buy"}
{"type": "orderbook_delta", "seq": 8142, "price": 68, "quantity": -8000, "ts": 1756428550.310328, "side": "sell"}
{"type": "orderbook_delta", "seq": 8143, "price": 42, "quantity": 500, "ts": 1756428550.361833, "side": "sell"}
{"type": "orderbook_delta", "seq": 8144, "price": 32, "quantity": 1250, "ts": 1756428550.362355, "side": "buy"}
{"type": "orderbook_delta", "seq": 8145, "price": 69, "quantity": 8000, "ts": 1756428550.364624, "side": "sell"}
{"type": "orderbook_delta", "seq": 8146, "price": 45, "quantity": -200, "ts": 1756428550.390491, "side": "sell"}
{"type": "orderbook_delta", "seq": 8147, "price": 44, "quantity": 200, "ts": 1756428550.426153, "side": "sell"}
{"type": "orderbook_delta", "seq": 8148, "price": 40, "quantity": -200, "ts": 1756428550.618237, "side": "sell"}
{"type": "orderbook_delta", "seq": 8149, "price": 41, "quantity": 200, "ts": 1756428550.618237, "side": "sell"}
{"type": "orderbook_delta", "seq": 8150, "price": 32, "quantity": -1250, "ts": 1756428550.667661, "side": "buy"}
{"type": "orderbook_delta", "seq": 8151, "price": 42, "quantity": -500, "ts": 1756428550.667776, "side": "sell"}
{"type": "orderbook_delta", "seq": 8152, "price": 47, "quantity": 1, "ts": 1756428550.671081, "side": "sell"}
{"type": "orderbook_delta", "seq": 8153, "price": 41, "quantity": 500, "ts": 1756428550.706519, "side": "sell"}
{"type": "orderbook_delta", "seq": 8154, "price": 31, "quantity": 1250, "ts": 1756428550.728323, "side": "buy"}
{"type": "orderbook_delta", "seq": 8155, "price": 41, "quantity": -200, "ts": 1756428550.767324, "side": "sell"}
{"type": "orderbook_delta", "seq": 8156, "price": 40, "quantity": 200, "ts": 1756428550.767324, "side": "sell"}
{"type": "orderbook_delta", "seq": 8157, "price": 36, "quantity": -100, "ts": 1756428551.284241, "side": "buy"}
{"type": "orderbook_delta", "seq": 8158, "price": 31, "quantity": -1250, "ts": 1756428551.296776, "side": "buy"}
{"type": "orderbook_delta", "seq": 8159, "price": 41, "quantity": -500, "ts": 1756428551.296882, "side": "sell"}
{"type": "orderbook_delta", "seq": 8160, "price": 36, "quantity": -500, "ts": 1756428551.39058, "side": "buy"}
{"type": "orderbook_delta", "seq": 8161, "price": 42, "quantity": 500, "ts": 1756428551.392135, "side": "sell"}
{"type": "orderbook_delta", "seq": 8162, "price": 32, "quantity": 1250, "ts": 1756428551.392386, "side": "buy"}
{"type": "orderbook_delta", "seq": 8163, "price": 35, "quantity": 500, "ts": 1756428551.443337, "side": "buy"}
{"type": "orderbook_delta", "seq": 8164, "price": 33, "quantity": -91, "ts": 1756428551.443839, "side": "buy"}
{"type": "orderbook_delta", "seq": 8165, "price": 34, "quantity": 91, "ts": 1756428551.443839, "side": "buy"}
{"type": "orderbook_delta", "seq": 8166, "price": 37, "quantity": 100, "ts": 1756428551.560975, "side": "buy"}
{"type": "orderbook_delta", "seq": 8167, "price": 34, "quantity": -91, "ts": 1756428551.681612, "side": "buy"}
{"type": "orderbook_delta", "seq": 8168, "price": 36, "quantity": 91, "ts": 1756428551.681612, "side": "buy"}
{"type": "orderbook_delta", "seq": 8169, "price": 35, "quantity": -500, "ts": 1756428551.721962, "side": "buy"}
{"type": "orderbook_delta", "seq": 8170, "price": 36, "quantity": 500, "ts": 1756428551.759947, "side": "buy"}
{"type": "orderbook_delta", "seq": 8171, "price": 36, "quantity": -91, "ts": 1756428551.766988, "side": "buy"}
{"type": "orderbook_delta", "seq": 8172, "price": 35, "quantity": 91, "ts": 1756428551.766988, "side": "buy"}
{"type": "orderbook_delta", "seq": 8173, "price": 43, "quantity": -100, "ts": 1756428551.83794, "side": "sell"}
{"type": "orderbook_delta", "seq": 8174, "price": 41, "quantity": 100, "ts": 1756428551.83794, "side": "sell"}
{"type": "orderbook_delta", "seq": 8175, "price": 96, "quantity": -4050, "ts": 1756428551.913619, "side": "sell"}
{"type": "orderbook_delta", "seq": 8176, "price": 98, "quantity": 8100, "ts": 1756428551.913619, "side": "sell"}
{"type": "orderbook_delta", "seq": 8177, "price": 95, "quantity": -7000, "ts": 1756428551.946864, "side": "sell"}
{"type": "orderbook_delta", "seq": 8178, "price": 97, "quantity": 7000, "ts": 1756428552.009491, "side": "sell"}
{"type": "orderbook_delta", "seq": 8179, "price": 41, "quantity": -100, "ts": 1756428552.34604, "side": "sell"}
{"type": "orderbook_delta", "seq": 8180, "price": 42, "quantity": 100, "ts": 1756428552.34604, "side": "sell"}
{"type": "orderbook_delta", "seq": 8181, "price": 46, "quantity": -1250, "ts": 1756428552.447997, "side": "sell"}
{"type": "orderbook_delta", "seq": 8182, "price": 42, "quantity": -500, "ts": 1756428552.448643, "side": "sell"}
{"type": "orderbook_delta", "seq": 8183, "price": 32, "quantity": -1250, "ts": 1756428552.450553, "side": "buy"}
{"type": "orderbook_delta", "seq": 8184, "price": 69, "quantity": -8000, "ts": 1756428552.451155, "side": "sell"}
{"type": "orderbook_delta", "seq": 8185, "price": 36, "quantity": -500, "ts": 1756428552.45131, "side": "buy"}
{"type": "orderbook_delta", "seq": 8186, "price": 44, "quantity": -200, "ts": 1756428552.473274, "side": "sell"}
{"type": "orderbook_delta", "seq": 8187, "price": 33, "quantity": -200, "ts": 1756428552.477616, "side": "buy"}
{"type": "orderbook_delta", "seq": 8188, "price": 40, "quantity": -200, "ts": 1756428552.487993, "side": "sell"}
{"type": "orderbook_delta", "seq": 8189, "price": 41, "quantity": 200, "ts": 1756428552.487993, "side": "sell"}
{"type": "orderbook_delta", "seq": 8190, "price": 35, "quantity": -91, "ts": 1756428552.490866, "side": "buy"}
{"type": "orderbook_delta", "seq": 8191, "price": 34, "quantity": 91, "ts": 1756428552.490866, "side": "buy"}
{"type": "orderbook_delta", "seq": 8192, "price": 68, "quantity": 8000, "ts": 1756428552.497781, "side": "sell"}
{"type": "orderbook_delta", "seq": 8193, "price": 44, "quantity": 1250, "ts": 1756428552.500021, "side": "sell"}
{"type": "orderbook_delta", "seq": 8194, "price": 34, "quantity": 500, "ts": 1756428552.501342, "side": "buy"}
{"type": "orderbook_delta", "seq": 8195, "price": 30, "quantity": 1250, "ts": 1756428552.506839, "side": "buy"}
{"type": "orderbook_delta", "seq": 8196, "price": 40, "quantity": 500, "ts": 1756428552.509129, "side": "sell"}
{"type": "orderbook_delta", "seq": 8197, "price": 32, "quantity": 200, "ts": 1756428552.512148, "side": "buy"}
{"type": "orderbook_delta", "seq": 8198, "price": 43, "quantity": 200, "ts": 1756428552.512729, "side": "sell"}
{"type": "orderbook_delta", "seq": 8199, "price": 32, "quantity": -250, "ts": 1756428552.527067, "side": "buy"}
{"type": "orderbook_delta", "seq": 8200, "price": 22, "quantity": 250, "ts": 1756428552.528335, "side": "buy"}
{"type": "orderbook_delta", "seq": 8201, "price": 34, "quantity": -91, "ts": 1756428552.538054, "side": "buy"}
{"type": "orderbook_delta", "seq": 8202, "price": 33, "quantity": 91, "ts": 1756428552.538054, "side": "buy"}
{"type": "orderbook_delta", "seq": 8203, "price": 41, "quantity": -200, "ts": 1756428552.561729, "side": "sell"}
{"type": "orderbook_delta", "seq": 8204, "price": 39, "quantity": 200, "ts": 1756428552.561729, "side": "sell"}
{"type": "orderbook_delta", "seq": 8205, "price": 22, "quantity": -250, "ts": 1756428552.571041, "side": "buy"}
{"type": "orderbook_delta", "seq": 8206, "price": 32, "quantity": -200, "ts": 1756428552.591983, "side": "buy"}
{"type": "orderbook_delta", "seq": 8207, "price": 40, "quantity": -500, "ts": 1756428552.595361, "side": "sell"}
{"type": "orderbook_delta", "seq": 8208, "price": 31, "quantity": 200, "ts": 1756428552.644251, "side": "buy"}
{"type": "orderbook_delta", "seq": 8209, "price": 41, "quantity": 500, "ts": 1756428552.649393, "side": "sell"}
{"type": "orderbook_delta", "seq": 8210, "price": 68, "quantity": -8000, "ts": 1756428552.709554, "side": "sell"}
{"type": "orderbook_delta", "seq": 8211, "price": 43, "quantity": -200, "ts": 1756428552.709921, "side": "sell"}
{"type": "orderbook_delta", "seq": 8212, "price": 66, "quantity": 8000, "ts": 1756428552.755222, "side": "sell"}
{"type": "orderbook_delta", "seq": 8213, "price": 42, "quantity": 200, "ts": 1756428552.77851, "side": "sell"}
{"type": "orderbook_delta", "seq": 8214, "price": 41, "quantity": -500, "ts": 1756428552.924042, "side": "sell"}
{"type": "orderbook_delta", "seq": 8215, "price": 39, "quantity": 500, "ts": 1756428552.949387, "side": "sell"}
{"type": "orderbook_delta", "seq": 8216, "price": 39, "quantity": -200, "ts": 1756428552.995745, "side": "sell"}
{"type": "orderbook_delta", "seq": 8217, "price": 38, "quantity": 200, "ts": 1756428552.995745, "side": "sell"}
{"type": "orderbook_delta", "seq": 8218, "price": 39, "quantity": -500, "ts": 1756428553.032499, "side": "sell"}
{"type": "orderbook_delta", "seq": 8219, "price": 41, "quantity": 500, "ts": 1756428553.069247, "side": "sell"}
{"type": "orderbook_delta", "seq": 8220, "price": 47, "quantity": 1, "ts": 1756428553.074856, "side": "sell"}
{"type": "orderbook_delta", "seq": 8221, "price": 42, "quantity": 250, "ts": 1756428553.095205, "side": "sell"}
{"type": "orderbook_delta", "seq": 8222, "price": 42, "quantity": -949, "ts": 1756428553.096509, "side": "sell"}
{"type": "orderbook_delta", "seq": 8223, "price": 52, "quantity": -250, "ts": 1756428553.116652, "side": "sell"}
{"type": "orderbook_delta", "seq": 8224, "price": 40, "quantity": 949, "ts": 1756428553.183549, "side": "sell"}
{"type": "orderbook_delta", "seq": 8225, "price": 41, "quantity": -500, "ts": 1756428553.234091, "side": "sell"}
{"type": "orderbook_delta", "seq": 8226, "price": 22, "quantity": 250, "ts": 1756428553.454282, "side": "buy"}
{"type": "orderbook_delta", "seq": 8227, "price": 34, "quantity": -500, "ts": 1756428553.454756, "side": "buy"}
{"type": "orderbook_delta", "seq": 8228, "price": 44, "quantity": -1250, "ts": 1756428553.454889, "side": "sell"}
{"type": "orderbook_delta", "seq": 8229, "price": 38, "quantity": -200, "ts": 1756428553.455256, "side": "sell"}
{"type": "orderbook_delta", "seq": 8230, "price": 39, "quantity": 200, "ts": 1756428553.455256, "side": "sell"}
{"type": "orderbook_delta", "seq": 8231, "price": 39, "quantity": 500, "ts": 1756428553.456249, "side": "sell"}
{"type": "orderbook_delta", "seq": 8232, "price": 30, "quantity": -1250, "ts": 1756428553.459163, "side": "buy"}
{"type": "orderbook_delta", "seq": 8233, "price": 39, "quantity": -500, "ts": 1756428553.505774, "side": "sell"}
{"type": "orderbook_delta", "seq": 8234, "price": 40, "quantity": 500, "ts": 1756428553.606218, "side": "sell"}
{"type": "orderbook_delta", "seq": 8235, "price": 34, "quantity": 500, "ts": 1756428553.614555, "side": "buy"}
{"type": "orderbook_delta", "seq": 8236, "price": 30, "quantity": 1250, "ts": 1756428553.615101, "side": "buy"}
{"type": "orderbook_delta", "seq": 8237, "price": 44, "quantity": 1250, "ts": 1756428553.615598, "side": "sell"}
{"type": "orderbook_delta", "seq": 8238, "price": 98, "quantity": -8100, "ts": 1756428553.689627, "side": "sell"}
{"type": "orderbook_delta", "seq": 8239, "price": 99, "quantity": 16200, "ts": 1756428553.689627, "side": "sell"}
{"type": "orderbook_delta", "seq": 8240, "price": 97, "quantity": -7000, "ts": 1756428553.745669, "side": "sell"}
{"type": "orderbook_delta", "seq": 8241, "price": 40, "quantity": 160, "ts": 1756428553.813992, "side": "sell"}
{"type": "orderbook_delta", "seq": 8242, "price": 98, "quantity": 7000, "ts": 1756428553.828889, "side": "sell"}
{"type": "orderbook_delta", "seq": 8243, "price": 42, "quantity": -100, "ts": 1756428553.906055, "side": "sell"}
{"type": "orderbook_delta", "seq": 8244, "price": 40, "quantity": 100, "ts": 1756428553.906055, "side": "sell"}
{"type": "orderbook_delta", "seq": 8245, "price": 33, "quantity": -91, "ts": 1756428554.064869, "side": "buy"}
{"type": "orderbook_delta", "seq": 8246, "price": 34, "quantity": 91, "ts": 1756428554.064869, "side": "buy"}
{"type": "orderbook_delta", "seq": 8247, "price": 22, "quantity": -250, "ts": 1756428554.119791, "side": "buy"}
{"type": "orderbook_delta", "seq": 8248, "price": 32, "quantity": 250, "ts": 1756428554.144448, "side": "buy"}
{"type": "orderbook_delta", "seq": 8249, "price": 40, "quantity": -100, "ts": 1756428554.207093, "side": "sell"}
{"type": "orderbook_delta", "seq": 8250, "price": 39, "quantity": 100, "ts": 1756428554.207093, "side": "sell"}
{"type": "orderbook_delta", "seq": 8251, "price": 34, "quantity": -91, "ts": 1756428554.645333, "side": "buy"}
{"type": "orderbook_delta", "seq": 8252, "price": 33, "quantity": 91, "ts": 1756428554.645333, "side": "buy"}
{"type": "orderbook_delta", "seq": 8253, "price": 33, "quantity": -91, "ts": 1756428554.704171, "side": "buy"}
{"type": "orderbook_delta", "seq": 8254, "price": 32, "quantity": 91, "ts": 1756428554.704171, "side": "buy"}
{"type": "orderbook_delta", "seq": 8255, "price": 39, "quantity": -100, "ts": 1756428554.750841, "side": "sell"}
{"type": "orderbook_delta", "seq": 8256, "price": 40, "quantity": 100, "ts": 1756428554.750841, "side": "sell"}
{"type": "orderbook_delta", "seq": 8257, "price": 40, "quantity": -100, "ts": 1756428554.802707, "side": "sell"}
{"type": "orderbook_delta", "seq": 8258, "price": 42, "quantity": 100, "ts": 1756428554.802707, "side": "sell"}
{"type": "orderbook_delta", "seq": 8259, "price": 66, "quantity": -99, "ts": 1756428555.799463, "side": "sell"}
{"type": "orderbook_delta", "seq": 8260, "price": 66, "quantity": -8000, "ts": 1756428555.885559, "side": "sell"}
{"type": "orderbook_delta", "seq": 8261, "price": 68, "quantity": 8000, "ts": 1756428555.935743, "side": "sell"}
{"type": "orderbook_delta", "seq": 8262, "price": 40, "quantity": -949, "ts": 1756428556.105672, "side": "sell"}
{"type": "orderbook_delta", "seq": 8263, "price": 52, "quantity": 250, "ts": 1756428556.106142, "side": "sell"}
{"type": "orderbook_delta", "seq": 8264, "price": 42, "quantity": -250, "ts": 1756428556.127231, "side": "sell"}
{"type": "orderbook_delta", "seq": 8265, "price": 41, "quantity": 949, "ts": 1756428556.171285, "side": "sell"}
{"type": "orderbook_delta", "seq": 8266, "price": 42, "quantity": -200, "ts": 1756428556.171575, "side": "sell"}
{"type": "orderbook_delta", "seq": 8267, "price": 43, "quantity": 200, "ts": 1756428556.208388, "side": "sell"}
{"type": "orderbook_delta", "seq": 8268, "price": 32, "quantity": -91, "ts": 1756428556.619975, "side": "buy"}
{"type": "orderbook_delta", "seq": 8269, "price": 35, "quantity": 91, "ts": 1756428556.619975, "side": "buy"}
{"type": "orderbook_delta", "seq": 8270, "price": 42, "quantity": -100, "ts": 1756428556.660568, "side": "sell"}
{"type": "orderbook_delta", "seq": 8271, "price": 40, "quantity": 100, "ts": 1756428556.660568, "side": "sell"}
{"type": "orderbook_delta", "seq": 8272, "price": 37, "quantity": 0, "ts": 1756428557.115382, "side": "buy"}
{"type": "trade", "seq": 72, "price": 37, "quantity": 100, "ts": 1756428557.115382, "side": "sell"}
{"type": "orderbook_delta", "seq": 8273, "price": 35, "quantity": 0, "ts": 1756428557.115382, "side": "buy"}
{"type": "trade", "seq": 73, "price": 35, "quantity": 91, "ts": 1756428557.115382, "side": "sell"}
{"type": "orderbook_delta", "seq": 8274, "price": 34, "quantity": 0, "ts": 1756428557.115382, "side": "buy"}
{"type": "trade", "seq": 74, "price": 34, "quantity": 100, "ts": 1756428557.115382, "side": "sell"}
{"type": "orderbook_delta", "seq": 8275, "price": 34, "quantity": 0, "ts": 1756428557.115382, "side": "buy"}
{"type": "trade", "seq": 75, "price": 34, "quantity": 46, "ts": 1756428557.120916, "side": "sell"}
{"type": "orderbook_delta", "seq": 8276, "price": 52, "quantity": -250, "ts": 1756428557.120916, "side": "sell"}
{"type": "orderbook_delta", "seq": 8277, "price": 42, "quantity": 250, "ts": 1756428557.121008, "side": "sell"}
{"type": "orderbook_delta", "seq": 8278, "price": 43, "quantity": -200, "ts": 1756428557.154315, "side": "sell"}
{"type": "orderbook_delta", "seq": 8279, "price": 34, "quantity": -454, "ts": 1756428557.158139, "side": "buy"}
{"type": "orderbook_delta", "seq": 8280, "price": 40, "quantity": -100, "ts": 1756428557.175143, "side": "sell"}
{"type": "orderbook_delta", "seq": 8281, "price": 38, "quantity": 100, "ts": 1756428557.175143, "side": "sell"}
{"type": "orderbook_delta", "seq": 8282, "price": 42, "quantity": 200, "ts": 1756428557.203103, "side": "sell"}
{"type": "orderbook_delta", "seq": 8283, "price": 33, "quantity": 500, "ts": 1756428557.205981, "side": "buy"}
{"type": "orderbook_delta", "seq": 8284, "price": 38, "quantity": 0, "ts": 1756428557.914745, "side": "sell"}
{"type": "trade", "seq": 76, "price": 38, "quantity": 1, "ts": 1756428558.120192, "side": "buy"}
{"type": "orderbook_delta", "seq": 8285, "price": 42, "quantity": -250, "ts": 1756428558.120192, "side": "sell"}
{"type": "orderbook_delta", "seq": 8286, "price": 52, "quantity": 250, "ts": 1756428558.125338, "side": "sell"}
{"type": "orderbook_delta", "seq": 8287, "price": 42, "quantity": -200, "ts": 1756428558.153089, "side": "sell"}
{"type": "orderbook_delta", "seq": 8288, "price": 43, "quantity": 200, "ts": 1756428558.190277, "side": "sell"}
{"type": "orderbook_delta", "seq": 8289, "price": 30, "quantity": 100, "ts": 1756428558.675973, "side": "buy"}
{"type": "orderbook_delta", "seq": 8290, "price": 30, "quantity": -100, "ts": 1756428559.355072, "side": "buy"}
{"type": "orderbook_delta", "seq": 8291, "price": 33, "quantity": 100, "ts": 1756428559.355072, "side": "buy"}
{"type": "orderbook_delta", "seq": 8292, "price": 33, "quantity": -500, "ts": 1756428559.382305, "side": "buy"}
{"type": "orderbook_delta", "seq": 8293, "price": 44, "quantity": -1250, "ts": 1756428559.405529, "side": "sell"}
{"type": "orderbook_delta", "seq": 8294, "price": 31, "quantity": -200, "ts": 1756428559.407573, "side": "buy"}
{"type": "orderbook_delta", "seq": 8295, "price": 30, "quantity": -1250, "ts": 1756428559.407913, "side": "buy"}
{"type": "orderbook_delta", "seq": 8296, "price": 40, "quantity": -500, "ts": 1756428559.40834, "side": "sell"}
{"type": "orderbook_delta", "seq": 8297, "price": 34, "quantity": 500, "ts": 1756428559.43078, "side": "buy"}
{"type": "orderbook_delta", "seq": 8298, "price": 45, "quantity": 1250, "ts": 1756428559.451716, "side": "sell"}
{"type": "orderbook_delta", "seq": 8299, "price": 41, "quantity": 500, "ts": 1756428559.453952, "side": "sell"}
{"type": "orderbook_delta", "seq": 8300, "price": 32, "quantity": 200, "ts": 1756428559.454226, "side": "buy"}
{"type": "orderbook_delta", "seq": 8301, "price": 31, "quantity": 1250, "ts": 1756428559.457895, "side": "buy"}
{"type": "orderbook_delta", "seq": 8302, "price": 33, "quantity": -100, "ts": 1756428559.875616, "side": "buy"}
{"type": "orderbook_delta", "seq": 8303, "price": 31, "quantity": 100, "ts": 1756428559.875616, "side": "buy"}
{"type": "orderbook_delta", "seq": 8304, "price": 34, "quantity": -500, "ts": 1756428559.922021, "side": "buy"}
{"type": "orderbook_delta", "seq": 8305, "price": 34, "quantity": 100, "ts": 1756428559.928568, "side": "buy"}
{"type": "orderbook_delta", "seq": 8306, "price": 31, "quantity": -100, "ts": 1756428559.930195, "side": "buy"}
{"type": "orderbook_delta", "seq": 8307, "price": 30, "quantity": 100, "ts": 1756428559.930195, "side": "buy"}
{"type": "orderbook_delta", "seq": 8308, "price": 33, "quantity": 500, "ts": 1756428559.958113, "side": "buy"}
{"type": "orderbook_delta", "seq": 8309, "price": 33, "quantity": -500, "ts": 1756428559.998954, "side": "buy"}
{"type": "orderbook_delta", "seq": 8310, "price": 35, "quantity": 500, "ts": 1756428560.038629, "side": "buy"}
{"type": "orderbook_delta", "seq": 8311, "price": 35, "quantity": 0, "ts": 1756428560.171542, "side": "buy"}
{"type": "orderbook_delta", "seq": 8312, "price": 32, "quantity": -200, "ts": 1756428560.216791, "side": "buy"}
{"type": "orderbook_delta", "seq": 8313, "price": 43, "quantity": -200, "ts": 1756428560.219643, "side": "sell"}
{"type": "trade", "seq": 77, "price": 35, "quantity": 145, "ts": 1756428560.261123, "side": "sell"}
{"type": "orderbook_delta", "seq": 8314, "price": 33, "quantity": 200, "ts": 1756428560.261123, "side": "buy"}
{"type": "orderbook_delta", "seq": 8315, "price": 44, "quantity": 200, "ts": 1756428560.261444, "side": "sell"}
{"type": "trade", "seq": 78, "price": 38, "quantity": 20, "ts": 1756428560.526067, "side": "buy"}
{"type": "orderbook_delta", "seq": 8316, "price": 38, "quantity": 0, "ts": 1756428560.526067, "side": "sell"}
{"type": "orderbook_delta", "seq": 8317, "price": 38, "quantity": -79, "ts": 1756428560.578793, "side": "sell"}
{"type": "orderbook_delta", "seq": 8318, "price": 39, "quantity": 79, "ts": 1756428560.578793, "side": "sell"}
{"type": "orderbook_delta", "seq": 8319, "price": 34, "quantity": -100, "ts": 1756428560.763348, "side": "buy"}
{"type": "orderbook_delta", "seq": 8320, "price": 39, "quantity": -79, "ts": 1756428560.76388, "side": "sell"}
{"type": "orderbook_delta", "seq": 8321, "price": 40, "quantity": 79, "ts": 1756428560.76388, "side": "sell"}
{"type": "orderbook_delta", "seq": 8322, "price": 35, "quantity": -355, "ts": 1756428560.783036, "side": "buy"}
{"type": "orderbook_delta", "seq": 8323, "price": 45, "quantity": -1250, "ts": 1756428560.784838, "side": "sell"}
{"type": "orderbook_delta", "seq": 8324, "price": 44, "quantity": -200, "ts": 1756428560.786337, "side": "sell"}
{"type": "orderbook_delta", "seq": 8325, "price": 33, "quantity": -200, "ts": 1756428560.786486, "side": "buy"}
{"type": "orderbook_delta", "seq": 8326, "price": 41, "quantity": -500, "ts": 1756428560.787404, "side": "sell"}
{"type": "orderbook_delta", "seq": 8327, "price": 31, "quantity": -1250, "ts": 1756428560.787811, "side": "buy"}
{"type": "orderbook_delta", "seq": 8328, "price": 32, "quantity": 200, "ts": 1756428560.828345, "side": "buy"}
{"type": "orderbook_delta", "seq": 8329, "price": 30, "quantity": 1250, "ts": 1756428560.828897, "side": "buy"}
{"type": "orderbook_delta", "seq": 8330, "price": 33, "quantity": 500, "ts": 1756428560.829142, "side": "buy"}
{"type": "orderbook_delta", "seq": 8331, "price": 44, "quantity": 1250, "ts": 1756428560.829362, "side": "sell"}
{"type": "orderbook_delta", "seq": 8332, "price": 40, "quantity": 500, "ts": 1756428560.830065, "side": "sell"}
{"type": "orderbook_delta", "seq": 8333, "price": 43, "quantity": 200, "ts": 1756428560.834002, "side": "sell"}
{"type": "orderbook_delta", "seq": 8334, "price": 35, "quantity": 100, "ts": 1756428561.005549, "side": "buy"}
{"type": "orderbook_delta", "seq": 8335, "price": 41, "quantity": -949, "ts": 1756428561.108517, "side": "sell"}
{"type": "orderbook_delta", "seq": 8336, "price": 52, "quantity": -250, "ts": 1756428561.112511, "side": "sell"}
{"type": "orderbook_delta", "seq": 8337, "price": 42, "quantity": 250, "ts": 1756428561.123436, "side": "sell"}
{"type": "orderbook_delta", "seq": 8338, "price": 42, "quantity": 949, "ts": 1756428561.150994, "side": "sell"}
{"type": "orderbook_delta", "seq": 8339, "price": 30, "quantity": -100, "ts": 1756428561.607349, "side": "buy"}
{"type": "orderbook_delta", "seq": 8340, "price": 33, "quantity": 100, "ts": 1756428561.607349, "side": "buy"}
{"type": "orderbook_delta", "seq": 8341, "price": 33, "quantity": -500, "ts": 1756428561.655357, "side": "buy"}
{"type": "orderbook_delta", "seq": 8342, "price": 40, "quantity": -160, "ts": 1756428561.723915, "side": "sell"}
{"type": "orderbook_delta", "seq": 8343, "price": 34, "quantity": 500, "ts": 1756428561.753523, "side": "buy"}
{"type": "orderbook_delta", "seq": 8344, "price": 38, "quantity": 260, "ts": 1756428561.949721, "side": "sell"}
{"type": "orderbook_delta", "seq": 8345, "price": 42, "quantity": -250, "ts": 1756428562.112531, "side": "sell"}
{"type": "orderbook_delta", "seq": 8346, "price": 52, "quantity": 250, "ts": 1756428562.112633, "side": "sell"}
{"type": "orderbook_delta", "seq": 8347, "price": 32, "quantity": -200, "ts": 1756428562.129034, "side": "buy"}
{"type": "orderbook_delta", "seq": 8348, "price": 43, "quantity": -200, "ts": 1756428562.130557, "side": "sell"}
{"type": "orderbook_delta", "seq": 8349, "price": 42, "quantity": 200, "ts": 1756428562.180953, "side": "sell"}
{"type": "orderbook_delta", "seq": 8350, "price": 31, "quantity": 200, "ts": 1756428562.183444, "side": "buy"}
{"type": "orderbook_delta", "seq": 8351, "price": 33, "quantity": -100, "ts": 1756428563.256922, "side": "buy"}
{"type": "orderbook_delta", "seq": 8352, "price": 32, "quantity": 100, "ts": 1756428563.256922, "side": "buy"}
{"type": "orderbook_delta", "seq": 8353, "price": 34, "quantity": -500, "ts": 1756428563.29779, "side": "buy"}
{"type": "orderbook_delta", "seq": 8354, "price": 33, "quantity": 500, "ts": 1756428563.343108, "side": "buy"}
{"type": "orderbook_delta", "seq": 8355, "price": 32, "quantity": -100, "ts": 1756428563.670381, "side": "buy"}
{"type": "orderbook_delta", "seq": 8356, "price": 31, "quantity": 100, "ts": 1756428563.670381, "side": "buy"}
{"type": "orderbook_delta", "seq": 8357, "price": 40, "quantity": -79, "ts": 1756428564.587451, "side": "sell"}
{"type": "orderbook_delta", "seq": 8358, "price": 38, "quantity": 79, "ts": 1756428564.587451, "side": "sell"}
{"type": "orderbook_delta", "seq": 8359, "price": 40, "quantity": -500, "ts": 1756428564.626087, "side": "sell"}
{"type": "orderbook_delta", "seq": 8360, "price": 41, "quantity": 500, "ts": 1756428564.689061, "side": "sell"}
{"type": "orderbook_delta", "seq": 8361, "price": 42, "quantity": -200, "ts": 1756428564.712668, "side": "sell"}
{"type": "orderbook_delta", "seq": 8362, "price": 30, "quantity": -1250, "ts": 1756428564.715217, "side": "buy"}
{"type": "orderbook_delta", "seq": 8363, "price": 31, "quantity": -200, "ts": 1756428564.715279, "side": "buy"}
{"type": "orderbook_delta", "seq": 8364, "price": 33, "quantity": -500, "ts": 1756428564.718748, "side": "buy"}
{"type": "orderbook_delta", "seq": 8365, "price": 44, "quantity": -1250, "ts": 1756428564.737829, "side": "sell"}
{"type": "orderbook_delta", "seq": 8366, "price": 43, "quantity": 200, "ts": 1756428564.772653, "side": "sell"}
{"type": "orderbook_delta", "seq": 8367, "price": 32, "quantity": 200, "ts": 1756428564.775381, "side": "buy"}
{"type": "orderbook_delta", "seq": 8368, "price": 35, "quantity": 500, "ts": 1756428564.778805, "side": "buy"}
{"type": "orderbook_delta", "seq": 8369, "price": 45, "quantity": 1250, "ts": 1756428564.780366, "side": "sell"}
{"type": "orderbook_delta", "seq": 8370, "price": 31, "quantity": 1250, "ts": 1756428564.78119, "side": "buy"}
{"type": "orderbook_delta", "seq": 8371, "price": 38, "quantity": -79, "ts": 1756428565.021885, "side": "sell"}
{"type": "orderbook_delta", "seq": 8372, "price": 40, "quantity": 79, "ts": 1756428565.021885, "side": "sell"}
{"type": "orderbook_delta", "seq": 8373, "price": 42, "quantity": 250, "ts": 1756428565.101162, "side": "sell"}
{"type": "orderbook_delta", "seq": 8374, "price": 52, "quantity": -250, "ts": 1756428565.102033, "side": "sell"}
{"type": "orderbook_delta", "seq": 8375, "price": 31, "quantity": -100, "ts": 1756428565.176717, "side": "buy"}
{"type": "orderbook_delta", "seq": 8376, "price": 34, "quantity": 100, "ts": 1756428565.176717, "side": "buy"}
{"type": "orderbook_delta", "seq": 8377, "price": 31, "quantity": -1250, "ts": 1756428565.996103, "side": "buy"}
{"type": "orderbook_delta", "seq": 8378, "price": 45, "quantity": -1250, "ts": 1756428565.996525, "side": "sell"}
{"type": "orderbook_delta", "seq": 8379, "price": 41, "quantity": -500, "ts": 1756428566.010564, "side": "sell"}
{"type": "orderbook_delta", "seq": 8380, "price": 35, "quantity": -500, "ts": 1756428566.01102, "side": "buy"}
{"type": "orderbook_delta", "seq": 8381, "price": 34, "quantity": -100, "ts": 1756428566.014758, "side": "buy"}
{"type": "orderbook_delta", "seq": 8382, "price": 33, "quantity": 100, "ts": 1756428566.014758, "side": "buy"}
{"type": "orderbook_delta", "seq": 8383, "price": 30, "quantity": 1250, "ts": 1756428566.046304, "side": "buy"}
{"type": "orderbook_delta", "seq": 8384, "price": 44, "quantity": 1250, "ts": 1756428566.047486, "side": "sell"}
{"type": "orderbook_delta", "seq": 8385, "price": 34, "quantity": 500, "ts": 1756428566.047793, "side": "buy"}
{"type": "orderbook_delta", "seq": 8386, "price": 40, "quantity": 500, "ts": 1756428566.048034, "side": "sell"}
{"type": "orderbook_delta", "seq": 8387, "price": 44, "quantity": -1250, "ts": 1756428566.192824, "side": "sell"}
{"type": "orderbook_delta", "seq": 8388, "price": 34, "quantity": -500, "ts": 1756428566.19612, "side": "buy"}
{"type": "orderbook_delta", "seq": 8389, "price": 45, "quantity": 1250, "ts": 1756428566.251844, "side": "sell"}
{"type": "orderbook_delta", "seq": 8390, "price": 35, "quantity": 500, "ts": 1756428566.304178, "side": "buy"}
{"type": "orderbook_delta", "seq": 8391, "price": 33, "quantity": -100, "ts": 1756428566.693513, "side": "buy"}
{"type": "orderbook_delta", "seq": 8392, "price": 32, "quantity": 100, "ts": 1756428566.693513, "side": "buy"}
{"type": "orderbook_delta", "seq": 8393, "price": 32, "quantity": -100, "ts": 1756428566.795892, "side": "buy"}
{"type": "orderbook_delta", "seq": 8394, "price": 31, "quantity": 100, "ts": 1756428566.795892, "side": "buy"}
{"type": "orderbook_delta", "seq": 8395, "price": 35, "quantity": -500, "ts": 1756428566.867592, "side": "buy"}
{"type": "orderbook_delta", "seq": 8396, "price": 45, "quantity": -1250, "ts": 1756428566.86821, "side": "sell"}
{"type": "orderbook_delta", "seq": 8397, "price": 33, "quantity": 500, "ts": 1756428566.911376, "side": "buy"}
{"type": "orderbook_delta", "seq": 8398, "price": 44, "quantity": 1250, "ts": 1756428566.916098, "side": "sell"}
{"type": "orderbook_delta", "seq": 8399, "price": 42, "quantity": -949, "ts": 1756428567.116669, "side": "sell"}
{"type": "orderbook_delta", "seq": 8400, "price": 40, "quantity": 949, "ts": 1756428567.162713, "side": "sell"}
{"type": "orderbook_delta", "seq": 8401, "price": 31, "quantity": -100, "ts": 1756428567.200635, "side": "buy"}
{"type": "orderbook_delta", "seq": 8402, "price": 30, "quantity": 100, "ts": 1756428567.200635, "side": "buy"}
{"type": "orderbook_delta", "seq": 8403, "price": 44, "quantity": -1250, "ts": 1756428567.31287, "side": "sell"}
{"type": "orderbook_delta", "seq": 8404, "price": 33, "quantity": -500, "ts": 1756428567.314938, "side": "buy"}
{"type": "orderbook_delta", "seq": 8405, "price": 45, "quantity": 1250, "ts": 1756428567.351749, "side": "sell"}
{"type": "orderbook_delta", "seq": 8406, "price": 35, "quantity": 500, "ts": 1756428567.352068, "side": "buy"}
{"type": "orderbook_delta", "seq": 8407, "price": 40, "quantity": -500, "ts": 1756428567.869171, "side": "sell"}
{"type": "orderbook_delta", "seq": 8408, "price": 41, "quantity": 500, "ts": 1756428567.909955, "side": "sell"}
{"type": "orderbook_delta", "seq": 8409, "price": 40, "quantity": -79, "ts": 1756428568.110018, "side": "sell"}
{"type": "orderbook_delta", "seq": 8410, "price": 37, "quantity": 79, "ts": 1756428568.110018, "side": "sell"}
{"type": "orderbook_delta", "seq": 8411, "price": 37, "quantity": -79, "ts": 1756428568.160617, "side": "sell"}
{"type": "orderbook_delta", "seq": 8412, "price": 38, "quantity": 79, "ts": 1756428568.160617, "side": "sell"}
{"type": "orderbook_delta", "seq": 8413, "price": 30, "quantity": -1250, "ts": 1756428568.520502, "side": "buy"}
{"type": "orderbook_delta", "seq": 8414, "price": 31, "quantity": 1250, "ts": 1756428568.571766, "side": "buy"}
{"type": "orderbook_delta", "seq": 8415, "price": 30, "quantity": -100, "ts": 1756428569.382052, "side": "buy"}
{"type": "orderbook_delta", "seq": 8416, "price": 32, "quantity": 100, "ts": 1756428569.382052, "side": "buy"}
{"type": "orderbook_delta", "seq": 8417, "price": 43, "quantity": -200, "ts": 1756428569.762127, "side": "sell"}
{"type": "orderbook_delta", "seq": 8418, "price": 32, "quantity": -200, "ts": 1756428569.762711, "side": "buy"}
{"type": "orderbook_delta", "seq": 8419, "price": 33, "quantity": 200, "ts": 1756428569.807139, "side": "buy"}
{"type": "orderbook_delta", "seq": 8420, "price": 44, "quantity": 200, "ts": 1756428569.828316, "side": "sell"}
{"type": "orderbook_delta", "seq": 8421, "price": 31, "quantity": -1250, "ts": 1756428570.981216, "side": "buy"}
{"type": "orderbook_delta", "seq": 8422, "price": 44, "quantity": -200, "ts": 1756428570.981528, "side": "sell"}
{"type": "orderbook_delta", "seq": 8423, "price": 41, "quantity": -500, "ts": 1756428570.982822, "side": "sell"}
{"type": "orderbook_delta", "seq": 8424, "price": 33, "quantity": -200, "ts": 1756428570.98542, "side": "buy"}
{"type": "orderbook_delta", "seq": 8425, "price": 30, "quantity": 1250, "ts": 1756428571.024455, "side": "buy"}
{"type": "orderbook_delta", "seq": 8426, "price": 32, "quantity": 200, "ts": 1756428571.024775, "side": "buy"}
{"type": "orderbook_delta", "seq": 8427, "price": 40, "quantity": 500, "ts": 1756428571.027018, "side": "sell"}
{"type": "orderbook_delta", "seq": 8428, "price": 43, "quantity": 200, "ts": 1756428571.03424, "side": "sell"}
{"type": "orderbook_delta", "seq": 8429, "price": 45, "quantity": -1250, "ts": 1756428572.259208, "side": "sell"}
{"type": "orderbook_delta", "seq": 8430, "price": 35, "quantity": -500, "ts": 1756428572.260262, "side": "buy"}
{"type": "orderbook_delta", "seq": 8431, "price": 44, "quantity": 1250, "ts": 1756428572.336945, "side": "sell"}
{"type": "orderbook_delta", "seq": 8432, "price": 33, "quantity": 500, "ts": 1756428572.421274, "side": "buy"}
{"type": "orderbook_delta", "seq": 8433, "price": 32, "quantity": -100, "ts": 1756428572.579847, "side": "buy"}
{"type": "orderbook_delta", "seq": 8434, "price": 30, "quantity": 100, "ts": 1756428572.579847, "side": "buy"}
{"type": "orderbook_delta", "seq": 8435, "price": 33, "quantity": -500, "ts": 1756428573.480615, "side": "buy"}
{"type": "orderbook_delta", "seq": 8436, "price": 30, "quantity": -1250, "ts": 1756428573.495293, "side": "buy"}
{"type": "orderbook_delta", "seq": 8437, "price": 44, "quantity": -1250, "ts": 1756428573.495426, "side": "sell"}
{"type": "orderbook_delta", "seq": 8438, "price": 40, "quantity": -500, "ts": 1756428573.495639, "side": "sell"}
{"type": "orderbook_delta", "seq": 8439, "price": 47, "quantity": 1, "ts": 1756428573.515526, "side": "sell"}
{"type": "orderbook_delta", "seq": 8440, "price": 41, "quantity": 500, "ts": 1756428573.582128, "side": "sell"}
{"type": "orderbook_delta", "seq": 8441, "price": 45, "quantity": 1250, "ts": 1756428573.582885, "side": "sell"}
{"type": "orderbook_delta", "seq": 8442, "price": 31, "quantity": 1250, "ts": 1756428573.583434, "side": "buy"}
{"type": "orderbook_delta", "seq": 8443, "price": 35, "quantity": 500, "ts": 1756428573.583898, "side": "buy"}
{"type": "orderbook_delta", "seq": 8444, "price": 99, "quantity": -16200, "ts": 1756428573.875886, "side": "sell"}
{"type": "orderbook_delta", "seq": 8445, "price": 98, "quantity": 8100, "ts": 1756428573.875886, "side": "sell"}
{"type": "orderbook_delta", "seq": 8446, "price": 98, "quantity": -7000, "ts": 1756428573.94511, "side": "sell"}
{"type": "orderbook_delta", "seq": 8447, "price": 97, "quantity": 7000, "ts": 1756428573.992748, "side": "sell"}
{"type": "orderbook_delta", "seq": 8448, "price": 40, "quantity": -949, "ts": 1756428574.184451, "side": "sell"}
{"type": "orderbook_delta", "seq": 8449, "price": 52, "quantity": 250, "ts": 1756428574.184825, "side": "sell"}
{"type": "orderbook_delta", "seq": 8450, "price": 41, "quantity": -500, "ts": 1756428574.196159, "side": "sell"}
{"type": "orderbook_delta", "seq": 8451, "price": 31, "quantity": -1250, "ts": 1756428574.196728, "side": "buy"}
{"type": "orderbook_delta", "seq": 8452, "price": 68, "quantity": -8000, "ts": 1756428574.197226, "side": "sell"}
{"type": "orderbook_delta", "seq": 8453, "price": 32, "quantity": -200, "ts": 1756428574.19735, "side": "buy"}
{"type": "orderbook_delta", "seq": 8454, "price": 35, "quantity": -500, "ts": 1756428574.197482, "side": "buy"}
{"type": "orderbook_delta", "seq": 8455, "price": 43, "quantity": -200, "ts": 1756428574.19853, "side": "sell"}
{"type": "orderbook_delta", "seq": 8456, "price": 38, "quantity": -79, "ts": 1756428574.246827, "side": "sell"}
{"type": "orderbook_delta", "seq": 8457, "price": 39, "quantity": 79, "ts": 1756428574.246827, "side": "sell"}
{"type": "orderbook_delta", "seq": 8458, "price": 42, "quantity": -250, "ts": 1756428574.254869, "side": "sell"}
{"type": "orderbook_delta", "seq": 8459, "price": 45, "quantity": -1250, "ts": 1756428574.285533, "side": "sell"}
{"type": "orderbook_delta", "seq": 8460, "price": 68, "quantity": 8000, "ts": 1756428574.406234, "side": "sell"}
{"type": "orderbook_delta", "seq": 8461, "price": 45, "quantity": 1250, "ts": 1756428574.407343, "side": "sell"}
{"type": "orderbook_delta", "seq": 8462, "price": 43, "quantity": 500, "ts": 1756428574.41483, "side": "sell"}
{"type": "orderbook_delta", "seq": 8463, "price": 43, "quantity": 200, "ts": 1756428574.415319, "side": "sell"}
{"type": "orderbook_delta", "seq": 8464, "price": 31, "quantity": 1250, "ts": 1756428574.415792, "side": "buy"}
{"type": "orderbook_delta", "seq": 8465, "price": 35, "quantity": 500, "ts": 1756428574.416774, "side": "buy"}
{"type": "orderbook_delta", "seq": 8466, "price": 42, "quantity": 949, "ts": 1756428574.424509, "side": "sell"}
{"type": "orderbook_delta", "seq": 8467, "price": 32, "quantity": 200, "ts": 1756428574.451693, "side": "buy"}
{"type": "orderbook_delta", "seq": 8468, "price": 43, "quantity": -500, "ts": 1756428574.494486, "side": "sell"}
{"type": "orderbook_delta", "seq": 8469, "price": 41, "quantity": 500, "ts": 1756428574.574249, "side": "sell"}
{"type": "orderbook_delta", "seq": 8470, "price": 30, "quantity": -100, "ts": 1756428574.607331, "side": "buy"}
{"type": "orderbook_delta", "seq": 8471, "price": 33, "quantity": 100, "ts": 1756428574.607331, "side": "buy"}
{"type": "orderbook_delta", "seq": 8472, "price": 35, "quantity": -500, "ts": 1756428574.715096, "side": "buy"}
{"type": "orderbook_delta", "seq": 8473, "price": 45, "quantity": -1250, "ts": 1756428574.715161, "side": "sell"}
{"type": "orderbook_delta", "seq": 8474, "price": 43, "quantity": -200, "ts": 1756428574.71708, "side": "sell"}
{"type": "orderbook_delta", "seq": 8475, "price": 31, "quantity": -1250, "ts": 1756428574.718167, "side": "buy"}
{"type": "orderbook_delta", "seq": 8476, "price": 32, "quantity": -200, "ts": 1756428574.720515, "side": "buy"}
{"type": "orderbook_delta", "seq": 8477, "price": 34, "quantity": 500, "ts": 1756428574.765804, "side": "buy"}
{"type": "orderbook_delta", "seq": 8478, "price": 31, "quantity": 200, "ts": 1756428574.766947, "side": "buy"}
{"type": "orderbook_delta", "seq": 8479, "price": 30, "quantity": 1250, "ts": 1756428574.76755, "side": "buy"}
{"type": "orderbook_delta", "seq": 8480, "price": 42, "quantity": 200, "ts": 1756428574.769177, "side": "sell"}
{"type": "orderbook_delta", "seq": 8481, "price": 44, "quantity": 1250, "ts": 1756428574.770127, "side": "sell"}
{"type": "orderbook_delta", "seq": 8482, "price": 34, "quantity": 250, "ts": 1756428575.109496, "side": "buy"}
{"type": "orderbook_delta", "seq": 8483, "price": 24, "quantity": -250, "ts": 1756428575.110268, "side": "buy"}
{"type": "orderbook_delta", "seq": 8484, "price": 24, "quantity": 250, "ts": 1756428575.603139, "side": "buy"}
{"type": "orderbook_delta", "seq": 8485, "price": 32, "quantity": -250, "ts": 1756428575.603933, "side": "buy"}
{"type": "orderbook_delta", "seq": 8486, "price": 22, "quantity": 250, "ts": 1756428575.615878, "side": "buy"}
{"type": "orderbook_delta", "seq": 8487, "price": 34, "quantity": -250, "ts": 1756428575.616108, "side": "buy"}
{"type": "orderbook_delta", "seq": 8488, "price": 98, "quantity": -8100, "ts": 1756428575.688361, "side": "sell"}
{"type": "orderbook_delta", "seq": 8489, "price": 97, "quantity": 5400, "ts": 1756428575.688361, "side": "sell"}
{"type": "orderbook_delta", "seq": 8490, "price": 97, "quantity": -7000, "ts": 1756428575.728282, "side": "sell"}
{"type": "orderbook_delta", "seq": 8491, "price": 96, "quantity": 7000, "ts": 1756428575.773496, "side": "sell"}
{"type": "orderbook_delta", "seq": 8492, "price": 34, "quantity": -500, "ts": 1756428575.988673, "side": "buy"}
{"type": "orderbook_delta", "seq": 8493, "price": 42, "quantity": -200, "ts": 1756428575.990842, "side": "sell"}
{"type": "orderbook_delta", "seq": 8494, "price": 44, "quantity": -1250, "ts": 1756428575.992963, "side": "sell"}
{"type": "orderbook_delta", "seq": 8495, "price": 33, "quantity": -100, "ts": 1756428576.038224, "side": "buy"}
{"type": "orderbook_delta", "seq": 8496, "price": 32, "quantity": 100, "ts": 1756428576.038224, "side": "buy"}
{"type": "orderbook_delta", "seq": 8497, "price": 43, "quantity": 200, "ts": 1756428576.039634, "side": "sell"}
{"type": "orderbook_delta", "seq": 8498, "price": 45, "quantity": 1250, "ts": 1756428576.0402, "side": "sell"}
{"type": "orderbook_delta", "seq": 8499, "price": 35, "quantity": 500, "ts": 1756428576.041333, "side": "buy"}
{"type": "orderbook_delta", "seq": 8500, "price": 42, "quantity": -949, "ts": 1756428576.103325, "side": "sell"}
{"type": "orderbook_delta", "seq": 8501, "price": 52, "quantity": -250, "ts": 1756428576.127128, "side": "sell"}
{"type": "orderbook_delta", "seq": 8502, "price": 41, "quantity": -500, "ts": 1756428576.144923, "side": "sell"}
{"type": "orderbook_delta", "seq": 8503, "price": 42, "quantity": 250, "ts": 1756428576.146689, "side": "sell"}
{"type": "orderbook_delta", "seq": 8504, "price": 40, "quantity": 949, "ts": 1756428576.177191, "side": "sell"}
{"type": "orderbook_delta", "seq": 8505, "price": 41, "quantity": 500, "ts": 1756428576.187112, "side": "sell"}
{"type": "orderbook_delta", "seq": 8506, "price": 41, "quantity": -500, "ts": 1756428576.242096, "side": "sell"}
{"type": "orderbook_delta", "seq": 8507, "price": 40, "quantity": 500, "ts": 1756428576.273458, "side": "sell"}
{"type": "trade", "seq": 79, "price": 38, "quantity": 254, "ts": 1756428576.400766, "side": "buy"}
{"type": "orderbook_delta", "seq": 8508, "price": 38, "quantity": 0, "ts": 1756428576.400766, "side": "sell"}
{"type": "orderbook_delta", "seq": 8509, "price": 97, "quantity": -5400, "ts": 1756428576.643849, "side": "sell"}
{"type": "orderbook_delta", "seq": 8510, "price": 98, "quantity": 8100, "ts": 1756428576.643849, "side": "sell"}
{"type": "orderbook_delta", "seq": 8511, "price": 96, "quantity": -7000, "ts": 1756428576.669086, "side": "sell"}
{"type": "orderbook_delta", "seq": 8512, "price": 97, "quantity": 7000, "ts": 1756428576.704349, "side": "sell"}
{"type": "trade", "seq": 80, "price": 35, "quantity": 100, "ts": 1756428576.773713, "side": "sell"}
{"type": "orderbook_delta", "seq": 8513, "price": 35, "quantity": 0, "ts": 1756428576.773713, "side": "buy"}
{"type": "trade", "seq": 81, "price": 35, "quantity": 176, "ts": 1756428576.773713, "side": "sell"}
{"type": "orderbook_delta", "seq": 8514, "price": 35, "quantity": 0, "ts": 1756428576.773713, "side": "buy"}
{"type": "orderbook_delta", "seq": 8515, "price": 35, "quantity": -324, "ts": 1756428576.820064, "side": "buy"}
{"type": "orderbook_delta", "seq": 8516, "price": 33, "quantity": 500, "ts": 1756428576.870741, "side": "buy"}
{"type": "orderbook_delta", "seq": 8517, "price": 32, "quantity": -100, "ts": 1756428576.935206, "side": "buy"}
{"type": "orderbook_delta", "seq": 8518, "price": 33, "quantity": 100, "ts": 1756428576.935206, "side": "buy"}
{"type": "orderbook_delta", "seq": 8519, "price": 33, "quantity": -500, "ts": 1756428576.968562, "side": "buy"}
{"type": "orderbook_delta", "seq": 8520, "price": 34, "quantity": 500, "ts": 1756428577.011119, "side": "buy"}
{"type": "orderbook_delta", "seq": 8521, "price": 33, "quantity": -100, "ts": 1756428577.046457, "side": "buy"}
{"type": "orderbook_delta", "seq": 8522, "price": 31, "quantity": 100, "ts": 1756428577.046457, "side": "buy"}
{"type": "orderbook_delta", "seq": 8523, "price": 34, "quantity": -500, "ts": 1756428577.087437, "side": "buy"}
{"type": "orderbook_delta", "seq": 8524, "price": 32, "quantity": 250, "ts": 1756428577.125866, "side": "buy"}
{"type": "orderbook_delta", "seq": 8525, "price": 32, "quantity": 500, "ts": 1756428577.136148, "side": "buy"}
{"type": "orderbook_delta", "seq": 8526, "price": 22, "quantity": -250, "ts": 1756428577.146129, "side": "buy"}
{"type": "orderbook_delta", "seq": 8527, "price": 31, "quantity": -200, "ts": 1756428577.168831, "side": "buy"}
{"type": "orderbook_delta", "seq": 8528, "price": 32, "quantity": -500, "ts": 1756428577.177348, "side": "buy"}
{"type": "orderbook_delta", "seq": 8529, "price": 32, "quantity": 200, "ts": 1756428577.20965, "side": "buy"}
{"type": "orderbook_delta", "seq": 8530, "price": 33, "quantity": 500, "ts": 1756428577.217929, "side": "buy"}
{"type": "orderbook_delta", "seq": 8531, "price": 30, "quantity": -1250, "ts": 1756428577.219693, "side": "buy"}
{"type": "orderbook_delta", "seq": 8532, "price": 40, "quantity": -500, "ts": 1756428577.22201, "side": "sell"}
{"type": "orderbook_delta", "seq": 8533, "price": 41, "quantity": 500, "ts": 1756428577.256322, "side": "sell"}
{"type": "orderbook_delta", "seq": 8534, "price": 31, "quantity": 1250, "ts": 1756428577.258707, "side": "buy"}
{"type": "orderbook_delta", "seq": 8535, "price": 39, "quantity": -79, "ts": 1756428577.336377, "side": "sell"}
{"type": "orderbook_delta", "seq": 8536, "price": 41, "quantity": 79, "ts": 1756428577.336377, "side": "sell"}
{"type": "orderbook_delta", "seq": 8537, "price": 32, "quantity": -200, "ts": 1756428577.771631, "side": "buy"}
{"type": "orderbook_delta", "seq": 8538, "price": 43, "quantity": -200, "ts": 1756428577.771764, "side": "sell"}
{"type": "orderbook_delta", "seq": 8539, "price": 39, "quantity": -200, "ts": 1756428577.817316, "side": "sell"}
{"type": "orderbook_delta", "seq": 8540, "price": 40, "quantity": 200, "ts": 1756428577.817316, "side": "sell"}
{"type": "orderbook_delta", "seq": 8541, "price": 44, "quantity": 200, "ts": 1756428577.826809, "side": "sell"}
{"type": "orderbook_delta", "seq": 8542, "price": 33, "quantity": 200, "ts": 1756428577.880535, "side": "buy"}
{"type": "orderbook_delta", "seq": 8543, "price": 98, "quantity": -8100, "ts": 1756428578.00061, "side": "sell"}
{"type": "orderbook_delta", "seq": 8544, "price": 97, "quantity": -7000, "ts": 1756428578.204801, "side": "sell"}
{"type": "orderbook_delta", "seq": 8545, "price": 44, "quantity": -200, "ts": 1756428578.465578, "side": "sell"}
{"type": "orderbook_delta", "seq": 8546, "price": 33, "quantity": -200, "ts": 1756428578.465794, "side": "buy"}
{"type": "orderbook_delta", "seq": 8547, "price": 32, "quantity": 200, "ts": 1756428578.506318, "side": "buy"}
{"type": "orderbook_delta", "seq": 8548, "price": 43, "quantity": 200, "ts": 1756428578.506846, "side": "sell"}
{"type": "orderbook_delta", "seq": 8549, "price": 31, "quantity": -100, "ts": 1756428578.644389, "side": "buy"}
{"type": "orderbook_delta", "seq": 8550, "price": 33, "quantity": 100, "ts": 1756428578.644389, "side": "buy"}
{"type": "orderbook_delta", "seq": 8551, "price": 33, "quantity": -500, "ts": 1756428578.677222, "side": "buy"}
{"type": "orderbook_delta", "seq": 8552, "price": 34, "quantity": 500, "ts": 1756428578.716841, "side": "buy"}
{"type": "orderbook_delta", "seq": 8553, "price": 41, "quantity": -79, "ts": 1756428578.718971, "side": "sell"}
{"type": "orderbook_delta", "seq": 8554, "price": 42, "quantity": 79, "ts": 1756428578.718971, "side": "sell"}
{"type": "orderbook_delta", "seq": 8555, "price": 40, "quantity": -200, "ts": 1756428578.773097, "side": "sell"}
{"type": "orderbook_delta", "seq": 8556, "price": 42, "quantity": 200, "ts": 1756428578.773097, "side": "sell"}
{"type": "orderbook_delta", "seq": 8557, "price": 34, "quantity": 100, "ts": 1756428578.850299, "side": "buy"}
{"type": "orderbook_delta", "seq": 8558, "price": 34, "quantity": -500, "ts": 1756428578.879509, "side": "buy"}
{"type": "orderbook_delta", "seq": 8559, "price": 35, "quantity": 500, "ts": 1756428578.911811, "side": "buy"}
{"type": "orderbook_delta", "seq": 8560, "price": 40, "quantity": -949, "ts": 1756428578.989901, "side": "sell"}
{"type": "orderbook_delta", "seq": 8561, "price": 52, "quantity": 250, "ts": 1756428578.989924, "side": "sell"}
{"type": "orderbook_delta", "seq": 8562, "price": 45, "quantity": -1250, "ts": 1756428579.002518, "side": "sell"}
{"type": "orderbook_delta", "seq": 8563, "price": 43, "quantity": -200, "ts": 1756428579.005669, "side": "sell"}
{"type": "orderbook_delta", "seq": 8564, "price": 42, "quantity": -250, "ts": 1756428579.00647, "side": "sell"}
{"type": "orderbook_delta", "seq": 8565, "price": 68, "quantity": -8000, "ts": 1756428579.006536, "side": "sell"}
{"type": "orderbook_delta", "seq": 8566, "price": 31, "quantity": -1250, "ts": 1756428579.006922, "side": "buy"}
{"type": "orderbook_delta", "seq": 8567, "price": 32, "quantity": -200, "ts": 1756428579.008304, "side": "buy"}
{"type": "orderbook_delta", "seq": 8568, "price": 41, "quantity": -500, "ts": 1756428579.008508, "side": "sell"}
{"type": "orderbook_delta", "seq": 8569, "price": 10, "quantity": 8000, "ts": 1756428579.01203, "side": "buy"}
{"type": "orderbook_delta", "seq": 8570, "price": 42, "quantity": -79, "ts": 1756428579.0184, "side": "sell"}
{"type": "orderbook_delta", "seq": 8571, "price": 43, "quantity": 79, "ts": 1756428579.0184, "side": "sell"}
{"type": "orderbook_delta", "seq": 8572, "price": 46, "quantity": 200, "ts": 1756428579.056901, "side": "sell"}
{"type": "orderbook_delta", "seq": 8573, "price": 98, "quantity": 8000, "ts": 1756428579.058505, "side": "sell"}
{"type": "orderbook_delta", "seq": 8574, "price": 43, "quantity": 500, "ts": 1756428579.059174, "side": "sell"}
{"type": "orderbook_delta", "seq": 8575, "price": 42, "quantity": 949, "ts": 1756428579.060758, "side": "sell"}
{"type": "orderbook_delta", "seq": 8576, "price": 33, "quantity": 200, "ts": 1756428579.061862, "side": "buy"}
{"type": "orderbook_delta", "seq": 8577, "price": 47, "quantity": 1250, "ts": 1756428579.065495, "side": "sell"}
{"type": "orderbook_delta", "seq": 8578, "price": 33, "quantity": 1250, "ts": 1756428579.075439, "side": "buy"}
{"type": "orderbook_delta", "seq": 8579, "price": 34, "quantity": 250, "ts": 1756428579.128595, "side": "buy"}
{"type": "orderbook_delta", "seq": 8580, "price": 24, "quantity": -250, "ts": 1756428579.131927, "side": "buy"}
{"type": "orderbook_delta", "seq": 8581, "price": 33, "quantity": -200, "ts": 1756428579.167872, "side": "buy"}
{"type": "orderbook_delta", "seq": 8582, "price": 47, "quantity": -1250, "ts": 1756428579.168305, "side": "sell"}
{"type": "orderbook_delta", "seq": 8583, "price": 35, "quantity": 200, "ts": 1756428579.215421, "side": "buy"}
{"type": "orderbook_delta", "seq": 8584, "price": 48, "quantity": 1250, "ts": 1756428579.217898, "side": "sell"}
{"type": "orderbook_delta", "seq": 8585, "price": 34, "quantity": -100, "ts": 1756428579.789759, "side": "buy"}
{"type": "orderbook_delta", "seq": 8586, "price": 35, "quantity": 100, "ts": 1756428580.012731, "side": "buy"}
{"type": "orderbook_delta", "seq": 8587, "price": 35, "quantity": -500, "ts": 1756428580.044979, "side": "buy"}
{"type": "orderbook_delta", "seq": 8588, "price": 36, "quantity": 500, "ts": 1756428580.179855, "side": "buy"}
{"type": "orderbook_delta", "seq": 8589, "price": 33, "quantity": -100, "ts": 1756428580.292077, "side": "buy"}
{"type": "orderbook_delta", "seq": 8590, "price": 36, "quantity": 100, "ts": 1756428580.292077, "side": "buy"}
{"type": "orderbook_delta", "seq": 8591, "price": 36, "quantity": -500, "ts": 1756428580.387492, "side": "buy"}
{"type": "orderbook_delta", "seq": 8592, "price": 37, "quantity": 500, "ts": 1756428580.43038, "side": "buy"}
{"type": "orderbook_delta", "seq": 8593, "price": 43, "quantity": -500, "ts": 1756428580.540328, "side": "sell"}
{"type": "orderbook_delta", "seq": 8594, "price": 10, "quantity": -8000, "ts": 1756428580.54071, "side": "buy"}
{"type": "orderbook_delta", "seq": 8595, "price": 11, "quantity": 8000, "ts": 1756428580.586819, "side": "buy"}
{"type": "orderbook_delta", "seq": 8596, "price": 44, "quantity": 500, "ts": 1756428580.587165, "side": "sell"}
{"type": "orderbook_delta", "seq": 8597, "price": 36, "quantity": -100, "ts": 1756428580.629213, "side": "buy"}
{"type": "orderbook_delta", "seq": 8598, "price": 34, "quantity": 100, "ts": 1756428580.629213, "side": "buy"}
{"type": "orderbook_delta", "seq": 8599, "price": 37, "quantity": -500, "ts": 1756428580.671462, "side": "buy"}
{"type": "orderbook_delta", "seq": 8600, "price": 36, "quantity": 500, "ts": 1756428580.716871, "side": "buy"}
{"type": "orderbook_delta", "seq": 8601, "price": 38, "quantity": -6, "ts": 1756428580.756213, "side": "sell"}
{"type": "orderbook_delta", "seq": 8602, "price": 43, "quantity": -79, "ts": 1756428580.779578, "side": "sell"}
{"type": "orderbook_delta", "seq": 8603, "price": 41, "quantity": 79, "ts": 1756428580.779578, "side": "sell"}
{"type": "orderbook_delta", "seq": 8604, "price": 11, "quantity": -8000, "ts": 1756428580.938414, "side": "buy"}
{"type": "orderbook_delta", "seq": 8605, "price": 38, "quantity": 106, "ts": 1756428581.015551, "side": "sell"}
{"type": "orderbook_delta", "seq": 8606, "price": 44, "quantity": -500, "ts": 1756428581.016427, "side": "sell"}
{"type": "orderbook_delta", "seq": 8607, "price": 41, "quantity": -79, "ts": 1756428581.068151, "side": "sell"}
{"type": "orderbook_delta", "seq": 8608, "price": 40, "quantity": 79, "ts": 1756428581.068151, "side": "sell"}
{"type": "orderbook_delta", "seq": 8609, "price": 54, "quantity": 250, "ts": 1756428581.105827, "side": "sell"}
{"type": "orderbook_delta", "seq": 8610, "price": 42, "quantity": -949, "ts": 1756428581.11443, "side": "sell"}
{"type": "orderbook_delta", "seq": 8611, "price": 44, "quantity": -250, "ts": 1756428581.125785, "side": "sell"}
{"type": "orderbook_delta", "seq": 8612, "price": 43, "quantity": 500, "ts": 1756428581.128295, "side": "sell"}
{"type": "orderbook_delta", "seq": 8613, "price": 10, "quantity": 8000, "ts": 1756428581.129142, "side": "buy"}
{"type": "orderbook_delta", "seq": 8614, "price": 44, "quantity": 949, "ts": 1756428581.183838, "side": "sell"}
{"type": "orderbook_delta", "seq": 8615, "price": 43, "quantity": -500, "ts": 1756428581.211117, "side": "sell"}
{"type": "orderbook_delta", "seq": 8616, "price": 43, "quantity": 500, "ts": 1756428581.257962, "side": "sell"}
{"type": "orderbook_delta", "seq": 8617, "price": 43, "quantity": -500, "ts": 1756428581.623668, "side": "sell"}
{"type": "orderbook_delta", "seq": 8618, "price": 40, "quantity": -79, "ts": 1756428581.652471, "side": "sell"}
{"type": "orderbook_delta", "seq": 8619, "price": 41, "quantity": 79, "ts": 1756428581.652471, "side": "sell"}
{"type": "orderbook_delta", "seq": 8620, "price": 44, "quantity": 500, "ts": 1756428581.659957, "side": "sell"}
{"type": "orderbook_delta", "seq": 8621, "price": 42, "quantity": -200, "ts": 1756428581.662503, "side": "sell"}
{"type": "orderbook_delta", "seq": 8622, "price": 44, "quantity": 200, "ts": 1756428581.662503, "side": "sell"}
{"type": "orderbook_delta", "seq": 8623, "price": 41, "quantity": -79, "ts": 1756428581.709544, "side": "sell"}
{"type": "orderbook_delta", "seq": 8624, "price": 43, "quantity": 79, "ts": 1756428581.709544, "side": "sell"}
{"type": "orderbook_delta", "seq": 8625, "price": 43, "quantity": -79, "ts": 1756428581.758019, "side": "sell"}
{"type": "orderbook_delta", "seq": 8626, "price": 44, "quantity": 79, "ts": 1756428581.758019, "side": "sell"}
{"type": "orderbook_delta", "seq": 8627, "price": 35, "quantity": -100, "ts": 1756428581.815808, "side": "buy"}
{"type": "orderbook_delta", "seq": 8628, "price": 36, "quantity": -500, "ts": 1756428581.858578, "side": "buy"}
{"type": "orderbook_delta", "seq": 8629, "price": 35, "quantity": 500, "ts": 1756428581.909722, "side": "buy"}
{"type": "orderbook_delta", "seq": 8630, "price": 37, "quantity": 100, "ts": 1756428582.068901, "side": "buy"}
{"type": "orderbook_delta", "seq": 8631, "price": 35, "quantity": -500, "ts": 1756428582.104763, "side": "buy"}
{"type": "orderbook_delta", "seq": 8632, "price": 37, "quantity": 500, "ts": 1756428582.142055, "side": "buy"}
{"type": "orderbook_delta", "seq": 8633, "price": 48, "quantity": -1250, "ts": 1756428582.173939, "side": "sell"}
{"type": "orderbook_delta", "seq": 8634, "price": 10, "quantity": -8000, "ts": 1756428582.178489, "side": "buy"}
{"type": "orderbook_delta", "seq": 8635, "price": 46, "quantity": -200, "ts": 1756428582.180092, "side": "sell"}
{"type": "orderbook_delta", "seq": 8636, "price": 33, "quantity": -1250, "ts": 1756428582.186069, "side": "buy"}
{"type": "orderbook_delta", "seq": 8637, "price": 34, "quantity": 1250, "ts": 1756428582.22743, "side": "buy"}
{"type": "orderbook_delta", "seq": 8638, "price": 49, "quantity": 1250, "ts": 1756428582.227659, "side": "sell"}
{"type": "orderbook_delta", "seq": 8639, "price": 47, "quantity": 200, "ts": 1756428582.232299, "side": "sell"}
{"type": "orderbook_delta", "seq": 8640, "price": 11, "quantity": 8000, "ts": 1756428582.232663, "side": "buy"}
{"type": "orderbook_delta", "seq": 8641, "price": 34, "quantity": -100, "ts": 1756428582.642165, "side": "buy"}
{"type": "orderbook_delta", "seq": 8642, "price": 37, "quantity": 100, "ts": 1756428582.642165, "side": "buy"}
{"type": "orderbook_delta", "seq": 8643, "price": 37, "quantity": -100, "ts": 1756428582.789025, "side": "buy"}
{"type": "orderbook_delta", "seq": 8644, "price": 36, "quantity": 100, "ts": 1756428582.789025, "side": "buy"}
{"type": "orderbook_delta", "seq": 8645, "price": 37, "quantity": -100, "ts": 1756428582.796292, "side": "buy"}
{"type": "orderbook_delta", "seq": 8646, "price": 36, "quantity": -100, "ts": 1756428583.01636, "side": "buy"}
{"type": "orderbook_delta", "seq": 8647, "price": 34, "quantity": 100, "ts": 1756428583.01636, "side": "buy"}
{"type": "orderbook_delta", "seq": 8648, "price": 37, "quantity": -500, "ts": 1756428583.051072, "side": "buy"}
{"type": "orderbook_delta", "seq": 8649, "price": 35, "quantity": 500, "ts": 1756428583.147456, "side": "buy"}
{"type": "orderbook_delta", "seq": 8650, "price": 47, "quantity": -200, "ts": 1756428583.147742, "side": "sell"}
{"type": "orderbook_delta", "seq": 8651, "price": 49, "quantity": -1250, "ts": 1756428583.14779, "side": "sell"}
{"type": "orderbook_delta", "seq": 8652, "price": 11, "quantity": -8000, "ts": 1756428583.147835, "side": "buy"}
{"type": "orderbook_delta", "seq": 8653, "price": 34, "quantity": -1250, "ts": 1756428583.148212, "side": "buy"}
{"type": "orderbook_delta", "seq": 8654, "price": 35, "quantity": 100, "ts": 1756428583.148826, "side": "buy"}
{"type": "orderbook_delta", "seq": 8655, "price": 44, "quantity": -500, "ts": 1756428583.151956, "side": "sell"}
{"type": "orderbook_delta", "seq": 8656, "price": 48, "quantity": 1250, "ts": 1756428583.196276, "side": "sell"}
{"type": "orderbook_delta", "seq": 8657, "price": 35, "quantity": -500, "ts": 1756428583.199553, "side": "buy"}
{"type": "orderbook_delta", "seq": 8658, "price": 10, "quantity": 8000, "ts": 1756428583.200695, "side": "buy"}
{"type": "orderbook_delta", "seq": 8659, "price": 33, "quantity": 1250, "ts": 1756428583.200978, "side": "buy"}
{"type": "orderbook_delta", "seq": 8660, "price": 43, "quantity": 500, "ts": 1756428583.20163, "side": "sell"}
{"type": "orderbook_delta", "seq": 8661, "price": 46, "quantity": 200, "ts": 1756428583.201887, "side": "sell"}
{"type": "orderbook_delta", "seq": 8662, "price": 36, "quantity": 500, "ts": 1756428583.249167, "side": "buy"}
{"type": "orderbook_delta", "seq": 8663, "price": 34, "quantity": -100, "ts": 1756428583.257068, "side": "buy"}
{"type": "orderbook_delta", "seq": 8664, "price": 33, "quantity": 100, "ts": 1756428583.257068, "side": "buy"}
{"type": "orderbook_delta", "seq": 8665, "price": 46, "quantity": -200, "ts": 1756428583.26258, "side": "sell"}
{"type": "orderbook_delta", "seq": 8666, "price": 98, "quantity": -8000, "ts": 1756428583.263902, "side": "sell"}
{"type": "orderbook_delta", "seq": 8667, "price": 35, "quantity": -200, "ts": 1756428583.264224, "side": "buy"}
{"type": "orderbook_delta", "seq": 8668, "price": 33, "quantity": -1250, "ts": 1756428583.265702, "side": "buy"}
{"type": "orderbook_delta", "seq": 8669, "price": 10, "quantity": -8000, "ts": 1756428583.265801, "side": "buy"}
{"type": "orderbook_delta", "seq": 8670, "price": 48, "quantity": -1250, "ts": 1756428583.266901, "side": "sell"}
{"type": "orderbook_delta", "seq": 8671, "price": 34, "quantity": -250, "ts": 1756428583.2772, "side": "buy"}
{"type": "orderbook_delta", "seq": 8672, "price": 24, "quantity": 250, "ts": 1756428583.277503, "side": "buy"}
{"type": "orderbook_delta", "seq": 8673, "price": 44, "quantity": -200, "ts": 1756428583.282543, "side": "sell"}
{"type": "orderbook_delta", "seq": 8674, "price": 42, "quantity": 200, "ts": 1756428583.282543, "side": "sell"}
{"type": "orderbook_delta", "seq": 8675, "price": 70, "quantity": 8000, "ts": 1756428583.31272, "side": "sell"}
{"type": "orderbook_delta", "seq": 8676, "price": 33, "quantity": 200, "ts": 1756428583.313076, "side": "buy"}
{"type": "orderbook_delta", "seq": 8677, "price": 32, "quantity": 1250, "ts": 1756428583.31413, "side": "buy"}
{"type": "orderbook_delta", "seq": 8678, "price": 43, "quantity": -500, "ts": 1756428583.315159, "side": "sell"}
{"type": "orderbook_delta", "seq": 8679, "price": 45, "quantity": 200, "ts": 1756428583.315286, "side": "sell"}
{"type": "orderbook_delta", "seq": 8680, "price": 47, "quantity": 1250, "ts": 1756428583.315765, "side": "sell"}
{"type": "orderbook_delta", "seq": 8681, "price": 33, "quantity": -100, "ts": 1756428583.380668, "side": "buy"}
{"type": "orderbook_delta", "seq": 8682, "price": 31, "quantity": 100, "ts": 1756428583.380668, "side": "buy"}
{"type": "orderbook_delta", "seq": 8683, "price": 42, "quantity": 500, "ts": 1756428583.407781, "side": "sell"}
{"type": "orderbook_delta", "seq": 8684, "price": 44, "quantity": -79, "ts": 1756428583.422406, "side": "sell"}
{"type": "orderbook_delta", "seq": 8685, "price": 41, "quantity": 79, "ts": 1756428583.422406, "side": "sell"}
{"type": "orderbook_delta", "seq": 8686, "price": 41, "quantity": -79, "ts": 1756428583.470189, "side": "sell"}
{"type": "orderbook_delta", "seq": 8687, "price": 43, "quantity": 79, "ts": 1756428583.470189, "side": "sell"}
{"type": "orderbook_delta", "seq": 8688, "price": 47, "quantity": -1250, "ts": 1756428583.508124, "side": "sell"}
{"type": "orderbook_delta", "seq": 8689, "price": 70, "quantity": -8000, "ts": 1756428583.509435, "side": "sell"}
{"type": "orderbook_delta", "seq": 8690, "price": 46, "quantity": 1250, "ts": 1756428583.551731, "side": "sell"}
{"type": "orderbook_delta", "seq": 8691, "price": 69, "quantity": 8000, "ts": 1756428583.555616, "side": "sell"}
{"type": "orderbook_delta", "seq": 8692, "price": 42, "quantity": -500, "ts": 1756428583.79985, "side": "sell"}
{"type": "orderbook_delta", "seq": 8693, "price": 46, "quantity": -1250, "ts": 1756428583.800078, "side": "sell"}
{"type": "orderbook_delta", "seq": 8694, "price": 10, "quantity": 8000, "ts": 1756428583.800096, "side": "buy"}
{"type": "orderbook_delta", "seq": 8695, "price": 32, "quantity": -1250, "ts": 1756428583.800409, "side": "buy"}
{"type": "orderbook_delta", "seq": 8696, "price": 45, "quantity": -200, "ts": 1756428583.800497, "side": "sell"}
{"type": "orderbook_delta", "seq": 8697, "price": 69, "quantity": -8000, "ts": 1756428583.803711, "side": "sell"}
{"type": "orderbook_delta", "seq": 8698, "price": 98, "quantity": 8000, "ts": 1756428583.839263, "side": "sell"}
{"type": "orderbook_delta", "seq": 8699, "price": 33, "quantity": 1250, "ts": 1756428583.83955, "side": "buy"}
{"type": "orderbook_delta", "seq": 8700, "price": 43, "quantity": 500, "ts": 1756428583.839957, "side": "sell"}
{"type": "orderbook_delta", "seq": 8701, "price": 46, "quantity": 200, "ts": 1756428583.844542, "side": "sell"}
{"type": "orderbook_delta", "seq": 8702, "price": 48, "quantity": 1250, "ts": 1756428583.853613, "side": "sell"}
{"type": "orderbook_delta", "seq": 8703, "price": 43, "quantity": -79, "ts": 1756428583.863435, "side": "sell"}
{"type": "orderbook_delta", "seq": 8704, "price": 44, "quantity": 79, "ts": 1756428583.863435, "side": "sell"}
{"type": "orderbook_delta", "seq": 8705, "price": 42, "quantity": -200, "ts": 1756428583.893411, "side": "sell"}
{"type": "orderbook_delta", "seq": 8706, "price": 45, "quantity": 200, "ts": 1756428583.893411, "side": "sell"}
{"type": "orderbook_delta", "seq": 8707, "price": 38, "quantity": -106, "ts": 1756428583.900284, "side": "sell"}
{"type": "orderbook_delta", "seq": 8708, "price": 44, "quantity": -79, "ts": 1756428583.917853, "side": "sell"}
{"type": "orderbook_delta", "seq": 8709, "price": 45, "quantity": 79, "ts": 1756428583.917853, "side": "sell"}
{"type": "orderbook_delta", "seq": 8710, "price": 45, "quantity": -79, "ts": 1756428584.019711, "side": "sell"}
{"type": "orderbook_delta", "seq": 8711, "price": 46, "quantity": 79, "ts": 1756428584.019711, "side": "sell"}
{"type": "orderbook_delta", "seq": 8712, "price": 44, "quantity": -949, "ts": 1756428584.13328, "side": "sell"}
{"type": "orderbook_delta", "seq": 8713, "price": 44, "quantity": 250, "ts": 1756428584.134041, "side": "sell"}
{"type": "orderbook_delta", "seq": 8714, "price": 54, "quantity": -250, "ts": 1756428584.146951, "side": "sell"}
{"type": "orderbook_delta", "seq": 8715, "price": 37, "quantity": 106, "ts": 1756428584.178297, "side": "sell"}
{"type": "orderbook_delta", "seq": 8716, "price": 46, "quantity": -79, "ts": 1756428584.185348, "side": "sell"}
{"type": "orderbook_delta", "seq": 8717, "price": 48, "quantity": 79, "ts": 1756428584.185348, "side": "sell"}
{"type": "orderbook_delta", "seq": 8718, "price": 42, "quantity": 949, "ts": 1756428584.194267, "side": "sell"}
{"type": "orderbook_delta", "seq": 8719, "price": 42, "quantity": -949, "ts": 1756428584.343488, "side": "sell"}
{"type": "orderbook_delta", "seq": 8720, "price": 56, "quantity": 250, "ts": 1756428584.345912, "side": "sell"}
{"type": "orderbook_delta", "seq": 8721, "price": 10, "quantity": -8000, "ts": 1756428584.35595, "side": "buy"}
{"type": "orderbook_delta", "seq": 8722, "price": 44, "quantity": -250, "ts": 1756428584.356036, "side": "sell"}
{"type": "trade", "seq": 82, "price": 37, "quantity": 106, "ts": 1756428584.356151, "side": "buy"}
{"type": "orderbook_delta", "seq": 8723, "price": 43, "quantity": -500, "ts": 1756428584.356151, "side": "sell"}
{"type": "orderbook_delta", "seq": 8724, "price": 37, "quantity": 0, "ts": 1756428584.357756, "side": "sell"}
{"type": "orderbook_delta", "seq": 8725, "price": 46, "quantity": -200, "ts": 1756428584.363194, "side": "sell"}
{"type": "orderbook_delta", "seq": 8726, "price": 48, "quantity": -1250, "ts": 1756428584.364797, "side": "sell"}
{"type": "orderbook_delta", "seq": 8727, "price": 54, "quantity": 250, "ts": 1756428584.365985, "side": "sell"}
{"type": "orderbook_delta", "seq": 8728, "price": 46, "quantity": -250, "ts": 1756428584.377468, "side": "sell"}
{"type": "orderbook_delta", "seq": 8729, "price": 48, "quantity": 200, "ts": 1756428584.406444, "side": "sell"}
{"type": "orderbook_delta", "seq": 8730, "price": 12, "quantity": 8000, "ts": 1756428584.40676, "side": "buy"}
{"type": "orderbook_delta", "seq": 8731, "price": 50, "quantity": 1250, "ts": 1756428584.407291, "side": "sell"}
{"type": "orderbook_delta", "seq": 8732, "price": 45, "quantity": 500, "ts": 1756428584.408956, "side": "sell"}
{"type": "orderbook_delta", "seq": 8733, "price": 46, "quantity": 949, "ts": 1756428584.430799, "side": "sell"}
{"type": "orderbook_delta", "seq": 8734, "price": 97, "quantity": 5400, "ts": 1756428584.492489, "side": "sell"}
{"type": "orderbook_delta", "seq": 8735, "price": 98, "quantity": -8000, "ts": 1756428584.531168, "side": "sell"}
{"type": "orderbook_delta", "seq": 8736, "price": 96, "quantity": 7000, "ts": 1756428584.531514, "side": "sell"}
{"type": "orderbook_delta", "seq": 8737, "price": 96, "quantity": 8000, "ts": 1756428584.56623, "side": "sell"}
{"type": "orderbook_delta", "seq": 8738, "price": 31, "quantity": -100, "ts": 1756428584.725305, "side": "buy"}
{"type": "orderbook_delta", "seq": 8739, "price": 36, "quantity": 100, "ts": 1756428584.725305, "side": "buy"}
{"type": "orderbook_delta", "seq": 8740, "price": 36, "quantity": -500, "ts": 1756428584.768269, "side": "buy"}
{"type": "orderbook_delta", "seq": 8741, "price": 37, "quantity": 500, "ts": 1756428584.805971, "side": "buy"}
{"type": "orderbook_delta", "seq": 8742, "price": 36, "quantity": -100, "ts": 1756428584.819034, "side": "buy"}
{"type": "orderbook_delta", "seq": 8743, "price": 34, "quantity": 100, "ts": 1756428584.819034, "side": "buy"}
{"type": "orderbook_delta", "seq": 8744, "price": 37, "quantity": -500, "ts": 1756428584.847391, "side": "buy"}
{"type": "orderbook_delta", "seq": 8745, "price": 36, "quantity": 500, "ts": 1756428584.894587, "side": "buy"}
{"type": "orderbook_delta", "seq": 8746, "price": 34, "quantity": -100, "ts": 1756428584.903024, "side": "buy"}
{"type": "orderbook_delta", "seq": 8747, "price": 33, "quantity": 100, "ts": 1756428584.903024, "side": "buy"}
{"type": "orderbook_delta", "seq": 8748, "price": 35, "quantity": -100, "ts": 1756428585.113526, "side": "buy"}
{"type": "orderbook_delta", "seq": 8749, "price": 36, "quantity": -500, "ts": 1756428585.142775, "side": "buy"}
{"type": "orderbook_delta", "seq": 8750, "price": 34, "quantity": 250, "ts": 1756428585.167835, "side": "buy"}
{"type": "orderbook_delta", "seq": 8751, "price": 24, "quantity": -250, "ts": 1756428585.168135, "side": "buy"}
{"type": "orderbook_delta", "seq": 8752, "price": 36, "quantity": 250, "ts": 1756428585.186905, "side": "buy"}
{"type": "orderbook_delta", "seq": 8753, "price": 26, "quantity": -250, "ts": 1756428585.187264, "side": "buy"}
{"type": "orderbook_delta", "seq": 8754, "price": 34, "quantity": 500, "ts": 1756428585.190215, "side": "buy"}
{"type": "orderbook_delta", "seq": 8755, "price": 33, "quantity": -1250, "ts": 1756428585.201549, "side": "buy"}
{"type": "orderbook_delta", "seq": 8756, "price": 33, "quantity": -200, "ts": 1756428585.203247, "side": "buy"}
{"type": "orderbook_delta", "seq": 8757, "price": 35, "quantity": 1250, "ts": 1756428585.230372, "side": "buy"}
{"type": "orderbook_delta", "seq": 8758, "price": 36, "quantity": -250, "ts": 1756428585.234383, "side": "buy"}
{"type": "orderbook_delta", "seq": 8759, "price": 37, "quantity": 200, "ts": 1756428585.254852, "side": "buy"}
{"type": "orderbook_delta", "seq": 8760, "price": 37, "quantity": 100, "ts": 1756428585.338658, "side": "buy"}
{"type": "orderbook_delta", "seq": 8761, "price": 37, "quantity": -200, "ts": 1756428585.367634, "side": "buy"}
{"type": "orderbook_delta", "seq": 8762, "price": 35, "quantity": 200, "ts": 1756428585.419764, "side": "buy"}
{"type": "orderbook_delta", "seq": 8763, "price": 34, "quantity": -500, "ts": 1756428585.452777, "side": "buy"}
{"type": "orderbook_delta", "seq": 8764, "price": 97, "quantity": 5400, "ts": 1756428585.456321, "side": "sell"}
{"type": "orderbook_delta", "seq": 8765, "price": 38, "quantity": 500, "ts": 1756428585.518813, "side": "buy"}
{"type": "orderbook_delta", "seq": 8766, "price": 48, "quantity": -79, "ts": 1756428585.548234, "side": "sell"}
{"type": "orderbook_delta", "seq": 8767, "price": 44, "quantity": 79, "ts": 1756428585.548234, "side": "sell"}
{"type": "orderbook_delta", "seq": 8768, "price": 46, "quantity": 250, "ts": 1756428586.205744, "side": "sell"}
{"type": "orderbook_delta", "seq": 8769, "price": 46, "quantity": -949, "ts": 1756428586.206219, "side": "sell"}
{"type": "orderbook_delta", "seq": 8770, "price": 44, "quantity": 106, "ts": 1756428586.221933, "side": "sell"}
{"type": "orderbook_delta", "seq": 8771, "price": 56, "quantity": -250, "ts": 1756428586.227824, "side": "sell"}
{"type": "orderbook_delta", "seq": 8772, "price": 50, "quantity": -1250, "ts": 1756428586.235647, "side": "sell"}
{"type": "orderbook_delta", "seq": 8773, "price": 12, "quantity": -8000, "ts": 1756428586.235732, "side": "buy"}
{"type": "orderbook_delta", "seq": 8774, "price": 48, "quantity": -200, "ts": 1756428586.235832, "side": "sell"}
{"type": "orderbook_delta", "seq": 8775, "price": 44, "quantity": 949, "ts": 1756428586.273656, "side": "sell"}
{"type": "orderbook_delta", "seq": 8776, "price": 44, "quantity": -79, "ts": 1756428586.280619, "side": "sell"}
{"type": "orderbook_delta", "seq": 8777, "price": 43, "quantity": 79, "ts": 1756428586.280619, "side": "sell"}
{"type": "orderbook_delta", "seq": 8778, "price": 47, "quantity": 200, "ts": 1756428586.289019, "side": "sell"}
{"type": "orderbook_delta", "seq": 8779, "price": 49, "quantity": 1250, "ts": 1756428586.289725, "side": "sell"}
{"type": "orderbook_delta", "seq": 8780, "price": 11, "quantity": 8000, "ts": 1756428586.289996, "side": "buy"}
{"type": "orderbook_delta", "seq": 8781, "price": 97, "quantity": -5400, "ts": 1756428586.292853, "side": "sell"}
{"type": "orderbook_delta", "seq": 8782, "price": 97, "quantity": -5400, "ts": 1756428586.338195, "side": "sell"}
{"type": "orderbook_delta", "seq": 8783, "price": 98, "quantity": 8100, "ts": 1756428586.338195, "side": "sell"}
{"type": "orderbook_delta", "seq": 8784, "price": 96, "quantity": -8000, "ts": 1756428586.375423, "side": "sell"}
{"type": "orderbook_delta", "seq": 8785, "price": 96, "quantity": -7000, "ts": 1756428586.382389, "side": "sell"}
{"type": "orderbook_delta", "seq": 8786, "price": 33, "quantity": -100, "ts": 1756428586.408526, "side": "buy"}
{"type": "orderbook_delta", "seq": 8787, "price": 36, "quantity": 100, "ts": 1756428586.408526, "side": "buy"}
{"type": "orderbook_delta", "seq": 8788, "price": 97, "quantity": 8000, "ts": 1756428586.41947, "side": "sell"}
{"type": "orderbook_delta", "seq": 8789, "price": 97, "quantity": 7000, "ts": 1756428586.420124, "side": "sell"}
{"type": "orderbook_delta", "seq": 8790, "price": 37, "quantity": -100, "ts": 1756428586.964799, "side": "buy"}
{"type": "orderbook_delta", "seq": 8791, "price": 38, "quantity": -500, "ts": 1756428587.015493, "side": "buy"}
{"type": "orderbook_delta", "seq": 8792, "price": 37, "quantity": 500, "ts": 1756428587.053843, "side": "buy"}
{"type": "orderbook_delta", "seq": 8793, "price": 43, "quantity": -79, "ts": 1756428587.178018, "side": "sell"}
{"type": "orderbook_delta", "seq": 8794, "price": 44, "quantity": 79, "ts": 1756428587.178018, "side": "sell"}
{"type": "orderbook_delta", "seq": 8795, "price": 39, "quantity": 100, "ts": 1756428587.198215, "side": "buy"}
{"type": "orderbook_delta", "seq": 8796, "price": 98, "quantity": -8100, "ts": 1756428587.251031, "side": "sell"}
{"type": "orderbook_delta", "seq": 8797, "price": 97, "quantity": 5400, "ts": 1756428587.251031, "side": "sell"}
{"type": "orderbook_delta", "seq": 8798, "price": 97, "quantity": -8000, "ts": 1756428587.30539, "side": "sell"}
{"type": "orderbook_delta", "seq": 8799, "price": 97, "quantity": -7000, "ts": 1756428587.305821, "side": "sell"}
{"type": "orderbook_delta", "seq": 8800, "price": 37, "quantity": -500, "ts": 1756428587.306112, "side": "buy"}
{"type": "orderbook_delta", "seq": 8801, "price": 39, "quantity": 500, "ts": 1756428587.356338, "side": "buy"}
{"type": "orderbook_delta", "seq": 8802, "price": 96, "quantity": 7000, "ts": 1756428587.357265, "side": "sell"}
{"type": "orderbook_delta", "seq": 8803, "price": 96, "quantity": 8000, "ts": 1756428587.357955, "side": "sell"}
{"type": "orderbook_delta", "seq": 8804, "price": 45, "quantity": -500, "ts": 1756428587.64984, "side": "sell"}
{"type": "orderbook_delta", "seq": 8805, "price": 11, "quantity": -8000, "ts": 1756428587.650393, "side": "buy"}
{"type": "orderbook_delta", "seq": 8806, "price": 39, "quantity": -500, "ts": 1756428587.651869, "side": "buy"}
{"type": "orderbook_delta", "seq": 8807, "price": 47, "quantity": -200, "ts": 1756428587.652016, "side": "sell"}
{"type": "orderbook_delta", "seq": 8808, "price": 49, "quantity": -1250, "ts": 1756428587.653422, "side": "sell"}
{"type": "orderbook_delta", "seq": 8809, "price": 40, "quantity": 500, "ts": 1756428587.682883, "side": "buy"}
{"type": "orderbook_delta", "seq": 8810, "price": 50, "quantity": 1250, "ts": 1756428587.684819, "side": "sell"}
{"type": "orderbook_delta", "seq": 8811, "price": 46, "quantity": 500, "ts": 1756428587.685595, "side": "sell"}
{"type": "orderbook_delta", "seq": 8812, "price": 12, "quantity": 8000, "ts": 1756428587.685875, "side": "buy"}
{"type": "orderbook_delta", "seq": 8813, "price": 48, "quantity": 200, "ts": 1756428587.686123, "side": "sell"}
{"type": "orderbook_delta", "seq": 8814, "price": 36, "quantity": -100, "ts": 1756428587.873769, "side": "buy"}
{"type": "orderbook_delta", "seq": 8815, "price": 35, "quantity": 100, "ts": 1756428587.873769, "side": "buy"}
{"type": "orderbook_delta", "seq": 8816, "price": 44, "quantity": -106, "ts": 1756428587.900738, "side": "sell"}
{"type": "orderbook_delta", "seq": 8817, "price": 42, "quantity": 106, "ts": 1756428588.157734, "side": "sell"}
{"type": "orderbook_delta", "seq": 8818, "price": 97, "quantity": -5400, "ts": 1756428588.164944, "side": "sell"}
{"type": "orderbook_delta", "seq": 8819, "price": 98, "quantity": 8100, "ts": 1756428588.164944, "side": "sell"}
{"type": "orderbook_delta", "seq": 8820, "price": 46, "quantity": -500, "ts": 1756428588.170477, "side": "sell"}
{"type": "orderbook_delta", "seq": 8821, "price": 96, "quantity": -8000, "ts": 1756428588.199474, "side": "sell"}
{"type": "orderbook_delta", "seq": 8822, "price": 96, "quantity": -7000, "ts": 1756428588.20363, "side": "sell"}
{"type": "orderbook_delta", "seq": 8823, "price": 45, "quantity": 500, "ts": 1756428588.223615, "side": "sell"}
{"type": "orderbook_delta", "seq": 8824, "price": 97, "quantity": 7000, "ts": 1756428588.23918, "side": "sell"}
{"type": "orderbook_delta", "seq": 8825, "price": 97, "quantity": 8000, "ts": 1756428588.240674, "side": "sell"}
{"type": "orderbook_delta", "seq": 8826, "price": 39, "quantity": -100, "ts": 1756428588.923, "side": "buy"}
{"type": "orderbook_delta", "seq": 8827, "price": 40, "quantity": -500, "ts": 1756428588.953389, "side": "buy"}
{"type": "orderbook_delta", "seq": 8828, "price": 36, "quantity": 500, "ts": 1756428588.986444, "side": "buy"}
{"type": "orderbook_delta", "seq": 8829, "price": 44, "quantity": -79, "ts": 1756428589.09806, "side": "sell"}
{"type": "orderbook_delta", "seq": 8830, "price": 45, "quantity": 79, "ts": 1756428589.09806, "side": "sell"}
{"type": "orderbook_delta", "seq": 8831, "price": 40, "quantity": 100, "ts": 1756428589.153435, "side": "buy"}
{"type": "orderbook_delta", "seq": 8832, "price": 36, "quantity": -500, "ts": 1756428589.258742, "side": "buy"}
{"type": "orderbook_delta", "seq": 8833, "price": 45, "quantity": -79, "ts": 1756428589.26057, "side": "sell"}
{"type": "orderbook_delta", "seq": 8834, "price": 46, "quantity": 79, "ts": 1756428589.26057, "side": "sell"}
{"type": "orderbook_delta", "seq": 8835, "price": 40, "quantity": 500, "ts": 1756428589.294876, "side": "buy"}
{"type": "orderbook_delta", "seq": 8836, "price": 35, "quantity": -100, "ts": 1756428589.378121, "side": "buy"}
{"type": "orderbook_delta", "seq": 8837, "price": 40, "quantity": 100, "ts": 1756428589.378121, "side": "buy"}
{"type": "orderbook_delta", "seq": 8838, "price": 40, "quantity": -100, "ts": 1756428589.89076, "side": "buy"}
{"type": "orderbook_delta", "seq": 8839, "price": 37, "quantity": 100, "ts": 1756428590.202964, "side": "buy"}
{"type": "orderbook_delta", "seq": 8840, "price": 40, "quantity": -100, "ts": 1756428590.209098, "side": "buy"}
{"type": "orderbook_delta", "seq": 8841, "price": 39, "quantity": 100, "ts": 1756428590.209098, "side": "buy"}
{"type": "orderbook_delta", "seq": 8842, "price": 40, "quantity": -500, "ts": 1756428590.382349, "side": "buy"}
{"type": "orderbook_delta", "seq": 8843, "price": 39, "quantity": -100, "ts": 1756428590.39743, "side": "buy"}
{"type": "orderbook_delta", "seq": 8844, "price": 37, "quantity": 100, "ts": 1756428590.39743, "side": "buy"}
{"type": "orderbook_delta", "seq": 8845, "price": 39, "quantity": 500, "ts": 1756428590.425326, "side": "buy"}
{"type": "orderbook_delta", "seq": 8846, "price": 39, "quantity": -500, "ts": 1756428590.463217, "side": "buy"}
{"type": "orderbook_delta", "seq": 8847, "price": 37, "quantity": -100, "ts": 1756428590.485243, "side": "buy"}
{"type": "orderbook_delta", "seq": 8848, "price": 36, "quantity": 100, "ts": 1756428590.485243, "side": "buy"}
{"type": "orderbook_delta", "seq": 8849, "price": 35, "quantity": -200, "ts": 1756428590.486434, "side": "buy"}
{"type": "orderbook_delta", "seq": 8850, "price": 38, "quantity": 500, "ts": 1756428590.50012, "side": "buy"}
{"type": "orderbook_delta", "seq": 8851, "price": 35, "quantity": 200, "ts": 1756428590.523999, "side": "buy"}
{"type": "orderbook_delta", "seq": 8852, "price": 44, "quantity": -949, "ts": 1756428591.100088, "side": "sell"}
{"type": "orderbook_delta", "seq": 8853, "price": 56, "quantity": 250, "ts": 1756428591.109225, "side": "sell"}
{"type": "orderbook_delta", "seq": 8854, "price": 46, "quantity": -250, "ts": 1756428591.115779, "side": "sell"}
{"type": "orderbook_delta", "seq": 8855, "price": 46, "quantity": 949, "ts": 1756428591.157619, "side": "sell"}
{"type": "orderbook_delta", "seq": 8856, "price": 37, "quantity": -100, "ts": 1756428591.2203, "side": "buy"}
{"type": "orderbook_delta", "seq": 8857, "price": 38, "quantity": -500, "ts": 1756428591.2945, "side": "buy"}
{"type": "orderbook_delta", "seq": 8858, "price": 46, "quantity": -79, "ts": 1756428591.295382, "side": "sell"}
{"type": "orderbook_delta", "seq": 8859, "price": 45, "quantity": 79, "ts": 1756428591.295382, "side": "sell"}
{"type": "orderbook_delta", "seq": 8860, "price": 37, "quantity": 500, "ts": 1756428591.326896, "side": "buy"}
{"type": "orderbook_delta", "seq": 8861, "price": 36, "quantity": -100, "ts": 1756428591.389506, "side": "buy"}
{"type": "orderbook_delta", "seq": 8862, "price": 37, "quantity": 100, "ts": 1756428591.389506, "side": "buy"}
