{"type": "orderbook_delta", "seq": 1780, "price": 50, "quantity": -250, "ts": 1756428212.266382, "side": "sell"}
{"type": "orderbook_delta", "seq": 1781, "price": 54, "quantity": -100, "ts": 1756428212.276612, "side": "sell"}
{"type": "orderbook_delta", "seq": 1782, "price": 55, "quantity": 100, "ts": 1756428212.276612, "side": "sell"}
{"type": "orderbook_delta", "seq": 1783, "price": 34, "quantity": -250, "ts": 1756428212.286524, "side": "buy"}
{"type": "orderbook_delta", "seq": 1784, "price": 49, "quantity": 67, "ts": 1756428212.34333, "side": "sell"}
{"type": "orderbook_delta", "seq": 1785, "price": 55, "quantity": -100, "ts": 1756428212.34871, "side": "sell"}
{"type": "orderbook_delta", "seq": 1786, "price": 56, "quantity": 100, "ts": 1756428212.34871, "side": "sell"}
{"type": "orderbook_delta", "seq": 1787, "price": 49, "quantity": -500, "ts": 1756428212.360433, "side": "sell"}
{"type": "orderbook_delta", "seq": 1788, "price": 40, "quantity": -200, "ts": 1756428212.36149, "side": "buy"}
{"type": "orderbook_delta", "seq": 1789, "price": 53, "quantity": -1250, "ts": 1756428212.363034, "side": "sell"}
{"type": "orderbook_delta", "seq": 1790, "price": 43, "quantity": -500, "ts": 1756428212.363311, "side": "buy"}
{"type": "orderbook_delta", "seq": 1791, "price": 38, "quantity": -1250, "ts": 1756428212.363792, "side": "buy"}
{"type": "orderbook_delta", "seq": 1792, "price": 51, "quantity": -200, "ts": 1756428212.364631, "side": "sell"}
{"type": "orderbook_delta", "seq": 1793, "price": 45, "quantity": 500, "ts": 1756428212.396641, "side": "buy"}
{"type": "orderbook_delta", "seq": 1794, "price": 42, "quantity": 200, "ts": 1756428212.39756, "side": "buy"}
{"type": "orderbook_delta", "seq": 1795, "price": 51, "quantity": 500, "ts": 1756428212.397926, "side": "sell"}
{"type": "orderbook_delta", "seq": 1796, "price": 53, "quantity": 200, "ts": 1756428212.399793, "side": "sell"}
{"type": "orderbook_delta", "seq": 1797, "price": 43, "quantity": -100, "ts": 1756428212.400127, "side": "buy"}
{"type": "orderbook_delta", "seq": 1798, "price": 45, "quantity": 100, "ts": 1756428212.400127, "side": "buy"}
{"type": "orderbook_delta", "seq": 1799, "price": 40, "quantity": 1250, "ts": 1756428212.400308, "side": "buy"}
{"type": "orderbook_delta", "seq": 1800, "price": 55, "quantity": 1250, "ts": 1756428212.401252, "side": "sell"}
{"type": "orderbook_delta", "seq": 1801, "price": 52, "quantity": -250, "ts": 1756428212.443339, "side": "sell"}
{"type": "orderbook_delta", "seq": 1802, "price": 62, "quantity": 250, "ts": 1756428212.447733, "side": "sell"}
{"type": "orderbook_delta", "seq": 1803, "price": 49, "quantity": -67, "ts": 1756428212.470713, "side": "sell"}
{"type": "orderbook_delta", "seq": 1804, "price": 64, "quantity": 250, "ts": 1756428212.475555, "side": "sell"}
{"type": "orderbook_delta", "seq": 1805, "price": 54, "quantity": -250, "ts": 1756428212.477325, "side": "sell"}
{"type": "orderbook_delta", "seq": 1806, "price": 51, "quantity": -500, "ts": 1756428212.481047, "side": "sell"}
{"type": "orderbook_delta", "seq": 1807, "price": 42, "quantity": -200, "ts": 1756428212.481377, "side": "buy"}
{"type": "orderbook_delta", "seq": 1808, "price": 53, "quantity": -200, "ts": 1756428212.481922, "side": "sell"}
{"type": "orderbook_delta", "seq": 1809, "price": 79, "quantity": -8000, "ts": 1756428212.482053, "side": "sell"}
{"type": "orderbook_delta", "seq": 1810, "price": 55, "quantity": -1250, "ts": 1756428212.485121, "side": "sell"}
{"type": "orderbook_delta", "seq": 1811, "price": 45, "quantity": -500, "ts": 1756428212.48685, "side": "buy"}
{"type": "orderbook_delta", "seq": 1812, "price": 40, "quantity": -1250, "ts": 1756428212.491791, "side": "buy"}
{"type": "orderbook_delta", "seq": 1813, "price": 52, "quantity": 67, "ts": 1756428212.522562, "side": "sell"}
{"type": "orderbook_delta", "seq": 1814, "price": 42, "quantity": 1250, "ts": 1756428212.529101, "side": "buy"}
{"type": "orderbook_delta", "seq": 1815, "price": 55, "quantity": 200, "ts": 1756428212.529361, "side": "sell"}
{"type": "orderbook_delta", "seq": 1816, "price": 98, "quantity": 8000, "ts": 1756428212.529751, "side": "sell"}
{"type": "orderbook_delta", "seq": 1817, "price": 44, "quantity": 200, "ts": 1756428212.53051, "side": "buy"}
{"type": "orderbook_delta", "seq": 1818, "price": 57, "quantity": 1250, "ts": 1756428212.530829, "side": "sell"}
{"type": "orderbook_delta", "seq": 1819, "price": 46, "quantity": 500, "ts": 1756428212.531678, "side": "buy"}
{"type": "orderbook_delta", "seq": 1820, "price": 55, "quantity": 500, "ts": 1756428212.532488, "side": "sell"}
{"type": "orderbook_delta", "seq": 1821, "price": 51, "quantity": -200, "ts": 1756428212.561294, "side": "sell"}
{"type": "orderbook_delta", "seq": 1822, "price": 55, "quantity": 200, "ts": 1756428212.561294, "side": "sell"}
{"type": "orderbook_delta", "seq": 1823, "price": 55, "quantity": -500, "ts": 1756428212.589229, "side": "sell"}
{"type": "orderbook_delta", "seq": 1824, "price": 52, "quantity": -67, "ts": 1756428212.620871, "side": "sell"}
{"type": "orderbook_delta", "seq": 1825, "price": 54, "quantity": 500, "ts": 1756428212.623268, "side": "sell"}
{"type": "orderbook_delta", "seq": 1826, "price": 57, "quantity": -1250, "ts": 1756428212.629577, "side": "sell"}
{"type": "orderbook_delta", "seq": 1827, "price": 42, "quantity": -1250, "ts": 1756428212.629638, "side": "buy"}
{"type": "orderbook_delta", "seq": 1828, "price": 55, "quantity": -200, "ts": 1756428212.629998, "side": "sell"}
{"type": "orderbook_delta", "seq": 1829, "price": 44, "quantity": -200, "ts": 1756428212.630254, "side": "buy"}
{"type": "orderbook_delta", "seq": 1830, "price": 45, "quantity": -100, "ts": 1756428212.658871, "side": "buy"}
{"type": "orderbook_delta", "seq": 1831, "price": 46, "quantity": 100, "ts": 1756428212.658871, "side": "buy"}
{"type": "orderbook_delta", "seq": 1832, "price": 45, "quantity": 200, "ts": 1756428212.668406, "side": "buy"}
{"type": "orderbook_delta", "seq": 1833, "price": 58, "quantity": 1250, "ts": 1756428212.669339, "side": "sell"}
{"type": "orderbook_delta", "seq": 1834, "price": 56, "quantity": 200, "ts": 1756428212.670524, "side": "sell"}
{"type": "orderbook_delta", "seq": 1835, "price": 43, "quantity": 1250, "ts": 1756428212.6712, "side": "buy"}
{"type": "orderbook_delta", "seq": 1836, "price": 53, "quantity": 67, "ts": 1756428212.686999, "side": "sell"}
{"type": "orderbook_delta", "seq": 1837, "price": 55, "quantity": -200, "ts": 1756428212.690396, "side": "sell"}
{"type": "orderbook_delta", "seq": 1838, "price": 57, "quantity": 200, "ts": 1756428212.690396, "side": "sell"}
{"type": "orderbook_delta", "seq": 1839, "price": 54, "quantity": -500, "ts": 1756428212.721338, "side": "sell"}
{"type": "orderbook_delta", "seq": 1840, "price": 56, "quantity": -100, "ts": 1756428212.741586, "side": "sell"}
{"type": "orderbook_delta", "seq": 1841, "price": 58, "quantity": 100, "ts": 1756428212.741586, "side": "sell"}
{"type": "orderbook_delta", "seq": 1842, "price": 55, "quantity": 500, "ts": 1756428212.757134, "side": "sell"}
{"type": "orderbook_delta", "seq": 1843, "price": 58, "quantity": -100, "ts": 1756428213.073421, "side": "sell"}
{"type": "orderbook_delta", "seq": 1844, "price": 59, "quantity": 100, "ts": 1756428213.073421, "side": "sell"}
{"type": "orderbook_delta", "seq": 1845, "price": 10, "quantity": -200, "ts": 1756428213.093891, "side": "buy"}
{"type": "orderbook_delta", "seq": 1846, "price": 20, "quantity": 200, "ts": 1756428213.093891, "side": "buy"}
{"type": "orderbook_delta", "seq": 1847, "price": 11, "quantity": -8000, "ts": 1756428213.118385, "side": "buy"}
{"type": "trade", "seq": 23, "price": 47, "quantity": 100, "ts": 1756428213.130714, "side": "buy"}
{"type": "orderbook_delta", "seq": 1848, "price": 47, "quantity": 0, "ts": 1756428213.130714, "side": "sell"}
{"type": "orderbook_delta", "seq": 1849, "price": 53, "quantity": -67, "ts": 1756428213.131941, "side": "sell"}
{"type": "orderbook_delta", "seq": 1850, "price": 38, "quantity": -250, "ts": 1756428213.17252, "side": "buy"}
{"type": "orderbook_delta", "seq": 1851, "price": 48, "quantity": 250, "ts": 1756428213.175054, "side": "buy"}
{"type": "orderbook_delta", "seq": 1852, "price": 36, "quantity": -250, "ts": 1756428213.186584, "side": "buy"}
{"type": "orderbook_delta", "seq": 1853, "price": 46, "quantity": 250, "ts": 1756428213.186605, "side": "buy"}
{"type": "orderbook_delta", "seq": 1854, "price": 46, "quantity": -500, "ts": 1756428213.219915, "side": "buy"}
{"type": "orderbook_delta", "seq": 1855, "price": 46, "quantity": -100, "ts": 1756428213.223301, "side": "buy"}
{"type": "orderbook_delta", "seq": 1856, "price": 49, "quantity": 100, "ts": 1756428213.223301, "side": "buy"}
{"type": "orderbook_delta", "seq": 1857, "price": 54, "quantity": 67, "ts": 1756428213.23916, "side": "sell"}
{"type": "orderbook_delta", "seq": 1858, "price": 54, "quantity": 100, "ts": 1756428213.254206, "side": "sell"}
{"type": "orderbook_delta", "seq": 1859, "price": 48, "quantity": 500, "ts": 1756428213.267901, "side": "buy"}
{"type": "orderbook_delta", "seq": 1860, "price": 48, "quantity": -250, "ts": 1756428213.27287, "side": "buy"}
{"type": "orderbook_delta", "seq": 1861, "price": 55, "quantity": -500, "ts": 1756428213.272986, "side": "sell"}
{"type": "orderbook_delta", "seq": 1862, "price": 38, "quantity": 250, "ts": 1756428213.273303, "side": "buy"}
{"type": "orderbook_delta", "seq": 1863, "price": 54, "quantity": 500, "ts": 1756428213.310174, "side": "sell"}
{"type": "orderbook_delta", "seq": 1864, "price": 48, "quantity": -500, "ts": 1756428213.391605, "side": "buy"}
{"type": "orderbook_delta", "seq": 1865, "price": 47, "quantity": 500, "ts": 1756428213.437213, "side": "buy"}
{"type": "orderbook_delta", "seq": 1866, "price": 20, "quantity": 8000, "ts": 1756428213.773319, "side": "buy"}
{"type": "orderbook_delta", "seq": 1867, "price": 56, "quantity": -200, "ts": 1756428213.775332, "side": "sell"}
{"type": "orderbook_delta", "seq": 1868, "price": 58, "quantity": -1250, "ts": 1756428213.775902, "side": "sell"}
{"type": "orderbook_delta", "seq": 1869, "price": 43, "quantity": -1250, "ts": 1756428213.775992, "side": "buy"}
{"type": "orderbook_delta", "seq": 1870, "price": 45, "quantity": -200, "ts": 1756428213.776364, "side": "buy"}
{"type": "orderbook_delta", "seq": 1871, "price": 54, "quantity": -67, "ts": 1756428213.804984, "side": "sell"}
{"type": "orderbook_delta", "seq": 1872, "price": 48, "quantity": 250, "ts": 1756428213.80731, "side": "buy"}
{"type": "orderbook_delta", "seq": 1873, "price": 20, "quantity": -8000, "ts": 1756428213.811336, "side": "buy"}
{"type": "orderbook_delta", "seq": 1874, "price": 47, "quantity": -500, "ts": 1756428213.811966, "side": "buy"}
{"type": "orderbook_delta", "seq": 1875, "price": 54, "quantity": -500, "ts": 1756428213.812287, "side": "sell"}
{"type": "orderbook_delta", "seq": 1876, "price": 54, "quantity": -100, "ts": 1756428213.815481, "side": "sell"}
{"type": "orderbook_delta", "seq": 1877, "price": 46, "quantity": 1250, "ts": 1756428213.826092, "side": "buy"}
{"type": "orderbook_delta", "seq": 1878, "price": 66, "quantity": 250, "ts": 1756428213.826692, "side": "sell"}
{"type": "orderbook_delta", "seq": 1879, "price": 38, "quantity": -250, "ts": 1756428213.846717, "side": "buy"}
{"type": "orderbook_delta", "seq": 1880, "price": 61, "quantity": 1250, "ts": 1756428213.851846, "side": "sell"}
{"type": "orderbook_delta", "seq": 1881, "price": 59, "quantity": 200, "ts": 1756428213.852099, "side": "sell"}
{"type": "orderbook_delta", "seq": 1882, "price": 68, "quantity": 250, "ts": 1756428213.857892, "side": "sell"}
{"type": "orderbook_delta", "seq": 1883, "price": 60, "quantity": -250, "ts": 1756428213.859154, "side": "sell"}
{"type": "orderbook_delta", "seq": 1884, "price": 70, "quantity": 250, "ts": 1756428213.860087, "side": "sell"}
{"type": "orderbook_delta", "seq": 1885, "price": 47, "quantity": 200, "ts": 1756428213.865452, "side": "buy"}
{"type": "orderbook_delta", "seq": 1886, "price": 56, "quantity": 500, "ts": 1756428213.865833, "side": "sell"}
{"type": "orderbook_delta", "seq": 1887, "price": 57, "quantity": -200, "ts": 1756428213.866715, "side": "sell"}
{"type": "orderbook_delta", "seq": 1888, "price": 59, "quantity": 200, "ts": 1756428213.866715, "side": "sell"}
{"type": "orderbook_delta", "seq": 1889, "price": 50, "quantity": 500, "ts": 1756428213.866935, "side": "buy"}
{"type": "orderbook_delta", "seq": 1890, "price": 21, "quantity": 8000, "ts": 1756428213.873979, "side": "buy"}
{"type": "orderbook_delta", "seq": 1891, "price": 56, "quantity": -250, "ts": 1756428213.876795, "side": "sell"}
{"type": "orderbook_delta", "seq": 1892, "price": 59, "quantity": -100, "ts": 1756428213.886946, "side": "sell"}
{"type": "orderbook_delta", "seq": 1893, "price": 60, "quantity": 100, "ts": 1756428213.886946, "side": "sell"}
{"type": "orderbook_delta", "seq": 1894, "price": 59, "quantity": -200, "ts": 1756428213.892602, "side": "sell"}
{"type": "orderbook_delta", "seq": 1895, "price": 58, "quantity": -250, "ts": 1756428213.896808, "side": "sell"}
{"type": "orderbook_delta", "seq": 1896, "price": 70, "quantity": -250, "ts": 1756428213.90613, "side": "sell"}
{"type": "orderbook_delta", "seq": 1897, "price": 60, "quantity": 250, "ts": 1756428213.908194, "side": "sell"}
{"type": "orderbook_delta", "seq": 1898, "price": 48, "quantity": -250, "ts": 1756428213.9084, "side": "buy"}
{"type": "orderbook_delta", "seq": 1899, "price": 47, "quantity": -200, "ts": 1756428213.911333, "side": "buy"}
{"type": "orderbook_delta", "seq": 1900, "price": 59, "quantity": -200, "ts": 1756428213.921502, "side": "sell"}
{"type": "orderbook_delta", "seq": 1901, "price": 60, "quantity": 200, "ts": 1756428213.921502, "side": "sell"}
{"type": "orderbook_delta", "seq": 1902, "price": 59, "quantity": 200, "ts": 1756428213.92576, "side": "sell"}
{"type": "orderbook_delta", "seq": 1903, "price": 56, "quantity": -500, "ts": 1756428213.931258, "side": "sell"}
{"type": "orderbook_delta", "seq": 1904, "price": 56, "quantity": 167, "ts": 1756428213.939651, "side": "sell"}
{"type": "orderbook_delta", "seq": 1905, "price": 49, "quantity": -100, "ts": 1756428213.940122, "side": "buy"}
{"type": "orderbook_delta", "seq": 1906, "price": 51, "quantity": 100, "ts": 1756428213.940122, "side": "buy"}
{"type": "orderbook_delta", "seq": 1907, "price": 47, "quantity": 200, "ts": 1756428213.941113, "side": "buy"}
{"type": "orderbook_delta", "seq": 1908, "price": 59, "quantity": 500, "ts": 1756428213.964511, "side": "sell"}
{"type": "orderbook_delta", "seq": 1909, "price": 50, "quantity": -500, "ts": 1756428213.975001, "side": "buy"}
{"type": "orderbook_delta", "seq": 1910, "price": 59, "quantity": -500, "ts": 1756428213.993952, "side": "sell"}
{"type": "orderbook_delta", "seq": 1911, "price": 47, "quantity": 500, "ts": 1756428214.010801, "side": "buy"}
{"type": "orderbook_delta", "seq": 1912, "price": 56, "quantity": 500, "ts": 1756428214.019987, "side": "sell"}
{"type": "orderbook_delta", "seq": 1913, "price": 56, "quantity": -167, "ts": 1756428214.109251, "side": "sell"}
{"type": "orderbook_delta", "seq": 1914, "price": 48, "quantity": 250, "ts": 1756428214.10983, "side": "buy"}
{"type": "orderbook_delta", "seq": 1915, "price": 52, "quantity": 250, "ts": 1756428214.126012, "side": "buy"}
{"type": "orderbook_delta", "seq": 1916, "price": 56, "quantity": -500, "ts": 1756428214.144973, "side": "sell"}
{"type": "orderbook_delta", "seq": 1917, "price": 47, "quantity": -500, "ts": 1756428214.145135, "side": "buy"}
{"type": "orderbook_delta", "seq": 1918, "price": 40, "quantity": -250, "ts": 1756428214.14576, "side": "buy"}
{"type": "orderbook_delta", "seq": 1919, "price": 50, "quantity": 250, "ts": 1756428214.146473, "side": "buy"}
{"type": "orderbook_delta", "seq": 1920, "price": 47, "quantity": -200, "ts": 1756428214.147403, "side": "buy"}
{"type": "orderbook_delta", "seq": 1921, "price": 42, "quantity": -250, "ts": 1756428214.167396, "side": "buy"}
{"type": "orderbook_delta", "seq": 1922, "price": 51, "quantity": -100, "ts": 1756428214.1873, "side": "buy"}
{"type": "orderbook_delta", "seq": 1923, "price": 52, "quantity": 100, "ts": 1756428214.1873, "side": "buy"}
{"type": "orderbook_delta", "seq": 1924, "price": 59, "quantity": 500, "ts": 1756428214.189094, "side": "sell"}
{"type": "orderbook_delta", "seq": 1925, "price": 48, "quantity": 200, "ts": 1756428214.190171, "side": "buy"}
{"type": "orderbook_delta", "seq": 1926, "price": 50, "quantity": 500, "ts": 1756428214.190606, "side": "buy"}
{"type": "orderbook_delta", "seq": 1927, "price": 52, "quantity": -250, "ts": 1756428214.214665, "side": "buy"}
{"type": "orderbook_delta", "seq": 1928, "price": 57, "quantity": 167, "ts": 1756428214.226097, "side": "sell"}
{"type": "orderbook_delta", "seq": 1929, "price": 59, "quantity": -500, "ts": 1756428214.262143, "side": "sell"}
{"type": "orderbook_delta", "seq": 1930, "price": 52, "quantity": 250, "ts": 1756428214.280387, "side": "buy"}
{"type": "orderbook_delta", "seq": 1931, "price": 56, "quantity": 500, "ts": 1756428214.316055, "side": "sell"}
{"type": "orderbook_delta", "seq": 1932, "price": 52, "quantity": -100, "ts": 1756428214.31824, "side": "buy"}
{"type": "orderbook_delta", "seq": 1933, "price": 51, "quantity": 100, "ts": 1756428214.31824, "side": "buy"}
{"type": "orderbook_delta", "seq": 1934, "price": 60, "quantity": -100, "ts": 1756428214.380397, "side": "sell"}
{"type": "orderbook_delta", "seq": 1935, "price": 61, "quantity": 100, "ts": 1756428214.380397, "side": "sell"}
{"type": "orderbook_delta", "seq": 1936, "price": 51, "quantity": -100, "ts": 1756428215.061663, "side": "buy"}
{"type": "orderbook_delta", "seq": 1937, "price": 52, "quantity": 100, "ts": 1756428215.061663, "side": "buy"}
{"type": "orderbook_delta", "seq": 1938, "price": 57, "quantity": -167, "ts": 1756428215.129659, "side": "sell"}
{"type": "orderbook_delta", "seq": 1939, "price": 42, "quantity": 250, "ts": 1756428215.13882, "side": "buy"}
{"type": "orderbook_delta", "seq": 1940, "price": 52, "quantity": -250, "ts": 1756428215.147053, "side": "buy"}
{"type": "orderbook_delta", "seq": 1941, "price": 58, "quantity": 250, "ts": 1756428215.156788, "side": "sell"}
{"type": "orderbook_delta", "seq": 1942, "price": 68, "quantity": -250, "ts": 1756428215.167505, "side": "sell"}
{"type": "orderbook_delta", "seq": 1943, "price": 56, "quantity": -500, "ts": 1756428215.191173, "side": "sell"}
{"type": "orderbook_delta", "seq": 1944, "price": 56, "quantity": 167, "ts": 1756428215.211225, "side": "sell"}
{"type": "orderbook_delta", "seq": 1945, "price": 57, "quantity": 500, "ts": 1756428215.236355, "side": "sell"}
{"type": "orderbook_delta", "seq": 1946, "price": 57, "quantity": -500, "ts": 1756428215.283695, "side": "sell"}
{"type": "orderbook_delta", "seq": 1947, "price": 56, "quantity": 500, "ts": 1756428215.318187, "side": "sell"}
{"type": "orderbook_delta", "seq": 1948, "price": 61, "quantity": -100, "ts": 1756428215.888075, "side": "sell"}
{"type": "orderbook_delta", "seq": 1949, "price": 59, "quantity": 100, "ts": 1756428215.888075, "side": "sell"}
{"type": "orderbook_delta", "seq": 1950, "price": 46, "quantity": -1250, "ts": 1756428216.175033, "side": "buy"}
{"type": "orderbook_delta", "seq": 1951, "price": 59, "quantity": -200, "ts": 1756428216.177593, "side": "sell"}
{"type": "orderbook_delta", "seq": 1952, "price": 61, "quantity": -1250, "ts": 1756428216.177911, "side": "sell"}
{"type": "orderbook_delta", "seq": 1953, "price": 48, "quantity": -200, "ts": 1756428216.184591, "side": "buy"}
{"type": "orderbook_delta", "seq": 1954, "price": 58, "quantity": 200, "ts": 1756428216.269503, "side": "sell"}
{"type": "orderbook_delta", "seq": 1955, "price": 45, "quantity": 1250, "ts": 1756428216.269822, "side": "buy"}
{"type": "orderbook_delta", "seq": 1956, "price": 47, "quantity": 200, "ts": 1756428216.272227, "side": "buy"}
{"type": "orderbook_delta", "seq": 1957, "price": 60, "quantity": 1250, "ts": 1756428216.274734, "side": "sell"}
{"type": "orderbook_delta", "seq": 1958, "price": 37, "quantity": 50, "ts": 1756428216.398878, "side": "buy"}
{"type": "orderbook_delta", "seq": 1959, "price": 52, "quantity": -100, "ts": 1756428217.376728, "side": "buy"}
{"type": "orderbook_delta", "seq": 1960, "price": 51, "quantity": 100, "ts": 1756428217.376728, "side": "buy"}
{"type": "orderbook_delta", "seq": 1961, "price": 59, "quantity": -100, "ts": 1756428218.185252, "side": "sell"}
{"type": "orderbook_delta", "seq": 1962, "price": 60, "quantity": 100, "ts": 1756428218.185252, "side": "sell"}
{"type": "orderbook_delta", "seq": 1963, "price": 47, "quantity": -200, "ts": 1756428218.230496, "side": "buy"}
{"type": "orderbook_delta", "seq": 1964, "price": 58, "quantity": -200, "ts": 1756428218.231439, "side": "sell"}
{"type": "orderbook_delta", "seq": 1965, "price": 50, "quantity": -500, "ts": 1756428218.235211, "side": "buy"}
{"type": "orderbook_delta", "seq": 1966, "price": 45, "quantity": -1250, "ts": 1756428218.247123, "side": "buy"}
{"type": "orderbook_delta", "seq": 1967, "price": 60, "quantity": -1250, "ts": 1756428218.251958, "side": "sell"}
{"type": "orderbook_delta", "seq": 1968, "price": 59, "quantity": 200, "ts": 1756428218.32449, "side": "sell"}
{"type": "orderbook_delta", "seq": 1969, "price": 46, "quantity": 1250, "ts": 1756428218.326763, "side": "buy"}
{"type": "orderbook_delta", "seq": 1970, "price": 48, "quantity": 200, "ts": 1756428218.32706, "side": "buy"}
{"type": "orderbook_delta", "seq": 1971, "price": 51, "quantity": 500, "ts": 1756428218.344863, "side": "buy"}
{"type": "orderbook_delta", "seq": 1972, "price": 51, "quantity": -100, "ts": 1756428218.399102, "side": "buy"}
{"type": "orderbook_delta", "seq": 1973, "price": 52, "quantity": 100, "ts": 1756428218.399102, "side": "buy"}
{"type": "orderbook_delta", "seq": 1974, "price": 61, "quantity": 1250, "ts": 1756428218.418714, "side": "sell"}
{"type": "orderbook_delta", "seq": 1975, "price": 43, "quantity": -100, "ts": 1756428218.468461, "side": "buy"}
{"type": "orderbook_delta", "seq": 1976, "price": 52, "quantity": 100, "ts": 1756428218.668549, "side": "buy"}
{"type": "orderbook_delta", "seq": 1977, "price": 55, "quantity": 100, "ts": 1756428219.612299, "side": "sell"}
{"type": "orderbook_delta", "seq": 1978, "price": 60, "quantity": -100, "ts": 1756428220.093881, "side": "sell"}
{"type": "orderbook_delta", "seq": 1979, "price": 61, "quantity": 100, "ts": 1756428220.093881, "side": "sell"}
{"type": "orderbook_delta", "seq": 1980, "price": 51, "quantity": -500, "ts": 1756428220.137273, "side": "buy"}
{"type": "orderbook_delta", "seq": 1981, "price": 50, "quantity": 500, "ts": 1756428220.178975, "side": "buy"}
{"type": "orderbook_delta", "seq": 1982, "price": 52, "quantity": -100, "ts": 1756428220.324147, "side": "buy"}
{"type": "orderbook_delta", "seq": 1983, "price": 51, "quantity": 100, "ts": 1756428220.324147, "side": "buy"}
{"type": "orderbook_delta", "seq": 1984, "price": 56, "quantity": -167, "ts": 1756428221.118604, "side": "sell"}
{"type": "orderbook_delta", "seq": 1985, "price": 68, "quantity": 250, "ts": 1756428221.12018, "side": "sell"}
{"type": "orderbook_delta", "seq": 1986, "price": 58, "quantity": -250, "ts": 1756428221.13688, "side": "sell"}
{"type": "orderbook_delta", "seq": 1987, "price": 56, "quantity": -500, "ts": 1756428221.150709, "side": "sell"}
{"type": "orderbook_delta", "seq": 1988, "price": 57, "quantity": 167, "ts": 1756428221.252217, "side": "sell"}
{"type": "orderbook_delta", "seq": 1989, "price": 59, "quantity": 500, "ts": 1756428221.252896, "side": "sell"}
{"type": "orderbook_delta", "seq": 1990, "price": 59, "quantity": -500, "ts": 1756428221.295995, "side": "sell"}
{"type": "orderbook_delta", "seq": 1991, "price": 56, "quantity": 500, "ts": 1756428221.343079, "side": "sell"}
{"type": "orderbook_delta", "seq": 1992, "price": 52, "quantity": 0, "ts": 1756428222.156271, "side": "buy"}
{"type": "orderbook_delta", "seq": 1993, "price": 75, "quantity": 100, "ts": 1756428222.202309, "side": "sell"}
{"type": "trade", "seq": 24, "price": 52, "quantity": 10, "ts": 1756428222.823435, "side": "sell"}
{"type": "orderbook_delta", "seq": 1994, "price": 61, "quantity": -100, "ts": 1756428222.823435, "side": "sell"}
{"type": "orderbook_delta", "seq": 1995, "price": 62, "quantity": 100, "ts": 1756428222.823435, "side": "sell"}
{"type": "orderbook_delta", "seq": 1996, "price": 56, "quantity": -500, "ts": 1756428222.872268, "side": "sell"}
{"type": "orderbook_delta", "seq": 1997, "price": 50, "quantity": -500, "ts": 1756428222.877627, "side": "buy"}
{"type": "orderbook_delta", "seq": 1998, "price": 57, "quantity": 500, "ts": 1756428222.927189, "side": "sell"}
{"type": "orderbook_delta", "seq": 1999, "price": 51, "quantity": 500, "ts": 1756428222.978759, "side": "buy"}
{"type": "orderbook_delta", "seq": 2000, "price": 51, "quantity": -100, "ts": 1756428223.027056, "side": "buy"}
{"type": "orderbook_delta", "seq": 2001, "price": 52, "quantity": 100, "ts": 1756428223.027056, "side": "buy"}
{"type": "orderbook_delta", "seq": 2002, "price": 57, "quantity": -167, "ts": 1756428223.115674, "side": "sell"}
{"type": "orderbook_delta", "seq": 2003, "price": 52, "quantity": 250, "ts": 1756428223.117352, "side": "buy"}
{"type": "orderbook_delta", "seq": 2004, "price": 57, "quantity": -500, "ts": 1756428223.14043, "side": "sell"}
{"type": "orderbook_delta", "seq": 2005, "price": 42, "quantity": -250, "ts": 1756428223.147354, "side": "buy"}
{"type": "orderbook_delta", "seq": 2006, "price": 70, "quantity": 250, "ts": 1756428223.18517, "side": "sell"}
{"type": "orderbook_delta", "seq": 2007, "price": 59, "quantity": 500, "ts": 1756428223.225891, "side": "sell"}
{"type": "orderbook_delta", "seq": 2008, "price": 52, "quantity": -100, "ts": 1756428223.300596, "side": "buy"}
{"type": "orderbook_delta", "seq": 2009, "price": 53, "quantity": 100, "ts": 1756428223.300596, "side": "buy"}
{"type": "orderbook_delta", "seq": 2010, "price": 60, "quantity": -250, "ts": 1756428223.302148, "side": "sell"}
{"type": "orderbook_delta", "seq": 2011, "price": 59, "quantity": 167, "ts": 1756428223.391361, "side": "sell"}
{"type": "orderbook_delta", "seq": 2012, "price": 59, "quantity": -500, "ts": 1756428223.448177, "side": "sell"}
{"type": "orderbook_delta", "seq": 2013, "price": 58, "quantity": 500, "ts": 1756428223.646274, "side": "sell"}
{"type": "orderbook_delta", "seq": 2014, "price": 59, "quantity": -167, "ts": 1756428224.146113, "side": "sell"}
{"type": "orderbook_delta", "seq": 2015, "price": 60, "quantity": 250, "ts": 1756428224.161731, "side": "sell"}
{"type": "orderbook_delta", "seq": 2016, "price": 58, "quantity": -500, "ts": 1756428224.215948, "side": "sell"}
{"type": "orderbook_delta", "seq": 2017, "price": 59, "quantity": 500, "ts": 1756428224.29051, "side": "sell"}
{"type": "orderbook_delta", "seq": 2018, "price": 70, "quantity": -250, "ts": 1756428224.346215, "side": "sell"}
{"type": "orderbook_delta", "seq": 2019, "price": 58, "quantity": 167, "ts": 1756428224.421184, "side": "sell"}
{"type": "orderbook_delta", "seq": 2020, "price": 59, "quantity": -500, "ts": 1756428224.496308, "side": "sell"}
{"type": "orderbook_delta", "seq": 2021, "price": 57, "quantity": 500, "ts": 1756428224.598727, "side": "sell"}
{"type": "orderbook_delta", "seq": 2022, "price": 53, "quantity": 0, "ts": 1756428224.621932, "side": "buy"}
{"type": "trade", "seq": 25, "price": 53, "quantity": 10, "ts": 1756428225.083184, "side": "sell"}
{"type": "orderbook_delta", "seq": 2023, "price": 46, "quantity": -1250, "ts": 1756428225.083184, "side": "buy"}
{"type": "orderbook_delta", "seq": 2024, "price": 59, "quantity": -200, "ts": 1756428225.083435, "side": "sell"}
{"type": "orderbook_delta", "seq": 2025, "price": 61, "quantity": -1250, "ts": 1756428225.085521, "side": "sell"}
{"type": "orderbook_delta", "seq": 2026, "price": 48, "quantity": -200, "ts": 1756428225.085966, "side": "buy"}
{"type": "orderbook_delta", "seq": 2027, "price": 49, "quantity": 200, "ts": 1756428225.130639, "side": "buy"}
{"type": "orderbook_delta", "seq": 2028, "price": 60, "quantity": 200, "ts": 1756428225.131237, "side": "sell"}
{"type": "orderbook_delta", "seq": 2029, "price": 47, "quantity": 1250, "ts": 1756428225.131958, "side": "buy"}
{"type": "orderbook_delta", "seq": 2030, "price": 60, "quantity": -200, "ts": 1756428225.136589, "side": "sell"}
{"type": "orderbook_delta", "seq": 2031, "price": 62, "quantity": 200, "ts": 1756428225.136589, "side": "sell"}
{"type": "orderbook_delta", "seq": 2032, "price": 62, "quantity": 1250, "ts": 1756428225.137554, "side": "sell"}
{"type": "orderbook_delta", "seq": 2033, "price": 62, "quantity": -200, "ts": 1756428225.189596, "side": "sell"}
{"type": "orderbook_delta", "seq": 2034, "price": 63, "quantity": 200, "ts": 1756428225.189596, "side": "sell"}
{"type": "orderbook_delta", "seq": 2035, "price": 58, "quantity": -167, "ts": 1756428225.211975, "side": "sell"}
{"type": "orderbook_delta", "seq": 2036, "price": 70, "quantity": 250, "ts": 1756428225.215391, "side": "sell"}
{"type": "orderbook_delta", "seq": 2037, "price": 62, "quantity": -1250, "ts": 1756428225.217006, "side": "sell"}
{"type": "orderbook_delta", "seq": 2038, "price": 60, "quantity": -200, "ts": 1756428225.218503, "side": "sell"}
{"type": "orderbook_delta", "seq": 2039, "price": 47, "quantity": -1250, "ts": 1756428225.218833, "side": "buy"}
{"type": "orderbook_delta", "seq": 2040, "price": 57, "quantity": -500, "ts": 1756428225.218881, "side": "sell"}
{"type": "orderbook_delta", "seq": 2041, "price": 49, "quantity": -200, "ts": 1756428225.219185, "side": "buy"}
{"type": "orderbook_delta", "seq": 2042, "price": 51, "quantity": -500, "ts": 1756428225.22172, "side": "buy"}
{"type": "orderbook_delta", "seq": 2043, "price": 60, "quantity": -250, "ts": 1756428225.226687, "side": "sell"}
{"type": "orderbook_delta", "seq": 2044, "price": 61, "quantity": 500, "ts": 1756428225.261654, "side": "sell"}
{"type": "orderbook_delta", "seq": 2045, "price": 50, "quantity": 200, "ts": 1756428225.262244, "side": "buy"}
{"type": "orderbook_delta", "seq": 2046, "price": 61, "quantity": 200, "ts": 1756428225.262944, "side": "sell"}
{"type": "orderbook_delta", "seq": 2047, "price": 53, "quantity": 500, "ts": 1756428225.263505, "side": "buy"}
{"type": "orderbook_delta", "seq": 2048, "price": 48, "quantity": 1250, "ts": 1756428225.263743, "side": "buy"}
{"type": "orderbook_delta", "seq": 2049, "price": 63, "quantity": 1250, "ts": 1756428225.26933, "side": "sell"}
{"type": "orderbook_delta", "seq": 2050, "price": 59, "quantity": 167, "ts": 1756428225.276448, "side": "sell"}
{"type": "orderbook_delta", "seq": 2051, "price": 61, "quantity": -500, "ts": 1756428225.309388, "side": "sell"}
{"type": "orderbook_delta", "seq": 2052, "price": 53, "quantity": -90, "ts": 1756428225.332897, "side": "buy"}
{"type": "orderbook_delta", "seq": 2053, "price": 54, "quantity": 90, "ts": 1756428225.332897, "side": "buy"}
{"type": "orderbook_delta", "seq": 2054, "price": 59, "quantity": 500, "ts": 1756428225.355121, "side": "sell"}
{"type": "orderbook_delta", "seq": 2055, "price": 63, "quantity": -1250, "ts": 1756428226.109503, "side": "sell"}
{"type": "orderbook_delta", "seq": 2056, "price": 48, "quantity": -1250, "ts": 1756428226.110888, "side": "buy"}
{"type": "orderbook_delta", "seq": 2057, "price": 50, "quantity": -200, "ts": 1756428226.113019, "side": "buy"}
{"type": "orderbook_delta", "seq": 2058, "price": 54, "quantity": 250, "ts": 1756428226.121083, "side": "buy"}
{"type": "orderbook_delta", "seq": 2059, "price": 61, "quantity": -200, "ts": 1756428226.137689, "side": "sell"}
{"type": "orderbook_delta", "seq": 2060, "price": 51, "quantity": 200, "ts": 1756428226.188725, "side": "buy"}
{"type": "orderbook_delta", "seq": 2061, "price": 49, "quantity": 1250, "ts": 1756428226.189073, "side": "buy"}
{"type": "orderbook_delta", "seq": 2062, "price": 62, "quantity": 200, "ts": 1756428226.190119, "side": "sell"}
{"type": "orderbook_delta", "seq": 2063, "price": 64, "quantity": 1250, "ts": 1756428226.1971, "side": "sell"}
{"type": "orderbook_delta", "seq": 2064, "price": 44, "quantity": -250, "ts": 1756428226.267346, "side": "buy"}
{"type": "trade", "seq": 26, "price": 55, "quantity": 3, "ts": 1756428226.921888, "side": "buy"}
{"type": "orderbook_delta", "seq": 2065, "price": 55, "quantity": 0, "ts": 1756428226.921888, "side": "sell"}
{"type": "orderbook_delta", "seq": 2066, "price": 55, "quantity": -97, "ts": 1756428227.209167, "side": "sell"}
{"type": "orderbook_delta", "seq": 2067, "price": 54, "quantity": -90, "ts": 1756428227.257852, "side": "buy"}
{"type": "orderbook_delta", "seq": 2068, "price": 55, "quantity": 90, "ts": 1756428227.257852, "side": "buy"}
{"type": "orderbook_delta", "seq": 2069, "price": 52, "quantity": -90, "ts": 1756428227.600859, "side": "buy"}
{"type": "orderbook_delta", "seq": 2070, "price": 59, "quantity": -167, "ts": 1756428228.108791, "side": "sell"}
{"type": "orderbook_delta", "seq": 2071, "price": 59, "quantity": -500, "ts": 1756428228.124845, "side": "sell"}
{"type": "orderbook_delta", "seq": 2072, "price": 44, "quantity": 250, "ts": 1756428228.126226, "side": "buy"}
{"type": "orderbook_delta", "seq": 2073, "price": 53, "quantity": -500, "ts": 1756428228.127419, "side": "buy"}
{"type": "orderbook_delta", "seq": 2074, "price": 54, "quantity": -250, "ts": 1756428228.147469, "side": "buy"}
{"type": "orderbook_delta", "seq": 2075, "price": 60, "quantity": 250, "ts": 1756428228.166775, "side": "sell"}
{"type": "orderbook_delta", "seq": 2076, "price": 54, "quantity": 500, "ts": 1756428228.173964, "side": "buy"}
{"type": "orderbook_delta", "seq": 2077, "price": 61, "quantity": 500, "ts": 1756428228.177421, "side": "sell"}
{"type": "orderbook_delta", "seq": 2078, "price": 55, "quantity": -90, "ts": 1756428228.201537, "side": "buy"}
{"type": "orderbook_delta", "seq": 2079, "price": 53, "quantity": 90, "ts": 1756428228.201537, "side": "buy"}
{"type": "orderbook_delta", "seq": 2080, "price": 54, "quantity": -500, "ts": 1756428228.206462, "side": "buy"}
{"type": "orderbook_delta", "seq": 2081, "price": 52, "quantity": -250, "ts": 1756428228.207563, "side": "buy"}
{"type": "orderbook_delta", "seq": 2082, "price": 42, "quantity": 250, "ts": 1756428228.207723, "side": "buy"}
{"type": "orderbook_delta", "seq": 2083, "price": 61, "quantity": -500, "ts": 1756428228.217394, "side": "sell"}
{"type": "orderbook_delta", "seq": 2084, "price": 54, "quantity": 500, "ts": 1756428228.247268, "side": "buy"}
{"type": "orderbook_delta", "seq": 2085, "price": 42, "quantity": -250, "ts": 1756428228.250681, "side": "buy"}
{"type": "orderbook_delta", "seq": 2086, "price": 60, "quantity": 500, "ts": 1756428228.263431, "side": "sell"}
{"type": "orderbook_delta", "seq": 2087, "price": 52, "quantity": 250, "ts": 1756428228.289437, "side": "buy"}
{"type": "orderbook_delta", "seq": 2088, "price": 70, "quantity": -250, "ts": 1756428228.306592, "side": "sell"}
{"type": "orderbook_delta", "seq": 2089, "price": 58, "quantity": 167, "ts": 1756428228.349461, "side": "sell"}
{"type": "orderbook_delta", "seq": 2090, "price": 53, "quantity": -90, "ts": 1756428228.959419, "side": "buy"}
{"type": "orderbook_delta", "seq": 2091, "price": 55, "quantity": 90, "ts": 1756428228.959419, "side": "buy"}
{"type": "orderbook_delta", "seq": 2092, "price": 54, "quantity": -500, "ts": 1756428228.995138, "side": "buy"}
{"type": "orderbook_delta", "seq": 2093, "price": 53, "quantity": 500, "ts": 1756428229.09787, "side": "buy"}
{"type": "orderbook_delta", "seq": 2094, "price": 42, "quantity": 250, "ts": 1756428229.157679, "side": "buy"}
{"type": "orderbook_delta", "seq": 2095, "price": 52, "quantity": -250, "ts": 1756428229.157921, "side": "buy"}
{"type": "orderbook_delta", "seq": 2096, "price": 53, "quantity": -500, "ts": 1756428229.19698, "side": "buy"}
{"type": "orderbook_delta", "seq": 2097, "price": 51, "quantity": 500, "ts": 1756428229.24177, "side": "buy"}
{"type": "orderbook_delta", "seq": 2098, "price": 42, "quantity": -250, "ts": 1756428229.97942, "side": "buy"}
{"type": "orderbook_delta", "seq": 2099, "price": 52, "quantity": 250, "ts": 1756428229.980679, "side": "buy"}
{"type": "orderbook_delta", "seq": 2100, "price": 51, "quantity": -500, "ts": 1756428230.010473, "side": "buy"}
{"type": "orderbook_delta", "seq": 2101, "price": 53, "quantity": 500, "ts": 1756428230.057949, "side": "buy"}
{"type": "orderbook_delta", "seq": 2102, "price": 60, "quantity": -500, "ts": 1756428230.193483, "side": "sell"}
{"type": "orderbook_delta", "seq": 2103, "price": 59, "quantity": 500, "ts": 1756428230.23124, "side": "sell"}
{"type": "orderbook_delta", "seq": 2104, "price": 54, "quantity": 250, "ts": 1756428231.10741, "side": "buy"}
{"type": "orderbook_delta", "seq": 2105, "price": 58, "quantity": -167, "ts": 1756428231.109172, "side": "sell"}
{"type": "orderbook_delta", "seq": 2106, "price": 62, "quantity": -100, "ts": 1756428231.128575, "side": "sell"}
{"type": "orderbook_delta", "seq": 2107, "price": 63, "quantity": 100, "ts": 1756428231.128575, "side": "sell"}
{"type": "orderbook_delta", "seq": 2108, "price": 70, "quantity": 250, "ts": 1756428231.137177, "side": "sell"}
{"type": "orderbook_delta", "seq": 2109, "price": 44, "quantity": -250, "ts": 1756428231.155707, "side": "buy"}
{"type": "orderbook_delta", "seq": 2110, "price": 60, "quantity": -250, "ts": 1756428231.166427, "side": "sell"}
{"type": "orderbook_delta", "seq": 2111, "price": 59, "quantity": -500, "ts": 1756428231.2224, "side": "sell"}
{"type": "orderbook_delta", "seq": 2112, "price": 60, "quantity": 167, "ts": 1756428231.234607, "side": "sell"}
{"type": "orderbook_delta", "seq": 2113, "price": 59, "quantity": 500, "ts": 1756428231.26082, "side": "sell"}
{"type": "orderbook_delta", "seq": 2114, "price": 55, "quantity": 100, "ts": 1756428231.696282, "side": "buy"}
{"type": "trade", "seq": 27, "price": 55, "quantity": 21, "ts": 1756428231.70743, "side": "sell"}
{"type": "orderbook_delta", "seq": 2115, "price": 55, "quantity": 0, "ts": 1756428231.70743, "side": "buy"}
{"type": "orderbook_delta", "seq": 2116, "price": 59, "quantity": -500, "ts": 1756428232.119398, "side": "sell"}
{"type": "orderbook_delta", "seq": 2117, "price": 53, "quantity": -500, "ts": 1756428232.127457, "side": "buy"}
{"type": "orderbook_delta", "seq": 2118, "price": 60, "quantity": -167, "ts": 1756428232.130027, "side": "sell"}
{"type": "orderbook_delta", "seq": 2119, "price": 44, "quantity": 250, "ts": 1756428232.168618, "side": "buy"}
{"type": "orderbook_delta", "seq": 2120, "price": 54, "quantity": -250, "ts": 1756428232.170573, "side": "buy"}
{"type": "orderbook_delta", "seq": 2121, "price": 59, "quantity": 167, "ts": 1756428232.170637, "side": "sell"}
{"type": "orderbook_delta", "seq": 2122, "price": 61, "quantity": 500, "ts": 1756428232.170917, "side": "sell"}
{"type": "orderbook_delta", "seq": 2123, "price": 54, "quantity": 500, "ts": 1756428232.17215, "side": "buy"}
{"type": "orderbook_delta", "seq": 2124, "price": 54, "quantity": -500, "ts": 1756428232.205213, "side": "buy"}
{"type": "orderbook_delta", "seq": 2125, "price": 44, "quantity": -250, "ts": 1756428232.216555, "side": "buy"}
{"type": "orderbook_delta", "seq": 2126, "price": 53, "quantity": 500, "ts": 1756428232.239278, "side": "buy"}
{"type": "orderbook_delta", "seq": 2127, "price": 1, "quantity": 19440, "ts": 1756428232.272738, "side": "buy"}
{"type": "orderbook_delta", "seq": 2128, "price": 55, "quantity": -69, "ts": 1756428232.278533, "side": "buy"}
{"type": "orderbook_delta", "seq": 2129, "price": 53, "quantity": 69, "ts": 1756428232.278533, "side": "buy"}
{"type": "orderbook_delta", "seq": 2130, "price": 53, "quantity": -500, "ts": 1756428232.315495, "side": "buy"}
{"type": "orderbook_delta", "seq": 2131, "price": 54, "quantity": 500, "ts": 1756428232.356651, "side": "buy"}
{"type": "orderbook_delta", "seq": 2132, "price": 2, "quantity": 7000, "ts": 1756428232.732821, "side": "buy"}
{"type": "orderbook_delta", "seq": 2133, "price": 53, "quantity": -69, "ts": 1756428233.021252, "side": "buy"}
{"type": "orderbook_delta", "seq": 2134, "price": 55, "quantity": 69, "ts": 1756428233.021252, "side": "buy"}
{"type": "orderbook_delta", "seq": 2135, "price": 54, "quantity": -500, "ts": 1756428233.058176, "side": "buy"}
{"type": "orderbook_delta", "seq": 2136, "price": 53, "quantity": 500, "ts": 1756428233.101021, "side": "buy"}
{"type": "orderbook_delta", "seq": 2137, "price": 44, "quantity": 250, "ts": 1756428233.125703, "side": "buy"}
{"type": "orderbook_delta", "seq": 2138, "price": 59, "quantity": -167, "ts": 1756428233.850442, "side": "sell"}
{"type": "orderbook_delta", "seq": 2139, "price": 54, "quantity": 250, "ts": 1756428233.851732, "side": "buy"}
{"type": "orderbook_delta", "seq": 2140, "price": 49, "quantity": -1250, "ts": 1756428233.859989, "side": "buy"}
{"type": "orderbook_delta", "seq": 2141, "price": 20, "quantity": -200, "ts": 1756428233.869335, "side": "buy"}
{"type": "orderbook_delta", "seq": 2142, "price": 30, "quantity": 200, "ts": 1756428233.869335, "side": "buy"}
{"type": "orderbook_delta", "seq": 2143, "price": 44, "quantity": -250, "ts": 1756428233.876857, "side": "buy"}
{"type": "orderbook_delta", "seq": 2144, "price": 53, "quantity": -500, "ts": 1756428233.895479, "side": "buy"}
{"type": "orderbook_delta", "seq": 2145, "price": 50, "quantity": 1250, "ts": 1756428233.897193, "side": "buy"}
{"type": "orderbook_delta", "seq": 2146, "price": 80, "quantity": -200, "ts": 1756428233.902838, "side": "sell"}
{"type": "orderbook_delta", "seq": 2147, "price": 90, "quantity": 200, "ts": 1756428233.902838, "side": "sell"}
{"type": "orderbook_delta", "seq": 2148, "price": 63, "quantity": -200, "ts": 1756428233.905579, "side": "sell"}
{"type": "orderbook_delta", "seq": 2149, "price": 64, "quantity": 200, "ts": 1756428233.905579, "side": "sell"}
{"type": "orderbook_delta", "seq": 2150, "price": 21, "quantity": -8000, "ts": 1756428233.920609, "side": "buy"}
{"type": "orderbook_delta", "seq": 2151, "price": 60, "quantity": 167, "ts": 1756428233.921745, "side": "sell"}
{"type": "orderbook_delta", "seq": 2152, "price": 98, "quantity": -8000, "ts": 1756428233.929404, "side": "sell"}
{"type": "orderbook_delta", "seq": 2153, "price": 54, "quantity": 500, "ts": 1756428233.934622, "side": "buy"}
{"type": "orderbook_delta", "seq": 2154, "price": 63, "quantity": -100, "ts": 1756428233.941206, "side": "sell"}
{"type": "orderbook_delta", "seq": 2155, "price": 64, "quantity": 100, "ts": 1756428233.941206, "side": "sell"}
{"type": "orderbook_delta", "seq": 2156, "price": 2, "quantity": 8000, "ts": 1756428233.963417, "side": "buy"}
{"type": "orderbook_delta", "seq": 2157, "price": 61, "quantity": -500, "ts": 1756428233.978941, "side": "sell"}
{"type": "orderbook_delta", "seq": 2158, "price": 54, "quantity": -250, "ts": 1756428233.981562, "side": "buy"}
{"type": "orderbook_delta", "seq": 2159, "price": 44, "quantity": 250, "ts": 1756428233.982207, "side": "buy"}
{"type": "orderbook_delta", "seq": 2160, "price": 89, "quantity": 8000, "ts": 1756428233.985507, "side": "sell"}
{"type": "orderbook_delta", "seq": 2161, "price": 44, "quantity": -250, "ts": 1756428234.019537, "side": "buy"}
{"type": "orderbook_delta", "seq": 2162, "price": 54, "quantity": -500, "ts": 1756428234.019718, "side": "buy"}
{"type": "orderbook_delta", "seq": 2163, "price": 60, "quantity": 500, "ts": 1756428234.030875, "side": "sell"}
{"type": "orderbook_delta", "seq": 2164, "price": 53, "quantity": 500, "ts": 1756428234.088006, "side": "buy"}
{"type": "orderbook_delta", "seq": 2165, "price": 50, "quantity": -1250, "ts": 1756428234.089632, "side": "buy"}
{"type": "orderbook_delta", "seq": 2166, "price": 49, "quantity": 1250, "ts": 1756428234.126663, "side": "buy"}
{"type": "orderbook_delta", "seq": 2167, "price": 62, "quantity": -250, "ts": 1756428234.129718, "side": "sell"}
{"type": "orderbook_delta", "seq": 2168, "price": 72, "quantity": 250, "ts": 1756428234.130269, "side": "sell"}
{"type": "orderbook_delta", "seq": 2169, "price": 64, "quantity": -100, "ts": 1756428234.165406, "side": "sell"}
{"type": "orderbook_delta", "seq": 2170, "price": 65, "quantity": 100, "ts": 1756428234.165406, "side": "sell"}
{"type": "orderbook_delta", "seq": 2171, "price": 62, "quantity": -200, "ts": 1756428234.17237, "side": "sell"}
{"type": "orderbook_delta", "seq": 2172, "price": 60, "quantity": -500, "ts": 1756428234.184193, "side": "sell"}
{"type": "orderbook_delta", "seq": 2173, "price": 49, "quantity": -1250, "ts": 1756428234.186804, "side": "buy"}
{"type": "orderbook_delta", "seq": 2174, "price": 64, "quantity": -1250, "ts": 1756428234.188739, "side": "sell"}
{"type": "orderbook_delta", "seq": 2175, "price": 51, "quantity": -200, "ts": 1756428234.189042, "side": "buy"}
{"type": "orderbook_delta", "seq": 2176, "price": 53, "quantity": -500, "ts": 1756428234.192155, "side": "buy"}
{"type": "orderbook_delta", "seq": 2177, "price": 64, "quantity": 200, "ts": 1756428234.205979, "side": "sell"}
{"type": "orderbook_delta", "seq": 2178, "price": 51, "quantity": 1250, "ts": 1756428234.236851, "side": "buy"}
{"type": "orderbook_delta", "seq": 2179, "price": 53, "quantity": 200, "ts": 1756428234.237363, "side": "buy"}
{"type": "orderbook_delta", "seq": 2180, "price": 56, "quantity": 500, "ts": 1756428234.237599, "side": "buy"}
{"type": "orderbook_delta", "seq": 2181, "price": 66, "quantity": 1250, "ts": 1756428234.246169, "side": "sell"}
{"type": "orderbook_delta", "seq": 2182, "price": 64, "quantity": -200, "ts": 1756428234.264666, "side": "sell"}
{"type": "orderbook_delta", "seq": 2183, "price": 66, "quantity": 200, "ts": 1756428234.264666, "side": "sell"}
{"type": "orderbook_delta", "seq": 2184, "price": 63, "quantity": 500, "ts": 1756428234.267296, "side": "sell"}
{"type": "orderbook_delta", "seq": 2185, "price": 46, "quantity": -250, "ts": 1756428234.282296, "side": "buy"}
{"type": "orderbook_delta", "seq": 2186, "price": 56, "quantity": 250, "ts": 1756428234.282316, "side": "buy"}
{"type": "orderbook_delta", "seq": 2187, "price": 55, "quantity": -69, "ts": 1756428234.295549, "side": "buy"}
{"type": "orderbook_delta", "seq": 2188, "price": 56, "quantity": 69, "ts": 1756428234.295549, "side": "buy"}
{"type": "orderbook_delta", "seq": 2189, "price": 54, "quantity": 250, "ts": 1756428234.296828, "side": "buy"}
{"type": "orderbook_delta", "seq": 2190, "price": 58, "quantity": 100, "ts": 1756428234.592433, "side": "sell"}
{"type": "orderbook_delta", "seq": 2191, "price": 56, "quantity": -69, "ts": 1756428234.935802, "side": "buy"}
{"type": "orderbook_delta", "seq": 2192, "price": 57, "quantity": 69, "ts": 1756428234.935802, "side": "buy"}
{"type": "orderbook_delta", "seq": 2193, "price": 66, "quantity": -1250, "ts": 1756428234.937929, "side": "sell"}
{"type": "orderbook_delta", "seq": 2194, "price": 53, "quantity": -200, "ts": 1756428234.938255, "side": "buy"}
{"type": "orderbook_delta", "seq": 2195, "price": 51, "quantity": -1250, "ts": 1756428234.939227, "side": "buy"}
{"type": "orderbook_delta", "seq": 2196, "price": 64, "quantity": -200, "ts": 1756428234.942252, "side": "sell"}
{"type": "orderbook_delta", "seq": 2197, "price": 89, "quantity": -8000, "ts": 1756428234.942316, "side": "sell"}
{"type": "orderbook_delta", "seq": 2198, "price": 60, "quantity": -167, "ts": 1756428234.956939, "side": "sell"}
{"type": "orderbook_delta", "seq": 2199, "price": 90, "quantity": 8000, "ts": 1756428234.992886, "side": "sell"}
{"type": "orderbook_delta", "seq": 2200, "price": 65, "quantity": 200, "ts": 1756428234.993483, "side": "sell"}
{"type": "orderbook_delta", "seq": 2201, "price": 54, "quantity": 200, "ts": 1756428234.993871, "side": "buy"}
{"type": "orderbook_delta", "seq": 2202, "price": 52, "quantity": 1250, "ts": 1756428235.001987, "side": "buy"}
{"type": "orderbook_delta", "seq": 2203, "price": 67, "quantity": 1250, "ts": 1756428235.005747, "side": "sell"}
{"type": "orderbook_delta", "seq": 2204, "price": 62, "quantity": 167, "ts": 1756428235.029484, "side": "sell"}
{"type": "orderbook_delta", "seq": 2205, "price": 74, "quantity": 250, "ts": 1756428235.149816, "side": "sell"}
{"type": "orderbook_delta", "seq": 2206, "price": 63, "quantity": -500, "ts": 1756428235.188461, "side": "sell"}
{"type": "orderbook_delta", "seq": 2207, "price": 64, "quantity": -250, "ts": 1756428235.226962, "side": "sell"}
{"type": "orderbook_delta", "seq": 2208, "price": 62, "quantity": 500, "ts": 1756428235.241758, "side": "sell"}
{"type": "orderbook_delta", "seq": 2209, "price": 55, "quantity": -100, "ts": 1756428235.502566, "side": "buy"}
{"type": "orderbook_delta", "seq": 2210, "price": 1, "quantity": -19440, "ts": 1756428235.603188, "side": "buy"}
{"type": "orderbook_delta", "seq": 2211, "price": 11, "quantity": 10, "ts": 1756428235.637421, "side": "buy"}
{"type": "orderbook_delta", "seq": 2212, "price": 2, "quantity": -8000, "ts": 1756428235.640837, "side": "buy"}
{"type": "orderbook_delta", "seq": 2213, "price": 2, "quantity": -7000, "ts": 1756428235.641464, "side": "buy"}
{"type": "orderbook_delta", "seq": 2214, "price": 12, "quantity": 8000, "ts": 1756428235.687807, "side": "buy"}
{"type": "orderbook_delta", "seq": 2215, "price": 56, "quantity": 100, "ts": 1756428235.756318, "side": "buy"}
{"type": "trade", "seq": 28, "price": 57, "quantity": 30, "ts": 1756428235.925081, "side": "sell"}
{"type": "orderbook_delta", "seq": 2216, "price": 57, "quantity": 0, "ts": 1756428235.925081, "side": "buy"}
{"type": "orderbook_delta", "seq": 2217, "price": 56, "quantity": -500, "ts": 1756428236.382893, "side": "buy"}
{"type": "orderbook_delta", "seq": 2218, "price": 62, "quantity": -500, "ts": 1756428236.395188, "side": "sell"}
{"type": "orderbook_delta", "seq": 2219, "price": 57, "quantity": 500, "ts": 1756428236.424086, "side": "buy"}
{"type": "orderbook_delta", "seq": 2220, "price": 52, "quantity": -1250, "ts": 1756428236.456921, "side": "buy"}
{"type": "orderbook_delta", "seq": 2221, "price": 65, "quantity": -100, "ts": 1756428236.500556, "side": "sell"}
{"type": "orderbook_delta", "seq": 2222, "price": 66, "quantity": 100, "ts": 1756428236.500556, "side": "sell"}
{"type": "orderbook_delta", "seq": 2223, "price": 64, "quantity": 500, "ts": 1756428236.50078, "side": "sell"}
{"type": "orderbook_delta", "seq": 2224, "price": 53, "quantity": 1250, "ts": 1756428236.50208, "side": "buy"}
{"type": "orderbook_delta", "seq": 2225, "price": 64, "quantity": -500, "ts": 1756428236.538963, "side": "sell"}
{"type": "orderbook_delta", "seq": 2226, "price": 65, "quantity": 500, "ts": 1756428236.596004, "side": "sell"}
{"type": "orderbook_delta", "seq": 2227, "price": 66, "quantity": -200, "ts": 1756428236.600798, "side": "sell"}
{"type": "orderbook_delta", "seq": 2228, "price": 67, "quantity": 200, "ts": 1756428236.600798, "side": "sell"}
{"type": "orderbook_delta", "seq": 2229, "price": 58, "quantity": 0, "ts": 1756428237.176249, "side": "sell"}
{"type": "orderbook_delta", "seq": 2230, "price": 62, "quantity": -167, "ts": 1756428237.176724, "side": "sell"}
{"type": "orderbook_delta", "seq": 2231, "price": 76, "quantity": 250, "ts": 1756428237.215586, "side": "sell"}
{"type": "orderbook_delta", "seq": 2232, "price": 57, "quantity": -39, "ts": 1756428237.233226, "side": "buy"}
{"type": "orderbook_delta", "seq": 2233, "price": 58, "quantity": 39, "ts": 1756428237.233226, "side": "buy"}
{"type": "orderbook_delta", "seq": 2234, "price": 66, "quantity": -250, "ts": 1756428237.246799, "side": "sell"}
{"type": "trade", "seq": 29, "price": 58, "quantity": 100, "ts": 1756428237.271574, "side": "buy"}
{"type": "orderbook_delta", "seq": 2235, "price": 48, "quantity": -250, "ts": 1756428237.271574, "side": "buy"}
{"type": "orderbook_delta", "seq": 2236, "price": 58, "quantity": 250, "ts": 1756428237.275885, "side": "buy"}
{"type": "orderbook_delta", "seq": 2237, "price": 64, "quantity": 267, "ts": 1756428237.321034, "side": "sell"}
{"type": "orderbook_delta", "seq": 2238, "price": 50, "quantity": -250, "ts": 1756428237.361159, "side": "buy"}
{"type": "orderbook_delta", "seq": 2239, "price": 60, "quantity": 250, "ts": 1756428237.361193, "side": "buy"}
{"type": "orderbook_delta", "seq": 2240, "price": 65, "quantity": -500, "ts": 1756428237.401413, "side": "sell"}
{"type": "orderbook_delta", "seq": 2241, "price": 54, "quantity": -200, "ts": 1756428237.422686, "side": "buy"}
{"type": "orderbook_delta", "seq": 2242, "price": 12, "quantity": -8000, "ts": 1756428237.42314, "side": "buy"}
{"type": "orderbook_delta", "seq": 2243, "price": 65, "quantity": -200, "ts": 1756428237.423771, "side": "sell"}
{"type": "orderbook_delta", "seq": 2244, "price": 50, "quantity": 250, "ts": 1756428237.441568, "side": "buy"}
{"type": "orderbook_delta", "seq": 2245, "price": 63, "quantity": 500, "ts": 1756428237.44542, "side": "sell"}
{"type": "orderbook_delta", "seq": 2246, "price": 55, "quantity": 200, "ts": 1756428237.46521, "side": "buy"}
{"type": "orderbook_delta", "seq": 2247, "price": 66, "quantity": 200, "ts": 1756428237.47449, "side": "sell"}
{"type": "orderbook_delta", "seq": 2248, "price": 30, "quantity": 8000, "ts": 1756428237.482802, "side": "buy"}
{"type": "orderbook_delta", "seq": 2249, "price": 60, "quantity": -250, "ts": 1756428237.51566, "side": "buy"}
{"type": "orderbook_delta", "seq": 2250, "price": 58, "quantity": -39, "ts": 1756428237.560052, "side": "buy"}
{"type": "orderbook_delta", "seq": 2251, "price": 59, "quantity": 39, "ts": 1756428237.560052, "side": "buy"}
{"type": "orderbook_delta", "seq": 2252, "price": 57, "quantity": -500, "ts": 1756428238.142072, "side": "buy"}
{"type": "orderbook_delta", "seq": 2253, "price": 63, "quantity": -500, "ts": 1756428238.142514, "side": "sell"}
{"type": "orderbook_delta", "seq": 2254, "price": 67, "quantity": -1250, "ts": 1756428238.144327, "side": "sell"}
{"type": "orderbook_delta", "seq": 2255, "price": 53, "quantity": -1250, "ts": 1756428238.14546, "side": "buy"}
{"type": "orderbook_delta", "seq": 2256, "price": 30, "quantity": -8000, "ts": 1756428238.146364, "side": "buy"}
{"type": "orderbook_delta", "seq": 2257, "price": 90, "quantity": -8000, "ts": 1756428238.155368, "side": "sell"}
{"type": "orderbook_delta", "seq": 2258, "price": 98, "quantity": 8000, "ts": 1756428238.198592, "side": "sell"}
{"type": "orderbook_delta", "seq": 2259, "price": 64, "quantity": 500, "ts": 1756428238.200729, "side": "sell"}
{"type": "orderbook_delta", "seq": 2260, "price": 31, "quantity": 8000, "ts": 1756428238.201268, "side": "buy"}
{"type": "orderbook_delta", "seq": 2261, "price": 68, "quantity": 1250, "ts": 1756428238.202103, "side": "sell"}
{"type": "orderbook_delta", "seq": 2262, "price": 58, "quantity": 500, "ts": 1756428238.202398, "side": "buy"}
{"type": "orderbook_delta", "seq": 2263, "price": 54, "quantity": 1250, "ts": 1756428238.216482, "side": "buy"}
{"type": "orderbook_delta", "seq": 2264, "price": 56, "quantity": -100, "ts": 1756428238.664848, "side": "buy"}
{"type": "orderbook_delta", "seq": 2265, "price": 64, "quantity": -267, "ts": 1756428239.124031, "side": "sell"}
{"type": "orderbook_delta", "seq": 2266, "price": 64, "quantity": -500, "ts": 1756428239.170776, "side": "sell"}
{"type": "orderbook_delta", "seq": 2267, "price": 63, "quantity": 267, "ts": 1756428239.210529, "side": "sell"}
{"type": "orderbook_delta", "seq": 2268, "price": 65, "quantity": 500, "ts": 1756428239.215863, "side": "sell"}
{"type": "orderbook_delta", "seq": 2269, "price": 66, "quantity": -100, "ts": 1756428239.219749, "side": "sell"}
{"type": "orderbook_delta", "seq": 2270, "price": 65, "quantity": 100, "ts": 1756428239.219749, "side": "sell"}
{"type": "orderbook_delta", "seq": 2271, "price": 65, "quantity": -500, "ts": 1756428239.26753, "side": "sell"}
{"type": "orderbook_delta", "seq": 2272, "price": 64, "quantity": 500, "ts": 1756428239.326971, "side": "sell"}
{"type": "orderbook_delta", "seq": 2273, "price": 76, "quantity": -250, "ts": 1756428240.106683, "side": "sell"}
{"type": "orderbook_delta", "seq": 2274, "price": 66, "quantity": 250, "ts": 1756428240.126182, "side": "sell"}
{"type": "orderbook_delta", "seq": 2275, "price": 54, "quantity": -1250, "ts": 1756428240.210059, "side": "buy"}
{"type": "orderbook_delta", "seq": 2276, "price": 53, "quantity": 1250, "ts": 1756428240.253155, "side": "buy"}
{"type": "orderbook_delta", "seq": 2277, "price": 59, "quantity": -39, "ts": 1756428240.476394, "side": "buy"}
{"type": "orderbook_delta", "seq": 2278, "price": 65, "quantity": -100, "ts": 1756428240.52646, "side": "sell"}
{"type": "orderbook_delta", "seq": 2279, "price": 64, "quantity": -500, "ts": 1756428240.572335, "side": "sell"}
{"type": "orderbook_delta", "seq": 2280, "price": 65, "quantity": 500, "ts": 1756428240.604584, "side": "sell"}
{"type": "orderbook_delta", "seq": 2281, "price": 63, "quantity": -267, "ts": 1756428241.092894, "side": "sell"}
{"type": "orderbook_delta", "seq": 2282, "price": 76, "quantity": 250, "ts": 1756428241.097956, "side": "sell"}
{"type": "orderbook_delta", "seq": 2283, "price": 66, "quantity": -250, "ts": 1756428241.126101, "side": "sell"}
{"type": "orderbook_delta", "seq": 2284, "price": 64, "quantity": 267, "ts": 1756428241.206033, "side": "sell"}
{"type": "orderbook_delta", "seq": 2285, "price": 65, "quantity": -500, "ts": 1756428241.273019, "side": "sell"}
{"type": "orderbook_delta", "seq": 2286, "price": 64, "quantity": 500, "ts": 1756428241.319784, "side": "sell"}
{"type": "orderbook_delta", "seq": 2287, "price": 59, "quantity": 100, "ts": 1756428241.508687, "side": "buy"}
{"type": "orderbook_delta", "seq": 2288, "price": 62, "quantity": 100, "ts": 1756428242.399522, "side": "sell"}
{"type": "orderbook_delta", "seq": 2289, "price": 53, "quantity": -1250, "ts": 1756428242.432145, "side": "buy"}
{"type": "orderbook_delta", "seq": 2290, "price": 54, "quantity": 1250, "ts": 1756428242.478943, "side": "buy"}
{"type": "orderbook_delta", "seq": 2291, "price": 66, "quantity": -200, "ts": 1756428242.609085, "side": "sell"}
{"type": "orderbook_delta", "seq": 2292, "price": 55, "quantity": -200, "ts": 1756428242.609268, "side": "buy"}
{"type": "orderbook_delta", "seq": 2293, "price": 58, "quantity": -500, "ts": 1756428242.610456, "side": "buy"}
{"type": "orderbook_delta", "seq": 2294, "price": 54, "quantity": -1250, "ts": 1756428242.61104, "side": "buy"}
{"type": "orderbook_delta", "seq": 2295, "price": 68, "quantity": -1250, "ts": 1756428242.611758, "side": "sell"}
{"type": "orderbook_delta", "seq": 2296, "price": 64, "quantity": -500, "ts": 1756428242.616727, "side": "sell"}
{"type": "orderbook_delta", "seq": 2297, "price": 68, "quantity": 200, "ts": 1756428242.667492, "side": "sell"}
{"type": "orderbook_delta", "seq": 2298, "price": 59, "quantity": 500, "ts": 1756428242.667769, "side": "buy"}
{"type": "orderbook_delta", "seq": 2299, "price": 69, "quantity": 1250, "ts": 1756428242.670465, "side": "sell"}
{"type": "orderbook_delta", "seq": 2300, "price": 67, "quantity": -200, "ts": 1756428242.675622, "side": "sell"}
{"type": "orderbook_delta", "seq": 2301, "price": 69, "quantity": 200, "ts": 1756428242.675622, "side": "sell"}
{"type": "orderbook_delta", "seq": 2302, "price": 57, "quantity": 200, "ts": 1756428242.676044, "side": "buy"}
{"type": "trade", "seq": 30, "price": 62, "quantity": 34, "ts": 1756428242.724498, "side": "buy"}
{"type": "orderbook_delta", "seq": 2303, "price": 62, "quantity": 0, "ts": 1756428242.724498, "side": "sell"}
{"type": "orderbook_delta", "seq": 2304, "price": 55, "quantity": 1250, "ts": 1756428242.729112, "side": "buy"}
{"type": "orderbook_delta", "seq": 2305, "price": 68, "quantity": -200, "ts": 1756428242.846757, "side": "sell"}
{"type": "orderbook_delta", "seq": 2306, "price": 59, "quantity": -500, "ts": 1756428242.847946, "side": "buy"}
{"type": "orderbook_delta", "seq": 2307, "price": 65, "quantity": 500, "ts": 1756428242.84797, "side": "sell"}
{"type": "orderbook_delta", "seq": 2308, "price": 57, "quantity": -200, "ts": 1756428242.849424, "side": "buy"}
{"type": "orderbook_delta", "seq": 2309, "price": 55, "quantity": -1250, "ts": 1756428242.850301, "side": "buy"}
{"type": "orderbook_delta", "seq": 2310, "price": 69, "quantity": -1250, "ts": 1756428242.85304, "side": "sell"}
{"type": "orderbook_delta", "seq": 2311, "price": 90, "quantity": -200, "ts": 1756428242.864958, "side": "sell"}
{"type": "orderbook_delta", "seq": 2312, "price": 57, "quantity": 1250, "ts": 1756428242.906244, "side": "buy"}
{"type": "orderbook_delta", "seq": 2313, "price": 72, "quantity": 1250, "ts": 1756428242.908121, "side": "sell"}
{"type": "orderbook_delta", "seq": 2314, "price": 60, "quantity": 500, "ts": 1756428242.908794, "side": "buy"}
{"type": "orderbook_delta", "seq": 2315, "price": 70, "quantity": 200, "ts": 1756428242.910312, "side": "sell"}
{"type": "orderbook_delta", "seq": 2316, "price": 59, "quantity": 200, "ts": 1756428242.927528, "side": "buy"}
{"type": "orderbook_delta", "seq": 2317, "price": 65, "quantity": -500, "ts": 1756428242.969506, "side": "sell"}
{"type": "orderbook_delta", "seq": 2318, "price": 69, "quantity": -200, "ts": 1756428242.974652, "side": "sell"}
{"type": "orderbook_delta", "seq": 2319, "price": 70, "quantity": 200, "ts": 1756428242.974652, "side": "sell"}
{"type": "orderbook_delta", "seq": 2320, "price": 67, "quantity": 500, "ts": 1756428243.028082, "side": "sell"}
{"type": "orderbook_delta", "seq": 2321, "price": 60, "quantity": 250, "ts": 1756428243.105684, "side": "buy"}
{"type": "orderbook_delta", "seq": 2322, "price": 64, "quantity": -267, "ts": 1756428243.107083, "side": "sell"}
{"type": "orderbook_delta", "seq": 2323, "price": 78, "quantity": 250, "ts": 1756428243.126481, "side": "sell"}
{"type": "orderbook_delta", "seq": 2324, "price": 72, "quantity": -1250, "ts": 1756428243.214819, "side": "sell"}
{"type": "orderbook_delta", "seq": 2325, "price": 68, "quantity": -250, "ts": 1756428243.215178, "side": "sell"}
{"type": "orderbook_delta", "seq": 2326, "price": 60, "quantity": -500, "ts": 1756428243.215762, "side": "buy"}
{"type": "orderbook_delta", "seq": 2327, "price": 50, "quantity": -250, "ts": 1756428243.237367, "side": "buy"}
{"type": "orderbook_delta", "seq": 2328, "price": 67, "quantity": -500, "ts": 1756428243.260847, "side": "sell"}
{"type": "orderbook_delta", "seq": 2329, "price": 61, "quantity": 500, "ts": 1756428243.264035, "side": "buy"}
{"type": "orderbook_delta", "seq": 2330, "price": 71, "quantity": 1250, "ts": 1756428243.269734, "side": "sell"}
{"type": "orderbook_delta", "seq": 2331, "price": 66, "quantity": 267, "ts": 1756428243.304464, "side": "sell"}
{"type": "orderbook_delta", "seq": 2332, "price": 69, "quantity": 500, "ts": 1756428243.350008, "side": "sell"}
{"type": "orderbook_delta", "seq": 2333, "price": 59, "quantity": -100, "ts": 1756428244.718836, "side": "buy"}
{"type": "orderbook_delta", "seq": 2334, "price": 61, "quantity": 93, "ts": 1756428244.974148, "side": "buy"}
{"type": "orderbook_delta", "seq": 2335, "price": 66, "quantity": -267, "ts": 1756428245.098368, "side": "sell"}
{"type": "orderbook_delta", "seq": 2336, "price": 68, "quantity": 250, "ts": 1756428245.100669, "side": "sell"}
{"type": "orderbook_delta", "seq": 2337, "price": 78, "quantity": -250, "ts": 1756428245.117574, "side": "sell"}
{"type": "orderbook_delta", "seq": 2338, "price": 69, "quantity": -500, "ts": 1756428245.167362, "side": "sell"}
{"type": "orderbook_delta", "seq": 2339, "price": 65, "quantity": 267, "ts": 1756428245.185412, "side": "sell"}
{"type": "orderbook_delta", "seq": 2340, "price": 67, "quantity": 500, "ts": 1756428245.21747, "side": "sell"}
{"type": "orderbook_delta", "seq": 2341, "price": 62, "quantity": -66, "ts": 1756428245.708365, "side": "sell"}
{"type": "orderbook_delta", "seq": 2342, "price": 61, "quantity": -500, "ts": 1756428245.746464, "side": "buy"}
{"type": "orderbook_delta", "seq": 2343, "price": 62, "quantity": 500, "ts": 1756428245.811198, "side": "buy"}
{"type": "orderbook_delta", "seq": 2344, "price": 61, "quantity": -93, "ts": 1756428246.201756, "side": "buy"}
{"type": "orderbook_delta", "seq": 2345, "price": 62, "quantity": -500, "ts": 1756428246.234963, "side": "buy"}
{"type": "orderbook_delta", "seq": 2346, "price": 60, "quantity": -250, "ts": 1756428246.277702, "side": "buy"}
{"type": "orderbook_delta", "seq": 2347, "price": 50, "quantity": 250, "ts": 1756428246.279516, "side": "buy"}
{"type": "orderbook_delta", "seq": 2348, "price": 61, "quantity": 500, "ts": 1756428246.282274, "side": "buy"}
{"type": "orderbook_delta", "seq": 2349, "price": 61, "quantity": -500, "ts": 1756428246.314802, "side": "buy"}
{"type": "orderbook_delta", "seq": 2350, "price": 50, "quantity": -250, "ts": 1756428246.322127, "side": "buy"}
{"type": "orderbook_delta", "seq": 2351, "price": 59, "quantity": 500, "ts": 1756428246.348347, "side": "buy"}
{"type": "orderbook_delta", "seq": 2352, "price": 71, "quantity": -1250, "ts": 1756428246.379734, "side": "sell"}
{"type": "orderbook_delta", "seq": 2353, "price": 57, "quantity": -1250, "ts": 1756428246.382553, "side": "buy"}
{"type": "orderbook_delta", "seq": 2354, "price": 61, "quantity": 127, "ts": 1756428246.396844, "side": "buy"}
{"type": "orderbook_delta", "seq": 2355, "price": 72, "quantity": 1250, "ts": 1756428246.428746, "side": "sell"}
{"type": "orderbook_delta", "seq": 2356, "price": 59, "quantity": -500, "ts": 1756428246.430421, "side": "buy"}
{"type": "orderbook_delta", "seq": 2357, "price": 58, "quantity": 1250, "ts": 1756428246.432224, "side": "buy"}
{"type": "orderbook_delta", "seq": 2358, "price": 60, "quantity": 250, "ts": 1756428246.436626, "side": "buy"}
{"type": "orderbook_delta", "seq": 2359, "price": 62, "quantity": 500, "ts": 1756428246.48201, "side": "buy"}
{"type": "orderbook_delta", "seq": 2360, "price": 61, "quantity": -127, "ts": 1756428247.145099, "side": "buy"}
{"type": "orderbook_delta", "seq": 2361, "price": 62, "quantity": -500, "ts": 1756428247.18426, "side": "buy"}
{"type": "orderbook_delta", "seq": 2362, "price": 58, "quantity": -1250, "ts": 1756428247.184524, "side": "buy"}
{"type": "orderbook_delta", "seq": 2363, "price": 61, "quantity": 500, "ts": 1756428247.245684, "side": "buy"}
{"type": "orderbook_delta", "seq": 2364, "price": 57, "quantity": 1250, "ts": 1756428247.248425, "side": "buy"}
{"type": "orderbook_delta", "seq": 2365, "price": 62, "quantity": 127, "ts": 1756428247.374918, "side": "buy"}
{"type": "orderbook_delta", "seq": 2366, "price": 61, "quantity": -500, "ts": 1756428247.444478, "side": "buy"}
{"type": "orderbook_delta", "seq": 2367, "price": 62, "quantity": 500, "ts": 1756428247.505396, "side": "buy"}
{"type": "orderbook_delta", "seq": 2368, "price": 67, "quantity": -500, "ts": 1756428248.478368, "side": "sell"}
{"type": "orderbook_delta", "seq": 2369, "price": 57, "quantity": -1250, "ts": 1756428248.478773, "side": "buy"}
{"type": "orderbook_delta", "seq": 2370, "price": 68, "quantity": 500, "ts": 1756428248.539988, "side": "sell"}
{"type": "orderbook_delta", "seq": 2371, "price": 58, "quantity": 1250, "ts": 1756428248.540968, "side": "buy"}
{"type": "orderbook_delta", "seq": 2372, "price": 37, "quantity": -50, "ts": 1756428248.602767, "side": "buy"}
{"type": "orderbook_delta", "seq": 2373, "price": 78, "quantity": 250, "ts": 1756428250.101154, "side": "sell"}
{"type": "orderbook_delta", "seq": 2374, "price": 65, "quantity": -267, "ts": 1756428250.104817, "side": "sell"}
{"type": "orderbook_delta", "seq": 2375, "price": 68, "quantity": -250, "ts": 1756428250.145296, "side": "sell"}
{"type": "orderbook_delta", "seq": 2376, "price": 65, "quantity": 100, "ts": 1756428250.181304, "side": "sell"}
{"type": "orderbook_delta", "seq": 2377, "price": 68, "quantity": -500, "ts": 1756428250.183487, "side": "sell"}
{"type": "orderbook_delta", "seq": 2378, "price": 66, "quantity": 267, "ts": 1756428250.188103, "side": "sell"}
{"type": "orderbook_delta", "seq": 2379, "price": 69, "quantity": 500, "ts": 1756428250.217747, "side": "sell"}
{"type": "orderbook_delta", "seq": 2380, "price": 72, "quantity": -1250, "ts": 1756428250.461306, "side": "sell"}
{"type": "orderbook_delta", "seq": 2381, "price": 62, "quantity": -500, "ts": 1756428250.461729, "side": "buy"}
{"type": "orderbook_delta", "seq": 2382, "price": 58, "quantity": -1250, "ts": 1756428250.461837, "side": "buy"}
{"type": "orderbook_delta", "seq": 2383, "price": 61, "quantity": 500, "ts": 1756428250.504766, "side": "buy"}
{"type": "orderbook_delta", "seq": 2384, "price": 71, "quantity": 1250, "ts": 1756428250.505851, "side": "sell"}
{"type": "orderbook_delta", "seq": 2385, "price": 57, "quantity": 1250, "ts": 1756428250.515549, "side": "buy"}
{"type": "orderbook_delta", "seq": 2386, "price": 61, "quantity": -500, "ts": 1756428252.494387, "side": "buy"}
{"type": "orderbook_delta", "seq": 2387, "price": 71, "quantity": -1250, "ts": 1756428252.494606, "side": "sell"}
{"type": "orderbook_delta", "seq": 2388, "price": 70, "quantity": -200, "ts": 1756428252.497791, "side": "sell"}
{"type": "orderbook_delta", "seq": 2389, "price": 59, "quantity": -200, "ts": 1756428252.508466, "side": "buy"}
{"type": "orderbook_delta", "seq": 2390, "price": 57, "quantity": -1250, "ts": 1756428252.553995, "side": "buy"}
{"type": "orderbook_delta", "seq": 2391, "price": 71, "quantity": 200, "ts": 1756428252.58196, "side": "sell"}
{"type": "orderbook_delta", "seq": 2392, "price": 62, "quantity": 500, "ts": 1756428252.585206, "side": "buy"}
{"type": "orderbook_delta", "seq": 2393, "price": 58, "quantity": 1250, "ts": 1756428252.58555, "side": "buy"}
{"type": "orderbook_delta", "seq": 2394, "price": 72, "quantity": 1250, "ts": 1756428252.585816, "side": "sell"}
{"type": "orderbook_delta", "seq": 2395, "price": 60, "quantity": 200, "ts": 1756428252.589433, "side": "buy"}
{"type": "orderbook_delta", "seq": 2396, "price": 71, "quantity": -200, "ts": 1756428253.913334, "side": "sell"}
{"type": "orderbook_delta", "seq": 2397, "price": 60, "quantity": -200, "ts": 1756428253.914052, "side": "buy"}
{"type": "orderbook_delta", "seq": 2398, "price": 59, "quantity": 200, "ts": 1756428253.9617, "side": "buy"}
{"type": "orderbook_delta", "seq": 2399, "price": 70, "quantity": 200, "ts": 1756428253.967471, "side": "sell"}
{"type": "orderbook_delta", "seq": 2400, "price": 58, "quantity": -1250, "ts": 1756428254.019034, "side": "buy"}
{"type": "orderbook_delta", "seq": 2401, "price": 59, "quantity": -200, "ts": 1756428254.019787, "side": "buy"}
{"type": "orderbook_delta", "seq": 2402, "price": 72, "quantity": -1250, "ts": 1756428254.020257, "side": "sell"}
{"type": "orderbook_delta", "seq": 2403, "price": 69, "quantity": -500, "ts": 1756428254.020722, "side": "sell"}
{"type": "orderbook_delta", "seq": 2404, "price": 70, "quantity": -200, "ts": 1756428254.021535, "side": "sell"}
{"type": "orderbook_delta", "seq": 2405, "price": 62, "quantity": -500, "ts": 1756428254.024396, "side": "buy"}
{"type": "orderbook_delta", "seq": 2406, "price": 69, "quantity": 200, "ts": 1756428254.064845, "side": "sell"}
{"type": "orderbook_delta", "seq": 2407, "price": 70, "quantity": 1250, "ts": 1756428254.065179, "side": "sell"}
{"type": "orderbook_delta", "seq": 2408, "price": 60, "quantity": 500, "ts": 1756428254.066992, "side": "buy"}
{"type": "orderbook_delta", "seq": 2409, "price": 57, "quantity": 200, "ts": 1756428254.067308, "side": "buy"}
{"type": "orderbook_delta", "seq": 2410, "price": 56, "quantity": 1250, "ts": 1756428254.067795, "side": "buy"}
{"type": "orderbook_delta", "seq": 2411, "price": 66, "quantity": 500, "ts": 1756428254.068357, "side": "sell"}
{"type": "orderbook_delta", "seq": 2412, "price": 70, "quantity": -200, "ts": 1756428254.13076, "side": "sell"}
{"type": "orderbook_delta", "seq": 2413, "price": 67, "quantity": 200, "ts": 1756428254.13076, "side": "sell"}
{"type": "orderbook_delta", "seq": 2414, "price": 50, "quantity": 250, "ts": 1756428254.366665, "side": "buy"}
{"type": "orderbook_delta", "seq": 2415, "price": 60, "quantity": -250, "ts": 1756428254.369228, "side": "buy"}
{"type": "orderbook_delta", "seq": 2416, "price": 60, "quantity": -500, "ts": 1756428254.369923, "side": "buy"}
{"type": "orderbook_delta", "seq": 2417, "price": 56, "quantity": -1250, "ts": 1756428254.372725, "side": "buy"}
{"type": "orderbook_delta", "seq": 2418, "price": 57, "quantity": -200, "ts": 1756428254.374267, "side": "buy"}
{"type": "orderbook_delta", "seq": 2419, "price": 66, "quantity": -500, "ts": 1756428254.375865, "side": "sell"}
{"type": "orderbook_delta", "seq": 2420, "price": 69, "quantity": -200, "ts": 1756428254.375931, "side": "sell"}
{"type": "orderbook_delta", "seq": 2421, "price": 70, "quantity": -1250, "ts": 1756428254.385768, "side": "sell"}
{"type": "orderbook_delta", "seq": 2422, "price": 69, "quantity": 1250, "ts": 1756428254.454409, "side": "sell"}
{"type": "orderbook_delta", "seq": 2423, "price": 59, "quantity": 500, "ts": 1756428254.455702, "side": "buy"}
{"type": "orderbook_delta", "seq": 2424, "price": 65, "quantity": 500, "ts": 1756428254.456613, "side": "sell"}
{"type": "orderbook_delta", "seq": 2425, "price": 54, "quantity": 1250, "ts": 1756428254.456902, "side": "buy"}
{"type": "orderbook_delta", "seq": 2426, "price": 67, "quantity": 200, "ts": 1756428254.458668, "side": "sell"}
{"type": "orderbook_delta", "seq": 2427, "price": 56, "quantity": 200, "ts": 1756428254.460713, "side": "buy"}
{"type": "orderbook_delta", "seq": 2428, "price": 54, "quantity": -1250, "ts": 1756428254.557976, "side": "buy"}
{"type": "orderbook_delta", "seq": 2429, "price": 59, "quantity": -500, "ts": 1756428254.558066, "side": "buy"}
{"type": "orderbook_delta", "seq": 2430, "price": 67, "quantity": -200, "ts": 1756428254.559021, "side": "sell"}
{"type": "orderbook_delta", "seq": 2431, "price": 65, "quantity": -500, "ts": 1756428254.560232, "side": "sell"}
{"type": "orderbook_delta", "seq": 2432, "price": 56, "quantity": -200, "ts": 1756428254.560289, "side": "buy"}
{"type": "orderbook_delta", "seq": 2433, "price": 31, "quantity": -8000, "ts": 1756428254.560339, "side": "buy"}
{"type": "orderbook_delta", "seq": 2434, "price": 55, "quantity": 200, "ts": 1756428254.601464, "side": "buy"}
{"type": "orderbook_delta", "seq": 2435, "price": 30, "quantity": 8000, "ts": 1756428254.602043, "side": "buy"}
{"type": "orderbook_delta", "seq": 2436, "price": 66, "quantity": 200, "ts": 1756428254.60295, "side": "sell"}
{"type": "orderbook_delta", "seq": 2437, "price": 58, "quantity": 500, "ts": 1756428254.603208, "side": "buy"}
{"type": "orderbook_delta", "seq": 2438, "price": 53, "quantity": 1250, "ts": 1756428254.60348, "side": "buy"}
{"type": "orderbook_delta", "seq": 2439, "price": 64, "quantity": 500, "ts": 1756428254.607452, "side": "sell"}
{"type": "orderbook_delta", "seq": 2440, "price": 55, "quantity": -200, "ts": 1756428254.982645, "side": "buy"}
{"type": "orderbook_delta", "seq": 2441, "price": 66, "quantity": -200, "ts": 1756428254.983453, "side": "sell"}
{"type": "orderbook_delta", "seq": 2442, "price": 69, "quantity": -1250, "ts": 1756428254.984852, "side": "sell"}
{"type": "orderbook_delta", "seq": 2443, "price": 58, "quantity": -500, "ts": 1756428254.985283, "side": "buy"}
{"type": "orderbook_delta", "seq": 2444, "price": 67, "quantity": -200, "ts": 1756428255.042835, "side": "sell"}
{"type": "orderbook_delta", "seq": 2445, "price": 66, "quantity": 200, "ts": 1756428255.042835, "side": "sell"}
{"type": "orderbook_delta", "seq": 2446, "price": 54, "quantity": 200, "ts": 1756428255.045166, "side": "buy"}
{"type": "orderbook_delta", "seq": 2447, "price": 65, "quantity": 200, "ts": 1756428255.045439, "side": "sell"}
{"type": "orderbook_delta", "seq": 2448, "price": 57, "quantity": 500, "ts": 1756428255.046461, "side": "buy"}
{"type": "orderbook_delta", "seq": 2449, "price": 67, "quantity": 1250, "ts": 1756428255.047078, "side": "sell"}
{"type": "orderbook_delta", "seq": 2450, "price": 67, "quantity": -1250, "ts": 1756428255.084503, "side": "sell"}
{"type": "orderbook_delta", "seq": 2451, "price": 69, "quantity": 1250, "ts": 1756428255.114378, "side": "sell"}
{"type": "orderbook_delta", "seq": 2452, "price": 66, "quantity": -267, "ts": 1756428255.131568, "side": "sell"}
{"type": "orderbook_delta", "seq": 2453, "price": 66, "quantity": 250, "ts": 1756428255.131849, "side": "sell"}
{"type": "orderbook_delta", "seq": 2454, "price": 78, "quantity": -250, "ts": 1756428255.148055, "side": "sell"}
{"type": "orderbook_delta", "seq": 2455, "price": 68, "quantity": 250, "ts": 1756428255.148294, "side": "sell"}
{"type": "orderbook_delta", "seq": 2456, "price": 69, "quantity": -1250, "ts": 1756428255.18203, "side": "sell"}
{"type": "orderbook_delta", "seq": 2457, "price": 76, "quantity": -250, "ts": 1756428255.186361, "side": "sell"}
{"type": "orderbook_delta", "seq": 2458, "price": 67, "quantity": 1250, "ts": 1756428255.226985, "side": "sell"}
{"type": "orderbook_delta", "seq": 2459, "price": 63, "quantity": 267, "ts": 1756428255.252306, "side": "sell"}
{"type": "orderbook_delta", "seq": 2460, "price": 64, "quantity": -500, "ts": 1756428255.294488, "side": "sell"}
{"type": "orderbook_delta", "seq": 2461, "price": 63, "quantity": 500, "ts": 1756428255.362573, "side": "sell"}
{"type": "orderbook_delta", "seq": 2462, "price": 66, "quantity": -250, "ts": 1756428255.769258, "side": "sell"}
{"type": "orderbook_delta", "seq": 2463, "price": 76, "quantity": 250, "ts": 1756428255.774339, "side": "sell"}
{"type": "orderbook_delta", "seq": 2464, "price": 30, "quantity": -8000, "ts": 1756428255.829143, "side": "buy"}
{"type": "orderbook_delta", "seq": 2465, "price": 12, "quantity": 8000, "ts": 1756428255.870926, "side": "buy"}
{"type": "orderbook_delta", "seq": 2466, "price": 62, "quantity": -127, "ts": 1756428255.981469, "side": "buy"}
{"type": "orderbook_delta", "seq": 2467, "price": 65, "quantity": -100, "ts": 1756428256.537565, "side": "sell"}
{"type": "orderbook_delta", "seq": 2468, "price": 54, "quantity": -200, "ts": 1756428256.647634, "side": "buy"}
{"type": "orderbook_delta", "seq": 2469, "price": 57, "quantity": -500, "ts": 1756428256.647716, "side": "buy"}
{"type": "orderbook_delta", "seq": 2470, "price": 12, "quantity": -8000, "ts": 1756428256.649157, "side": "buy"}
{"type": "orderbook_delta", "seq": 2471, "price": 67, "quantity": -1250, "ts": 1756428256.649305, "side": "sell"}
{"type": "orderbook_delta", "seq": 2472, "price": 65, "quantity": -200, "ts": 1756428256.651315, "side": "sell"}
{"type": "orderbook_delta", "seq": 2473, "price": 66, "quantity": 200, "ts": 1756428256.696831, "side": "sell"}
{"type": "orderbook_delta", "seq": 2474, "price": 68, "quantity": 1250, "ts": 1756428256.698211, "side": "sell"}
{"type": "orderbook_delta", "seq": 2475, "price": 55, "quantity": 200, "ts": 1756428256.699093, "side": "buy"}
{"type": "orderbook_delta", "seq": 2476, "price": 30, "quantity": 8000, "ts": 1756428256.6997, "side": "buy"}
{"type": "orderbook_delta", "seq": 2477, "price": 58, "quantity": 500, "ts": 1756428256.699941, "side": "buy"}
{"type": "orderbook_delta", "seq": 2478, "price": 68, "quantity": -1250, "ts": 1756428256.756634, "side": "sell"}
{"type": "orderbook_delta", "seq": 2479, "price": 66, "quantity": -200, "ts": 1756428256.757782, "side": "sell"}
{"type": "orderbook_delta", "seq": 2480, "price": 58, "quantity": -500, "ts": 1756428256.757906, "side": "buy"}
{"type": "orderbook_delta", "seq": 2481, "price": 55, "quantity": -200, "ts": 1756428256.760021, "side": "buy"}
{"type": "orderbook_delta", "seq": 2482, "price": 65, "quantity": 200, "ts": 1756428256.827463, "side": "sell"}
{"type": "orderbook_delta", "seq": 2483, "price": 54, "quantity": 200, "ts": 1756428256.828069, "side": "buy"}
{"type": "orderbook_delta", "seq": 2484, "price": 57, "quantity": 500, "ts": 1756428256.828588, "side": "buy"}
{"type": "orderbook_delta", "seq": 2485, "price": 67, "quantity": 1250, "ts": 1756428256.829902, "side": "sell"}
{"type": "orderbook_delta", "seq": 2486, "price": 59, "quantity": 127, "ts": 1756428257.042966, "side": "buy"}
{"type": "orderbook_delta", "seq": 2487, "price": 76, "quantity": -250, "ts": 1756428257.108753, "side": "sell"}
{"type": "orderbook_delta", "seq": 2488, "price": 66, "quantity": 250, "ts": 1756428257.11168, "side": "sell"}
{"type": "trade", "seq": 31, "price": 63, "quantity": 77, "ts": 1756428257.601057, "side": "buy"}
{"type": "orderbook_delta", "seq": 2489, "price": 63, "quantity": 0, "ts": 1756428257.601057, "side": "sell"}
{"type": "orderbook_delta", "seq": 2490, "price": 62, "quantity": 100, "ts": 1756428257.756487, "side": "sell"}
{"type": "orderbook_delta", "seq": 2491, "price": 53, "quantity": -1250, "ts": 1756428258.7029, "side": "buy"}
{"type": "orderbook_delta", "seq": 2492, "price": 30, "quantity": -8000, "ts": 1756428258.706267, "side": "buy"}
{"type": "orderbook_delta", "seq": 2493, "price": 63, "quantity": -500, "ts": 1756428258.710318, "side": "sell"}
{"type": "orderbook_delta", "seq": 2494, "price": 12, "quantity": 8000, "ts": 1756428258.750946, "side": "buy"}
{"type": "orderbook_delta", "seq": 2495, "price": 52, "quantity": 1250, "ts": 1756428258.753514, "side": "buy"}
{"type": "orderbook_delta", "seq": 2496, "price": 62, "quantity": 500, "ts": 1756428258.756163, "side": "sell"}
{"type": "orderbook_delta", "seq": 2497, "price": 63, "quantity": -190, "ts": 1756428259.091531, "side": "sell"}
{"type": "orderbook_delta", "seq": 2498, "price": 48, "quantity": 250, "ts": 1756428259.094573, "side": "buy"}
{"type": "orderbook_delta", "seq": 2499, "price": 74, "quantity": -250, "ts": 1756428259.107204, "side": "sell"}
{"type": "orderbook_delta", "seq": 2500, "price": 64, "quantity": 250, "ts": 1756428259.107224, "side": "sell"}
{"type": "orderbook_delta", "seq": 2501, "price": 58, "quantity": -250, "ts": 1756428259.1269, "side": "buy"}
{"type": "orderbook_delta", "seq": 2502, "price": 62, "quantity": 190, "ts": 1756428259.264348, "side": "sell"}
{"type": "orderbook_delta", "seq": 2503, "price": 64, "quantity": -250, "ts": 1756428260.124509, "side": "sell"}
{"type": "orderbook_delta", "seq": 2504, "price": 74, "quantity": 250, "ts": 1756428260.160823, "side": "sell"}
{"type": "orderbook_delta", "seq": 2505, "price": 62, "quantity": -500, "ts": 1756428260.72833, "side": "sell"}
{"type": "orderbook_delta", "seq": 2506, "price": 65, "quantity": 500, "ts": 1756428260.763999, "side": "sell"}
{"type": "orderbook_delta", "seq": 2507, "price": 57, "quantity": -500, "ts": 1756428262.761671, "side": "buy"}
{"type": "orderbook_delta", "seq": 2508, "price": 65, "quantity": -500, "ts": 1756428262.761814, "side": "sell"}
{"type": "orderbook_delta", "seq": 2509, "price": 56, "quantity": 500, "ts": 1756428262.801503, "side": "buy"}
{"type": "orderbook_delta", "seq": 2510, "price": 62, "quantity": 500, "ts": 1756428262.804372, "side": "sell"}
{"type": "orderbook_delta", "seq": 2511, "price": 7, "quantity": 2777, "ts": 1756428263.828468, "side": "buy"}
{"type": "orderbook_delta", "seq": 2512, "price": 56, "quantity": -500, "ts": 1756428263.900749, "side": "buy"}
{"type": "orderbook_delta", "seq": 2513, "price": 52, "quantity": -1250, "ts": 1756428263.9021, "side": "buy"}
{"type": "orderbook_delta", "seq": 2514, "price": 62, "quantity": -500, "ts": 1756428263.903141, "side": "sell"}
{"type": "orderbook_delta", "seq": 2515, "price": 90, "quantity": 200, "ts": 1756428263.930472, "side": "sell"}
{"type": "orderbook_delta", "seq": 2516, "price": 67, "quantity": -1250, "ts": 1756428263.941926, "side": "sell"}
{"type": "orderbook_delta", "seq": 2517, "price": 98, "quantity": -8000, "ts": 1756428263.965146, "side": "sell"}
{"type": "orderbook_delta", "seq": 2518, "price": 54, "quantity": -200, "ts": 1756428263.97478, "side": "buy"}
{"type": "orderbook_delta", "seq": 2519, "price": 66, "quantity": -200, "ts": 1756428263.996013, "side": "sell"}
{"type": "orderbook_delta", "seq": 2520, "price": 64, "quantity": 200, "ts": 1756428263.996013, "side": "sell"}
{"type": "orderbook_delta", "seq": 2521, "price": 89, "quantity": 8000, "ts": 1756428264.010247, "side": "sell"}
{"type": "orderbook_delta", "seq": 2522, "price": 66, "quantity": 1250, "ts": 1756428264.020022, "side": "sell"}
{"type": "orderbook_delta", "seq": 2523, "price": 61, "quantity": 500, "ts": 1756428264.021496, "side": "sell"}
{"type": "orderbook_delta", "seq": 2524, "price": 53, "quantity": 200, "ts": 1756428264.025005, "side": "buy"}
{"type": "orderbook_delta", "seq": 2525, "price": 51, "quantity": 1250, "ts": 1756428264.027109, "side": "buy"}
{"type": "orderbook_delta", "seq": 2526, "price": 65, "quantity": -200, "ts": 1756428264.044216, "side": "sell"}
{"type": "orderbook_delta", "seq": 2527, "price": 46, "quantity": 250, "ts": 1756428264.061266, "side": "buy"}
{"type": "orderbook_delta", "seq": 2528, "price": 56, "quantity": -250, "ts": 1756428264.061968, "side": "buy"}
{"type": "orderbook_delta", "seq": 2529, "price": 66, "quantity": -1250, "ts": 1756428264.067716, "side": "sell"}
{"type": "orderbook_delta", "seq": 2530, "price": 63, "quantity": 200, "ts": 1756428264.096264, "side": "sell"}
{"type": "orderbook_delta", "seq": 2531, "price": 55, "quantity": 500, "ts": 1756428264.096549, "side": "buy"}
{"type": "orderbook_delta", "seq": 2532, "price": 62, "quantity": -190, "ts": 1756428264.182528, "side": "sell"}
{"type": "orderbook_delta", "seq": 2533, "price": 44, "quantity": 250, "ts": 1756428264.182569, "side": "buy"}
{"type": "orderbook_delta", "seq": 2534, "price": 65, "quantity": 1250, "ts": 1756428264.182816, "side": "sell"}
{"type": "orderbook_delta", "seq": 2535, "price": 53, "quantity": -200, "ts": 1756428264.190842, "side": "buy"}
{"type": "orderbook_delta", "seq": 2536, "price": 64, "quantity": 250, "ts": 1756428264.197919, "side": "sell"}
{"type": "orderbook_delta", "seq": 2537, "price": 54, "quantity": -250, "ts": 1756428264.198193, "side": "buy"}
{"type": "orderbook_delta", "seq": 2538, "price": 74, "quantity": -250, "ts": 1756428264.218071, "side": "sell"}
{"type": "orderbook_delta", "seq": 2539, "price": 55, "quantity": -500, "ts": 1756428264.238841, "side": "buy"}
{"type": "orderbook_delta", "seq": 2540, "price": 52, "quantity": 200, "ts": 1756428264.240641, "side": "buy"}
{"type": "orderbook_delta", "seq": 2541, "price": 61, "quantity": 190, "ts": 1756428264.264546, "side": "sell"}
{"type": "orderbook_delta", "seq": 2542, "price": 53, "quantity": 500, "ts": 1756428264.287375, "side": "buy"}
{"type": "orderbook_delta", "seq": 2543, "price": 61, "quantity": -500, "ts": 1756428264.850851, "side": "sell"}
{"type": "orderbook_delta", "seq": 2544, "price": 51, "quantity": -1250, "ts": 1756428264.854175, "side": "buy"}
{"type": "orderbook_delta", "seq": 2545, "price": 65, "quantity": -1250, "ts": 1756428264.854391, "side": "sell"}
{"type": "orderbook_delta", "seq": 2546, "price": 63, "quantity": -200, "ts": 1756428264.856165, "side": "sell"}
{"type": "orderbook_delta", "seq": 2547, "price": 52, "quantity": -200, "ts": 1756428264.857191, "side": "buy"}
{"type": "orderbook_delta", "seq": 2548, "price": 52, "quantity": 1250, "ts": 1756428264.906711, "side": "buy"}
{"type": "orderbook_delta", "seq": 2549, "price": 65, "quantity": 200, "ts": 1756428264.907102, "side": "sell"}
{"type": "orderbook_delta", "seq": 2550, "price": 66, "quantity": 1250, "ts": 1756428264.907358, "side": "sell"}
{"type": "orderbook_delta", "seq": 2551, "price": 62, "quantity": 500, "ts": 1756428264.907585, "side": "sell"}
{"type": "orderbook_delta", "seq": 2552, "price": 53, "quantity": 200, "ts": 1756428264.907971, "side": "buy"}
{"type": "orderbook_delta", "seq": 2553, "price": 54, "quantity": 250, "ts": 1756428264.99727, "side": "buy"}
{"type": "orderbook_delta", "seq": 2554, "price": 44, "quantity": -250, "ts": 1756428265.001058, "side": "buy"}
{"type": "orderbook_delta", "seq": 2555, "price": 53, "quantity": -200, "ts": 1756428265.091156, "side": "buy"}
{"type": "orderbook_delta", "seq": 2556, "price": 53, "quantity": -500, "ts": 1756428265.091344, "side": "buy"}
{"type": "orderbook_delta", "seq": 2557, "price": 55, "quantity": 500, "ts": 1756428265.138186, "side": "buy"}
{"type": "orderbook_delta", "seq": 2558, "price": 54, "quantity": 200, "ts": 1756428265.138968, "side": "buy"}
{"type": "orderbook_delta", "seq": 2559, "price": 64, "quantity": -200, "ts": 1756428265.180825, "side": "sell"}
{"type": "orderbook_delta", "seq": 2560, "price": 63, "quantity": 200, "ts": 1756428265.180825, "side": "sell"}
{"type": "orderbook_delta", "seq": 2561, "price": 59, "quantity": -127, "ts": 1756428265.391441, "side": "buy"}
{"type": "orderbook_delta", "seq": 2562, "price": 60, "quantity": 127, "ts": 1756428265.607464, "side": "buy"}
{"type": "orderbook_delta", "seq": 2563, "price": 62, "quantity": -500, "ts": 1756428265.878031, "side": "sell"}
{"type": "orderbook_delta", "seq": 2564, "price": 65, "quantity": -200, "ts": 1756428265.901814, "side": "sell"}
{"type": "orderbook_delta", "seq": 2565, "price": 52, "quantity": -1250, "ts": 1756428265.917221, "side": "buy"}
{"type": "orderbook_delta", "seq": 2566, "price": 54, "quantity": -200, "ts": 1756428265.942205, "side": "buy"}
{"type": "orderbook_delta", "seq": 2567, "price": 64, "quantity": 200, "ts": 1756428265.999536, "side": "sell"}
{"type": "orderbook_delta", "seq": 2568, "price": 61, "quantity": 500, "ts": 1756428266.000995, "side": "sell"}
{"type": "orderbook_delta", "seq": 2569, "price": 53, "quantity": 200, "ts": 1756428266.011732, "side": "buy"}
{"type": "orderbook_delta", "seq": 2570, "price": 51, "quantity": 1250, "ts": 1756428266.137563, "side": "buy"}
{"type": "orderbook_delta", "seq": 2571, "price": 62, "quantity": -100, "ts": 1756428266.388815, "side": "sell"}
{"type": "orderbook_delta", "seq": 2572, "price": 64, "quantity": -200, "ts": 1756428266.936943, "side": "sell"}
{"type": "orderbook_delta", "seq": 2573, "price": 55, "quantity": -500, "ts": 1756428266.937255, "side": "buy"}
{"type": "orderbook_delta", "seq": 2574, "price": 66, "quantity": -1250, "ts": 1756428266.937435, "side": "sell"}
{"type": "orderbook_delta", "seq": 2575, "price": 51, "quantity": -1250, "ts": 1756428266.98036, "side": "buy"}
{"type": "orderbook_delta", "seq": 2576, "price": 44, "quantity": 250, "ts": 1756428266.997269, "side": "buy"}
{"type": "orderbook_delta", "seq": 2577, "price": 54, "quantity": -250, "ts": 1756428267.000974, "side": "buy"}
{"type": "orderbook_delta", "seq": 2578, "price": 53, "quantity": -200, "ts": 1756428267.260129, "side": "buy"}
{"type": "orderbook_delta", "seq": 2579, "price": 65, "quantity": 1250, "ts": 1756428267.352379, "side": "sell"}
{"type": "orderbook_delta", "seq": 2580, "price": 50, "quantity": 1250, "ts": 1756428267.353316, "side": "buy"}
{"type": "orderbook_delta", "seq": 2581, "price": 63, "quantity": 200, "ts": 1756428267.355272, "side": "sell"}
{"type": "orderbook_delta", "seq": 2582, "price": 53, "quantity": 500, "ts": 1756428267.359456, "side": "buy"}
{"type": "orderbook_delta", "seq": 2583, "price": 52, "quantity": 200, "ts": 1756428267.369576, "side": "buy"}
{"type": "orderbook_delta", "seq": 2584, "price": 54, "quantity": 250, "ts": 1756428267.996059, "side": "buy"}
{"type": "orderbook_delta", "seq": 2585, "price": 44, "quantity": -250, "ts": 1756428267.999313, "side": "buy"}
{"type": "orderbook_delta", "seq": 2586, "price": 53, "quantity": -500, "ts": 1756428268.183311, "side": "buy"}
{"type": "orderbook_delta", "seq": 2587, "price": 54, "quantity": 500, "ts": 1756428268.241224, "side": "buy"}
{"type": "orderbook_delta", "seq": 2588, "price": 50, "quantity": -1250, "ts": 1756428269.000087, "side": "buy"}
{"type": "orderbook_delta", "seq": 2589, "price": 65, "quantity": -1250, "ts": 1756428269.000694, "side": "sell"}
{"type": "orderbook_delta", "seq": 2590, "price": 63, "quantity": -200, "ts": 1756428269.002307, "side": "sell"}
{"type": "orderbook_delta", "seq": 2591, "price": 52, "quantity": -200, "ts": 1756428269.002786, "side": "buy"}
{"type": "orderbook_delta", "seq": 2592, "price": 62, "quantity": 200, "ts": 1756428269.039685, "side": "sell"}
{"type": "orderbook_delta", "seq": 2593, "price": 51, "quantity": 200, "ts": 1756428269.040013, "side": "buy"}
{"type": "orderbook_delta", "seq": 2594, "price": 49, "quantity": 1250, "ts": 1756428269.040828, "side": "buy"}
{"type": "orderbook_delta", "seq": 2595, "price": 64, "quantity": 1250, "ts": 1756428269.105188, "side": "sell"}
{"type": "orderbook_delta", "seq": 2596, "price": 64, "quantity": -1250, "ts": 1756428271.105413, "side": "sell"}
{"type": "orderbook_delta", "seq": 2597, "price": 62, "quantity": -200, "ts": 1756428271.106793, "side": "sell"}
{"type": "orderbook_delta", "seq": 2598, "price": 54, "quantity": -500, "ts": 1756428271.107575, "side": "buy"}
{"type": "orderbook_delta", "seq": 2599, "price": 49, "quantity": -1250, "ts": 1756428271.110587, "side": "buy"}
{"type": "orderbook_delta", "seq": 2600, "price": 51, "quantity": -200, "ts": 1756428271.112427, "side": "buy"}
{"type": "orderbook_delta", "seq": 2601, "price": 50, "quantity": 1250, "ts": 1756428271.154907, "side": "buy"}
{"type": "orderbook_delta", "seq": 2602, "price": 55, "quantity": 500, "ts": 1756428271.157579, "side": "buy"}
{"type": "orderbook_delta", "seq": 2603, "price": 52, "quantity": 200, "ts": 1756428271.19884, "side": "buy"}
{"type": "orderbook_delta", "seq": 2604, "price": 63, "quantity": 200, "ts": 1756428271.200334, "side": "sell"}
{"type": "orderbook_delta", "seq": 2605, "price": 65, "quantity": 1250, "ts": 1756428271.465448, "side": "sell"}
{"type": "orderbook_delta", "seq": 2606, "price": 63, "quantity": -200, "ts": 1756428272.644119, "side": "sell"}
{"type": "orderbook_delta", "seq": 2607, "price": 64, "quantity": 200, "ts": 1756428272.644119, "side": "sell"}
{"type": "orderbook_delta", "seq": 2608, "price": 50, "quantity": -1250, "ts": 1756428272.932041, "side": "buy"}
{"type": "orderbook_delta", "seq": 2609, "price": 52, "quantity": -200, "ts": 1756428272.932235, "side": "buy"}
{"type": "orderbook_delta", "seq": 2610, "price": 63, "quantity": -200, "ts": 1756428272.932684, "side": "sell"}
{"type": "orderbook_delta", "seq": 2611, "price": 65, "quantity": -1250, "ts": 1756428272.935777, "side": "sell"}
{"type": "orderbook_delta", "seq": 2612, "price": 64, "quantity": 200, "ts": 1756428272.974514, "side": "sell"}
{"type": "orderbook_delta", "seq": 2613, "price": 66, "quantity": 1250, "ts": 1756428272.975398, "side": "sell"}
{"type": "orderbook_delta", "seq": 2614, "price": 53, "quantity": 200, "ts": 1756428272.979155, "side": "buy"}
{"type": "orderbook_delta", "seq": 2615, "price": 51, "quantity": 1250, "ts": 1756428273.01527, "side": "buy"}
{"type": "orderbook_delta", "seq": 2616, "price": 61, "quantity": -500, "ts": 1756428273.133532, "side": "sell"}
{"type": "orderbook_delta", "seq": 2617, "price": 56, "quantity": 250, "ts": 1756428273.154356, "side": "buy"}
{"type": "orderbook_delta", "seq": 2618, "price": 46, "quantity": -250, "ts": 1756428273.161039, "side": "buy"}
{"type": "orderbook_delta", "seq": 2619, "price": 74, "quantity": 250, "ts": 1756428273.162896, "side": "sell"}
{"type": "orderbook_delta", "seq": 2620, "price": 63, "quantity": 500, "ts": 1756428273.170559, "side": "sell"}
{"type": "orderbook_delta", "seq": 2621, "price": 61, "quantity": -190, "ts": 1756428273.170899, "side": "sell"}
{"type": "orderbook_delta", "seq": 2622, "price": 64, "quantity": -200, "ts": 1756428273.172871, "side": "sell"}
{"type": "orderbook_delta", "seq": 2623, "price": 51, "quantity": -1250, "ts": 1756428273.174612, "side": "buy"}
{"type": "orderbook_delta", "seq": 2624, "price": 55, "quantity": -500, "ts": 1756428273.194246, "side": "buy"}
{"type": "orderbook_delta", "seq": 2625, "price": 64, "quantity": -250, "ts": 1756428273.195951, "side": "sell"}
{"type": "orderbook_delta", "seq": 2626, "price": 56, "quantity": 500, "ts": 1756428273.228517, "side": "buy"}
{"type": "orderbook_delta", "seq": 2627, "price": 53, "quantity": -200, "ts": 1756428273.234915, "side": "buy"}
{"type": "orderbook_delta", "seq": 2628, "price": 62, "quantity": 190, "ts": 1756428273.243165, "side": "sell"}
{"type": "orderbook_delta", "seq": 2629, "price": 64, "quantity": -200, "ts": 1756428273.245459, "side": "sell"}
{"type": "orderbook_delta", "seq": 2630, "price": 65, "quantity": 200, "ts": 1756428273.245459, "side": "sell"}
{"type": "orderbook_delta", "seq": 2631, "price": 54, "quantity": 200, "ts": 1756428273.33218, "side": "buy"}
{"type": "orderbook_delta", "seq": 2632, "price": 65, "quantity": 200, "ts": 1756428273.332764, "side": "sell"}
{"type": "orderbook_delta", "seq": 2633, "price": 63, "quantity": -500, "ts": 1756428273.333254, "side": "sell"}
{"type": "orderbook_delta", "seq": 2634, "price": 52, "quantity": 1250, "ts": 1756428273.333629, "side": "buy"}
{"type": "orderbook_delta", "seq": 2635, "price": 62, "quantity": 500, "ts": 1756428273.374804, "side": "sell"}
{"type": "orderbook_delta", "seq": 2636, "price": 52, "quantity": -1250, "ts": 1756428273.792611, "side": "buy"}
{"type": "orderbook_delta", "seq": 2637, "price": 54, "quantity": -200, "ts": 1756428273.795063, "side": "buy"}
{"type": "orderbook_delta", "seq": 2638, "price": 65, "quantity": -200, "ts": 1756428273.839479, "side": "sell"}
{"type": "orderbook_delta", "seq": 2639, "price": 51, "quantity": 1250, "ts": 1756428273.890508, "side": "buy"}
{"type": "orderbook_delta", "seq": 2640, "price": 64, "quantity": 200, "ts": 1756428273.890831, "side": "sell"}
{"type": "orderbook_delta", "seq": 2641, "price": 53, "quantity": 200, "ts": 1756428273.90021, "side": "buy"}
{"type": "orderbook_delta", "seq": 2642, "price": 62, "quantity": -190, "ts": 1756428275.111537, "side": "sell"}
{"type": "orderbook_delta", "seq": 2643, "price": 74, "quantity": -250, "ts": 1756428275.126422, "side": "sell"}
{"type": "orderbook_delta", "seq": 2644, "price": 64, "quantity": 250, "ts": 1756428275.133172, "side": "sell"}
{"type": "orderbook_delta", "seq": 2645, "price": 62, "quantity": -500, "ts": 1756428275.141728, "side": "sell"}
{"type": "orderbook_delta", "seq": 2646, "price": 63, "quantity": 500, "ts": 1756428275.17662, "side": "sell"}
{"type": "orderbook_delta", "seq": 2647, "price": 61, "quantity": 190, "ts": 1756428275.180058, "side": "sell"}
{"type": "orderbook_delta", "seq": 2648, "price": 56, "quantity": -500, "ts": 1756428275.196414, "side": "buy"}
{"type": "orderbook_delta", "seq": 2649, "price": 63, "quantity": -500, "ts": 1756428275.218146, "side": "sell"}
{"type": "orderbook_delta", "seq": 2650, "price": 55, "quantity": 500, "ts": 1756428275.248829, "side": "buy"}
{"type": "orderbook_delta", "seq": 2651, "price": 61, "quantity": 500, "ts": 1756428275.253238, "side": "sell"}
{"type": "orderbook_delta", "seq": 2652, "price": 64, "quantity": -200, "ts": 1756428275.525522, "side": "sell"}
{"type": "orderbook_delta", "seq": 2653, "price": 53, "quantity": -200, "ts": 1756428275.527151, "side": "buy"}
{"type": "orderbook_delta", "seq": 2654, "price": 51, "quantity": -1250, "ts": 1756428275.528063, "side": "buy"}
{"type": "orderbook_delta", "seq": 2655, "price": 66, "quantity": -1250, "ts": 1756428275.535354, "side": "sell"}
{"type": "orderbook_delta", "seq": 2656, "price": 55, "quantity": -500, "ts": 1756428275.567182, "side": "buy"}
{"type": "orderbook_delta", "seq": 2657, "price": 50, "quantity": 1250, "ts": 1756428275.571497, "side": "buy"}
{"type": "orderbook_delta", "seq": 2658, "price": 51, "quantity": 200, "ts": 1756428275.572193, "side": "buy"}
{"type": "orderbook_delta", "seq": 2659, "price": 63, "quantity": 200, "ts": 1756428275.572448, "side": "sell"}
{"type": "orderbook_delta", "seq": 2660, "price": 64, "quantity": 1250, "ts": 1756428275.576537, "side": "sell"}
{"type": "orderbook_delta", "seq": 2661, "price": 60, "quantity": -127, "ts": 1756428275.602716, "side": "buy"}
{"type": "orderbook_delta", "seq": 2662, "price": 54, "quantity": 500, "ts": 1756428275.608998, "side": "buy"}
{"type": "orderbook_delta", "seq": 2663, "price": 61, "quantity": -500, "ts": 1756428275.633343, "side": "sell"}
{"type": "orderbook_delta", "seq": 2664, "price": 46, "quantity": 250, "ts": 1756428275.638809, "side": "buy"}
{"type": "orderbook_delta", "seq": 2665, "price": 56, "quantity": -250, "ts": 1756428275.639359, "side": "buy"}
{"type": "orderbook_delta", "seq": 2666, "price": 65, "quantity": -200, "ts": 1756428275.64954, "side": "sell"}
{"type": "orderbook_delta", "seq": 2667, "price": 63, "quantity": 200, "ts": 1756428275.64954, "side": "sell"}
{"type": "orderbook_delta", "seq": 2668, "price": 63, "quantity": -200, "ts": 1756428275.686176, "side": "sell"}
{"type": "orderbook_delta", "seq": 2669, "price": 60, "quantity": 500, "ts": 1756428275.695632, "side": "sell"}
{"type": "orderbook_delta", "seq": 2670, "price": 62, "quantity": 200, "ts": 1756428275.741172, "side": "sell"}
{"type": "orderbook_delta", "seq": 2671, "price": 61, "quantity": -190, "ts": 1756428276.102881, "side": "sell"}
{"type": "orderbook_delta", "seq": 2672, "price": 60, "quantity": -500, "ts": 1756428276.132548, "side": "sell"}
{"type": "orderbook_delta", "seq": 2673, "price": 60, "quantity": 190, "ts": 1756428276.139492, "side": "sell"}
{"type": "orderbook_delta", "seq": 2674, "price": 62, "quantity": 500, "ts": 1756428276.170762, "side": "sell"}
{"type": "orderbook_delta", "seq": 2675, "price": 62, "quantity": -500, "ts": 1756428276.222979, "side": "sell"}
{"type": "orderbook_delta", "seq": 2676, "price": 60, "quantity": 500, "ts": 1756428276.266073, "side": "sell"}
{"type": "orderbook_delta", "seq": 2677, "price": 55, "quantity": 127, "ts": 1756428276.357507, "side": "buy"}
{"type": "orderbook_delta", "seq": 2678, "price": 72, "quantity": -250, "ts": 1756428277.106121, "side": "sell"}
{"type": "orderbook_delta", "seq": 2679, "price": 62, "quantity": 250, "ts": 1756428277.106351, "side": "sell"}
{"type": "orderbook_delta", "seq": 2680, "price": 50, "quantity": -1250, "ts": 1756428277.209232, "side": "buy"}
{"type": "orderbook_delta", "seq": 2681, "price": 49, "quantity": 1250, "ts": 1756428277.258801, "side": "buy"}
{"type": "orderbook_delta", "seq": 2682, "price": 59, "quantity": 100, "ts": 1756428277.331332, "side": "sell"}
{"type": "orderbook_delta", "seq": 2683, "price": 60, "quantity": -500, "ts": 1756428277.490122, "side": "sell"}
{"type": "orderbook_delta", "seq": 2684, "price": 59, "quantity": 500, "ts": 1756428277.529824, "side": "sell"}
{"type": "orderbook_delta", "seq": 2685, "price": 7, "quantity": -2777, "ts": 1756428277.645387, "side": "buy"}
{"type": "orderbook_delta", "seq": 2686, "price": 11, "quantity": 1767, "ts": 1756428277.645387, "side": "buy"}
{"type": "orderbook_delta", "seq": 2687, "price": 55, "quantity": -127, "ts": 1756428278.343889, "side": "buy"}
{"type": "orderbook_delta", "seq": 2688, "price": 56, "quantity": 127, "ts": 1756428278.570049, "side": "buy"}
{"type": "orderbook_delta", "seq": 2689, "price": 60, "quantity": -190, "ts": 1756428279.1076, "side": "sell"}
{"type": "orderbook_delta", "seq": 2690, "price": 59, "quantity": -500, "ts": 1756428279.162182, "side": "sell"}
{"type": "orderbook_delta", "seq": 2691, "price": 59, "quantity": 190, "ts": 1756428279.171557, "side": "sell"}
{"type": "orderbook_delta", "seq": 2692, "price": 61, "quantity": 500, "ts": 1756428279.268194, "side": "sell"}
{"type": "orderbook_delta", "seq": 2693, "price": 56, "quantity": -127, "ts": 1756428279.311504, "side": "buy"}
{"type": "orderbook_delta", "seq": 2694, "price": 55, "quantity": 127, "ts": 1756428279.516769, "side": "buy"}
{"type": "orderbook_delta", "seq": 2695, "price": 55, "quantity": -127, "ts": 1756428280.293646, "side": "buy"}
{"type": "orderbook_delta", "seq": 2696, "price": 56, "quantity": 127, "ts": 1756428280.494603, "side": "buy"}
{"type": "orderbook_delta", "seq": 2697, "price": 61, "quantity": -500, "ts": 1756428281.092773, "side": "sell"}
{"type": "orderbook_delta", "seq": 2698, "price": 54, "quantity": -500, "ts": 1756428281.09745, "side": "buy"}
{"type": "orderbook_delta", "seq": 2699, "price": 59, "quantity": -190, "ts": 1756428281.104337, "side": "sell"}
{"type": "orderbook_delta", "seq": 2700, "price": 53, "quantity": 500, "ts": 1756428281.129854, "side": "buy"}
{"type": "orderbook_delta", "seq": 2701, "price": 60, "quantity": 190, "ts": 1756428281.140418, "side": "sell"}
{"type": "orderbook_delta", "seq": 2702, "price": 59, "quantity": 500, "ts": 1756428281.141217, "side": "sell"}
{"type": "orderbook_delta", "seq": 2703, "price": 56, "quantity": -127, "ts": 1756428281.767868, "side": "buy"}
{"type": "orderbook_delta", "seq": 2704, "price": 55, "quantity": 127, "ts": 1756428281.977323, "side": "buy"}
{"type": "orderbook_delta", "seq": 2705, "price": 49, "quantity": -1250, "ts": 1756428283.018201, "side": "buy"}
{"type": "orderbook_delta", "seq": 2706, "price": 53, "quantity": -500, "ts": 1756428283.018372, "side": "buy"}
{"type": "orderbook_delta", "seq": 2707, "price": 51, "quantity": -200, "ts": 1756428283.019033, "side": "buy"}
{"type": "orderbook_delta", "seq": 2708, "price": 59, "quantity": -500, "ts": 1756428283.020273, "side": "sell"}
{"type": "orderbook_delta", "seq": 2709, "price": 64, "quantity": -1250, "ts": 1756428283.021049, "side": "sell"}
{"type": "orderbook_delta", "seq": 2710, "price": 62, "quantity": -200, "ts": 1756428283.021407, "side": "sell"}
{"type": "orderbook_delta", "seq": 2711, "price": 52, "quantity": 500, "ts": 1756428283.057239, "side": "buy"}
{"type": "orderbook_delta", "seq": 2712, "price": 58, "quantity": 500, "ts": 1756428283.057941, "side": "sell"}
{"type": "orderbook_delta", "seq": 2713, "price": 50, "quantity": 200, "ts": 1756428283.061071, "side": "buy"}
{"type": "orderbook_delta", "seq": 2714, "price": 61, "quantity": 200, "ts": 1756428283.06139, "side": "sell"}
{"type": "orderbook_delta", "seq": 2715, "price": 63, "quantity": 1250, "ts": 1756428283.081034, "side": "sell"}
{"type": "orderbook_delta", "seq": 2716, "price": 48, "quantity": 1250, "ts": 1756428283.082514, "side": "buy"}
{"type": "orderbook_delta", "seq": 2717, "price": 63, "quantity": -200, "ts": 1756428283.085262, "side": "sell"}
{"type": "orderbook_delta", "seq": 2718, "price": 62, "quantity": 200, "ts": 1756428283.085262, "side": "sell"}
{"type": "orderbook_delta", "seq": 2719, "price": 50, "quantity": -200, "ts": 1756428283.608425, "side": "buy"}
{"type": "orderbook_delta", "seq": 2720, "price": 63, "quantity": -1250, "ts": 1756428283.612274, "side": "sell"}
{"type": "orderbook_delta", "seq": 2721, "price": 61, "quantity": -200, "ts": 1756428283.619835, "side": "sell"}
{"type": "orderbook_delta", "seq": 2722, "price": 48, "quantity": -1250, "ts": 1756428283.643614, "side": "buy"}
{"type": "orderbook_delta", "seq": 2723, "price": 62, "quantity": 1250, "ts": 1756428283.677514, "side": "sell"}
{"type": "orderbook_delta", "seq": 2724, "price": 49, "quantity": 200, "ts": 1756428283.677885, "side": "buy"}
{"type": "orderbook_delta", "seq": 2725, "price": 47, "quantity": 1250, "ts": 1756428283.678216, "side": "buy"}
{"type": "orderbook_delta", "seq": 2726, "price": 60, "quantity": 200, "ts": 1756428283.679936, "side": "sell"}
{"type": "orderbook_delta", "seq": 2727, "price": 62, "quantity": -200, "ts": 1756428283.719661, "side": "sell"}
{"type": "orderbook_delta", "seq": 2728, "price": 61, "quantity": 200, "ts": 1756428283.719661, "side": "sell"}
{"type": "orderbook_delta", "seq": 2729, "price": 52, "quantity": -250, "ts": 1756428283.911623, "side": "buy"}
{"type": "orderbook_delta", "seq": 2730, "price": 62, "quantity": -1250, "ts": 1756428283.914705, "side": "sell"}
{"type": "orderbook_delta", "seq": 2731, "price": 49, "quantity": -200, "ts": 1756428283.916324, "side": "buy"}
{"type": "orderbook_delta", "seq": 2732, "price": 47, "quantity": -1250, "ts": 1756428283.916451, "side": "buy"}
{"type": "orderbook_delta", "seq": 2733, "price": 60, "quantity": -200, "ts": 1756428283.917542, "side": "sell"}
{"type": "orderbook_delta", "seq": 2734, "price": 52, "quantity": -500, "ts": 1756428283.919602, "side": "buy"}
{"type": "orderbook_delta", "seq": 2735, "price": 54, "quantity": -250, "ts": 1756428283.926045, "side": "buy"}
{"type": "orderbook_delta", "seq": 2736, "price": 61, "quantity": 1250, "ts": 1756428283.973242, "side": "sell"}
{"type": "orderbook_delta", "seq": 2737, "price": 59, "quantity": 200, "ts": 1756428283.973893, "side": "sell"}
{"type": "orderbook_delta", "seq": 2738, "price": 48, "quantity": 200, "ts": 1756428283.974996, "side": "buy"}
{"type": "orderbook_delta", "seq": 2739, "price": 51, "quantity": 500, "ts": 1756428283.975535, "side": "buy"}
{"type": "orderbook_delta", "seq": 2740, "price": 42, "quantity": 250, "ts": 1756428283.976554, "side": "buy"}
{"type": "orderbook_delta", "seq": 2741, "price": 46, "quantity": 1250, "ts": 1756428283.980137, "side": "buy"}
{"type": "orderbook_delta", "seq": 2742, "price": 50, "quantity": -250, "ts": 1756428283.999919, "side": "buy"}
{"type": "orderbook_delta", "seq": 2743, "price": 44, "quantity": 250, "ts": 1756428284.000588, "side": "buy"}
{"type": "orderbook_delta", "seq": 2744, "price": 40, "quantity": 250, "ts": 1756428284.005654, "side": "buy"}
{"type": "orderbook_delta", "seq": 2745, "price": 51, "quantity": -500, "ts": 1756428284.035385, "side": "buy"}
{"type": "orderbook_delta", "seq": 2746, "price": 49, "quantity": 500, "ts": 1756428284.07801, "side": "buy"}
{"type": "orderbook_delta", "seq": 2747, "price": 60, "quantity": -190, "ts": 1756428284.154118, "side": "sell"}
{"type": "orderbook_delta", "seq": 2748, "price": 40, "quantity": -250, "ts": 1756428284.166704, "side": "buy"}
{"type": "orderbook_delta", "seq": 2749, "price": 46, "quantity": -1250, "ts": 1756428284.176217, "side": "buy"}
{"type": "orderbook_delta", "seq": 2750, "price": 61, "quantity": -1250, "ts": 1756428284.177101, "side": "sell"}
{"type": "orderbook_delta", "seq": 2751, "price": 48, "quantity": -200, "ts": 1756428284.17833, "side": "buy"}
{"type": "orderbook_delta", "seq": 2752, "price": 59, "quantity": -200, "ts": 1756428284.187149, "side": "sell"}
{"type": "orderbook_delta", "seq": 2753, "price": 70, "quantity": -250, "ts": 1756428284.197373, "side": "sell"}
{"type": "orderbook_delta", "seq": 2754, "price": 60, "quantity": 250, "ts": 1756428284.19849, "side": "sell"}
{"type": "orderbook_delta", "seq": 2755, "price": 61, "quantity": -200, "ts": 1756428284.205621, "side": "sell"}
{"type": "orderbook_delta", "seq": 2756, "price": 59, "quantity": 200, "ts": 1756428284.205621, "side": "sell"}
{"type": "orderbook_delta", "seq": 2757, "price": 68, "quantity": -250, "ts": 1756428284.236937, "side": "sell"}
{"type": "orderbook_delta", "seq": 2758, "price": 58, "quantity": 250, "ts": 1756428284.237411, "side": "sell"}
{"type": "orderbook_delta", "seq": 2759, "price": 59, "quantity": 200, "ts": 1756428284.240941, "side": "sell"}
{"type": "orderbook_delta", "seq": 2760, "price": 60, "quantity": 1250, "ts": 1756428284.241224, "side": "sell"}
{"type": "orderbook_delta", "seq": 2761, "price": 47, "quantity": 200, "ts": 1756428284.241864, "side": "buy"}
{"type": "orderbook_delta", "seq": 2762, "price": 45, "quantity": 1250, "ts": 1756428284.246897, "side": "buy"}
{"type": "orderbook_delta", "seq": 2763, "price": 58, "quantity": -500, "ts": 1756428284.272157, "side": "sell"}
{"type": "orderbook_delta", "seq": 2764, "price": 50, "quantity": 250, "ts": 1756428284.276426, "side": "buy"}
{"type": "orderbook_delta", "seq": 2765, "price": 57, "quantity": 190, "ts": 1756428284.284788, "side": "sell"}
{"type": "orderbook_delta", "seq": 2766, "price": 59, "quantity": -200, "ts": 1756428284.286092, "side": "sell"}
{"type": "orderbook_delta", "seq": 2767, "price": 57, "quantity": 500, "ts": 1756428284.304892, "side": "sell"}
{"type": "orderbook_delta", "seq": 2768, "price": 49, "quantity": -500, "ts": 1756428284.330569, "side": "buy"}
{"type": "orderbook_delta", "seq": 2769, "price": 58, "quantity": 200, "ts": 1756428284.331324, "side": "sell"}
{"type": "orderbook_delta", "seq": 2770, "price": 57, "quantity": -500, "ts": 1756428284.358321, "side": "sell"}
{"type": "orderbook_delta", "seq": 2771, "price": 50, "quantity": 500, "ts": 1756428284.372293, "side": "buy"}
{"type": "orderbook_delta", "seq": 2772, "price": 56, "quantity": 500, "ts": 1756428284.422936, "side": "sell"}
{"type": "orderbook_delta", "seq": 2773, "price": 59, "quantity": -100, "ts": 1756428284.532753, "side": "sell"}
{"type": "orderbook_delta", "seq": 2774, "price": 58, "quantity": 100, "ts": 1756428284.729028, "side": "sell"}
{"type": "orderbook_delta", "seq": 2775, "price": 11, "quantity": -1767, "ts": 1756428285.1073, "side": "buy"}
{"type": "orderbook_delta", "seq": 2776, "price": 7, "quantity": 2777, "ts": 1756428285.1073, "side": "buy"}
{"type": "orderbook_delta", "seq": 2777, "price": 45, "quantity": -1250, "ts": 1756428285.1386, "side": "buy"}
{"type": "orderbook_delta", "seq": 2778, "price": 58, "quantity": -200, "ts": 1756428285.139301, "side": "sell"}
{"type": "orderbook_delta", "seq": 2779, "price": 47, "quantity": -200, "ts": 1756428285.141476, "side": "buy"}
{"type": "orderbook_delta", "seq": 2780, "price": 60, "quantity": -1250, "ts": 1756428285.148836, "side": "sell"}
{"type": "orderbook_delta", "seq": 2781, "price": 61, "quantity": 1250, "ts": 1756428285.198553, "side": "sell"}
{"type": "orderbook_delta", "seq": 2782, "price": 46, "quantity": 1250, "ts": 1756428285.199133, "side": "buy"}
{"type": "orderbook_delta", "seq": 2783, "price": 59, "quantity": 200, "ts": 1756428285.201236, "side": "sell"}
{"type": "orderbook_delta", "seq": 2784, "price": 48, "quantity": 200, "ts": 1756428285.209332, "side": "buy"}
{"type": "orderbook_delta", "seq": 2785, "price": 58, "quantity": -100, "ts": 1756428285.460747, "side": "sell"}
{"type": "orderbook_delta", "seq": 2786, "price": 40, "quantity": 250, "ts": 1756428286.118763, "side": "buy"}
{"type": "trade", "seq": 32, "price": 55, "quantity": 127, "ts": 1756428286.122007, "side": "sell"}
{"type": "orderbook_delta", "seq": 2787, "price": 46, "quantity": -1250, "ts": 1756428286.122007, "side": "buy"}
{"type": "orderbook_delta", "seq": 2788, "price": 50, "quantity": -250, "ts": 1756428286.122536, "side": "buy"}
{"type": "orderbook_delta", "seq": 2789, "price": 61, "quantity": -1250, "ts": 1756428286.124731, "side": "sell"}
{"type": "orderbook_delta", "seq": 2790, "price": 48, "quantity": -200, "ts": 1756428286.12484, "side": "buy"}
{"type": "orderbook_delta", "seq": 2791, "price": 50, "quantity": -500, "ts": 1756428286.125762, "side": "buy"}
{"type": "orderbook_delta", "seq": 2792, "price": 30, "quantity": -200, "ts": 1756428286.130759, "side": "buy"}
{"type": "orderbook_delta", "seq": 2793, "price": 20, "quantity": 200, "ts": 1756428286.130759, "side": "buy"}
{"type": "orderbook_delta", "seq": 2794, "price": 59, "quantity": -200, "ts": 1756428286.134706, "side": "sell"}
{"type": "orderbook_delta", "seq": 2795, "price": 56, "quantity": -500, "ts": 1756428286.135341, "side": "sell"}
{"type": "orderbook_delta", "seq": 2796, "price": 57, "quantity": -190, "ts": 1756428286.13661, "side": "sell"}
{"type": "orderbook_delta", "seq": 2797, "price": 56, "quantity": 250, "ts": 1756428286.141145, "side": "sell"}
{"type": "orderbook_delta", "seq": 2798, "price": 66, "quantity": -250, "ts": 1756428286.156598, "side": "sell"}
{"type": "orderbook_delta", "seq": 2799, "price": 55, "quantity": 0, "ts": 1756428286.160865, "side": "buy"}
{"type": "orderbook_delta", "seq": 2800, "price": 48, "quantity": -250, "ts": 1756428286.18021, "side": "buy"}
{"type": "orderbook_delta", "seq": 2801, "price": 38, "quantity": 250, "ts": 1756428286.182057, "side": "buy"}
{"type": "orderbook_delta", "seq": 2802, "price": 56, "quantity": -250, "ts": 1756428286.208498, "side": "sell"}
{"type": "orderbook_delta", "seq": 2803, "price": 54, "quantity": 190, "ts": 1756428286.232415, "side": "sell"}
{"type": "orderbook_delta", "seq": 2804, "price": 59, "quantity": -200, "ts": 1756428286.379949, "side": "sell"}
{"type": "orderbook_delta", "seq": 2805, "price": 57, "quantity": 200, "ts": 1756428286.379949, "side": "sell"}
{"type": "orderbook_delta", "seq": 2806, "price": 54, "quantity": -190, "ts": 1756428287.156239, "side": "sell"}
{"type": "orderbook_delta", "seq": 2807, "price": 36, "quantity": 250, "ts": 1756428287.158366, "side": "buy"}
{"type": "orderbook_delta", "seq": 2808, "price": 46, "quantity": -250, "ts": 1756428287.176299, "side": "buy"}
{"type": "orderbook_delta", "seq": 2809, "price": 53, "quantity": 190, "ts": 1756428287.218568, "side": "sell"}
{"type": "orderbook_delta", "seq": 2810, "price": 7, "quantity": -2777, "ts": 1756428287.626544, "side": "buy"}
{"type": "orderbook_delta", "seq": 2811, "price": 1, "quantity": 19440, "ts": 1756428287.626544, "side": "buy"}
{"type": "orderbook_delta", "seq": 2812, "price": 2, "quantity": 7000, "ts": 1756428287.923966, "side": "buy"}
{"type": "orderbook_delta", "seq": 2813, "price": 47, "quantity": 127, "ts": 1756428288.060287, "side": "buy"}
{"type": "orderbook_delta", "seq": 2814, "price": 45, "quantity": 500, "ts": 1756428288.40658, "side": "buy"}
{"type": "orderbook_delta", "seq": 2815, "price": 56, "quantity": 200, "ts": 1756428288.406901, "side": "sell"}
{"type": "orderbook_delta", "seq": 2816, "price": 56, "quantity": 1250, "ts": 1756428288.408602, "side": "sell"}
{"type": "orderbook_delta", "seq": 2817, "price": 43, "quantity": 200, "ts": 1756428288.409948, "side": "buy"}
{"type": "orderbook_delta", "seq": 2818, "price": 41, "quantity": 1250, "ts": 1756428288.410837, "side": "buy"}
{"type": "orderbook_delta", "seq": 2819, "price": 52, "quantity": 500, "ts": 1756428288.440742, "side": "sell"}
{"type": "orderbook_delta", "seq": 2820, "price": 36, "quantity": -250, "ts": 1756428288.478198, "side": "buy"}
{"type": "orderbook_delta", "seq": 2821, "price": 46, "quantity": 250, "ts": 1756428288.480041, "side": "buy"}
{"type": "orderbook_delta", "seq": 2822, "price": 56, "quantity": 250, "ts": 1756428288.506718, "side": "sell"}
{"type": "orderbook_delta", "seq": 2823, "price": 45, "quantity": -500, "ts": 1756428288.593481, "side": "buy"}
{"type": "orderbook_delta", "seq": 2824, "price": 1, "quantity": -19440, "ts": 1756428288.593949, "side": "buy"}
{"type": "orderbook_delta", "seq": 2825, "price": 3, "quantity": 6480, "ts": 1756428288.593949, "side": "buy"}
{"type": "orderbook_delta", "seq": 2826, "price": 56, "quantity": -200, "ts": 1756428288.595166, "side": "sell"}
{"type": "orderbook_delta", "seq": 2827, "price": 46, "quantity": 500, "ts": 1756428288.627999, "side": "buy"}
{"type": "orderbook_delta", "seq": 2828, "price": 2, "quantity": -7000, "ts": 1756428288.628397, "side": "buy"}
{"type": "orderbook_delta", "seq": 2829, "price": 55, "quantity": 200, "ts": 1756428288.646083, "side": "sell"}
{"type": "orderbook_delta", "seq": 2830, "price": 4, "quantity": 7000, "ts": 1756428288.667359, "side": "buy"}
{"type": "orderbook_delta", "seq": 2831, "price": 54, "quantity": 250, "ts": 1756428289.111623, "side": "sell"}
{"type": "orderbook_delta", "seq": 2832, "price": 53, "quantity": -190, "ts": 1756428289.112376, "side": "sell"}
{"type": "orderbook_delta", "seq": 2833, "price": 64, "quantity": -250, "ts": 1756428289.126848, "side": "sell"}
{"type": "orderbook_delta", "seq": 2834, "price": 55, "quantity": -200, "ts": 1756428289.142103, "side": "sell"}
{"type": "orderbook_delta", "seq": 2835, "price": 52, "quantity": -500, "ts": 1756428289.142849, "side": "sell"}
{"type": "orderbook_delta", "seq": 2836, "price": 46, "quantity": -500, "ts": 1756428289.165076, "side": "buy"}
{"type": "orderbook_delta", "seq": 2837, "price": 52, "quantity": 190, "ts": 1756428289.16879, "side": "sell"}
{"type": "orderbook_delta", "seq": 2838, "price": 53, "quantity": 500, "ts": 1756428289.176288, "side": "sell"}
{"type": "orderbook_delta", "seq": 2839, "price": 54, "quantity": 200, "ts": 1756428289.178422, "side": "sell"}
{"type": "orderbook_delta", "seq": 2840, "price": 57, "quantity": -200, "ts": 1756428289.192639, "side": "sell"}
{"type": "orderbook_delta", "seq": 2841, "price": 53, "quantity": 200, "ts": 1756428289.192639, "side": "sell"}
{"type": "orderbook_delta", "seq": 2842, "price": 36, "quantity": 250, "ts": 1756428289.207616, "side": "buy"}
{"type": "orderbook_delta", "seq": 2843, "price": 46, "quantity": -250, "ts": 1756428289.2085, "side": "buy"}
{"type": "orderbook_delta", "seq": 2844, "price": 45, "quantity": 500, "ts": 1756428289.217535, "side": "buy"}
{"type": "orderbook_delta", "seq": 2845, "price": 53, "quantity": -500, "ts": 1756428289.277762, "side": "sell"}
{"type": "orderbook_delta", "seq": 2846, "price": 51, "quantity": 500, "ts": 1756428289.318199, "side": "sell"}
{"type": "orderbook_delta", "seq": 2847, "price": 46, "quantity": 250, "ts": 1756428289.357684, "side": "buy"}
{"type": "orderbook_delta", "seq": 2848, "price": 36, "quantity": -250, "ts": 1756428289.36066, "side": "buy"}
{"type": "orderbook_delta", "seq": 2849, "price": 52, "quantity": -190, "ts": 1756428291.099381, "side": "sell"}
{"type": "orderbook_delta", "seq": 2850, "price": 64, "quantity": 250, "ts": 1756428291.102298, "side": "sell"}
{"type": "orderbook_delta", "seq": 2851, "price": 54, "quantity": -250, "ts": 1756428291.117042, "side": "sell"}
{"type": "orderbook_delta", "seq": 2852, "price": 51, "quantity": -500, "ts": 1756428291.152946, "side": "sell"}
{"type": "orderbook_delta", "seq": 2853, "price": 54, "quantity": -200, "ts": 1756428291.153468, "side": "sell"}
{"type": "orderbook_delta", "seq": 2854, "price": 53, "quantity": 190, "ts": 1756428291.162357, "side": "sell"}
{"type": "orderbook_delta", "seq": 2855, "price": 52, "quantity": 500, "ts": 1756428291.198093, "side": "sell"}
{"type": "orderbook_delta", "seq": 2856, "price": 55, "quantity": 200, "ts": 1756428291.198459, "side": "sell"}
{"type": "orderbook_delta", "seq": 2857, "price": 45, "quantity": -500, "ts": 1756428291.21136, "side": "buy"}
{"type": "orderbook_delta", "seq": 2858, "price": 46, "quantity": 500, "ts": 1756428291.246667, "side": "buy"}
{"type": "orderbook_delta", "seq": 2859, "price": 47, "quantity": -127, "ts": 1756428291.453569, "side": "buy"}
{"type": "orderbook_delta", "seq": 2860, "price": 47, "quantity": 100, "ts": 1756428291.656864, "side": "buy"}
{"type": "orderbook_delta", "seq": 2861, "price": 47, "quantity": -100, "ts": 1756428292.396205, "side": "buy"}
{"type": "orderbook_delta", "seq": 2862, "price": 48, "quantity": 100, "ts": 1756428292.596752, "side": "buy"}
{"type": "orderbook_delta", "seq": 2863, "price": 3, "quantity": -6480, "ts": 1756428292.880001, "side": "buy"}
{"type": "orderbook_delta", "seq": 2864, "price": 4, "quantity": 4860, "ts": 1756428292.880001, "side": "buy"}
{"type": "orderbook_delta", "seq": 2865, "price": 4, "quantity": -7000, "ts": 1756428292.919521, "side": "buy"}
{"type": "orderbook_delta", "seq": 2866, "price": 5, "quantity": 7000, "ts": 1756428292.961813, "side": "buy"}
{"type": "orderbook_delta", "seq": 2867, "price": 53, "quantity": -190, "ts": 1756428293.146368, "side": "sell"}
{"type": "orderbook_delta", "seq": 2868, "price": 54, "quantity": 250, "ts": 1756428293.149099, "side": "sell"}
{"type": "orderbook_delta", "seq": 2869, "price": 64, "quantity": -250, "ts": 1756428293.166803, "side": "sell"}
{"type": "orderbook_delta", "seq": 2870, "price": 55, "quantity": -200, "ts": 1756428293.186658, "side": "sell"}
{"type": "orderbook_delta", "seq": 2871, "price": 51, "quantity": 190, "ts": 1756428293.208518, "side": "sell"}
{"type": "orderbook_delta", "seq": 2872, "price": 54, "quantity": 200, "ts": 1756428293.227186, "side": "sell"}
{"type": "orderbook_delta", "seq": 2873, "price": 51, "quantity": 100, "ts": 1756428293.453983, "side": "sell"}
{"type": "orderbook_delta", "seq": 2874, "price": 52, "quantity": -500, "ts": 1756428293.579112, "side": "sell"}
{"type": "orderbook_delta", "seq": 2875, "price": 46, "quantity": -500, "ts": 1756428293.58321, "side": "buy"}
{"type": "orderbook_delta", "seq": 2876, "price": 45, "quantity": 500, "ts": 1756428293.619535, "side": "buy"}
{"type": "orderbook_delta", "seq": 2877, "price": 51, "quantity": 500, "ts": 1756428293.622203, "side": "sell"}
{"type": "orderbook_delta", "seq": 2878, "price": 43, "quantity": -200, "ts": 1756428293.864625, "side": "buy"}
{"type": "orderbook_delta", "seq": 2879, "price": 54, "quantity": -200, "ts": 1756428293.867221, "side": "sell"}
{"type": "orderbook_delta", "seq": 2880, "price": 41, "quantity": -1250, "ts": 1756428293.868105, "side": "buy"}
{"type": "orderbook_delta", "seq": 2881, "price": 56, "quantity": -1250, "ts": 1756428293.869039, "side": "sell"}
{"type": "orderbook_delta", "seq": 2882, "price": 40, "quantity": 1250, "ts": 1756428293.920394, "side": "buy"}
{"type": "orderbook_delta", "seq": 2883, "price": 55, "quantity": 1250, "ts": 1756428293.923216, "side": "sell"}
{"type": "orderbook_delta", "seq": 2884, "price": 53, "quantity": 200, "ts": 1756428293.923995, "side": "sell"}
{"type": "orderbook_delta", "seq": 2885, "price": 42, "quantity": 200, "ts": 1756428293.924395, "side": "buy"}
{"type": "orderbook_delta", "seq": 2886, "price": 46, "quantity": -250, "ts": 1756428294.270608, "side": "buy"}
{"type": "orderbook_delta", "seq": 2887, "price": 36, "quantity": 250, "ts": 1756428294.295314, "side": "buy"}
{"type": "orderbook_delta", "seq": 2888, "price": 42, "quantity": -200, "ts": 1756428295.829809, "side": "buy"}
{"type": "orderbook_delta", "seq": 2889, "price": 40, "quantity": -1250, "ts": 1756428295.829944, "side": "buy"}
{"type": "orderbook_delta", "seq": 2890, "price": 55, "quantity": -1250, "ts": 1756428295.83114, "side": "sell"}
{"type": "orderbook_delta", "seq": 2891, "price": 53, "quantity": -200, "ts": 1756428295.834667, "side": "sell"}
{"type": "orderbook_delta", "seq": 2892, "price": 54, "quantity": 200, "ts": 1756428295.864879, "side": "sell"}
{"type": "orderbook_delta", "seq": 2893, "price": 41, "quantity": 1250, "ts": 1756428295.867048, "side": "buy"}
{"type": "orderbook_delta", "seq": 2894, "price": 56, "quantity": 1250, "ts": 1756428295.871923, "side": "sell"}
{"type": "orderbook_delta", "seq": 2895, "price": 43, "quantity": 200, "ts": 1756428295.875111, "side": "buy"}
{"type": "orderbook_delta", "seq": 2896, "price": 4, "quantity": -4860, "ts": 1756428295.92762, "side": "buy"}
{"type": "orderbook_delta", "seq": 2897, "price": 1, "quantity": 19440, "ts": 1756428295.92762, "side": "buy"}
{"type": "orderbook_delta", "seq": 2898, "price": 5, "quantity": -7000, "ts": 1756428295.970533, "side": "buy"}
{"type": "orderbook_delta", "seq": 2899, "price": 2, "quantity": 7000, "ts": 1756428296.008767, "side": "buy"}
{"type": "orderbook_delta", "seq": 2900, "price": 56, "quantity": -1250, "ts": 1756428296.364261, "side": "sell"}
{"type": "orderbook_delta", "seq": 2901, "price": 45, "quantity": -500, "ts": 1756428296.364585, "side": "buy"}
{"type": "orderbook_delta", "seq": 2902, "price": 41, "quantity": -1250, "ts": 1756428296.364799, "side": "buy"}
{"type": "orderbook_delta", "seq": 2903, "price": 54, "quantity": -200, "ts": 1756428296.365744, "side": "sell"}
{"type": "orderbook_delta", "seq": 2904, "price": 43, "quantity": -200, "ts": 1756428296.370608, "side": "buy"}
{"type": "orderbook_delta", "seq": 2905, "price": 51, "quantity": -500, "ts": 1756428296.378529, "side": "sell"}
{"type": "orderbook_delta", "seq": 2906, "price": 53, "quantity": -200, "ts": 1756428296.386724, "side": "sell"}
{"type": "orderbook_delta", "seq": 2907, "price": 51, "quantity": 200, "ts": 1756428296.386724, "side": "sell"}
{"type": "orderbook_delta", "seq": 2908, "price": 52, "quantity": 200, "ts": 1756428296.42642, "side": "sell"}
{"type": "orderbook_delta", "seq": 2909, "price": 43, "quantity": 500, "ts": 1756428296.427248, "side": "buy"}
{"type": "orderbook_delta", "seq": 2910, "price": 39, "quantity": 1250, "ts": 1756428296.427516, "side": "buy"}
{"type": "orderbook_delta", "seq": 2911, "price": 41, "quantity": 200, "ts": 1756428296.428484, "side": "buy"}
{"type": "orderbook_delta", "seq": 2912, "price": 53, "quantity": 1250, "ts": 1756428296.428884, "side": "sell"}
{"type": "orderbook_delta", "seq": 2913, "price": 50, "quantity": 500, "ts": 1756428296.478123, "side": "sell"}
{"type": "orderbook_delta", "seq": 2914, "price": 52, "quantity": -200, "ts": 1756428296.495972, "side": "sell"}
{"type": "orderbook_delta", "seq": 2915, "price": 51, "quantity": -200, "ts": 1756428296.522642, "side": "sell"}
{"type": "orderbook_delta", "seq": 2916, "price": 49, "quantity": 200, "ts": 1756428296.522642, "side": "sell"}
{"type": "orderbook_delta", "seq": 2917, "price": 53, "quantity": 200, "ts": 1756428296.545017, "side": "sell"}
{"type": "orderbook_delta", "seq": 2918, "price": 50, "quantity": -500, "ts": 1756428296.594703, "side": "sell"}
{"type": "orderbook_delta", "seq": 2919, "price": 49, "quantity": 500, "ts": 1756428296.630564, "side": "sell"}
{"type": "orderbook_delta", "seq": 2920, "price": 44, "quantity": -250, "ts": 1756428296.76887, "side": "buy"}
{"type": "orderbook_delta", "seq": 2921, "price": 34, "quantity": 250, "ts": 1756428296.769982, "side": "buy"}
{"type": "orderbook_delta", "seq": 2922, "price": 53, "quantity": -200, "ts": 1756428296.778702, "side": "sell"}
{"type": "orderbook_delta", "seq": 2923, "price": 39, "quantity": -1250, "ts": 1756428296.77967, "side": "buy"}
{"type": "orderbook_delta", "seq": 2924, "price": 43, "quantity": -500, "ts": 1756428296.779756, "side": "buy"}
{"type": "orderbook_delta", "seq": 2925, "price": 41, "quantity": -200, "ts": 1756428296.781316, "side": "buy"}
{"type": "orderbook_delta", "seq": 2926, "price": 20, "quantity": -200, "ts": 1756428296.815997, "side": "buy"}
{"type": "orderbook_delta", "seq": 2927, "price": 10, "quantity": 200, "ts": 1756428296.815997, "side": "buy"}
{"type": "orderbook_delta", "seq": 2928, "price": 51, "quantity": 200, "ts": 1756428296.838786, "side": "sell"}
{"type": "orderbook_delta", "seq": 2929, "price": 40, "quantity": 200, "ts": 1756428296.839454, "side": "buy"}
{"type": "orderbook_delta", "seq": 2930, "price": 42, "quantity": 500, "ts": 1756428296.839703, "side": "buy"}
{"type": "orderbook_delta", "seq": 2931, "price": 90, "quantity": -200, "ts": 1756428296.855296, "side": "sell"}
{"type": "orderbook_delta", "seq": 2932, "price": 80, "quantity": 200, "ts": 1756428296.855296, "side": "sell"}
{"type": "orderbook_delta", "seq": 2933, "price": 89, "quantity": -8000, "ts": 1756428296.890173, "side": "sell"}
{"type": "orderbook_delta", "seq": 2934, "price": 38, "quantity": 1250, "ts": 1756428296.917574, "side": "buy"}
{"type": "orderbook_delta", "seq": 2935, "price": 1, "quantity": -19440, "ts": 1756428296.918345, "side": "buy"}
{"type": "orderbook_delta", "seq": 2936, "price": 2, "quantity": 9720, "ts": 1756428296.918345, "side": "buy"}
{"type": "orderbook_delta", "seq": 2937, "price": 79, "quantity": 8000, "ts": 1756428296.930643, "side": "sell"}
{"type": "orderbook_delta", "seq": 2938, "price": 2, "quantity": -7000, "ts": 1756428296.981408, "side": "buy"}
{"type": "orderbook_delta", "seq": 2939, "price": 3, "quantity": 7000, "ts": 1756428297.045249, "side": "buy"}
{"type": "orderbook_delta", "seq": 2940, "price": 52, "quantity": 250, "ts": 1756428297.210119, "side": "sell"}
{"type": "orderbook_delta", "seq": 2941, "price": 51, "quantity": -190, "ts": 1756428297.21038, "side": "sell"}
{"type": "orderbook_delta", "seq": 2942, "price": 62, "quantity": -250, "ts": 1756428297.228881, "side": "sell"}
{"type": "orderbook_delta", "seq": 2943, "price": 49, "quantity": 190, "ts": 1756428297.272005, "side": "sell"}
{"type": "orderbook_delta", "seq": 2944, "price": 48, "quantity": -100, "ts": 1756428297.406376, "side": "buy"}
{"type": "orderbook_delta", "seq": 2945, "price": 49, "quantity": -500, "ts": 1756428297.445644, "side": "sell"}
{"type": "orderbook_delta", "seq": 2946, "price": 48, "quantity": 500, "ts": 1756428297.484826, "side": "sell"}
{"type": "orderbook_delta", "seq": 2947, "price": 51, "quantity": -100, "ts": 1756428297.628863, "side": "sell"}
{"type": "orderbook_delta", "seq": 2948, "price": 2, "quantity": -9720, "ts": 1756428297.979687, "side": "buy"}
{"type": "orderbook_delta", "seq": 2949, "price": 1, "quantity": 19440, "ts": 1756428297.979687, "side": "buy"}
{"type": "orderbook_delta", "seq": 2950, "price": 3, "quantity": -7000, "ts": 1756428298.023389, "side": "buy"}
{"type": "orderbook_delta", "seq": 2951, "price": 2, "quantity": 7000, "ts": 1756428298.0807, "side": "buy"}
{"type": "orderbook_delta", "seq": 2952, "price": 49, "quantity": -190, "ts": 1756428298.126546, "side": "sell"}
{"type": "orderbook_delta", "seq": 2953, "price": 44, "quantity": 250, "ts": 1756428298.206548, "side": "buy"}
{"type": "orderbook_delta", "seq": 2954, "price": 34, "quantity": -250, "ts": 1756428298.208886, "side": "buy"}
{"type": "orderbook_delta", "seq": 2955, "price": 50, "quantity": 190, "ts": 1756428298.257499, "side": "sell"}
{"type": "orderbook_delta", "seq": 2956, "price": 43, "quantity": 100, "ts": 1756428298.427755, "side": "buy"}
{"type": "orderbook_delta", "seq": 2957, "price": 1, "quantity": -19440, "ts": 1756428298.843583, "side": "buy"}
{"type": "orderbook_delta", "seq": 2958, "price": 2, "quantity": 9720, "ts": 1756428298.843583, "side": "buy"}
{"type": "orderbook_delta", "seq": 2959, "price": 2, "quantity": -7000, "ts": 1756428298.882653, "side": "buy"}
{"type": "orderbook_delta", "seq": 2960, "price": 3, "quantity": 7000, "ts": 1756428298.922676, "side": "buy"}
{"type": "orderbook_delta", "seq": 2961, "price": 47, "quantity": 100, "ts": 1756428299.207358, "side": "sell"}
{"type": "trade", "seq": 33, "price": 47, "quantity": 80, "ts": 1756428299.269796, "side": "buy"}
{"type": "orderbook_delta", "seq": 2962, "price": 47, "quantity": 0, "ts": 1756428299.269796, "side": "sell"}
{"type": "orderbook_delta", "seq": 2963, "price": 2, "quantity": -9720, "ts": 1756428299.793241, "side": "buy"}
{"type": "orderbook_delta", "seq": 2964, "price": 1, "quantity": 19440, "ts": 1756428299.793241, "side": "buy"}
{"type": "orderbook_delta", "seq": 2965, "price": 3, "quantity": -7000, "ts": 1756428299.844333, "side": "buy"}
{"type": "orderbook_delta", "seq": 2966, "price": 2, "quantity": 7000, "ts": 1756428299.880425, "side": "buy"}
{"type": "orderbook_delta", "seq": 2967, "price": 50, "quantity": -190, "ts": 1756428300.203823, "side": "sell"}
{"type": "orderbook_delta", "seq": 2968, "price": 49, "quantity": 190, "ts": 1756428300.283133, "side": "sell"}
{"type": "orderbook_delta", "seq": 2969, "price": 43, "quantity": -100, "ts": 1756428300.364408, "side": "buy"}
{"type": "orderbook_delta", "seq": 2970, "price": 48, "quantity": -500, "ts": 1756428300.37046, "side": "sell"}
{"type": "orderbook_delta", "seq": 2971, "price": 42, "quantity": -500, "ts": 1756428300.372818, "side": "buy"}
{"type": "orderbook_delta", "seq": 2972, "price": 43, "quantity": 500, "ts": 1756428300.431612, "side": "buy"}
{"type": "orderbook_delta", "seq": 2973, "price": 49, "quantity": 500, "ts": 1756428300.433298, "side": "sell"}
{"type": "orderbook_delta", "seq": 2974, "price": 38, "quantity": -1250, "ts": 1756428300.519123, "side": "buy"}
{"type": "orderbook_delta", "seq": 2975, "price": 51, "quantity": -200, "ts": 1756428300.519256, "side": "sell"}
{"type": "orderbook_delta", "seq": 2976, "price": 53, "quantity": -1250, "ts": 1756428300.522265, "side": "sell"}
{"type": "orderbook_delta", "seq": 2977, "price": 40, "quantity": -200, "ts": 1756428300.532631, "side": "buy"}
{"type": "orderbook_delta", "seq": 2978, "price": 49, "quantity": -200, "ts": 1756428300.533339, "side": "sell"}
{"type": "orderbook_delta", "seq": 2979, "price": 50, "quantity": 200, "ts": 1756428300.533339, "side": "sell"}
{"type": "orderbook_delta", "seq": 2980, "price": 39, "quantity": 1250, "ts": 1756428300.576056, "side": "buy"}
{"type": "orderbook_delta", "seq": 2981, "price": 41, "quantity": 200, "ts": 1756428300.576587, "side": "buy"}
{"type": "orderbook_delta", "seq": 2982, "price": 52, "quantity": 200, "ts": 1756428300.589588, "side": "sell"}
{"type": "orderbook_delta", "seq": 2983, "price": 44, "quantity": 100, "ts": 1756428300.604483, "side": "buy"}
{"type": "orderbook_delta", "seq": 2984, "price": 54, "quantity": 1250, "ts": 1756428300.648427, "side": "sell"}
{"type": "orderbook_delta", "seq": 2985, "price": 49, "quantity": -500, "ts": 1756428301.39403, "side": "sell"}
{"type": "orderbook_delta", "seq": 2986, "price": 43, "quantity": -500, "ts": 1756428301.396911, "side": "buy"}
{"type": "orderbook_delta", "seq": 2987, "price": 44, "quantity": 500, "ts": 1756428301.491849, "side": "buy"}
{"type": "orderbook_delta", "seq": 2988, "price": 50, "quantity": 500, "ts": 1756428301.492595, "side": "sell"}
{"type": "orderbook_delta", "seq": 2989, "price": 50, "quantity": -200, "ts": 1756428301.595025, "side": "sell"}
{"type": "orderbook_delta", "seq": 2990, "price": 51, "quantity": 200, "ts": 1756428301.595025, "side": "sell"}
{"type": "orderbook_delta", "seq": 2991, "price": 49, "quantity": -190, "ts": 1756428302.136736, "side": "sell"}
{"type": "orderbook_delta", "seq": 2992, "price": 50, "quantity": 190, "ts": 1756428302.203546, "side": "sell"}
{"type": "orderbook_delta", "seq": 2993, "price": 50, "quantity": -500, "ts": 1756428303.413376, "side": "sell"}
{"type": "orderbook_delta", "seq": 2994, "price": 44, "quantity": -500, "ts": 1756428303.423082, "side": "buy"}
{"type": "orderbook_delta", "seq": 2995, "price": 49, "quantity": 500, "ts": 1756428303.477221, "side": "sell"}
{"type": "orderbook_delta", "seq": 2996, "price": 43, "quantity": 500, "ts": 1756428303.477855, "side": "buy"}
{"type": "orderbook_delta", "seq": 2997, "price": 54, "quantity": -1250, "ts": 1756428305.816245, "side": "sell"}
{"type": "orderbook_delta", "seq": 2998, "price": 52, "quantity": -200, "ts": 1756428305.81666, "side": "sell"}
{"type": "orderbook_delta", "seq": 2999, "price": 41, "quantity": -200, "ts": 1756428305.816985, "side": "buy"}
{"type": "orderbook_delta", "seq": 3000, "price": 39, "quantity": -1250, "ts": 1756428305.822591, "side": "buy"}
{"type": "orderbook_delta", "seq": 3001, "price": 38, "quantity": 1250, "ts": 1756428305.868544, "side": "buy"}
{"type": "orderbook_delta", "seq": 3002, "price": 51, "quantity": 200, "ts": 1756428305.872393, "side": "sell"}
{"type": "orderbook_delta", "seq": 3003, "price": 53, "quantity": 1250, "ts": 1756428305.872709, "side": "sell"}
{"type": "orderbook_delta", "seq": 3004, "price": 40, "quantity": 200, "ts": 1756428305.875313, "side": "buy"}
{"type": "trade", "seq": 34, "price": 47, "quantity": 20, "ts": 1756428305.884411, "side": "buy"}
{"type": "orderbook_delta", "seq": 3005, "price": 47, "quantity": 0, "ts": 1756428305.884411, "side": "sell"}
{"type": "trade", "seq": 35, "price": 49, "quantity": 16, "ts": 1756428305.884411, "side": "buy"}
{"type": "orderbook_delta", "seq": 3006, "price": 49, "quantity": 0, "ts": 1756428305.884411, "side": "sell"}
{"type": "orderbook_delta", "seq": 3007, "price": 43, "quantity": -500, "ts": 1756428305.892634, "side": "buy"}
{"type": "orderbook_delta", "seq": 3008, "price": 79, "quantity": -8000, "ts": 1756428305.89976, "side": "sell"}
{"type": "orderbook_delta", "seq": 3009, "price": 44, "quantity": -250, "ts": 1756428305.901347, "side": "buy"}
{"type": "orderbook_delta", "seq": 3010, "price": 49, "quantity": -484, "ts": 1756428305.905487, "side": "sell"}
{"type": "orderbook_delta", "seq": 3011, "price": 40, "quantity": -200, "ts": 1756428305.915089, "side": "buy"}
{"type": "orderbook_delta", "seq": 3012, "price": 51, "quantity": -200, "ts": 1756428305.916511, "side": "sell"}
{"type": "orderbook_delta", "seq": 3013, "price": 38, "quantity": -1250, "ts": 1756428305.916602, "side": "buy"}
{"type": "orderbook_delta", "seq": 3014, "price": 34, "quantity": 250, "ts": 1756428305.9414, "side": "buy"}
{"type": "orderbook_delta", "seq": 3015, "price": 49, "quantity": 500, "ts": 1756428305.941655, "side": "sell"}
{"type": "orderbook_delta", "seq": 3016, "price": 75, "quantity": 8000, "ts": 1756428305.942449, "side": "sell"}
{"type": "orderbook_delta", "seq": 3017, "price": 41, "quantity": 500, "ts": 1756428305.944448, "side": "buy"}
{"type": "orderbook_delta", "seq": 3018, "price": 53, "quantity": -1250, "ts": 1756428305.946215, "side": "sell"}
{"type": "orderbook_delta", "seq": 3019, "price": 49, "quantity": 200, "ts": 1756428305.963056, "side": "sell"}
{"type": "orderbook_delta", "seq": 3020, "price": 38, "quantity": 200, "ts": 1756428305.96552, "side": "buy"}
{"type": "orderbook_delta", "seq": 3021, "price": 51, "quantity": 1250, "ts": 1756428305.996779, "side": "sell"}
{"type": "orderbook_delta", "seq": 3022, "price": 42, "quantity": -250, "ts": 1756428306.014813, "side": "buy"}
{"type": "orderbook_delta", "seq": 3023, "price": 32, "quantity": 250, "ts": 1756428306.018133, "side": "buy"}
{"type": "orderbook_delta", "seq": 3024, "price": 36, "quantity": 1250, "ts": 1756428306.040197, "side": "buy"}
{"type": "orderbook_delta", "seq": 3025, "price": 51, "quantity": -200, "ts": 1756428306.046367, "side": "sell"}
{"type": "orderbook_delta", "seq": 3026, "price": 48, "quantity": 200, "ts": 1756428306.046367, "side": "sell"}
{"type": "orderbook_delta", "seq": 3027, "price": 40, "quantity": -250, "ts": 1756428306.053249, "side": "buy"}
{"type": "orderbook_delta", "seq": 3028, "price": 30, "quantity": 250, "ts": 1756428306.056054, "side": "buy"}
{"type": "orderbook_delta", "seq": 3029, "price": 75, "quantity": -8000, "ts": 1756428306.073774, "side": "sell"}
{"type": "orderbook_delta", "seq": 3030, "price": 40, "quantity": 250, "ts": 1756428306.111937, "side": "buy"}
{"type": "orderbook_delta", "seq": 3031, "price": 50, "quantity": -190, "ts": 1756428306.118733, "side": "sell"}
{"type": "orderbook_delta", "seq": 3032, "price": 49, "quantity": -500, "ts": 1756428306.123586, "side": "sell"}
{"type": "orderbook_delta", "seq": 3033, "price": 50, "quantity": 250, "ts": 1756428306.125829, "side": "sell"}
{"type": "orderbook_delta", "seq": 3034, "price": 30, "quantity": -250, "ts": 1756428306.135559, "side": "buy"}
{"type": "orderbook_delta", "seq": 3035, "price": 41, "quantity": -500, "ts": 1756428306.139952, "side": "buy"}
{"type": "orderbook_delta", "seq": 3036, "price": 60, "quantity": -250, "ts": 1756428306.157246, "side": "sell"}
{"type": "orderbook_delta", "seq": 3037, "price": 47, "quantity": 500, "ts": 1756428306.16951, "side": "sell"}
{"type": "orderbook_delta", "seq": 3038, "price": 47, "quantity": 190, "ts": 1756428306.199241, "side": "sell"}
{"type": "orderbook_delta", "seq": 3039, "price": 40, "quantity": 500, "ts": 1756428306.264248, "side": "buy"}
{"type": "orderbook_delta", "seq": 3040, "price": 74, "quantity": 8000, "ts": 1756428306.338134, "side": "sell"}
{"type": "orderbook_delta", "seq": 3041, "price": 47, "quantity": -500, "ts": 1756428306.386841, "side": "sell"}
{"type": "orderbook_delta", "seq": 3042, "price": 46, "quantity": 500, "ts": 1756428306.500595, "side": "sell"}
{"type": "orderbook_delta", "seq": 3043, "price": 44, "quantity": -100, "ts": 1756428306.881436, "side": "buy"}
{"type": "orderbook_delta", "seq": 3044, "price": 45, "quantity": 100, "ts": 1756428307.124456, "side": "buy"}
{"type": "orderbook_delta", "seq": 3045, "price": 51, "quantity": -1250, "ts": 1756428307.281497, "side": "sell"}
{"type": "orderbook_delta", "seq": 3046, "price": 36, "quantity": -1250, "ts": 1756428307.286333, "side": "buy"}
{"type": "orderbook_delta", "seq": 3047, "price": 38, "quantity": -200, "ts": 1756428307.286997, "side": "buy"}
{"type": "orderbook_delta", "seq": 3048, "price": 49, "quantity": -200, "ts": 1756428307.287185, "side": "sell"}
{"type": "orderbook_delta", "seq": 3049, "price": 48, "quantity": 200, "ts": 1756428307.331227, "side": "sell"}
{"type": "orderbook_delta", "seq": 3050, "price": 50, "quantity": 1250, "ts": 1756428307.332266, "side": "sell"}
{"type": "orderbook_delta", "seq": 3051, "price": 37, "quantity": 200, "ts": 1756428307.332582, "side": "buy"}
{"type": "orderbook_delta", "seq": 3052, "price": 35, "quantity": 1250, "ts": 1756428307.334933, "side": "buy"}
{"type": "orderbook_delta", "seq": 3053, "price": 40, "quantity": -500, "ts": 1756428307.343134, "side": "buy"}
{"type": "orderbook_delta", "seq": 3054, "price": 12, "quantity": -8000, "ts": 1756428307.34607, "side": "buy"}
{"type": "orderbook_delta", "seq": 3055, "price": 37, "quantity": -200, "ts": 1756428307.371075, "side": "buy"}
{"type": "orderbook_delta", "seq": 3056, "price": 48, "quantity": -200, "ts": 1756428307.37335, "side": "sell"}
{"type": "orderbook_delta", "seq": 3057, "price": 30, "quantity": 250, "ts": 1756428307.376021, "side": "buy"}
{"type": "orderbook_delta", "seq": 3058, "price": 40, "quantity": -250, "ts": 1756428307.376637, "side": "buy"}
{"type": "orderbook_delta", "seq": 3059, "price": 50, "quantity": -1250, "ts": 1756428307.377577, "side": "sell"}
{"type": "orderbook_delta", "seq": 3060, "price": 11, "quantity": 8000, "ts": 1756428307.401611, "side": "buy"}
{"type": "orderbook_delta", "seq": 3061, "price": 39, "quantity": 500, "ts": 1756428307.402058, "side": "buy"}
{"type": "orderbook_delta", "seq": 3062, "price": 37, "quantity": 200, "ts": 1756428307.418065, "side": "buy"}
{"type": "orderbook_delta", "seq": 3063, "price": 50, "quantity": 1250, "ts": 1756428307.41862, "side": "sell"}
{"type": "orderbook_delta", "seq": 3064, "price": 48, "quantity": 200, "ts": 1756428307.422336, "side": "sell"}
{"type": "orderbook_delta", "seq": 3065, "price": 11, "quantity": -8000, "ts": 1756428307.454106, "side": "buy"}
{"type": "orderbook_delta", "seq": 3066, "price": 12, "quantity": 8000, "ts": 1756428307.537962, "side": "buy"}
{"type": "orderbook_delta", "seq": 3067, "price": 48, "quantity": -200, "ts": 1756428307.597784, "side": "sell"}
{"type": "orderbook_delta", "seq": 3068, "price": 47, "quantity": 200, "ts": 1756428307.597784, "side": "sell"}
{"type": "orderbook_delta", "seq": 3069, "price": 48, "quantity": -200, "ts": 1756428307.633959, "side": "sell"}
{"type": "orderbook_delta", "seq": 3070, "price": 49, "quantity": 200, "ts": 1756428307.671978, "side": "sell"}
{"type": "orderbook_delta", "seq": 3071, "price": 1, "quantity": -19440, "ts": 1756428307.865584, "side": "buy"}
{"type": "orderbook_delta", "seq": 3072, "price": 2, "quantity": -7000, "ts": 1756428307.915065, "side": "buy"}
{"type": "orderbook_delta", "seq": 3073, "price": 12, "quantity": -8000, "ts": 1756428308.071036, "side": "buy"}
{"type": "orderbook_delta", "seq": 3074, "price": 50, "quantity": -1250, "ts": 1756428308.071172, "side": "sell"}
{"type": "orderbook_delta", "seq": 3075, "price": 35, "quantity": -1250, "ts": 1756428308.105606, "side": "buy"}
{"type": "orderbook_delta", "seq": 3076, "price": 49, "quantity": -200, "ts": 1756428308.10635, "side": "sell"}
{"type": "orderbook_delta", "seq": 3077, "price": 37, "quantity": -200, "ts": 1756428308.107525, "side": "buy"}
{"type": "orderbook_delta", "seq": 3078, "price": 47, "quantity": -190, "ts": 1756428308.135957, "side": "sell"}
{"type": "orderbook_delta", "seq": 3079, "price": 56, "quantity": -250, "ts": 1756428308.157689, "side": "sell"}
{"type": "orderbook_delta", "seq": 3080, "price": 48, "quantity": 250, "ts": 1756428308.158021, "side": "sell"}
{"type": "orderbook_delta", "seq": 3081, "price": 11, "quantity": 8000, "ts": 1756428308.162066, "side": "buy"}
{"type": "orderbook_delta", "seq": 3082, "price": 47, "quantity": 200, "ts": 1756428308.162907, "side": "sell"}
{"type": "orderbook_delta", "seq": 3083, "price": 49, "quantity": 1250, "ts": 1756428308.169239, "side": "sell"}
{"type": "orderbook_delta", "seq": 3084, "price": 34, "quantity": 1250, "ts": 1756428308.177204, "side": "buy"}
{"type": "orderbook_delta", "seq": 3085, "price": 46, "quantity": 250, "ts": 1756428308.20865, "side": "sell"}
{"type": "orderbook_delta", "seq": 3086, "price": 36, "quantity": 200, "ts": 1756428308.213941, "side": "buy"}
{"type": "orderbook_delta", "seq": 3087, "price": 58, "quantity": -250, "ts": 1756428308.297061, "side": "sell"}
{"type": "orderbook_delta", "seq": 3088, "price": 46, "quantity": 190, "ts": 1756428308.364137, "side": "sell"}
{"type": "orderbook_delta", "seq": 3089, "price": 34, "quantity": -1250, "ts": 1756428309.120098, "side": "buy"}
{"type": "orderbook_delta", "seq": 3090, "price": 11, "quantity": -8000, "ts": 1756428309.120918, "side": "buy"}
{"type": "orderbook_delta", "seq": 3091, "price": 47, "quantity": -200, "ts": 1756428309.120995, "side": "sell"}
{"type": "orderbook_delta", "seq": 3092, "price": 49, "quantity": -1250, "ts": 1756428309.121054, "side": "sell"}
{"type": "orderbook_delta", "seq": 3093, "price": 46, "quantity": -250, "ts": 1756428309.121203, "side": "sell"}
{"type": "orderbook_delta", "seq": 3094, "price": 36, "quantity": -200, "ts": 1756428309.121747, "side": "buy"}
{"type": "orderbook_delta", "seq": 3095, "price": 56, "quantity": 250, "ts": 1756428309.121877, "side": "sell"}
{"type": "orderbook_delta", "seq": 3096, "price": 50, "quantity": 1250, "ts": 1756428309.175245, "side": "sell"}
{"type": "orderbook_delta", "seq": 3097, "price": 35, "quantity": 1250, "ts": 1756428309.175674, "side": "buy"}
{"type": "orderbook_delta", "seq": 3098, "price": 48, "quantity": 200, "ts": 1756428309.176752, "side": "sell"}
{"type": "orderbook_delta", "seq": 3099, "price": 12, "quantity": 8000, "ts": 1756428309.177074, "side": "buy"}
{"type": "orderbook_delta", "seq": 3100, "price": 37, "quantity": 200, "ts": 1756428309.177948, "side": "buy"}
{"type": "orderbook_delta", "seq": 3101, "price": 50, "quantity": -1250, "ts": 1756428309.334643, "side": "sell"}
{"type": "orderbook_delta", "seq": 3102, "price": 49, "quantity": 1250, "ts": 1756428309.37084, "side": "sell"}
{"type": "orderbook_delta", "seq": 3103, "price": 49, "quantity": -1250, "ts": 1756428309.5289, "side": "sell"}
{"type": "orderbook_delta", "seq": 3104, "price": 50, "quantity": 1250, "ts": 1756428309.580193, "side": "sell"}
{"type": "orderbook_delta", "seq": 3105, "price": 37, "quantity": -200, "ts": 1756428309.72736, "side": "buy"}
{"type": "orderbook_delta", "seq": 3106, "price": 48, "quantity": -200, "ts": 1756428309.72871, "side": "sell"}
{"type": "orderbook_delta", "seq": 3107, "price": 35, "quantity": -1250, "ts": 1756428309.731257, "side": "buy"}
{"type": "orderbook_delta", "seq": 3108, "price": 38, "quantity": 200, "ts": 1756428309.761106, "side": "buy"}
{"type": "orderbook_delta", "seq": 3109, "price": 36, "quantity": 1250, "ts": 1756428309.766652, "side": "buy"}
{"type": "orderbook_delta", "seq": 3110, "price": 49, "quantity": 200, "ts": 1756428309.767128, "side": "sell"}
{"type": "orderbook_delta", "seq": 3111, "price": 40, "quantity": 250, "ts": 1756428310.107335, "side": "buy"}
{"type": "orderbook_delta", "seq": 3112, "price": 30, "quantity": -250, "ts": 1756428310.108267, "side": "buy"}
{"type": "orderbook_delta", "seq": 3113, "price": 39, "quantity": -500, "ts": 1756428310.190683, "side": "buy"}
{"type": "orderbook_delta", "seq": 3114, "price": 40, "quantity": 500, "ts": 1756428310.233477, "side": "buy"}
{"type": "orderbook_delta", "seq": 3115, "price": 49, "quantity": -200, "ts": 1756428310.298644, "side": "sell"}
{"type": "orderbook_delta", "seq": 3116, "price": 36, "quantity": -1250, "ts": 1756428310.298849, "side": "buy"}
{"type": "orderbook_delta", "seq": 3117, "price": 38, "quantity": -200, "ts": 1756428310.300572, "side": "buy"}
{"type": "orderbook_delta", "seq": 3118, "price": 37, "quantity": 200, "ts": 1756428310.352039, "side": "buy"}
{"type": "orderbook_delta", "seq": 3119, "price": 35, "quantity": 1250, "ts": 1756428310.355435, "side": "buy"}
{"type": "orderbook_delta", "seq": 3120, "price": 48, "quantity": 200, "ts": 1756428310.355721, "side": "sell"}
{"type": "orderbook_delta", "seq": 3121, "price": 40, "quantity": -250, "ts": 1756428311.174202, "side": "buy"}
{"type": "orderbook_delta", "seq": 3122, "price": 30, "quantity": 250, "ts": 1756428311.174229, "side": "buy"}
{"type": "orderbook_delta", "seq": 3123, "price": 40, "quantity": -500, "ts": 1756428311.20602, "side": "buy"}
{"type": "orderbook_delta", "seq": 3124, "price": 39, "quantity": 500, "ts": 1756428311.250238, "side": "buy"}
{"type": "orderbook_delta", "seq": 3125, "price": 40, "quantity": 250, "ts": 1756428312.136005, "side": "buy"}
{"type": "orderbook_delta", "seq": 3126, "price": 30, "quantity": -250, "ts": 1756428312.136639, "side": "buy"}
{"type": "orderbook_delta", "seq": 3127, "price": 34, "quantity": 100, "ts": 1756428312.697424, "side": "buy"}
{"type": "orderbook_delta", "seq": 3128, "price": 39, "quantity": -500, "ts": 1756428312.859807, "side": "buy"}
{"type": "orderbook_delta", "seq": 3129, "price": 37, "quantity": -200, "ts": 1756428312.864542, "side": "buy"}
{"type": "orderbook_delta", "seq": 3130, "price": 48, "quantity": -200, "ts": 1756428312.865662, "side": "sell"}
{"type": "orderbook_delta", "seq": 3131, "price": 35, "quantity": -1250, "ts": 1756428312.867058, "side": "buy"}
{"type": "orderbook_delta", "seq": 3132, "price": 50, "quantity": -1250, "ts": 1756428312.869192, "side": "sell"}
{"type": "orderbook_delta", "seq": 3133, "price": 40, "quantity": 500, "ts": 1756428312.89817, "side": "buy"}
{"type": "orderbook_delta", "seq": 3134, "price": 47, "quantity": -200, "ts": 1756428312.902887, "side": "sell"}
{"type": "orderbook_delta", "seq": 3135, "price": 48, "quantity": 200, "ts": 1756428312.902887, "side": "sell"}
{"type": "orderbook_delta", "seq": 3136, "price": 51, "quantity": 1250, "ts": 1756428312.920127, "side": "sell"}
{"type": "orderbook_delta", "seq": 3137, "price": 36, "quantity": 1250, "ts": 1756428312.923685, "side": "buy"}
{"type": "orderbook_delta", "seq": 3138, "price": 49, "quantity": 200, "ts": 1756428312.926624, "side": "sell"}
{"type": "orderbook_delta", "seq": 3139, "price": 38, "quantity": 200, "ts": 1756428312.930732, "side": "buy"}
{"type": "orderbook_delta", "seq": 3140, "price": 49, "quantity": -200, "ts": 1756428313.240728, "side": "sell"}
{"type": "orderbook_delta", "seq": 3141, "price": 36, "quantity": -1250, "ts": 1756428313.241078, "side": "buy"}
{"type": "orderbook_delta", "seq": 3142, "price": 74, "quantity": -8000, "ts": 1756428313.241239, "side": "sell"}
{"type": "orderbook_delta", "seq": 3143, "price": 51, "quantity": -1250, "ts": 1756428313.242288, "side": "sell"}
{"type": "orderbook_delta", "seq": 3144, "price": 40, "quantity": -500, "ts": 1756428313.245263, "side": "buy"}
{"type": "orderbook_delta", "seq": 3145, "price": 46, "quantity": -500, "ts": 1756428313.251477, "side": "sell"}
{"type": "orderbook_delta", "seq": 3146, "price": 38, "quantity": -200, "ts": 1756428313.252395, "side": "buy"}
{"type": "orderbook_delta", "seq": 3147, "price": 75, "quantity": 8000, "ts": 1756428313.289452, "side": "sell"}
{"type": "orderbook_delta", "seq": 3148, "price": 39, "quantity": 200, "ts": 1756428313.290784, "side": "buy"}
{"type": "orderbook_delta", "seq": 3149, "price": 50, "quantity": 200, "ts": 1756428313.291043, "side": "sell"}
{"type": "orderbook_delta", "seq": 3150, "price": 37, "quantity": 1250, "ts": 1756428313.291293, "side": "buy"}
{"type": "orderbook_delta", "seq": 3151, "price": 41, "quantity": 500, "ts": 1756428313.292327, "side": "buy"}
{"type": "orderbook_delta", "seq": 3152, "price": 52, "quantity": 1250, "ts": 1756428313.292847, "side": "sell"}
{"type": "orderbook_delta", "seq": 3153, "price": 47, "quantity": 500, "ts": 1756428313.294253, "side": "sell"}
{"type": "orderbook_delta", "seq": 3154, "price": 47, "quantity": -500, "ts": 1756428313.832166, "side": "sell"}
{"type": "orderbook_delta", "seq": 3155, "price": 75, "quantity": -8000, "ts": 1756428313.835146, "side": "sell"}
{"type": "orderbook_delta", "seq": 3156, "price": 48, "quantity": 500, "ts": 1756428313.870423, "side": "sell"}
{"type": "orderbook_delta", "seq": 3157, "price": 79, "quantity": 8000, "ts": 1756428313.874012, "side": "sell"}
{"type": "orderbook_delta", "seq": 3158, "price": 46, "quantity": -190, "ts": 1756428314.132865, "side": "sell"}
{"type": "orderbook_delta", "seq": 3159, "price": 42, "quantity": 250, "ts": 1756428314.140175, "side": "buy"}
{"type": "orderbook_delta", "seq": 3160, "price": 32, "quantity": -250, "ts": 1756428314.147468, "side": "buy"}
{"type": "orderbook_delta", "seq": 3161, "price": 58, "quantity": 250, "ts": 1756428314.171267, "side": "sell"}
{"type": "orderbook_delta", "seq": 3162, "price": 41, "quantity": -500, "ts": 1756428314.193878, "side": "buy"}
{"type": "orderbook_delta", "seq": 3163, "price": 42, "quantity": 500, "ts": 1756428314.301652, "side": "buy"}
{"type": "orderbook_delta", "seq": 3164, "price": 48, "quantity": -250, "ts": 1756428314.35945, "side": "sell"}
{"type": "orderbook_delta", "seq": 3165, "price": 49, "quantity": 190, "ts": 1756428314.425175, "side": "sell"}
{"type": "orderbook_delta", "seq": 3166, "price": 34, "quantity": -250, "ts": 1756428315.105627, "side": "buy"}
{"type": "orderbook_delta", "seq": 3167, "price": 44, "quantity": 250, "ts": 1756428315.106315, "side": "buy"}
{"type": "orderbook_delta", "seq": 3168, "price": 50, "quantity": -250, "ts": 1756428315.126847, "side": "sell"}
{"type": "orderbook_delta", "seq": 3169, "price": 60, "quantity": 250, "ts": 1756428315.127146, "side": "sell"}
{"type": "orderbook_delta", "seq": 3170, "price": 50, "quantity": -200, "ts": 1756428315.164548, "side": "sell"}
{"type": "orderbook_delta", "seq": 3171, "price": 51, "quantity": 200, "ts": 1756428315.206429, "side": "sell"}
{"type": "orderbook_delta", "seq": 3172, "price": 45, "quantity": 100, "ts": 1756428315.740172, "side": "buy"}
{"type": "orderbook_delta", "seq": 3173, "price": 44, "quantity": -250, "ts": 1756428316.119844, "side": "buy"}
{"type": "orderbook_delta", "seq": 3174, "price": 34, "quantity": 250, "ts": 1756428316.125386, "side": "buy"}
{"type": "orderbook_delta", "seq": 3175, "price": 50, "quantity": 250, "ts": 1756428317.09003, "side": "sell"}
{"type": "orderbook_delta", "seq": 3176, "price": 49, "quantity": -190, "ts": 1756428317.095732, "side": "sell"}
{"type": "orderbook_delta", "seq": 3177, "price": 60, "quantity": -250, "ts": 1756428317.115054, "side": "sell"}
{"type": "orderbook_delta", "seq": 3178, "price": 48, "quantity": 190, "ts": 1756428317.151367, "side": "sell"}
{"type": "orderbook_delta", "seq": 3179, "price": 51, "quantity": -200, "ts": 1756428317.216874, "side": "sell"}
{"type": "orderbook_delta", "seq": 3180, "price": 50, "quantity": 200, "ts": 1756428317.270276, "side": "sell"}
{"type": "orderbook_delta", "seq": 3181, "price": 42, "quantity": -250, "ts": 1756428318.548703, "side": "buy"}
{"type": "orderbook_delta", "seq": 3182, "price": 30, "quantity": 250, "ts": 1756428318.550997, "side": "buy"}
{"type": "orderbook_delta", "seq": 3183, "price": 32, "quantity": 250, "ts": 1756428318.551236, "side": "buy"}
{"type": "orderbook_delta", "seq": 3184, "price": 40, "quantity": -250, "ts": 1756428318.551702, "side": "buy"}
{"type": "orderbook_delta", "seq": 3185, "price": 39, "quantity": -200, "ts": 1756428318.558499, "side": "buy"}
{"type": "orderbook_delta", "seq": 3186, "price": 50, "quantity": -200, "ts": 1756428318.560052, "side": "sell"}
{"type": "orderbook_delta", "seq": 3187, "price": 52, "quantity": -1250, "ts": 1756428318.56118, "side": "sell"}
{"type": "orderbook_delta", "seq": 3188, "price": 79, "quantity": -8000, "ts": 1756428318.561623, "side": "sell"}
{"type": "orderbook_delta", "seq": 3189, "price": 37, "quantity": -1250, "ts": 1756428318.564865, "side": "buy"}
{"type": "orderbook_delta", "seq": 3190, "price": 42, "quantity": -500, "ts": 1756428318.58114, "side": "buy"}
{"type": "orderbook_delta", "seq": 3191, "price": 48, "quantity": -500, "ts": 1756428318.590232, "side": "sell"}
{"type": "orderbook_delta", "seq": 3192, "price": 39, "quantity": 500, "ts": 1756428318.638712, "side": "buy"}
{"type": "orderbook_delta", "seq": 3193, "price": 47, "quantity": 500, "ts": 1756428318.640742, "side": "sell"}
{"type": "orderbook_delta", "seq": 3194, "price": 38, "quantity": 200, "ts": 1756428318.64099, "side": "buy"}
{"type": "orderbook_delta", "seq": 3195, "price": 36, "quantity": 1250, "ts": 1756428318.641202, "side": "buy"}
{"type": "orderbook_delta", "seq": 3196, "price": 74, "quantity": 8000, "ts": 1756428318.641655, "side": "sell"}
{"type": "orderbook_delta", "seq": 3197, "price": 51, "quantity": 1250, "ts": 1756428318.641925, "side": "sell"}
{"type": "orderbook_delta", "seq": 3198, "price": 49, "quantity": 200, "ts": 1756428318.642143, "side": "sell"}
{"type": "orderbook_delta", "seq": 3199, "price": 74, "quantity": -8000, "ts": 1756428319.030304, "side": "sell"}
{"type": "orderbook_delta", "seq": 3200, "price": 38, "quantity": -200, "ts": 1756428319.032374, "side": "buy"}
{"type": "orderbook_delta", "seq": 3201, "price": 51, "quantity": -1250, "ts": 1756428319.032437, "side": "sell"}
{"type": "orderbook_delta", "seq": 3202, "price": 49, "quantity": -200, "ts": 1756428319.032762, "side": "sell"}
{"type": "orderbook_delta", "seq": 3203, "price": 36, "quantity": -1250, "ts": 1756428319.033169, "side": "buy"}
{"type": "orderbook_delta", "seq": 3204, "price": 39, "quantity": 200, "ts": 1756428319.081904, "side": "buy"}
{"type": "orderbook_delta", "seq": 3205, "price": 37, "quantity": 1250, "ts": 1756428319.082501, "side": "buy"}
{"type": "orderbook_delta", "seq": 3206, "price": 75, "quantity": 8000, "ts": 1756428319.084452, "side": "sell"}
{"type": "orderbook_delta", "seq": 3207, "price": 50, "quantity": 200, "ts": 1756428319.084742, "side": "sell"}
{"type": "orderbook_delta", "seq": 3208, "price": 52, "quantity": 1250, "ts": 1756428319.085845, "side": "sell"}
{"type": "orderbook_delta", "seq": 3209, "price": 48, "quantity": -190, "ts": 1756428319.11705, "side": "sell"}
{"type": "orderbook_delta", "seq": 3210, "price": 58, "quantity": -250, "ts": 1756428319.136275, "side": "sell"}
{"type": "orderbook_delta", "seq": 3211, "price": 48, "quantity": 250, "ts": 1756428319.136407, "side": "sell"}
{"type": "orderbook_delta", "seq": 3212, "price": 46, "quantity": 190, "ts": 1756428319.227044, "side": "sell"}
{"type": "orderbook_delta", "seq": 3213, "price": 46, "quantity": -190, "ts": 1756428320.146216, "side": "sell"}
{"type": "orderbook_delta", "seq": 3214, "price": 40, "quantity": 250, "ts": 1756428320.14744, "side": "buy"}
{"type": "orderbook_delta", "seq": 3215, "price": 58, "quantity": 250, "ts": 1756428320.166531, "side": "sell"}
{"type": "orderbook_delta", "seq": 3216, "price": 30, "quantity": -250, "ts": 1756428320.167914, "side": "buy"}
{"type": "orderbook_delta", "seq": 3217, "price": 39, "quantity": -500, "ts": 1756428320.186176, "side": "buy"}
{"type": "orderbook_delta", "seq": 3218, "price": 48, "quantity": -250, "ts": 1756428320.207552, "side": "sell"}
{"type": "orderbook_delta", "seq": 3219, "price": 41, "quantity": 500, "ts": 1756428320.22783, "side": "buy"}
{"type": "orderbook_delta", "seq": 3220, "price": 48, "quantity": 190, "ts": 1756428320.254187, "side": "sell"}
{"type": "orderbook_delta", "seq": 3221, "price": 32, "quantity": -250, "ts": 1756428321.016553, "side": "buy"}
{"type": "orderbook_delta", "seq": 3222, "price": 42, "quantity": 250, "ts": 1756428321.019499, "side": "buy"}
{"type": "orderbook_delta", "seq": 3223, "price": 42, "quantity": -250, "ts": 1756428322.444812, "side": "buy"}
{"type": "orderbook_delta", "seq": 3224, "price": 32, "quantity": 250, "ts": 1756428322.448842, "side": "buy"}
{"type": "orderbook_delta", "seq": 3225, "price": 52, "quantity": -1250, "ts": 1756428322.462043, "side": "sell"}
{"type": "orderbook_delta", "seq": 3226, "price": 48, "quantity": -200, "ts": 1756428322.492183, "side": "sell"}
{"type": "orderbook_delta", "seq": 3227, "price": 47, "quantity": 200, "ts": 1756428322.492183, "side": "sell"}
{"type": "orderbook_delta", "seq": 3228, "price": 51, "quantity": 1250, "ts": 1756428322.498207, "side": "sell"}
{"type": "orderbook_delta", "seq": 3229, "price": 50, "quantity": -200, "ts": 1756428322.557506, "side": "sell"}
{"type": "orderbook_delta", "seq": 3230, "price": 47, "quantity": -500, "ts": 1756428322.557744, "side": "sell"}
{"type": "orderbook_delta", "seq": 3231, "price": 75, "quantity": -8000, "ts": 1756428322.558282, "side": "sell"}
{"type": "orderbook_delta", "seq": 3232, "price": 41, "quantity": -500, "ts": 1756428322.558476, "side": "buy"}
{"type": "orderbook_delta", "seq": 3233, "price": 37, "quantity": -1250, "ts": 1756428322.559515, "side": "buy"}
{"type": "orderbook_delta", "seq": 3234, "price": 39, "quantity": -200, "ts": 1756428322.56771, "side": "buy"}
{"type": "orderbook_delta", "seq": 3235, "price": 49, "quantity": 200, "ts": 1756428322.655447, "side": "sell"}
{"type": "orderbook_delta", "seq": 3236, "price": 46, "quantity": 500, "ts": 1756428322.656, "side": "sell"}
{"type": "orderbook_delta", "seq": 3237, "price": 74, "quantity": 8000, "ts": 1756428322.656474, "side": "sell"}
{"type": "orderbook_delta", "seq": 3238, "price": 36, "quantity": 1250, "ts": 1756428322.657054, "side": "buy"}
{"type": "orderbook_delta", "seq": 3239, "price": 40, "quantity": 500, "ts": 1756428322.65751, "side": "buy"}
{"type": "orderbook_delta", "seq": 3240, "price": 38, "quantity": 200, "ts": 1756428322.791461, "side": "buy"}
{"type": "orderbook_delta", "seq": 3241, "price": 40, "quantity": -250, "ts": 1756428322.793831, "side": "buy"}
{"type": "orderbook_delta", "seq": 3242, "price": 30, "quantity": 250, "ts": 1756428322.793873, "side": "buy"}
{"type": "orderbook_delta", "seq": 3243, "price": 40, "quantity": -500, "ts": 1756428322.828271, "side": "buy"}
{"type": "orderbook_delta", "seq": 3244, "price": 39, "quantity": 500, "ts": 1756428322.904687, "side": "buy"}
{"type": "orderbook_delta", "seq": 3245, "price": 30, "quantity": -250, "ts": 1756428323.019087, "side": "buy"}
{"type": "orderbook_delta", "seq": 3246, "price": 40, "quantity": 250, "ts": 1756428323.022582, "side": "buy"}
{"type": "orderbook_delta", "seq": 3247, "price": 39, "quantity": -500, "ts": 1756428323.114629, "side": "buy"}
{"type": "orderbook_delta", "seq": 3248, "price": 48, "quantity": -190, "ts": 1756428323.132835, "side": "sell"}
{"type": "orderbook_delta", "seq": 3249, "price": 40, "quantity": 500, "ts": 1756428323.184187, "side": "buy"}
{"type": "orderbook_delta", "seq": 3250, "price": 47, "quantity": 190, "ts": 1756428323.195128, "side": "sell"}
{"type": "orderbook_delta", "seq": 3251, "price": 45, "quantity": -100, "ts": 1756428323.850568, "side": "buy"}
{"type": "orderbook_delta", "seq": 3252, "price": 47, "quantity": -190, "ts": 1756428324.150006, "side": "sell"}
{"type": "orderbook_delta", "seq": 3253, "price": 48, "quantity": 250, "ts": 1756428324.151029, "side": "sell"}
{"type": "orderbook_delta", "seq": 3254, "price": 58, "quantity": -250, "ts": 1756428324.165289, "side": "sell"}
{"type": "orderbook_delta", "seq": 3255, "price": 46, "quantity": 190, "ts": 1756428324.202265, "side": "sell"}
{"type": "orderbook_delta", "seq": 3256, "price": 36, "quantity": -1250, "ts": 1756428324.234257, "side": "buy"}
{"type": "orderbook_delta", "seq": 3257, "price": 38, "quantity": -200, "ts": 1756428324.234481, "side": "buy"}
{"type": "orderbook_delta", "seq": 3258, "price": 51, "quantity": -1250, "ts": 1756428324.240856, "side": "sell"}
{"type": "orderbook_delta", "seq": 3259, "price": 49, "quantity": -200, "ts": 1756428324.242693, "side": "sell"}
{"type": "orderbook_delta", "seq": 3260, "price": 48, "quantity": 200, "ts": 1756428324.28553, "side": "sell"}
{"type": "orderbook_delta", "seq": 3261, "price": 37, "quantity": 200, "ts": 1756428324.285871, "side": "buy"}
{"type": "orderbook_delta", "seq": 3262, "price": 35, "quantity": 1250, "ts": 1756428324.293982, "side": "buy"}
{"type": "orderbook_delta", "seq": 3263, "price": 44, "quantity": 50, "ts": 1756428324.295471, "side": "buy"}
{"type": "orderbook_delta", "seq": 3264, "price": 40, "quantity": -500, "ts": 1756428324.300527, "side": "buy"}
{"type": "orderbook_delta", "seq": 3265, "price": 50, "quantity": 1250, "ts": 1756428324.323964, "side": "sell"}
{"type": "orderbook_delta", "seq": 3266, "price": 47, "quantity": -200, "ts": 1756428324.33722, "side": "sell"}
{"type": "orderbook_delta", "seq": 3267, "price": 46, "quantity": 200, "ts": 1756428324.33722, "side": "sell"}
{"type": "orderbook_delta", "seq": 3268, "price": 39, "quantity": 500, "ts": 1756428324.350425, "side": "buy"}
{"type": "orderbook_delta", "seq": 3269, "price": 40, "quantity": -250, "ts": 1756428325.144046, "side": "buy"}
{"type": "orderbook_delta", "seq": 3270, "price": 30, "quantity": 250, "ts": 1756428325.156541, "side": "buy"}
{"type": "orderbook_delta", "seq": 3271, "price": 46, "quantity": 0, "ts": 1756428325.463963, "side": "sell"}
{"type": "trade", "seq": 36, "price": 46, "quantity": 100, "ts": 1756428325.463963, "side": "buy"}
{"type": "orderbook_delta", "seq": 3272, "price": 45, "quantity": -100, "ts": 1756428325.463963, "side": "buy"}
{"type": "orderbook_delta", "seq": 3273, "price": 37, "quantity": -200, "ts": 1756428325.470529, "side": "buy"}
{"type": "orderbook_delta", "seq": 3274, "price": 50, "quantity": -1250, "ts": 1756428325.470582, "side": "sell"}
{"type": "orderbook_delta", "seq": 3275, "price": 35, "quantity": -1250, "ts": 1756428325.475936, "side": "buy"}
{"type": "orderbook_delta", "seq": 3276, "price": 12, "quantity": -8000, "ts": 1756428325.476124, "side": "buy"}
{"type": "orderbook_delta", "seq": 3277, "price": 48, "quantity": -200, "ts": 1756428325.480057, "side": "sell"}
{"type": "orderbook_delta", "seq": 3278, "price": 46, "quantity": -400, "ts": 1756428325.515532, "side": "sell"}
{"type": "orderbook_delta", "seq": 3279, "price": 46, "quantity": -190, "ts": 1756428325.520728, "side": "sell"}
{"type": "orderbook_delta", "seq": 3280, "price": 11, "quantity": 8000, "ts": 1756428325.522425, "side": "buy"}
{"type": "orderbook_delta", "seq": 3281, "price": 47, "quantity": 200, "ts": 1756428325.522714, "side": "sell"}
{"type": "orderbook_delta", "seq": 3282, "price": 34, "quantity": 1250, "ts": 1756428325.523202, "side": "buy"}
{"type": "orderbook_delta", "seq": 3283, "price": 49, "quantity": 1250, "ts": 1756428325.524135, "side": "sell"}
{"type": "orderbook_delta", "seq": 3284, "price": 36, "quantity": 200, "ts": 1756428325.528415, "side": "buy"}
{"type": "orderbook_delta", "seq": 3285, "price": 45, "quantity": 500, "ts": 1756428325.56299, "side": "sell"}
{"type": "orderbook_delta", "seq": 3286, "price": 45, "quantity": 190, "ts": 1756428325.574211, "side": "sell"}
{"type": "orderbook_delta", "seq": 3287, "price": 39, "quantity": -500, "ts": 1756428325.922382, "side": "buy"}
{"type": "orderbook_delta", "seq": 3288, "price": 38, "quantity": 500, "ts": 1756428325.961394, "side": "buy"}
{"type": "orderbook_delta", "seq": 3289, "price": 56, "quantity": -250, "ts": 1756428326.101172, "side": "sell"}
{"type": "orderbook_delta", "seq": 3290, "price": 46, "quantity": 250, "ts": 1756428326.101662, "side": "sell"}
{"type": "orderbook_delta", "seq": 3291, "price": 36, "quantity": -200, "ts": 1756428326.482812, "side": "buy"}
{"type": "orderbook_delta", "seq": 3292, "price": 49, "quantity": -1250, "ts": 1756428326.48291, "side": "sell"}
{"type": "orderbook_delta", "seq": 3293, "price": 47, "quantity": -200, "ts": 1756428326.483116, "side": "sell"}
{"type": "orderbook_delta", "seq": 3294, "price": 34, "quantity": -1250, "ts": 1756428326.488705, "side": "buy"}
{"type": "orderbook_delta", "seq": 3295, "price": 11, "quantity": -8000, "ts": 1756428326.497279, "side": "buy"}
{"type": "orderbook_delta", "seq": 3296, "price": 38, "quantity": -500, "ts": 1756428326.504901, "side": "buy"}
{"type": "orderbook_delta", "seq": 3297, "price": 47, "quantity": 1250, "ts": 1756428326.519692, "side": "sell"}
{"type": "orderbook_delta", "seq": 3298, "price": 34, "quantity": 200, "ts": 1756428326.520256, "side": "buy"}
{"type": "orderbook_delta", "seq": 3299, "price": 45, "quantity": 200, "ts": 1756428326.520706, "side": "sell"}
{"type": "orderbook_delta", "seq": 3300, "price": 10, "quantity": 8000, "ts": 1756428326.540944, "side": "buy"}
{"type": "orderbook_delta", "seq": 3301, "price": 37, "quantity": 500, "ts": 1756428326.546941, "side": "buy"}
{"type": "orderbook_delta", "seq": 3302, "price": 32, "quantity": 1250, "ts": 1756428326.548098, "side": "buy"}
{"type": "orderbook_delta", "seq": 3303, "price": 46, "quantity": -200, "ts": 1756428326.787775, "side": "sell"}
{"type": "orderbook_delta", "seq": 3304, "price": 45, "quantity": 200, "ts": 1756428326.787775, "side": "sell"}
{"type": "orderbook_delta", "seq": 3305, "price": 45, "quantity": -190, "ts": 1756428327.124935, "side": "sell"}
{"type": "trade", "seq": 37, "price": 44, "quantity": 50, "ts": 1756428327.124935, "side": "sell"}
{"type": "trade", "seq": 38, "price": 45, "quantity": 36, "ts": 1756428327.136838, "side": "buy"}
{"type": "orderbook_delta", "seq": 3306, "price": 34, "quantity": -200, "ts": 1756428327.136838, "side": "buy"}
{"type": "orderbook_delta", "seq": 3307, "price": 38, "quantity": -250, "ts": 1756428327.136979, "side": "buy"}
{"type": "orderbook_delta", "seq": 3308, "price": 37, "quantity": -500, "ts": 1756428327.138143, "side": "buy"}
{"type": "orderbook_delta", "seq": 3309, "price": 47, "quantity": -1250, "ts": 1756428327.141545, "side": "sell"}
{"type": "orderbook_delta", "seq": 3310, "price": 10, "quantity": -200, "ts": 1756428327.14163, "side": "buy"}
{"type": "orderbook_delta", "seq": 3311, "price": 44, "quantity": 0, "ts": 1756428327.142071, "side": "buy"}
{"type": "orderbook_delta", "seq": 3312, "price": 28, "quantity": 250, "ts": 1756428327.147505, "side": "buy"}
{"type": "orderbook_delta", "seq": 3313, "price": 45, "quantity": 0, "ts": 1756428327.147709, "side": "sell"}
{"type": "orderbook_delta", "seq": 3314, "price": 45, "quantity": -200, "ts": 1756428327.161982, "side": "sell"}
{"type": "orderbook_delta", "seq": 3315, "price": 10, "quantity": -8000, "ts": 1756428327.17239, "side": "buy"}
{"type": "orderbook_delta", "seq": 3316, "price": 80, "quantity": -200, "ts": 1756428327.17661, "side": "sell"}
{"type": "orderbook_delta", "seq": 3317, "price": 70, "quantity": 200, "ts": 1756428327.17661, "side": "sell"}
{"type": "orderbook_delta", "seq": 3318, "price": 44, "quantity": 190, "ts": 1756428327.185794, "side": "sell"}
{"type": "orderbook_delta", "seq": 3319, "price": 45, "quantity": -200, "ts": 1756428327.198457, "side": "sell"}
{"type": "orderbook_delta", "seq": 3320, "price": 44, "quantity": 200, "ts": 1756428327.198457, "side": "sell"}
{"type": "orderbook_delta", "seq": 3321, "price": 32, "quantity": -1250, "ts": 1756428327.222158, "side": "buy"}
{"type": "orderbook_delta", "seq": 3322, "price": 46, "quantity": 1250, "ts": 1756428327.222844, "side": "sell"}
{"type": "orderbook_delta", "seq": 3323, "price": 36, "quantity": 500, "ts": 1756428327.226432, "side": "buy"}
{"type": "orderbook_delta", "seq": 3324, "price": 74, "quantity": -8000, "ts": 1756428327.227058, "side": "sell"}
{"type": "orderbook_delta", "seq": 3325, "price": 33, "quantity": 200, "ts": 1756428327.229817, "side": "buy"}
{"type": "orderbook_delta", "seq": 3326, "price": 44, "quantity": 200, "ts": 1756428327.262846, "side": "sell"}
{"type": "orderbook_delta", "seq": 3327, "price": 44, "quantity": -190, "ts": 1756428327.269695, "side": "sell"}
{"type": "orderbook_delta", "seq": 3328, "price": 45, "quantity": -464, "ts": 1756428327.300205, "side": "sell"}
{"type": "orderbook_delta", "seq": 3329, "price": 31, "quantity": 1250, "ts": 1756428327.307489, "side": "buy"}
{"type": "orderbook_delta", "seq": 3330, "price": 69, "quantity": 8000, "ts": 1756428327.307987, "side": "sell"}
{"type": "orderbook_delta", "seq": 3331, "price": 43, "quantity": 190, "ts": 1756428327.308249, "side": "sell"}
{"type": "orderbook_delta", "seq": 3332, "price": 43, "quantity": 500, "ts": 1756428327.339953, "side": "sell"}
{"type": "orderbook_delta", "seq": 3333, "price": 44, "quantity": -200, "ts": 1756428327.470506, "side": "sell"}
{"type": "orderbook_delta", "seq": 3334, "price": 42, "quantity": 200, "ts": 1756428327.470506, "side": "sell"}
{"type": "orderbook_delta", "seq": 3335, "price": 43, "quantity": -500, "ts": 1756428327.471374, "side": "sell"}
{"type": "orderbook_delta", "seq": 3336, "price": 44, "quantity": -200, "ts": 1756428327.566621, "side": "sell"}
{"type": "orderbook_delta", "seq": 3337, "price": 41, "quantity": 500, "ts": 1756428327.567236, "side": "sell"}
{"type": "orderbook_delta", "seq": 3338, "price": 45, "quantity": 200, "ts": 1756428327.628739, "side": "sell"}
{"type": "orderbook_delta", "seq": 3339, "price": 31, "quantity": -1250, "ts": 1756428327.880395, "side": "buy"}
{"type": "orderbook_delta", "seq": 3340, "price": 41, "quantity": -500, "ts": 1756428327.882283, "side": "sell"}
{"type": "orderbook_delta", "seq": 3341, "price": 33, "quantity": -200, "ts": 1756428327.88234, "side": "buy"}
{"type": "orderbook_delta", "seq": 3342, "price": 32, "quantity": 1250, "ts": 1756428327.913673, "side": "buy"}
{"type": "orderbook_delta", "seq": 3343, "price": 34, "quantity": 200, "ts": 1756428327.916848, "side": "buy"}
{"type": "orderbook_delta", "seq": 3344, "price": 42, "quantity": 500, "ts": 1756428327.922074, "side": "sell"}
{"type": "orderbook_delta", "seq": 3345, "price": 36, "quantity": -250, "ts": 1756428327.996727, "side": "buy"}
{"type": "orderbook_delta", "seq": 3346, "price": 36, "quantity": -500, "ts": 1756428327.999573, "side": "buy"}
{"type": "orderbook_delta", "seq": 3347, "price": 42, "quantity": -500, "ts": 1756428327.999751, "side": "sell"}
{"type": "orderbook_delta", "seq": 3348, "price": 34, "quantity": -200, "ts": 1756428328.000031, "side": "buy"}
{"type": "orderbook_delta", "seq": 3349, "price": 32, "quantity": -1250, "ts": 1756428328.003784, "side": "buy"}
{"type": "orderbook_delta", "seq": 3350, "price": 26, "quantity": 250, "ts": 1756428328.005153, "side": "buy"}
{"type": "orderbook_delta", "seq": 3351, "price": 46, "quantity": -1250, "ts": 1756428328.010507, "side": "sell"}
{"type": "orderbook_delta", "seq": 3352, "price": 42, "quantity": -200, "ts": 1756428328.036057, "side": "sell"}
{"type": "orderbook_delta", "seq": 3353, "price": 41, "quantity": 200, "ts": 1756428328.036057, "side": "sell"}
{"type": "orderbook_delta", "seq": 3354, "price": 45, "quantity": -200, "ts": 1756428328.038268, "side": "sell"}
{"type": "orderbook_delta", "seq": 3355, "price": 32, "quantity": 200, "ts": 1756428328.048938, "side": "buy"}
{"type": "orderbook_delta", "seq": 3356, "price": 30, "quantity": 1250, "ts": 1756428328.051718, "side": "buy"}
{"type": "orderbook_delta", "seq": 3357, "price": 34, "quantity": 500, "ts": 1756428328.05202, "side": "buy"}
{"type": "orderbook_delta", "seq": 3358, "price": 45, "quantity": 1250, "ts": 1756428328.052315, "side": "sell"}
{"type": "orderbook_delta", "seq": 3359, "price": 41, "quantity": 500, "ts": 1756428328.052541, "side": "sell"}
{"type": "orderbook_delta", "seq": 3360, "price": 46, "quantity": -250, "ts": 1756428328.077781, "side": "sell"}
{"type": "orderbook_delta", "seq": 3361, "price": 56, "quantity": 250, "ts": 1756428328.078511, "side": "sell"}
{"type": "orderbook_delta", "seq": 3362, "price": 41, "quantity": -200, "ts": 1756428328.095029, "side": "sell"}
{"type": "orderbook_delta", "seq": 3363, "price": 45, "quantity": 200, "ts": 1756428328.095029, "side": "sell"}
{"type": "orderbook_delta", "seq": 3364, "price": 41, "quantity": -500, "ts": 1756428328.0953, "side": "sell"}
{"type": "orderbook_delta", "seq": 3365, "price": 32, "quantity": -200, "ts": 1756428328.096333, "side": "buy"}
{"type": "orderbook_delta", "seq": 3366, "price": 69, "quantity": -8000, "ts": 1756428328.097984, "side": "sell"}
{"type": "orderbook_delta", "seq": 3367, "price": 43, "quantity": -190, "ts": 1756428328.134237, "side": "sell"}
{"type": "orderbook_delta", "seq": 3368, "price": 34, "quantity": -250, "ts": 1756428328.138981, "side": "buy"}
{"type": "orderbook_delta", "seq": 3369, "price": 24, "quantity": 250, "ts": 1756428328.139262, "side": "buy"}
{"type": "orderbook_delta", "seq": 3370, "price": 44, "quantity": 100, "ts": 1756428328.14427, "side": "buy"}
{"type": "trade", "seq": 39, "price": 44, "quantity": 100, "ts": 1756428328.146164, "side": "sell"}
{"type": "orderbook_delta", "seq": 3371, "price": 52, "quantity": -250, "ts": 1756428328.146164, "side": "sell"}
{"type": "orderbook_delta", "seq": 3372, "price": 44, "quantity": 0, "ts": 1756428328.146749, "side": "buy"}
{"type": "orderbook_delta", "seq": 3373, "price": 44, "quantity": 150, "ts": 1756428328.146749, "side": "sell"}
{"type": "orderbook_delta", "seq": 3374, "price": 42, "quantity": 250, "ts": 1756428328.177458, "side": "sell"}
{"type": "orderbook_delta", "seq": 3375, "price": 42, "quantity": 200, "ts": 1756428328.181403, "side": "sell"}
{"type": "orderbook_delta", "seq": 3376, "price": 45, "quantity": -1250, "ts": 1756428328.182258, "side": "sell"}
{"type": "orderbook_delta", "seq": 3377, "price": 46, "quantity": 250, "ts": 1756428328.196485, "side": "sell"}
{"type": "orderbook_delta", "seq": 3378, "price": 66, "quantity": 8000, "ts": 1756428328.206019, "side": "sell"}
{"type": "orderbook_delta", "seq": 3379, "price": 43, "quantity": 500, "ts": 1756428328.206401, "side": "sell"}
{"type": "orderbook_delta", "seq": 3380, "price": 31, "quantity": 200, "ts": 1756428328.211223, "side": "buy"}
{"type": "orderbook_delta", "seq": 3381, "price": 44, "quantity": 1250, "ts": 1756428328.242471, "side": "sell"}
{"type": "orderbook_delta", "seq": 3382, "price": 44, "quantity": -150, "ts": 1756428328.342043, "side": "sell"}
{"type": "orderbook_delta", "seq": 3383, "price": 43, "quantity": -500, "ts": 1756428328.34361, "side": "sell"}
{"type": "orderbook_delta", "seq": 3384, "price": 34, "quantity": -500, "ts": 1756428328.345117, "side": "buy"}
{"type": "orderbook_delta", "seq": 3385, "price": 30, "quantity": -1250, "ts": 1756428328.347593, "side": "buy"}
{"type": "orderbook_delta", "seq": 3386, "price": 31, "quantity": -200, "ts": 1756428328.347862, "side": "buy"}
{"type": "orderbook_delta", "seq": 3387, "price": 44, "quantity": -1250, "ts": 1756428328.347912, "side": "sell"}
{"type": "orderbook_delta", "seq": 3388, "price": 66, "quantity": -8000, "ts": 1756428328.348526, "side": "sell"}
{"type": "orderbook_delta", "seq": 3389, "price": 42, "quantity": -250, "ts": 1756428328.358275, "side": "sell"}
{"type": "orderbook_delta", "seq": 3390, "price": 56, "quantity": -250, "ts": 1756428328.358395, "side": "sell"}
{"type": "orderbook_delta", "seq": 3391, "price": 45, "quantity": -200, "ts": 1756428328.364062, "side": "sell"}
{"type": "orderbook_delta", "seq": 3392, "price": 42, "quantity": 200, "ts": 1756428328.364062, "side": "sell"}
{"type": "orderbook_delta", "seq": 3393, "price": 42, "quantity": -200, "ts": 1756428328.364662, "side": "sell"}
{"type": "orderbook_delta", "seq": 3394, "price": 54, "quantity": -250, "ts": 1756428328.378199, "side": "sell"}
{"type": "orderbook_delta", "seq": 3395, "price": 41, "quantity": 500, "ts": 1756428328.380371, "side": "sell"}
{"type": "orderbook_delta", "seq": 3396, "price": 32, "quantity": 500, "ts": 1756428328.381825, "side": "buy"}
{"type": "orderbook_delta", "seq": 3397, "price": 41, "quantity": 1250, "ts": 1756428328.414965, "side": "sell"}
{"type": "orderbook_delta", "seq": 3398, "price": 29, "quantity": 200, "ts": 1756428328.415289, "side": "buy"}
{"type": "orderbook_delta", "seq": 3399, "price": 65, "quantity": 8000, "ts": 1756428328.415624, "side": "sell"}
{"type": "orderbook_delta", "seq": 3400, "price": 41, "quantity": 200, "ts": 1756428328.416714, "side": "sell"}
{"type": "orderbook_delta", "seq": 3401, "price": 32, "quantity": -250, "ts": 1756428328.427312, "side": "buy"}
{"type": "orderbook_delta", "seq": 3402, "price": 22, "quantity": 250, "ts": 1756428328.429867, "side": "buy"}
{"type": "orderbook_delta", "seq": 3403, "price": 42, "quantity": 250, "ts": 1756428328.433208, "side": "sell"}
{"type": "orderbook_delta", "seq": 3404, "price": 32, "quantity": -500, "ts": 1756428328.445314, "side": "buy"}
{"type": "orderbook_delta", "seq": 3405, "price": 44, "quantity": 250, "ts": 1756428328.446507, "side": "sell"}
{"type": "orderbook_delta", "seq": 3406, "price": 31, "quantity": 500, "ts": 1756428328.476124, "side": "buy"}
{"type": "orderbook_delta", "seq": 3407, "price": 27, "quantity": 1250, "ts": 1756428328.535245, "side": "buy"}
{"type": "orderbook_delta", "seq": 3408, "price": 27, "quantity": -1250, "ts": 1756428328.607262, "side": "buy"}
{"type": "orderbook_delta", "seq": 3409, "price": 29, "quantity": -200, "ts": 1756428328.60777, "side": "buy"}
{"type": "orderbook_delta", "seq": 3410, "price": 41, "quantity": -1250, "ts": 1756428328.628871, "side": "sell"}
{"type": "orderbook_delta", "seq": 3411, "price": 29, "quantity": 1250, "ts": 1756428328.685916, "side": "buy"}
{"type": "orderbook_delta", "seq": 3412, "price": 43, "quantity": 1250, "ts": 1756428328.686213, "side": "sell"}
{"type": "orderbook_delta", "seq": 3413, "price": 42, "quantity": -200, "ts": 1756428328.687649, "side": "sell"}
{"type": "orderbook_delta", "seq": 3414, "price": 41, "quantity": 200, "ts": 1756428328.687649, "side": "sell"}
{"type": "orderbook_delta", "seq": 3415, "price": 30, "quantity": 200, "ts": 1756428328.688325, "side": "buy"}
{"type": "orderbook_delta", "seq": 3416, "price": 41, "quantity": -500, "ts": 1756428328.83848, "side": "sell"}
{"type": "orderbook_delta", "seq": 3417, "price": 40, "quantity": 500, "ts": 1756428328.895585, "side": "sell"}
{"type": "orderbook_delta", "seq": 3418, "price": 41, "quantity": -200, "ts": 1756428328.957709, "side": "sell"}
{"type": "orderbook_delta", "seq": 3419, "price": 39, "quantity": 200, "ts": 1756428328.957709, "side": "sell"}
{"type": "orderbook_delta", "seq": 3420, "price": 40, "quantity": -500, "ts": 1756428329.001363, "side": "sell"}
{"type": "orderbook_delta", "seq": 3421, "price": 41, "quantity": 90, "ts": 1756428329.017718, "side": "sell"}
{"type": "orderbook_delta", "seq": 3422, "price": 29, "quantity": -1250, "ts": 1756428329.034844, "side": "buy"}
{"type": "orderbook_delta", "seq": 3423, "price": 43, "quantity": -1250, "ts": 1756428329.036138, "side": "sell"}
{"type": "orderbook_delta", "seq": 3424, "price": 38, "quantity": 500, "ts": 1756428329.063846, "side": "sell"}
{"type": "orderbook_delta", "seq": 3425, "price": 28, "quantity": 1250, "ts": 1756428329.105703, "side": "buy"}
{"type": "orderbook_delta", "seq": 3426, "price": 42, "quantity": 1250, "ts": 1756428329.112092, "side": "sell"}
{"type": "orderbook_delta", "seq": 3427, "price": 41, "quantity": -90, "ts": 1756428329.141142, "side": "sell"}
{"type": "orderbook_delta", "seq": 3428, "price": 32, "quantity": 250, "ts": 1756428329.145634, "side": "buy"}
{"type": "orderbook_delta", "seq": 3429, "price": 39, "quantity": -200, "ts": 1756428329.15588, "side": "sell"}
{"type": "orderbook_delta", "seq": 3430, "price": 37, "quantity": 200, "ts": 1756428329.15588, "side": "sell"}
{"type": "orderbook_delta", "seq": 3431, "price": 22, "quantity": -250, "ts": 1756428329.157471, "side": "buy"}
{"type": "orderbook_delta", "seq": 3432, "price": 40, "quantity": 250, "ts": 1756428329.167532, "side": "sell"}
{"type": "orderbook_delta", "seq": 3433, "price": 31, "quantity": -500, "ts": 1756428329.187316, "side": "buy"}
{"type": "orderbook_delta", "seq": 3434, "price": 50, "quantity": -250, "ts": 1756428329.197419, "side": "sell"}
{"type": "orderbook_delta", "seq": 3435, "price": 38, "quantity": -500, "ts": 1756428329.209647, "side": "sell"}
{"type": "orderbook_delta", "seq": 3436, "price": 39, "quantity": 90, "ts": 1756428329.240995, "side": "sell"}
{"type": "orderbook_delta", "seq": 3437, "price": 32, "quantity": 500, "ts": 1756428329.246299, "side": "buy"}
{"type": "orderbook_delta", "seq": 3438, "price": 39, "quantity": 500, "ts": 1756428329.251481, "side": "sell"}
{"type": "orderbook_delta", "seq": 3439, "price": 39, "quantity": -500, "ts": 1756428329.294622, "side": "sell"}
{"type": "orderbook_delta", "seq": 3440, "price": 38, "quantity": 500, "ts": 1756428329.357618, "side": "sell"}
{"type": "orderbook_delta", "seq": 3441, "price": 37, "quantity": -200, "ts": 1756428329.408925, "side": "sell"}
{"type": "orderbook_delta", "seq": 3442, "price": 39, "quantity": 200, "ts": 1756428329.408925, "side": "sell"}
{"type": "orderbook_delta", "seq": 3443, "price": 50, "quantity": 250, "ts": 1756428329.516442, "side": "sell"}
{"type": "orderbook_delta", "seq": 3444, "price": 40, "quantity": -250, "ts": 1756428329.519574, "side": "sell"}
{"type": "orderbook_delta", "seq": 3445, "price": 30, "quantity": -200, "ts": 1756428329.520761, "side": "buy"}
{"type": "orderbook_delta", "seq": 3446, "price": 28, "quantity": -1250, "ts": 1756428329.521296, "side": "buy"}
{"type": "orderbook_delta", "seq": 3447, "price": 42, "quantity": -1250, "ts": 1756428329.521681, "side": "sell"}
{"type": "orderbook_delta", "seq": 3448, "price": 32, "quantity": -500, "ts": 1756428329.524517, "side": "buy"}
{"type": "orderbook_delta", "seq": 3449, "price": 41, "quantity": -200, "ts": 1756428329.525053, "side": "sell"}
{"type": "orderbook_delta", "seq": 3450, "price": 65, "quantity": -8000, "ts": 1756428329.526892, "side": "sell"}
{"type": "orderbook_delta", "seq": 3451, "price": 39, "quantity": -200, "ts": 1756428329.52851, "side": "sell"}
{"type": "orderbook_delta", "seq": 3452, "price": 37, "quantity": 200, "ts": 1756428329.52851, "side": "sell"}
{"type": "orderbook_delta", "seq": 3453, "price": 38, "quantity": -500, "ts": 1756428329.530058, "side": "sell"}
{"type": "orderbook_delta", "seq": 3454, "price": 32, "quantity": -250, "ts": 1756428329.56761, "side": "buy"}
{"type": "orderbook_delta", "seq": 3455, "price": 22, "quantity": 250, "ts": 1756428329.570053, "side": "buy"}
{"type": "orderbook_delta", "seq": 3456, "price": 32, "quantity": 200, "ts": 1756428329.574302, "side": "buy"}
{"type": "orderbook_delta", "seq": 3457, "price": 41, "quantity": 500, "ts": 1756428329.575054, "side": "sell"}
{"type": "orderbook_delta", "seq": 3458, "price": 44, "quantity": 1250, "ts": 1756428329.575376, "side": "sell"}
{"type": "orderbook_delta", "seq": 3459, "price": 43, "quantity": 200, "ts": 1756428329.576464, "side": "sell"}
{"type": "orderbook_delta", "seq": 3460, "price": 30, "quantity": 1250, "ts": 1756428329.577103, "side": "buy"}
{"type": "orderbook_delta", "seq": 3461, "price": 34, "quantity": 500, "ts": 1756428329.577561, "side": "buy"}
{"type": "orderbook_delta", "seq": 3462, "price": 69, "quantity": 8000, "ts": 1756428329.585974, "side": "sell"}
{"type": "orderbook_delta", "seq": 3463, "price": 52, "quantity": 250, "ts": 1756428329.586968, "side": "sell"}
{"type": "orderbook_delta", "seq": 3464, "price": 42, "quantity": -250, "ts": 1756428329.587171, "side": "sell"}
{"type": "orderbook_delta", "seq": 3465, "price": 32, "quantity": -200, "ts": 1756428329.611782, "side": "buy"}
{"type": "orderbook_delta", "seq": 3466, "price": 41, "quantity": -500, "ts": 1756428329.621466, "side": "sell"}
{"type": "orderbook_delta", "seq": 3467, "price": 31, "quantity": 200, "ts": 1756428329.648632, "side": "buy"}
{"type": "orderbook_delta", "seq": 3468, "price": 43, "quantity": 500, "ts": 1756428329.66175, "side": "sell"}
{"type": "orderbook_delta", "seq": 3469, "price": 34, "quantity": -500, "ts": 1756428329.675474, "side": "buy"}
{"type": "orderbook_delta", "seq": 3470, "price": 30, "quantity": -1250, "ts": 1756428329.675682, "side": "buy"}
{"type": "orderbook_delta", "seq": 3471, "price": 44, "quantity": -1250, "ts": 1756428329.675734, "side": "sell"}
{"type": "orderbook_delta", "seq": 3472, "price": 31, "quantity": 1250, "ts": 1756428329.721187, "side": "buy"}
{"type": "orderbook_delta", "seq": 3473, "price": 35, "quantity": 500, "ts": 1756428329.721493, "side": "buy"}
{"type": "orderbook_delta", "seq": 3474, "price": 45, "quantity": 1250, "ts": 1756428329.724599, "side": "sell"}
{"type": "orderbook_delta", "seq": 3475, "price": 32, "quantity": 250, "ts": 1756428329.975908, "side": "buy"}
{"type": "orderbook_delta", "seq": 3476, "price": 22, "quantity": -250, "ts": 1756428329.976142, "side": "buy"}
{"type": "orderbook_delta", "seq": 3477, "price": 42, "quantity": 250, "ts": 1756428330.007816, "side": "sell"}
{"type": "orderbook_delta", "seq": 3478, "price": 52, "quantity": -250, "ts": 1756428330.008023, "side": "sell"}
{"type": "orderbook_delta", "seq": 3479, "price": 43, "quantity": -500, "ts": 1756428330.096407, "side": "sell"}
{"type": "orderbook_delta", "seq": 3480, "price": 31, "quantity": -200, "ts": 1756428330.096892, "side": "buy"}
{"type": "orderbook_delta", "seq": 3481, "price": 39, "quantity": -90, "ts": 1756428330.118594, "side": "sell"}
{"type": "orderbook_delta", "seq": 3482, "price": 34, "quantity": 250, "ts": 1756428330.13651, "side": "buy"}
{"type": "orderbook_delta", "seq": 3483, "price": 32, "quantity": 200, "ts": 1756428330.145426, "side": "buy"}
{"type": "orderbook_delta", "seq": 3484, "price": 41, "quantity": 500, "ts": 1756428330.146999, "side": "sell"}
{"type": "orderbook_delta", "seq": 3485, "price": 24, "quantity": -250, "ts": 1756428330.156904, "side": "buy"}
{"type": "orderbook_delta", "seq": 3486, "price": 40, "quantity": 90, "ts": 1756428330.201861, "side": "sell"}
{"type": "orderbook_delta", "seq": 3487, "price": 41, "quantity": -500, "ts": 1756428330.547361, "side": "sell"}
{"type": "orderbook_delta", "seq": 3488, "price": 69, "quantity": -8000, "ts": 1756428330.548136, "side": "sell"}
{"type": "orderbook_delta", "seq": 3489, "price": 31, "quantity": -1250, "ts": 1756428330.549976, "side": "buy"}
{"type": "orderbook_delta", "seq": 3490, "price": 32, "quantity": -200, "ts": 1756428330.551272, "side": "buy"}
{"type": "orderbook_delta", "seq": 3491, "price": 35, "quantity": -500, "ts": 1756428330.560241, "side": "buy"}
{"type": "orderbook_delta", "seq": 3492, "price": 45, "quantity": -1250, "ts": 1756428330.562615, "side": "sell"}
{"type": "orderbook_delta", "seq": 3493, "price": 24, "quantity": 250, "ts": 1756428330.599501, "side": "buy"}
{"type": "orderbook_delta", "seq": 3494, "price": 32, "quantity": -250, "ts": 1756428330.607064, "side": "buy"}
{"type": "orderbook_delta", "seq": 3495, "price": 52, "quantity": 250, "ts": 1756428330.607322, "side": "sell"}
{"type": "orderbook_delta", "seq": 3496, "price": 42, "quantity": -250, "ts": 1756428330.61107, "side": "sell"}
{"type": "orderbook_delta", "seq": 3497, "price": 22, "quantity": 250, "ts": 1756428330.616079, "side": "buy"}
{"type": "orderbook_delta", "seq": 3498, "price": 34, "quantity": -250, "ts": 1756428330.625278, "side": "buy"}
{"type": "orderbook_delta", "seq": 3499, "price": 43, "quantity": -200, "ts": 1756428330.63828, "side": "sell"}
{"type": "orderbook_delta", "seq": 3500, "price": 35, "quantity": 100, "ts": 1756428330.650387, "side": "buy"}
{"type": "orderbook_delta", "seq": 3501, "price": 20, "quantity": 250, "ts": 1756428330.696148, "side": "buy"}
{"type": "orderbook_delta", "seq": 3502, "price": 29, "quantity": 200, "ts": 1756428330.696397, "side": "buy"}
{"type": "orderbook_delta", "seq": 3503, "price": 37, "quantity": 500, "ts": 1756428330.696965, "side": "sell"}
{"type": "orderbook_delta", "seq": 3504, "price": 65, "quantity": 8000, "ts": 1756428330.697218, "side": "sell"}
{"type": "orderbook_delta", "seq": 3505, "price": 43, "quantity": 1250, "ts": 1756428330.697443, "side": "sell"}
{"type": "orderbook_delta", "seq": 3506, "price": 27, "quantity": 1250, "ts": 1756428330.698131, "side": "buy"}
{"type": "orderbook_delta", "seq": 3507, "price": 31, "quantity": 500, "ts": 1756428330.699312, "side": "buy"}
{"type": "orderbook_delta", "seq": 3508, "price": 43, "quantity": 200, "ts": 1756428330.751433, "side": "sell"}
{"type": "orderbook_delta", "seq": 3509, "price": 30, "quantity": -250, "ts": 1756428330.751753, "side": "buy"}
{"type": "orderbook_delta", "seq": 3510, "price": 31, "quantity": -500, "ts": 1756428330.785725, "side": "buy"}
{"type": "orderbook_delta", "seq": 3511, "price": 29, "quantity": 500, "ts": 1756428330.826892, "side": "buy"}
{"type": "orderbook_delta", "seq": 3512, "price": 30, "quantity": 250, "ts": 1756428331.018946, "side": "buy"}
{"type": "orderbook_delta", "seq": 3513, "price": 20, "quantity": -250, "ts": 1756428331.019469, "side": "buy"}
{"type": "orderbook_delta", "seq": 3514, "price": 42, "quantity": 250, "ts": 1756428331.037593, "side": "sell"}
{"type": "orderbook_delta", "seq": 3515, "price": 52, "quantity": -250, "ts": 1756428331.037808, "side": "sell"}
{"type": "orderbook_delta", "seq": 3516, "price": 29, "quantity": -500, "ts": 1756428331.057737, "side": "buy"}
{"type": "orderbook_delta", "seq": 3517, "price": 43, "quantity": -200, "ts": 1756428331.075859, "side": "sell"}
{"type": "orderbook_delta", "seq": 3518, "price": 43, "quantity": -1250, "ts": 1756428331.078393, "side": "sell"}
{"type": "orderbook_delta", "seq": 3519, "price": 37, "quantity": -200, "ts": 1756428331.092755, "side": "sell"}
{"type": "orderbook_delta", "seq": 3520, "price": 39, "quantity": 200, "ts": 1756428331.092755, "side": "sell"}
{"type": "orderbook_delta", "seq": 3521, "price": 31, "quantity": 500, "ts": 1756428331.1039, "side": "buy"}
{"type": "orderbook_delta", "seq": 3522, "price": 40, "quantity": -90, "ts": 1756428331.115438, "side": "sell"}
{"type": "orderbook_delta", "seq": 3523, "price": 20, "quantity": 250, "ts": 1756428331.126856, "side": "buy"}
{"type": "orderbook_delta", "seq": 3524, "price": 41, "quantity": 200, "ts": 1756428331.127091, "side": "sell"}
{"type": "orderbook_delta", "seq": 3525, "price": 41, "quantity": 1250, "ts": 1756428331.127353, "side": "sell"}
{"type": "orderbook_delta", "seq": 3526, "price": 30, "quantity": -250, "ts": 1756428331.137432, "side": "buy"}
{"type": "orderbook_delta", "seq": 3527, "price": 39, "quantity": -200, "ts": 1756428331.138417, "side": "sell"}
{"type": "orderbook_delta", "seq": 3528, "price": 36, "quantity": 200, "ts": 1756428331.138417, "side": "sell"}
{"type": "orderbook_delta", "seq": 3529, "price": 37, "quantity": -500, "ts": 1756428331.139995, "side": "sell"}
{"type": "orderbook_delta", "seq": 3530, "price": 40, "quantity": 250, "ts": 1756428331.146301, "side": "sell"}
{"type": "orderbook_delta", "seq": 3531, "price": 50, "quantity": -250, "ts": 1756428331.176291, "side": "sell"}
{"type": "orderbook_delta", "seq": 3532, "price": 31, "quantity": -500, "ts": 1756428331.176987, "side": "buy"}
{"type": "orderbook_delta", "seq": 3533, "price": 41, "quantity": 500, "ts": 1756428331.17727, "side": "sell"}
{"type": "orderbook_delta", "seq": 3534, "price": 41, "quantity": -200, "ts": 1756428331.18789, "side": "sell"}
{"type": "orderbook_delta", "seq": 3535, "price": 20, "quantity": -250, "ts": 1756428331.191049, "side": "buy"}
{"type": "orderbook_delta", "seq": 3536, "price": 29, "quantity": 500, "ts": 1756428331.212897, "side": "buy"}
{"type": "orderbook_delta", "seq": 3537, "price": 41, "quantity": -500, "ts": 1756428331.216555, "side": "sell"}
{"type": "orderbook_delta", "seq": 3538, "price": 40, "quantity": 200, "ts": 1756428331.226425, "side": "sell"}
{"type": "orderbook_delta", "seq": 3539, "price": 37, "quantity": 90, "ts": 1756428331.232225, "side": "sell"}
{"type": "orderbook_delta", "seq": 3540, "price": 39, "quantity": 500, "ts": 1756428331.250251, "side": "sell"}
{"type": "orderbook_delta", "seq": 3541, "price": 39, "quantity": -500, "ts": 1756428331.290382, "side": "sell"}
{"type": "orderbook_delta", "seq": 3542, "price": 37, "quantity": 500, "ts": 1756428331.33424, "side": "sell"}
{"type": "orderbook_delta", "seq": 3543, "price": 27, "quantity": -1250, "ts": 1756428331.787239, "side": "buy"}
{"type": "orderbook_delta", "seq": 3544, "price": 41, "quantity": -1250, "ts": 1756428331.787871, "side": "sell"}
{"type": "orderbook_delta", "seq": 3545, "price": 37, "quantity": -500, "ts": 1756428331.787987, "side": "sell"}
{"type": "orderbook_delta", "seq": 3546, "price": 28, "quantity": 1250, "ts": 1756428331.830753, "side": "buy"}
{"type": "orderbook_delta", "seq": 3547, "price": 39, "quantity": 500, "ts": 1756428331.831059, "side": "sell"}
{"type": "orderbook_delta", "seq": 3548, "price": 42, "quantity": 1250, "ts": 1756428331.831914, "side": "sell"}
