{"type": "orderbook_delta", "seq": 5315, "price": 46, "quantity": -200, "ts": 1756428415.160717, "side": "buy"}
{"type": "orderbook_delta", "seq": 5316, "price": 44, "quantity": -1250, "ts": 1756428415.161519, "side": "buy"}
{"type": "orderbook_delta", "seq": 5317, "price": 57, "quantity": -200, "ts": 1756428415.165636, "side": "sell"}
{"type": "orderbook_delta", "seq": 5318, "price": 68, "quantity": -250, "ts": 1756428415.166983, "side": "sell"}
{"type": "orderbook_delta", "seq": 5319, "price": 59, "quantity": -1250, "ts": 1756428415.168513, "side": "sell"}
{"type": "orderbook_delta", "seq": 5320, "price": 60, "quantity": 1250, "ts": 1756428415.213383, "side": "sell"}
{"type": "orderbook_delta", "seq": 5321, "price": 58, "quantity": 200, "ts": 1756428415.215904, "side": "sell"}
{"type": "orderbook_delta", "seq": 5322, "price": 47, "quantity": 200, "ts": 1756428415.21629, "side": "buy"}
{"type": "orderbook_delta", "seq": 5323, "price": 45, "quantity": 1250, "ts": 1756428415.216972, "side": "buy"}
{"type": "orderbook_delta", "seq": 5324, "price": 50, "quantity": -250, "ts": 1756428415.226509, "side": "buy"}
{"type": "orderbook_delta", "seq": 5325, "price": 55, "quantity": 1000, "ts": 1756428415.270946, "side": "sell"}
{"type": "orderbook_delta", "seq": 5326, "price": 56, "quantity": -500, "ts": 1756428415.374481, "side": "sell"}
{"type": "orderbook_delta", "seq": 5327, "price": 54, "quantity": 100, "ts": 1756428415.388239, "side": "buy"}
{"type": "orderbook_delta", "seq": 5328, "price": 55, "quantity": 500, "ts": 1756428415.406628, "side": "sell"}
{"type": "orderbook_delta", "seq": 5329, "price": 66, "quantity": -250, "ts": 1756428416.129993, "side": "sell"}
{"type": "orderbook_delta", "seq": 5330, "price": 56, "quantity": 250, "ts": 1756428416.132269, "side": "sell"}
{"type": "orderbook_delta", "seq": 5331, "price": 66, "quantity": 250, "ts": 1756428416.174971, "side": "sell"}
{"type": "orderbook_delta", "seq": 5332, "price": 56, "quantity": -250, "ts": 1756428416.177122, "side": "sell"}
{"type": "orderbook_delta", "seq": 5333, "price": 45, "quantity": -1250, "ts": 1756428416.189576, "side": "buy"}
{"type": "orderbook_delta", "seq": 5334, "price": 58, "quantity": -200, "ts": 1756428416.191416, "side": "sell"}
{"type": "orderbook_delta", "seq": 5335, "price": 47, "quantity": -200, "ts": 1756428416.191485, "side": "buy"}
{"type": "orderbook_delta", "seq": 5336, "price": 49, "quantity": -500, "ts": 1756428416.19154, "side": "buy"}
{"type": "orderbook_delta", "seq": 5337, "price": 60, "quantity": -1250, "ts": 1756428416.192806, "side": "sell"}
{"type": "orderbook_delta", "seq": 5338, "price": 57, "quantity": 200, "ts": 1756428416.245494, "side": "sell"}
{"type": "orderbook_delta", "seq": 5339, "price": 48, "quantity": 500, "ts": 1756428416.245848, "side": "buy"}
{"type": "orderbook_delta", "seq": 5340, "price": 44, "quantity": 1250, "ts": 1756428416.246656, "side": "buy"}
{"type": "orderbook_delta", "seq": 5341, "price": 46, "quantity": 200, "ts": 1756428416.247132, "side": "buy"}
{"type": "orderbook_delta", "seq": 5342, "price": 59, "quantity": 1250, "ts": 1756428416.249328, "side": "sell"}
{"type": "orderbook_delta", "seq": 5343, "price": 47, "quantity": -100, "ts": 1756428416.357628, "side": "buy"}
{"type": "orderbook_delta", "seq": 5344, "price": 49, "quantity": 100, "ts": 1756428416.357628, "side": "buy"}
{"type": "orderbook_delta", "seq": 5345, "price": 57, "quantity": -200, "ts": 1756428416.412974, "side": "sell"}
{"type": "orderbook_delta", "seq": 5346, "price": 56, "quantity": 200, "ts": 1756428416.412974, "side": "sell"}
{"type": "orderbook_delta", "seq": 5347, "price": 46, "quantity": -200, "ts": 1756428416.964327, "side": "buy"}
{"type": "orderbook_delta", "seq": 5348, "price": 57, "quantity": -200, "ts": 1756428416.964401, "side": "sell"}
{"type": "orderbook_delta", "seq": 5349, "price": 44, "quantity": -1250, "ts": 1756428416.987334, "side": "buy"}
{"type": "orderbook_delta", "seq": 5350, "price": 59, "quantity": -1250, "ts": 1756428417.027181, "side": "sell"}
{"type": "orderbook_delta", "seq": 5351, "price": 45, "quantity": 200, "ts": 1756428417.069834, "side": "buy"}
{"type": "orderbook_delta", "seq": 5352, "price": 43, "quantity": 1250, "ts": 1756428417.072357, "side": "buy"}
{"type": "orderbook_delta", "seq": 5353, "price": 56, "quantity": 200, "ts": 1756428417.073758, "side": "sell"}
{"type": "orderbook_delta", "seq": 5354, "price": 58, "quantity": 1250, "ts": 1756428417.074788, "side": "sell"}
{"type": "orderbook_delta", "seq": 5355, "price": 58, "quantity": -100, "ts": 1756428417.473036, "side": "sell"}
{"type": "orderbook_delta", "seq": 5356, "price": 55, "quantity": 100, "ts": 1756428417.473036, "side": "sell"}
{"type": "orderbook_delta", "seq": 5357, "price": 48, "quantity": -500, "ts": 1756428417.711682, "side": "buy"}
{"type": "orderbook_delta", "seq": 5358, "price": 47, "quantity": 500, "ts": 1756428417.749578, "side": "buy"}
{"type": "orderbook_delta", "seq": 5359, "price": 55, "quantity": -100, "ts": 1756428417.934089, "side": "sell"}
{"type": "orderbook_delta", "seq": 5360, "price": 57, "quantity": 100, "ts": 1756428417.934089, "side": "sell"}
{"type": "orderbook_delta", "seq": 5361, "price": 66, "quantity": -250, "ts": 1756428418.114036, "side": "sell"}
{"type": "orderbook_delta", "seq": 5362, "price": 56, "quantity": 250, "ts": 1756428418.115952, "side": "sell"}
{"type": "orderbook_delta", "seq": 5363, "price": 49, "quantity": -100, "ts": 1756428419.172356, "side": "buy"}
{"type": "orderbook_delta", "seq": 5364, "price": 48, "quantity": 100, "ts": 1756428419.172356, "side": "buy"}
{"type": "orderbook_delta", "seq": 5365, "price": 57, "quantity": -100, "ts": 1756428419.749207, "side": "sell"}
{"type": "orderbook_delta", "seq": 5366, "price": 55, "quantity": 100, "ts": 1756428419.749207, "side": "sell"}
{"type": "orderbook_delta", "seq": 5367, "price": 48, "quantity": -100, "ts": 1756428419.977076, "side": "buy"}
{"type": "orderbook_delta", "seq": 5368, "price": 49, "quantity": 100, "ts": 1756428419.977076, "side": "buy"}
{"type": "trade", "seq": 60, "price": 55, "quantity": 35, "ts": 1756428420.0, "side": "buy"}
{"type": "orderbook_delta", "seq": 5369, "price": 55, "quantity": 0, "ts": 1756428420.08705, "side": "sell"}
{"type": "orderbook_delta", "seq": 5370, "price": 55, "quantity": -965, "ts": 1756428420.206811, "side": "sell"}
{"type": "orderbook_delta", "seq": 5371, "price": 45, "quantity": -200, "ts": 1756428420.206895, "side": "buy"}
{"type": "orderbook_delta", "seq": 5372, "price": 58, "quantity": -1250, "ts": 1756428420.20727, "side": "sell"}
{"type": "orderbook_delta", "seq": 5373, "price": 43, "quantity": -1250, "ts": 1756428420.207318, "side": "buy"}
{"type": "orderbook_delta", "seq": 5374, "price": 56, "quantity": -200, "ts": 1756428420.207561, "side": "sell"}
{"type": "trade", "seq": 61, "price": 54, "quantity": 100, "ts": 1756428420.252383, "side": "sell"}
{"type": "orderbook_delta", "seq": 5375, "price": 54, "quantity": 0, "ts": 1756428420.252383, "side": "buy"}
{"type": "orderbook_delta", "seq": 5376, "price": 54, "quantity": 901, "ts": 1756428420.252383, "side": "sell"}
{"type": "orderbook_delta", "seq": 5377, "price": 47, "quantity": -500, "ts": 1756428420.255858, "side": "buy"}
{"type": "orderbook_delta", "seq": 5378, "price": 49, "quantity": -100, "ts": 1756428420.271163, "side": "buy"}
{"type": "orderbook_delta", "seq": 5379, "price": 48, "quantity": 100, "ts": 1756428420.271163, "side": "buy"}
{"type": "orderbook_delta", "seq": 5380, "price": 38, "quantity": 250, "ts": 1756428420.287672, "side": "buy"}
{"type": "orderbook_delta", "seq": 5381, "price": 54, "quantity": -901, "ts": 1756428420.290926, "side": "sell"}
{"type": "orderbook_delta", "seq": 5382, "price": 56, "quantity": 1250, "ts": 1756428420.29106, "side": "sell"}
{"type": "orderbook_delta", "seq": 5383, "price": 43, "quantity": 200, "ts": 1756428420.291379, "side": "buy"}
{"type": "orderbook_delta", "seq": 5384, "price": 55, "quantity": 200, "ts": 1756428420.291691, "side": "sell"}
{"type": "orderbook_delta", "seq": 5385, "price": 55, "quantity": -500, "ts": 1756428420.293439, "side": "sell"}
{"type": "orderbook_delta", "seq": 5386, "price": 41, "quantity": 1250, "ts": 1756428420.293468, "side": "buy"}
{"type": "orderbook_delta", "seq": 5387, "price": 48, "quantity": -250, "ts": 1756428420.307709, "side": "buy"}
{"type": "orderbook_delta", "seq": 5388, "price": 44, "quantity": 500, "ts": 1756428420.311, "side": "buy"}
{"type": "orderbook_delta", "seq": 5389, "price": 53, "quantity": 901, "ts": 1756428420.330526, "side": "sell"}
{"type": "orderbook_delta", "seq": 5390, "price": 48, "quantity": -100, "ts": 1756428420.331148, "side": "buy"}
{"type": "orderbook_delta", "seq": 5391, "price": 46, "quantity": 100, "ts": 1756428420.331148, "side": "buy"}
{"type": "orderbook_delta", "seq": 5392, "price": 41, "quantity": -1250, "ts": 1756428420.332846, "side": "buy"}
{"type": "orderbook_delta", "seq": 5393, "price": 56, "quantity": -1250, "ts": 1756428420.332905, "side": "sell"}
{"type": "orderbook_delta", "seq": 5394, "price": 43, "quantity": -200, "ts": 1756428420.334988, "side": "buy"}
{"type": "orderbook_delta", "seq": 5395, "price": 30, "quantity": -200, "ts": 1756428420.336368, "side": "buy"}
{"type": "orderbook_delta", "seq": 5396, "price": 20, "quantity": 200, "ts": 1756428420.336368, "side": "buy"}
{"type": "orderbook_delta", "seq": 5397, "price": 55, "quantity": -200, "ts": 1756428420.337394, "side": "sell"}
{"type": "orderbook_delta", "seq": 5398, "price": 53, "quantity": 500, "ts": 1756428420.338901, "side": "sell"}
{"type": "orderbook_delta", "seq": 5399, "price": 56, "quantity": -200, "ts": 1756428420.351, "side": "sell"}
{"type": "orderbook_delta", "seq": 5400, "price": 53, "quantity": 200, "ts": 1756428420.351, "side": "sell"}
{"type": "orderbook_delta", "seq": 5401, "price": 90, "quantity": -200, "ts": 1756428420.369592, "side": "sell"}
{"type": "orderbook_delta", "seq": 5402, "price": 80, "quantity": 200, "ts": 1756428420.369592, "side": "sell"}
{"type": "orderbook_delta", "seq": 5403, "price": 55, "quantity": -100, "ts": 1756428420.375276, "side": "sell"}
{"type": "orderbook_delta", "seq": 5404, "price": 54, "quantity": 100, "ts": 1756428420.375276, "side": "sell"}
{"type": "orderbook_delta", "seq": 5405, "price": 39, "quantity": 1250, "ts": 1756428420.385481, "side": "buy"}
{"type": "orderbook_delta", "seq": 5406, "price": 54, "quantity": 1250, "ts": 1756428420.38579, "side": "sell"}
{"type": "orderbook_delta", "seq": 5407, "price": 41, "quantity": 200, "ts": 1756428420.386251, "side": "buy"}
{"type": "orderbook_delta", "seq": 5408, "price": 53, "quantity": 200, "ts": 1756428420.386507, "side": "sell"}
{"type": "orderbook_delta", "seq": 5409, "price": 53, "quantity": -500, "ts": 1756428420.389646, "side": "sell"}
{"type": "orderbook_delta", "seq": 5410, "price": 52, "quantity": 500, "ts": 1756428420.42704, "side": "sell"}
{"type": "orderbook_delta", "seq": 5411, "price": 54, "quantity": -1250, "ts": 1756428420.429096, "side": "sell"}
{"type": "orderbook_delta", "seq": 5412, "price": 53, "quantity": -200, "ts": 1756428420.439585, "side": "sell"}
{"type": "orderbook_delta", "seq": 5413, "price": 46, "quantity": -100, "ts": 1756428420.440539, "side": "buy"}
{"type": "orderbook_delta", "seq": 5414, "price": 42, "quantity": 100, "ts": 1756428420.440539, "side": "buy"}
{"type": "orderbook_delta", "seq": 5415, "price": 55, "quantity": 1250, "ts": 1756428420.474467, "side": "sell"}
{"type": "orderbook_delta", "seq": 5416, "price": 89, "quantity": -8000, "ts": 1756428420.475076, "side": "sell"}
{"type": "orderbook_delta", "seq": 5417, "price": 53, "quantity": -200, "ts": 1756428420.475987, "side": "sell"}
{"type": "orderbook_delta", "seq": 5418, "price": 55, "quantity": 200, "ts": 1756428420.475987, "side": "sell"}
{"type": "orderbook_delta", "seq": 5419, "price": 52, "quantity": 200, "ts": 1756428420.491806, "side": "sell"}
{"type": "orderbook_delta", "seq": 5420, "price": 54, "quantity": -100, "ts": 1756428420.506599, "side": "sell"}
{"type": "orderbook_delta", "seq": 5421, "price": 55, "quantity": 100, "ts": 1756428420.506599, "side": "sell"}
{"type": "orderbook_delta", "seq": 5422, "price": 46, "quantity": -250, "ts": 1756428420.514747, "side": "buy"}
{"type": "orderbook_delta", "seq": 5423, "price": 36, "quantity": 250, "ts": 1756428420.515721, "side": "buy"}
{"type": "orderbook_delta", "seq": 5424, "price": 44, "quantity": -500, "ts": 1756428420.52568, "side": "buy"}
{"type": "orderbook_delta", "seq": 5425, "price": 79, "quantity": 8000, "ts": 1756428420.57555, "side": "sell"}
{"type": "orderbook_delta", "seq": 5426, "price": 55, "quantity": -1250, "ts": 1756428420.576333, "side": "sell"}
{"type": "orderbook_delta", "seq": 5427, "price": 55, "quantity": -200, "ts": 1756428420.581657, "side": "sell"}
{"type": "orderbook_delta", "seq": 5428, "price": 52, "quantity": 200, "ts": 1756428420.581657, "side": "sell"}
{"type": "orderbook_delta", "seq": 5429, "price": 52, "quantity": -500, "ts": 1756428420.62499, "side": "sell"}
{"type": "orderbook_delta", "seq": 5430, "price": 43, "quantity": 500, "ts": 1756428420.630156, "side": "buy"}
{"type": "orderbook_delta", "seq": 5431, "price": 55, "quantity": 1250, "ts": 1756428420.644045, "side": "sell"}
{"type": "orderbook_delta", "seq": 5432, "price": 51, "quantity": 500, "ts": 1756428420.986052, "side": "sell"}
{"type": "orderbook_delta", "seq": 5433, "price": 53, "quantity": -901, "ts": 1756428421.114522, "side": "sell"}
{"type": "orderbook_delta", "seq": 5434, "price": 43, "quantity": -500, "ts": 1756428421.17557, "side": "buy"}
{"type": "orderbook_delta", "seq": 5435, "price": 44, "quantity": 500, "ts": 1756428421.250385, "side": "buy"}
{"type": "orderbook_delta", "seq": 5436, "price": 54, "quantity": 250, "ts": 1756428421.281347, "side": "sell"}
{"type": "orderbook_delta", "seq": 5437, "price": 55, "quantity": -1250, "ts": 1756428421.317149, "side": "sell"}
{"type": "orderbook_delta", "seq": 5438, "price": 52, "quantity": 250, "ts": 1756428421.380437, "side": "sell"}
{"type": "orderbook_delta", "seq": 5439, "price": 54, "quantity": 1250, "ts": 1756428421.414444, "side": "sell"}
{"type": "orderbook_delta", "seq": 5440, "price": 44, "quantity": -500, "ts": 1756428421.444275, "side": "buy"}
{"type": "orderbook_delta", "seq": 5441, "price": 34, "quantity": 250, "ts": 1756428421.458399, "side": "buy"}
{"type": "orderbook_delta", "seq": 5442, "price": 52, "quantity": -200, "ts": 1756428421.500226, "side": "sell"}
{"type": "orderbook_delta", "seq": 5443, "price": 54, "quantity": -1250, "ts": 1756428421.504143, "side": "sell"}
{"type": "orderbook_delta", "seq": 5444, "price": 39, "quantity": -1250, "ts": 1756428421.506577, "side": "buy"}
{"type": "orderbook_delta", "seq": 5445, "price": 41, "quantity": -200, "ts": 1756428421.506699, "side": "buy"}
{"type": "orderbook_delta", "seq": 5446, "price": 52, "quantity": -200, "ts": 1756428421.544653, "side": "sell"}
{"type": "orderbook_delta", "seq": 5447, "price": 50, "quantity": 200, "ts": 1756428421.544653, "side": "sell"}
{"type": "orderbook_delta", "seq": 5448, "price": 43, "quantity": 500, "ts": 1756428421.545534, "side": "buy"}
{"type": "orderbook_delta", "seq": 5449, "price": 44, "quantity": -250, "ts": 1756428421.594471, "side": "buy"}
{"type": "orderbook_delta", "seq": 5450, "price": 40, "quantity": 200, "ts": 1756428421.601368, "side": "buy"}
{"type": "orderbook_delta", "seq": 5451, "price": 38, "quantity": 1250, "ts": 1756428421.601898, "side": "buy"}
{"type": "orderbook_delta", "seq": 5452, "price": 51, "quantity": 200, "ts": 1756428421.602388, "side": "sell"}
{"type": "orderbook_delta", "seq": 5453, "price": 53, "quantity": 1250, "ts": 1756428421.602856, "side": "sell"}
{"type": "orderbook_delta", "seq": 5454, "price": 42, "quantity": -100, "ts": 1756428421.669547, "side": "buy"}
{"type": "orderbook_delta", "seq": 5455, "price": 41, "quantity": 100, "ts": 1756428421.669547, "side": "buy"}
{"type": "orderbook_delta", "seq": 5456, "price": 62, "quantity": -250, "ts": 1756428421.687872, "side": "sell"}
{"type": "orderbook_delta", "seq": 5457, "price": 51, "quantity": -500, "ts": 1756428421.689457, "side": "sell"}
{"type": "orderbook_delta", "seq": 5458, "price": 43, "quantity": -500, "ts": 1756428421.694317, "side": "buy"}
{"type": "orderbook_delta", "seq": 5459, "price": 55, "quantity": -100, "ts": 1756428421.726933, "side": "sell"}
{"type": "orderbook_delta", "seq": 5460, "price": 49, "quantity": 100, "ts": 1756428421.726933, "side": "sell"}
{"type": "orderbook_delta", "seq": 5461, "price": 64, "quantity": -250, "ts": 1756428421.727353, "side": "sell"}
{"type": "orderbook_delta", "seq": 5462, "price": 49, "quantity": 500, "ts": 1756428421.737043, "side": "sell"}
{"type": "orderbook_delta", "seq": 5463, "price": 42, "quantity": 500, "ts": 1756428421.737358, "side": "buy"}
{"type": "orderbook_delta", "seq": 5464, "price": 50, "quantity": 901, "ts": 1756428421.770504, "side": "sell"}
{"type": "orderbook_delta", "seq": 5465, "price": 49, "quantity": -500, "ts": 1756428421.801455, "side": "sell"}
{"type": "orderbook_delta", "seq": 5466, "price": 48, "quantity": 500, "ts": 1756428421.849406, "side": "sell"}
{"type": "orderbook_delta", "seq": 5467, "price": 50, "quantity": -901, "ts": 1756428421.889536, "side": "sell"}
{"type": "orderbook_delta", "seq": 5468, "price": 53, "quantity": -1250, "ts": 1756428421.929465, "side": "sell"}
{"type": "orderbook_delta", "seq": 5469, "price": 50, "quantity": 901, "ts": 1756428421.929492, "side": "sell"}
{"type": "orderbook_delta", "seq": 5470, "price": 51, "quantity": -200, "ts": 1756428421.933049, "side": "sell"}
{"type": "orderbook_delta", "seq": 5471, "price": 38, "quantity": -1250, "ts": 1756428421.936785, "side": "buy"}
{"type": "orderbook_delta", "seq": 5472, "price": 49, "quantity": -100, "ts": 1756428421.976716, "side": "sell"}
{"type": "orderbook_delta", "seq": 5473, "price": 48, "quantity": 100, "ts": 1756428421.976716, "side": "sell"}
{"type": "orderbook_delta", "seq": 5474, "price": 40, "quantity": -200, "ts": 1756428422.033479, "side": "buy"}
{"type": "orderbook_delta", "seq": 5475, "price": 50, "quantity": -901, "ts": 1756428422.09293, "side": "sell"}
{"type": "orderbook_delta", "seq": 5476, "price": 50, "quantity": 250, "ts": 1756428422.099902, "side": "sell"}
{"type": "orderbook_delta", "seq": 5477, "price": 60, "quantity": -250, "ts": 1756428422.107214, "side": "sell"}
{"type": "orderbook_delta", "seq": 5478, "price": 48, "quantity": -500, "ts": 1756428422.126563, "side": "sell"}
{"type": "orderbook_delta", "seq": 5479, "price": 42, "quantity": -500, "ts": 1756428422.133152, "side": "buy"}
{"type": "orderbook_delta", "seq": 5480, "price": 49, "quantity": 200, "ts": 1756428422.137525, "side": "sell"}
{"type": "orderbook_delta", "seq": 5481, "price": 51, "quantity": 1250, "ts": 1756428422.137892, "side": "sell"}
{"type": "orderbook_delta", "seq": 5482, "price": 36, "quantity": 1250, "ts": 1756428422.143949, "side": "buy"}
{"type": "orderbook_delta", "seq": 5483, "price": 50, "quantity": -200, "ts": 1756428422.1472, "side": "sell"}
{"type": "orderbook_delta", "seq": 5484, "price": 49, "quantity": 200, "ts": 1756428422.1472, "side": "sell"}
{"type": "orderbook_delta", "seq": 5485, "price": 38, "quantity": 200, "ts": 1756428422.14817, "side": "buy"}
{"type": "orderbook_delta", "seq": 5486, "price": 48, "quantity": 901, "ts": 1756428422.162446, "side": "sell"}
{"type": "orderbook_delta", "seq": 5487, "price": 47, "quantity": 500, "ts": 1756428422.186966, "side": "sell"}
{"type": "orderbook_delta", "seq": 5488, "price": 41, "quantity": 500, "ts": 1756428422.191454, "side": "buy"}
{"type": "orderbook_delta", "seq": 5489, "price": 51, "quantity": -1250, "ts": 1756428422.292772, "side": "sell"}
{"type": "orderbook_delta", "seq": 5490, "price": 36, "quantity": -1250, "ts": 1756428422.295408, "side": "buy"}
{"type": "orderbook_delta", "seq": 5491, "price": 12, "quantity": -8000, "ts": 1756428422.295651, "side": "buy"}
{"type": "orderbook_delta", "seq": 5492, "price": 38, "quantity": -200, "ts": 1756428422.300852, "side": "buy"}
{"type": "orderbook_delta", "seq": 5493, "price": 49, "quantity": -200, "ts": 1756428422.304064, "side": "sell"}
{"type": "orderbook_delta", "seq": 5494, "price": 42, "quantity": -250, "ts": 1756428422.306978, "side": "buy"}
{"type": "orderbook_delta", "seq": 5495, "price": 49, "quantity": -200, "ts": 1756428422.318263, "side": "sell"}
{"type": "orderbook_delta", "seq": 5496, "price": 47, "quantity": 200, "ts": 1756428422.318263, "side": "sell"}
{"type": "orderbook_delta", "seq": 5497, "price": 47, "quantity": -500, "ts": 1756428422.359955, "side": "sell"}
{"type": "orderbook_delta", "seq": 5498, "price": 47, "quantity": -200, "ts": 1756428422.3722, "side": "sell"}
{"type": "orderbook_delta", "seq": 5499, "price": 46, "quantity": 200, "ts": 1756428422.3722, "side": "sell"}
{"type": "orderbook_delta", "seq": 5500, "price": 45, "quantity": 500, "ts": 1756428422.419254, "side": "sell"}
{"type": "orderbook_delta", "seq": 5501, "price": 41, "quantity": -500, "ts": 1756428422.442591, "side": "buy"}
{"type": "orderbook_delta", "seq": 5502, "price": 32, "quantity": 250, "ts": 1756428422.45696, "side": "buy"}
{"type": "orderbook_delta", "seq": 5503, "price": 47, "quantity": 200, "ts": 1756428422.480023, "side": "sell"}
{"type": "orderbook_delta", "seq": 5504, "price": 39, "quantity": 500, "ts": 1756428422.484337, "side": "buy"}
{"type": "orderbook_delta", "seq": 5505, "price": 11, "quantity": 8000, "ts": 1756428422.486574, "side": "buy"}
{"type": "orderbook_delta", "seq": 5506, "price": 36, "quantity": 200, "ts": 1756428422.48684, "side": "buy"}
{"type": "orderbook_delta", "seq": 5507, "price": 34, "quantity": 1250, "ts": 1756428422.487135, "side": "buy"}
{"type": "orderbook_delta", "seq": 5508, "price": 49, "quantity": 1250, "ts": 1756428422.487387, "side": "sell"}
{"type": "orderbook_delta", "seq": 5509, "price": 36, "quantity": -200, "ts": 1756428422.748292, "side": "buy"}
{"type": "orderbook_delta", "seq": 5510, "price": 49, "quantity": -1250, "ts": 1756428422.750055, "side": "sell"}
{"type": "orderbook_delta", "seq": 5511, "price": 39, "quantity": -500, "ts": 1756428422.75171, "side": "buy"}
{"type": "orderbook_delta", "seq": 5512, "price": 47, "quantity": -200, "ts": 1756428422.75547, "side": "sell"}
{"type": "orderbook_delta", "seq": 5513, "price": 41, "quantity": -100, "ts": 1756428422.766895, "side": "buy"}
{"type": "orderbook_delta", "seq": 5514, "price": 40, "quantity": 100, "ts": 1756428422.766895, "side": "buy"}
{"type": "orderbook_delta", "seq": 5515, "price": 46, "quantity": -200, "ts": 1756428422.774955, "side": "sell"}
{"type": "orderbook_delta", "seq": 5516, "price": 45, "quantity": 200, "ts": 1756428422.774955, "side": "sell"}
{"type": "orderbook_delta", "seq": 5517, "price": 46, "quantity": 200, "ts": 1756428422.803098, "side": "sell"}
{"type": "orderbook_delta", "seq": 5518, "price": 38, "quantity": 500, "ts": 1756428422.80361, "side": "buy"}
{"type": "orderbook_delta", "seq": 5519, "price": 35, "quantity": 200, "ts": 1756428422.80393, "side": "buy"}
{"type": "orderbook_delta", "seq": 5520, "price": 48, "quantity": 1250, "ts": 1756428422.804538, "side": "sell"}
{"type": "orderbook_delta", "seq": 5521, "price": 45, "quantity": -500, "ts": 1756428422.815663, "side": "sell"}
{"type": "orderbook_delta", "seq": 5522, "price": 40, "quantity": -100, "ts": 1756428422.822106, "side": "buy"}
{"type": "orderbook_delta", "seq": 5523, "price": 39, "quantity": 100, "ts": 1756428422.822106, "side": "buy"}
{"type": "orderbook_delta", "seq": 5524, "price": 46, "quantity": -200, "ts": 1756428422.834944, "side": "sell"}
{"type": "orderbook_delta", "seq": 5525, "price": 44, "quantity": 500, "ts": 1756428422.858438, "side": "sell"}
{"type": "orderbook_delta", "seq": 5526, "price": 47, "quantity": 200, "ts": 1756428422.874811, "side": "sell"}
{"type": "orderbook_delta", "seq": 5527, "price": 39, "quantity": -100, "ts": 1756428423.052276, "side": "buy"}
{"type": "orderbook_delta", "seq": 5528, "price": 37, "quantity": 100, "ts": 1756428423.052276, "side": "buy"}
{"type": "orderbook_delta", "seq": 5529, "price": 11, "quantity": -8000, "ts": 1756428423.076458, "side": "buy"}
{"type": "orderbook_delta", "seq": 5530, "price": 34, "quantity": -1250, "ts": 1756428423.077251, "side": "buy"}
{"type": "orderbook_delta", "seq": 5531, "price": 48, "quantity": -901, "ts": 1756428423.103656, "side": "sell"}
{"type": "orderbook_delta", "seq": 5532, "price": 48, "quantity": -100, "ts": 1756428423.10595, "side": "sell"}
{"type": "orderbook_delta", "seq": 5533, "price": 49, "quantity": 100, "ts": 1756428423.10595, "side": "sell"}
{"type": "orderbook_delta", "seq": 5534, "price": 40, "quantity": -250, "ts": 1756428423.11681, "side": "buy"}
{"type": "orderbook_delta", "seq": 5535, "price": 30, "quantity": 250, "ts": 1756428423.125644, "side": "buy"}
{"type": "orderbook_delta", "seq": 5536, "price": 58, "quantity": -250, "ts": 1756428423.136619, "side": "sell"}
{"type": "orderbook_delta", "seq": 5537, "price": 48, "quantity": 250, "ts": 1756428423.146031, "side": "sell"}
{"type": "orderbook_delta", "seq": 5538, "price": 45, "quantity": 901, "ts": 1756428423.188231, "side": "sell"}
{"type": "orderbook_delta", "seq": 5539, "price": 48, "quantity": -1250, "ts": 1756428423.204381, "side": "sell"}
{"type": "orderbook_delta", "seq": 5540, "price": 47, "quantity": -200, "ts": 1756428423.207536, "side": "sell"}
{"type": "orderbook_delta", "seq": 5541, "price": 49, "quantity": 1250, "ts": 1756428423.247998, "side": "sell"}
{"type": "orderbook_delta", "seq": 5542, "price": 49, "quantity": 200, "ts": 1756428423.248333, "side": "sell"}
{"type": "orderbook_delta", "seq": 5543, "price": 33, "quantity": 1250, "ts": 1756428423.258472, "side": "buy"}
{"type": "orderbook_delta", "seq": 5544, "price": 49, "quantity": -200, "ts": 1756428423.285705, "side": "sell"}
{"type": "orderbook_delta", "seq": 5545, "price": 49, "quantity": -1250, "ts": 1756428423.286187, "side": "sell"}
{"type": "orderbook_delta", "seq": 5546, "price": 47, "quantity": 200, "ts": 1756428423.330078, "side": "sell"}
{"type": "orderbook_delta", "seq": 5547, "price": 48, "quantity": 1250, "ts": 1756428423.331707, "side": "sell"}
{"type": "orderbook_delta", "seq": 5548, "price": 49, "quantity": -100, "ts": 1756428423.882198, "side": "sell"}
{"type": "orderbook_delta", "seq": 5549, "price": 45, "quantity": 100, "ts": 1756428423.882198, "side": "sell"}
{"type": "orderbook_delta", "seq": 5550, "price": 37, "quantity": -100, "ts": 1756428424.555793, "side": "buy"}
{"type": "orderbook_delta", "seq": 5551, "price": 39, "quantity": 100, "ts": 1756428424.555793, "side": "buy"}
{"type": "orderbook_delta", "seq": 5552, "price": 35, "quantity": -200, "ts": 1756428425.126513, "side": "buy"}
{"type": "orderbook_delta", "seq": 5553, "price": 11, "quantity": 8000, "ts": 1756428425.12801, "side": "buy"}
{"type": "orderbook_delta", "seq": 5554, "price": 33, "quantity": -1250, "ts": 1756428425.134751, "side": "buy"}
{"type": "orderbook_delta", "seq": 5555, "price": 34, "quantity": 1250, "ts": 1756428425.176864, "side": "buy"}
{"type": "orderbook_delta", "seq": 5556, "price": 36, "quantity": 200, "ts": 1756428425.179698, "side": "buy"}
{"type": "orderbook_delta", "seq": 5557, "price": 11, "quantity": -8000, "ts": 1756428426.715544, "side": "buy"}
{"type": "orderbook_delta", "seq": 5558, "price": 36, "quantity": -200, "ts": 1756428426.717381, "side": "buy"}
{"type": "orderbook_delta", "seq": 5559, "price": 34, "quantity": -1250, "ts": 1756428426.723245, "side": "buy"}
{"type": "orderbook_delta", "seq": 5560, "price": 33, "quantity": 1250, "ts": 1756428426.770054, "side": "buy"}
{"type": "orderbook_delta", "seq": 5561, "price": 35, "quantity": 200, "ts": 1756428426.770705, "side": "buy"}
{"type": "orderbook_delta", "seq": 5562, "price": 45, "quantity": -100, "ts": 1756428427.144852, "side": "sell"}
{"type": "orderbook_delta", "seq": 5563, "price": 44, "quantity": 100, "ts": 1756428427.144852, "side": "sell"}
{"type": "orderbook_delta", "seq": 5564, "price": 39, "quantity": -100, "ts": 1756428427.604185, "side": "buy"}
{"type": "orderbook_delta", "seq": 5565, "price": 37, "quantity": 100, "ts": 1756428427.604185, "side": "buy"}
{"type": "orderbook_delta", "seq": 5566, "price": 44, "quantity": -100, "ts": 1756428427.642297, "side": "sell"}
{"type": "orderbook_delta", "seq": 5567, "price": 45, "quantity": 100, "ts": 1756428427.642297, "side": "sell"}
{"type": "orderbook_delta", "seq": 5568, "price": 40, "quantity": 100, "ts": 1756428428.049503, "side": "buy"}
{"type": "orderbook_delta", "seq": 5569, "price": 35, "quantity": -200, "ts": 1756428428.253553, "side": "buy"}
{"type": "orderbook_delta", "seq": 5570, "price": 11, "quantity": 8000, "ts": 1756428428.253652, "side": "buy"}
{"type": "orderbook_delta", "seq": 5571, "price": 38, "quantity": -500, "ts": 1756428428.254719, "side": "buy"}
{"type": "orderbook_delta", "seq": 5572, "price": 48, "quantity": -1250, "ts": 1756428428.254774, "side": "sell"}
{"type": "orderbook_delta", "seq": 5573, "price": 33, "quantity": -1250, "ts": 1756428428.255929, "side": "buy"}
{"type": "orderbook_delta", "seq": 5574, "price": 39, "quantity": 500, "ts": 1756428428.304472, "side": "buy"}
{"type": "orderbook_delta", "seq": 5575, "price": 49, "quantity": 1250, "ts": 1756428428.310545, "side": "sell"}
{"type": "orderbook_delta", "seq": 5576, "price": 34, "quantity": 1250, "ts": 1756428428.310813, "side": "buy"}
{"type": "orderbook_delta", "seq": 5577, "price": 36, "quantity": 200, "ts": 1756428428.319603, "side": "buy"}
{"type": "orderbook_delta", "seq": 5578, "price": 45, "quantity": -100, "ts": 1756428428.860441, "side": "sell"}
{"type": "orderbook_delta", "seq": 5579, "price": 44, "quantity": 100, "ts": 1756428428.860441, "side": "sell"}
{"type": "orderbook_delta", "seq": 5580, "price": 44, "quantity": -100, "ts": 1756428428.920374, "side": "sell"}
{"type": "orderbook_delta", "seq": 5581, "price": 46, "quantity": 100, "ts": 1756428428.920374, "side": "sell"}
{"type": "orderbook_delta", "seq": 5582, "price": 45, "quantity": -901, "ts": 1756428429.029963, "side": "sell"}
{"type": "orderbook_delta", "seq": 5583, "price": 44, "quantity": -500, "ts": 1756428429.031849, "side": "sell"}
{"type": "orderbook_delta", "seq": 5584, "price": 34, "quantity": -1250, "ts": 1756428429.032009, "side": "buy"}
{"type": "orderbook_delta", "seq": 5585, "price": 47, "quantity": -200, "ts": 1756428429.041405, "side": "sell"}
{"type": "orderbook_delta", "seq": 5586, "price": 49, "quantity": -1250, "ts": 1756428429.041572, "side": "sell"}
{"type": "orderbook_delta", "seq": 5587, "price": 11, "quantity": -8000, "ts": 1756428429.042541, "side": "buy"}
{"type": "orderbook_delta", "seq": 5588, "price": 36, "quantity": -200, "ts": 1756428429.043131, "side": "buy"}
{"type": "orderbook_delta", "seq": 5589, "price": 46, "quantity": 901, "ts": 1756428429.069245, "side": "sell"}
{"type": "orderbook_delta", "seq": 5590, "price": 45, "quantity": -200, "ts": 1756428429.070443, "side": "sell"}
{"type": "orderbook_delta", "seq": 5591, "price": 46, "quantity": 200, "ts": 1756428429.070443, "side": "sell"}
{"type": "orderbook_delta", "seq": 5592, "price": 35, "quantity": 1250, "ts": 1756428429.078664, "side": "buy"}
{"type": "orderbook_delta", "seq": 5593, "price": 45, "quantity": 500, "ts": 1756428429.080662, "side": "sell"}
{"type": "orderbook_delta", "seq": 5594, "price": 12, "quantity": 8000, "ts": 1756428429.096271, "side": "buy"}
{"type": "orderbook_delta", "seq": 5595, "price": 50, "quantity": 1250, "ts": 1756428429.097102, "side": "sell"}
{"type": "orderbook_delta", "seq": 5596, "price": 37, "quantity": 200, "ts": 1756428429.097737, "side": "buy"}
{"type": "orderbook_delta", "seq": 5597, "price": 48, "quantity": 200, "ts": 1756428429.098055, "side": "sell"}
{"type": "orderbook_delta", "seq": 5598, "price": 37, "quantity": -100, "ts": 1756428429.118149, "side": "buy"}
{"type": "orderbook_delta", "seq": 5599, "price": 40, "quantity": 100, "ts": 1756428429.118149, "side": "buy"}
{"type": "orderbook_delta", "seq": 5600, "price": 45, "quantity": -500, "ts": 1756428429.147599, "side": "sell"}
{"type": "orderbook_delta", "seq": 5601, "price": 39, "quantity": -500, "ts": 1756428429.149183, "side": "buy"}
{"type": "orderbook_delta", "seq": 5602, "price": 40, "quantity": -100, "ts": 1756428429.163413, "side": "buy"}
{"type": "orderbook_delta", "seq": 5603, "price": 38, "quantity": 100, "ts": 1756428429.163413, "side": "buy"}
{"type": "orderbook_delta", "seq": 5604, "price": 40, "quantity": 500, "ts": 1756428429.197251, "side": "buy"}
{"type": "orderbook_delta", "seq": 5605, "price": 28, "quantity": 250, "ts": 1756428429.197776, "side": "buy"}
{"type": "orderbook_delta", "seq": 5606, "price": 38, "quantity": -250, "ts": 1756428429.200261, "side": "buy"}
{"type": "orderbook_delta", "seq": 5607, "price": 46, "quantity": -100, "ts": 1756428429.202274, "side": "sell"}
{"type": "orderbook_delta", "seq": 5608, "price": 48, "quantity": 100, "ts": 1756428429.202274, "side": "sell"}
{"type": "orderbook_delta", "seq": 5609, "price": 46, "quantity": 500, "ts": 1756428429.206669, "side": "sell"}
{"type": "orderbook_delta", "seq": 5610, "price": 48, "quantity": -100, "ts": 1756428429.249603, "side": "sell"}
{"type": "orderbook_delta", "seq": 5611, "price": 49, "quantity": 100, "ts": 1756428429.249603, "side": "sell"}
{"type": "orderbook_delta", "seq": 5612, "price": 50, "quantity": -1250, "ts": 1756428429.288432, "side": "sell"}
{"type": "orderbook_delta", "seq": 5613, "price": 48, "quantity": -200, "ts": 1756428429.309786, "side": "sell"}
{"type": "orderbook_delta", "seq": 5614, "price": 46, "quantity": -200, "ts": 1756428429.322306, "side": "sell"}
{"type": "orderbook_delta", "seq": 5615, "price": 47, "quantity": 200, "ts": 1756428429.322306, "side": "sell"}
{"type": "orderbook_delta", "seq": 5616, "price": 35, "quantity": -1250, "ts": 1756428429.340204, "side": "buy"}
{"type": "orderbook_delta", "seq": 5617, "price": 35, "quantity": 1250, "ts": 1756428429.408971, "side": "buy"}
{"type": "orderbook_delta", "seq": 5618, "price": 48, "quantity": 200, "ts": 1756428429.413459, "side": "sell"}
{"type": "orderbook_delta", "seq": 5619, "price": 50, "quantity": 1250, "ts": 1756428429.415997, "side": "sell"}
{"type": "orderbook_delta", "seq": 5620, "price": 28, "quantity": -250, "ts": 1756428429.679621, "side": "buy"}
{"type": "orderbook_delta", "seq": 5621, "price": 38, "quantity": 250, "ts": 1756428429.680785, "side": "buy"}
{"type": "orderbook_delta", "seq": 5622, "price": 35, "quantity": -1250, "ts": 1756428429.685554, "side": "buy"}
{"type": "orderbook_delta", "seq": 5623, "price": 48, "quantity": -200, "ts": 1756428429.689598, "side": "sell"}
{"type": "orderbook_delta", "seq": 5624, "price": 37, "quantity": -200, "ts": 1756428429.714992, "side": "buy"}
{"type": "orderbook_delta", "seq": 5625, "price": 49, "quantity": 200, "ts": 1756428429.736103, "side": "sell"}
{"type": "orderbook_delta", "seq": 5626, "price": 38, "quantity": 200, "ts": 1756428429.739908, "side": "buy"}
{"type": "orderbook_delta", "seq": 5627, "price": 36, "quantity": 1250, "ts": 1756428429.742027, "side": "buy"}
{"type": "orderbook_delta", "seq": 5628, "price": 38, "quantity": -200, "ts": 1756428429.831856, "side": "buy"}
{"type": "orderbook_delta", "seq": 5629, "price": 36, "quantity": -1250, "ts": 1756428429.836193, "side": "buy"}
{"type": "orderbook_delta", "seq": 5630, "price": 49, "quantity": -200, "ts": 1756428429.8704, "side": "sell"}
{"type": "orderbook_delta", "seq": 5631, "price": 48, "quantity": 200, "ts": 1756428429.92583, "side": "sell"}
{"type": "orderbook_delta", "seq": 5632, "price": 37, "quantity": 200, "ts": 1756428429.926302, "side": "buy"}
{"type": "orderbook_delta", "seq": 5633, "price": 35, "quantity": 1250, "ts": 1756428429.929738, "side": "buy"}
{"type": "orderbook_delta", "seq": 5634, "price": 46, "quantity": -901, "ts": 1756428430.109271, "side": "sell"}
{"type": "orderbook_delta", "seq": 5635, "price": 40, "quantity": 250, "ts": 1756428430.112088, "side": "buy"}
{"type": "orderbook_delta", "seq": 5636, "price": 30, "quantity": -250, "ts": 1756428430.127093, "side": "buy"}
{"type": "orderbook_delta", "seq": 5637, "price": 58, "quantity": 250, "ts": 1756428430.127182, "side": "sell"}
{"type": "orderbook_delta", "seq": 5638, "price": 48, "quantity": -250, "ts": 1756428430.146362, "side": "sell"}
{"type": "orderbook_delta", "seq": 5639, "price": 48, "quantity": -200, "ts": 1756428430.189104, "side": "sell"}
{"type": "orderbook_delta", "seq": 5640, "price": 47, "quantity": 901, "ts": 1756428430.191533, "side": "sell"}
{"type": "orderbook_delta", "seq": 5641, "price": 49, "quantity": 200, "ts": 1756428430.276009, "side": "sell"}
{"type": "orderbook_delta", "seq": 5642, "price": 40, "quantity": -500, "ts": 1756428430.277443, "side": "buy"}
{"type": "orderbook_delta", "seq": 5643, "price": 39, "quantity": 500, "ts": 1756428430.329699, "side": "buy"}
{"type": "orderbook_delta", "seq": 5644, "price": 75, "quantity": -7, "ts": 1756428430.600837, "side": "sell"}
{"type": "orderbook_delta", "seq": 5645, "price": 38, "quantity": -100, "ts": 1756428430.652228, "side": "buy"}
{"type": "orderbook_delta", "seq": 5646, "price": 41, "quantity": 100, "ts": 1756428430.652228, "side": "buy"}
{"type": "orderbook_delta", "seq": 5647, "price": 47, "quantity": -901, "ts": 1756428431.120341, "side": "sell"}
{"type": "orderbook_delta", "seq": 5648, "price": 48, "quantity": 250, "ts": 1756428431.121656, "side": "sell"}
{"type": "orderbook_delta", "seq": 5649, "price": 58, "quantity": -250, "ts": 1756428431.136662, "side": "sell"}
{"type": "orderbook_delta", "seq": 5650, "price": 49, "quantity": -200, "ts": 1756428431.153924, "side": "sell"}
{"type": "orderbook_delta", "seq": 5651, "price": 46, "quantity": 901, "ts": 1756428431.183212, "side": "sell"}
{"type": "orderbook_delta", "seq": 5652, "price": 48, "quantity": 200, "ts": 1756428431.2054, "side": "sell"}
{"type": "orderbook_delta", "seq": 5653, "price": 46, "quantity": -500, "ts": 1756428431.227051, "side": "sell"}
{"type": "orderbook_delta", "seq": 5654, "price": 45, "quantity": 500, "ts": 1756428431.2852, "side": "sell"}
{"type": "orderbook_delta", "seq": 5655, "price": 58, "quantity": 250, "ts": 1756428431.368905, "side": "sell"}
{"type": "orderbook_delta", "seq": 5656, "price": 46, "quantity": -901, "ts": 1756428431.369723, "side": "sell"}
{"type": "orderbook_delta", "seq": 5657, "price": 48, "quantity": -200, "ts": 1756428431.376812, "side": "sell"}
{"type": "orderbook_delta", "seq": 5658, "price": 39, "quantity": -500, "ts": 1756428431.376876, "side": "buy"}
{"type": "orderbook_delta", "seq": 5659, "price": 35, "quantity": -1250, "ts": 1756428431.377122, "side": "buy"}
{"type": "orderbook_delta", "seq": 5660, "price": 50, "quantity": -1250, "ts": 1756428431.38044, "side": "sell"}
{"type": "orderbook_delta", "seq": 5661, "price": 37, "quantity": -200, "ts": 1756428431.38141, "side": "buy"}
{"type": "orderbook_delta", "seq": 5662, "price": 48, "quantity": -250, "ts": 1756428431.396575, "side": "sell"}
{"type": "orderbook_delta", "seq": 5663, "price": 45, "quantity": -500, "ts": 1756428431.414131, "side": "sell"}
{"type": "orderbook_delta", "seq": 5664, "price": 48, "quantity": 901, "ts": 1756428431.440016, "side": "sell"}
{"type": "orderbook_delta", "seq": 5665, "price": 51, "quantity": 200, "ts": 1756428431.44745, "side": "sell"}
{"type": "orderbook_delta", "seq": 5666, "price": 60, "quantity": 250, "ts": 1756428431.448183, "side": "sell"}
{"type": "orderbook_delta", "seq": 5667, "price": 38, "quantity": 1250, "ts": 1756428431.448696, "side": "buy"}
{"type": "orderbook_delta", "seq": 5668, "price": 50, "quantity": -250, "ts": 1756428431.448964, "side": "sell"}
{"type": "orderbook_delta", "seq": 5669, "price": 53, "quantity": 1250, "ts": 1756428431.449317, "side": "sell"}
{"type": "orderbook_delta", "seq": 5670, "price": 49, "quantity": -100, "ts": 1756428431.449731, "side": "sell"}
{"type": "orderbook_delta", "seq": 5671, "price": 50, "quantity": 100, "ts": 1756428431.449731, "side": "sell"}
{"type": "orderbook_delta", "seq": 5672, "price": 40, "quantity": 200, "ts": 1756428431.450509, "side": "buy"}
{"type": "orderbook_delta", "seq": 5673, "price": 42, "quantity": 500, "ts": 1756428431.451261, "side": "buy"}
{"type": "orderbook_delta", "seq": 5674, "price": 49, "quantity": 500, "ts": 1756428431.453464, "side": "sell"}
{"type": "orderbook_delta", "seq": 5675, "price": 47, "quantity": -200, "ts": 1756428431.466953, "side": "sell"}
{"type": "orderbook_delta", "seq": 5676, "price": 50, "quantity": 200, "ts": 1756428431.466953, "side": "sell"}
{"type": "orderbook_delta", "seq": 5677, "price": 60, "quantity": -250, "ts": 1756428431.501409, "side": "sell"}
{"type": "orderbook_delta", "seq": 5678, "price": 41, "quantity": -100, "ts": 1756428431.510338, "side": "buy"}
{"type": "orderbook_delta", "seq": 5679, "price": 42, "quantity": 100, "ts": 1756428431.510338, "side": "buy"}
{"type": "orderbook_delta", "seq": 5680, "price": 50, "quantity": -100, "ts": 1756428431.565934, "side": "sell"}
{"type": "orderbook_delta", "seq": 5681, "price": 51, "quantity": 100, "ts": 1756428431.565934, "side": "sell"}
{"type": "orderbook_delta", "seq": 5682, "price": 42, "quantity": -500, "ts": 1756428431.59914, "side": "buy"}
{"type": "orderbook_delta", "seq": 5683, "price": 42, "quantity": -100, "ts": 1756428431.646643, "side": "buy"}
{"type": "orderbook_delta", "seq": 5684, "price": 41, "quantity": 100, "ts": 1756428431.646643, "side": "buy"}
{"type": "orderbook_delta", "seq": 5685, "price": 43, "quantity": 500, "ts": 1756428431.687745, "side": "buy"}
{"type": "orderbook_delta", "seq": 5686, "price": 43, "quantity": -500, "ts": 1756428431.736104, "side": "buy"}
{"type": "orderbook_delta", "seq": 5687, "price": 42, "quantity": 500, "ts": 1756428431.775213, "side": "buy"}
{"type": "orderbook_delta", "seq": 5688, "price": 50, "quantity": -200, "ts": 1756428431.789123, "side": "sell"}
{"type": "orderbook_delta", "seq": 5689, "price": 49, "quantity": 200, "ts": 1756428431.789123, "side": "sell"}
{"type": "orderbook_delta", "seq": 5690, "price": 49, "quantity": -200, "ts": 1756428431.836046, "side": "sell"}
{"type": "orderbook_delta", "seq": 5691, "price": 47, "quantity": 200, "ts": 1756428431.836046, "side": "sell"}
{"type": "orderbook_delta", "seq": 5692, "price": 40, "quantity": -200, "ts": 1756428431.848335, "side": "buy"}
{"type": "orderbook_delta", "seq": 5693, "price": 53, "quantity": -1250, "ts": 1756428431.849598, "side": "sell"}
{"type": "orderbook_delta", "seq": 5694, "price": 42, "quantity": -500, "ts": 1756428431.850132, "side": "buy"}
{"type": "orderbook_delta", "seq": 5695, "price": 49, "quantity": -500, "ts": 1756428431.852031, "side": "sell"}
{"type": "orderbook_delta", "seq": 5696, "price": 51, "quantity": -200, "ts": 1756428431.852464, "side": "sell"}
{"type": "orderbook_delta", "seq": 5697, "price": 38, "quantity": -1250, "ts": 1756428431.85588, "side": "buy"}
{"type": "orderbook_delta", "seq": 5698, "price": 51, "quantity": 1250, "ts": 1756428431.924311, "side": "sell"}
{"type": "orderbook_delta", "seq": 5699, "price": 51, "quantity": 200, "ts": 1756428431.927192, "side": "sell"}
{"type": "orderbook_delta", "seq": 5700, "price": 40, "quantity": 500, "ts": 1756428431.929257, "side": "buy"}
{"type": "orderbook_delta", "seq": 5701, "price": 38, "quantity": 200, "ts": 1756428431.929722, "side": "buy"}
{"type": "orderbook_delta", "seq": 5702, "price": 46, "quantity": 500, "ts": 1756428431.929986, "side": "sell"}
{"type": "orderbook_delta", "seq": 5703, "price": 36, "quantity": 1250, "ts": 1756428431.930211, "side": "buy"}
{"type": "orderbook_delta", "seq": 5704, "price": 38, "quantity": -200, "ts": 1756428431.970558, "side": "buy"}
{"type": "orderbook_delta", "seq": 5705, "price": 51, "quantity": -200, "ts": 1756428432.068577, "side": "sell"}
{"type": "orderbook_delta", "seq": 5706, "price": 51, "quantity": 200, "ts": 1756428432.106658, "side": "sell"}
{"type": "orderbook_delta", "seq": 5707, "price": 48, "quantity": 250, "ts": 1756428432.115825, "side": "sell"}
{"type": "orderbook_delta", "seq": 5708, "price": 38, "quantity": 200, "ts": 1756428432.116041, "side": "buy"}
{"type": "orderbook_delta", "seq": 5709, "price": 48, "quantity": -901, "ts": 1756428432.137239, "side": "sell"}
{"type": "orderbook_delta", "seq": 5710, "price": 50, "quantity": 250, "ts": 1756428432.147315, "side": "sell"}
{"type": "orderbook_delta", "seq": 5711, "price": 58, "quantity": -250, "ts": 1756428432.15628, "side": "sell"}
{"type": "orderbook_delta", "seq": 5712, "price": 51, "quantity": -1250, "ts": 1756428432.186617, "side": "sell"}
{"type": "orderbook_delta", "seq": 5713, "price": 51, "quantity": -200, "ts": 1756428432.187002, "side": "sell"}
{"type": "orderbook_delta", "seq": 5714, "price": 47, "quantity": 901, "ts": 1756428432.212551, "side": "sell"}
{"type": "orderbook_delta", "seq": 5715, "price": 50, "quantity": 1250, "ts": 1756428432.226803, "side": "sell"}
{"type": "orderbook_delta", "seq": 5716, "price": 49, "quantity": 200, "ts": 1756428432.229979, "side": "sell"}
{"type": "orderbook_delta", "seq": 5717, "price": 54, "quantity": 19, "ts": 1756428432.275398, "side": "sell"}
{"type": "orderbook_delta", "seq": 5718, "price": 49, "quantity": -200, "ts": 1756428433.019188, "side": "sell"}
{"type": "orderbook_delta", "seq": 5719, "price": 36, "quantity": -1250, "ts": 1756428433.021577, "side": "buy"}
{"type": "orderbook_delta", "seq": 5720, "price": 38, "quantity": -200, "ts": 1756428433.0246, "side": "buy"}
{"type": "orderbook_delta", "seq": 5721, "price": 40, "quantity": -500, "ts": 1756428433.048258, "side": "buy"}
{"type": "orderbook_delta", "seq": 5722, "price": 47, "quantity": -200, "ts": 1756428433.055395, "side": "sell"}
{"type": "orderbook_delta", "seq": 5723, "price": 48, "quantity": 200, "ts": 1756428433.055395, "side": "sell"}
{"type": "orderbook_delta", "seq": 5724, "price": 49, "quantity": 200, "ts": 1756428433.056109, "side": "sell"}
{"type": "orderbook_delta", "seq": 5725, "price": 38, "quantity": 200, "ts": 1756428433.057643, "side": "buy"}
{"type": "orderbook_delta", "seq": 5726, "price": 50, "quantity": -1250, "ts": 1756428433.058757, "side": "sell"}
{"type": "orderbook_delta", "seq": 5727, "price": 36, "quantity": 1250, "ts": 1756428433.061958, "side": "buy"}
{"type": "orderbook_delta", "seq": 5728, "price": 51, "quantity": -100, "ts": 1756428433.070028, "side": "sell"}
{"type": "orderbook_delta", "seq": 5729, "price": 49, "quantity": 100, "ts": 1756428433.070028, "side": "sell"}
{"type": "orderbook_delta", "seq": 5730, "price": 51, "quantity": 1250, "ts": 1756428433.10329, "side": "sell"}
{"type": "orderbook_delta", "seq": 5731, "price": 41, "quantity": 500, "ts": 1756428433.11236, "side": "buy"}
{"type": "orderbook_delta", "seq": 5732, "price": 47, "quantity": -901, "ts": 1756428433.126227, "side": "sell"}
{"type": "orderbook_delta", "seq": 5733, "price": 42, "quantity": 250, "ts": 1756428433.146938, "side": "buy"}
{"type": "orderbook_delta", "seq": 5734, "price": 41, "quantity": -100, "ts": 1756428433.167329, "side": "buy"}
{"type": "orderbook_delta", "seq": 5735, "price": 42, "quantity": 100, "ts": 1756428433.167329, "side": "buy"}
{"type": "orderbook_delta", "seq": 5736, "price": 58, "quantity": 250, "ts": 1756428433.167703, "side": "sell"}
{"type": "orderbook_delta", "seq": 5737, "price": 48, "quantity": -250, "ts": 1756428433.186228, "side": "sell"}
{"type": "orderbook_delta", "seq": 5738, "price": 46, "quantity": -500, "ts": 1756428433.202093, "side": "sell"}
{"type": "orderbook_delta", "seq": 5739, "price": 32, "quantity": -250, "ts": 1756428433.21598, "side": "buy"}
{"type": "orderbook_delta", "seq": 5740, "price": 47, "quantity": 500, "ts": 1756428433.237412, "side": "sell"}
{"type": "orderbook_delta", "seq": 5741, "price": 48, "quantity": 901, "ts": 1756428433.262926, "side": "sell"}
{"type": "orderbook_delta", "seq": 5742, "price": 42, "quantity": -100, "ts": 1756428433.413802, "side": "buy"}
{"type": "orderbook_delta", "seq": 5743, "price": 43, "quantity": 100, "ts": 1756428433.413802, "side": "buy"}
{"type": "orderbook_delta", "seq": 5744, "price": 41, "quantity": -500, "ts": 1756428433.483755, "side": "buy"}
{"type": "orderbook_delta", "seq": 5745, "price": 40, "quantity": 500, "ts": 1756428433.510825, "side": "buy"}
{"type": "orderbook_delta", "seq": 5746, "price": 40, "quantity": -100, "ts": 1756428433.825032, "side": "buy"}
{"type": "orderbook_delta", "seq": 5747, "price": 42, "quantity": 100, "ts": 1756428434.026946, "side": "buy"}
{"type": "orderbook_delta", "seq": 5748, "price": 48, "quantity": -200, "ts": 1756428434.081402, "side": "sell"}
{"type": "orderbook_delta", "seq": 5749, "price": 47, "quantity": 200, "ts": 1756428434.081402, "side": "sell"}
{"type": "orderbook_delta", "seq": 5750, "price": 43, "quantity": -100, "ts": 1756428434.111049, "side": "buy"}
{"type": "orderbook_delta", "seq": 5751, "price": 42, "quantity": 100, "ts": 1756428434.111049, "side": "buy"}
{"type": "orderbook_delta", "seq": 5752, "price": 47, "quantity": -500, "ts": 1756428434.117517, "side": "sell"}
{"type": "orderbook_delta", "seq": 5753, "price": 49, "quantity": -100, "ts": 1756428434.15229, "side": "sell"}
{"type": "orderbook_delta", "seq": 5754, "price": 50, "quantity": 100, "ts": 1756428434.15229, "side": "sell"}
{"type": "orderbook_delta", "seq": 5755, "price": 42, "quantity": -250, "ts": 1756428434.15362, "side": "buy"}
{"type": "orderbook_delta", "seq": 5756, "price": 36, "quantity": -1250, "ts": 1756428434.156739, "side": "buy"}
{"type": "orderbook_delta", "seq": 5757, "price": 49, "quantity": -200, "ts": 1756428434.156856, "side": "sell"}
{"type": "orderbook_delta", "seq": 5758, "price": 32, "quantity": 250, "ts": 1756428434.157764, "side": "buy"}
{"type": "orderbook_delta", "seq": 5759, "price": 46, "quantity": 500, "ts": 1756428434.158751, "side": "sell"}
{"type": "orderbook_delta", "seq": 5760, "price": 38, "quantity": -200, "ts": 1756428434.167894, "side": "buy"}
{"type": "orderbook_delta", "seq": 5761, "price": 51, "quantity": -1250, "ts": 1756428434.176136, "side": "sell"}
{"type": "orderbook_delta", "seq": 5762, "price": 37, "quantity": 200, "ts": 1756428434.221185, "side": "buy"}
{"type": "orderbook_delta", "seq": 5763, "price": 50, "quantity": 1250, "ts": 1756428434.221688, "side": "sell"}
{"type": "orderbook_delta", "seq": 5764, "price": 48, "quantity": 200, "ts": 1756428434.224428, "side": "sell"}
{"type": "orderbook_delta", "seq": 5765, "price": 35, "quantity": 1250, "ts": 1756428434.228078, "side": "buy"}
{"type": "orderbook_delta", "seq": 5766, "price": 37, "quantity": -200, "ts": 1756428434.554075, "side": "buy"}
{"type": "orderbook_delta", "seq": 5767, "price": 35, "quantity": -1250, "ts": 1756428434.554875, "side": "buy"}
{"type": "orderbook_delta", "seq": 5768, "price": 50, "quantity": -1250, "ts": 1756428434.559742, "side": "sell"}
{"type": "orderbook_delta", "seq": 5769, "price": 48, "quantity": -200, "ts": 1756428434.576341, "side": "sell"}
{"type": "orderbook_delta", "seq": 5770, "price": 42, "quantity": -100, "ts": 1756428434.65086, "side": "buy"}
{"type": "orderbook_delta", "seq": 5771, "price": 41, "quantity": 100, "ts": 1756428434.65086, "side": "buy"}
{"type": "orderbook_delta", "seq": 5772, "price": 49, "quantity": 200, "ts": 1756428434.67312, "side": "sell"}
{"type": "orderbook_delta", "seq": 5773, "price": 36, "quantity": 1250, "ts": 1756428434.673559, "side": "buy"}
{"type": "orderbook_delta", "seq": 5774, "price": 51, "quantity": 1250, "ts": 1756428434.676265, "side": "sell"}
{"type": "orderbook_delta", "seq": 5775, "price": 38, "quantity": 200, "ts": 1756428434.677133, "side": "buy"}
{"type": "orderbook_delta", "seq": 5776, "price": 41, "quantity": -100, "ts": 1756428434.715416, "side": "buy"}
{"type": "orderbook_delta", "seq": 5777, "price": 40, "quantity": 100, "ts": 1756428434.715416, "side": "buy"}
{"type": "orderbook_delta", "seq": 5778, "price": 40, "quantity": -100, "ts": 1756428434.818116, "side": "buy"}
{"type": "orderbook_delta", "seq": 5779, "price": 39, "quantity": 100, "ts": 1756428434.818116, "side": "buy"}
{"type": "orderbook_delta", "seq": 5780, "price": 39, "quantity": -100, "ts": 1756428434.865374, "side": "buy"}
{"type": "orderbook_delta", "seq": 5781, "price": 37, "quantity": 100, "ts": 1756428434.865374, "side": "buy"}
{"type": "orderbook_delta", "seq": 5782, "price": 51, "quantity": -1250, "ts": 1756428434.871695, "side": "sell"}
{"type": "orderbook_delta", "seq": 5783, "price": 50, "quantity": 1250, "ts": 1756428434.912184, "side": "sell"}
{"type": "orderbook_delta", "seq": 5784, "price": 48, "quantity": -901, "ts": 1756428435.130553, "side": "sell"}
{"type": "orderbook_delta", "seq": 5785, "price": 48, "quantity": 250, "ts": 1756428435.167278, "side": "sell"}
{"type": "orderbook_delta", "seq": 5786, "price": 58, "quantity": -250, "ts": 1756428435.167508, "side": "sell"}
{"type": "orderbook_delta", "seq": 5787, "price": 46, "quantity": 901, "ts": 1756428435.217763, "side": "sell"}
{"type": "orderbook_delta", "seq": 5788, "price": 50, "quantity": -100, "ts": 1756428435.300128, "side": "sell"}
{"type": "orderbook_delta", "seq": 5789, "price": 45, "quantity": 100, "ts": 1756428435.300128, "side": "sell"}
{"type": "orderbook_delta", "seq": 5790, "price": 49, "quantity": -200, "ts": 1756428436.032086, "side": "sell"}
{"type": "orderbook_delta", "seq": 5791, "price": 38, "quantity": -200, "ts": 1756428436.035533, "side": "buy"}
{"type": "orderbook_delta", "seq": 5792, "price": 36, "quantity": -1250, "ts": 1756428436.036062, "side": "buy"}
{"type": "orderbook_delta", "seq": 5793, "price": 46, "quantity": -500, "ts": 1756428436.040533, "side": "sell"}
{"type": "orderbook_delta", "seq": 5794, "price": 37, "quantity": 200, "ts": 1756428436.074827, "side": "buy"}
{"type": "orderbook_delta", "seq": 5795, "price": 48, "quantity": 200, "ts": 1756428436.075146, "side": "sell"}
{"type": "orderbook_delta", "seq": 5796, "price": 35, "quantity": 1250, "ts": 1756428436.076814, "side": "buy"}
{"type": "orderbook_delta", "seq": 5797, "price": 45, "quantity": 500, "ts": 1756428436.079075, "side": "sell"}
{"type": "orderbook_delta", "seq": 5798, "price": 46, "quantity": -901, "ts": 1756428436.12691, "side": "sell"}
{"type": "orderbook_delta", "seq": 5799, "price": 47, "quantity": 901, "ts": 1756428436.171837, "side": "sell"}
{"type": "orderbook_delta", "seq": 5800, "price": 37, "quantity": -100, "ts": 1756428436.348262, "side": "buy"}
{"type": "orderbook_delta", "seq": 5801, "price": 40, "quantity": 100, "ts": 1756428436.348262, "side": "buy"}
{"type": "orderbook_delta", "seq": 5802, "price": 47, "quantity": -901, "ts": 1756428437.112635, "side": "sell"}
{"type": "orderbook_delta", "seq": 5803, "price": 46, "quantity": 901, "ts": 1756428437.150437, "side": "sell"}
{"type": "orderbook_delta", "seq": 5804, "price": 45, "quantity": -100, "ts": 1756428437.383292, "side": "sell"}
{"type": "orderbook_delta", "seq": 5805, "price": 46, "quantity": 100, "ts": 1756428437.383292, "side": "sell"}
{"type": "orderbook_delta", "seq": 5806, "price": 40, "quantity": -100, "ts": 1756428437.455022, "side": "buy"}
{"type": "orderbook_delta", "seq": 5807, "price": 39, "quantity": 100, "ts": 1756428437.455022, "side": "buy"}
{"type": "orderbook_delta", "seq": 5808, "price": 46, "quantity": -100, "ts": 1756428437.50404, "side": "sell"}
{"type": "orderbook_delta", "seq": 5809, "price": 47, "quantity": 100, "ts": 1756428437.50404, "side": "sell"}
{"type": "orderbook_delta", "seq": 5810, "price": 45, "quantity": -500, "ts": 1756428437.556232, "side": "sell"}
{"type": "orderbook_delta", "seq": 5811, "price": 47, "quantity": -100, "ts": 1756428437.557369, "side": "sell"}
{"type": "orderbook_delta", "seq": 5812, "price": 49, "quantity": 100, "ts": 1756428437.557369, "side": "sell"}
{"type": "orderbook_delta", "seq": 5813, "price": 35, "quantity": -1250, "ts": 1756428437.561863, "side": "buy"}
{"type": "orderbook_delta", "seq": 5814, "price": 36, "quantity": 1250, "ts": 1756428437.612321, "side": "buy"}
{"type": "orderbook_delta", "seq": 5815, "price": 46, "quantity": 500, "ts": 1756428437.613385, "side": "sell"}
{"type": "orderbook_delta", "seq": 5816, "price": 45, "quantity": 100, "ts": 1756428437.788072, "side": "sell"}
{"type": "orderbook_delta", "seq": 5817, "price": 46, "quantity": -901, "ts": 1756428438.098905, "side": "sell"}
{"type": "orderbook_delta", "seq": 5818, "price": 58, "quantity": 250, "ts": 1756428438.103288, "side": "sell"}
{"type": "orderbook_delta", "seq": 5819, "price": 48, "quantity": -250, "ts": 1756428438.116682, "side": "sell"}
{"type": "orderbook_delta", "seq": 5820, "price": 49, "quantity": -100, "ts": 1756428438.118383, "side": "sell"}
{"type": "orderbook_delta", "seq": 5821, "price": 50, "quantity": 100, "ts": 1756428438.118383, "side": "sell"}
{"type": "orderbook_delta", "seq": 5822, "price": 48, "quantity": -200, "ts": 1756428438.151575, "side": "sell"}
{"type": "orderbook_delta", "seq": 5823, "price": 47, "quantity": 901, "ts": 1756428438.162188, "side": "sell"}
{"type": "orderbook_delta", "seq": 5824, "price": 49, "quantity": 200, "ts": 1756428438.193136, "side": "sell"}
{"type": "orderbook_delta", "seq": 5825, "price": 37, "quantity": -200, "ts": 1756428438.649862, "side": "buy"}
{"type": "orderbook_delta", "seq": 5826, "price": 46, "quantity": -500, "ts": 1756428438.651679, "side": "sell"}
{"type": "orderbook_delta", "seq": 5827, "price": 40, "quantity": -500, "ts": 1756428438.652174, "side": "buy"}
{"type": "orderbook_delta", "seq": 5828, "price": 50, "quantity": -1250, "ts": 1756428438.653922, "side": "sell"}
{"type": "orderbook_delta", "seq": 5829, "price": 47, "quantity": -200, "ts": 1756428438.691597, "side": "sell"}
{"type": "orderbook_delta", "seq": 5830, "price": 49, "quantity": 200, "ts": 1756428438.691597, "side": "sell"}
{"type": "orderbook_delta", "seq": 5831, "price": 51, "quantity": 1250, "ts": 1756428438.696092, "side": "sell"}
{"type": "orderbook_delta", "seq": 5832, "price": 38, "quantity": 200, "ts": 1756428438.696581, "side": "buy"}
{"type": "orderbook_delta", "seq": 5833, "price": 41, "quantity": 500, "ts": 1756428438.697647, "side": "buy"}
{"type": "orderbook_delta", "seq": 5834, "price": 47, "quantity": 500, "ts": 1756428438.700174, "side": "sell"}
{"type": "orderbook_delta", "seq": 5835, "price": 51, "quantity": -1250, "ts": 1756428438.877399, "side": "sell"}
{"type": "orderbook_delta", "seq": 5836, "price": 36, "quantity": -1250, "ts": 1756428438.878374, "side": "buy"}
{"type": "orderbook_delta", "seq": 5837, "price": 38, "quantity": -200, "ts": 1756428438.879548, "side": "buy"}
{"type": "orderbook_delta", "seq": 5838, "price": 49, "quantity": -200, "ts": 1756428438.879707, "side": "sell"}
{"type": "orderbook_delta", "seq": 5839, "price": 50, "quantity": -100, "ts": 1756428438.88446, "side": "sell"}
{"type": "orderbook_delta", "seq": 5840, "price": 51, "quantity": 100, "ts": 1756428438.88446, "side": "sell"}
{"type": "orderbook_delta", "seq": 5841, "price": 39, "quantity": -100, "ts": 1756428438.925958, "side": "buy"}
{"type": "orderbook_delta", "seq": 5842, "price": 42, "quantity": 100, "ts": 1756428438.925958, "side": "buy"}
{"type": "orderbook_delta", "seq": 5843, "price": 39, "quantity": 200, "ts": 1756428438.929173, "side": "buy"}
{"type": "orderbook_delta", "seq": 5844, "price": 52, "quantity": 1250, "ts": 1756428438.929945, "side": "sell"}
{"type": "orderbook_delta", "seq": 5845, "price": 50, "quantity": 200, "ts": 1756428438.93091, "side": "sell"}
{"type": "orderbook_delta", "seq": 5846, "price": 37, "quantity": 1250, "ts": 1756428438.931931, "side": "buy"}
{"type": "orderbook_delta", "seq": 5847, "price": 47, "quantity": -901, "ts": 1756428439.20451, "side": "sell"}
{"type": "orderbook_delta", "seq": 5848, "price": 47, "quantity": -500, "ts": 1756428439.235263, "side": "sell"}
{"type": "orderbook_delta", "seq": 5849, "price": 48, "quantity": 901, "ts": 1756428439.241917, "side": "sell"}
{"type": "orderbook_delta", "seq": 5850, "price": 50, "quantity": -200, "ts": 1756428439.281688, "side": "sell"}
{"type": "orderbook_delta", "seq": 5851, "price": 52, "quantity": -1250, "ts": 1756428439.281827, "side": "sell"}
{"type": "orderbook_delta", "seq": 5852, "price": 41, "quantity": -500, "ts": 1756428439.364599, "side": "buy"}
{"type": "orderbook_delta", "seq": 5853, "price": 48, "quantity": 500, "ts": 1756428439.364615, "side": "sell"}
{"type": "orderbook_delta", "seq": 5854, "price": 37, "quantity": -1250, "ts": 1756428439.364896, "side": "buy"}
{"type": "orderbook_delta", "seq": 5855, "price": 39, "quantity": -200, "ts": 1756428439.364938, "side": "buy"}
{"type": "orderbook_delta", "seq": 5856, "price": 42, "quantity": 500, "ts": 1756428439.399463, "side": "buy"}
{"type": "orderbook_delta", "seq": 5857, "price": 51, "quantity": 200, "ts": 1756428439.399741, "side": "sell"}
{"type": "orderbook_delta", "seq": 5858, "price": 53, "quantity": 1250, "ts": 1756428439.399985, "side": "sell"}
{"type": "orderbook_delta", "seq": 5859, "price": 40, "quantity": 200, "ts": 1756428439.401759, "side": "buy"}
{"type": "orderbook_delta", "seq": 5860, "price": 38, "quantity": 1250, "ts": 1756428439.402532, "side": "buy"}
{"type": "trade", "seq": 62, "price": 45, "quantity": 32, "ts": 1756428439.41109, "side": "buy"}
{"type": "orderbook_delta", "seq": 5861, "price": 42, "quantity": -100, "ts": 1756428439.41109, "side": "buy"}
{"type": "orderbook_delta", "seq": 5862, "price": 41, "quantity": 100, "ts": 1756428439.41109, "side": "buy"}
{"type": "orderbook_delta", "seq": 5863, "price": 45, "quantity": 0, "ts": 1756428439.41394, "side": "sell"}
{"type": "orderbook_delta", "seq": 5864, "price": 41, "quantity": -100, "ts": 1756428440.160939, "side": "buy"}
{"type": "orderbook_delta", "seq": 5865, "price": 42, "quantity": 100, "ts": 1756428440.160939, "side": "buy"}
{"type": "orderbook_delta", "seq": 5866, "price": 32, "quantity": -250, "ts": 1756428440.17698, "side": "buy"}
{"type": "orderbook_delta", "seq": 5867, "price": 42, "quantity": 250, "ts": 1756428440.236864, "side": "buy"}
{"type": "orderbook_delta", "seq": 5868, "price": 60, "quantity": 250, "ts": 1756428440.287022, "side": "sell"}
{"type": "orderbook_delta", "seq": 5869, "price": 42, "quantity": -500, "ts": 1756428440.287797, "side": "buy"}
{"type": "orderbook_delta", "seq": 5870, "price": 48, "quantity": -901, "ts": 1756428440.288687, "side": "sell"}
{"type": "orderbook_delta", "seq": 5871, "price": 38, "quantity": -1250, "ts": 1756428440.288759, "side": "buy"}
{"type": "orderbook_delta", "seq": 5872, "price": 48, "quantity": -500, "ts": 1756428440.288812, "side": "sell"}
{"type": "orderbook_delta", "seq": 5873, "price": 40, "quantity": -200, "ts": 1756428440.290133, "side": "buy"}
{"type": "orderbook_delta", "seq": 5874, "price": 53, "quantity": -1250, "ts": 1756428440.290458, "side": "sell"}
{"type": "orderbook_delta", "seq": 5875, "price": 51, "quantity": -100, "ts": 1756428440.307869, "side": "sell"}
{"type": "orderbook_delta", "seq": 5876, "price": 52, "quantity": 100, "ts": 1756428440.307869, "side": "sell"}
{"type": "orderbook_delta", "seq": 5877, "price": 50, "quantity": -250, "ts": 1756428440.308271, "side": "sell"}
{"type": "orderbook_delta", "seq": 5878, "price": 51, "quantity": -200, "ts": 1756428440.311438, "side": "sell"}
{"type": "orderbook_delta", "seq": 5879, "price": 41, "quantity": 1250, "ts": 1756428440.359242, "side": "buy"}
{"type": "orderbook_delta", "seq": 5880, "price": 56, "quantity": 1250, "ts": 1756428440.360685, "side": "sell"}
{"type": "orderbook_delta", "seq": 5881, "price": 50, "quantity": 901, "ts": 1756428440.361455, "side": "sell"}
{"type": "orderbook_delta", "seq": 5882, "price": 54, "quantity": 200, "ts": 1756428440.362207, "side": "sell"}
{"type": "orderbook_delta", "seq": 5883, "price": 41, "quantity": 200, "ts": 1756428440.362897, "side": "buy"}
{"type": "orderbook_delta", "seq": 5884, "price": 51, "quantity": 500, "ts": 1756428440.363182, "side": "sell"}
{"type": "orderbook_delta", "seq": 5885, "price": 43, "quantity": 500, "ts": 1756428440.363525, "side": "buy"}
{"type": "orderbook_delta", "seq": 5886, "price": 52, "quantity": -100, "ts": 1756428440.383973, "side": "sell"}
{"type": "orderbook_delta", "seq": 5887, "price": 53, "quantity": 100, "ts": 1756428440.383973, "side": "sell"}
{"type": "orderbook_delta", "seq": 5888, "price": 41, "quantity": -200, "ts": 1756428440.398524, "side": "buy"}
{"type": "orderbook_delta", "seq": 5889, "price": 53, "quantity": -100, "ts": 1756428440.434723, "side": "sell"}
{"type": "orderbook_delta", "seq": 5890, "price": 54, "quantity": 100, "ts": 1756428440.434723, "side": "sell"}
{"type": "orderbook_delta", "seq": 5891, "price": 43, "quantity": 200, "ts": 1756428440.440313, "side": "buy"}
{"type": "orderbook_delta", "seq": 5892, "price": 49, "quantity": -200, "ts": 1756428440.520271, "side": "sell"}
{"type": "orderbook_delta", "seq": 5893, "price": 53, "quantity": 200, "ts": 1756428440.520271, "side": "sell"}
{"type": "orderbook_delta", "seq": 5894, "price": 43, "quantity": -200, "ts": 1756428440.566715, "side": "buy"}
{"type": "orderbook_delta", "seq": 5895, "price": 41, "quantity": -1250, "ts": 1756428440.566902, "side": "buy"}
{"type": "orderbook_delta", "seq": 5896, "price": 54, "quantity": -200, "ts": 1756428440.567323, "side": "sell"}
{"type": "orderbook_delta", "seq": 5897, "price": 56, "quantity": -1250, "ts": 1756428440.570311, "side": "sell"}
{"type": "orderbook_delta", "seq": 5898, "price": 54, "quantity": -100, "ts": 1756428440.578862, "side": "sell"}
{"type": "orderbook_delta", "seq": 5899, "price": 55, "quantity": 100, "ts": 1756428440.578862, "side": "sell"}
{"type": "orderbook_delta", "seq": 5900, "price": 40, "quantity": 1250, "ts": 1756428440.627238, "side": "buy"}
{"type": "orderbook_delta", "seq": 5901, "price": 42, "quantity": 200, "ts": 1756428440.629412, "side": "buy"}
{"type": "orderbook_delta", "seq": 5902, "price": 53, "quantity": 200, "ts": 1756428440.631231, "side": "sell"}
{"type": "orderbook_delta", "seq": 5903, "price": 55, "quantity": 1250, "ts": 1756428440.631857, "side": "sell"}
{"type": "orderbook_delta", "seq": 5904, "price": 42, "quantity": -100, "ts": 1756428440.754934, "side": "buy"}
{"type": "orderbook_delta", "seq": 5905, "price": 44, "quantity": 100, "ts": 1756428440.754934, "side": "buy"}
{"type": "orderbook_delta", "seq": 5906, "price": 55, "quantity": -1250, "ts": 1756428440.765452, "side": "sell"}
{"type": "orderbook_delta", "seq": 5907, "price": 79, "quantity": -8000, "ts": 1756428440.765704, "side": "sell"}
{"type": "orderbook_delta", "seq": 5908, "price": 42, "quantity": -200, "ts": 1756428440.765944, "side": "buy"}
{"type": "orderbook_delta", "seq": 5909, "price": 40, "quantity": -1250, "ts": 1756428440.766175, "side": "buy"}
{"type": "orderbook_delta", "seq": 5910, "price": 51, "quantity": -500, "ts": 1756428440.766501, "side": "sell"}
{"type": "orderbook_delta", "seq": 5911, "price": 53, "quantity": -200, "ts": 1756428440.771917, "side": "sell"}
{"type": "trade", "seq": 63, "price": 45, "quantity": 68, "ts": 1756428440.987052, "side": "buy"}
{"type": "orderbook_delta", "seq": 5912, "price": 43, "quantity": -500, "ts": 1756428440.987052, "side": "buy"}
{"type": "orderbook_delta", "seq": 5913, "price": 41, "quantity": 1250, "ts": 1756428440.990637, "side": "buy"}
{"type": "orderbook_delta", "seq": 5914, "price": 54, "quantity": 200, "ts": 1756428440.991119, "side": "sell"}
{"type": "orderbook_delta", "seq": 5915, "price": 43, "quantity": 200, "ts": 1756428440.992473, "side": "buy"}
{"type": "orderbook_delta", "seq": 5916, "price": 80, "quantity": 8000, "ts": 1756428440.993237, "side": "sell"}
{"type": "orderbook_delta", "seq": 5917, "price": 52, "quantity": 500, "ts": 1756428440.993725, "side": "sell"}
{"type": "orderbook_delta", "seq": 5918, "price": 56, "quantity": 1250, "ts": 1756428440.99461, "side": "sell"}
{"type": "orderbook_delta", "seq": 5919, "price": 53, "quantity": -200, "ts": 1756428441.07431, "side": "sell"}
{"type": "orderbook_delta", "seq": 5920, "price": 54, "quantity": 200, "ts": 1756428441.07431, "side": "sell"}
{"type": "orderbook_delta", "seq": 5921, "price": 50, "quantity": -901, "ts": 1756428441.095848, "side": "sell"}
{"type": "orderbook_delta", "seq": 5922, "price": 45, "quantity": 0, "ts": 1756428441.09843, "side": "sell"}
{"type": "orderbook_delta", "seq": 5923, "price": 44, "quantity": 500, "ts": 1756428441.13007, "side": "buy"}
{"type": "orderbook_delta", "seq": 5924, "price": 62, "quantity": 250, "ts": 1756428441.147048, "side": "sell"}
{"type": "orderbook_delta", "seq": 5925, "price": 54, "quantity": -200, "ts": 1756428441.418954, "side": "sell"}
{"type": "orderbook_delta", "seq": 5926, "price": 41, "quantity": -1250, "ts": 1756428441.419618, "side": "buy"}
{"type": "orderbook_delta", "seq": 5927, "price": 56, "quantity": -1250, "ts": 1756428441.420772, "side": "sell"}
{"type": "orderbook_delta", "seq": 5928, "price": 44, "quantity": -500, "ts": 1756428441.421426, "side": "buy"}
{"type": "orderbook_delta", "seq": 5929, "price": 44, "quantity": -100, "ts": 1756428441.423027, "side": "buy"}
{"type": "orderbook_delta", "seq": 5930, "price": 45, "quantity": 100, "ts": 1756428441.423027, "side": "buy"}
{"type": "orderbook_delta", "seq": 5931, "price": 46, "quantity": 250, "ts": 1756428441.446231, "side": "buy"}
{"type": "orderbook_delta", "seq": 5932, "price": 80, "quantity": -8000, "ts": 1756428441.446817, "side": "sell"}
{"type": "orderbook_delta", "seq": 5933, "price": 36, "quantity": -250, "ts": 1756428441.447104, "side": "buy"}
{"type": "orderbook_delta", "seq": 5934, "price": 52, "quantity": -500, "ts": 1756428441.447745, "side": "sell"}
{"type": "orderbook_delta", "seq": 5935, "price": 54, "quantity": -250, "ts": 1756428441.55808, "side": "sell"}
{"type": "orderbook_delta", "seq": 5936, "price": 64, "quantity": 250, "ts": 1756428441.558712, "side": "sell"}
{"type": "orderbook_delta", "seq": 5937, "price": 44, "quantity": 250, "ts": 1756428441.559022, "side": "buy"}
{"type": "orderbook_delta", "seq": 5938, "price": 52, "quantity": -250, "ts": 1756428441.559344, "side": "sell"}
{"type": "orderbook_delta", "seq": 5939, "price": 42, "quantity": 1250, "ts": 1756428441.585041, "side": "buy"}
{"type": "orderbook_delta", "seq": 5940, "price": 53, "quantity": 500, "ts": 1756428441.585624, "side": "sell"}
{"type": "orderbook_delta", "seq": 5941, "price": 57, "quantity": 1250, "ts": 1756428441.586955, "side": "sell"}
{"type": "orderbook_delta", "seq": 5942, "price": 98, "quantity": 8000, "ts": 1756428441.587409, "side": "sell"}
{"type": "orderbook_delta", "seq": 5943, "price": 47, "quantity": 500, "ts": 1756428441.58949, "side": "buy"}
{"type": "orderbook_delta", "seq": 5944, "price": 55, "quantity": 200, "ts": 1756428441.589964, "side": "sell"}
{"type": "orderbook_delta", "seq": 5945, "price": 45, "quantity": -100, "ts": 1756428441.617646, "side": "buy"}
{"type": "orderbook_delta", "seq": 5946, "price": 43, "quantity": -200, "ts": 1756428441.643854, "side": "buy"}
{"type": "orderbook_delta", "seq": 5947, "price": 66, "quantity": 250, "ts": 1756428441.646438, "side": "sell"}
{"type": "orderbook_delta", "seq": 5948, "price": 56, "quantity": -250, "ts": 1756428441.64774, "side": "sell"}
{"type": "orderbook_delta", "seq": 5949, "price": 46, "quantity": -250, "ts": 1756428441.671392, "side": "buy"}
{"type": "orderbook_delta", "seq": 5950, "price": 34, "quantity": -250, "ts": 1756428441.678096, "side": "buy"}
{"type": "orderbook_delta", "seq": 5951, "price": 44, "quantity": 200, "ts": 1756428441.705355, "side": "buy"}
{"type": "orderbook_delta", "seq": 5952, "price": 55, "quantity": -200, "ts": 1756428441.706034, "side": "sell"}
{"type": "orderbook_delta", "seq": 5953, "price": 66, "quantity": -250, "ts": 1756428441.706309, "side": "sell"}
{"type": "orderbook_delta", "seq": 5954, "price": 47, "quantity": -500, "ts": 1756428441.71649, "side": "buy"}
{"type": "orderbook_delta", "seq": 5955, "price": 55, "quantity": -100, "ts": 1756428441.744428, "side": "sell"}
{"type": "orderbook_delta", "seq": 5956, "price": 53, "quantity": 969, "ts": 1756428441.746818, "side": "sell"}
{"type": "orderbook_delta", "seq": 5957, "price": 57, "quantity": 200, "ts": 1756428441.795185, "side": "sell"}
{"type": "orderbook_delta", "seq": 5958, "price": 45, "quantity": 500, "ts": 1756428441.797347, "side": "buy"}
{"type": "orderbook_delta", "seq": 5959, "price": 45, "quantity": 100, "ts": 1756428441.799417, "side": "buy"}
{"type": "orderbook_delta", "seq": 5960, "price": 45, "quantity": -500, "ts": 1756428441.839816, "side": "buy"}
{"type": "orderbook_delta", "seq": 5961, "price": 56, "quantity": 100, "ts": 1756428441.861586, "side": "sell"}
{"type": "orderbook_delta", "seq": 5962, "price": 46, "quantity": 500, "ts": 1756428441.876185, "side": "buy"}
{"type": "orderbook_delta", "seq": 5963, "price": 45, "quantity": -100, "ts": 1756428442.042136, "side": "buy"}
{"type": "orderbook_delta", "seq": 5964, "price": 47, "quantity": 100, "ts": 1756428442.042136, "side": "buy"}
{"type": "orderbook_delta", "seq": 5965, "price": 46, "quantity": -500, "ts": 1756428442.094655, "side": "buy"}
{"type": "orderbook_delta", "seq": 5966, "price": 38, "quantity": -250, "ts": 1756428442.125337, "side": "buy"}
{"type": "orderbook_delta", "seq": 5967, "price": 48, "quantity": 250, "ts": 1756428442.129195, "side": "buy"}
{"type": "orderbook_delta", "seq": 5968, "price": 47, "quantity": 500, "ts": 1756428442.144206, "side": "buy"}
{"type": "orderbook_delta", "seq": 5969, "price": 53, "quantity": -500, "ts": 1756428442.153623, "side": "sell"}
{"type": "orderbook_delta", "seq": 5970, "price": 46, "quantity": 250, "ts": 1756428442.176346, "side": "buy"}
{"type": "orderbook_delta", "seq": 5971, "price": 47, "quantity": -500, "ts": 1756428442.180243, "side": "buy"}
{"type": "orderbook_delta", "seq": 5972, "price": 52, "quantity": 500, "ts": 1756428442.203906, "side": "sell"}
{"type": "orderbook_delta", "seq": 5973, "price": 46, "quantity": 500, "ts": 1756428442.2142, "side": "buy"}
{"type": "orderbook_delta", "seq": 5974, "price": 48, "quantity": -250, "ts": 1756428442.250093, "side": "buy"}
{"type": "orderbook_delta", "seq": 5975, "price": 47, "quantity": -100, "ts": 1756428442.288072, "side": "buy"}
{"type": "orderbook_delta", "seq": 5976, "price": 48, "quantity": 100, "ts": 1756428442.288072, "side": "buy"}
{"type": "orderbook_delta", "seq": 5977, "price": 52, "quantity": -500, "ts": 1756428442.341485, "side": "sell"}
{"type": "orderbook_delta", "seq": 5978, "price": 57, "quantity": -1250, "ts": 1756428442.341713, "side": "sell"}
{"type": "orderbook_delta", "seq": 5979, "price": 44, "quantity": -200, "ts": 1756428442.342678, "side": "buy"}
{"type": "orderbook_delta", "seq": 5980, "price": 42, "quantity": -1250, "ts": 1756428442.342947, "side": "buy"}
{"type": "orderbook_delta", "seq": 5981, "price": 46, "quantity": -500, "ts": 1756428442.344031, "side": "buy"}
{"type": "orderbook_delta", "seq": 5982, "price": 45, "quantity": 200, "ts": 1756428442.384265, "side": "buy"}
{"type": "orderbook_delta", "seq": 5983, "price": 53, "quantity": 500, "ts": 1756428442.384808, "side": "sell"}
{"type": "orderbook_delta", "seq": 5984, "price": 43, "quantity": 1250, "ts": 1756428442.386621, "side": "buy"}
{"type": "orderbook_delta", "seq": 5985, "price": 47, "quantity": 500, "ts": 1756428442.387998, "side": "buy"}
{"type": "orderbook_delta", "seq": 5986, "price": 58, "quantity": 1250, "ts": 1756428442.391061, "side": "sell"}
{"type": "orderbook_delta", "seq": 5987, "price": 54, "quantity": -200, "ts": 1756428442.393298, "side": "sell"}
{"type": "orderbook_delta", "seq": 5988, "price": 55, "quantity": 200, "ts": 1756428442.393298, "side": "sell"}
{"type": "orderbook_delta", "seq": 5989, "price": 48, "quantity": -100, "ts": 1756428442.585645, "side": "buy"}
{"type": "orderbook_delta", "seq": 5990, "price": 47, "quantity": 100, "ts": 1756428442.585645, "side": "buy"}
{"type": "orderbook_delta", "seq": 5991, "price": 56, "quantity": -100, "ts": 1756428442.680482, "side": "sell"}
{"type": "orderbook_delta", "seq": 5992, "price": 58, "quantity": 100, "ts": 1756428442.680482, "side": "sell"}
{"type": "orderbook_delta", "seq": 5993, "price": 48, "quantity": 250, "ts": 1756428443.09759, "side": "buy"}
{"type": "orderbook_delta", "seq": 5994, "price": 53, "quantity": -969, "ts": 1756428443.101435, "side": "sell"}
{"type": "orderbook_delta", "seq": 5995, "price": 54, "quantity": 969, "ts": 1756428443.152956, "side": "sell"}
{"type": "orderbook_delta", "seq": 5996, "price": 42, "quantity": -100, "ts": 1756428443.161266, "side": "buy"}
{"type": "orderbook_delta", "seq": 5997, "price": 12, "quantity": -8000, "ts": 1756428443.256261, "side": "buy"}
{"type": "orderbook_delta", "seq": 5998, "price": 53, "quantity": -500, "ts": 1756428443.259125, "side": "sell"}
{"type": "orderbook_delta", "seq": 5999, "price": 43, "quantity": -1250, "ts": 1756428443.260072, "side": "buy"}
{"type": "orderbook_delta", "seq": 6000, "price": 45, "quantity": -200, "ts": 1756428443.260417, "side": "buy"}
{"type": "orderbook_delta", "seq": 6001, "price": 47, "quantity": -500, "ts": 1756428443.263516, "side": "buy"}
{"type": "orderbook_delta", "seq": 6002, "price": 58, "quantity": -1250, "ts": 1756428443.264927, "side": "sell"}
{"type": "orderbook_delta", "seq": 6003, "price": 55, "quantity": -200, "ts": 1756428443.286176, "side": "sell"}
{"type": "orderbook_delta", "seq": 6004, "price": 58, "quantity": 200, "ts": 1756428443.286176, "side": "sell"}
{"type": "orderbook_delta", "seq": 6005, "price": 54, "quantity": 500, "ts": 1756428443.299094, "side": "sell"}
{"type": "orderbook_delta", "seq": 6006, "price": 46, "quantity": 200, "ts": 1756428443.299965, "side": "buy"}
{"type": "orderbook_delta", "seq": 6007, "price": 20, "quantity": 8000, "ts": 1756428443.300336, "side": "buy"}
{"type": "orderbook_delta", "seq": 6008, "price": 38, "quantity": 250, "ts": 1756428443.300671, "side": "buy"}
{"type": "orderbook_delta", "seq": 6009, "price": 59, "quantity": 1250, "ts": 1756428443.301191, "side": "sell"}
{"type": "orderbook_delta", "seq": 6010, "price": 44, "quantity": 1250, "ts": 1756428443.301907, "side": "buy"}
{"type": "orderbook_delta", "seq": 6011, "price": 48, "quantity": -250, "ts": 1756428443.30226, "side": "buy"}
{"type": "orderbook_delta", "seq": 6012, "price": 48, "quantity": 500, "ts": 1756428443.307665, "side": "buy"}
{"type": "orderbook_delta", "seq": 6013, "price": 47, "quantity": -100, "ts": 1756428443.345316, "side": "buy"}
{"type": "orderbook_delta", "seq": 6014, "price": 49, "quantity": 100, "ts": 1756428443.345316, "side": "buy"}
{"type": "orderbook_delta", "seq": 6015, "price": 38, "quantity": -250, "ts": 1756428443.371882, "side": "buy"}
{"type": "orderbook_delta", "seq": 6016, "price": 48, "quantity": -500, "ts": 1756428443.381093, "side": "buy"}
{"type": "orderbook_delta", "seq": 6017, "price": 47, "quantity": 500, "ts": 1756428443.415713, "side": "buy"}
{"type": "orderbook_delta", "seq": 6018, "price": 54, "quantity": -500, "ts": 1756428443.623966, "side": "sell"}
{"type": "orderbook_delta", "seq": 6019, "price": 20, "quantity": -8000, "ts": 1756428443.624519, "side": "buy"}
{"type": "orderbook_delta", "seq": 6020, "price": 47, "quantity": -500, "ts": 1756428443.628092, "side": "buy"}
{"type": "orderbook_delta", "seq": 6021, "price": 49, "quantity": 500, "ts": 1756428443.666715, "side": "buy"}
{"type": "orderbook_delta", "seq": 6022, "price": 21, "quantity": 8000, "ts": 1756428443.669704, "side": "buy"}
{"type": "orderbook_delta", "seq": 6023, "price": 57, "quantity": 500, "ts": 1756428443.670104, "side": "sell"}
{"type": "orderbook_delta", "seq": 6024, "price": 49, "quantity": -100, "ts": 1756428443.721568, "side": "buy"}
{"type": "orderbook_delta", "seq": 6025, "price": 50, "quantity": 100, "ts": 1756428443.721568, "side": "buy"}
{"type": "orderbook_delta", "seq": 6026, "price": 49, "quantity": -500, "ts": 1756428443.782412, "side": "buy"}
{"type": "orderbook_delta", "seq": 6027, "price": 46, "quantity": -200, "ts": 1756428443.784683, "side": "buy"}
{"type": "orderbook_delta", "seq": 6028, "price": 57, "quantity": -200, "ts": 1756428443.790176, "side": "sell"}
{"type": "orderbook_delta", "seq": 6029, "price": 59, "quantity": -1250, "ts": 1756428443.790332, "side": "sell"}
{"type": "orderbook_delta", "seq": 6030, "price": 44, "quantity": -1250, "ts": 1756428443.812043, "side": "buy"}
{"type": "orderbook_delta", "seq": 6031, "price": 47, "quantity": 500, "ts": 1756428443.81878, "side": "buy"}
{"type": "orderbook_delta", "seq": 6032, "price": 45, "quantity": 1250, "ts": 1756428443.844227, "side": "buy"}
{"type": "orderbook_delta", "seq": 6033, "price": 58, "quantity": 200, "ts": 1756428443.846634, "side": "sell"}
{"type": "orderbook_delta", "seq": 6034, "price": 60, "quantity": 1250, "ts": 1756428443.846923, "side": "sell"}
{"type": "orderbook_delta", "seq": 6035, "price": 47, "quantity": 200, "ts": 1756428443.847166, "side": "buy"}
{"type": "orderbook_delta", "seq": 6036, "price": 58, "quantity": -100, "ts": 1756428444.238801, "side": "sell"}
{"type": "orderbook_delta", "seq": 6037, "price": 55, "quantity": 100, "ts": 1756428444.238801, "side": "sell"}
{"type": "orderbook_delta", "seq": 6038, "price": 57, "quantity": -500, "ts": 1756428444.269351, "side": "sell"}
{"type": "orderbook_delta", "seq": 6039, "price": 55, "quantity": 500, "ts": 1756428444.30942, "side": "sell"}
{"type": "orderbook_delta", "seq": 6040, "price": 54, "quantity": -969, "ts": 1756428444.910136, "side": "sell"}
{"type": "orderbook_delta", "seq": 6041, "price": 66, "quantity": 250, "ts": 1756428444.910329, "side": "sell"}
{"type": "orderbook_delta", "seq": 6042, "price": 55, "quantity": 969, "ts": 1756428444.954194, "side": "sell"}
{"type": "orderbook_delta", "seq": 6043, "price": 55, "quantity": -100, "ts": 1756428444.959718, "side": "sell"}
{"type": "orderbook_delta", "seq": 6044, "price": 57, "quantity": 100, "ts": 1756428444.959718, "side": "sell"}
{"type": "orderbook_delta", "seq": 6045, "price": 57, "quantity": -100, "ts": 1756428445.043704, "side": "sell"}
{"type": "orderbook_delta", "seq": 6046, "price": 58, "quantity": 100, "ts": 1756428445.043704, "side": "sell"}
{"type": "orderbook_delta", "seq": 6047, "price": 58, "quantity": -200, "ts": 1756428445.160753, "side": "sell"}
{"type": "orderbook_delta", "seq": 6048, "price": 60, "quantity": -1250, "ts": 1756428445.160858, "side": "sell"}
{"type": "orderbook_delta", "seq": 6049, "price": 21, "quantity": -8000, "ts": 1756428445.161273, "side": "buy"}
{"type": "orderbook_delta", "seq": 6050, "price": 55, "quantity": -500, "ts": 1756428445.161665, "side": "sell"}
{"type": "orderbook_delta", "seq": 6051, "price": 47, "quantity": -200, "ts": 1756428445.161963, "side": "buy"}
{"type": "orderbook_delta", "seq": 6052, "price": 45, "quantity": -1250, "ts": 1756428445.162528, "side": "buy"}
{"type": "orderbook_delta", "seq": 6053, "price": 54, "quantity": 500, "ts": 1756428445.204702, "side": "sell"}
{"type": "orderbook_delta", "seq": 6054, "price": 44, "quantity": 1250, "ts": 1756428445.205749, "side": "buy"}
{"type": "orderbook_delta", "seq": 6055, "price": 46, "quantity": 200, "ts": 1756428445.207401, "side": "buy"}
{"type": "orderbook_delta", "seq": 6056, "price": 59, "quantity": 1250, "ts": 1756428445.208263, "side": "sell"}
{"type": "orderbook_delta", "seq": 6057, "price": 20, "quantity": 8000, "ts": 1756428445.210531, "side": "buy"}
{"type": "orderbook_delta", "seq": 6058, "price": 57, "quantity": 200, "ts": 1756428445.214655, "side": "sell"}
{"type": "orderbook_delta", "seq": 6059, "price": 58, "quantity": -200, "ts": 1756428445.266073, "side": "sell"}
{"type": "orderbook_delta", "seq": 6060, "price": 57, "quantity": 200, "ts": 1756428445.266073, "side": "sell"}
{"type": "orderbook_delta", "seq": 6061, "price": 46, "quantity": -200, "ts": 1756428445.343445, "side": "buy"}
{"type": "orderbook_delta", "seq": 6062, "price": 59, "quantity": -1250, "ts": 1756428445.345187, "side": "sell"}
{"type": "orderbook_delta", "seq": 6063, "price": 57, "quantity": -200, "ts": 1756428445.346791, "side": "sell"}
{"type": "orderbook_delta", "seq": 6064, "price": 44, "quantity": -1250, "ts": 1756428445.34994, "side": "buy"}
{"type": "orderbook_delta", "seq": 6065, "price": 50, "quantity": -100, "ts": 1756428445.416544, "side": "buy"}
{"type": "orderbook_delta", "seq": 6066, "price": 48, "quantity": 100, "ts": 1756428445.416544, "side": "buy"}
{"type": "orderbook_delta", "seq": 6067, "price": 43, "quantity": 1250, "ts": 1756428445.439067, "side": "buy"}
{"type": "orderbook_delta", "seq": 6068, "price": 58, "quantity": 1250, "ts": 1756428445.439339, "side": "sell"}
{"type": "orderbook_delta", "seq": 6069, "price": 56, "quantity": 200, "ts": 1756428445.439606, "side": "sell"}
{"type": "orderbook_delta", "seq": 6070, "price": 45, "quantity": 200, "ts": 1756428445.444136, "side": "buy"}
{"type": "orderbook_delta", "seq": 6071, "price": 47, "quantity": -500, "ts": 1756428445.579261, "side": "buy"}
{"type": "orderbook_delta", "seq": 6072, "price": 48, "quantity": 500, "ts": 1756428445.632801, "side": "buy"}
{"type": "orderbook_delta", "seq": 6073, "price": 48, "quantity": -100, "ts": 1756428446.232518, "side": "buy"}
{"type": "orderbook_delta", "seq": 6074, "price": 49, "quantity": 100, "ts": 1756428446.232518, "side": "buy"}
{"type": "orderbook_delta", "seq": 6075, "price": 48, "quantity": -500, "ts": 1756428446.267231, "side": "buy"}
{"type": "orderbook_delta", "seq": 6076, "price": 47, "quantity": 500, "ts": 1756428446.326256, "side": "buy"}
{"type": "orderbook_delta", "seq": 6077, "price": 58, "quantity": -100, "ts": 1756428446.624647, "side": "sell"}
{"type": "orderbook_delta", "seq": 6078, "price": 56, "quantity": 100, "ts": 1756428446.624647, "side": "sell"}
{"type": "orderbook_delta", "seq": 6079, "price": 54, "quantity": -500, "ts": 1756428446.799352, "side": "sell"}
{"type": "orderbook_delta", "seq": 6080, "price": 58, "quantity": -1250, "ts": 1756428446.799721, "side": "sell"}
{"type": "orderbook_delta", "seq": 6081, "price": 56, "quantity": -200, "ts": 1756428446.799827, "side": "sell"}
{"type": "orderbook_delta", "seq": 6082, "price": 20, "quantity": -8000, "ts": 1756428446.800384, "side": "buy"}
{"type": "orderbook_delta", "seq": 6083, "price": 47, "quantity": -500, "ts": 1756428446.801094, "side": "buy"}
{"type": "orderbook_delta", "seq": 6084, "price": 45, "quantity": -200, "ts": 1756428446.80158, "side": "buy"}
{"type": "orderbook_delta", "seq": 6085, "price": 43, "quantity": -1250, "ts": 1756428446.806339, "side": "buy"}
{"type": "orderbook_delta", "seq": 6086, "price": 44, "quantity": 1250, "ts": 1756428446.854097, "side": "buy"}
{"type": "orderbook_delta", "seq": 6087, "price": 59, "quantity": 1250, "ts": 1756428446.85567, "side": "sell"}
{"type": "orderbook_delta", "seq": 6088, "price": 21, "quantity": 8000, "ts": 1756428446.856168, "side": "buy"}
{"type": "orderbook_delta", "seq": 6089, "price": 55, "quantity": 500, "ts": 1756428446.856476, "side": "sell"}
{"type": "orderbook_delta", "seq": 6090, "price": 49, "quantity": 500, "ts": 1756428446.857514, "side": "buy"}
{"type": "orderbook_delta", "seq": 6091, "price": 46, "quantity": 200, "ts": 1756428446.858183, "side": "buy"}
{"type": "orderbook_delta", "seq": 6092, "price": 57, "quantity": 200, "ts": 1756428446.859478, "side": "sell"}
{"type": "orderbook_delta", "seq": 6093, "price": 49, "quantity": -100, "ts": 1756428446.908151, "side": "buy"}
{"type": "orderbook_delta", "seq": 6094, "price": 50, "quantity": 100, "ts": 1756428446.908151, "side": "buy"}
{"type": "orderbook_delta", "seq": 6095, "price": 49, "quantity": -500, "ts": 1756428446.942188, "side": "buy"}
{"type": "orderbook_delta", "seq": 6096, "price": 47, "quantity": 500, "ts": 1756428446.975044, "side": "buy"}
{"type": "orderbook_delta", "seq": 6097, "price": 49, "quantity": 100, "ts": 1756428447.521275, "side": "buy"}
{"type": "orderbook_delta", "seq": 6098, "price": 55, "quantity": -500, "ts": 1756428447.616193, "side": "sell"}
{"type": "orderbook_delta", "seq": 6099, "price": 21, "quantity": -8000, "ts": 1756428447.616262, "side": "buy"}
{"type": "orderbook_delta", "seq": 6100, "price": 20, "quantity": 8000, "ts": 1756428447.685723, "side": "buy"}
{"type": "orderbook_delta", "seq": 6101, "price": 54, "quantity": 500, "ts": 1756428447.687456, "side": "sell"}
{"type": "orderbook_delta", "seq": 6102, "price": 50, "quantity": -100, "ts": 1756428447.692194, "side": "buy"}
{"type": "orderbook_delta", "seq": 6103, "price": 48, "quantity": 100, "ts": 1756428447.692194, "side": "buy"}
{"type": "orderbook_delta", "seq": 6104, "price": 57, "quantity": -200, "ts": 1756428447.707614, "side": "sell"}
{"type": "orderbook_delta", "seq": 6105, "price": 54, "quantity": 200, "ts": 1756428447.707614, "side": "sell"}
{"type": "orderbook_delta", "seq": 6106, "price": 47, "quantity": -500, "ts": 1756428447.726787, "side": "buy"}
{"type": "orderbook_delta", "seq": 6107, "price": 56, "quantity": -100, "ts": 1756428447.731375, "side": "sell"}
{"type": "orderbook_delta", "seq": 6108, "price": 57, "quantity": 100, "ts": 1756428447.731375, "side": "sell"}
{"type": "orderbook_delta", "seq": 6109, "price": 48, "quantity": 500, "ts": 1756428447.935303, "side": "buy"}
{"type": "orderbook_delta", "seq": 6110, "price": 38, "quantity": 250, "ts": 1756428448.010586, "side": "buy"}
{"type": "orderbook_delta", "seq": 6111, "price": 54, "quantity": -500, "ts": 1756428448.019656, "side": "sell"}
{"type": "orderbook_delta", "seq": 6112, "price": 57, "quantity": -200, "ts": 1756428448.020002, "side": "sell"}
{"type": "orderbook_delta", "seq": 6113, "price": 44, "quantity": -1250, "ts": 1756428448.020313, "side": "buy"}
{"type": "orderbook_delta", "seq": 6114, "price": 48, "quantity": -500, "ts": 1756428448.022032, "side": "buy"}
{"type": "orderbook_delta", "seq": 6115, "price": 46, "quantity": -200, "ts": 1756428448.022263, "side": "buy"}
{"type": "orderbook_delta", "seq": 6116, "price": 59, "quantity": -1250, "ts": 1756428448.029011, "side": "sell"}
{"type": "orderbook_delta", "seq": 6117, "price": 20, "quantity": -8000, "ts": 1756428448.029488, "side": "buy"}
{"type": "orderbook_delta", "seq": 6118, "price": 44, "quantity": 200, "ts": 1756428448.090541, "side": "buy"}
{"type": "orderbook_delta", "seq": 6119, "price": 57, "quantity": 1250, "ts": 1756428448.092852, "side": "sell"}
{"type": "orderbook_delta", "seq": 6120, "price": 47, "quantity": 500, "ts": 1756428448.093169, "side": "buy"}
{"type": "orderbook_delta", "seq": 6121, "price": 53, "quantity": 500, "ts": 1756428448.093455, "side": "sell"}
{"type": "orderbook_delta", "seq": 6122, "price": 12, "quantity": 8000, "ts": 1756428448.093924, "side": "buy"}
{"type": "orderbook_delta", "seq": 6123, "price": 42, "quantity": 1250, "ts": 1756428448.097142, "side": "buy"}
{"type": "orderbook_delta", "seq": 6124, "price": 55, "quantity": -969, "ts": 1756428448.097609, "side": "sell"}
{"type": "orderbook_delta", "seq": 6125, "price": 36, "quantity": 250, "ts": 1756428448.098878, "side": "buy"}
{"type": "orderbook_delta", "seq": 6126, "price": 56, "quantity": 250, "ts": 1756428448.116691, "side": "sell"}
{"type": "orderbook_delta", "seq": 6127, "price": 66, "quantity": -250, "ts": 1756428448.135997, "side": "sell"}
{"type": "orderbook_delta", "seq": 6128, "price": 55, "quantity": 200, "ts": 1756428448.144889, "side": "sell"}
{"type": "orderbook_delta", "seq": 6129, "price": 46, "quantity": -250, "ts": 1756428448.224625, "side": "buy"}
{"type": "orderbook_delta", "seq": 6130, "price": 36, "quantity": -250, "ts": 1756428448.227319, "side": "buy"}
{"type": "orderbook_delta", "seq": 6131, "price": 49, "quantity": -100, "ts": 1756428448.256997, "side": "buy"}
{"type": "orderbook_delta", "seq": 6132, "price": 47, "quantity": -500, "ts": 1756428448.257853, "side": "buy"}
{"type": "orderbook_delta", "seq": 6133, "price": 53, "quantity": 969, "ts": 1756428448.277562, "side": "sell"}
{"type": "orderbook_delta", "seq": 6134, "price": 45, "quantity": 500, "ts": 1756428448.312669, "side": "buy"}
{"type": "orderbook_delta", "seq": 6135, "price": 48, "quantity": -100, "ts": 1756428448.364237, "side": "buy"}
{"type": "orderbook_delta", "seq": 6136, "price": 46, "quantity": 100, "ts": 1756428448.364237, "side": "buy"}
{"type": "orderbook_delta", "seq": 6137, "price": 45, "quantity": -500, "ts": 1756428448.407963, "side": "buy"}
{"type": "orderbook_delta", "seq": 6138, "price": 47, "quantity": 500, "ts": 1756428448.45198, "side": "buy"}
{"type": "orderbook_delta", "seq": 6139, "price": 46, "quantity": -100, "ts": 1756428448.458467, "side": "buy"}
{"type": "orderbook_delta", "seq": 6140, "price": 45, "quantity": 100, "ts": 1756428448.458467, "side": "buy"}
{"type": "orderbook_delta", "seq": 6141, "price": 50, "quantity": 100, "ts": 1756428448.461615, "side": "buy"}
{"type": "orderbook_delta", "seq": 6142, "price": 47, "quantity": -500, "ts": 1756428448.492761, "side": "buy"}
{"type": "orderbook_delta", "seq": 6143, "price": 57, "quantity": -100, "ts": 1756428448.507971, "side": "sell"}
{"type": "orderbook_delta", "seq": 6144, "price": 54, "quantity": 100, "ts": 1756428448.507971, "side": "sell"}
{"type": "orderbook_delta", "seq": 6145, "price": 46, "quantity": 500, "ts": 1756428448.527694, "side": "buy"}
{"type": "orderbook_delta", "seq": 6146, "price": 53, "quantity": -969, "ts": 1756428449.113163, "side": "sell"}
{"type": "orderbook_delta", "seq": 6147, "price": 52, "quantity": 969, "ts": 1756428449.148955, "side": "sell"}
{"type": "orderbook_delta", "seq": 6148, "price": 45, "quantity": -100, "ts": 1756428449.218036, "side": "buy"}
{"type": "orderbook_delta", "seq": 6149, "price": 47, "quantity": 100, "ts": 1756428449.218036, "side": "buy"}
{"type": "orderbook_delta", "seq": 6150, "price": 46, "quantity": -500, "ts": 1756428449.285976, "side": "buy"}
{"type": "orderbook_delta", "seq": 6151, "price": 47, "quantity": 500, "ts": 1756428449.35543, "side": "buy"}
{"type": "orderbook_delta", "seq": 6152, "price": 47, "quantity": -100, "ts": 1756428449.491411, "side": "buy"}
{"type": "orderbook_delta", "seq": 6153, "price": 48, "quantity": 100, "ts": 1756428449.491411, "side": "buy"}
{"type": "orderbook_delta", "seq": 6154, "price": 47, "quantity": -500, "ts": 1756428449.601531, "side": "buy"}
{"type": "orderbook_delta", "seq": 6155, "price": 45, "quantity": 500, "ts": 1756428449.638646, "side": "buy"}
{"type": "orderbook_delta", "seq": 6156, "price": 54, "quantity": -100, "ts": 1756428449.772725, "side": "sell"}
{"type": "orderbook_delta", "seq": 6157, "price": 55, "quantity": 100, "ts": 1756428449.772725, "side": "sell"}
{"type": "orderbook_delta", "seq": 6158, "price": 66, "quantity": 250, "ts": 1756428449.98165, "side": "sell"}
{"type": "orderbook_delta", "seq": 6159, "price": 45, "quantity": -500, "ts": 1756428449.982137, "side": "buy"}
{"type": "orderbook_delta", "seq": 6160, "price": 52, "quantity": -969, "ts": 1756428449.984244, "side": "sell"}
{"type": "orderbook_delta", "seq": 6161, "price": 53, "quantity": -500, "ts": 1756428449.984977, "side": "sell"}
{"type": "orderbook_delta", "seq": 6162, "price": 44, "quantity": -200, "ts": 1756428449.986027, "side": "buy"}
{"type": "orderbook_delta", "seq": 6163, "price": 42, "quantity": -1250, "ts": 1756428449.986206, "side": "buy"}
{"type": "orderbook_delta", "seq": 6164, "price": 55, "quantity": -200, "ts": 1756428449.9865, "side": "sell"}
{"type": "orderbook_delta", "seq": 6165, "price": 12, "quantity": -8000, "ts": 1756428449.986566, "side": "buy"}
{"type": "orderbook_delta", "seq": 6166, "price": 56, "quantity": -250, "ts": 1756428449.996955, "side": "sell"}
{"type": "orderbook_delta", "seq": 6167, "price": 57, "quantity": -1250, "ts": 1756428449.997082, "side": "sell"}
{"type": "orderbook_delta", "seq": 6168, "price": 55, "quantity": -100, "ts": 1756428450.03853, "side": "sell"}
{"type": "orderbook_delta", "seq": 6169, "price": 56, "quantity": 100, "ts": 1756428450.03853, "side": "sell"}
{"type": "orderbook_delta", "seq": 6170, "price": 55, "quantity": 500, "ts": 1756428450.040882, "side": "sell"}
{"type": "orderbook_delta", "seq": 6171, "price": 55, "quantity": 969, "ts": 1756428450.045938, "side": "sell"}
{"type": "orderbook_delta", "seq": 6172, "price": 45, "quantity": 200, "ts": 1756428450.046346, "side": "buy"}
{"type": "orderbook_delta", "seq": 6173, "price": 21, "quantity": 8000, "ts": 1756428450.046854, "side": "buy"}
{"type": "orderbook_delta", "seq": 6174, "price": 54, "quantity": -200, "ts": 1756428450.0474, "side": "sell"}
{"type": "orderbook_delta", "seq": 6175, "price": 58, "quantity": 200, "ts": 1756428450.0474, "side": "sell"}
{"type": "orderbook_delta", "seq": 6176, "price": 60, "quantity": 1250, "ts": 1756428450.047973, "side": "sell"}
{"type": "orderbook_delta", "seq": 6177, "price": 58, "quantity": 200, "ts": 1756428450.048203, "side": "sell"}
{"type": "orderbook_delta", "seq": 6178, "price": 45, "quantity": 1250, "ts": 1756428450.048448, "side": "buy"}
{"type": "orderbook_delta", "seq": 6179, "price": 58, "quantity": -250, "ts": 1756428450.086256, "side": "sell"}
{"type": "orderbook_delta", "seq": 6180, "price": 56, "quantity": -100, "ts": 1756428450.090077, "side": "sell"}
{"type": "orderbook_delta", "seq": 6181, "price": 57, "quantity": 100, "ts": 1756428450.090077, "side": "sell"}
{"type": "orderbook_delta", "seq": 6182, "price": 58, "quantity": -200, "ts": 1756428450.099374, "side": "sell"}
{"type": "orderbook_delta", "seq": 6183, "price": 59, "quantity": 200, "ts": 1756428450.099374, "side": "sell"}
{"type": "orderbook_delta", "seq": 6184, "price": 49, "quantity": 500, "ts": 1756428450.121511, "side": "buy"}
{"type": "orderbook_delta", "seq": 6185, "price": 46, "quantity": 250, "ts": 1756428450.1317, "side": "buy"}
{"type": "orderbook_delta", "seq": 6186, "price": 36, "quantity": 250, "ts": 1756428450.150003, "side": "buy"}
{"type": "orderbook_delta", "seq": 6187, "price": 45, "quantity": -200, "ts": 1756428450.163259, "side": "buy"}
{"type": "orderbook_delta", "seq": 6188, "price": 47, "quantity": 200, "ts": 1756428450.197303, "side": "buy"}
{"type": "orderbook_delta", "seq": 6189, "price": 57, "quantity": -100, "ts": 1756428450.222824, "side": "sell"}
{"type": "orderbook_delta", "seq": 6190, "price": 58, "quantity": 100, "ts": 1756428450.222824, "side": "sell"}
{"type": "orderbook_delta", "seq": 6191, "price": 68, "quantity": 250, "ts": 1756428450.246932, "side": "sell"}
{"type": "orderbook_delta", "seq": 6192, "price": 48, "quantity": -100, "ts": 1756428450.266616, "side": "buy"}
{"type": "orderbook_delta", "seq": 6193, "price": 49, "quantity": 100, "ts": 1756428450.266616, "side": "buy"}
{"type": "orderbook_delta", "seq": 6194, "price": 36, "quantity": -250, "ts": 1756428450.306464, "side": "buy"}
{"type": "orderbook_delta", "seq": 6195, "price": 58, "quantity": -100, "ts": 1756428450.332009, "side": "sell"}
{"type": "orderbook_delta", "seq": 6196, "price": 59, "quantity": 100, "ts": 1756428450.332009, "side": "sell"}
{"type": "orderbook_delta", "seq": 6197, "price": 68, "quantity": -250, "ts": 1756428450.335688, "side": "sell"}
{"type": "orderbook_delta", "seq": 6198, "price": 59, "quantity": -200, "ts": 1756428450.412275, "side": "sell"}
{"type": "orderbook_delta", "seq": 6199, "price": 61, "quantity": 200, "ts": 1756428450.412275, "side": "sell"}
{"type": "orderbook_delta", "seq": 6200, "price": 58, "quantity": -200, "ts": 1756428450.443252, "side": "sell"}
{"type": "orderbook_delta", "seq": 6201, "price": 59, "quantity": -100, "ts": 1756428450.466105, "side": "sell"}
{"type": "orderbook_delta", "seq": 6202, "price": 60, "quantity": 100, "ts": 1756428450.466105, "side": "sell"}
{"type": "orderbook_delta", "seq": 6203, "price": 59, "quantity": 200, "ts": 1756428450.484383, "side": "sell"}
{"type": "orderbook_delta", "seq": 6204, "price": 48, "quantity": 250, "ts": 1756428450.77517, "side": "buy"}
{"type": "orderbook_delta", "seq": 6205, "price": 55, "quantity": -969, "ts": 1756428450.777213, "side": "sell"}
{"type": "orderbook_delta", "seq": 6206, "price": 55, "quantity": -500, "ts": 1756428450.778407, "side": "sell"}
{"type": "orderbook_delta", "seq": 6207, "price": 60, "quantity": -1250, "ts": 1756428450.77985, "side": "sell"}
{"type": "orderbook_delta", "seq": 6208, "price": 45, "quantity": -1250, "ts": 1756428450.780242, "side": "buy"}
{"type": "orderbook_delta", "seq": 6209, "price": 60, "quantity": -100, "ts": 1756428450.781064, "side": "sell"}
{"type": "orderbook_delta", "seq": 6210, "price": 61, "quantity": 100, "ts": 1756428450.781064, "side": "sell"}
{"type": "orderbook_delta", "seq": 6211, "price": 59, "quantity": -200, "ts": 1756428450.783901, "side": "sell"}
{"type": "orderbook_delta", "seq": 6212, "price": 68, "quantity": 250, "ts": 1756428450.78592, "side": "sell"}
{"type": "orderbook_delta", "seq": 6213, "price": 49, "quantity": -500, "ts": 1756428450.788273, "side": "buy"}
{"type": "orderbook_delta", "seq": 6214, "price": 38, "quantity": -250, "ts": 1756428450.798701, "side": "buy"}
{"type": "orderbook_delta", "seq": 6215, "price": 47, "quantity": -200, "ts": 1756428450.801348, "side": "buy"}
{"type": "orderbook_delta", "seq": 6216, "price": 20, "quantity": -200, "ts": 1756428450.832075, "side": "buy"}
{"type": "orderbook_delta", "seq": 6217, "price": 30, "quantity": 200, "ts": 1756428450.832075, "side": "buy"}
{"type": "orderbook_delta", "seq": 6218, "price": 51, "quantity": 500, "ts": 1756428450.837368, "side": "buy"}
{"type": "orderbook_delta", "seq": 6219, "price": 59, "quantity": 500, "ts": 1756428450.838144, "side": "sell"}
{"type": "orderbook_delta", "seq": 6220, "price": 62, "quantity": 200, "ts": 1756428450.838379, "side": "sell"}
{"type": "orderbook_delta", "seq": 6221, "price": 64, "quantity": 1250, "ts": 1756428450.839759, "side": "sell"}
{"type": "orderbook_delta", "seq": 6222, "price": 49, "quantity": 1250, "ts": 1756428450.839988, "side": "buy"}
{"type": "orderbook_delta", "seq": 6223, "price": 49, "quantity": 200, "ts": 1756428450.854744, "side": "buy"}
{"type": "orderbook_delta", "seq": 6224, "price": 80, "quantity": -200, "ts": 1756428450.860322, "side": "sell"}
{"type": "orderbook_delta", "seq": 6225, "price": 90, "quantity": 200, "ts": 1756428450.860322, "side": "sell"}
{"type": "orderbook_delta", "seq": 6226, "price": 57, "quantity": 969, "ts": 1756428450.862216, "side": "sell"}
{"type": "orderbook_delta", "seq": 6227, "price": 21, "quantity": -8000, "ts": 1756428450.877046, "side": "buy"}
{"type": "orderbook_delta", "seq": 6228, "price": 98, "quantity": -8000, "ts": 1756428450.894985, "side": "sell"}
{"type": "orderbook_delta", "seq": 6229, "price": 12, "quantity": 8000, "ts": 1756428450.918241, "side": "buy"}
{"type": "orderbook_delta", "seq": 6230, "price": 89, "quantity": 8000, "ts": 1756428450.937115, "side": "sell"}
{"type": "orderbook_delta", "seq": 6231, "price": 38, "quantity": 250, "ts": 1756428451.06413, "side": "buy"}
{"type": "orderbook_delta", "seq": 6232, "price": 48, "quantity": -250, "ts": 1756428451.072488, "side": "buy"}
{"type": "orderbook_delta", "seq": 6233, "price": 57, "quantity": -969, "ts": 1756428451.110322, "side": "sell"}
{"type": "orderbook_delta", "seq": 6234, "price": 52, "quantity": 250, "ts": 1756428451.126399, "side": "buy"}
{"type": "orderbook_delta", "seq": 6235, "price": 40, "quantity": -250, "ts": 1756428451.147229, "side": "buy"}
{"type": "orderbook_delta", "seq": 6236, "price": 50, "quantity": 250, "ts": 1756428451.167116, "side": "buy"}
{"type": "orderbook_delta", "seq": 6237, "price": 60, "quantity": -250, "ts": 1756428451.167362, "side": "sell"}
{"type": "orderbook_delta", "seq": 6238, "price": 38, "quantity": -250, "ts": 1756428451.176093, "side": "buy"}
{"type": "orderbook_delta", "seq": 6239, "price": 49, "quantity": -200, "ts": 1756428451.183537, "side": "buy"}
{"type": "orderbook_delta", "seq": 6240, "price": 49, "quantity": -1250, "ts": 1756428451.184496, "side": "buy"}
{"type": "orderbook_delta", "seq": 6241, "price": 70, "quantity": 250, "ts": 1756428451.187001, "side": "sell"}
{"type": "orderbook_delta", "seq": 6242, "price": 51, "quantity": -500, "ts": 1756428451.191706, "side": "buy"}
{"type": "orderbook_delta", "seq": 6243, "price": 42, "quantity": -250, "ts": 1756428451.207524, "side": "buy"}
{"type": "orderbook_delta", "seq": 6244, "price": 61, "quantity": -100, "ts": 1756428451.209842, "side": "sell"}
{"type": "orderbook_delta", "seq": 6245, "price": 62, "quantity": 100, "ts": 1756428451.209842, "side": "sell"}
{"type": "orderbook_delta", "seq": 6246, "price": 47, "quantity": 200, "ts": 1756428451.217733, "side": "buy"}
{"type": "orderbook_delta", "seq": 6247, "price": 47, "quantity": 1250, "ts": 1756428451.219202, "side": "buy"}
{"type": "orderbook_delta", "seq": 6248, "price": 53, "quantity": 500, "ts": 1756428451.226195, "side": "buy"}
{"type": "orderbook_delta", "seq": 6249, "price": 59, "quantity": 969, "ts": 1756428451.25233, "side": "sell"}
{"type": "orderbook_delta", "seq": 6250, "price": 47, "quantity": -200, "ts": 1756428451.347069, "side": "buy"}
{"type": "orderbook_delta", "seq": 6251, "price": 64, "quantity": -1250, "ts": 1756428451.383172, "side": "sell"}
{"type": "orderbook_delta", "seq": 6252, "price": 51, "quantity": 200, "ts": 1756428451.386965, "side": "buy"}
{"type": "orderbook_delta", "seq": 6253, "price": 63, "quantity": 1250, "ts": 1756428451.416011, "side": "sell"}
{"type": "orderbook_delta", "seq": 6254, "price": 49, "quantity": -100, "ts": 1756428451.431764, "side": "buy"}
{"type": "orderbook_delta", "seq": 6255, "price": 53, "quantity": 100, "ts": 1756428451.431764, "side": "buy"}
{"type": "orderbook_delta", "seq": 6256, "price": 51, "quantity": -200, "ts": 1756428451.724705, "side": "buy"}
{"type": "orderbook_delta", "seq": 6257, "price": 53, "quantity": -500, "ts": 1756428451.72482, "side": "buy"}
{"type": "orderbook_delta", "seq": 6258, "price": 63, "quantity": -1250, "ts": 1756428451.72569, "side": "sell"}
{"type": "orderbook_delta", "seq": 6259, "price": 62, "quantity": -200, "ts": 1756428451.727387, "side": "sell"}
{"type": "orderbook_delta", "seq": 6260, "price": 59, "quantity": -500, "ts": 1756428451.729209, "side": "sell"}
{"type": "orderbook_delta", "seq": 6261, "price": 58, "quantity": 500, "ts": 1756428451.76489, "side": "sell"}
{"type": "orderbook_delta", "seq": 6262, "price": 47, "quantity": 200, "ts": 1756428451.765907, "side": "buy"}
{"type": "orderbook_delta", "seq": 6263, "price": 52, "quantity": 500, "ts": 1756428451.768031, "side": "buy"}
{"type": "orderbook_delta", "seq": 6264, "price": 62, "quantity": 1250, "ts": 1756428451.769112, "side": "sell"}
{"type": "orderbook_delta", "seq": 6265, "price": 60, "quantity": 200, "ts": 1756428451.769406, "side": "sell"}
{"type": "orderbook_delta", "seq": 6266, "price": 53, "quantity": -100, "ts": 1756428451.874524, "side": "buy"}
{"type": "orderbook_delta", "seq": 6267, "price": 51, "quantity": 100, "ts": 1756428451.874524, "side": "buy"}
{"type": "orderbook_delta", "seq": 6268, "price": 52, "quantity": -500, "ts": 1756428451.881719, "side": "buy"}
{"type": "orderbook_delta", "seq": 6269, "price": 58, "quantity": -500, "ts": 1756428451.881772, "side": "sell"}
{"type": "orderbook_delta", "seq": 6270, "price": 47, "quantity": -1250, "ts": 1756428451.881866, "side": "buy"}
{"type": "orderbook_delta", "seq": 6271, "price": 62, "quantity": -1250, "ts": 1756428451.882007, "side": "sell"}
{"type": "orderbook_delta", "seq": 6272, "price": 47, "quantity": -200, "ts": 1756428451.88205, "side": "buy"}
{"type": "orderbook_delta", "seq": 6273, "price": 60, "quantity": -200, "ts": 1756428451.882162, "side": "sell"}
{"type": "orderbook_delta", "seq": 6274, "price": 61, "quantity": -200, "ts": 1756428451.88335, "side": "sell"}
{"type": "orderbook_delta", "seq": 6275, "price": 57, "quantity": 200, "ts": 1756428451.88335, "side": "sell"}
{"type": "orderbook_delta", "seq": 6276, "price": 42, "quantity": 250, "ts": 1756428451.89788, "side": "buy"}
{"type": "orderbook_delta", "seq": 6277, "price": 52, "quantity": -250, "ts": 1756428451.899165, "side": "buy"}
{"type": "orderbook_delta", "seq": 6278, "price": 40, "quantity": 250, "ts": 1756428451.91649, "side": "buy"}
{"type": "orderbook_delta", "seq": 6279, "price": 48, "quantity": 250, "ts": 1756428451.936257, "side": "buy"}
{"type": "orderbook_delta", "seq": 6280, "price": 59, "quantity": 1250, "ts": 1756428451.937042, "side": "sell"}
{"type": "orderbook_delta", "seq": 6281, "price": 46, "quantity": 200, "ts": 1756428451.939035, "side": "buy"}
{"type": "orderbook_delta", "seq": 6282, "price": 54, "quantity": 500, "ts": 1756428451.939308, "side": "sell"}
{"type": "orderbook_delta", "seq": 6283, "price": 44, "quantity": 1250, "ts": 1756428451.93981, "side": "buy"}
{"type": "orderbook_delta", "seq": 6284, "price": 47, "quantity": 500, "ts": 1756428451.941362, "side": "buy"}
{"type": "orderbook_delta", "seq": 6285, "price": 57, "quantity": 200, "ts": 1756428451.941615, "side": "sell"}
{"type": "orderbook_delta", "seq": 6286, "price": 50, "quantity": -250, "ts": 1756428451.958079, "side": "buy"}
{"type": "orderbook_delta", "seq": 6287, "price": 47, "quantity": -500, "ts": 1756428451.98736, "side": "buy"}
{"type": "orderbook_delta", "seq": 6288, "price": 51, "quantity": -100, "ts": 1756428452.010694, "side": "buy"}
{"type": "orderbook_delta", "seq": 6289, "price": 49, "quantity": 100, "ts": 1756428452.010694, "side": "buy"}
{"type": "orderbook_delta", "seq": 6290, "price": 48, "quantity": 500, "ts": 1756428452.030145, "side": "buy"}
{"type": "orderbook_delta", "seq": 6291, "price": 58, "quantity": 250, "ts": 1756428452.097447, "side": "sell"}
{"type": "orderbook_delta", "seq": 6292, "price": 59, "quantity": -969, "ts": 1756428452.103083, "side": "sell"}
{"type": "orderbook_delta", "seq": 6293, "price": 70, "quantity": -250, "ts": 1756428452.116737, "side": "sell"}
{"type": "orderbook_delta", "seq": 6294, "price": 59, "quantity": -1250, "ts": 1756428452.134581, "side": "sell"}
{"type": "orderbook_delta", "seq": 6295, "price": 60, "quantity": 250, "ts": 1756428452.137347, "side": "sell"}
{"type": "orderbook_delta", "seq": 6296, "price": 68, "quantity": -250, "ts": 1756428452.166651, "side": "sell"}
{"type": "orderbook_delta", "seq": 6297, "price": 61, "quantity": 1250, "ts": 1756428452.168299, "side": "sell"}
{"type": "orderbook_delta", "seq": 6298, "price": 61, "quantity": -1250, "ts": 1756428452.212762, "side": "sell"}
{"type": "orderbook_delta", "seq": 6299, "price": 55, "quantity": 969, "ts": 1756428452.245373, "side": "sell"}
{"type": "orderbook_delta", "seq": 6300, "price": 59, "quantity": 1250, "ts": 1756428452.258251, "side": "sell"}
{"type": "orderbook_delta", "seq": 6301, "price": 62, "quantity": -100, "ts": 1756428452.818809, "side": "sell"}
{"type": "orderbook_delta", "seq": 6302, "price": 58, "quantity": 100, "ts": 1756428452.818809, "side": "sell"}
{"type": "orderbook_delta", "seq": 6303, "price": 54, "quantity": -500, "ts": 1756428454.014413, "side": "sell"}
{"type": "orderbook_delta", "seq": 6304, "price": 48, "quantity": -500, "ts": 1756428454.016751, "side": "buy"}
{"type": "orderbook_delta", "seq": 6305, "price": 55, "quantity": 500, "ts": 1756428454.073241, "side": "sell"}
{"type": "orderbook_delta", "seq": 6306, "price": 49, "quantity": 500, "ts": 1756428454.081526, "side": "buy"}
{"type": "orderbook_delta", "seq": 6307, "price": 49, "quantity": -100, "ts": 1756428454.281022, "side": "buy"}
{"type": "orderbook_delta", "seq": 6308, "price": 50, "quantity": 100, "ts": 1756428454.281022, "side": "buy"}
{"type": "orderbook_delta", "seq": 6309, "price": 49, "quantity": -500, "ts": 1756428454.311088, "side": "buy"}
{"type": "orderbook_delta", "seq": 6310, "price": 59, "quantity": -1250, "ts": 1756428454.311304, "side": "sell"}
{"type": "orderbook_delta", "seq": 6311, "price": 44, "quantity": -1250, "ts": 1756428454.311492, "side": "buy"}
{"type": "orderbook_delta", "seq": 6312, "price": 57, "quantity": -200, "ts": 1756428454.314327, "side": "sell"}
{"type": "orderbook_delta", "seq": 6313, "price": 46, "quantity": -200, "ts": 1756428454.316326, "side": "buy"}
{"type": "orderbook_delta", "seq": 6314, "price": 55, "quantity": -500, "ts": 1756428454.31659, "side": "sell"}
{"type": "orderbook_delta", "seq": 6315, "price": 60, "quantity": 1250, "ts": 1756428454.370195, "side": "sell"}
{"type": "orderbook_delta", "seq": 6316, "price": 50, "quantity": 500, "ts": 1756428454.372174, "side": "buy"}
{"type": "orderbook_delta", "seq": 6317, "price": 58, "quantity": 200, "ts": 1756428454.373121, "side": "sell"}
{"type": "orderbook_delta", "seq": 6318, "price": 47, "quantity": 200, "ts": 1756428454.376239, "side": "buy"}
{"type": "orderbook_delta", "seq": 6319, "price": 56, "quantity": 500, "ts": 1756428454.37781, "side": "sell"}
{"type": "orderbook_delta", "seq": 6320, "price": 46, "quantity": 1250, "ts": 1756428454.381288, "side": "buy"}
{"type": "orderbook_delta", "seq": 6321, "price": 46, "quantity": -1250, "ts": 1756428454.436167, "side": "buy"}
{"type": "orderbook_delta", "seq": 6322, "price": 45, "quantity": 1250, "ts": 1756428454.484244, "side": "buy"}
{"type": "orderbook_delta", "seq": 6323, "price": 50, "quantity": -100, "ts": 1756428454.526932, "side": "buy"}
{"type": "orderbook_delta", "seq": 6324, "price": 51, "quantity": 100, "ts": 1756428454.526932, "side": "buy"}
{"type": "orderbook_delta", "seq": 6325, "price": 55, "quantity": -969, "ts": 1756428455.119664, "side": "sell"}
{"type": "orderbook_delta", "seq": 6326, "price": 50, "quantity": 250, "ts": 1756428455.137525, "side": "buy"}
{"type": "orderbook_delta", "seq": 6327, "price": 40, "quantity": -250, "ts": 1756428455.156326, "side": "buy"}
{"type": "orderbook_delta", "seq": 6328, "price": 56, "quantity": 969, "ts": 1756428455.225646, "side": "sell"}
{"type": "orderbook_delta", "seq": 6329, "price": 56, "quantity": -500, "ts": 1756428455.549426, "side": "sell"}
{"type": "orderbook_delta", "seq": 6330, "price": 45, "quantity": -1250, "ts": 1756428455.551333, "side": "buy"}
{"type": "orderbook_delta", "seq": 6331, "price": 47, "quantity": -200, "ts": 1756428455.552424, "side": "buy"}
{"type": "orderbook_delta", "seq": 6332, "price": 50, "quantity": -500, "ts": 1756428455.552549, "side": "buy"}
{"type": "orderbook_delta", "seq": 6333, "price": 60, "quantity": -1250, "ts": 1756428455.553122, "side": "sell"}
{"type": "orderbook_delta", "seq": 6334, "price": 58, "quantity": -200, "ts": 1756428455.553501, "side": "sell"}
{"type": "orderbook_delta", "seq": 6335, "price": 50, "quantity": -250, "ts": 1756428455.567285, "side": "buy"}
{"type": "orderbook_delta", "seq": 6336, "price": 46, "quantity": 200, "ts": 1756428455.585441, "side": "buy"}
{"type": "orderbook_delta", "seq": 6337, "price": 57, "quantity": 200, "ts": 1756428455.586251, "side": "sell"}
{"type": "orderbook_delta", "seq": 6338, "price": 55, "quantity": 500, "ts": 1756428455.586903, "side": "sell"}
{"type": "orderbook_delta", "seq": 6339, "price": 59, "quantity": 1250, "ts": 1756428455.587767, "side": "sell"}
{"type": "orderbook_delta", "seq": 6340, "price": 44, "quantity": 1250, "ts": 1756428455.588047, "side": "buy"}
{"type": "orderbook_delta", "seq": 6341, "price": 49, "quantity": 500, "ts": 1756428455.588772, "side": "buy"}
{"type": "orderbook_delta", "seq": 6342, "price": 51, "quantity": -100, "ts": 1756428455.659219, "side": "buy"}
{"type": "orderbook_delta", "seq": 6343, "price": 49, "quantity": 100, "ts": 1756428455.659219, "side": "buy"}
{"type": "orderbook_delta", "seq": 6344, "price": 40, "quantity": 250, "ts": 1756428455.715954, "side": "buy"}
{"type": "orderbook_delta", "seq": 6345, "price": 58, "quantity": -100, "ts": 1756428455.835215, "side": "sell"}
{"type": "orderbook_delta", "seq": 6346, "price": 55, "quantity": 100, "ts": 1756428455.835215, "side": "sell"}
{"type": "orderbook_delta", "seq": 6347, "price": 57, "quantity": -200, "ts": 1756428455.874738, "side": "sell"}
{"type": "orderbook_delta", "seq": 6348, "price": 55, "quantity": 200, "ts": 1756428455.874738, "side": "sell"}
{"type": "orderbook_delta", "seq": 6349, "price": 55, "quantity": -100, "ts": 1756428455.886398, "side": "sell"}
{"type": "orderbook_delta", "seq": 6350, "price": 59, "quantity": -1250, "ts": 1756428455.934595, "side": "sell"}
{"type": "orderbook_delta", "seq": 6351, "price": 46, "quantity": -200, "ts": 1756428455.936256, "side": "buy"}
{"type": "orderbook_delta", "seq": 6352, "price": 57, "quantity": -200, "ts": 1756428455.936853, "side": "sell"}
{"type": "orderbook_delta", "seq": 6353, "price": 44, "quantity": -1250, "ts": 1756428455.938342, "side": "buy"}
{"type": "orderbook_delta", "seq": 6354, "price": 55, "quantity": -500, "ts": 1756428455.939537, "side": "sell"}
{"type": "orderbook_delta", "seq": 6355, "price": 49, "quantity": -500, "ts": 1756428455.940877, "side": "buy"}
{"type": "orderbook_delta", "seq": 6356, "price": 45, "quantity": 200, "ts": 1756428455.98305, "side": "buy"}
{"type": "orderbook_delta", "seq": 6357, "price": 48, "quantity": 500, "ts": 1756428455.985203, "side": "buy"}
{"type": "orderbook_delta", "seq": 6358, "price": 43, "quantity": 1250, "ts": 1756428455.985471, "side": "buy"}
{"type": "orderbook_delta", "seq": 6359, "price": 56, "quantity": 200, "ts": 1756428455.985716, "side": "sell"}
{"type": "orderbook_delta", "seq": 6360, "price": 54, "quantity": 500, "ts": 1756428455.986756, "side": "sell"}
{"type": "orderbook_delta", "seq": 6361, "price": 58, "quantity": 1250, "ts": 1756428455.987502, "side": "sell"}
{"type": "orderbook_delta", "seq": 6362, "price": 55, "quantity": -200, "ts": 1756428456.140046, "side": "sell"}
{"type": "orderbook_delta", "seq": 6363, "price": 57, "quantity": 200, "ts": 1756428456.140046, "side": "sell"}
{"type": "orderbook_delta", "seq": 6364, "price": 56, "quantity": -969, "ts": 1756428456.14879, "side": "sell"}
{"type": "orderbook_delta", "seq": 6365, "price": 56, "quantity": 250, "ts": 1756428456.148853, "side": "sell"}
{"type": "orderbook_delta", "seq": 6366, "price": 66, "quantity": -250, "ts": 1756428456.166984, "side": "sell"}
{"type": "orderbook_delta", "seq": 6367, "price": 54, "quantity": 969, "ts": 1756428456.209859, "side": "sell"}
{"type": "orderbook_delta", "seq": 6368, "price": 57, "quantity": -200, "ts": 1756428456.242543, "side": "sell"}
{"type": "orderbook_delta", "seq": 6369, "price": 58, "quantity": 200, "ts": 1756428456.242543, "side": "sell"}
{"type": "orderbook_delta", "seq": 6370, "price": 54, "quantity": -500, "ts": 1756428456.435485, "side": "sell"}
{"type": "orderbook_delta", "seq": 6371, "price": 48, "quantity": -500, "ts": 1756428456.436599, "side": "buy"}
{"type": "orderbook_delta", "seq": 6372, "price": 53, "quantity": 500, "ts": 1756428456.479374, "side": "sell"}
{"type": "orderbook_delta", "seq": 6373, "price": 47, "quantity": 500, "ts": 1756428456.479831, "side": "buy"}
{"type": "orderbook_delta", "seq": 6374, "price": 58, "quantity": -200, "ts": 1756428456.521331, "side": "sell"}
{"type": "orderbook_delta", "seq": 6375, "price": 59, "quantity": 200, "ts": 1756428456.521331, "side": "sell"}
{"type": "orderbook_delta", "seq": 6376, "price": 59, "quantity": -200, "ts": 1756428456.739211, "side": "sell"}
{"type": "orderbook_delta", "seq": 6377, "price": 58, "quantity": 200, "ts": 1756428456.739211, "side": "sell"}
{"type": "orderbook_delta", "seq": 6378, "price": 68, "quantity": 250, "ts": 1756428456.814532, "side": "sell"}
{"type": "orderbook_delta", "seq": 6379, "price": 66, "quantity": 250, "ts": 1756428456.817853, "side": "sell"}
{"type": "orderbook_delta", "seq": 6380, "price": 58, "quantity": -250, "ts": 1756428456.81884, "side": "sell"}
{"type": "orderbook_delta", "seq": 6381, "price": 43, "quantity": -1250, "ts": 1756428456.819522, "side": "buy"}
{"type": "orderbook_delta", "seq": 6382, "price": 54, "quantity": -969, "ts": 1756428456.82008, "side": "sell"}
{"type": "orderbook_delta", "seq": 6383, "price": 56, "quantity": -200, "ts": 1756428456.82017, "side": "sell"}
{"type": "orderbook_delta", "seq": 6384, "price": 47, "quantity": -500, "ts": 1756428456.820843, "side": "buy"}
{"type": "orderbook_delta", "seq": 6385, "price": 53, "quantity": -500, "ts": 1756428456.821733, "side": "sell"}
{"type": "orderbook_delta", "seq": 6386, "price": 58, "quantity": -1250, "ts": 1756428456.821868, "side": "sell"}
{"type": "orderbook_delta", "seq": 6387, "price": 45, "quantity": -200, "ts": 1756428456.825953, "side": "buy"}
{"type": "orderbook_delta", "seq": 6388, "price": 56, "quantity": -250, "ts": 1756428456.836884, "side": "sell"}
{"type": "orderbook_delta", "seq": 6389, "price": 48, "quantity": 200, "ts": 1756428456.861984, "side": "buy"}
{"type": "orderbook_delta", "seq": 6390, "price": 61, "quantity": 1250, "ts": 1756428456.865248, "side": "sell"}
{"type": "orderbook_delta", "seq": 6391, "price": 57, "quantity": 500, "ts": 1756428456.866869, "side": "sell"}
{"type": "orderbook_delta", "seq": 6392, "price": 59, "quantity": 200, "ts": 1756428456.868472, "side": "sell"}
{"type": "orderbook_delta", "seq": 6393, "price": 51, "quantity": 500, "ts": 1756428456.869177, "side": "buy"}
{"type": "orderbook_delta", "seq": 6394, "price": 57, "quantity": 969, "ts": 1756428456.880097, "side": "sell"}
{"type": "orderbook_delta", "seq": 6395, "price": 38, "quantity": 250, "ts": 1756428456.882834, "side": "buy"}
{"type": "orderbook_delta", "seq": 6396, "price": 48, "quantity": -250, "ts": 1756428456.906893, "side": "buy"}
{"type": "orderbook_delta", "seq": 6397, "price": 70, "quantity": 250, "ts": 1756428456.906911, "side": "sell"}
{"type": "orderbook_delta", "seq": 6398, "price": 49, "quantity": -100, "ts": 1756428456.911858, "side": "buy"}
{"type": "orderbook_delta", "seq": 6399, "price": 52, "quantity": 100, "ts": 1756428456.911858, "side": "buy"}
{"type": "orderbook_delta", "seq": 6400, "price": 46, "quantity": 1250, "ts": 1756428456.913585, "side": "buy"}
{"type": "orderbook_delta", "seq": 6401, "price": 60, "quantity": -250, "ts": 1756428456.92686, "side": "sell"}
{"type": "orderbook_delta", "seq": 6402, "price": 48, "quantity": -200, "ts": 1756428456.942, "side": "buy"}
{"type": "orderbook_delta", "seq": 6403, "price": 38, "quantity": -250, "ts": 1756428456.965856, "side": "buy"}
{"type": "orderbook_delta", "seq": 6404, "price": 59, "quantity": -200, "ts": 1756428456.983999, "side": "sell"}
{"type": "orderbook_delta", "seq": 6405, "price": 47, "quantity": 200, "ts": 1756428456.985182, "side": "buy"}
{"type": "orderbook_delta", "seq": 6406, "price": 70, "quantity": -250, "ts": 1756428456.986651, "side": "sell"}
{"type": "orderbook_delta", "seq": 6407, "price": 61, "quantity": 200, "ts": 1756428457.015453, "side": "sell"}
{"type": "orderbook_delta", "seq": 6408, "price": 52, "quantity": -100, "ts": 1756428457.080676, "side": "buy"}
{"type": "orderbook_delta", "seq": 6409, "price": 51, "quantity": 100, "ts": 1756428457.080676, "side": "buy"}
{"type": "orderbook_delta", "seq": 6410, "price": 40, "quantity": -250, "ts": 1756428457.136838, "side": "buy"}
{"type": "orderbook_delta", "seq": 6411, "price": 50, "quantity": -100, "ts": 1756428457.147674, "side": "buy"}
{"type": "orderbook_delta", "seq": 6412, "price": 50, "quantity": 250, "ts": 1756428457.148541, "side": "buy"}
{"type": "orderbook_delta", "seq": 6413, "price": 48, "quantity": 250, "ts": 1756428457.165969, "side": "buy"}
{"type": "orderbook_delta", "seq": 6414, "price": 47, "quantity": -200, "ts": 1756428457.205357, "side": "buy"}
{"type": "orderbook_delta", "seq": 6415, "price": 48, "quantity": 200, "ts": 1756428457.245559, "side": "buy"}
{"type": "orderbook_delta", "seq": 6416, "price": 57, "quantity": -500, "ts": 1756428457.341189, "side": "sell"}
{"type": "orderbook_delta", "seq": 6417, "price": 51, "quantity": -500, "ts": 1756428457.341353, "side": "buy"}
{"type": "orderbook_delta", "seq": 6418, "price": 51, "quantity": 100, "ts": 1756428457.358981, "side": "buy"}
{"type": "orderbook_delta", "seq": 6419, "price": 50, "quantity": 500, "ts": 1756428457.381591, "side": "buy"}
{"type": "orderbook_delta", "seq": 6420, "price": 56, "quantity": 500, "ts": 1756428457.38209, "side": "sell"}
{"type": "orderbook_delta", "seq": 6421, "price": 59, "quantity": 100, "ts": 1756428457.395526, "side": "sell"}
{"type": "orderbook_delta", "seq": 6422, "price": 50, "quantity": -500, "ts": 1756428457.744637, "side": "buy"}
{"type": "orderbook_delta", "seq": 6423, "price": 46, "quantity": -1250, "ts": 1756428457.745425, "side": "buy"}
{"type": "orderbook_delta", "seq": 6424, "price": 61, "quantity": -200, "ts": 1756428457.747888, "side": "sell"}
{"type": "orderbook_delta", "seq": 6425, "price": 48, "quantity": -200, "ts": 1756428457.761614, "side": "buy"}
{"type": "orderbook_delta", "seq": 6426, "price": 58, "quantity": -200, "ts": 1756428457.785397, "side": "sell"}
{"type": "orderbook_delta", "seq": 6427, "price": 55, "quantity": 200, "ts": 1756428457.785397, "side": "sell"}
{"type": "orderbook_delta", "seq": 6428, "price": 46, "quantity": 200, "ts": 1756428457.845151, "side": "buy"}
{"type": "orderbook_delta", "seq": 6429, "price": 49, "quantity": 500, "ts": 1756428457.845463, "side": "buy"}
{"type": "orderbook_delta", "seq": 6430, "price": 57, "quantity": 200, "ts": 1756428457.845706, "side": "sell"}
{"type": "orderbook_delta", "seq": 6431, "price": 44, "quantity": 1250, "ts": 1756428457.846704, "side": "buy"}
{"type": "orderbook_delta", "seq": 6432, "price": 56, "quantity": -500, "ts": 1756428457.854343, "side": "sell"}
{"type": "orderbook_delta", "seq": 6433, "price": 55, "quantity": 500, "ts": 1756428457.889249, "side": "sell"}
{"type": "orderbook_delta", "seq": 6434, "price": 46, "quantity": -200, "ts": 1756428458.104446, "side": "buy"}
{"type": "orderbook_delta", "seq": 6435, "price": 57, "quantity": -200, "ts": 1756428458.104755, "side": "sell"}
{"type": "orderbook_delta", "seq": 6436, "price": 44, "quantity": -1250, "ts": 1756428458.104847, "side": "buy"}
{"type": "orderbook_delta", "seq": 6437, "price": 57, "quantity": -969, "ts": 1756428458.125929, "side": "sell"}
{"type": "orderbook_delta", "seq": 6438, "price": 58, "quantity": 250, "ts": 1756428458.131088, "side": "sell"}
{"type": "orderbook_delta", "seq": 6439, "price": 47, "quantity": 200, "ts": 1756428458.136634, "side": "buy"}
{"type": "orderbook_delta", "seq": 6440, "price": 61, "quantity": 200, "ts": 1756428458.142459, "side": "sell"}
{"type": "orderbook_delta", "seq": 6441, "price": 68, "quantity": -250, "ts": 1756428458.146213, "side": "sell"}
{"type": "orderbook_delta", "seq": 6442, "price": 60, "quantity": 250, "ts": 1756428458.14634, "side": "sell"}
{"type": "orderbook_delta", "seq": 6443, "price": 45, "quantity": 1250, "ts": 1756428458.150131, "side": "buy"}
{"type": "orderbook_delta", "seq": 6444, "price": 61, "quantity": -1250, "ts": 1756428458.201028, "side": "sell"}
{"type": "orderbook_delta", "seq": 6445, "price": 56, "quantity": 969, "ts": 1756428458.212506, "side": "sell"}
{"type": "orderbook_delta", "seq": 6446, "price": 61, "quantity": -200, "ts": 1756428458.227096, "side": "sell"}
{"type": "orderbook_delta", "seq": 6447, "price": 60, "quantity": 1250, "ts": 1756428458.280607, "side": "sell"}
{"type": "orderbook_delta", "seq": 6448, "price": 58, "quantity": 200, "ts": 1756428458.282098, "side": "sell"}
{"type": "orderbook_delta", "seq": 6449, "price": 45, "quantity": -1250, "ts": 1756428458.417453, "side": "buy"}
{"type": "orderbook_delta", "seq": 6450, "price": 49, "quantity": -500, "ts": 1756428458.417681, "side": "buy"}
{"type": "orderbook_delta", "seq": 6451, "price": 58, "quantity": -200, "ts": 1756428458.417913, "side": "sell"}
{"type": "orderbook_delta", "seq": 6452, "price": 55, "quantity": -500, "ts": 1756428458.418276, "side": "sell"}
{"type": "orderbook_delta", "seq": 6453, "price": 47, "quantity": -200, "ts": 1756428458.419591, "side": "buy"}
{"type": "orderbook_delta", "seq": 6454, "price": 60, "quantity": -1250, "ts": 1756428458.420004, "side": "sell"}
{"type": "orderbook_delta", "seq": 6455, "price": 58, "quantity": 1250, "ts": 1756428458.461798, "side": "sell"}
{"type": "orderbook_delta", "seq": 6456, "price": 54, "quantity": 500, "ts": 1756428458.462434, "side": "sell"}
{"type": "orderbook_delta", "seq": 6457, "price": 43, "quantity": 1250, "ts": 1756428458.464896, "side": "buy"}
{"type": "orderbook_delta", "seq": 6458, "price": 48, "quantity": 500, "ts": 1756428458.465625, "side": "buy"}
{"type": "orderbook_delta", "seq": 6459, "price": 56, "quantity": 200, "ts": 1756428458.465977, "side": "sell"}
{"type": "orderbook_delta", "seq": 6460, "price": 45, "quantity": 200, "ts": 1756428458.466933, "side": "buy"}
{"type": "orderbook_delta", "seq": 6461, "price": 59, "quantity": -100, "ts": 1756428458.519825, "side": "sell"}
{"type": "orderbook_delta", "seq": 6462, "price": 60, "quantity": 100, "ts": 1756428458.519825, "side": "sell"}
{"type": "orderbook_delta", "seq": 6463, "price": 40, "quantity": 250, "ts": 1756428458.581907, "side": "buy"}
{"type": "orderbook_delta", "seq": 6464, "price": 50, "quantity": -250, "ts": 1756428458.595968, "side": "buy"}
{"type": "orderbook_delta", "seq": 6465, "price": 51, "quantity": -100, "ts": 1756428458.652391, "side": "buy"}
{"type": "orderbook_delta", "seq": 6466, "price": 49, "quantity": 100, "ts": 1756428458.652391, "side": "buy"}
{"type": "orderbook_delta", "seq": 6467, "price": 56, "quantity": -969, "ts": 1756428459.138247, "side": "sell"}
{"type": "orderbook_delta", "seq": 6468, "price": 56, "quantity": -200, "ts": 1756428459.167182, "side": "sell"}
{"type": "orderbook_delta", "seq": 6469, "price": 57, "quantity": 200, "ts": 1756428459.210839, "side": "sell"}
{"type": "orderbook_delta", "seq": 6470, "price": 54, "quantity": 969, "ts": 1756428459.211185, "side": "sell"}
{"type": "orderbook_delta", "seq": 6471, "price": 60, "quantity": -100, "ts": 1756428459.276371, "side": "sell"}
{"type": "orderbook_delta", "seq": 6472, "price": 57, "quantity": 100, "ts": 1756428459.276371, "side": "sell"}
{"type": "orderbook_delta", "seq": 6473, "price": 45, "quantity": -200, "ts": 1756428460.9214, "side": "buy"}
{"type": "orderbook_delta", "seq": 6474, "price": 43, "quantity": -1250, "ts": 1756428460.925417, "side": "buy"}
{"type": "orderbook_delta", "seq": 6475, "price": 58, "quantity": -1250, "ts": 1756428460.92565, "side": "sell"}
{"type": "orderbook_delta", "seq": 6476, "price": 46, "quantity": 200, "ts": 1756428460.971032, "side": "buy"}
{"type": "orderbook_delta", "seq": 6477, "price": 59, "quantity": 1250, "ts": 1756428460.971364, "side": "sell"}
{"type": "orderbook_delta", "seq": 6478, "price": 44, "quantity": 1250, "ts": 1756428460.996678, "side": "buy"}
{"type": "trade", "seq": 64, "price": 54, "quantity": 19, "ts": 1756428461.0, "side": "buy"}
{"type": "trade", "seq": 65, "price": 54, "quantity": 1, "ts": 1756428461.0, "side": "buy"}
{"type": "orderbook_delta", "seq": 6479, "price": 54, "quantity": 0, "ts": 1756428461.226362, "side": "sell"}
{"type": "orderbook_delta", "seq": 6480, "price": 54, "quantity": 0, "ts": 1756428461.226362, "side": "sell"}
{"type": "orderbook_delta", "seq": 6481, "price": 57, "quantity": -100, "ts": 1756428461.739046, "side": "sell"}
{"type": "orderbook_delta", "seq": 6482, "price": 58, "quantity": 100, "ts": 1756428461.739046, "side": "sell"}
{"type": "orderbook_delta", "seq": 6483, "price": 55, "quantity": -200, "ts": 1756428461.930966, "side": "sell"}
{"type": "orderbook_delta", "seq": 6484, "price": 57, "quantity": 200, "ts": 1756428461.930966, "side": "sell"}
{"type": "orderbook_delta", "seq": 6485, "price": 56, "quantity": 250, "ts": 1756428462.116142, "side": "sell"}
{"type": "orderbook_delta", "seq": 6486, "price": 66, "quantity": -250, "ts": 1756428462.126888, "side": "sell"}
{"type": "orderbook_delta", "seq": 6487, "price": 54, "quantity": 100, "ts": 1756428462.937298, "side": "sell"}
{"type": "orderbook_delta", "seq": 6488, "price": 56, "quantity": -250, "ts": 1756428463.115385, "side": "sell"}
{"type": "orderbook_delta", "seq": 6489, "price": 66, "quantity": 250, "ts": 1756428463.117521, "side": "sell"}
{"type": "orderbook_delta", "seq": 6490, "price": 46, "quantity": -200, "ts": 1756428463.406844, "side": "buy"}
{"type": "orderbook_delta", "seq": 6491, "price": 59, "quantity": -1250, "ts": 1756428463.408033, "side": "sell"}
{"type": "orderbook_delta", "seq": 6492, "price": 57, "quantity": -200, "ts": 1756428463.411192, "side": "sell"}
{"type": "orderbook_delta", "seq": 6493, "price": 44, "quantity": -1250, "ts": 1756428463.411959, "side": "buy"}
{"type": "orderbook_delta", "seq": 6494, "price": 45, "quantity": 200, "ts": 1756428463.440244, "side": "buy"}
{"type": "orderbook_delta", "seq": 6495, "price": 43, "quantity": 1250, "ts": 1756428463.441443, "side": "buy"}
{"type": "orderbook_delta", "seq": 6496, "price": 56, "quantity": 200, "ts": 1756428463.441716, "side": "sell"}
{"type": "orderbook_delta", "seq": 6497, "price": 58, "quantity": 1250, "ts": 1756428463.446055, "side": "sell"}
{"type": "orderbook_delta", "seq": 6498, "price": 56, "quantity": 250, "ts": 1756428464.101171, "side": "sell"}
{"type": "orderbook_delta", "seq": 6499, "price": 66, "quantity": -250, "ts": 1756428464.104946, "side": "sell"}
{"type": "orderbook_delta", "seq": 6500, "price": 58, "quantity": -100, "ts": 1756428464.281198, "side": "sell"}
{"type": "orderbook_delta", "seq": 6501, "price": 55, "quantity": 100, "ts": 1756428464.281198, "side": "sell"}
{"type": "orderbook_delta", "seq": 6502, "price": 55, "quantity": -100, "ts": 1756428464.631477, "side": "sell"}
{"type": "orderbook_delta", "seq": 6503, "price": 56, "quantity": 100, "ts": 1756428464.631477, "side": "sell"}
{"type": "orderbook_delta", "seq": 6504, "price": 54, "quantity": -499, "ts": 1756428464.847557, "side": "sell"}
{"type": "orderbook_delta", "seq": 6505, "price": 48, "quantity": -500, "ts": 1756428464.850078, "side": "buy"}
{"type": "orderbook_delta", "seq": 6506, "price": 45, "quantity": -200, "ts": 1756428464.850529, "side": "buy"}
{"type": "orderbook_delta", "seq": 6507, "price": 58, "quantity": -1250, "ts": 1756428464.869934, "side": "sell"}
{"type": "orderbook_delta", "seq": 6508, "price": 56, "quantity": -200, "ts": 1756428464.872729, "side": "sell"}
{"type": "orderbook_delta", "seq": 6509, "price": 43, "quantity": -1250, "ts": 1756428464.884579, "side": "buy"}
{"type": "orderbook_delta", "seq": 6510, "price": 44, "quantity": 1250, "ts": 1756428464.917421, "side": "buy"}
{"type": "orderbook_delta", "seq": 6511, "price": 46, "quantity": 200, "ts": 1756428464.917757, "side": "buy"}
{"type": "orderbook_delta", "seq": 6512, "price": 55, "quantity": 500, "ts": 1756428464.918135, "side": "sell"}
{"type": "orderbook_delta", "seq": 6513, "price": 59, "quantity": 1250, "ts": 1756428464.918408, "side": "sell"}
{"type": "orderbook_delta", "seq": 6514, "price": 49, "quantity": 500, "ts": 1756428464.919478, "side": "buy"}
{"type": "orderbook_delta", "seq": 6515, "price": 57, "quantity": 200, "ts": 1756428464.919981, "side": "sell"}
{"type": "orderbook_delta", "seq": 6516, "price": 66, "quantity": 250, "ts": 1756428465.161012, "side": "sell"}
{"type": "orderbook_delta", "seq": 6517, "price": 56, "quantity": -250, "ts": 1756428465.16125, "side": "sell"}
{"type": "orderbook_delta", "seq": 6518, "price": 56, "quantity": -100, "ts": 1756428465.320384, "side": "sell"}
{"type": "orderbook_delta", "seq": 6519, "price": 58, "quantity": 100, "ts": 1756428465.320384, "side": "sell"}
{"type": "orderbook_delta", "seq": 6520, "price": 55, "quantity": -500, "ts": 1756428465.359567, "side": "sell"}
{"type": "orderbook_delta", "seq": 6521, "price": 56, "quantity": 500, "ts": 1756428465.402796, "side": "sell"}
{"type": "orderbook_delta", "seq": 6522, "price": 49, "quantity": -100, "ts": 1756428465.683233, "side": "buy"}
{"type": "orderbook_delta", "seq": 6523, "price": 50, "quantity": 100, "ts": 1756428465.683233, "side": "buy"}
{"type": "orderbook_delta", "seq": 6524, "price": 56, "quantity": -500, "ts": 1756428466.482371, "side": "sell"}
{"type": "orderbook_delta", "seq": 6525, "price": 46, "quantity": -200, "ts": 1756428466.482445, "side": "buy"}
{"type": "orderbook_delta", "seq": 6526, "price": 49, "quantity": -500, "ts": 1756428466.484431, "side": "buy"}
{"type": "orderbook_delta", "seq": 6527, "price": 59, "quantity": -1250, "ts": 1756428466.48539, "side": "sell"}
{"type": "orderbook_delta", "seq": 6528, "price": 44, "quantity": -1250, "ts": 1756428466.485446, "side": "buy"}
{"type": "orderbook_delta", "seq": 6529, "price": 57, "quantity": -200, "ts": 1756428466.487186, "side": "sell"}
{"type": "orderbook_delta", "seq": 6530, "price": 54, "quantity": 500, "ts": 1756428466.536496, "side": "sell"}
{"type": "orderbook_delta", "seq": 6531, "price": 56, "quantity": 200, "ts": 1756428466.537726, "side": "sell"}
{"type": "orderbook_delta", "seq": 6532, "price": 48, "quantity": 500, "ts": 1756428466.540185, "side": "buy"}
{"type": "orderbook_delta", "seq": 6533, "price": 58, "quantity": 1250, "ts": 1756428466.540702, "side": "sell"}
{"type": "orderbook_delta", "seq": 6534, "price": 45, "quantity": 200, "ts": 1756428466.540976, "side": "buy"}
{"type": "orderbook_delta", "seq": 6535, "price": 50, "quantity": -100, "ts": 1756428466.545791, "side": "buy"}
{"type": "orderbook_delta", "seq": 6536, "price": 49, "quantity": 100, "ts": 1756428466.545791, "side": "buy"}
{"type": "orderbook_delta", "seq": 6537, "price": 43, "quantity": 1250, "ts": 1756428466.546024, "side": "buy"}
{"type": "orderbook_delta", "seq": 6538, "price": 54, "quantity": -969, "ts": 1756428468.106896, "side": "sell"}
{"type": "orderbook_delta", "seq": 6539, "price": 45, "quantity": -200, "ts": 1756428468.158982, "side": "buy"}
{"type": "orderbook_delta", "seq": 6540, "price": 58, "quantity": -1250, "ts": 1756428468.16069, "side": "sell"}
{"type": "orderbook_delta", "seq": 6541, "price": 43, "quantity": -1250, "ts": 1756428468.161229, "side": "buy"}
{"type": "orderbook_delta", "seq": 6542, "price": 55, "quantity": 969, "ts": 1756428468.170897, "side": "sell"}
{"type": "orderbook_delta", "seq": 6543, "price": 56, "quantity": -200, "ts": 1756428468.183998, "side": "sell"}
{"type": "orderbook_delta", "seq": 6544, "price": 59, "quantity": 1250, "ts": 1756428468.229664, "side": "sell"}
{"type": "orderbook_delta", "seq": 6545, "price": 44, "quantity": 1250, "ts": 1756428468.230792, "side": "buy"}
{"type": "orderbook_delta", "seq": 6546, "price": 46, "quantity": 200, "ts": 1756428468.231168, "side": "buy"}
{"type": "orderbook_delta", "seq": 6547, "price": 57, "quantity": 200, "ts": 1756428468.254218, "side": "sell"}
{"type": "orderbook_delta", "seq": 6548, "price": 55, "quantity": -969, "ts": 1756428469.106143, "side": "sell"}
{"type": "orderbook_delta", "seq": 6549, "price": 56, "quantity": 250, "ts": 1756428469.106503, "side": "sell"}
{"type": "orderbook_delta", "seq": 6550, "price": 66, "quantity": -250, "ts": 1756428469.146691, "side": "sell"}
{"type": "orderbook_delta", "seq": 6551, "price": 54, "quantity": 969, "ts": 1756428469.192036, "side": "sell"}
{"type": "orderbook_delta", "seq": 6552, "price": 48, "quantity": -500, "ts": 1756428469.813478, "side": "buy"}
{"type": "orderbook_delta", "seq": 6553, "price": 54, "quantity": -500, "ts": 1756428469.813549, "side": "sell"}
{"type": "orderbook_delta", "seq": 6554, "price": 49, "quantity": 500, "ts": 1756428469.845726, "side": "buy"}
{"type": "orderbook_delta", "seq": 6555, "price": 55, "quantity": 500, "ts": 1756428469.846027, "side": "sell"}
{"type": "orderbook_delta", "seq": 6556, "price": 49, "quantity": -100, "ts": 1756428469.902021, "side": "buy"}
{"type": "orderbook_delta", "seq": 6557, "price": 50, "quantity": 100, "ts": 1756428469.902021, "side": "buy"}
{"type": "orderbook_delta", "seq": 6558, "price": 55, "quantity": -500, "ts": 1756428469.947575, "side": "sell"}
{"type": "orderbook_delta", "seq": 6559, "price": 49, "quantity": -500, "ts": 1756428469.948233, "side": "buy"}
{"type": "orderbook_delta", "seq": 6560, "price": 44, "quantity": -1250, "ts": 1756428469.962692, "side": "buy"}
{"type": "orderbook_delta", "seq": 6561, "price": 59, "quantity": -1250, "ts": 1756428469.962994, "side": "sell"}
{"type": "orderbook_delta", "seq": 6562, "price": 46, "quantity": -200, "ts": 1756428469.96579, "side": "buy"}
{"type": "orderbook_delta", "seq": 6563, "price": 57, "quantity": -200, "ts": 1756428469.967952, "side": "sell"}
{"type": "orderbook_delta", "seq": 6564, "price": 54, "quantity": 500, "ts": 1756428469.983866, "side": "sell"}
{"type": "orderbook_delta", "seq": 6565, "price": 48, "quantity": 500, "ts": 1756428469.986537, "side": "buy"}
{"type": "orderbook_delta", "seq": 6566, "price": 57, "quantity": -200, "ts": 1756428470.001792, "side": "sell"}
{"type": "orderbook_delta", "seq": 6567, "price": 55, "quantity": 200, "ts": 1756428470.001792, "side": "sell"}
{"type": "orderbook_delta", "seq": 6568, "price": 43, "quantity": 1250, "ts": 1756428470.002914, "side": "buy"}
{"type": "orderbook_delta", "seq": 6569, "price": 58, "quantity": 1250, "ts": 1756428470.006547, "side": "sell"}
{"type": "orderbook_delta", "seq": 6570, "price": 56, "quantity": 200, "ts": 1756428470.007199, "side": "sell"}
{"type": "orderbook_delta", "seq": 6571, "price": 45, "quantity": 200, "ts": 1756428470.019479, "side": "buy"}
{"type": "orderbook_delta", "seq": 6572, "price": 50, "quantity": -100, "ts": 1756428470.086254, "side": "buy"}
{"type": "orderbook_delta", "seq": 6573, "price": 48, "quantity": 100, "ts": 1756428470.086254, "side": "buy"}
{"type": "orderbook_delta", "seq": 6574, "price": 58, "quantity": -100, "ts": 1756428470.142538, "side": "sell"}
{"type": "orderbook_delta", "seq": 6575, "price": 53, "quantity": 100, "ts": 1756428470.142538, "side": "sell"}
{"type": "orderbook_delta", "seq": 6576, "price": 53, "quantity": -100, "ts": 1756428470.194578, "side": "sell"}
{"type": "orderbook_delta", "seq": 6577, "price": 54, "quantity": 100, "ts": 1756428470.194578, "side": "sell"}
{"type": "orderbook_delta", "seq": 6578, "price": 54, "quantity": -969, "ts": 1756428471.128479, "side": "sell"}
{"type": "orderbook_delta", "seq": 6579, "price": 53, "quantity": 969, "ts": 1756428471.202706, "side": "sell"}
{"type": "orderbook_delta", "seq": 6580, "price": 54, "quantity": -500, "ts": 1756428471.438493, "side": "sell"}
{"type": "orderbook_delta", "seq": 6581, "price": 48, "quantity": -500, "ts": 1756428471.446981, "side": "buy"}
{"type": "orderbook_delta", "seq": 6582, "price": 47, "quantity": 500, "ts": 1756428471.490553, "side": "buy"}
{"type": "orderbook_delta", "seq": 6583, "price": 53, "quantity": 500, "ts": 1756428471.491938, "side": "sell"}
{"type": "orderbook_delta", "seq": 6584, "price": 48, "quantity": -100, "ts": 1756428471.591731, "side": "buy"}
{"type": "orderbook_delta", "seq": 6585, "price": 49, "quantity": 100, "ts": 1756428471.591731, "side": "buy"}
{"type": "orderbook_delta", "seq": 6586, "price": 54, "quantity": -100, "ts": 1756428472.103671, "side": "sell"}
{"type": "orderbook_delta", "seq": 6587, "price": 53, "quantity": 100, "ts": 1756428472.103671, "side": "sell"}
{"type": "orderbook_delta", "seq": 6588, "price": 53, "quantity": -969, "ts": 1756428472.13364, "side": "sell"}
{"type": "orderbook_delta", "seq": 6589, "price": 36, "quantity": 250, "ts": 1756428472.134968, "side": "buy"}
{"type": "orderbook_delta", "seq": 6590, "price": 54, "quantity": 250, "ts": 1756428472.147206, "side": "sell"}
{"type": "orderbook_delta", "seq": 6591, "price": 46, "quantity": -250, "ts": 1756428472.147552, "side": "buy"}
{"type": "orderbook_delta", "seq": 6592, "price": 38, "quantity": 250, "ts": 1756428472.167143, "side": "buy"}
{"type": "orderbook_delta", "seq": 6593, "price": 47, "quantity": -500, "ts": 1756428472.184236, "side": "buy"}
{"type": "orderbook_delta", "seq": 6594, "price": 48, "quantity": -250, "ts": 1756428472.186883, "side": "buy"}
{"type": "orderbook_delta", "seq": 6595, "price": 64, "quantity": -250, "ts": 1756428472.205642, "side": "sell"}
{"type": "orderbook_delta", "seq": 6596, "price": 45, "quantity": 500, "ts": 1756428472.21405, "side": "buy"}
{"type": "orderbook_delta", "seq": 6597, "price": 53, "quantity": -100, "ts": 1756428472.23311, "side": "sell"}
{"type": "orderbook_delta", "seq": 6598, "price": 54, "quantity": 100, "ts": 1756428472.23311, "side": "sell"}
{"type": "orderbook_delta", "seq": 6599, "price": 52, "quantity": 969, "ts": 1756428472.249815, "side": "sell"}
{"type": "orderbook_delta", "seq": 6600, "price": 49, "quantity": -100, "ts": 1756428472.282006, "side": "buy"}
{"type": "orderbook_delta", "seq": 6601, "price": 46, "quantity": 100, "ts": 1756428472.282006, "side": "buy"}
{"type": "orderbook_delta", "seq": 6602, "price": 54, "quantity": -100, "ts": 1756428472.335387, "side": "sell"}
{"type": "orderbook_delta", "seq": 6603, "price": 55, "quantity": 100, "ts": 1756428472.335387, "side": "sell"}
{"type": "orderbook_delta", "seq": 6604, "price": 45, "quantity": -500, "ts": 1756428472.384936, "side": "buy"}
{"type": "orderbook_delta", "seq": 6605, "price": 47, "quantity": 500, "ts": 1756428472.433758, "side": "buy"}
{"type": "orderbook_delta", "seq": 6606, "price": 46, "quantity": -100, "ts": 1756428473.036944, "side": "buy"}
{"type": "orderbook_delta", "seq": 6607, "price": 48, "quantity": 100, "ts": 1756428473.036944, "side": "buy"}
{"type": "orderbook_delta", "seq": 6608, "price": 53, "quantity": -500, "ts": 1756428473.064861, "side": "sell"}
{"type": "orderbook_delta", "seq": 6609, "price": 47, "quantity": -500, "ts": 1756428473.099499, "side": "buy"}
{"type": "orderbook_delta", "seq": 6610, "price": 51, "quantity": -100, "ts": 1756428473.105048, "side": "buy"}
{"type": "orderbook_delta", "seq": 6611, "price": 54, "quantity": 500, "ts": 1756428473.109475, "side": "sell"}
{"type": "orderbook_delta", "seq": 6612, "price": 48, "quantity": 500, "ts": 1756428473.135613, "side": "buy"}
{"type": "orderbook_delta", "seq": 6613, "price": 54, "quantity": -100, "ts": 1756428473.317877, "side": "sell"}
{"type": "orderbook_delta", "seq": 6614, "price": 48, "quantity": -100, "ts": 1756428473.774542, "side": "buy"}
{"type": "orderbook_delta", "seq": 6615, "price": 49, "quantity": 100, "ts": 1756428473.774542, "side": "buy"}
{"type": "orderbook_delta", "seq": 6616, "price": 48, "quantity": -500, "ts": 1756428473.80642, "side": "buy"}
{"type": "orderbook_delta", "seq": 6617, "price": 45, "quantity": 500, "ts": 1756428473.853042, "side": "buy"}
{"type": "orderbook_delta", "seq": 6618, "price": 55, "quantity": -100, "ts": 1756428473.989005, "side": "sell"}
{"type": "orderbook_delta", "seq": 6619, "price": 53, "quantity": 100, "ts": 1756428473.989005, "side": "sell"}
{"type": "orderbook_delta", "seq": 6620, "price": 36, "quantity": -250, "ts": 1756428474.098815, "side": "buy"}
{"type": "orderbook_delta", "seq": 6621, "price": 46, "quantity": 250, "ts": 1756428474.10232, "side": "buy"}
{"type": "orderbook_delta", "seq": 6622, "price": 45, "quantity": -500, "ts": 1756428474.13002, "side": "buy"}
{"type": "orderbook_delta", "seq": 6623, "price": 47, "quantity": 500, "ts": 1756428474.179731, "side": "buy"}
{"type": "orderbook_delta", "seq": 6624, "price": 54, "quantity": -500, "ts": 1756428474.711051, "side": "sell"}
{"type": "orderbook_delta", "seq": 6625, "price": 53, "quantity": 500, "ts": 1756428474.756066, "side": "sell"}
{"type": "orderbook_delta", "seq": 6626, "price": 49, "quantity": -100, "ts": 1756428475.289693, "side": "buy"}
{"type": "orderbook_delta", "seq": 6627, "price": 48, "quantity": 100, "ts": 1756428475.289693, "side": "buy"}
{"type": "orderbook_delta", "seq": 6628, "price": 49, "quantity": 100, "ts": 1756428475.385264, "side": "buy"}
{"type": "orderbook_delta", "seq": 6629, "price": 52, "quantity": 100, "ts": 1756428476.134614, "side": "sell"}
{"type": "orderbook_delta", "seq": 6630, "price": 45, "quantity": -200, "ts": 1756428476.175002, "side": "buy"}
{"type": "orderbook_delta", "seq": 6631, "price": 58, "quantity": -1250, "ts": 1756428476.176661, "side": "sell"}
{"type": "orderbook_delta", "seq": 6632, "price": 56, "quantity": -200, "ts": 1756428476.176744, "side": "sell"}
{"type": "orderbook_delta", "seq": 6633, "price": 43, "quantity": -1250, "ts": 1756428476.237498, "side": "buy"}
{"type": "orderbook_delta", "seq": 6634, "price": 43, "quantity": 1250, "ts": 1756428476.338268, "side": "buy"}
{"type": "orderbook_delta", "seq": 6635, "price": 45, "quantity": 200, "ts": 1756428476.35152, "side": "buy"}
{"type": "orderbook_delta", "seq": 6636, "price": 58, "quantity": 1250, "ts": 1756428476.36769, "side": "sell"}
{"type": "orderbook_delta", "seq": 6637, "price": 56, "quantity": 200, "ts": 1756428476.374645, "side": "sell"}
{"type": "orderbook_delta", "seq": 6638, "price": 56, "quantity": -200, "ts": 1756428476.466354, "side": "sell"}
{"type": "orderbook_delta", "seq": 6639, "price": 45, "quantity": -200, "ts": 1756428476.46645, "side": "buy"}
{"type": "orderbook_delta", "seq": 6640, "price": 58, "quantity": -1250, "ts": 1756428476.469596, "side": "sell"}
{"type": "orderbook_delta", "seq": 6641, "price": 43, "quantity": -1250, "ts": 1756428476.470517, "side": "buy"}
{"type": "orderbook_delta", "seq": 6642, "price": 47, "quantity": -500, "ts": 1756428476.471988, "side": "buy"}
{"type": "orderbook_delta", "seq": 6643, "price": 53, "quantity": -500, "ts": 1756428476.475069, "side": "sell"}
{"type": "orderbook_delta", "seq": 6644, "price": 55, "quantity": -200, "ts": 1756428476.484319, "side": "sell"}
{"type": "orderbook_delta", "seq": 6645, "price": 54, "quantity": 200, "ts": 1756428476.484319, "side": "sell"}
{"type": "orderbook_delta", "seq": 6646, "price": 43, "quantity": 200, "ts": 1756428476.502043, "side": "buy"}
{"type": "orderbook_delta", "seq": 6647, "price": 56, "quantity": 1250, "ts": 1756428476.504582, "side": "sell"}
{"type": "orderbook_delta", "seq": 6648, "price": 54, "quantity": 200, "ts": 1756428476.505103, "side": "sell"}
{"type": "orderbook_delta", "seq": 6649, "price": 41, "quantity": 1250, "ts": 1756428476.507945, "side": "buy"}
{"type": "orderbook_delta", "seq": 6650, "price": 52, "quantity": 500, "ts": 1756428476.517076, "side": "sell"}
{"type": "orderbook_delta", "seq": 6651, "price": 30, "quantity": -200, "ts": 1756428476.529958, "side": "buy"}
{"type": "orderbook_delta", "seq": 6652, "price": 20, "quantity": 200, "ts": 1756428476.529958, "side": "buy"}
{"type": "orderbook_delta", "seq": 6653, "price": 54, "quantity": -200, "ts": 1756428476.530207, "side": "sell"}
{"type": "orderbook_delta", "seq": 6654, "price": 52, "quantity": 200, "ts": 1756428476.530207, "side": "sell"}
{"type": "orderbook_delta", "seq": 6655, "price": 46, "quantity": 500, "ts": 1756428476.55837, "side": "buy"}
{"type": "orderbook_delta", "seq": 6656, "price": 90, "quantity": -200, "ts": 1756428476.576392, "side": "sell"}
{"type": "orderbook_delta", "seq": 6657, "price": 80, "quantity": 200, "ts": 1756428476.576392, "side": "sell"}
{"type": "orderbook_delta", "seq": 6658, "price": 53, "quantity": -100, "ts": 1756428476.577338, "side": "sell"}
{"type": "orderbook_delta", "seq": 6659, "price": 52, "quantity": 100, "ts": 1756428476.577338, "side": "sell"}
{"type": "orderbook_delta", "seq": 6660, "price": 89, "quantity": -8000, "ts": 1756428476.609483, "side": "sell"}
{"type": "orderbook_delta", "seq": 6661, "price": 48, "quantity": -100, "ts": 1756428476.654233, "side": "buy"}
{"type": "orderbook_delta", "seq": 6662, "price": 46, "quantity": 100, "ts": 1756428476.654233, "side": "buy"}
{"type": "orderbook_delta", "seq": 6663, "price": 46, "quantity": -100, "ts": 1756428476.754044, "side": "buy"}
{"type": "orderbook_delta", "seq": 6664, "price": 45, "quantity": 100, "ts": 1756428476.754044, "side": "buy"}
{"type": "orderbook_delta", "seq": 6665, "price": 80, "quantity": 8000, "ts": 1756428476.795601, "side": "sell"}
{"type": "orderbook_delta", "seq": 6666, "price": 52, "quantity": -100, "ts": 1756428476.816306, "side": "sell"}
{"type": "orderbook_delta", "seq": 6667, "price": 53, "quantity": 100, "ts": 1756428476.816306, "side": "sell"}
{"type": "orderbook_delta", "seq": 6668, "price": 53, "quantity": -100, "ts": 1756428476.901127, "side": "sell"}
{"type": "orderbook_delta", "seq": 6669, "price": 54, "quantity": 100, "ts": 1756428476.901127, "side": "sell"}
{"type": "orderbook_delta", "seq": 6670, "price": 52, "quantity": -500, "ts": 1756428476.998088, "side": "sell"}
{"type": "orderbook_delta", "seq": 6671, "price": 46, "quantity": -500, "ts": 1756428477.000667, "side": "buy"}
{"type": "orderbook_delta", "seq": 6672, "price": 45, "quantity": 500, "ts": 1756428477.055091, "side": "buy"}
{"type": "orderbook_delta", "seq": 6673, "price": 51, "quantity": 500, "ts": 1756428477.065542, "side": "sell"}
{"type": "orderbook_delta", "seq": 6674, "price": 54, "quantity": -100, "ts": 1756428477.066104, "side": "sell"}
{"type": "orderbook_delta", "seq": 6675, "price": 55, "quantity": 100, "ts": 1756428477.066104, "side": "sell"}
{"type": "orderbook_delta", "seq": 6676, "price": 36, "quantity": 250, "ts": 1756428477.077041, "side": "buy"}
{"type": "orderbook_delta", "seq": 6677, "price": 46, "quantity": -250, "ts": 1756428477.081731, "side": "buy"}
{"type": "orderbook_delta", "seq": 6678, "price": 36, "quantity": -250, "ts": 1756428477.121581, "side": "buy"}
{"type": "orderbook_delta", "seq": 6679, "price": 52, "quantity": -969, "ts": 1756428477.17984, "side": "sell"}
{"type": "orderbook_delta", "seq": 6680, "price": 51, "quantity": 969, "ts": 1756428477.298391, "side": "sell"}
{"type": "orderbook_delta", "seq": 6681, "price": 80, "quantity": -8000, "ts": 1756428477.430294, "side": "sell"}
{"type": "orderbook_delta", "seq": 6682, "price": 79, "quantity": 8000, "ts": 1756428477.472613, "side": "sell"}
{"type": "orderbook_delta", "seq": 6683, "price": 45, "quantity": -100, "ts": 1756428478.264852, "side": "buy"}
{"type": "orderbook_delta", "seq": 6684, "price": 46, "quantity": 100, "ts": 1756428478.264852, "side": "buy"}
{"type": "orderbook_delta", "seq": 6685, "price": 55, "quantity": -100, "ts": 1756428478.533458, "side": "sell"}
{"type": "orderbook_delta", "seq": 6686, "price": 53, "quantity": 100, "ts": 1756428478.533458, "side": "sell"}
{"type": "orderbook_delta", "seq": 6687, "price": 43, "quantity": -200, "ts": 1756428478.564088, "side": "buy"}
{"type": "orderbook_delta", "seq": 6688, "price": 56, "quantity": -1250, "ts": 1756428478.565451, "side": "sell"}
{"type": "orderbook_delta", "seq": 6689, "price": 54, "quantity": -200, "ts": 1756428478.566821, "side": "sell"}
{"type": "orderbook_delta", "seq": 6690, "price": 41, "quantity": -1250, "ts": 1756428478.56925, "side": "buy"}
{"type": "orderbook_delta", "seq": 6691, "price": 53, "quantity": 200, "ts": 1756428478.614288, "side": "sell"}
{"type": "orderbook_delta", "seq": 6692, "price": 40, "quantity": 1250, "ts": 1756428478.615799, "side": "buy"}
{"type": "orderbook_delta", "seq": 6693, "price": 55, "quantity": 1250, "ts": 1756428478.616284, "side": "sell"}
{"type": "orderbook_delta", "seq": 6694, "price": 42, "quantity": 200, "ts": 1756428478.616593, "side": "buy"}
{"type": "orderbook_delta", "seq": 6695, "price": 40, "quantity": -1250, "ts": 1756428479.612848, "side": "buy"}
{"type": "orderbook_delta", "seq": 6696, "price": 53, "quantity": -200, "ts": 1756428479.61469, "side": "sell"}
{"type": "orderbook_delta", "seq": 6697, "price": 42, "quantity": -200, "ts": 1756428479.617211, "side": "buy"}
{"type": "orderbook_delta", "seq": 6698, "price": 55, "quantity": -1250, "ts": 1756428479.619726, "side": "sell"}
{"type": "orderbook_delta", "seq": 6699, "price": 56, "quantity": 1250, "ts": 1756428479.679393, "side": "sell"}
{"type": "orderbook_delta", "seq": 6700, "price": 54, "quantity": 200, "ts": 1756428479.68032, "side": "sell"}
{"type": "orderbook_delta", "seq": 6701, "price": 41, "quantity": 1250, "ts": 1756428479.680854, "side": "buy"}
{"type": "orderbook_delta", "seq": 6702, "price": 43, "quantity": 200, "ts": 1756428479.681758, "side": "buy"}
{"type": "orderbook_delta", "seq": 6703, "price": 49, "quantity": -100, "ts": 1756428480.806436, "side": "buy"}
{"type": "orderbook_delta", "seq": 6704, "price": 52, "quantity": -100, "ts": 1756428481.022569, "side": "sell"}
{"type": "orderbook_delta", "seq": 6705, "price": 52, "quantity": 250, "ts": 1756428481.134969, "side": "sell"}
{"type": "orderbook_delta", "seq": 6706, "price": 62, "quantity": -250, "ts": 1756428481.138566, "side": "sell"}
{"type": "orderbook_delta", "seq": 6707, "price": 47, "quantity": 100, "ts": 1756428483.836677, "side": "buy"}
{"type": "orderbook_delta", "seq": 6708, "price": 46, "quantity": -100, "ts": 1756428483.837316, "side": "buy"}
{"type": "orderbook_delta", "seq": 6709, "price": 45, "quantity": 100, "ts": 1756428483.837316, "side": "buy"}
{"type": "orderbook_delta", "seq": 6710, "price": 51, "quantity": -500, "ts": 1756428484.457536, "side": "sell"}
{"type": "orderbook_delta", "seq": 6711, "price": 45, "quantity": -500, "ts": 1756428484.458772, "side": "buy"}
{"type": "orderbook_delta", "seq": 6712, "price": 79, "quantity": -8000, "ts": 1756428484.482455, "side": "sell"}
{"type": "orderbook_delta", "seq": 6713, "price": 80, "quantity": 8000, "ts": 1756428484.52847, "side": "sell"}
{"type": "orderbook_delta", "seq": 6714, "price": 52, "quantity": 500, "ts": 1756428484.530041, "side": "sell"}
{"type": "orderbook_delta", "seq": 6715, "price": 46, "quantity": 500, "ts": 1756428484.53035, "side": "buy"}
{"type": "orderbook_delta", "seq": 6716, "price": 53, "quantity": -100, "ts": 1756428484.931473, "side": "sell"}
{"type": "orderbook_delta", "seq": 6717, "price": 54, "quantity": 100, "ts": 1756428484.931473, "side": "sell"}
{"type": "orderbook_delta", "seq": 6718, "price": 45, "quantity": -100, "ts": 1756428485.391906, "side": "buy"}
{"type": "orderbook_delta", "seq": 6719, "price": 47, "quantity": 100, "ts": 1756428485.391906, "side": "buy"}
{"type": "orderbook_delta", "seq": 6720, "price": 46, "quantity": -500, "ts": 1756428485.429104, "side": "buy"}
{"type": "orderbook_delta", "seq": 6721, "price": 45, "quantity": 500, "ts": 1756428485.466032, "side": "buy"}
{"type": "orderbook_delta", "seq": 6722, "price": 47, "quantity": -100, "ts": 1756428485.576058, "side": "buy"}
{"type": "orderbook_delta", "seq": 6723, "price": 46, "quantity": 100, "ts": 1756428485.576058, "side": "buy"}
{"type": "orderbook_delta", "seq": 6724, "price": 45, "quantity": -500, "ts": 1756428485.620397, "side": "buy"}
{"type": "orderbook_delta", "seq": 6725, "price": 46, "quantity": 500, "ts": 1756428485.65265, "side": "buy"}
{"type": "orderbook_delta", "seq": 6726, "price": 80, "quantity": -8000, "ts": 1756428485.901482, "side": "sell"}
{"type": "orderbook_delta", "seq": 6727, "price": 46, "quantity": -500, "ts": 1756428485.902461, "side": "buy"}
{"type": "orderbook_delta", "seq": 6728, "price": 52, "quantity": -500, "ts": 1756428485.903466, "side": "sell"}
{"type": "orderbook_delta", "seq": 6729, "price": 79, "quantity": 8000, "ts": 1756428485.935568, "side": "sell"}
{"type": "orderbook_delta", "seq": 6730, "price": 45, "quantity": 500, "ts": 1756428485.936254, "side": "buy"}
{"type": "orderbook_delta", "seq": 6731, "price": 51, "quantity": 500, "ts": 1756428485.93737, "side": "sell"}
{"type": "orderbook_delta", "seq": 6732, "price": 54, "quantity": -100, "ts": 1756428486.432115, "side": "sell"}
{"type": "orderbook_delta", "seq": 6733, "price": 52, "quantity": 100, "ts": 1756428486.432115, "side": "sell"}
{"type": "orderbook_delta", "seq": 6734, "price": 50, "quantity": 100, "ts": 1756428486.649362, "side": "sell"}
{"type": "orderbook_delta", "seq": 6735, "price": 79, "quantity": -8000, "ts": 1756428487.387909, "side": "sell"}
{"type": "orderbook_delta", "seq": 6736, "price": 80, "quantity": 8000, "ts": 1756428487.424302, "side": "sell"}
{"type": "orderbook_delta", "seq": 6737, "price": 52, "quantity": -250, "ts": 1756428489.149946, "side": "sell"}
{"type": "orderbook_delta", "seq": 6738, "price": 62, "quantity": 250, "ts": 1756428489.149966, "side": "sell"}
{"type": "orderbook_delta", "seq": 6739, "price": 51, "quantity": -500, "ts": 1756428489.185717, "side": "sell"}
{"type": "orderbook_delta", "seq": 6740, "price": 45, "quantity": -500, "ts": 1756428489.188196, "side": "buy"}
{"type": "orderbook_delta", "seq": 6741, "price": 52, "quantity": 500, "ts": 1756428489.239124, "side": "sell"}
{"type": "orderbook_delta", "seq": 6742, "price": 46, "quantity": -100, "ts": 1756428489.289353, "side": "buy"}
{"type": "orderbook_delta", "seq": 6743, "price": 45, "quantity": 100, "ts": 1756428489.289353, "side": "buy"}
{"type": "orderbook_delta", "seq": 6744, "price": 46, "quantity": 500, "ts": 1756428489.32902, "side": "buy"}
{"type": "orderbook_delta", "seq": 6745, "price": 45, "quantity": -100, "ts": 1756428490.032277, "side": "buy"}
{"type": "orderbook_delta", "seq": 6746, "price": 47, "quantity": 100, "ts": 1756428490.032277, "side": "buy"}
{"type": "orderbook_delta", "seq": 6747, "price": 46, "quantity": -500, "ts": 1756428490.061093, "side": "buy"}
{"type": "orderbook_delta", "seq": 6748, "price": 80, "quantity": -8000, "ts": 1756428490.082345, "side": "sell"}
{"type": "orderbook_delta", "seq": 6749, "price": 52, "quantity": -500, "ts": 1756428490.084786, "side": "sell"}
{"type": "orderbook_delta", "seq": 6750, "price": 51, "quantity": 500, "ts": 1756428490.125685, "side": "sell"}
{"type": "orderbook_delta", "seq": 6751, "price": 79, "quantity": 8000, "ts": 1756428490.126043, "side": "sell"}
{"type": "orderbook_delta", "seq": 6752, "price": 56, "quantity": -1250, "ts": 1756428490.129065, "side": "sell"}
{"type": "orderbook_delta", "seq": 6753, "price": 41, "quantity": -1250, "ts": 1756428490.130717, "side": "buy"}
{"type": "orderbook_delta", "seq": 6754, "price": 54, "quantity": -200, "ts": 1756428490.130857, "side": "sell"}
{"type": "orderbook_delta", "seq": 6755, "price": 44, "quantity": -250, "ts": 1756428490.143159, "side": "buy"}
{"type": "orderbook_delta", "seq": 6756, "price": 34, "quantity": 250, "ts": 1756428490.144145, "side": "buy"}
{"type": "orderbook_delta", "seq": 6757, "price": 43, "quantity": -200, "ts": 1756428490.149583, "side": "buy"}
{"type": "orderbook_delta", "seq": 6758, "price": 36, "quantity": 250, "ts": 1756428490.156105, "side": "buy"}
{"type": "orderbook_delta", "seq": 6759, "price": 47, "quantity": -100, "ts": 1756428490.179109, "side": "buy"}
{"type": "orderbook_delta", "seq": 6760, "price": 45, "quantity": 100, "ts": 1756428490.179109, "side": "buy"}
{"type": "orderbook_delta", "seq": 6761, "price": 42, "quantity": 200, "ts": 1756428490.201951, "side": "buy"}
{"type": "orderbook_delta", "seq": 6762, "price": 40, "quantity": 1250, "ts": 1756428490.202568, "side": "buy"}
{"type": "orderbook_delta", "seq": 6763, "price": 55, "quantity": 1250, "ts": 1756428490.203124, "side": "sell"}
{"type": "orderbook_delta", "seq": 6764, "price": 53, "quantity": 200, "ts": 1756428490.204181, "side": "sell"}
{"type": "orderbook_delta", "seq": 6765, "price": 45, "quantity": 500, "ts": 1756428490.287095, "side": "buy"}
{"type": "orderbook_delta", "seq": 6766, "price": 53, "quantity": -200, "ts": 1756428490.331117, "side": "sell"}
{"type": "orderbook_delta", "seq": 6767, "price": 40, "quantity": -1250, "ts": 1756428490.332434, "side": "buy"}
{"type": "orderbook_delta", "seq": 6768, "price": 51, "quantity": -500, "ts": 1756428490.333085, "side": "sell"}
{"type": "orderbook_delta", "seq": 6769, "price": 55, "quantity": -1250, "ts": 1756428490.33479, "side": "sell"}
{"type": "orderbook_delta", "seq": 6770, "price": 45, "quantity": -500, "ts": 1756428490.354873, "side": "buy"}
{"type": "orderbook_delta", "seq": 6771, "price": 43, "quantity": 500, "ts": 1756428490.384287, "side": "buy"}
{"type": "orderbook_delta", "seq": 6772, "price": 42, "quantity": -200, "ts": 1756428490.394709, "side": "buy"}
{"type": "orderbook_delta", "seq": 6773, "price": 50, "quantity": 500, "ts": 1756428490.453139, "side": "sell"}
{"type": "orderbook_delta", "seq": 6774, "price": 52, "quantity": 200, "ts": 1756428490.454626, "side": "sell"}
{"type": "orderbook_delta", "seq": 6775, "price": 39, "quantity": 1250, "ts": 1756428490.455039, "side": "buy"}
{"type": "orderbook_delta", "seq": 6776, "price": 54, "quantity": 1250, "ts": 1756428490.466169, "side": "sell"}
{"type": "orderbook_delta", "seq": 6777, "price": 41, "quantity": 200, "ts": 1756428490.468673, "side": "buy"}
{"type": "orderbook_delta", "seq": 6778, "price": 52, "quantity": -100, "ts": 1756428490.549113, "side": "sell"}
{"type": "orderbook_delta", "seq": 6779, "price": 53, "quantity": 100, "ts": 1756428490.549113, "side": "sell"}
{"type": "orderbook_delta", "seq": 6780, "price": 53, "quantity": -100, "ts": 1756428490.705431, "side": "sell"}
{"type": "orderbook_delta", "seq": 6781, "price": 54, "quantity": 100, "ts": 1756428490.705431, "side": "sell"}
{"type": "orderbook_delta", "seq": 6782, "price": 41, "quantity": -200, "ts": 1756428490.979961, "side": "buy"}
{"type": "orderbook_delta", "seq": 6783, "price": 39, "quantity": -1250, "ts": 1756428490.980206, "side": "buy"}
{"type": "orderbook_delta", "seq": 6784, "price": 52, "quantity": -200, "ts": 1756428490.982857, "side": "sell"}
{"type": "orderbook_delta", "seq": 6785, "price": 53, "quantity": 200, "ts": 1756428491.020555, "side": "sell"}
{"type": "orderbook_delta", "seq": 6786, "price": 42, "quantity": 200, "ts": 1756428491.020968, "side": "buy"}
{"type": "orderbook_delta", "seq": 6787, "price": 40, "quantity": 1250, "ts": 1756428491.054178, "side": "buy"}
{"type": "orderbook_delta", "seq": 6788, "price": 34, "quantity": -250, "ts": 1756428491.089996, "side": "buy"}
{"type": "orderbook_delta", "seq": 6789, "price": 62, "quantity": -250, "ts": 1756428491.117452, "side": "sell"}
{"type": "orderbook_delta", "seq": 6790, "price": 52, "quantity": 250, "ts": 1756428491.119104, "side": "sell"}
{"type": "orderbook_delta", "seq": 6791, "price": 54, "quantity": -1250, "ts": 1756428491.123845, "side": "sell"}
{"type": "orderbook_delta", "seq": 6792, "price": 55, "quantity": 1250, "ts": 1756428491.151868, "side": "sell"}
{"type": "orderbook_delta", "seq": 6793, "price": 44, "quantity": 250, "ts": 1756428491.176097, "side": "buy"}
{"type": "orderbook_delta", "seq": 6794, "price": 43, "quantity": -500, "ts": 1756428491.216173, "side": "buy"}
{"type": "orderbook_delta", "seq": 6795, "price": 44, "quantity": 500, "ts": 1756428491.254552, "side": "buy"}
{"type": "orderbook_delta", "seq": 6796, "price": 53, "quantity": -200, "ts": 1756428491.398835, "side": "sell"}
{"type": "orderbook_delta", "seq": 6797, "price": 40, "quantity": -1250, "ts": 1756428491.399103, "side": "buy"}
{"type": "orderbook_delta", "seq": 6798, "price": 44, "quantity": -500, "ts": 1756428491.399618, "side": "buy"}
{"type": "orderbook_delta", "seq": 6799, "price": 34, "quantity": 250, "ts": 1756428491.399839, "side": "buy"}
{"type": "orderbook_delta", "seq": 6800, "price": 55, "quantity": -1250, "ts": 1756428491.400442, "side": "sell"}
{"type": "orderbook_delta", "seq": 6801, "price": 42, "quantity": -200, "ts": 1756428491.410825, "side": "buy"}
{"type": "orderbook_delta", "seq": 6802, "price": 50, "quantity": -500, "ts": 1756428491.410886, "side": "sell"}
{"type": "orderbook_delta", "seq": 6803, "price": 44, "quantity": -250, "ts": 1756428491.411725, "side": "buy"}
{"type": "orderbook_delta", "seq": 6804, "price": 52, "quantity": -200, "ts": 1756428491.440705, "side": "sell"}
{"type": "orderbook_delta", "seq": 6805, "price": 51, "quantity": 200, "ts": 1756428491.440705, "side": "sell"}
{"type": "orderbook_delta", "seq": 6806, "price": 40, "quantity": 200, "ts": 1756428491.459356, "side": "buy"}
{"type": "orderbook_delta", "seq": 6807, "price": 38, "quantity": 1250, "ts": 1756428491.461347, "side": "buy"}
{"type": "orderbook_delta", "seq": 6808, "price": 53, "quantity": 1250, "ts": 1756428491.47311, "side": "sell"}
{"type": "orderbook_delta", "seq": 6809, "price": 49, "quantity": 500, "ts": 1756428491.473381, "side": "sell"}
{"type": "orderbook_delta", "seq": 6810, "price": 51, "quantity": 200, "ts": 1756428491.480302, "side": "sell"}
{"type": "orderbook_delta", "seq": 6811, "price": 40, "quantity": -200, "ts": 1756428491.509697, "side": "buy"}
{"type": "orderbook_delta", "seq": 6812, "price": 53, "quantity": -1250, "ts": 1756428491.511081, "side": "sell"}
{"type": "orderbook_delta", "seq": 6813, "price": 38, "quantity": -1250, "ts": 1756428491.511342, "side": "buy"}
{"type": "orderbook_delta", "seq": 6814, "price": 45, "quantity": -100, "ts": 1756428491.517934, "side": "buy"}
{"type": "orderbook_delta", "seq": 6815, "price": 42, "quantity": 100, "ts": 1756428491.517934, "side": "buy"}
{"type": "orderbook_delta", "seq": 6816, "price": 42, "quantity": 500, "ts": 1756428491.518202, "side": "buy"}
{"type": "orderbook_delta", "seq": 6817, "price": 51, "quantity": -200, "ts": 1756428491.518636, "side": "sell"}
{"type": "orderbook_delta", "seq": 6818, "price": 49, "quantity": 200, "ts": 1756428491.518636, "side": "sell"}
{"type": "orderbook_delta", "seq": 6819, "price": 51, "quantity": -200, "ts": 1756428491.520318, "side": "sell"}
{"type": "orderbook_delta", "seq": 6820, "price": 36, "quantity": 1250, "ts": 1756428491.544285, "side": "buy"}
{"type": "orderbook_delta", "seq": 6821, "price": 51, "quantity": 1250, "ts": 1756428491.545753, "side": "sell"}
{"type": "orderbook_delta", "seq": 6822, "price": 38, "quantity": 200, "ts": 1756428491.547025, "side": "buy"}
{"type": "orderbook_delta", "seq": 6823, "price": 50, "quantity": 200, "ts": 1756428491.55776, "side": "sell"}
{"type": "orderbook_delta", "seq": 6824, "price": 42, "quantity": -500, "ts": 1756428491.578558, "side": "buy"}
{"type": "orderbook_delta", "seq": 6825, "price": 49, "quantity": -200, "ts": 1756428491.596657, "side": "sell"}
{"type": "orderbook_delta", "seq": 6826, "price": 48, "quantity": 200, "ts": 1756428491.596657, "side": "sell"}
{"type": "orderbook_delta", "seq": 6827, "price": 41, "quantity": 500, "ts": 1756428491.635115, "side": "buy"}
{"type": "orderbook_delta", "seq": 6828, "price": 42, "quantity": -100, "ts": 1756428491.641952, "side": "buy"}
{"type": "orderbook_delta", "seq": 6829, "price": 41, "quantity": 100, "ts": 1756428491.641952, "side": "buy"}
{"type": "orderbook_delta", "seq": 6830, "price": 41, "quantity": -100, "ts": 1756428491.686621, "side": "buy"}
{"type": "orderbook_delta", "seq": 6831, "price": 37, "quantity": 100, "ts": 1756428491.686621, "side": "buy"}
{"type": "orderbook_delta", "seq": 6832, "price": 50, "quantity": -200, "ts": 1756428491.695268, "side": "sell"}
{"type": "orderbook_delta", "seq": 6833, "price": 49, "quantity": -500, "ts": 1756428491.69738, "side": "sell"}
{"type": "orderbook_delta", "seq": 6834, "price": 41, "quantity": -500, "ts": 1756428491.720006, "side": "buy"}
{"type": "orderbook_delta", "seq": 6835, "price": 51, "quantity": -1250, "ts": 1756428491.720825, "side": "sell"}
{"type": "orderbook_delta", "seq": 6836, "price": 38, "quantity": -200, "ts": 1756428491.721264, "side": "buy"}
{"type": "orderbook_delta", "seq": 6837, "price": 36, "quantity": -1250, "ts": 1756428491.727151, "side": "buy"}
{"type": "orderbook_delta", "seq": 6838, "price": 42, "quantity": -250, "ts": 1756428491.736494, "side": "buy"}
{"type": "orderbook_delta", "seq": 6839, "price": 32, "quantity": 250, "ts": 1756428491.736614, "side": "buy"}
{"type": "orderbook_delta", "seq": 6840, "price": 48, "quantity": 200, "ts": 1756428491.745591, "side": "sell"}
{"type": "orderbook_delta", "seq": 6841, "price": 35, "quantity": 1250, "ts": 1756428491.771038, "side": "buy"}
{"type": "orderbook_delta", "seq": 6842, "price": 40, "quantity": 500, "ts": 1756428491.771769, "side": "buy"}
{"type": "orderbook_delta", "seq": 6843, "price": 37, "quantity": 200, "ts": 1756428491.772485, "side": "buy"}
{"type": "orderbook_delta", "seq": 6844, "price": 50, "quantity": 1250, "ts": 1756428491.773926, "side": "sell"}
{"type": "orderbook_delta", "seq": 6845, "price": 12, "quantity": -8000, "ts": 1756428491.779216, "side": "buy"}
{"type": "orderbook_delta", "seq": 6846, "price": 47, "quantity": 0, "ts": 1756428491.780915, "side": "buy"}
{"type": "orderbook_delta", "seq": 6847, "price": 48, "quantity": -200, "ts": 1756428491.797151, "side": "sell"}
{"type": "orderbook_delta", "seq": 6848, "price": 40, "quantity": -500, "ts": 1756428491.804611, "side": "buy"}
{"type": "orderbook_delta", "seq": 6849, "price": 37, "quantity": -200, "ts": 1756428491.805036, "side": "buy"}
{"type": "orderbook_delta", "seq": 6850, "price": 35, "quantity": -1250, "ts": 1756428491.805145, "side": "buy"}
{"type": "orderbook_delta", "seq": 6851, "price": 48, "quantity": 500, "ts": 1756428491.818471, "side": "sell"}
{"type": "orderbook_delta", "seq": 6852, "price": 11, "quantity": 8000, "ts": 1756428491.823187, "side": "buy"}
{"type": "orderbook_delta", "seq": 6853, "price": 47, "quantity": 200, "ts": 1756428491.839639, "side": "sell"}
{"type": "orderbook_delta", "seq": 6854, "price": 34, "quantity": 1250, "ts": 1756428491.847291, "side": "buy"}
{"type": "orderbook_delta", "seq": 6855, "price": 39, "quantity": 500, "ts": 1756428491.848601, "side": "buy"}
{"type": "trade", "seq": 66, "price": 47, "quantity": 100, "ts": 1756428491.850806, "side": "sell"}
{"type": "orderbook_delta", "seq": 6856, "price": 48, "quantity": -200, "ts": 1756428491.850806, "side": "sell"}
{"type": "orderbook_delta", "seq": 6857, "price": 47, "quantity": 200, "ts": 1756428491.850806, "side": "sell"}
{"type": "orderbook_delta", "seq": 6858, "price": 36, "quantity": 200, "ts": 1756428491.856186, "side": "buy"}
{"type": "orderbook_delta", "seq": 6859, "price": 48, "quantity": -500, "ts": 1756428491.88707, "side": "sell"}
{"type": "orderbook_delta", "seq": 6860, "price": 40, "quantity": -250, "ts": 1756428491.889065, "side": "buy"}
{"type": "orderbook_delta", "seq": 6861, "price": 30, "quantity": 250, "ts": 1756428491.890687, "side": "buy"}
{"type": "orderbook_delta", "seq": 6862, "price": 47, "quantity": -200, "ts": 1756428491.90613, "side": "sell"}
{"type": "orderbook_delta", "seq": 6863, "price": 46, "quantity": 200, "ts": 1756428491.90613, "side": "sell"}
{"type": "orderbook_delta", "seq": 6864, "price": 46, "quantity": 500, "ts": 1756428491.930577, "side": "sell"}
{"type": "orderbook_delta", "seq": 6865, "price": 30, "quantity": -250, "ts": 1756428491.93153, "side": "buy"}
{"type": "orderbook_delta", "seq": 6866, "price": 47, "quantity": -200, "ts": 1756428491.940202, "side": "sell"}
{"type": "orderbook_delta", "seq": 6867, "price": 46, "quantity": -500, "ts": 1756428491.978319, "side": "sell"}
{"type": "orderbook_delta", "seq": 6868, "price": 50, "quantity": 200, "ts": 1756428491.988124, "side": "sell"}
{"type": "orderbook_delta", "seq": 6869, "price": 45, "quantity": 500, "ts": 1756428492.029297, "side": "sell"}
{"type": "orderbook_delta", "seq": 6870, "price": 30, "quantity": 250, "ts": 1756428492.03972, "side": "buy"}
{"type": "orderbook_delta", "seq": 6871, "price": 36, "quantity": -200, "ts": 1756428492.046876, "side": "buy"}
{"type": "orderbook_delta", "seq": 6872, "price": 20, "quantity": -200, "ts": 1756428492.056489, "side": "buy"}
{"type": "orderbook_delta", "seq": 6873, "price": 10, "quantity": 200, "ts": 1756428492.056489, "side": "buy"}
{"type": "orderbook_delta", "seq": 6874, "price": 50, "quantity": -200, "ts": 1756428492.062482, "side": "sell"}
{"type": "orderbook_delta", "seq": 6875, "price": 39, "quantity": -500, "ts": 1756428492.064728, "side": "buy"}
{"type": "orderbook_delta", "seq": 6876, "price": 46, "quantity": -200, "ts": 1756428492.093041, "side": "sell"}
{"type": "orderbook_delta", "seq": 6877, "price": 45, "quantity": 200, "ts": 1756428492.093041, "side": "sell"}
{"type": "orderbook_delta", "seq": 6878, "price": 80, "quantity": -200, "ts": 1756428492.09563, "side": "sell"}
{"type": "orderbook_delta", "seq": 6879, "price": 70, "quantity": 200, "ts": 1756428492.09563, "side": "sell"}
{"type": "orderbook_delta", "seq": 6880, "price": 50, "quantity": 200, "ts": 1756428492.095975, "side": "sell"}
{"type": "orderbook_delta", "seq": 6881, "price": 36, "quantity": 200, "ts": 1756428492.098687, "side": "buy"}
{"type": "orderbook_delta", "seq": 6882, "price": 28, "quantity": 250, "ts": 1756428492.10074, "side": "buy"}
{"type": "orderbook_delta", "seq": 6883, "price": 38, "quantity": 500, "ts": 1756428492.104991, "side": "buy"}
{"type": "orderbook_delta", "seq": 6884, "price": 51, "quantity": -969, "ts": 1756428492.11735, "side": "sell"}
{"type": "orderbook_delta", "seq": 6885, "price": 45, "quantity": -500, "ts": 1756428492.122627, "side": "sell"}
{"type": "orderbook_delta", "seq": 6886, "price": 79, "quantity": -8000, "ts": 1756428492.132396, "side": "sell"}
{"type": "orderbook_delta", "seq": 6887, "price": 58, "quantity": -250, "ts": 1756428492.136661, "side": "sell"}
{"type": "orderbook_delta", "seq": 6888, "price": 50, "quantity": -1250, "ts": 1756428492.153307, "side": "sell"}
{"type": "orderbook_delta", "seq": 6889, "price": 50, "quantity": -200, "ts": 1756428492.156588, "side": "sell"}
{"type": "orderbook_delta", "seq": 6890, "price": 50, "quantity": 250, "ts": 1756428492.157386, "side": "sell"}
{"type": "orderbook_delta", "seq": 6891, "price": 44, "quantity": 500, "ts": 1756428492.161859, "side": "sell"}
{"type": "orderbook_delta", "seq": 6892, "price": 98, "quantity": 8000, "ts": 1756428492.175876, "side": "sell"}
{"type": "orderbook_delta", "seq": 6893, "price": 48, "quantity": 250, "ts": 1756428492.177117, "side": "sell"}
{"type": "orderbook_delta", "seq": 6894, "price": 38, "quantity": -250, "ts": 1756428492.17808, "side": "buy"}
{"type": "orderbook_delta", "seq": 6895, "price": 49, "quantity": 200, "ts": 1756428492.201904, "side": "sell"}
{"type": "orderbook_delta", "seq": 6896, "price": 54, "quantity": -100, "ts": 1756428492.205862, "side": "sell"}
{"type": "orderbook_delta", "seq": 6897, "price": 47, "quantity": 100, "ts": 1756428492.205862, "side": "sell"}
{"type": "orderbook_delta", "seq": 6898, "price": 49, "quantity": 1250, "ts": 1756428492.206469, "side": "sell"}
{"type": "orderbook_delta", "seq": 6899, "price": 28, "quantity": -250, "ts": 1756428492.274727, "side": "buy"}
{"type": "orderbook_delta", "seq": 6900, "price": 60, "quantity": -250, "ts": 1756428492.275755, "side": "sell"}
{"type": "orderbook_delta", "seq": 6901, "price": 38, "quantity": 250, "ts": 1756428492.277353, "side": "buy"}
{"type": "orderbook_delta", "seq": 6902, "price": 49, "quantity": -200, "ts": 1756428492.305256, "side": "sell"}
{"type": "orderbook_delta", "seq": 6903, "price": 45, "quantity": 969, "ts": 1756428492.32088, "side": "sell"}
{"type": "orderbook_delta", "seq": 6904, "price": 47, "quantity": 200, "ts": 1756428492.368759, "side": "sell"}
{"type": "orderbook_delta", "seq": 6905, "price": 49, "quantity": -1250, "ts": 1756428492.379297, "side": "sell"}
{"type": "orderbook_delta", "seq": 6906, "price": 36, "quantity": -200, "ts": 1756428492.379933, "side": "buy"}
{"type": "orderbook_delta", "seq": 6907, "price": 48, "quantity": 1250, "ts": 1756428492.432634, "side": "sell"}
{"type": "orderbook_delta", "seq": 6908, "price": 37, "quantity": -100, "ts": 1756428492.434673, "side": "buy"}
{"type": "orderbook_delta", "seq": 6909, "price": 38, "quantity": 100, "ts": 1756428492.434673, "side": "buy"}
{"type": "orderbook_delta", "seq": 6910, "price": 35, "quantity": 200, "ts": 1756428492.443245, "side": "buy"}
{"type": "orderbook_delta", "seq": 6911, "price": 38, "quantity": -100, "ts": 1756428493.192798, "side": "buy"}
{"type": "orderbook_delta", "seq": 6912, "price": 39, "quantity": 100, "ts": 1756428493.192798, "side": "buy"}
{"type": "orderbook_delta", "seq": 6913, "price": 47, "quantity": -100, "ts": 1756428493.719838, "side": "sell"}
{"type": "orderbook_delta", "seq": 6914, "price": 44, "quantity": 100, "ts": 1756428493.719838, "side": "sell"}
{"type": "orderbook_delta", "seq": 6915, "price": 44, "quantity": -100, "ts": 1756428493.839195, "side": "sell"}
{"type": "orderbook_delta", "seq": 6916, "price": 45, "quantity": 100, "ts": 1756428493.839195, "side": "sell"}
{"type": "orderbook_delta", "seq": 6917, "price": 35, "quantity": -200, "ts": 1756428494.164999, "side": "buy"}
{"type": "orderbook_delta", "seq": 6918, "price": 36, "quantity": 200, "ts": 1756428494.284016, "side": "buy"}
{"type": "orderbook_delta", "seq": 6919, "price": 39, "quantity": 100, "ts": 1756428494.642624, "side": "buy"}
{"type": "orderbook_delta", "seq": 6920, "price": 34, "quantity": -1250, "ts": 1756428494.708212, "side": "buy"}
{"type": "orderbook_delta", "seq": 6921, "price": 11, "quantity": -8000, "ts": 1756428494.709461, "side": "buy"}
{"type": "orderbook_delta", "seq": 6922, "price": 36, "quantity": -200, "ts": 1756428494.710535, "side": "buy"}
{"type": "orderbook_delta", "seq": 6923, "price": 10, "quantity": 8000, "ts": 1756428494.760579, "side": "buy"}
{"type": "orderbook_delta", "seq": 6924, "price": 35, "quantity": 200, "ts": 1756428494.761792, "side": "buy"}
{"type": "orderbook_delta", "seq": 6925, "price": 33, "quantity": 1250, "ts": 1756428494.764105, "side": "buy"}
{"type": "orderbook_delta", "seq": 6926, "price": 45, "quantity": -100, "ts": 1756428495.318639, "side": "sell"}
{"type": "orderbook_delta", "seq": 6927, "price": 44, "quantity": 100, "ts": 1756428495.318639, "side": "sell"}
{"type": "orderbook_delta", "seq": 6928, "price": 33, "quantity": -1250, "ts": 1756428496.137012, "side": "buy"}
{"type": "orderbook_delta", "seq": 6929, "price": 10, "quantity": -8000, "ts": 1756428496.137125, "side": "buy"}
{"type": "orderbook_delta", "seq": 6930, "price": 44, "quantity": -500, "ts": 1756428496.137173, "side": "sell"}
{"type": "orderbook_delta", "seq": 6931, "price": 38, "quantity": -500, "ts": 1756428496.137292, "side": "buy"}
{"type": "orderbook_delta", "seq": 6932, "price": 35, "quantity": -200, "ts": 1756428496.13774, "side": "buy"}
{"type": "orderbook_delta", "seq": 6933, "price": 48, "quantity": -1250, "ts": 1756428496.138134, "side": "sell"}
{"type": "orderbook_delta", "seq": 6934, "price": 45, "quantity": 500, "ts": 1756428496.186129, "side": "sell"}
{"type": "orderbook_delta", "seq": 6935, "price": 11, "quantity": 8000, "ts": 1756428496.187853, "side": "buy"}
{"type": "orderbook_delta", "seq": 6936, "price": 34, "quantity": 1250, "ts": 1756428496.18811, "side": "buy"}
{"type": "orderbook_delta", "seq": 6937, "price": 39, "quantity": 500, "ts": 1756428496.189559, "side": "buy"}
{"type": "orderbook_delta", "seq": 6938, "price": 36, "quantity": 200, "ts": 1756428496.189885, "side": "buy"}
{"type": "orderbook_delta", "seq": 6939, "price": 49, "quantity": 1250, "ts": 1756428496.190256, "side": "sell"}
{"type": "orderbook_delta", "seq": 6940, "price": 39, "quantity": -100, "ts": 1756428496.945077, "side": "buy"}
{"type": "orderbook_delta", "seq": 6941, "price": 38, "quantity": 100, "ts": 1756428496.945077, "side": "buy"}
{"type": "orderbook_delta", "seq": 6942, "price": 56, "quantity": -250, "ts": 1756428497.120083, "side": "sell"}
{"type": "orderbook_delta", "seq": 6943, "price": 46, "quantity": 250, "ts": 1756428497.121084, "side": "sell"}
{"type": "orderbook_delta", "seq": 6944, "price": 45, "quantity": -500, "ts": 1756428497.554266, "side": "sell"}
{"type": "orderbook_delta", "seq": 6945, "price": 39, "quantity": -500, "ts": 1756428497.554945, "side": "buy"}
{"type": "orderbook_delta", "seq": 6946, "price": 38, "quantity": 500, "ts": 1756428497.584222, "side": "buy"}
{"type": "orderbook_delta", "seq": 6947, "price": 44, "quantity": 500, "ts": 1756428497.585526, "side": "sell"}
{"type": "orderbook_delta", "seq": 6948, "price": 44, "quantity": -100, "ts": 1756428498.190738, "side": "sell"}
{"type": "orderbook_delta", "seq": 6949, "price": 45, "quantity": 100, "ts": 1756428498.190738, "side": "sell"}
{"type": "orderbook_delta", "seq": 6950, "price": 11, "quantity": -8000, "ts": 1756428498.937539, "side": "buy"}
{"type": "orderbook_delta", "seq": 6951, "price": 49, "quantity": -1250, "ts": 1756428498.93874, "side": "sell"}
{"type": "orderbook_delta", "seq": 6952, "price": 44, "quantity": -500, "ts": 1756428498.938799, "side": "sell"}
{"type": "orderbook_delta", "seq": 6953, "price": 36, "quantity": -200, "ts": 1756428498.941048, "side": "buy"}
{"type": "orderbook_delta", "seq": 6954, "price": 47, "quantity": -200, "ts": 1756428498.941205, "side": "sell"}
{"type": "orderbook_delta", "seq": 6955, "price": 34, "quantity": -1250, "ts": 1756428498.956365, "side": "buy"}
{"type": "orderbook_delta", "seq": 6956, "price": 38, "quantity": -500, "ts": 1756428498.961582, "side": "buy"}
{"type": "orderbook_delta", "seq": 6957, "price": 12, "quantity": 8000, "ts": 1756428499.044955, "side": "buy"}
{"type": "orderbook_delta", "seq": 6958, "price": 48, "quantity": 200, "ts": 1756428499.04605, "side": "sell"}
{"type": "orderbook_delta", "seq": 6959, "price": 39, "quantity": 500, "ts": 1756428499.04664, "side": "buy"}
{"type": "orderbook_delta", "seq": 6960, "price": 35, "quantity": 1250, "ts": 1756428499.046931, "side": "buy"}
{"type": "orderbook_delta", "seq": 6961, "price": 50, "quantity": 1250, "ts": 1756428499.047212, "side": "sell"}
{"type": "orderbook_delta", "seq": 6962, "price": 45, "quantity": 500, "ts": 1756428499.04745, "side": "sell"}
{"type": "orderbook_delta", "seq": 6963, "price": 37, "quantity": 200, "ts": 1756428499.048248, "side": "buy"}
{"type": "orderbook_delta", "seq": 6964, "price": 28, "quantity": 250, "ts": 1756428499.124433, "side": "buy"}
{"type": "orderbook_delta", "seq": 6965, "price": 45, "quantity": -969, "ts": 1756428499.126012, "side": "sell"}
{"type": "orderbook_delta", "seq": 6966, "price": 38, "quantity": -250, "ts": 1756428499.146581, "side": "buy"}
{"type": "orderbook_delta", "seq": 6967, "price": 44, "quantity": 969, "ts": 1756428499.192418, "side": "sell"}
{"type": "orderbook_delta", "seq": 6968, "price": 39, "quantity": -100, "ts": 1756428499.481124, "side": "buy"}
{"type": "orderbook_delta", "seq": 6969, "price": 45, "quantity": -100, "ts": 1756428499.689033, "side": "sell"}
{"type": "orderbook_delta", "seq": 6970, "price": 43, "quantity": 100, "ts": 1756428499.689033, "side": "sell"}
{"type": "orderbook_delta", "seq": 6971, "price": 40, "quantity": 100, "ts": 1756428499.706384, "side": "buy"}
{"type": "orderbook_delta", "seq": 6972, "price": 43, "quantity": -100, "ts": 1756428499.792618, "side": "sell"}
{"type": "orderbook_delta", "seq": 6973, "price": 44, "quantity": 100, "ts": 1756428499.792618, "side": "sell"}
{"type": "orderbook_delta", "seq": 6974, "price": 28, "quantity": -250, "ts": 1756428500.130972, "side": "buy"}
{"type": "orderbook_delta", "seq": 6975, "price": 38, "quantity": 250, "ts": 1756428500.143941, "side": "buy"}
{"type": "orderbook_delta", "seq": 6976, "price": 44, "quantity": -100, "ts": 1756428501.04957, "side": "sell"}
{"type": "orderbook_delta", "seq": 6977, "price": 45, "quantity": 100, "ts": 1756428501.04957, "side": "sell"}
{"type": "orderbook_delta", "seq": 6978, "price": 44, "quantity": -969, "ts": 1756428501.125315, "side": "sell"}
{"type": "orderbook_delta", "seq": 6979, "price": 45, "quantity": 969, "ts": 1756428501.226521, "side": "sell"}
{"type": "orderbook_delta", "seq": 6980, "price": 48, "quantity": -200, "ts": 1756428501.767088, "side": "sell"}
{"type": "orderbook_delta", "seq": 6981, "price": 39, "quantity": -500, "ts": 1756428501.767237, "side": "buy"}
{"type": "orderbook_delta", "seq": 6982, "price": 12, "quantity": -8000, "ts": 1756428501.768294, "side": "buy"}
{"type": "orderbook_delta", "seq": 6983, "price": 45, "quantity": -500, "ts": 1756428501.76878, "side": "sell"}
{"type": "orderbook_delta", "seq": 6984, "price": 35, "quantity": -1250, "ts": 1756428501.770008, "side": "buy"}
{"type": "orderbook_delta", "seq": 6985, "price": 50, "quantity": -1250, "ts": 1756428501.770302, "side": "sell"}
{"type": "orderbook_delta", "seq": 6986, "price": 37, "quantity": -200, "ts": 1756428501.770864, "side": "buy"}
{"type": "orderbook_delta", "seq": 6987, "price": 36, "quantity": 200, "ts": 1756428501.813496, "side": "buy"}
{"type": "orderbook_delta", "seq": 6988, "price": 11, "quantity": 8000, "ts": 1756428501.813848, "side": "buy"}
{"type": "orderbook_delta", "seq": 6989, "price": 38, "quantity": 500, "ts": 1756428501.814784, "side": "buy"}
{"type": "orderbook_delta", "seq": 6990, "price": 44, "quantity": 500, "ts": 1756428501.815425, "side": "sell"}
{"type": "orderbook_delta", "seq": 6991, "price": 34, "quantity": 1250, "ts": 1756428501.815818, "side": "buy"}
{"type": "orderbook_delta", "seq": 6992, "price": 47, "quantity": 200, "ts": 1756428501.816086, "side": "sell"}
{"type": "orderbook_delta", "seq": 6993, "price": 49, "quantity": 1250, "ts": 1756428501.817583, "side": "sell"}
{"type": "orderbook_delta", "seq": 6994, "price": 45, "quantity": -100, "ts": 1756428502.074507, "side": "sell"}
{"type": "orderbook_delta", "seq": 6995, "price": 46, "quantity": 100, "ts": 1756428502.074507, "side": "sell"}
{"type": "orderbook_delta", "seq": 6996, "price": 38, "quantity": -100, "ts": 1756428502.380183, "side": "buy"}
{"type": "orderbook_delta", "seq": 6997, "price": 39, "quantity": 100, "ts": 1756428502.380183, "side": "buy"}
{"type": "orderbook_delta", "seq": 6998, "price": 34, "quantity": -1250, "ts": 1756428503.260601, "side": "buy"}
{"type": "orderbook_delta", "seq": 6999, "price": 38, "quantity": -500, "ts": 1756428503.262362, "side": "buy"}
{"type": "orderbook_delta", "seq": 7000, "price": 44, "quantity": -500, "ts": 1756428503.262692, "side": "sell"}
{"type": "orderbook_delta", "seq": 7001, "price": 39, "quantity": 500, "ts": 1756428503.295141, "side": "buy"}
{"type": "orderbook_delta", "seq": 7002, "price": 35, "quantity": 1250, "ts": 1756428503.298602, "side": "buy"}
{"type": "orderbook_delta", "seq": 7003, "price": 45, "quantity": 500, "ts": 1756428503.305359, "side": "sell"}
{"type": "orderbook_delta", "seq": 7004, "price": 39, "quantity": -100, "ts": 1756428503.407411, "side": "buy"}
{"type": "orderbook_delta", "seq": 7005, "price": 40, "quantity": 100, "ts": 1756428503.407411, "side": "buy"}
{"type": "orderbook_delta", "seq": 7006, "price": 46, "quantity": -100, "ts": 1756428503.461579, "side": "sell"}
{"type": "orderbook_delta", "seq": 7007, "price": 45, "quantity": 100, "ts": 1756428503.461579, "side": "sell"}
{"type": "orderbook_delta", "seq": 7008, "price": 45, "quantity": -100, "ts": 1756428503.910332, "side": "sell"}
{"type": "orderbook_delta", "seq": 7009, "price": 46, "quantity": 100, "ts": 1756428503.910332, "side": "sell"}
{"type": "orderbook_delta", "seq": 7010, "price": 46, "quantity": -100, "ts": 1756428504.034016, "side": "sell"}
{"type": "orderbook_delta", "seq": 7011, "price": 47, "quantity": 100, "ts": 1756428504.034016, "side": "sell"}
{"type": "orderbook_delta", "seq": 7012, "price": 36, "quantity": -200, "ts": 1756428504.060892, "side": "buy"}
{"type": "orderbook_delta", "seq": 7013, "price": 11, "quantity": -8000, "ts": 1756428504.062845, "side": "buy"}
{"type": "orderbook_delta", "seq": 7014, "price": 47, "quantity": -200, "ts": 1756428504.064823, "side": "sell"}
{"type": "orderbook_delta", "seq": 7015, "price": 39, "quantity": -500, "ts": 1756428504.064964, "side": "buy"}
{"type": "orderbook_delta", "seq": 7016, "price": 45, "quantity": -500, "ts": 1756428504.065028, "side": "sell"}
{"type": "orderbook_delta", "seq": 7017, "price": 49, "quantity": -1250, "ts": 1756428504.090117, "side": "sell"}
{"type": "orderbook_delta", "seq": 7018, "price": 45, "quantity": -200, "ts": 1756428504.103987, "side": "sell"}
{"type": "orderbook_delta", "seq": 7019, "price": 47, "quantity": 200, "ts": 1756428504.103987, "side": "sell"}
{"type": "orderbook_delta", "seq": 7020, "price": 40, "quantity": -100, "ts": 1756428504.126195, "side": "buy"}
{"type": "orderbook_delta", "seq": 7021, "price": 39, "quantity": 100, "ts": 1756428504.126195, "side": "buy"}
{"type": "orderbook_delta", "seq": 7022, "price": 50, "quantity": 1250, "ts": 1756428504.126713, "side": "sell"}
{"type": "orderbook_delta", "seq": 7023, "price": 37, "quantity": 200, "ts": 1756428504.127474, "side": "buy"}
{"type": "orderbook_delta", "seq": 7024, "price": 40, "quantity": 500, "ts": 1756428504.127814, "side": "buy"}
{"type": "orderbook_delta", "seq": 7025, "price": 46, "quantity": 500, "ts": 1756428504.128655, "side": "sell"}
{"type": "orderbook_delta", "seq": 7026, "price": 48, "quantity": 200, "ts": 1756428504.129536, "side": "sell"}
{"type": "orderbook_delta", "seq": 7027, "price": 28, "quantity": 250, "ts": 1756428504.15606, "side": "buy"}
{"type": "orderbook_delta", "seq": 7028, "price": 38, "quantity": -250, "ts": 1756428504.156361, "side": "buy"}
{"type": "orderbook_delta", "seq": 7029, "price": 12, "quantity": 8000, "ts": 1756428504.16043, "side": "buy"}
{"type": "orderbook_delta", "seq": 7030, "price": 47, "quantity": -100, "ts": 1756428504.174791, "side": "sell"}
{"type": "orderbook_delta", "seq": 7031, "price": 49, "quantity": 100, "ts": 1756428504.174791, "side": "sell"}
{"type": "orderbook_delta", "seq": 7032, "price": 56, "quantity": 250, "ts": 1756428504.175479, "side": "sell"}
{"type": "orderbook_delta", "seq": 7033, "price": 46, "quantity": -250, "ts": 1756428504.176376, "side": "sell"}
{"type": "orderbook_delta", "seq": 7034, "price": 35, "quantity": -1250, "ts": 1756428504.387386, "side": "buy"}
{"type": "orderbook_delta", "seq": 7035, "price": 36, "quantity": 1250, "ts": 1756428504.430947, "side": "buy"}
{"type": "orderbook_delta", "seq": 7036, "price": 46, "quantity": -500, "ts": 1756428504.679922, "side": "sell"}
{"type": "orderbook_delta", "seq": 7037, "price": 36, "quantity": -1250, "ts": 1756428504.68127, "side": "buy"}
{"type": "orderbook_delta", "seq": 7038, "price": 40, "quantity": -500, "ts": 1756428504.682047, "side": "buy"}
{"type": "orderbook_delta", "seq": 7039, "price": 39, "quantity": 500, "ts": 1756428504.722774, "side": "buy"}
{"type": "orderbook_delta", "seq": 7040, "price": 35, "quantity": 1250, "ts": 1756428504.723073, "side": "buy"}
{"type": "orderbook_delta", "seq": 7041, "price": 45, "quantity": 500, "ts": 1756428504.728299, "side": "sell"}
{"type": "orderbook_delta", "seq": 7042, "price": 50, "quantity": -100, "ts": 1756428504.851086, "side": "sell"}
{"type": "orderbook_delta", "seq": 7043, "price": 39, "quantity": -100, "ts": 1756428504.88104, "side": "buy"}
{"type": "orderbook_delta", "seq": 7044, "price": 40, "quantity": 100, "ts": 1756428504.88104, "side": "buy"}
{"type": "orderbook_delta", "seq": 7045, "price": 39, "quantity": -500, "ts": 1756428504.926731, "side": "buy"}
{"type": "orderbook_delta", "seq": 7046, "price": 37, "quantity": 500, "ts": 1756428504.970142, "side": "buy"}
{"type": "orderbook_delta", "seq": 7047, "price": 43, "quantity": 100, "ts": 1756428505.058534, "side": "sell"}
{"type": "orderbook_delta", "seq": 7048, "price": 38, "quantity": 250, "ts": 1756428505.091106, "side": "buy"}
{"type": "orderbook_delta", "seq": 7049, "price": 28, "quantity": -250, "ts": 1756428505.091345, "side": "buy"}
{"type": "orderbook_delta", "seq": 7050, "price": 37, "quantity": -500, "ts": 1756428505.126582, "side": "buy"}
{"type": "orderbook_delta", "seq": 7051, "price": 39, "quantity": 500, "ts": 1756428505.164877, "side": "buy"}
{"type": "orderbook_delta", "seq": 7052, "price": 49, "quantity": -100, "ts": 1756428505.627984, "side": "sell"}
{"type": "orderbook_delta", "seq": 7053, "price": 46, "quantity": 100, "ts": 1756428505.627984, "side": "sell"}
{"type": "orderbook_delta", "seq": 7054, "price": 45, "quantity": -969, "ts": 1756428506.112092, "side": "sell"}
{"type": "orderbook_delta", "seq": 7055, "price": 12, "quantity": -8000, "ts": 1756428506.136192, "side": "buy"}
{"type": "orderbook_delta", "seq": 7056, "price": 50, "quantity": -1250, "ts": 1756428506.139847, "side": "sell"}
{"type": "orderbook_delta", "seq": 7057, "price": 46, "quantity": 969, "ts": 1756428506.152808, "side": "sell"}
{"type": "orderbook_delta", "seq": 7058, "price": 49, "quantity": 1250, "ts": 1756428506.17459, "side": "sell"}
{"type": "orderbook_delta", "seq": 7059, "price": 11, "quantity": 8000, "ts": 1756428506.254597, "side": "buy"}
{"type": "orderbook_delta", "seq": 7060, "price": 46, "quantity": -100, "ts": 1756428506.29087, "side": "sell"}
{"type": "orderbook_delta", "seq": 7061, "price": 48, "quantity": 100, "ts": 1756428506.29087, "side": "sell"}
{"type": "orderbook_delta", "seq": 7062, "price": 40, "quantity": -100, "ts": 1756428506.832296, "side": "buy"}
{"type": "orderbook_delta", "seq": 7063, "price": 39, "quantity": 100, "ts": 1756428506.832296, "side": "buy"}
{"type": "orderbook_delta", "seq": 7064, "price": 45, "quantity": -500, "ts": 1756428507.499272, "side": "sell"}
{"type": "orderbook_delta", "seq": 7065, "price": 11, "quantity": -8000, "ts": 1756428507.499972, "side": "buy"}
{"type": "orderbook_delta", "seq": 7066, "price": 39, "quantity": -500, "ts": 1756428507.500085, "side": "buy"}
{"type": "orderbook_delta", "seq": 7067, "price": 49, "quantity": -1250, "ts": 1756428507.500857, "side": "sell"}
{"type": "orderbook_delta", "seq": 7068, "price": 50, "quantity": 1250, "ts": 1756428507.538789, "side": "sell"}
{"type": "orderbook_delta", "seq": 7069, "price": 46, "quantity": 500, "ts": 1756428507.539054, "side": "sell"}
{"type": "orderbook_delta", "seq": 7070, "price": 40, "quantity": 500, "ts": 1756428507.539356, "side": "buy"}
{"type": "orderbook_delta", "seq": 7071, "price": 12, "quantity": 8000, "ts": 1756428507.541188, "side": "buy"}
{"type": "orderbook_delta", "seq": 7072, "price": 35, "quantity": -1250, "ts": 1756428507.855557, "side": "buy"}
{"type": "orderbook_delta", "seq": 7073, "price": 37, "quantity": -200, "ts": 1756428507.856612, "side": "buy"}
{"type": "orderbook_delta", "seq": 7074, "price": 50, "quantity": -1250, "ts": 1756428507.857203, "side": "sell"}
{"type": "orderbook_delta", "seq": 7075, "price": 48, "quantity": -200, "ts": 1756428507.858963, "side": "sell"}
{"type": "orderbook_delta", "seq": 7076, "price": 36, "quantity": 1250, "ts": 1756428507.892417, "side": "buy"}
{"type": "orderbook_delta", "seq": 7077, "price": 38, "quantity": 200, "ts": 1756428507.897974, "side": "buy"}
{"type": "orderbook_delta", "seq": 7078, "price": 51, "quantity": 1250, "ts": 1756428507.898572, "side": "sell"}
{"type": "orderbook_delta", "seq": 7079, "price": 49, "quantity": 200, "ts": 1756428507.90229, "side": "sell"}
{"type": "orderbook_delta", "seq": 7080, "price": 48, "quantity": -100, "ts": 1756428507.918396, "side": "sell"}
{"type": "orderbook_delta", "seq": 7081, "price": 49, "quantity": 100, "ts": 1756428507.918396, "side": "sell"}
{"type": "orderbook_delta", "seq": 7082, "price": 47, "quantity": -200, "ts": 1756428507.938058, "side": "sell"}
{"type": "orderbook_delta", "seq": 7083, "price": 49, "quantity": 200, "ts": 1756428507.938058, "side": "sell"}
{"type": "orderbook_delta", "seq": 7084, "price": 51, "quantity": -1250, "ts": 1756428508.030715, "side": "sell"}
{"type": "orderbook_delta", "seq": 7085, "price": 49, "quantity": -100, "ts": 1756428508.030795, "side": "sell"}
{"type": "orderbook_delta", "seq": 7086, "price": 50, "quantity": 100, "ts": 1756428508.030795, "side": "sell"}
{"type": "orderbook_delta", "seq": 7087, "price": 58, "quantity": 250, "ts": 1756428508.031043, "side": "sell"}
{"type": "orderbook_delta", "seq": 7088, "price": 49, "quantity": -200, "ts": 1756428508.031348, "side": "sell"}
{"type": "orderbook_delta", "seq": 7089, "price": 46, "quantity": -969, "ts": 1756428508.031417, "side": "sell"}
{"type": "orderbook_delta", "seq": 7090, "price": 38, "quantity": -200, "ts": 1756428508.031462, "side": "buy"}
{"type": "orderbook_delta", "seq": 7091, "price": 36, "quantity": -1250, "ts": 1756428508.031565, "side": "buy"}
