{"type": "orderbook_delta", "seq": 3549, "price": 37, "quantity": -90, "ts": 1756428332.200327, "side": "sell"}
{"type": "orderbook_delta", "seq": 3550, "price": 38, "quantity": 90, "ts": 1756428332.259122, "side": "sell"}
{"type": "orderbook_delta", "seq": 3551, "price": 39, "quantity": -500, "ts": 1756428332.297513, "side": "sell"}
{"type": "orderbook_delta", "seq": 3552, "price": 65, "quantity": -8000, "ts": 1756428332.306081, "side": "sell"}
{"type": "orderbook_delta", "seq": 3553, "price": 40, "quantity": -200, "ts": 1756428332.306451, "side": "sell"}
{"type": "orderbook_delta", "seq": 3554, "price": 28, "quantity": -1250, "ts": 1756428332.306918, "side": "buy"}
{"type": "orderbook_delta", "seq": 3555, "price": 42, "quantity": -1250, "ts": 1756428332.324387, "side": "sell"}
{"type": "orderbook_delta", "seq": 3556, "price": 39, "quantity": 500, "ts": 1756428332.330771, "side": "sell"}
{"type": "orderbook_delta", "seq": 3557, "price": 29, "quantity": -500, "ts": 1756428332.361707, "side": "buy"}
{"type": "orderbook_delta", "seq": 3558, "price": 36, "quantity": -200, "ts": 1756428332.374731, "side": "sell"}
{"type": "orderbook_delta", "seq": 3559, "price": 39, "quantity": 200, "ts": 1756428332.374731, "side": "sell"}
{"type": "orderbook_delta", "seq": 3560, "price": 29, "quantity": 1250, "ts": 1756428332.427985, "side": "buy"}
{"type": "orderbook_delta", "seq": 3561, "price": 42, "quantity": 200, "ts": 1756428332.428803, "side": "sell"}
{"type": "orderbook_delta", "seq": 3562, "price": 34, "quantity": 500, "ts": 1756428332.431986, "side": "buy"}
{"type": "orderbook_delta", "seq": 3563, "price": 44, "quantity": 1250, "ts": 1756428332.432256, "side": "sell"}
{"type": "orderbook_delta", "seq": 3564, "price": 66, "quantity": 8000, "ts": 1756428332.432485, "side": "sell"}
{"type": "orderbook_delta", "seq": 3565, "price": 22, "quantity": -250, "ts": 1756428333.016472, "side": "buy"}
{"type": "orderbook_delta", "seq": 3566, "price": 32, "quantity": 250, "ts": 1756428333.020591, "side": "buy"}
{"type": "orderbook_delta", "seq": 3567, "price": 38, "quantity": -90, "ts": 1756428333.029159, "side": "sell"}
{"type": "orderbook_delta", "seq": 3568, "price": 50, "quantity": 250, "ts": 1756428333.029442, "side": "sell"}
{"type": "orderbook_delta", "seq": 3569, "price": 34, "quantity": -500, "ts": 1756428333.045469, "side": "buy"}
{"type": "orderbook_delta", "seq": 3570, "price": 39, "quantity": -500, "ts": 1756428333.04552, "side": "sell"}
{"type": "orderbook_delta", "seq": 3571, "price": 66, "quantity": -8000, "ts": 1756428333.045565, "side": "sell"}
{"type": "orderbook_delta", "seq": 3572, "price": 44, "quantity": -1250, "ts": 1756428333.045991, "side": "sell"}
{"type": "orderbook_delta", "seq": 3573, "price": 39, "quantity": -200, "ts": 1756428333.047201, "side": "sell"}
{"type": "orderbook_delta", "seq": 3574, "price": 40, "quantity": 200, "ts": 1756428333.047201, "side": "sell"}
{"type": "orderbook_delta", "seq": 3575, "price": 30, "quantity": 250, "ts": 1756428333.047427, "side": "buy"}
{"type": "orderbook_delta", "seq": 3576, "price": 40, "quantity": -250, "ts": 1756428333.047679, "side": "sell"}
{"type": "orderbook_delta", "seq": 3577, "price": 42, "quantity": -200, "ts": 1756428333.047944, "side": "sell"}
{"type": "orderbook_delta", "seq": 3578, "price": 29, "quantity": -200, "ts": 1756428333.07026, "side": "buy"}
{"type": "orderbook_delta", "seq": 3579, "price": 29, "quantity": -1250, "ts": 1756428333.088529, "side": "buy"}
{"type": "orderbook_delta", "seq": 3580, "price": 40, "quantity": 90, "ts": 1756428333.09206, "side": "sell"}
{"type": "orderbook_delta", "seq": 3581, "price": 69, "quantity": 8000, "ts": 1756428333.09585, "side": "sell"}
{"type": "orderbook_delta", "seq": 3582, "price": 35, "quantity": 500, "ts": 1756428333.096991, "side": "buy"}
{"type": "orderbook_delta", "seq": 3583, "price": 40, "quantity": 500, "ts": 1756428333.099236, "side": "sell"}
{"type": "orderbook_delta", "seq": 3584, "price": 45, "quantity": 1250, "ts": 1756428333.101443, "side": "sell"}
{"type": "orderbook_delta", "seq": 3585, "price": 43, "quantity": 200, "ts": 1756428333.105298, "side": "sell"}
{"type": "orderbook_delta", "seq": 3586, "price": 22, "quantity": 250, "ts": 1756428333.106033, "side": "buy"}
{"type": "orderbook_delta", "seq": 3587, "price": 32, "quantity": 200, "ts": 1756428333.111996, "side": "buy"}
{"type": "orderbook_delta", "seq": 3588, "price": 32, "quantity": -250, "ts": 1756428333.114415, "side": "buy"}
{"type": "orderbook_delta", "seq": 3589, "price": 42, "quantity": -250, "ts": 1756428333.116776, "side": "sell"}
{"type": "orderbook_delta", "seq": 3590, "price": 30, "quantity": 1250, "ts": 1756428333.13108, "side": "buy"}
{"type": "orderbook_delta", "seq": 3591, "price": 52, "quantity": 250, "ts": 1756428333.221757, "side": "sell"}
{"type": "orderbook_delta", "seq": 3592, "price": 43, "quantity": -200, "ts": 1756428333.222018, "side": "sell"}
{"type": "orderbook_delta", "seq": 3593, "price": 32, "quantity": -200, "ts": 1756428333.222467, "side": "buy"}
{"type": "orderbook_delta", "seq": 3594, "price": 22, "quantity": -250, "ts": 1756428333.222906, "side": "buy"}
{"type": "orderbook_delta", "seq": 3595, "price": 30, "quantity": -1250, "ts": 1756428333.22494, "side": "buy"}
{"type": "orderbook_delta", "seq": 3596, "price": 40, "quantity": -500, "ts": 1756428333.22576, "side": "sell"}
{"type": "orderbook_delta", "seq": 3597, "price": 31, "quantity": 1250, "ts": 1756428333.259187, "side": "buy"}
{"type": "orderbook_delta", "seq": 3598, "price": 44, "quantity": 200, "ts": 1756428333.272109, "side": "sell"}
{"type": "orderbook_delta", "seq": 3599, "price": 43, "quantity": 500, "ts": 1756428333.278168, "side": "sell"}
{"type": "orderbook_delta", "seq": 3600, "price": 31, "quantity": 200, "ts": 1756428333.30614, "side": "buy"}
{"type": "trade", "seq": 40, "price": 35, "quantity": 75, "ts": 1756428333.404923, "side": "sell"}
{"type": "orderbook_delta", "seq": 3601, "price": 35, "quantity": 0, "ts": 1756428333.404923, "side": "buy"}
{"type": "orderbook_delta", "seq": 3602, "price": 24, "quantity": -250, "ts": 1756428334.019285, "side": "buy"}
{"type": "orderbook_delta", "seq": 3603, "price": 32, "quantity": 250, "ts": 1756428334.01977, "side": "buy"}
{"type": "orderbook_delta", "seq": 3604, "price": 34, "quantity": 250, "ts": 1756428334.037551, "side": "buy"}
{"type": "orderbook_delta", "seq": 3605, "price": 52, "quantity": -250, "ts": 1756428334.037816, "side": "sell"}
{"type": "orderbook_delta", "seq": 3606, "price": 31, "quantity": -200, "ts": 1756428334.05442, "side": "buy"}
{"type": "orderbook_delta", "seq": 3607, "price": 42, "quantity": 250, "ts": 1756428334.056927, "side": "sell"}
{"type": "orderbook_delta", "seq": 3608, "price": 33, "quantity": 200, "ts": 1756428334.085899, "side": "buy"}
{"type": "orderbook_delta", "seq": 3609, "price": 43, "quantity": -500, "ts": 1756428334.095051, "side": "sell"}
{"type": "orderbook_delta", "seq": 3610, "price": 40, "quantity": -90, "ts": 1756428334.105877, "side": "sell"}
{"type": "orderbook_delta", "seq": 3611, "price": 42, "quantity": -250, "ts": 1756428334.126116, "side": "sell"}
{"type": "orderbook_delta", "seq": 3612, "price": 41, "quantity": 500, "ts": 1756428334.129887, "side": "sell"}
{"type": "orderbook_delta", "seq": 3613, "price": 52, "quantity": 250, "ts": 1756428334.132098, "side": "sell"}
{"type": "orderbook_delta", "seq": 3614, "price": 41, "quantity": 90, "ts": 1756428334.185607, "side": "sell"}
{"type": "orderbook_delta", "seq": 3615, "price": 41, "quantity": -500, "ts": 1756428334.190466, "side": "sell"}
{"type": "orderbook_delta", "seq": 3616, "price": 43, "quantity": 500, "ts": 1756428334.243057, "side": "sell"}
{"type": "orderbook_delta", "seq": 3617, "price": 43, "quantity": -500, "ts": 1756428334.298499, "side": "sell"}
{"type": "orderbook_delta", "seq": 3618, "price": 34, "quantity": -250, "ts": 1756428334.31653, "side": "buy"}
{"type": "orderbook_delta", "seq": 3619, "price": 24, "quantity": 250, "ts": 1756428334.319812, "side": "buy"}
{"type": "orderbook_delta", "seq": 3620, "price": 31, "quantity": -1250, "ts": 1756428334.321593, "side": "buy"}
{"type": "orderbook_delta", "seq": 3621, "price": 33, "quantity": -200, "ts": 1756428334.325663, "side": "buy"}
{"type": "orderbook_delta", "seq": 3622, "price": 44, "quantity": -200, "ts": 1756428334.32583, "side": "sell"}
{"type": "orderbook_delta", "seq": 3623, "price": 35, "quantity": -500, "ts": 1756428334.326741, "side": "buy"}
{"type": "orderbook_delta", "seq": 3624, "price": 69, "quantity": -8000, "ts": 1756428334.326807, "side": "sell"}
{"type": "orderbook_delta", "seq": 3625, "price": 45, "quantity": -1250, "ts": 1756428334.327274, "side": "sell"}
{"type": "orderbook_delta", "seq": 3626, "price": 39, "quantity": 500, "ts": 1756428334.340135, "side": "sell"}
{"type": "orderbook_delta", "seq": 3627, "price": 30, "quantity": 200, "ts": 1756428334.368296, "side": "buy"}
{"type": "orderbook_delta", "seq": 3628, "price": 28, "quantity": 1250, "ts": 1756428334.370494, "side": "buy"}
{"type": "orderbook_delta", "seq": 3629, "price": 33, "quantity": 500, "ts": 1756428334.371182, "side": "buy"}
{"type": "orderbook_delta", "seq": 3630, "price": 43, "quantity": 200, "ts": 1756428334.371451, "side": "sell"}
{"type": "orderbook_delta", "seq": 3631, "price": 43, "quantity": 1250, "ts": 1756428334.372714, "side": "sell"}
{"type": "orderbook_delta", "seq": 3632, "price": 32, "quantity": -250, "ts": 1756428334.378756, "side": "buy"}
{"type": "orderbook_delta", "seq": 3633, "price": 22, "quantity": 250, "ts": 1756428334.387956, "side": "buy"}
{"type": "orderbook_delta", "seq": 3634, "price": 33, "quantity": -500, "ts": 1756428334.420622, "side": "buy"}
{"type": "orderbook_delta", "seq": 3635, "price": 65, "quantity": 8000, "ts": 1756428334.443271, "side": "sell"}
{"type": "orderbook_delta", "seq": 3636, "price": 32, "quantity": 500, "ts": 1756428334.465173, "side": "buy"}
{"type": "orderbook_delta", "seq": 3637, "price": 32, "quantity": -500, "ts": 1756428334.506922, "side": "buy"}
{"type": "orderbook_delta", "seq": 3638, "price": 40, "quantity": -200, "ts": 1756428334.537318, "side": "sell"}
{"type": "orderbook_delta", "seq": 3639, "price": 39, "quantity": 200, "ts": 1756428334.537318, "side": "sell"}
{"type": "orderbook_delta", "seq": 3640, "price": 31, "quantity": 500, "ts": 1756428334.549304, "side": "buy"}
{"type": "orderbook_delta", "seq": 3641, "price": 39, "quantity": -500, "ts": 1756428334.584926, "side": "sell"}
{"type": "orderbook_delta", "seq": 3642, "price": 38, "quantity": 500, "ts": 1756428334.620042, "side": "sell"}
{"type": "orderbook_delta", "seq": 3643, "price": 32, "quantity": 250, "ts": 1756428334.835113, "side": "buy"}
{"type": "orderbook_delta", "seq": 3644, "price": 22, "quantity": -250, "ts": 1756428334.835322, "side": "buy"}
{"type": "orderbook_delta", "seq": 3645, "price": 31, "quantity": -500, "ts": 1756428334.874903, "side": "buy"}
{"type": "orderbook_delta", "seq": 3646, "price": 32, "quantity": 500, "ts": 1756428334.911709, "side": "buy"}
{"type": "orderbook_delta", "seq": 3647, "price": 41, "quantity": -90, "ts": 1756428335.112726, "side": "sell"}
{"type": "orderbook_delta", "seq": 3648, "price": 39, "quantity": -200, "ts": 1756428335.117543, "side": "sell"}
{"type": "orderbook_delta", "seq": 3649, "price": 37, "quantity": 200, "ts": 1756428335.117543, "side": "sell"}
{"type": "orderbook_delta", "seq": 3650, "price": 40, "quantity": 250, "ts": 1756428335.136726, "side": "sell"}
{"type": "orderbook_delta", "seq": 3651, "price": 50, "quantity": -250, "ts": 1756428335.137219, "side": "sell"}
{"type": "orderbook_delta", "seq": 3652, "price": 42, "quantity": 250, "ts": 1756428335.155577, "side": "sell"}
{"type": "orderbook_delta", "seq": 3653, "price": 38, "quantity": -500, "ts": 1756428335.174399, "side": "sell"}
{"type": "orderbook_delta", "seq": 3654, "price": 52, "quantity": -250, "ts": 1756428335.176837, "side": "sell"}
{"type": "orderbook_delta", "seq": 3655, "price": 43, "quantity": -1250, "ts": 1756428335.190187, "side": "sell"}
{"type": "orderbook_delta", "seq": 3656, "price": 43, "quantity": -200, "ts": 1756428335.193775, "side": "sell"}
{"type": "orderbook_delta", "seq": 3657, "price": 39, "quantity": 90, "ts": 1756428335.22003, "side": "sell"}
{"type": "orderbook_delta", "seq": 3658, "price": 39, "quantity": 500, "ts": 1756428335.224877, "side": "sell"}
{"type": "orderbook_delta", "seq": 3659, "price": 42, "quantity": 1250, "ts": 1756428335.230237, "side": "sell"}
{"type": "orderbook_delta", "seq": 3660, "price": 41, "quantity": 200, "ts": 1756428335.231058, "side": "sell"}
{"type": "orderbook_delta", "seq": 3661, "price": 37, "quantity": -200, "ts": 1756428335.235852, "side": "sell"}
{"type": "orderbook_delta", "seq": 3662, "price": 39, "quantity": 200, "ts": 1756428335.235852, "side": "sell"}
{"type": "orderbook_delta", "seq": 3663, "price": 39, "quantity": -500, "ts": 1756428335.260438, "side": "sell"}
{"type": "orderbook_delta", "seq": 3664, "price": 39, "quantity": -200, "ts": 1756428335.289868, "side": "sell"}
{"type": "orderbook_delta", "seq": 3665, "price": 38, "quantity": 200, "ts": 1756428335.289868, "side": "sell"}
{"type": "orderbook_delta", "seq": 3666, "price": 38, "quantity": 500, "ts": 1756428335.30014, "side": "sell"}
{"type": "orderbook_delta", "seq": 3667, "price": 42, "quantity": -1250, "ts": 1756428335.441675, "side": "sell"}
{"type": "orderbook_delta", "seq": 3668, "price": 28, "quantity": -1250, "ts": 1756428335.443601, "side": "buy"}
{"type": "orderbook_delta", "seq": 3669, "price": 32, "quantity": -500, "ts": 1756428335.450639, "side": "buy"}
{"type": "orderbook_delta", "seq": 3670, "price": 29, "quantity": 1250, "ts": 1756428335.483076, "side": "buy"}
{"type": "orderbook_delta", "seq": 3671, "price": 43, "quantity": 1250, "ts": 1756428335.484638, "side": "sell"}
{"type": "orderbook_delta", "seq": 3672, "price": 38, "quantity": -200, "ts": 1756428335.662837, "side": "sell"}
{"type": "orderbook_delta", "seq": 3673, "price": 37, "quantity": 200, "ts": 1756428335.662837, "side": "sell"}
{"type": "orderbook_delta", "seq": 3674, "price": 33, "quantity": 500, "ts": 1756428335.663084, "side": "buy"}
{"type": "orderbook_delta", "seq": 3675, "price": 22, "quantity": 250, "ts": 1756428335.664654, "side": "buy"}
{"type": "orderbook_delta", "seq": 3676, "price": 32, "quantity": -250, "ts": 1756428335.664851, "side": "buy"}
{"type": "orderbook_delta", "seq": 3677, "price": 29, "quantity": -1250, "ts": 1756428335.665321, "side": "buy"}
{"type": "orderbook_delta", "seq": 3678, "price": 43, "quantity": -1250, "ts": 1756428335.666103, "side": "sell"}
{"type": "orderbook_delta", "seq": 3679, "price": 28, "quantity": 1250, "ts": 1756428335.709884, "side": "buy"}
{"type": "orderbook_delta", "seq": 3680, "price": 42, "quantity": 1250, "ts": 1756428335.710206, "side": "sell"}
{"type": "orderbook_delta", "seq": 3681, "price": 33, "quantity": -500, "ts": 1756428335.71051, "side": "buy"}
{"type": "orderbook_delta", "seq": 3682, "price": 31, "quantity": 500, "ts": 1756428335.764258, "side": "buy"}
{"type": "orderbook_delta", "seq": 3683, "price": 42, "quantity": -1250, "ts": 1756428335.847392, "side": "sell"}
{"type": "orderbook_delta", "seq": 3684, "price": 28, "quantity": -1250, "ts": 1756428335.855262, "side": "buy"}
{"type": "orderbook_delta", "seq": 3685, "price": 43, "quantity": 1250, "ts": 1756428335.893419, "side": "sell"}
{"type": "orderbook_delta", "seq": 3686, "price": 29, "quantity": 1250, "ts": 1756428335.894886, "side": "buy"}
{"type": "orderbook_delta", "seq": 3687, "price": 30, "quantity": -200, "ts": 1756428336.125586, "side": "buy"}
{"type": "orderbook_delta", "seq": 3688, "price": 41, "quantity": -200, "ts": 1756428336.126242, "side": "sell"}
{"type": "orderbook_delta", "seq": 3689, "price": 65, "quantity": -8000, "ts": 1756428336.12734, "side": "sell"}
{"type": "orderbook_delta", "seq": 3690, "price": 39, "quantity": -90, "ts": 1756428336.137416, "side": "sell"}
{"type": "orderbook_delta", "seq": 3691, "price": 38, "quantity": -500, "ts": 1756428336.161188, "side": "sell"}
{"type": "orderbook_delta", "seq": 3692, "price": 38, "quantity": 90, "ts": 1756428336.206536, "side": "sell"}
{"type": "orderbook_delta", "seq": 3693, "price": 66, "quantity": 8000, "ts": 1756428336.20942, "side": "sell"}
{"type": "orderbook_delta", "seq": 3694, "price": 31, "quantity": 200, "ts": 1756428336.211916, "side": "buy"}
{"type": "orderbook_delta", "seq": 3695, "price": 39, "quantity": 500, "ts": 1756428336.214773, "side": "sell"}
{"type": "orderbook_delta", "seq": 3696, "price": 42, "quantity": 200, "ts": 1756428336.230438, "side": "sell"}
{"type": "orderbook_delta", "seq": 3697, "price": 37, "quantity": -200, "ts": 1756428336.778419, "side": "sell"}
{"type": "orderbook_delta", "seq": 3698, "price": 38, "quantity": 200, "ts": 1756428336.778419, "side": "sell"}
{"type": "orderbook_delta", "seq": 3699, "price": 31, "quantity": -500, "ts": 1756428336.888512, "side": "buy"}
{"type": "orderbook_delta", "seq": 3700, "price": 39, "quantity": -500, "ts": 1756428336.889766, "side": "sell"}
{"type": "orderbook_delta", "seq": 3701, "price": 43, "quantity": -1250, "ts": 1756428336.889846, "side": "sell"}
{"type": "orderbook_delta", "seq": 3702, "price": 29, "quantity": -1250, "ts": 1756428336.890544, "side": "buy"}
{"type": "orderbook_delta", "seq": 3703, "price": 30, "quantity": 1250, "ts": 1756428336.933058, "side": "buy"}
{"type": "orderbook_delta", "seq": 3704, "price": 40, "quantity": 500, "ts": 1756428336.933405, "side": "sell"}
{"type": "orderbook_delta", "seq": 3705, "price": 34, "quantity": 500, "ts": 1756428336.933832, "side": "buy"}
{"type": "orderbook_delta", "seq": 3706, "price": 44, "quantity": 1250, "ts": 1756428336.989701, "side": "sell"}
{"type": "orderbook_delta", "seq": 3707, "price": 22, "quantity": -250, "ts": 1756428337.176676, "side": "buy"}
{"type": "orderbook_delta", "seq": 3708, "price": 32, "quantity": 250, "ts": 1756428337.196477, "side": "buy"}
{"type": "orderbook_delta", "seq": 3709, "price": 36, "quantity": 75, "ts": 1756428337.815136, "side": "sell"}
{"type": "orderbook_delta", "seq": 3710, "price": 32, "quantity": -250, "ts": 1756428337.85402, "side": "buy"}
{"type": "orderbook_delta", "seq": 3711, "price": 22, "quantity": 250, "ts": 1756428337.85897, "side": "buy"}
{"type": "orderbook_delta", "seq": 3712, "price": 31, "quantity": -200, "ts": 1756428337.861837, "side": "buy"}
{"type": "orderbook_delta", "seq": 3713, "price": 66, "quantity": -8000, "ts": 1756428337.862028, "side": "sell"}
{"type": "orderbook_delta", "seq": 3714, "price": 30, "quantity": -1250, "ts": 1756428337.862122, "side": "buy"}
{"type": "orderbook_delta", "seq": 3715, "price": 40, "quantity": -500, "ts": 1756428337.862714, "side": "sell"}
{"type": "orderbook_delta", "seq": 3716, "price": 34, "quantity": -500, "ts": 1756428337.862883, "side": "buy"}
{"type": "orderbook_delta", "seq": 3717, "price": 42, "quantity": -200, "ts": 1756428337.863982, "side": "sell"}
{"type": "orderbook_delta", "seq": 3718, "price": 44, "quantity": -1250, "ts": 1756428337.871385, "side": "sell"}
{"type": "orderbook_delta", "seq": 3719, "price": 38, "quantity": 500, "ts": 1756428337.939168, "side": "sell"}
{"type": "orderbook_delta", "seq": 3720, "price": 29, "quantity": 1250, "ts": 1756428337.939752, "side": "buy"}
{"type": "orderbook_delta", "seq": 3721, "price": 41, "quantity": 200, "ts": 1756428337.941368, "side": "sell"}
{"type": "orderbook_delta", "seq": 3722, "price": 65, "quantity": 8000, "ts": 1756428337.941817, "side": "sell"}
{"type": "orderbook_delta", "seq": 3723, "price": 30, "quantity": 200, "ts": 1756428337.94212, "side": "buy"}
{"type": "orderbook_delta", "seq": 3724, "price": 31, "quantity": 500, "ts": 1756428337.942904, "side": "buy"}
{"type": "orderbook_delta", "seq": 3725, "price": 43, "quantity": 1250, "ts": 1756428337.944113, "side": "sell"}
{"type": "orderbook_delta", "seq": 3726, "price": 38, "quantity": -500, "ts": 1756428338.008571, "side": "sell"}
{"type": "orderbook_delta", "seq": 3727, "price": 39, "quantity": 500, "ts": 1756428338.048441, "side": "sell"}
{"type": "orderbook_delta", "seq": 3728, "price": 39, "quantity": -500, "ts": 1756428338.284761, "side": "sell"}
{"type": "orderbook_delta", "seq": 3729, "price": 38, "quantity": 500, "ts": 1756428338.361178, "side": "sell"}
{"type": "orderbook_delta", "seq": 3730, "price": 65, "quantity": -8000, "ts": 1756428338.696406, "side": "sell"}
{"type": "orderbook_delta", "seq": 3731, "price": 30, "quantity": -200, "ts": 1756428338.698878, "side": "buy"}
{"type": "orderbook_delta", "seq": 3732, "price": 41, "quantity": -200, "ts": 1756428338.698968, "side": "sell"}
{"type": "orderbook_delta", "seq": 3733, "price": 31, "quantity": -500, "ts": 1756428338.700865, "side": "buy"}
{"type": "orderbook_delta", "seq": 3734, "price": 38, "quantity": -500, "ts": 1756428338.707302, "side": "sell"}
{"type": "orderbook_delta", "seq": 3735, "price": 75, "quantity": -100, "ts": 1756428338.73634, "side": "sell"}
{"type": "orderbook_delta", "seq": 3736, "price": 42, "quantity": 200, "ts": 1756428338.742204, "side": "sell"}
{"type": "orderbook_delta", "seq": 3737, "price": 34, "quantity": 500, "ts": 1756428338.742753, "side": "buy"}
{"type": "orderbook_delta", "seq": 3738, "price": 39, "quantity": 500, "ts": 1756428338.74489, "side": "sell"}
{"type": "orderbook_delta", "seq": 3739, "price": 66, "quantity": 8000, "ts": 1756428338.745926, "side": "sell"}
{"type": "orderbook_delta", "seq": 3740, "price": 31, "quantity": 200, "ts": 1756428338.747133, "side": "buy"}
{"type": "orderbook_delta", "seq": 3741, "price": 38, "quantity": -200, "ts": 1756428338.787483, "side": "sell"}
{"type": "orderbook_delta", "seq": 3742, "price": 66, "quantity": -8000, "ts": 1756428339.090318, "side": "sell"}
{"type": "orderbook_delta", "seq": 3743, "price": 31, "quantity": -200, "ts": 1756428339.092622, "side": "buy"}
{"type": "orderbook_delta", "seq": 3744, "price": 42, "quantity": -200, "ts": 1756428339.092756, "side": "sell"}
{"type": "orderbook_delta", "seq": 3745, "price": 39, "quantity": -500, "ts": 1756428339.094164, "side": "sell"}
{"type": "orderbook_delta", "seq": 3746, "price": 34, "quantity": -500, "ts": 1756428339.094225, "side": "buy"}
{"type": "orderbook_delta", "seq": 3747, "price": 38, "quantity": -90, "ts": 1756428339.120301, "side": "sell"}
{"type": "orderbook_delta", "seq": 3748, "price": 30, "quantity": 200, "ts": 1756428339.131325, "side": "buy"}
{"type": "orderbook_delta", "seq": 3749, "price": 65, "quantity": 8000, "ts": 1756428339.131651, "side": "sell"}
{"type": "orderbook_delta", "seq": 3750, "price": 31, "quantity": 500, "ts": 1756428339.131891, "side": "buy"}
{"type": "orderbook_delta", "seq": 3751, "price": 41, "quantity": 200, "ts": 1756428339.133128, "side": "sell"}
{"type": "orderbook_delta", "seq": 3752, "price": 38, "quantity": 500, "ts": 1756428339.142232, "side": "sell"}
{"type": "orderbook_delta", "seq": 3753, "price": 37, "quantity": 90, "ts": 1756428339.175037, "side": "sell"}
{"type": "orderbook_delta", "seq": 3754, "price": 38, "quantity": -500, "ts": 1756428339.182677, "side": "sell"}
{"type": "orderbook_delta", "seq": 3755, "price": 39, "quantity": 500, "ts": 1756428339.25092, "side": "sell"}
{"type": "orderbook_delta", "seq": 3756, "price": 29, "quantity": -1250, "ts": 1756428339.450507, "side": "buy"}
{"type": "orderbook_delta", "seq": 3757, "price": 43, "quantity": -1250, "ts": 1756428339.451065, "side": "sell"}
{"type": "orderbook_delta", "seq": 3758, "price": 42, "quantity": 1250, "ts": 1756428339.490635, "side": "sell"}
{"type": "orderbook_delta", "seq": 3759, "price": 28, "quantity": 1250, "ts": 1756428339.491314, "side": "buy"}
{"type": "orderbook_delta", "seq": 3760, "price": 42, "quantity": -1250, "ts": 1756428340.05695, "side": "sell"}
{"type": "orderbook_delta", "seq": 3761, "price": 39, "quantity": -500, "ts": 1756428340.057322, "side": "sell"}
{"type": "orderbook_delta", "seq": 3762, "price": 30, "quantity": -200, "ts": 1756428340.058634, "side": "buy"}
{"type": "orderbook_delta", "seq": 3763, "price": 41, "quantity": -200, "ts": 1756428340.058826, "side": "sell"}
{"type": "orderbook_delta", "seq": 3764, "price": 41, "quantity": 1250, "ts": 1756428340.244385, "side": "sell"}
{"type": "orderbook_delta", "seq": 3765, "price": 29, "quantity": 200, "ts": 1756428340.247255, "side": "buy"}
{"type": "orderbook_delta", "seq": 3766, "price": 40, "quantity": 200, "ts": 1756428340.247704, "side": "sell"}
{"type": "orderbook_delta", "seq": 3767, "price": 37, "quantity": 500, "ts": 1756428340.248157, "side": "sell"}
{"type": "orderbook_delta", "seq": 3768, "price": 40, "quantity": -200, "ts": 1756428340.595033, "side": "sell"}
{"type": "orderbook_delta", "seq": 3769, "price": 29, "quantity": -200, "ts": 1756428340.595295, "side": "buy"}
{"type": "orderbook_delta", "seq": 3770, "price": 28, "quantity": -1250, "ts": 1756428340.596085, "side": "buy"}
{"type": "orderbook_delta", "seq": 3771, "price": 39, "quantity": 200, "ts": 1756428340.705438, "side": "sell"}
{"type": "orderbook_delta", "seq": 3772, "price": 27, "quantity": 1250, "ts": 1756428340.708987, "side": "buy"}
{"type": "orderbook_delta", "seq": 3773, "price": 28, "quantity": 200, "ts": 1756428340.710053, "side": "buy"}
{"type": "orderbook_delta", "seq": 3774, "price": 39, "quantity": -200, "ts": 1756428340.884411, "side": "sell"}
{"type": "orderbook_delta", "seq": 3775, "price": 28, "quantity": -200, "ts": 1756428340.885287, "side": "buy"}
{"type": "orderbook_delta", "seq": 3776, "price": 29, "quantity": 200, "ts": 1756428340.945799, "side": "buy"}
{"type": "orderbook_delta", "seq": 3777, "price": 40, "quantity": 200, "ts": 1756428340.947642, "side": "sell"}
{"type": "orderbook_delta", "seq": 3778, "price": 20, "quantity": 250, "ts": 1756428341.185662, "side": "buy"}
{"type": "orderbook_delta", "seq": 3779, "price": 30, "quantity": -250, "ts": 1756428341.197113, "side": "buy"}
{"type": "orderbook_delta", "seq": 3780, "price": 36, "quantity": 0, "ts": 1756428341.230951, "side": "sell"}
{"type": "orderbook_delta", "seq": 3781, "price": 37, "quantity": 0, "ts": 1756428341.230951, "side": "sell"}
{"type": "orderbook_delta", "seq": 3782, "price": 37, "quantity": 0, "ts": 1756428341.230951, "side": "sell"}
{"type": "orderbook_delta", "seq": 3783, "price": 31, "quantity": -500, "ts": 1756428341.237134, "side": "buy"}
{"type": "trade", "seq": 41, "price": 36, "quantity": 75, "ts": 1756428341.237134, "side": "buy"}
{"type": "trade", "seq": 42, "price": 37, "quantity": 90, "ts": 1756428341.237134, "side": "buy"}
{"type": "trade", "seq": 43, "price": 37, "quantity": 22, "ts": 1756428341.275501, "side": "buy"}
{"type": "orderbook_delta", "seq": 3784, "price": 29, "quantity": 500, "ts": 1756428341.275501, "side": "buy"}
{"type": "orderbook_delta", "seq": 3785, "price": 37, "quantity": -478, "ts": 1756428341.285247, "side": "sell"}
{"type": "orderbook_delta", "seq": 3786, "price": 39, "quantity": 500, "ts": 1756428341.332744, "side": "sell"}
{"type": "orderbook_delta", "seq": 3787, "price": 48, "quantity": -250, "ts": 1756428342.114337, "side": "sell"}
{"type": "orderbook_delta", "seq": 3788, "price": 38, "quantity": 250, "ts": 1756428342.120575, "side": "sell"}
{"type": "orderbook_delta", "seq": 3789, "price": 39, "quantity": -500, "ts": 1756428342.151473, "side": "sell"}
{"type": "orderbook_delta", "seq": 3790, "price": 37, "quantity": 500, "ts": 1756428342.195578, "side": "sell"}
{"type": "orderbook_delta", "seq": 3791, "price": 41, "quantity": -1250, "ts": 1756428342.649991, "side": "sell"}
{"type": "orderbook_delta", "seq": 3792, "price": 27, "quantity": -1250, "ts": 1756428342.655896, "side": "buy"}
{"type": "orderbook_delta", "seq": 3793, "price": 42, "quantity": 1250, "ts": 1756428342.691692, "side": "sell"}
{"type": "orderbook_delta", "seq": 3794, "price": 28, "quantity": 1250, "ts": 1756428342.695247, "side": "buy"}
{"type": "orderbook_delta", "seq": 3795, "price": 35, "quantity": -25, "ts": 1756428343.19802, "side": "buy"}
{"type": "orderbook_delta", "seq": 3796, "price": 30, "quantity": 250, "ts": 1756428343.21734, "side": "buy"}
{"type": "orderbook_delta", "seq": 3797, "price": 20, "quantity": -250, "ts": 1756428343.217609, "side": "buy"}
{"type": "orderbook_delta", "seq": 3798, "price": 48, "quantity": 250, "ts": 1756428343.236857, "side": "sell"}
{"type": "orderbook_delta", "seq": 3799, "price": 38, "quantity": -250, "ts": 1756428343.237122, "side": "sell"}
{"type": "orderbook_delta", "seq": 3800, "price": 29, "quantity": -500, "ts": 1756428343.26985, "side": "buy"}
{"type": "orderbook_delta", "seq": 3801, "price": 37, "quantity": -500, "ts": 1756428343.277836, "side": "sell"}
{"type": "orderbook_delta", "seq": 3802, "price": 31, "quantity": 500, "ts": 1756428343.31176, "side": "buy"}
{"type": "orderbook_delta", "seq": 3803, "price": 39, "quantity": 500, "ts": 1756428343.314797, "side": "sell"}
{"type": "orderbook_delta", "seq": 3804, "price": 42, "quantity": -1250, "ts": 1756428344.349277, "side": "sell"}
{"type": "orderbook_delta", "seq": 3805, "price": 28, "quantity": -1250, "ts": 1756428344.349487, "side": "buy"}
{"type": "orderbook_delta", "seq": 3806, "price": 41, "quantity": 1250, "ts": 1756428344.39521, "side": "sell"}
{"type": "orderbook_delta", "seq": 3807, "price": 27, "quantity": 1250, "ts": 1756428344.399828, "side": "buy"}
{"type": "orderbook_delta", "seq": 3808, "price": 29, "quantity": -200, "ts": 1756428346.028787, "side": "buy"}
{"type": "orderbook_delta", "seq": 3809, "price": 40, "quantity": -200, "ts": 1756428346.030211, "side": "sell"}
{"type": "orderbook_delta", "seq": 3810, "price": 27, "quantity": -1250, "ts": 1756428346.031485, "side": "buy"}
{"type": "orderbook_delta", "seq": 3811, "price": 41, "quantity": -1250, "ts": 1756428346.032734, "side": "sell"}
{"type": "orderbook_delta", "seq": 3812, "price": 30, "quantity": 200, "ts": 1756428346.069599, "side": "buy"}
{"type": "orderbook_delta", "seq": 3813, "price": 43, "quantity": 1250, "ts": 1756428346.071499, "side": "sell"}
{"type": "orderbook_delta", "seq": 3814, "price": 29, "quantity": 1250, "ts": 1756428346.071798, "side": "buy"}
{"type": "orderbook_delta", "seq": 3815, "price": 41, "quantity": 200, "ts": 1756428346.075133, "side": "sell"}
{"type": "orderbook_delta", "seq": 3816, "price": 22, "quantity": -250, "ts": 1756428347.126011, "side": "buy"}
{"type": "orderbook_delta", "seq": 3817, "price": 32, "quantity": 250, "ts": 1756428347.126053, "side": "buy"}
{"type": "orderbook_delta", "seq": 3818, "price": 31, "quantity": -500, "ts": 1756428347.157317, "side": "buy"}
{"type": "orderbook_delta", "seq": 3819, "price": 50, "quantity": 250, "ts": 1756428347.166873, "side": "sell"}
{"type": "orderbook_delta", "seq": 3820, "price": 40, "quantity": -250, "ts": 1756428347.185395, "side": "sell"}
{"type": "orderbook_delta", "seq": 3821, "price": 33, "quantity": 500, "ts": 1756428347.209322, "side": "buy"}
{"type": "orderbook_delta", "seq": 3822, "price": 39, "quantity": -500, "ts": 1756428347.27222, "side": "sell"}
{"type": "orderbook_delta", "seq": 3823, "price": 24, "quantity": -250, "ts": 1756428347.307825, "side": "buy"}
{"type": "orderbook_delta", "seq": 3824, "price": 34, "quantity": 250, "ts": 1756428347.308512, "side": "buy"}
{"type": "orderbook_delta", "seq": 3825, "price": 41, "quantity": 500, "ts": 1756428347.391445, "side": "sell"}
{"type": "orderbook_delta", "seq": 3826, "price": 41, "quantity": -200, "ts": 1756428347.741222, "side": "sell"}
{"type": "orderbook_delta", "seq": 3827, "price": 30, "quantity": -200, "ts": 1756428347.74138, "side": "buy"}
{"type": "orderbook_delta", "seq": 3828, "price": 65, "quantity": -8000, "ts": 1756428347.742203, "side": "sell"}
{"type": "orderbook_delta", "seq": 3829, "price": 31, "quantity": 200, "ts": 1756428347.774556, "side": "buy"}
{"type": "orderbook_delta", "seq": 3830, "price": 42, "quantity": 200, "ts": 1756428347.775894, "side": "sell"}
{"type": "orderbook_delta", "seq": 3831, "price": 66, "quantity": 8000, "ts": 1756428347.79985, "side": "sell"}
{"type": "orderbook_delta", "seq": 3832, "price": 99, "quantity": 16200, "ts": 1756428348.032243, "side": "sell"}
{"type": "orderbook_delta", "seq": 3833, "price": 98, "quantity": 7000, "ts": 1756428348.60529, "side": "sell"}
{"type": "orderbook_delta", "seq": 3834, "price": 43, "quantity": -1250, "ts": 1756428348.61615, "side": "sell"}
{"type": "orderbook_delta", "seq": 3835, "price": 33, "quantity": -500, "ts": 1756428348.619638, "side": "buy"}
{"type": "orderbook_delta", "seq": 3836, "price": 34, "quantity": -250, "ts": 1756428348.626652, "side": "buy"}
{"type": "orderbook_delta", "seq": 3837, "price": 24, "quantity": 250, "ts": 1756428348.647341, "side": "buy"}
{"type": "orderbook_delta", "seq": 3838, "price": 44, "quantity": 1250, "ts": 1756428348.676774, "side": "sell"}
{"type": "orderbook_delta", "seq": 3839, "price": 34, "quantity": 500, "ts": 1756428348.684076, "side": "buy"}
{"type": "orderbook_delta", "seq": 3840, "price": 50, "quantity": -250, "ts": 1756428349.116291, "side": "sell"}
{"type": "orderbook_delta", "seq": 3841, "price": 40, "quantity": 250, "ts": 1756428349.117113, "side": "sell"}
{"type": "orderbook_delta", "seq": 3842, "price": 41, "quantity": -500, "ts": 1756428349.160196, "side": "sell"}
{"type": "orderbook_delta", "seq": 3843, "price": 39, "quantity": 500, "ts": 1756428349.198021, "side": "sell"}
{"type": "orderbook_delta", "seq": 3844, "price": 29, "quantity": -1250, "ts": 1756428349.223497, "side": "buy"}
{"type": "orderbook_delta", "seq": 3845, "price": 30, "quantity": 1250, "ts": 1756428349.29118, "side": "buy"}
{"type": "orderbook_delta", "seq": 3846, "price": 34, "quantity": -500, "ts": 1756428349.547437, "side": "buy"}
{"type": "orderbook_delta", "seq": 3847, "price": 39, "quantity": -500, "ts": 1756428349.5475, "side": "sell"}
{"type": "orderbook_delta", "seq": 3848, "price": 31, "quantity": -200, "ts": 1756428349.54783, "side": "buy"}
{"type": "orderbook_delta", "seq": 3849, "price": 44, "quantity": -1250, "ts": 1756428349.548052, "side": "sell"}
{"type": "orderbook_delta", "seq": 3850, "price": 42, "quantity": -200, "ts": 1756428349.548278, "side": "sell"}
{"type": "orderbook_delta", "seq": 3851, "price": 66, "quantity": -8000, "ts": 1756428349.548353, "side": "sell"}
{"type": "orderbook_delta", "seq": 3852, "price": 30, "quantity": -1250, "ts": 1756428349.638257, "side": "buy"}
{"type": "orderbook_delta", "seq": 3853, "price": 40, "quantity": -250, "ts": 1756428349.638288, "side": "sell"}
{"type": "orderbook_delta", "seq": 3854, "price": 50, "quantity": 250, "ts": 1756428349.638612, "side": "sell"}
{"type": "orderbook_delta", "seq": 3855, "price": 69, "quantity": 8000, "ts": 1756428349.715463, "side": "sell"}
{"type": "orderbook_delta", "seq": 3856, "price": 35, "quantity": 500, "ts": 1756428349.715769, "side": "buy"}
{"type": "orderbook_delta", "seq": 3857, "price": 42, "quantity": 500, "ts": 1756428349.716017, "side": "sell"}
{"type": "orderbook_delta", "seq": 3858, "price": 33, "quantity": 200, "ts": 1756428349.71624, "side": "buy"}
{"type": "orderbook_delta", "seq": 3859, "price": 46, "quantity": 1250, "ts": 1756428349.716463, "side": "sell"}
{"type": "orderbook_delta", "seq": 3860, "price": 52, "quantity": 250, "ts": 1756428349.716701, "side": "sell"}
{"type": "orderbook_delta", "seq": 3861, "price": 42, "quantity": -250, "ts": 1756428349.716888, "side": "sell"}
{"type": "orderbook_delta", "seq": 3862, "price": 44, "quantity": 200, "ts": 1756428349.717584, "side": "sell"}
{"type": "orderbook_delta", "seq": 3863, "price": 32, "quantity": 1250, "ts": 1756428349.720409, "side": "buy"}
{"type": "orderbook_delta", "seq": 3864, "price": 32, "quantity": -250, "ts": 1756428349.721467, "side": "buy"}
{"type": "orderbook_delta", "seq": 3865, "price": 22, "quantity": 250, "ts": 1756428349.721975, "side": "buy"}
{"type": "orderbook_delta", "seq": 3866, "price": 33, "quantity": -200, "ts": 1756428349.758425, "side": "buy"}
{"type": "orderbook_delta", "seq": 3867, "price": 42, "quantity": -500, "ts": 1756428349.759015, "side": "sell"}
{"type": "orderbook_delta", "seq": 3868, "price": 32, "quantity": -1250, "ts": 1756428349.759621, "side": "buy"}
{"type": "orderbook_delta", "seq": 3869, "price": 32, "quantity": 250, "ts": 1756428349.769306, "side": "buy"}
{"type": "orderbook_delta", "seq": 3870, "price": 22, "quantity": -250, "ts": 1756428349.769766, "side": "buy"}
{"type": "orderbook_delta", "seq": 3871, "price": 52, "quantity": -250, "ts": 1756428349.773111, "side": "sell"}
{"type": "orderbook_delta", "seq": 3872, "price": 43, "quantity": 500, "ts": 1756428349.803827, "side": "sell"}
{"type": "orderbook_delta", "seq": 3873, "price": 33, "quantity": 200, "ts": 1756428349.804781, "side": "buy"}
{"type": "orderbook_delta", "seq": 3874, "price": 32, "quantity": 1250, "ts": 1756428349.805118, "side": "buy"}
{"type": "orderbook_delta", "seq": 3875, "price": 42, "quantity": 250, "ts": 1756428349.863245, "side": "sell"}
{"type": "orderbook_delta", "seq": 3876, "price": 43, "quantity": -500, "ts": 1756428349.900797, "side": "sell"}
{"type": "orderbook_delta", "seq": 3877, "price": 42, "quantity": 500, "ts": 1756428350.025677, "side": "sell"}
{"type": "orderbook_delta", "seq": 3878, "price": 34, "quantity": 250, "ts": 1756428350.166145, "side": "buy"}
{"type": "orderbook_delta", "seq": 3879, "price": 24, "quantity": -250, "ts": 1756428350.1666, "side": "buy"}
{"type": "orderbook_delta", "seq": 3880, "price": 52, "quantity": 250, "ts": 1756428350.186194, "side": "sell"}
{"type": "orderbook_delta", "seq": 3881, "price": 42, "quantity": -250, "ts": 1756428350.186445, "side": "sell"}
{"type": "orderbook_delta", "seq": 3882, "price": 42, "quantity": -500, "ts": 1756428350.282634, "side": "sell"}
{"type": "orderbook_delta", "seq": 3883, "price": 43, "quantity": 500, "ts": 1756428350.33137, "side": "sell"}
{"type": "orderbook_delta", "seq": 3884, "price": 33, "quantity": -200, "ts": 1756428350.561653, "side": "buy"}
{"type": "orderbook_delta", "seq": 3885, "price": 46, "quantity": -1250, "ts": 1756428350.567223, "side": "sell"}
{"type": "orderbook_delta", "seq": 3886, "price": 44, "quantity": -200, "ts": 1756428350.568705, "side": "sell"}
{"type": "orderbook_delta", "seq": 3887, "price": 69, "quantity": -8000, "ts": 1756428350.571216, "side": "sell"}
{"type": "orderbook_delta", "seq": 3888, "price": 32, "quantity": -1250, "ts": 1756428350.58001, "side": "buy"}
{"type": "orderbook_delta", "seq": 3889, "price": 45, "quantity": 200, "ts": 1756428350.605551, "side": "sell"}
{"type": "orderbook_delta", "seq": 3890, "price": 34, "quantity": 200, "ts": 1756428350.608094, "side": "buy"}
{"type": "orderbook_delta", "seq": 3891, "price": 33, "quantity": 1250, "ts": 1756428350.619842, "side": "buy"}
{"type": "orderbook_delta", "seq": 3892, "price": 70, "quantity": 8000, "ts": 1756428350.705003, "side": "sell"}
{"type": "orderbook_delta", "seq": 3893, "price": 47, "quantity": 1250, "ts": 1756428350.950807, "side": "sell"}
{"type": "orderbook_delta", "seq": 3894, "price": 36, "quantity": 250, "ts": 1756428351.100428, "side": "buy"}
{"type": "orderbook_delta", "seq": 3895, "price": 26, "quantity": -250, "ts": 1756428351.107612, "side": "buy"}
{"type": "orderbook_delta", "seq": 3896, "price": 35, "quantity": -500, "ts": 1756428351.14, "side": "buy"}
{"type": "orderbook_delta", "seq": 3897, "price": 34, "quantity": -200, "ts": 1756428351.180918, "side": "buy"}
{"type": "orderbook_delta", "seq": 3898, "price": 47, "quantity": -1250, "ts": 1756428351.184766, "side": "sell"}
{"type": "orderbook_delta", "seq": 3899, "price": 70, "quantity": -8000, "ts": 1756428351.185189, "side": "sell"}
{"type": "orderbook_delta", "seq": 3900, "price": 37, "quantity": 500, "ts": 1756428351.189609, "side": "buy"}
{"type": "orderbook_delta", "seq": 3901, "price": 45, "quantity": -200, "ts": 1756428351.190344, "side": "sell"}
{"type": "orderbook_delta", "seq": 3902, "price": 34, "quantity": 200, "ts": 1756428351.227811, "side": "buy"}
{"type": "orderbook_delta", "seq": 3903, "price": 47, "quantity": 1250, "ts": 1756428351.228728, "side": "sell"}
{"type": "orderbook_delta", "seq": 3904, "price": 45, "quantity": 200, "ts": 1756428351.23108, "side": "sell"}
{"type": "orderbook_delta", "seq": 3905, "price": 70, "quantity": 8000, "ts": 1756428351.23226, "side": "sell"}
{"type": "orderbook_delta", "seq": 3906, "price": 47, "quantity": -1250, "ts": 1756428352.884948, "side": "sell"}
{"type": "orderbook_delta", "seq": 3907, "price": 70, "quantity": -8000, "ts": 1756428352.886659, "side": "sell"}
{"type": "orderbook_delta", "seq": 3908, "price": 45, "quantity": -200, "ts": 1756428352.886927, "side": "sell"}
{"type": "orderbook_delta", "seq": 3909, "price": 34, "quantity": -200, "ts": 1756428352.89008, "side": "buy"}
{"type": "orderbook_delta", "seq": 3910, "price": 98, "quantity": 8000, "ts": 1756428352.924767, "side": "sell"}
{"type": "orderbook_delta", "seq": 3911, "price": 46, "quantity": 200, "ts": 1756428352.925839, "side": "sell"}
{"type": "orderbook_delta", "seq": 3912, "price": 35, "quantity": 200, "ts": 1756428352.928874, "side": "buy"}
{"type": "orderbook_delta", "seq": 3913, "price": 48, "quantity": 1250, "ts": 1756428352.936678, "side": "sell"}
{"type": "orderbook_delta", "seq": 3914, "price": 38, "quantity": 100, "ts": 1756428353.017392, "side": "buy"}
{"type": "orderbook_delta", "seq": 3915, "price": 54, "quantity": 250, "ts": 1756428353.099155, "side": "sell"}
{"type": "orderbook_delta", "seq": 3916, "price": 44, "quantity": -250, "ts": 1756428353.116408, "side": "sell"}
{"type": "orderbook_delta", "seq": 3917, "price": 37, "quantity": -500, "ts": 1756428353.149305, "side": "buy"}
{"type": "orderbook_delta", "seq": 3918, "price": 43, "quantity": -500, "ts": 1756428353.153296, "side": "sell"}
{"type": "orderbook_delta", "seq": 3919, "price": 45, "quantity": 500, "ts": 1756428353.186986, "side": "sell"}
{"type": "orderbook_delta", "seq": 3920, "price": 38, "quantity": 500, "ts": 1756428353.187777, "side": "buy"}
{"type": "orderbook_delta", "seq": 3921, "price": 66, "quantity": 50, "ts": 1756428354.12324, "side": "sell"}
{"type": "orderbook_delta", "seq": 3922, "price": 35, "quantity": -200, "ts": 1756428354.128932, "side": "buy"}
{"type": "orderbook_delta", "seq": 3923, "price": 12, "quantity": 8000, "ts": 1756428354.129008, "side": "buy"}
{"type": "orderbook_delta", "seq": 3924, "price": 33, "quantity": -1250, "ts": 1756428354.129285, "side": "buy"}
{"type": "orderbook_delta", "seq": 3925, "price": 46, "quantity": -200, "ts": 1756428354.129379, "side": "sell"}
{"type": "orderbook_delta", "seq": 3926, "price": 48, "quantity": -1250, "ts": 1756428354.129425, "side": "sell"}
{"type": "orderbook_delta", "seq": 3927, "price": 38, "quantity": -500, "ts": 1756428354.129515, "side": "buy"}
{"type": "orderbook_delta", "seq": 3928, "price": 28, "quantity": -250, "ts": 1756428354.147547, "side": "buy"}
{"type": "orderbook_delta", "seq": 3929, "price": 38, "quantity": 250, "ts": 1756428354.147756, "side": "buy"}
{"type": "orderbook_delta", "seq": 3930, "price": 36, "quantity": 200, "ts": 1756428354.17066, "side": "buy"}
{"type": "orderbook_delta", "seq": 3931, "price": 47, "quantity": 200, "ts": 1756428354.172503, "side": "sell"}
{"type": "orderbook_delta", "seq": 3932, "price": 35, "quantity": 1250, "ts": 1756428354.17613, "side": "buy"}
{"type": "orderbook_delta", "seq": 3933, "price": 49, "quantity": 1250, "ts": 1756428354.18, "side": "sell"}
{"type": "orderbook_delta", "seq": 3934, "price": 45, "quantity": -500, "ts": 1756428354.189072, "side": "sell"}
{"type": "orderbook_delta", "seq": 3935, "price": 47, "quantity": -200, "ts": 1756428354.204369, "side": "sell"}
{"type": "orderbook_delta", "seq": 3936, "price": 36, "quantity": -200, "ts": 1756428354.208007, "side": "buy"}
{"type": "orderbook_delta", "seq": 3937, "price": 49, "quantity": -1250, "ts": 1756428354.220324, "side": "sell"}
{"type": "orderbook_delta", "seq": 3938, "price": 35, "quantity": -1250, "ts": 1756428354.220693, "side": "buy"}
{"type": "orderbook_delta", "seq": 3939, "price": 46, "quantity": 500, "ts": 1756428354.224932, "side": "sell"}
{"type": "orderbook_delta", "seq": 3940, "price": 56, "quantity": 250, "ts": 1756428354.228537, "side": "sell"}
{"type": "orderbook_delta", "seq": 3941, "price": 46, "quantity": -250, "ts": 1756428354.229176, "side": "sell"}
{"type": "orderbook_delta", "seq": 3942, "price": 48, "quantity": 200, "ts": 1756428354.250191, "side": "sell"}
{"type": "orderbook_delta", "seq": 3943, "price": 37, "quantity": 200, "ts": 1756428354.250579, "side": "buy"}
{"type": "orderbook_delta", "seq": 3944, "price": 50, "quantity": 1250, "ts": 1756428354.269172, "side": "sell"}
{"type": "orderbook_delta", "seq": 3945, "price": 46, "quantity": -500, "ts": 1756428354.270095, "side": "sell"}
{"type": "orderbook_delta", "seq": 3946, "price": 36, "quantity": 1250, "ts": 1756428354.271704, "side": "buy"}
{"type": "orderbook_delta", "seq": 3947, "price": 39, "quantity": 500, "ts": 1756428354.28179, "side": "buy"}
{"type": "orderbook_delta", "seq": 3948, "price": 56, "quantity": -250, "ts": 1756428354.317342, "side": "sell"}
{"type": "orderbook_delta", "seq": 3949, "price": 46, "quantity": 250, "ts": 1756428354.320022, "side": "sell"}
{"type": "orderbook_delta", "seq": 3950, "price": 47, "quantity": 500, "ts": 1756428354.320673, "side": "sell"}
{"type": "orderbook_delta", "seq": 3951, "price": 47, "quantity": -500, "ts": 1756428354.351869, "side": "sell"}
{"type": "orderbook_delta", "seq": 3952, "price": 46, "quantity": 500, "ts": 1756428354.389767, "side": "sell"}
{"type": "orderbook_delta", "seq": 3953, "price": 36, "quantity": -1250, "ts": 1756428354.599486, "side": "buy"}
{"type": "orderbook_delta", "seq": 3954, "price": 35, "quantity": 1250, "ts": 1756428354.643951, "side": "buy"}
{"type": "orderbook_delta", "seq": 3955, "price": 35, "quantity": -1250, "ts": 1756428354.810028, "side": "buy"}
{"type": "orderbook_delta", "seq": 3956, "price": 36, "quantity": 1250, "ts": 1756428354.845363, "side": "buy"}
{"type": "orderbook_delta", "seq": 3957, "price": 48, "quantity": -200, "ts": 1756428355.030192, "side": "sell"}
{"type": "orderbook_delta", "seq": 3958, "price": 36, "quantity": -1250, "ts": 1756428355.031484, "side": "buy"}
{"type": "orderbook_delta", "seq": 3959, "price": 50, "quantity": -1250, "ts": 1756428355.031677, "side": "sell"}
{"type": "orderbook_delta", "seq": 3960, "price": 37, "quantity": -200, "ts": 1756428355.032298, "side": "buy"}
{"type": "orderbook_delta", "seq": 3961, "price": 46, "quantity": -500, "ts": 1756428355.036988, "side": "sell"}
{"type": "orderbook_delta", "seq": 3962, "price": 37, "quantity": 1250, "ts": 1756428355.075644, "side": "buy"}
{"type": "orderbook_delta", "seq": 3963, "price": 50, "quantity": 200, "ts": 1756428355.077662, "side": "sell"}
{"type": "orderbook_delta", "seq": 3964, "price": 47, "quantity": 500, "ts": 1756428355.079546, "side": "sell"}
{"type": "orderbook_delta", "seq": 3965, "price": 10, "quantity": 200, "ts": 1756428355.081608, "side": "buy"}
{"type": "orderbook_delta", "seq": 3966, "price": 39, "quantity": 200, "ts": 1756428355.08187, "side": "buy"}
{"type": "orderbook_delta", "seq": 3967, "price": 51, "quantity": 1250, "ts": 1756428355.133106, "side": "sell"}
{"type": "orderbook_delta", "seq": 3968, "price": 30, "quantity": -250, "ts": 1756428355.21435, "side": "buy"}
{"type": "orderbook_delta", "seq": 3969, "price": 40, "quantity": 250, "ts": 1756428355.214575, "side": "buy"}
{"type": "orderbook_delta", "seq": 3970, "price": 39, "quantity": -200, "ts": 1756428355.217216, "side": "buy"}
{"type": "orderbook_delta", "seq": 3971, "price": 50, "quantity": -200, "ts": 1756428355.299123, "side": "sell"}
{"type": "orderbook_delta", "seq": 3972, "price": 46, "quantity": -250, "ts": 1756428355.300326, "side": "sell"}
{"type": "orderbook_delta", "seq": 3973, "price": 56, "quantity": 250, "ts": 1756428355.300354, "side": "sell"}
{"type": "orderbook_delta", "seq": 3974, "price": 39, "quantity": -500, "ts": 1756428355.301166, "side": "buy"}
{"type": "orderbook_delta", "seq": 3975, "price": 49, "quantity": 200, "ts": 1756428355.342394, "side": "sell"}
{"type": "orderbook_delta", "seq": 3976, "price": 38, "quantity": 200, "ts": 1756428355.34271, "side": "buy"}
{"type": "orderbook_delta", "seq": 3977, "price": 41, "quantity": 500, "ts": 1756428355.345667, "side": "buy"}
{"type": "orderbook_delta", "seq": 3978, "price": 41, "quantity": 0, "ts": 1756428355.615651, "side": "buy"}
{"type": "trade", "seq": 44, "price": 41, "quantity": 141, "ts": 1756428355.684867, "side": "sell"}
{"type": "orderbook_delta", "seq": 3979, "price": 58, "quantity": 250, "ts": 1756428355.684867, "side": "sell"}
{"type": "orderbook_delta", "seq": 3980, "price": 49, "quantity": -200, "ts": 1756428355.690521, "side": "sell"}
{"type": "orderbook_delta", "seq": 3981, "price": 47, "quantity": -500, "ts": 1756428355.691446, "side": "sell"}
{"type": "orderbook_delta", "seq": 3982, "price": 38, "quantity": -200, "ts": 1756428355.691514, "side": "buy"}
{"type": "orderbook_delta", "seq": 3983, "price": 48, "quantity": -250, "ts": 1756428355.696545, "side": "sell"}
{"type": "orderbook_delta", "seq": 3984, "price": 51, "quantity": -1250, "ts": 1756428355.718025, "side": "sell"}
{"type": "orderbook_delta", "seq": 3985, "price": 39, "quantity": 200, "ts": 1756428355.759058, "side": "buy"}
{"type": "orderbook_delta", "seq": 3986, "price": 52, "quantity": 1250, "ts": 1756428355.7601, "side": "sell"}
{"type": "orderbook_delta", "seq": 3987, "price": 50, "quantity": 200, "ts": 1756428355.768296, "side": "sell"}
{"type": "orderbook_delta", "seq": 3988, "price": 49, "quantity": 500, "ts": 1756428355.768574, "side": "sell"}
{"type": "orderbook_delta", "seq": 3989, "price": 38, "quantity": -100, "ts": 1756428355.890739, "side": "buy"}
{"type": "orderbook_delta", "seq": 3990, "price": 50, "quantity": -200, "ts": 1756428356.054342, "side": "sell"}
{"type": "orderbook_delta", "seq": 3991, "price": 39, "quantity": -200, "ts": 1756428356.055598, "side": "buy"}
{"type": "orderbook_delta", "seq": 3992, "price": 37, "quantity": -1250, "ts": 1756428356.056077, "side": "buy"}
{"type": "orderbook_delta", "seq": 3993, "price": 52, "quantity": -1250, "ts": 1756428356.087874, "side": "sell"}
{"type": "orderbook_delta", "seq": 3994, "price": 40, "quantity": 100, "ts": 1756428356.098767, "side": "buy"}
{"type": "orderbook_delta", "seq": 3995, "price": 38, "quantity": 1250, "ts": 1756428356.129719, "side": "buy"}
{"type": "orderbook_delta", "seq": 3996, "price": 40, "quantity": 200, "ts": 1756428356.130893, "side": "buy"}
{"type": "orderbook_delta", "seq": 3997, "price": 51, "quantity": 200, "ts": 1756428356.133169, "side": "sell"}
{"type": "orderbook_delta", "seq": 3998, "price": 53, "quantity": 1250, "ts": 1756428356.134657, "side": "sell"}
{"type": "orderbook_delta", "seq": 3999, "price": 38, "quantity": -1250, "ts": 1756428356.236911, "side": "buy"}
{"type": "orderbook_delta", "seq": 4000, "price": 40, "quantity": -200, "ts": 1756428356.237044, "side": "buy"}
{"type": "orderbook_delta", "seq": 4001, "price": 51, "quantity": -200, "ts": 1756428356.238971, "side": "sell"}
{"type": "orderbook_delta", "seq": 4002, "price": 53, "quantity": -1250, "ts": 1756428356.241651, "side": "sell"}
{"type": "orderbook_delta", "seq": 4003, "price": 38, "quantity": 1250, "ts": 1756428356.282489, "side": "buy"}
{"type": "orderbook_delta", "seq": 4004, "price": 51, "quantity": 200, "ts": 1756428356.284184, "side": "sell"}
{"type": "orderbook_delta", "seq": 4005, "price": 40, "quantity": 200, "ts": 1756428356.284487, "side": "buy"}
{"type": "orderbook_delta", "seq": 4006, "price": 53, "quantity": 1250, "ts": 1756428356.288482, "side": "sell"}
{"type": "orderbook_delta", "seq": 4007, "price": 60, "quantity": 250, "ts": 1756428356.527345, "side": "sell"}
{"type": "orderbook_delta", "seq": 4008, "price": 50, "quantity": -250, "ts": 1756428356.528247, "side": "sell"}
{"type": "orderbook_delta", "seq": 4009, "price": 40, "quantity": -200, "ts": 1756428356.540615, "side": "buy"}
{"type": "orderbook_delta", "seq": 4010, "price": 53, "quantity": -1250, "ts": 1756428356.541818, "side": "sell"}
{"type": "orderbook_delta", "seq": 4011, "price": 38, "quantity": -1250, "ts": 1756428356.542411, "side": "buy"}
{"type": "orderbook_delta", "seq": 4012, "price": 51, "quantity": -200, "ts": 1756428356.545113, "side": "sell"}
{"type": "orderbook_delta", "seq": 4013, "price": 49, "quantity": -500, "ts": 1756428356.581503, "side": "sell"}
{"type": "orderbook_delta", "seq": 4014, "price": 54, "quantity": 1250, "ts": 1756428356.591973, "side": "sell"}
{"type": "orderbook_delta", "seq": 4015, "price": 41, "quantity": 200, "ts": 1756428356.593682, "side": "buy"}
{"type": "orderbook_delta", "seq": 4016, "price": 39, "quantity": 1250, "ts": 1756428356.597031, "side": "buy"}
{"type": "orderbook_delta", "seq": 4017, "price": 52, "quantity": 200, "ts": 1756428356.597336, "side": "sell"}
{"type": "orderbook_delta", "seq": 4018, "price": 62, "quantity": 250, "ts": 1756428356.61598, "side": "sell"}
{"type": "orderbook_delta", "seq": 4019, "price": 52, "quantity": -250, "ts": 1756428356.618497, "side": "sell"}
{"type": "orderbook_delta", "seq": 4020, "price": 51, "quantity": 500, "ts": 1756428356.632544, "side": "sell"}
{"type": "orderbook_delta", "seq": 4021, "price": 52, "quantity": -200, "ts": 1756428356.647778, "side": "sell"}
{"type": "orderbook_delta", "seq": 4022, "price": 62, "quantity": -250, "ts": 1756428356.678481, "side": "sell"}
{"type": "orderbook_delta", "seq": 4023, "price": 51, "quantity": -500, "ts": 1756428356.67883, "side": "sell"}
{"type": "orderbook_delta", "seq": 4024, "price": 52, "quantity": 250, "ts": 1756428356.67919, "side": "sell"}
{"type": "orderbook_delta", "seq": 4025, "price": 53, "quantity": 200, "ts": 1756428356.690531, "side": "sell"}
{"type": "orderbook_delta", "seq": 4026, "price": 51, "quantity": 500, "ts": 1756428356.717547, "side": "sell"}
{"type": "orderbook_delta", "seq": 4027, "price": 53, "quantity": -200, "ts": 1756428356.732153, "side": "sell"}
{"type": "orderbook_delta", "seq": 4028, "price": 52, "quantity": 200, "ts": 1756428356.785095, "side": "sell"}
{"type": "orderbook_delta", "seq": 4029, "price": 32, "quantity": -250, "ts": 1756428357.156882, "side": "buy"}
{"type": "orderbook_delta", "seq": 4030, "price": 42, "quantity": 250, "ts": 1756428357.158267, "side": "buy"}
{"type": "orderbook_delta", "seq": 4031, "price": 41, "quantity": -359, "ts": 1756428357.191476, "side": "buy"}
{"type": "orderbook_delta", "seq": 4032, "price": 43, "quantity": 500, "ts": 1756428357.228528, "side": "buy"}
{"type": "orderbook_delta", "seq": 4033, "price": 34, "quantity": -250, "ts": 1756428357.267427, "side": "buy"}
{"type": "orderbook_delta", "seq": 4034, "price": 44, "quantity": 250, "ts": 1756428357.27448, "side": "buy"}
{"type": "orderbook_delta", "seq": 4035, "price": 41, "quantity": -200, "ts": 1756428358.000843, "side": "buy"}
{"type": "orderbook_delta", "seq": 4036, "price": 39, "quantity": -1250, "ts": 1756428358.001189, "side": "buy"}
{"type": "orderbook_delta", "seq": 4037, "price": 52, "quantity": -200, "ts": 1756428358.001362, "side": "sell"}
{"type": "orderbook_delta", "seq": 4038, "price": 43, "quantity": -500, "ts": 1756428358.001671, "side": "buy"}
{"type": "orderbook_delta", "seq": 4039, "price": 54, "quantity": -1250, "ts": 1756428358.006814, "side": "sell"}
{"type": "orderbook_delta", "seq": 4040, "price": 40, "quantity": 1250, "ts": 1756428358.048091, "side": "buy"}
{"type": "orderbook_delta", "seq": 4041, "price": 44, "quantity": 500, "ts": 1756428358.048324, "side": "buy"}
{"type": "orderbook_delta", "seq": 4042, "price": 53, "quantity": 200, "ts": 1756428358.050841, "side": "sell"}
{"type": "orderbook_delta", "seq": 4043, "price": 55, "quantity": 1250, "ts": 1756428358.052212, "side": "sell"}
{"type": "orderbook_delta", "seq": 4044, "price": 42, "quantity": 200, "ts": 1756428358.055707, "side": "buy"}
{"type": "orderbook_delta", "seq": 4045, "price": 44, "quantity": -500, "ts": 1756428359.722581, "side": "buy"}
{"type": "orderbook_delta", "seq": 4046, "price": 55, "quantity": -1250, "ts": 1756428359.72365, "side": "sell"}
{"type": "orderbook_delta", "seq": 4047, "price": 42, "quantity": -200, "ts": 1756428359.726443, "side": "buy"}
{"type": "orderbook_delta", "seq": 4048, "price": 53, "quantity": -200, "ts": 1756428359.738384, "side": "sell"}
{"type": "orderbook_delta", "seq": 4049, "price": 40, "quantity": -1250, "ts": 1756428359.75548, "side": "buy"}
{"type": "orderbook_delta", "seq": 4050, "price": 43, "quantity": 500, "ts": 1756428359.872619, "side": "buy"}
{"type": "orderbook_delta", "seq": 4051, "price": 41, "quantity": 200, "ts": 1756428359.873206, "side": "buy"}
{"type": "orderbook_delta", "seq": 4052, "price": 54, "quantity": 1250, "ts": 1756428359.873792, "side": "sell"}
{"type": "orderbook_delta", "seq": 4053, "price": 52, "quantity": 200, "ts": 1756428359.875731, "side": "sell"}
{"type": "orderbook_delta", "seq": 4054, "price": 39, "quantity": 1250, "ts": 1756428359.876539, "side": "buy"}
{"type": "orderbook_delta", "seq": 4055, "price": 34, "quantity": 250, "ts": 1756428360.139649, "side": "buy"}
{"type": "orderbook_delta", "seq": 4056, "price": 44, "quantity": -250, "ts": 1756428360.14663, "side": "buy"}
{"type": "orderbook_delta", "seq": 4057, "price": 43, "quantity": -500, "ts": 1756428360.164031, "side": "buy"}
{"type": "orderbook_delta", "seq": 4058, "price": 52, "quantity": -250, "ts": 1756428360.190179, "side": "sell"}
{"type": "orderbook_delta", "seq": 4059, "price": 43, "quantity": 500, "ts": 1756428360.193006, "side": "buy"}
{"type": "orderbook_delta", "seq": 4060, "price": 62, "quantity": 250, "ts": 1756428360.201211, "side": "sell"}
{"type": "orderbook_delta", "seq": 4061, "price": 39, "quantity": -1250, "ts": 1756428360.202224, "side": "buy"}
{"type": "orderbook_delta", "seq": 4062, "price": 54, "quantity": -1250, "ts": 1756428360.203542, "side": "sell"}
{"type": "orderbook_delta", "seq": 4063, "price": 51, "quantity": -500, "ts": 1756428360.203676, "side": "sell"}
{"type": "orderbook_delta", "seq": 4064, "price": 41, "quantity": -200, "ts": 1756428360.20521, "side": "buy"}
{"type": "orderbook_delta", "seq": 4065, "price": 52, "quantity": -200, "ts": 1756428360.209139, "side": "sell"}
{"type": "orderbook_delta", "seq": 4066, "price": 40, "quantity": -100, "ts": 1756428360.217219, "side": "buy"}
{"type": "orderbook_delta", "seq": 4067, "price": 10, "quantity": -200, "ts": 1756428360.230527, "side": "buy"}
{"type": "orderbook_delta", "seq": 4068, "price": 20, "quantity": 200, "ts": 1756428360.230527, "side": "buy"}
{"type": "orderbook_delta", "seq": 4069, "price": 56, "quantity": 1250, "ts": 1756428360.242992, "side": "sell"}
{"type": "orderbook_delta", "seq": 4070, "price": 54, "quantity": 200, "ts": 1756428360.249704, "side": "sell"}
{"type": "orderbook_delta", "seq": 4071, "price": 53, "quantity": 500, "ts": 1756428360.250017, "side": "sell"}
{"type": "orderbook_delta", "seq": 4072, "price": 41, "quantity": 1250, "ts": 1756428360.25061, "side": "buy"}
{"type": "orderbook_delta", "seq": 4073, "price": 43, "quantity": 200, "ts": 1756428360.251075, "side": "buy"}
{"type": "orderbook_delta", "seq": 4074, "price": 54, "quantity": -250, "ts": 1756428360.251939, "side": "sell"}
{"type": "orderbook_delta", "seq": 4075, "price": 64, "quantity": 250, "ts": 1756428360.255242, "side": "sell"}
{"type": "orderbook_delta", "seq": 4076, "price": 70, "quantity": -200, "ts": 1756428360.261413, "side": "sell"}
{"type": "orderbook_delta", "seq": 4077, "price": 80, "quantity": 200, "ts": 1756428360.261413, "side": "sell"}
{"type": "orderbook_delta", "seq": 4078, "price": 98, "quantity": -8000, "ts": 1756428360.288459, "side": "sell"}
{"type": "orderbook_delta", "seq": 4079, "price": 53, "quantity": -500, "ts": 1756428360.290148, "side": "sell"}
{"type": "orderbook_delta", "seq": 4080, "price": 64, "quantity": -250, "ts": 1756428360.299201, "side": "sell"}
{"type": "orderbook_delta", "seq": 4081, "price": 54, "quantity": -200, "ts": 1756428360.319179, "side": "sell"}
{"type": "orderbook_delta", "seq": 4082, "price": 55, "quantity": 200, "ts": 1756428360.36558, "side": "sell"}
{"type": "orderbook_delta", "seq": 4083, "price": 55, "quantity": 500, "ts": 1756428360.366861, "side": "sell"}
{"type": "orderbook_delta", "seq": 4084, "price": 80, "quantity": 8000, "ts": 1756428360.367581, "side": "sell"}
{"type": "orderbook_delta", "seq": 4085, "price": 45, "quantity": 100, "ts": 1756428360.423424, "side": "buy"}
{"type": "orderbook_delta", "seq": 4086, "price": 43, "quantity": -500, "ts": 1756428360.452162, "side": "buy"}
{"type": "orderbook_delta", "seq": 4087, "price": 46, "quantity": 500, "ts": 1756428360.564157, "side": "buy"}
{"type": "orderbook_delta", "seq": 4088, "price": 41, "quantity": -1250, "ts": 1756428360.706056, "side": "buy"}
{"type": "orderbook_delta", "seq": 4089, "price": 42, "quantity": 1250, "ts": 1756428360.751001, "side": "buy"}
{"type": "orderbook_delta", "seq": 4090, "price": 34, "quantity": -250, "ts": 1756428361.127453, "side": "buy"}
{"type": "orderbook_delta", "seq": 4091, "price": 46, "quantity": 250, "ts": 1756428361.146467, "side": "buy"}
{"type": "orderbook_delta", "seq": 4092, "price": 42, "quantity": -1250, "ts": 1756428361.168465, "side": "buy"}
{"type": "orderbook_delta", "seq": 4093, "price": 44, "quantity": 250, "ts": 1756428361.186414, "side": "buy"}
{"type": "orderbook_delta", "seq": 4094, "price": 36, "quantity": -250, "ts": 1756428361.187276, "side": "buy"}
{"type": "orderbook_delta", "seq": 4095, "price": 50, "quantity": 100, "ts": 1756428361.199243, "side": "sell"}
{"type": "orderbook_delta", "seq": 4096, "price": 41, "quantity": 1250, "ts": 1756428361.217251, "side": "buy"}
{"type": "orderbook_delta", "seq": 4097, "price": 54, "quantity": 200, "ts": 1756428361.599215, "side": "sell"}
{"type": "orderbook_delta", "seq": 4098, "price": 55, "quantity": -500, "ts": 1756428361.650787, "side": "sell"}
{"type": "orderbook_delta", "seq": 4099, "price": 55, "quantity": -200, "ts": 1756428361.739363, "side": "sell"}
{"type": "orderbook_delta", "seq": 4100, "price": 54, "quantity": 200, "ts": 1756428361.775329, "side": "sell"}
{"type": "orderbook_delta", "seq": 4101, "price": 53, "quantity": 500, "ts": 1756428361.779578, "side": "sell"}
{"type": "orderbook_delta", "seq": 4102, "price": 54, "quantity": -200, "ts": 1756428363.005214, "side": "sell"}
{"type": "orderbook_delta", "seq": 4103, "price": 43, "quantity": -200, "ts": 1756428363.007463, "side": "buy"}
{"type": "orderbook_delta", "seq": 4104, "price": 56, "quantity": -1250, "ts": 1756428363.009065, "side": "sell"}
{"type": "orderbook_delta", "seq": 4105, "price": 41, "quantity": -1250, "ts": 1756428363.009128, "side": "buy"}
{"type": "orderbook_delta", "seq": 4106, "price": 42, "quantity": 1250, "ts": 1756428363.045562, "side": "buy"}
{"type": "orderbook_delta", "seq": 4107, "price": 57, "quantity": 1250, "ts": 1756428363.046039, "side": "sell"}
{"type": "orderbook_delta", "seq": 4108, "price": 54, "quantity": -200, "ts": 1756428363.04777, "side": "sell"}
{"type": "orderbook_delta", "seq": 4109, "price": 55, "quantity": 200, "ts": 1756428363.049041, "side": "sell"}
{"type": "orderbook_delta", "seq": 4110, "price": 44, "quantity": 200, "ts": 1756428363.057354, "side": "buy"}
{"type": "orderbook_delta", "seq": 4111, "price": 53, "quantity": -500, "ts": 1756428363.082807, "side": "sell"}
{"type": "orderbook_delta", "seq": 4112, "price": 55, "quantity": 500, "ts": 1756428363.128786, "side": "sell"}
{"type": "orderbook_delta", "seq": 4113, "price": 46, "quantity": -250, "ts": 1756428363.142117, "side": "buy"}
{"type": "orderbook_delta", "seq": 4114, "price": 36, "quantity": 250, "ts": 1756428363.144264, "side": "buy"}
{"type": "orderbook_delta", "seq": 4115, "price": 64, "quantity": 250, "ts": 1756428363.156742, "side": "sell"}
{"type": "orderbook_delta", "seq": 4116, "price": 80, "quantity": -8000, "ts": 1756428363.630382, "side": "sell"}
{"type": "orderbook_delta", "seq": 4117, "price": 98, "quantity": 8000, "ts": 1756428363.66829, "side": "sell"}
{"type": "orderbook_delta", "seq": 4118, "price": 44, "quantity": -200, "ts": 1756428363.732293, "side": "buy"}
{"type": "orderbook_delta", "seq": 4119, "price": 57, "quantity": -1250, "ts": 1756428363.737951, "side": "sell"}
{"type": "orderbook_delta", "seq": 4120, "price": 55, "quantity": -200, "ts": 1756428363.742552, "side": "sell"}
{"type": "orderbook_delta", "seq": 4121, "price": 42, "quantity": -1250, "ts": 1756428363.75821, "side": "buy"}
{"type": "orderbook_delta", "seq": 4122, "price": 56, "quantity": 200, "ts": 1756428363.858947, "side": "sell"}
{"type": "orderbook_delta", "seq": 4123, "price": 45, "quantity": 200, "ts": 1756428363.85973, "side": "buy"}
{"type": "orderbook_delta", "seq": 4124, "price": 58, "quantity": 1250, "ts": 1756428363.860043, "side": "sell"}
{"type": "orderbook_delta", "seq": 4125, "price": 43, "quantity": 1250, "ts": 1756428363.860544, "side": "buy"}
{"type": "orderbook_delta", "seq": 4126, "price": 45, "quantity": -100, "ts": 1756428363.911215, "side": "buy"}
{"type": "orderbook_delta", "seq": 4127, "price": 43, "quantity": -1250, "ts": 1756428363.925023, "side": "buy"}
{"type": "orderbook_delta", "seq": 4128, "price": 56, "quantity": -200, "ts": 1756428363.926697, "side": "sell"}
{"type": "orderbook_delta", "seq": 4129, "price": 46, "quantity": -500, "ts": 1756428363.946634, "side": "buy"}
{"type": "orderbook_delta", "seq": 4130, "price": 12, "quantity": -8000, "ts": 1756428363.947442, "side": "buy"}
{"type": "orderbook_delta", "seq": 4131, "price": 58, "quantity": -1250, "ts": 1756428363.971665, "side": "sell"}
{"type": "orderbook_delta", "seq": 4132, "price": 44, "quantity": -250, "ts": 1756428363.99629, "side": "buy"}
{"type": "orderbook_delta", "seq": 4133, "price": 45, "quantity": 500, "ts": 1756428364.000709, "side": "buy"}
{"type": "orderbook_delta", "seq": 4134, "price": 34, "quantity": 250, "ts": 1756428364.002081, "side": "buy"}
{"type": "orderbook_delta", "seq": 4135, "price": 45, "quantity": -200, "ts": 1756428364.032156, "side": "buy"}
{"type": "orderbook_delta", "seq": 4136, "price": 45, "quantity": -500, "ts": 1756428364.038638, "side": "buy"}
{"type": "orderbook_delta", "seq": 4137, "price": 43, "quantity": 1250, "ts": 1756428364.061186, "side": "buy"}
{"type": "orderbook_delta", "seq": 4138, "price": 59, "quantity": 1250, "ts": 1756428364.062552, "side": "sell"}
{"type": "orderbook_delta", "seq": 4139, "price": 57, "quantity": 200, "ts": 1756428364.062839, "side": "sell"}
{"type": "orderbook_delta", "seq": 4140, "price": 21, "quantity": 8000, "ts": 1756428364.067939, "side": "buy"}
{"type": "orderbook_delta", "seq": 4141, "price": 43, "quantity": 200, "ts": 1756428364.068281, "side": "buy"}
{"type": "orderbook_delta", "seq": 4142, "price": 43, "quantity": 500, "ts": 1756428364.094444, "side": "buy"}
{"type": "orderbook_delta", "seq": 4143, "price": 46, "quantity": 250, "ts": 1756428364.167033, "side": "buy"}
{"type": "orderbook_delta", "seq": 4144, "price": 36, "quantity": -250, "ts": 1756428364.167284, "side": "buy"}
{"type": "orderbook_delta", "seq": 4145, "price": 21, "quantity": -8000, "ts": 1756428364.189116, "side": "buy"}
{"type": "orderbook_delta", "seq": 4146, "price": 46, "quantity": 100, "ts": 1756428364.206659, "side": "buy"}
{"type": "orderbook_delta", "seq": 4147, "price": 44, "quantity": 250, "ts": 1756428364.207188, "side": "buy"}
{"type": "orderbook_delta", "seq": 4148, "price": 20, "quantity": 8000, "ts": 1756428364.225584, "side": "buy"}
{"type": "orderbook_delta", "seq": 4149, "price": 66, "quantity": 250, "ts": 1756428364.226604, "side": "sell"}
{"type": "orderbook_delta", "seq": 4150, "price": 43, "quantity": -500, "ts": 1756428364.285692, "side": "buy"}
{"type": "orderbook_delta", "seq": 4151, "price": 43, "quantity": -200, "ts": 1756428364.286559, "side": "buy"}
{"type": "orderbook_delta", "seq": 4152, "price": 34, "quantity": -250, "ts": 1756428364.287211, "side": "buy"}
{"type": "orderbook_delta", "seq": 4153, "price": 43, "quantity": -1250, "ts": 1756428364.290055, "side": "buy"}
{"type": "orderbook_delta", "seq": 4154, "price": 47, "quantity": 500, "ts": 1756428364.324957, "side": "buy"}
{"type": "orderbook_delta", "seq": 4155, "price": 46, "quantity": 200, "ts": 1756428364.325671, "side": "buy"}
{"type": "orderbook_delta", "seq": 4156, "price": 56, "quantity": -250, "ts": 1756428364.327435, "side": "sell"}
{"type": "orderbook_delta", "seq": 4157, "price": 44, "quantity": 1250, "ts": 1756428364.331119, "side": "buy"}
{"type": "orderbook_delta", "seq": 4158, "price": 38, "quantity": -250, "ts": 1756428364.373035, "side": "buy"}
{"type": "orderbook_delta", "seq": 4159, "price": 48, "quantity": 250, "ts": 1756428364.373275, "side": "buy"}
{"type": "orderbook_delta", "seq": 4160, "price": 55, "quantity": -500, "ts": 1756428364.392554, "side": "sell"}
{"type": "orderbook_delta", "seq": 4161, "price": 47, "quantity": -500, "ts": 1756428364.407081, "side": "buy"}
{"type": "orderbook_delta", "seq": 4162, "price": 46, "quantity": -200, "ts": 1756428364.417215, "side": "buy"}
{"type": "orderbook_delta", "seq": 4163, "price": 59, "quantity": -1250, "ts": 1756428364.418306, "side": "sell"}
{"type": "orderbook_delta", "seq": 4164, "price": 20, "quantity": -8000, "ts": 1756428364.419639, "side": "buy"}
{"type": "orderbook_delta", "seq": 4165, "price": 57, "quantity": 500, "ts": 1756428364.421852, "side": "sell"}
{"type": "orderbook_delta", "seq": 4166, "price": 44, "quantity": -1250, "ts": 1756428364.422545, "side": "buy"}
{"type": "orderbook_delta", "seq": 4167, "price": 57, "quantity": -200, "ts": 1756428364.43145, "side": "sell"}
{"type": "orderbook_delta", "seq": 4168, "price": 49, "quantity": 500, "ts": 1756428364.448621, "side": "buy"}
{"type": "orderbook_delta", "seq": 4169, "price": 47, "quantity": 200, "ts": 1756428364.480025, "side": "buy"}
{"type": "orderbook_delta", "seq": 4170, "price": 21, "quantity": 8000, "ts": 1756428364.481246, "side": "buy"}
{"type": "orderbook_delta", "seq": 4171, "price": 45, "quantity": 1250, "ts": 1756428364.481529, "side": "buy"}
{"type": "orderbook_delta", "seq": 4172, "price": 58, "quantity": 200, "ts": 1756428364.483965, "side": "sell"}
{"type": "orderbook_delta", "seq": 4173, "price": 60, "quantity": 1250, "ts": 1756428364.486376, "side": "sell"}
{"type": "orderbook_delta", "seq": 4174, "price": 47, "quantity": -200, "ts": 1756428364.679388, "side": "buy"}
{"type": "orderbook_delta", "seq": 4175, "price": 58, "quantity": -200, "ts": 1756428364.679891, "side": "sell"}
{"type": "orderbook_delta", "seq": 4176, "price": 45, "quantity": -1250, "ts": 1756428364.68454, "side": "buy"}
{"type": "orderbook_delta", "seq": 4177, "price": 60, "quantity": -1250, "ts": 1756428364.694441, "side": "sell"}
{"type": "orderbook_delta", "seq": 4178, "price": 57, "quantity": 200, "ts": 1756428364.734702, "side": "sell"}
{"type": "orderbook_delta", "seq": 4179, "price": 46, "quantity": 200, "ts": 1756428364.738952, "side": "buy"}
{"type": "orderbook_delta", "seq": 4180, "price": 44, "quantity": 1250, "ts": 1756428364.740592, "side": "buy"}
{"type": "orderbook_delta", "seq": 4181, "price": 59, "quantity": 1250, "ts": 1756428364.787852, "side": "sell"}
{"type": "orderbook_delta", "seq": 4182, "price": 44, "quantity": -1250, "ts": 1756428365.062339, "side": "buy"}
{"type": "orderbook_delta", "seq": 4183, "price": 57, "quantity": -200, "ts": 1756428365.062486, "side": "sell"}
{"type": "orderbook_delta", "seq": 4184, "price": 46, "quantity": -200, "ts": 1756428365.062591, "side": "buy"}
{"type": "orderbook_delta", "seq": 4185, "price": 59, "quantity": -1250, "ts": 1756428365.06264, "side": "sell"}
{"type": "orderbook_delta", "seq": 4186, "price": 59, "quantity": 200, "ts": 1756428365.106948, "side": "sell"}
{"type": "orderbook_delta", "seq": 4187, "price": 61, "quantity": 1250, "ts": 1756428365.107968, "side": "sell"}
{"type": "orderbook_delta", "seq": 4188, "price": 46, "quantity": 1250, "ts": 1756428365.11031, "side": "buy"}
{"type": "orderbook_delta", "seq": 4189, "price": 48, "quantity": 200, "ts": 1756428365.113595, "side": "buy"}
{"type": "orderbook_delta", "seq": 4190, "price": 48, "quantity": -200, "ts": 1756428365.576852, "side": "buy"}
{"type": "orderbook_delta", "seq": 4191, "price": 59, "quantity": -200, "ts": 1756428365.577409, "side": "sell"}
{"type": "orderbook_delta", "seq": 4192, "price": 61, "quantity": -1250, "ts": 1756428365.579593, "side": "sell"}
{"type": "orderbook_delta", "seq": 4193, "price": 46, "quantity": -1250, "ts": 1756428365.617206, "side": "buy"}
{"type": "orderbook_delta", "seq": 4194, "price": 60, "quantity": 1250, "ts": 1756428365.661921, "side": "sell"}
{"type": "orderbook_delta", "seq": 4195, "price": 58, "quantity": 200, "ts": 1756428365.662211, "side": "sell"}
{"type": "orderbook_delta", "seq": 4196, "price": 45, "quantity": 1250, "ts": 1756428365.663617, "side": "buy"}
{"type": "orderbook_delta", "seq": 4197, "price": 47, "quantity": 200, "ts": 1756428365.677494, "side": "buy"}
{"type": "orderbook_delta", "seq": 4198, "price": 45, "quantity": -1250, "ts": 1756428366.050074, "side": "buy"}
{"type": "trade", "seq": 45, "price": 50, "quantity": 100, "ts": 1756428366.050181, "side": "buy"}
{"type": "orderbook_delta", "seq": 4199, "price": 60, "quantity": -1250, "ts": 1756428366.050181, "side": "sell"}
{"type": "orderbook_delta", "seq": 4200, "price": 47, "quantity": -200, "ts": 1756428366.050414, "side": "buy"}
{"type": "orderbook_delta", "seq": 4201, "price": 58, "quantity": -200, "ts": 1756428366.050871, "side": "sell"}
{"type": "orderbook_delta", "seq": 4202, "price": 46, "quantity": 1250, "ts": 1756428366.093909, "side": "buy"}
{"type": "orderbook_delta", "seq": 4203, "price": 59, "quantity": 200, "ts": 1756428366.097793, "side": "sell"}
{"type": "orderbook_delta", "seq": 4204, "price": 48, "quantity": 200, "ts": 1756428366.099105, "side": "buy"}
{"type": "orderbook_delta", "seq": 4205, "price": 63, "quantity": 200, "ts": 1756428366.100687, "side": "sell"}
{"type": "orderbook_delta", "seq": 4206, "price": 61, "quantity": 1250, "ts": 1756428366.103954, "side": "sell"}
{"type": "orderbook_delta", "seq": 4207, "price": 58, "quantity": -250, "ts": 1756428366.105355, "side": "sell"}
{"type": "orderbook_delta", "seq": 4208, "price": 50, "quantity": 0, "ts": 1756428366.105482, "side": "sell"}
{"type": "orderbook_delta", "seq": 4209, "price": 68, "quantity": 250, "ts": 1756428366.12617, "side": "sell"}
{"type": "orderbook_delta", "seq": 4210, "price": 57, "quantity": -500, "ts": 1756428366.136945, "side": "sell"}
{"type": "orderbook_delta", "seq": 4211, "price": 63, "quantity": -200, "ts": 1756428366.179635, "side": "sell"}
{"type": "orderbook_delta", "seq": 4212, "price": 64, "quantity": 200, "ts": 1756428366.179635, "side": "sell"}
{"type": "orderbook_delta", "seq": 4213, "price": 59, "quantity": 500, "ts": 1756428366.189913, "side": "sell"}
{"type": "orderbook_delta", "seq": 4214, "price": 50, "quantity": 250, "ts": 1756428366.269099, "side": "buy"}
{"type": "orderbook_delta", "seq": 4215, "price": 40, "quantity": -250, "ts": 1756428366.270816, "side": "buy"}
{"type": "orderbook_delta", "seq": 4216, "price": 56, "quantity": 100, "ts": 1756428366.272065, "side": "sell"}
{"type": "orderbook_delta", "seq": 4217, "price": 59, "quantity": -500, "ts": 1756428366.395025, "side": "sell"}
{"type": "orderbook_delta", "seq": 4218, "price": 49, "quantity": -500, "ts": 1756428366.396669, "side": "buy"}
{"type": "orderbook_delta", "seq": 4219, "price": 50, "quantity": 500, "ts": 1756428366.437678, "side": "buy"}
{"type": "orderbook_delta", "seq": 4220, "price": 56, "quantity": 500, "ts": 1756428366.45183, "side": "sell"}
{"type": "trade", "seq": 46, "price": 50, "quantity": 250, "ts": 1756428368.0, "side": "sell"}
{"type": "orderbook_delta", "seq": 4221, "price": 50, "quantity": 0, "ts": 1756428368.414017, "side": "buy"}
{"type": "orderbook_delta", "seq": 4222, "price": 50, "quantity": 0, "ts": 1756428368.414017, "side": "buy"}
{"type": "orderbook_delta", "seq": 4223, "price": 48, "quantity": 0, "ts": 1756428368.414017, "side": "buy"}
{"type": "orderbook_delta", "seq": 4224, "price": 48, "quantity": 0, "ts": 1756428368.414017, "side": "buy"}
{"type": "orderbook_delta", "seq": 4225, "price": 46, "quantity": 0, "ts": 1756428368.414017, "side": "buy"}
{"type": "orderbook_delta", "seq": 4226, "price": 46, "quantity": 0, "ts": 1756428368.414017, "side": "buy"}
{"type": "orderbook_delta", "seq": 4227, "price": 46, "quantity": 0, "ts": 1756428368.414017, "side": "buy"}
{"type": "trade", "seq": 47, "price": 50, "quantity": 500, "ts": 1756428368.414017, "side": "sell"}
{"type": "trade", "seq": 48, "price": 48, "quantity": 250, "ts": 1756428368.414017, "side": "sell"}
{"type": "trade", "seq": 49, "price": 48, "quantity": 200, "ts": 1756428368.414017, "side": "sell"}
{"type": "trade", "seq": 50, "price": 46, "quantity": 250, "ts": 1756428368.414017, "side": "sell"}
{"type": "trade", "seq": 51, "price": 46, "quantity": 100, "ts": 1756428368.414017, "side": "sell"}
{"type": "trade", "seq": 52, "price": 46, "quantity": 313, "ts": 1756428368.482213, "side": "sell"}
{"type": "orderbook_delta", "seq": 4228, "price": 56, "quantity": 250, "ts": 1756428368.482213, "side": "sell"}
{"type": "orderbook_delta", "seq": 4229, "price": 46, "quantity": -937, "ts": 1756428368.495341, "side": "buy"}
{"type": "orderbook_delta", "seq": 4230, "price": 56, "quantity": 250, "ts": 1756428368.497636, "side": "sell"}
{"type": "orderbook_delta", "seq": 4231, "price": 61, "quantity": -1250, "ts": 1756428368.554743, "side": "sell"}
{"type": "orderbook_delta", "seq": 4232, "price": 56, "quantity": 250, "ts": 1756428368.568275, "side": "sell"}
{"type": "orderbook_delta", "seq": 4233, "price": 99, "quantity": -16200, "ts": 1756428368.572473, "side": "sell"}
{"type": "orderbook_delta", "seq": 4234, "price": 40, "quantity": 250, "ts": 1756428368.600922, "side": "buy"}
{"type": "orderbook_delta", "seq": 4235, "price": 98, "quantity": -7000, "ts": 1756428368.601955, "side": "sell"}
{"type": "orderbook_delta", "seq": 4236, "price": 60, "quantity": 1250, "ts": 1756428368.625143, "side": "sell"}
{"type": "orderbook_delta", "seq": 4237, "price": 48, "quantity": 250, "ts": 1756428368.648034, "side": "buy"}
{"type": "orderbook_delta", "seq": 4238, "price": 46, "quantity": 250, "ts": 1756428368.699135, "side": "buy"}
{"type": "orderbook_delta", "seq": 4239, "price": 50, "quantity": 250, "ts": 1756428369.145137, "side": "buy"}
{"type": "orderbook_delta", "seq": 4240, "price": 56, "quantity": -250, "ts": 1756428369.154406, "side": "sell"}
{"type": "orderbook_delta", "seq": 4241, "price": 56, "quantity": -250, "ts": 1756428369.188285, "side": "sell"}
{"type": "orderbook_delta", "seq": 4242, "price": 60, "quantity": -1250, "ts": 1756428369.195433, "side": "sell"}
{"type": "orderbook_delta", "seq": 4243, "price": 56, "quantity": -500, "ts": 1756428369.19568, "side": "sell"}
{"type": "orderbook_delta", "seq": 4244, "price": 70, "quantity": 250, "ts": 1756428369.205773, "side": "sell"}
{"type": "orderbook_delta", "seq": 4245, "price": 59, "quantity": -200, "ts": 1756428369.206474, "side": "sell"}
{"type": "orderbook_delta", "seq": 4246, "price": 60, "quantity": -250, "ts": 1756428369.20811, "side": "sell"}
{"type": "orderbook_delta", "seq": 4247, "price": 64, "quantity": -200, "ts": 1756428369.255096, "side": "sell"}
{"type": "orderbook_delta", "seq": 4248, "price": 66, "quantity": 200, "ts": 1756428369.255096, "side": "sell"}
{"type": "orderbook_delta", "seq": 4249, "price": 61, "quantity": 500, "ts": 1756428369.282975, "side": "sell"}
{"type": "orderbook_delta", "seq": 4250, "price": 61, "quantity": 200, "ts": 1756428369.286219, "side": "sell"}
{"type": "orderbook_delta", "seq": 4251, "price": 62, "quantity": 1250, "ts": 1756428369.286708, "side": "sell"}
{"type": "orderbook_delta", "seq": 4252, "price": 56, "quantity": -250, "ts": 1756428369.31146, "side": "sell"}
{"type": "orderbook_delta", "seq": 4253, "price": 66, "quantity": -200, "ts": 1756428369.318949, "side": "sell"}
{"type": "orderbook_delta", "seq": 4254, "price": 68, "quantity": 200, "ts": 1756428369.318949, "side": "sell"}
{"type": "orderbook_delta", "seq": 4255, "price": 56, "quantity": -100, "ts": 1756428369.351862, "side": "sell"}
{"type": "orderbook_delta", "seq": 4256, "price": 62, "quantity": -1250, "ts": 1756428369.369347, "side": "sell"}
{"type": "orderbook_delta", "seq": 4257, "price": 61, "quantity": -200, "ts": 1756428369.373506, "side": "sell"}
{"type": "orderbook_delta", "seq": 4258, "price": 40, "quantity": -250, "ts": 1756428369.399567, "side": "buy"}
{"type": "orderbook_delta", "seq": 4259, "price": 62, "quantity": 200, "ts": 1756428369.424418, "side": "sell"}
{"type": "orderbook_delta", "seq": 4260, "price": 64, "quantity": 1250, "ts": 1756428369.426644, "side": "sell"}
{"type": "orderbook_delta", "seq": 4261, "price": 20, "quantity": -200, "ts": 1756428369.45131, "side": "buy"}
{"type": "orderbook_delta", "seq": 4262, "price": 30, "quantity": 200, "ts": 1756428369.45131, "side": "buy"}
{"type": "orderbook_delta", "seq": 4263, "price": 80, "quantity": -200, "ts": 1756428369.454214, "side": "sell"}
{"type": "orderbook_delta", "seq": 4264, "price": 90, "quantity": 200, "ts": 1756428369.454214, "side": "sell"}
{"type": "orderbook_delta", "seq": 4265, "price": 58, "quantity": 850, "ts": 1756428369.474052, "side": "sell"}
{"type": "orderbook_delta", "seq": 4266, "price": 21, "quantity": -8000, "ts": 1756428369.485806, "side": "buy"}
{"type": "orderbook_delta", "seq": 4267, "price": 98, "quantity": -8000, "ts": 1756428369.485903, "side": "sell"}
{"type": "orderbook_delta", "seq": 4268, "price": 89, "quantity": 8000, "ts": 1756428369.528725, "side": "sell"}
{"type": "orderbook_delta", "seq": 4269, "price": 12, "quantity": 8000, "ts": 1756428369.534542, "side": "buy"}
{"type": "orderbook_delta", "seq": 4270, "price": 64, "quantity": -1250, "ts": 1756428369.720043, "side": "sell"}
{"type": "orderbook_delta", "seq": 4271, "price": 62, "quantity": -200, "ts": 1756428369.760487, "side": "sell"}
{"type": "orderbook_delta", "seq": 4272, "price": 65, "quantity": 1250, "ts": 1756428369.800787, "side": "sell"}
{"type": "orderbook_delta", "seq": 4273, "price": 63, "quantity": 200, "ts": 1756428369.803728, "side": "sell"}
{"type": "orderbook_delta", "seq": 4274, "price": 58, "quantity": -850, "ts": 1756428369.923465, "side": "sell"}
{"type": "orderbook_delta", "seq": 4275, "price": 63, "quantity": -200, "ts": 1756428369.929565, "side": "sell"}
{"type": "orderbook_delta", "seq": 4276, "price": 65, "quantity": -1250, "ts": 1756428369.9338, "side": "sell"}
{"type": "orderbook_delta", "seq": 4277, "price": 62, "quantity": 200, "ts": 1756428369.975597, "side": "sell"}
{"type": "orderbook_delta", "seq": 4278, "price": 64, "quantity": 1250, "ts": 1756428369.976273, "side": "sell"}
{"type": "orderbook_delta", "seq": 4279, "price": 49, "quantity": 100, "ts": 1756428369.976833, "side": "buy"}
{"type": "orderbook_delta", "seq": 4280, "price": 59, "quantity": 850, "ts": 1756428369.978993, "side": "sell"}
{"type": "orderbook_delta", "seq": 4281, "price": 64, "quantity": -1250, "ts": 1756428370.059871, "side": "sell"}
{"type": "orderbook_delta", "seq": 4282, "price": 62, "quantity": -200, "ts": 1756428370.060022, "side": "sell"}
{"type": "orderbook_delta", "seq": 4283, "price": 65, "quantity": 1250, "ts": 1756428370.105106, "side": "sell"}
{"type": "orderbook_delta", "seq": 4284, "price": 63, "quantity": 200, "ts": 1756428370.1082, "side": "sell"}
{"type": "orderbook_delta", "seq": 4285, "price": 59, "quantity": -850, "ts": 1756428370.108758, "side": "sell"}
{"type": "orderbook_delta", "seq": 4286, "price": 52, "quantity": 250, "ts": 1756428370.145658, "side": "buy"}
{"type": "orderbook_delta", "seq": 4287, "price": 42, "quantity": -250, "ts": 1756428370.166293, "side": "buy"}
{"type": "orderbook_delta", "seq": 4288, "price": 60, "quantity": 850, "ts": 1756428370.209314, "side": "sell"}
{"type": "orderbook_delta", "seq": 4289, "price": 61, "quantity": -500, "ts": 1756428370.249287, "side": "sell"}
{"type": "orderbook_delta", "seq": 4290, "price": 60, "quantity": 500, "ts": 1756428370.288633, "side": "sell"}
{"type": "orderbook_delta", "seq": 4291, "price": 50, "quantity": 1250, "ts": 1756428370.571699, "side": "buy"}
{"type": "orderbook_delta", "seq": 4292, "price": 52, "quantity": 200, "ts": 1756428370.571991, "side": "buy"}
{"type": "orderbook_delta", "seq": 4293, "price": 53, "quantity": 500, "ts": 1756428370.574787, "side": "buy"}
{"type": "orderbook_delta", "seq": 4294, "price": 44, "quantity": -250, "ts": 1756428370.620213, "side": "buy"}
{"type": "orderbook_delta", "seq": 4295, "price": 54, "quantity": 250, "ts": 1756428370.62123, "side": "buy"}
{"type": "orderbook_delta", "seq": 4296, "price": 53, "quantity": -500, "ts": 1756428370.650341, "side": "buy"}
{"type": "orderbook_delta", "seq": 4297, "price": 54, "quantity": 500, "ts": 1756428370.70173, "side": "buy"}
{"type": "orderbook_delta", "seq": 4298, "price": 56, "quantity": 200, "ts": 1756428371.289467, "side": "buy"}
{"type": "orderbook_delta", "seq": 4299, "price": 65, "quantity": -1250, "ts": 1756428371.378267, "side": "sell"}
{"type": "orderbook_delta", "seq": 4300, "price": 49, "quantity": -100, "ts": 1756428371.393759, "side": "buy"}
{"type": "orderbook_delta", "seq": 4301, "price": 64, "quantity": 1250, "ts": 1756428371.410229, "side": "sell"}
{"type": "orderbook_delta", "seq": 4302, "price": 64, "quantity": -1250, "ts": 1756428371.455324, "side": "sell"}
{"type": "orderbook_delta", "seq": 4303, "price": 65, "quantity": 1250, "ts": 1756428371.499707, "side": "sell"}
{"type": "orderbook_delta", "seq": 4304, "price": 51, "quantity": 100, "ts": 1756428371.599714, "side": "buy"}
{"type": "orderbook_delta", "seq": 4305, "price": 51, "quantity": -100, "ts": 1756428372.320926, "side": "buy"}
{"type": "orderbook_delta", "seq": 4306, "price": 72, "quantity": 250, "ts": 1756428372.447204, "side": "sell"}
{"type": "orderbook_delta", "seq": 4307, "price": 62, "quantity": -250, "ts": 1756428372.450677, "side": "sell"}
{"type": "orderbook_delta", "seq": 4308, "price": 54, "quantity": -500, "ts": 1756428372.470328, "side": "buy"}
{"type": "orderbook_delta", "seq": 4309, "price": 60, "quantity": -500, "ts": 1756428372.473503, "side": "sell"}
{"type": "orderbook_delta", "seq": 4310, "price": 63, "quantity": 500, "ts": 1756428372.524235, "side": "sell"}
{"type": "orderbook_delta", "seq": 4311, "price": 55, "quantity": 500, "ts": 1756428372.534062, "side": "buy"}
{"type": "orderbook_delta", "seq": 4312, "price": 55, "quantity": 100, "ts": 1756428372.544882, "side": "buy"}
{"type": "orderbook_delta", "seq": 4313, "price": 63, "quantity": -500, "ts": 1756428372.579885, "side": "sell"}
{"type": "orderbook_delta", "seq": 4314, "price": 55, "quantity": -500, "ts": 1756428372.580688, "side": "buy"}
{"type": "orderbook_delta", "seq": 4315, "price": 65, "quantity": -1250, "ts": 1756428372.59154, "side": "sell"}
{"type": "orderbook_delta", "seq": 4316, "price": 52, "quantity": -200, "ts": 1756428372.594326, "side": "buy"}
{"type": "orderbook_delta", "seq": 4317, "price": 50, "quantity": -1250, "ts": 1756428372.597403, "side": "buy"}
{"type": "orderbook_delta", "seq": 4318, "price": 62, "quantity": 250, "ts": 1756428372.600385, "side": "sell"}
{"type": "orderbook_delta", "seq": 4319, "price": 72, "quantity": -250, "ts": 1756428372.600684, "side": "sell"}
{"type": "orderbook_delta", "seq": 4320, "price": 53, "quantity": 500, "ts": 1756428372.697247, "side": "buy"}
{"type": "orderbook_delta", "seq": 4321, "price": 59, "quantity": 500, "ts": 1756428372.697553, "side": "sell"}
{"type": "orderbook_delta", "seq": 4322, "price": 63, "quantity": -200, "ts": 1756428372.698482, "side": "sell"}
{"type": "orderbook_delta", "seq": 4323, "price": 51, "quantity": 200, "ts": 1756428372.699191, "side": "buy"}
{"type": "orderbook_delta", "seq": 4324, "price": 49, "quantity": 1250, "ts": 1756428372.700104, "side": "buy"}
{"type": "orderbook_delta", "seq": 4325, "price": 64, "quantity": 1250, "ts": 1756428372.700516, "side": "sell"}
{"type": "orderbook_delta", "seq": 4326, "price": 42, "quantity": 250, "ts": 1756428372.702342, "side": "buy"}
{"type": "orderbook_delta", "seq": 4327, "price": 44, "quantity": 250, "ts": 1756428372.71868, "side": "buy"}
{"type": "orderbook_delta", "seq": 4328, "price": 54, "quantity": -250, "ts": 1756428372.719643, "side": "buy"}
{"type": "orderbook_delta", "seq": 4329, "price": 52, "quantity": -250, "ts": 1756428372.736829, "side": "buy"}
{"type": "orderbook_delta", "seq": 4330, "price": 49, "quantity": -1250, "ts": 1756428372.746998, "side": "buy"}
{"type": "orderbook_delta", "seq": 4331, "price": 51, "quantity": -200, "ts": 1756428372.747776, "side": "buy"}
{"type": "orderbook_delta", "seq": 4332, "price": 61, "quantity": 200, "ts": 1756428372.747955, "side": "sell"}
{"type": "orderbook_delta", "seq": 4333, "price": 64, "quantity": -1250, "ts": 1756428372.750194, "side": "sell"}
{"type": "orderbook_delta", "seq": 4334, "price": 42, "quantity": -250, "ts": 1756428372.763476, "side": "buy"}
{"type": "orderbook_delta", "seq": 4335, "price": 53, "quantity": -500, "ts": 1756428372.769549, "side": "buy"}
{"type": "orderbook_delta", "seq": 4336, "price": 48, "quantity": 1250, "ts": 1756428372.790915, "side": "buy"}
{"type": "orderbook_delta", "seq": 4337, "price": 63, "quantity": 1250, "ts": 1756428372.791198, "side": "sell"}
{"type": "orderbook_delta", "seq": 4338, "price": 51, "quantity": 500, "ts": 1756428372.805703, "side": "buy"}
{"type": "orderbook_delta", "seq": 4339, "price": 50, "quantity": 200, "ts": 1756428372.807182, "side": "buy"}
{"type": "orderbook_delta", "seq": 4340, "price": 68, "quantity": -200, "ts": 1756428372.831851, "side": "sell"}
{"type": "orderbook_delta", "seq": 4341, "price": 66, "quantity": 200, "ts": 1756428372.831851, "side": "sell"}
{"type": "orderbook_delta", "seq": 4342, "price": 60, "quantity": -850, "ts": 1756428373.092566, "side": "sell"}
{"type": "orderbook_delta", "seq": 4343, "price": 59, "quantity": 850, "ts": 1756428373.153185, "side": "sell"}
{"type": "orderbook_delta", "seq": 4344, "price": 55, "quantity": -100, "ts": 1756428373.280265, "side": "buy"}
{"type": "orderbook_delta", "seq": 4345, "price": 56, "quantity": 100, "ts": 1756428373.519839, "side": "buy"}
{"type": "orderbook_delta", "seq": 4346, "price": 50, "quantity": -200, "ts": 1756428374.117323, "side": "buy"}
{"type": "orderbook_delta", "seq": 4347, "price": 63, "quantity": -1250, "ts": 1756428374.119327, "side": "sell"}
{"type": "orderbook_delta", "seq": 4348, "price": 48, "quantity": -1250, "ts": 1756428374.119806, "side": "buy"}
{"type": "orderbook_delta", "seq": 4349, "price": 61, "quantity": -200, "ts": 1756428374.126149, "side": "sell"}
{"type": "orderbook_delta", "seq": 4350, "price": 64, "quantity": 1250, "ts": 1756428374.157891, "side": "sell"}
{"type": "orderbook_delta", "seq": 4351, "price": 49, "quantity": 1250, "ts": 1756428374.160146, "side": "buy"}
{"type": "orderbook_delta", "seq": 4352, "price": 51, "quantity": 200, "ts": 1756428374.16351, "side": "buy"}
{"type": "orderbook_delta", "seq": 4353, "price": 62, "quantity": 200, "ts": 1756428374.176531, "side": "sell"}
{"type": "orderbook_delta", "seq": 4354, "price": 64, "quantity": -1250, "ts": 1756428374.532841, "side": "sell"}
{"type": "orderbook_delta", "seq": 4355, "price": 63, "quantity": 1250, "ts": 1756428374.567176, "side": "sell"}
{"type": "orderbook_delta", "seq": 4356, "price": 59, "quantity": -850, "ts": 1756428375.1337, "side": "sell"}
{"type": "orderbook_delta", "seq": 4357, "price": 60, "quantity": 250, "ts": 1756428375.133773, "side": "sell"}
{"type": "orderbook_delta", "seq": 4358, "price": 62, "quantity": -200, "ts": 1756428375.136731, "side": "sell"}
{"type": "orderbook_delta", "seq": 4359, "price": 51, "quantity": -200, "ts": 1756428375.136885, "side": "buy"}
{"type": "orderbook_delta", "seq": 4360, "price": 70, "quantity": -250, "ts": 1756428375.14883, "side": "sell"}
{"type": "orderbook_delta", "seq": 4361, "price": 63, "quantity": -1250, "ts": 1756428375.156391, "side": "sell"}
{"type": "orderbook_delta", "seq": 4362, "price": 59, "quantity": -500, "ts": 1756428375.158056, "side": "sell"}
{"type": "orderbook_delta", "seq": 4363, "price": 49, "quantity": -1250, "ts": 1756428375.162078, "side": "buy"}
{"type": "orderbook_delta", "seq": 4364, "price": 62, "quantity": 1250, "ts": 1756428375.192543, "side": "sell"}
{"type": "orderbook_delta", "seq": 4365, "price": 59, "quantity": 500, "ts": 1756428375.196337, "side": "sell"}
{"type": "orderbook_delta", "seq": 4366, "price": 60, "quantity": -250, "ts": 1756428375.201164, "side": "sell"}
{"type": "orderbook_delta", "seq": 4367, "price": 58, "quantity": 850, "ts": 1756428375.209587, "side": "sell"}
{"type": "orderbook_delta", "seq": 4368, "price": 59, "quantity": -500, "ts": 1756428375.238214, "side": "sell"}
{"type": "orderbook_delta", "seq": 4369, "price": 49, "quantity": 200, "ts": 1756428375.271203, "side": "buy"}
{"type": "orderbook_delta", "seq": 4370, "price": 61, "quantity": 200, "ts": 1756428375.27522, "side": "sell"}
{"type": "orderbook_delta", "seq": 4371, "price": 47, "quantity": 1250, "ts": 1756428375.275526, "side": "buy"}
{"type": "orderbook_delta", "seq": 4372, "price": 57, "quantity": 500, "ts": 1756428375.278101, "side": "sell"}
{"type": "orderbook_delta", "seq": 4373, "price": 66, "quantity": -200, "ts": 1756428375.288568, "side": "sell"}
{"type": "orderbook_delta", "seq": 4374, "price": 64, "quantity": 200, "ts": 1756428375.288568, "side": "sell"}
{"type": "orderbook_delta", "seq": 4375, "price": 42, "quantity": 250, "ts": 1756428375.771122, "side": "buy"}
{"type": "orderbook_delta", "seq": 4376, "price": 51, "quantity": -500, "ts": 1756428375.775538, "side": "buy"}
{"type": "orderbook_delta", "seq": 4377, "price": 49, "quantity": -200, "ts": 1756428375.775805, "side": "buy"}
{"type": "orderbook_delta", "seq": 4378, "price": 47, "quantity": -1250, "ts": 1756428375.775855, "side": "buy"}
{"type": "orderbook_delta", "seq": 4379, "price": 62, "quantity": -1250, "ts": 1756428375.787802, "side": "sell"}
{"type": "orderbook_delta", "seq": 4380, "price": 61, "quantity": -200, "ts": 1756428375.858235, "side": "sell"}
{"type": "orderbook_delta", "seq": 4381, "price": 64, "quantity": -200, "ts": 1756428375.898913, "side": "sell"}
{"type": "orderbook_delta", "seq": 4382, "price": 62, "quantity": 200, "ts": 1756428375.898913, "side": "sell"}
{"type": "orderbook_delta", "seq": 4383, "price": 58, "quantity": 1250, "ts": 1756428375.926862, "side": "sell"}
{"type": "orderbook_delta", "seq": 4384, "price": 57, "quantity": 200, "ts": 1756428375.927303, "side": "sell"}
{"type": "orderbook_delta", "seq": 4385, "price": 48, "quantity": 500, "ts": 1756428375.927869, "side": "buy"}
{"type": "orderbook_delta", "seq": 4386, "price": 43, "quantity": 1250, "ts": 1756428375.92833, "side": "buy"}
{"type": "orderbook_delta", "seq": 4387, "price": 45, "quantity": 200, "ts": 1756428375.929999, "side": "buy"}
{"type": "orderbook_delta", "seq": 4388, "price": 62, "quantity": -200, "ts": 1756428375.950923, "side": "sell"}
{"type": "orderbook_delta", "seq": 4389, "price": 60, "quantity": 200, "ts": 1756428375.950923, "side": "sell"}
{"type": "orderbook_delta", "seq": 4390, "price": 40, "quantity": 250, "ts": 1756428376.055888, "side": "buy"}
{"type": "trade", "seq": 53, "price": 56, "quantity": 200, "ts": 1756428376.062891, "side": "sell"}
{"type": "orderbook_delta", "seq": 4391, "price": 48, "quantity": -500, "ts": 1756428376.062891, "side": "buy"}
{"type": "trade", "seq": 54, "price": 56, "quantity": 100, "ts": 1756428376.06352, "side": "sell"}
{"type": "orderbook_delta", "seq": 4392, "price": 56, "quantity": 0, "ts": 1756428376.06352, "side": "buy"}
{"type": "orderbook_delta", "seq": 4393, "price": 56, "quantity": 0, "ts": 1756428376.06352, "side": "buy"}
{"type": "orderbook_delta", "seq": 4394, "price": 50, "quantity": -250, "ts": 1756428376.087827, "side": "buy"}
{"type": "orderbook_delta", "seq": 4395, "price": 48, "quantity": -250, "ts": 1756428376.111766, "side": "buy"}
{"type": "orderbook_delta", "seq": 4396, "price": 58, "quantity": -850, "ts": 1756428376.115274, "side": "sell"}
{"type": "orderbook_delta", "seq": 4397, "price": 38, "quantity": 250, "ts": 1756428376.116848, "side": "buy"}
{"type": "orderbook_delta", "seq": 4398, "price": 47, "quantity": 500, "ts": 1756428376.118135, "side": "buy"}
{"type": "orderbook_delta", "seq": 4399, "price": 68, "quantity": -250, "ts": 1756428376.135895, "side": "sell"}
{"type": "orderbook_delta", "seq": 4400, "price": 56, "quantity": 250, "ts": 1756428376.135988, "side": "sell"}
{"type": "orderbook_delta", "seq": 4401, "price": 66, "quantity": -250, "ts": 1756428376.176164, "side": "sell"}
{"type": "orderbook_delta", "seq": 4402, "price": 60, "quantity": 250, "ts": 1756428376.176198, "side": "sell"}
{"type": "orderbook_delta", "seq": 4403, "price": 38, "quantity": -250, "ts": 1756428376.179731, "side": "buy"}
{"type": "orderbook_delta", "seq": 4404, "price": 48, "quantity": 250, "ts": 1756428376.181079, "side": "buy"}
{"type": "orderbook_delta", "seq": 4405, "price": 58, "quantity": 250, "ts": 1756428376.216527, "side": "sell"}
{"type": "orderbook_delta", "seq": 4406, "price": 54, "quantity": 850, "ts": 1756428376.259543, "side": "sell"}
{"type": "orderbook_delta", "seq": 4407, "price": 57, "quantity": -500, "ts": 1756428376.284723, "side": "sell"}
{"type": "orderbook_delta", "seq": 4408, "price": 58, "quantity": -1250, "ts": 1756428376.284801, "side": "sell"}
{"type": "orderbook_delta", "seq": 4409, "price": 57, "quantity": -200, "ts": 1756428376.284908, "side": "sell"}
{"type": "orderbook_delta", "seq": 4410, "price": 58, "quantity": 1250, "ts": 1756428376.315263, "side": "sell"}
{"type": "orderbook_delta", "seq": 4411, "price": 56, "quantity": 200, "ts": 1756428376.316253, "side": "sell"}
{"type": "orderbook_delta", "seq": 4412, "price": 55, "quantity": 500, "ts": 1756428376.316783, "side": "sell"}
{"type": "orderbook_delta", "seq": 4413, "price": 55, "quantity": -500, "ts": 1756428376.389684, "side": "sell"}
{"type": "orderbook_delta", "seq": 4414, "price": 53, "quantity": 500, "ts": 1756428376.438154, "side": "sell"}
{"type": "orderbook_delta", "seq": 4415, "price": 59, "quantity": 100, "ts": 1756428376.531817, "side": "sell"}
{"type": "orderbook_delta", "seq": 4416, "price": 54, "quantity": -850, "ts": 1756428377.150322, "side": "sell"}
{"type": "orderbook_delta", "seq": 4417, "price": 54, "quantity": 250, "ts": 1756428377.168139, "side": "sell"}
{"type": "orderbook_delta", "seq": 4418, "price": 38, "quantity": 250, "ts": 1756428377.185798, "side": "buy"}
{"type": "orderbook_delta", "seq": 4419, "price": 48, "quantity": -250, "ts": 1756428377.186035, "side": "buy"}
{"type": "orderbook_delta", "seq": 4420, "price": 53, "quantity": -500, "ts": 1756428377.188287, "side": "sell"}
{"type": "orderbook_delta", "seq": 4421, "price": 60, "quantity": -200, "ts": 1756428377.221235, "side": "sell"}
{"type": "orderbook_delta", "seq": 4422, "price": 58, "quantity": 200, "ts": 1756428377.221235, "side": "sell"}
{"type": "orderbook_delta", "seq": 4423, "price": 53, "quantity": 500, "ts": 1756428377.227142, "side": "sell"}
{"type": "orderbook_delta", "seq": 4424, "price": 64, "quantity": -250, "ts": 1756428377.246067, "side": "sell"}
{"type": "orderbook_delta", "seq": 4425, "price": 52, "quantity": 850, "ts": 1756428377.292474, "side": "sell"}
{"type": "orderbook_delta", "seq": 4426, "price": 59, "quantity": -100, "ts": 1756428377.611419, "side": "sell"}
{"type": "orderbook_delta", "seq": 4427, "price": 49, "quantity": 100, "ts": 1756428377.873588, "side": "buy"}
{"type": "orderbook_delta", "seq": 4428, "price": 66, "quantity": -50, "ts": 1756428378.039382, "side": "sell"}
{"type": "orderbook_delta", "seq": 4429, "price": 69, "quantity": 50, "ts": 1756428378.039382, "side": "sell"}
{"type": "orderbook_delta", "seq": 4430, "price": 58, "quantity": -1250, "ts": 1756428378.178743, "side": "sell"}
{"type": "orderbook_delta", "seq": 4431, "price": 45, "quantity": -200, "ts": 1756428378.179392, "side": "buy"}
{"type": "orderbook_delta", "seq": 4432, "price": 56, "quantity": -200, "ts": 1756428378.17994, "side": "sell"}
{"type": "orderbook_delta", "seq": 4433, "price": 43, "quantity": -1250, "ts": 1756428378.192121, "side": "buy"}
{"type": "orderbook_delta", "seq": 4434, "price": 57, "quantity": 1250, "ts": 1756428378.246543, "side": "sell"}
{"type": "orderbook_delta", "seq": 4435, "price": 55, "quantity": 200, "ts": 1756428378.246844, "side": "sell"}
{"type": "orderbook_delta", "seq": 4436, "price": 42, "quantity": 1250, "ts": 1756428378.248944, "side": "buy"}
{"type": "orderbook_delta", "seq": 4437, "price": 44, "quantity": 200, "ts": 1756428378.249251, "side": "buy"}
{"type": "orderbook_delta", "seq": 4438, "price": 69, "quantity": 0, "ts": 1756428379.023024, "side": "sell"}
{"type": "orderbook_delta", "seq": 4439, "price": 64, "quantity": 250, "ts": 1756428379.136623, "side": "sell"}
{"type": "orderbook_delta", "seq": 4440, "price": 52, "quantity": -850, "ts": 1756428379.137501, "side": "sell"}
{"type": "orderbook_delta", "seq": 4441, "price": 54, "quantity": -250, "ts": 1756428379.156541, "side": "sell"}
{"type": "orderbook_delta", "seq": 4442, "price": 53, "quantity": -500, "ts": 1756428379.196957, "side": "sell"}
{"type": "orderbook_delta", "seq": 4443, "price": 53, "quantity": 850, "ts": 1756428379.220793, "side": "sell"}
{"type": "orderbook_delta", "seq": 4444, "price": 55, "quantity": 500, "ts": 1756428379.236746, "side": "sell"}
{"type": "orderbook_delta", "seq": 4445, "price": 55, "quantity": -500, "ts": 1756428379.279993, "side": "sell"}
{"type": "orderbook_delta", "seq": 4446, "price": 53, "quantity": 500, "ts": 1756428379.318829, "side": "sell"}
{"type": "orderbook_delta", "seq": 4447, "price": 38, "quantity": -250, "ts": 1756428380.129342, "side": "buy"}
{"type": "orderbook_delta", "seq": 4448, "price": 48, "quantity": 250, "ts": 1756428380.132196, "side": "buy"}
{"type": "orderbook_delta", "seq": 4449, "price": 52, "quantity": 100, "ts": 1756428380.578953, "side": "sell"}
{"type": "orderbook_delta", "seq": 4450, "price": 42, "quantity": -1250, "ts": 1756428380.938901, "side": "buy"}
{"type": "orderbook_delta", "seq": 4451, "price": 57, "quantity": -1250, "ts": 1756428380.939286, "side": "sell"}
{"type": "orderbook_delta", "seq": 4452, "price": 53, "quantity": -500, "ts": 1756428380.941134, "side": "sell"}
{"type": "orderbook_delta", "seq": 4453, "price": 47, "quantity": -500, "ts": 1756428380.943275, "side": "buy"}
{"type": "orderbook_delta", "seq": 4454, "price": 44, "quantity": -200, "ts": 1756428380.943495, "side": "buy"}
{"type": "orderbook_delta", "seq": 4455, "price": 38, "quantity": 250, "ts": 1756428380.961414, "side": "buy"}
{"type": "orderbook_delta", "seq": 4456, "price": 48, "quantity": -250, "ts": 1756428380.961811, "side": "buy"}
{"type": "orderbook_delta", "seq": 4457, "price": 43, "quantity": 200, "ts": 1756428380.980173, "side": "buy"}
{"type": "orderbook_delta", "seq": 4458, "price": 56, "quantity": 1250, "ts": 1756428380.98044, "side": "sell"}
{"type": "orderbook_delta", "seq": 4459, "price": 41, "quantity": 1250, "ts": 1756428380.980702, "side": "buy"}
{"type": "orderbook_delta", "seq": 4460, "price": 51, "quantity": 500, "ts": 1756428380.980935, "side": "sell"}
{"type": "orderbook_delta", "seq": 4461, "price": 45, "quantity": 500, "ts": 1756428380.981177, "side": "buy"}
{"type": "orderbook_delta", "seq": 4462, "price": 30, "quantity": -200, "ts": 1756428381.012317, "side": "buy"}
{"type": "orderbook_delta", "seq": 4463, "price": 20, "quantity": 200, "ts": 1756428381.012317, "side": "buy"}
{"type": "orderbook_delta", "seq": 4464, "price": 58, "quantity": -200, "ts": 1756428381.020734, "side": "sell"}
{"type": "orderbook_delta", "seq": 4465, "price": 57, "quantity": 200, "ts": 1756428381.020734, "side": "sell"}
{"type": "orderbook_delta", "seq": 4466, "price": 90, "quantity": -200, "ts": 1756428381.109401, "side": "sell"}
{"type": "orderbook_delta", "seq": 4467, "price": 80, "quantity": 200, "ts": 1756428381.109401, "side": "sell"}
{"type": "orderbook_delta", "seq": 4468, "price": 57, "quantity": -200, "ts": 1756428381.116798, "side": "sell"}
{"type": "orderbook_delta", "seq": 4469, "price": 56, "quantity": 200, "ts": 1756428381.116798, "side": "sell"}
{"type": "orderbook_delta", "seq": 4470, "price": 53, "quantity": -850, "ts": 1756428381.127963, "side": "sell"}
{"type": "orderbook_delta", "seq": 4471, "price": 36, "quantity": 250, "ts": 1756428381.13162, "side": "buy"}
{"type": "orderbook_delta", "seq": 4472, "price": 54, "quantity": 250, "ts": 1756428381.148553, "side": "sell"}
{"type": "orderbook_delta", "seq": 4473, "price": 64, "quantity": -250, "ts": 1756428381.148781, "side": "sell"}
{"type": "orderbook_delta", "seq": 4474, "price": 89, "quantity": -8000, "ts": 1756428381.15376, "side": "sell"}
{"type": "orderbook_delta", "seq": 4475, "price": 46, "quantity": -250, "ts": 1756428381.167836, "side": "buy"}
{"type": "orderbook_delta", "seq": 4476, "price": 55, "quantity": -200, "ts": 1756428381.181046, "side": "sell"}
{"type": "orderbook_delta", "seq": 4477, "price": 79, "quantity": 8000, "ts": 1756428381.188832, "side": "sell"}
{"type": "orderbook_delta", "seq": 4478, "price": 54, "quantity": 200, "ts": 1756428381.222246, "side": "sell"}
{"type": "orderbook_delta", "seq": 4479, "price": 51, "quantity": 850, "ts": 1756428381.231878, "side": "sell"}
{"type": "orderbook_delta", "seq": 4480, "price": 43, "quantity": -200, "ts": 1756428381.371849, "side": "buy"}
{"type": "orderbook_delta", "seq": 4481, "price": 54, "quantity": -200, "ts": 1756428381.374849, "side": "sell"}
{"type": "orderbook_delta", "seq": 4482, "price": 56, "quantity": -1250, "ts": 1756428381.377327, "side": "sell"}
{"type": "orderbook_delta", "seq": 4483, "price": 41, "quantity": -1250, "ts": 1756428381.377462, "side": "buy"}
{"type": "orderbook_delta", "seq": 4484, "price": 40, "quantity": 1250, "ts": 1756428381.426967, "side": "buy"}
{"type": "orderbook_delta", "seq": 4485, "price": 53, "quantity": 200, "ts": 1756428381.427813, "side": "sell"}
{"type": "orderbook_delta", "seq": 4486, "price": 55, "quantity": 1250, "ts": 1756428381.428768, "side": "sell"}
{"type": "orderbook_delta", "seq": 4487, "price": 42, "quantity": 200, "ts": 1756428381.429052, "side": "buy"}
{"type": "orderbook_delta", "seq": 4488, "price": 51, "quantity": -850, "ts": 1756428382.150718, "side": "sell"}
{"type": "orderbook_delta", "seq": 4489, "price": 52, "quantity": 250, "ts": 1756428382.167269, "side": "sell"}
{"type": "orderbook_delta", "seq": 4490, "price": 62, "quantity": -250, "ts": 1756428382.25761, "side": "sell"}
{"type": "orderbook_delta", "seq": 4491, "price": 50, "quantity": 850, "ts": 1756428382.304347, "side": "sell"}
{"type": "orderbook_delta", "seq": 4492, "price": 45, "quantity": -500, "ts": 1756428382.68569, "side": "buy"}
{"type": "orderbook_delta", "seq": 4493, "price": 42, "quantity": -200, "ts": 1756428382.685952, "side": "buy"}
{"type": "orderbook_delta", "seq": 4494, "price": 53, "quantity": -200, "ts": 1756428382.686064, "side": "sell"}
{"type": "orderbook_delta", "seq": 4495, "price": 40, "quantity": -1250, "ts": 1756428382.68612, "side": "buy"}
{"type": "orderbook_delta", "seq": 4496, "price": 51, "quantity": -500, "ts": 1756428382.686416, "side": "sell"}
{"type": "orderbook_delta", "seq": 4497, "price": 55, "quantity": -1250, "ts": 1756428382.687192, "side": "sell"}
{"type": "orderbook_delta", "seq": 4498, "price": 56, "quantity": -200, "ts": 1756428382.711591, "side": "sell"}
{"type": "orderbook_delta", "seq": 4499, "price": 54, "quantity": 200, "ts": 1756428382.711591, "side": "sell"}
{"type": "orderbook_delta", "seq": 4500, "price": 39, "quantity": 1250, "ts": 1756428382.724714, "side": "buy"}
{"type": "orderbook_delta", "seq": 4501, "price": 41, "quantity": 200, "ts": 1756428382.727777, "side": "buy"}
{"type": "orderbook_delta", "seq": 4502, "price": 52, "quantity": 200, "ts": 1756428382.728049, "side": "sell"}
{"type": "orderbook_delta", "seq": 4503, "price": 53, "quantity": 1250, "ts": 1756428382.728865, "side": "sell"}
{"type": "orderbook_delta", "seq": 4504, "price": 50, "quantity": 500, "ts": 1756428382.729881, "side": "sell"}
{"type": "orderbook_delta", "seq": 4505, "price": 43, "quantity": 500, "ts": 1756428382.736281, "side": "buy"}
{"type": "orderbook_delta", "seq": 4506, "price": 54, "quantity": -200, "ts": 1756428382.760686, "side": "sell"}
{"type": "orderbook_delta", "seq": 4507, "price": 53, "quantity": 200, "ts": 1756428382.760686, "side": "sell"}
{"type": "orderbook_delta", "seq": 4508, "price": 53, "quantity": -1250, "ts": 1756428383.105593, "side": "sell"}
{"type": "orderbook_delta", "seq": 4509, "price": 54, "quantity": 1250, "ts": 1756428383.142038, "side": "sell"}
{"type": "orderbook_delta", "seq": 4510, "price": 39, "quantity": -1250, "ts": 1756428383.147827, "side": "buy"}
{"type": "orderbook_delta", "seq": 4511, "price": 41, "quantity": -200, "ts": 1756428383.148673, "side": "buy"}
{"type": "orderbook_delta", "seq": 4512, "price": 43, "quantity": -500, "ts": 1756428383.151175, "side": "buy"}
{"type": "orderbook_delta", "seq": 4513, "price": 52, "quantity": -200, "ts": 1756428383.151623, "side": "sell"}
{"type": "orderbook_delta", "seq": 4514, "price": 54, "quantity": -1250, "ts": 1756428383.18307, "side": "sell"}
{"type": "orderbook_delta", "seq": 4515, "price": 40, "quantity": 200, "ts": 1756428383.204054, "side": "buy"}
{"type": "orderbook_delta", "seq": 4516, "price": 42, "quantity": 500, "ts": 1756428383.204449, "side": "buy"}
{"type": "orderbook_delta", "seq": 4517, "price": 51, "quantity": 200, "ts": 1756428383.204776, "side": "sell"}
{"type": "orderbook_delta", "seq": 4518, "price": 38, "quantity": 1250, "ts": 1756428383.205528, "side": "buy"}
{"type": "orderbook_delta", "seq": 4519, "price": 53, "quantity": 1250, "ts": 1756428383.21818, "side": "sell"}
{"type": "orderbook_delta", "seq": 4520, "price": 53, "quantity": -200, "ts": 1756428383.993257, "side": "sell"}
{"type": "orderbook_delta", "seq": 4521, "price": 55, "quantity": 200, "ts": 1756428383.993257, "side": "sell"}
{"type": "orderbook_delta", "seq": 4522, "price": 40, "quantity": -200, "ts": 1756428384.061682, "side": "buy"}
{"type": "orderbook_delta", "seq": 4523, "price": 51, "quantity": -200, "ts": 1756428384.061737, "side": "sell"}
{"type": "orderbook_delta", "seq": 4524, "price": 53, "quantity": -1250, "ts": 1756428384.066242, "side": "sell"}
{"type": "orderbook_delta", "seq": 4525, "price": 42, "quantity": -500, "ts": 1756428384.067501, "side": "buy"}
{"type": "orderbook_delta", "seq": 4526, "price": 38, "quantity": -1250, "ts": 1756428384.082809, "side": "buy"}
{"type": "orderbook_delta", "seq": 4527, "price": 40, "quantity": 1250, "ts": 1756428384.126286, "side": "buy"}
{"type": "orderbook_delta", "seq": 4528, "price": 55, "quantity": 1250, "ts": 1756428384.127426, "side": "sell"}
{"type": "orderbook_delta", "seq": 4529, "price": 44, "quantity": 500, "ts": 1756428384.128592, "side": "buy"}
{"type": "orderbook_delta", "seq": 4530, "price": 42, "quantity": 200, "ts": 1756428384.128822, "side": "buy"}
{"type": "orderbook_delta", "seq": 4531, "price": 53, "quantity": 200, "ts": 1756428384.12959, "side": "sell"}
{"type": "orderbook_delta", "seq": 4532, "price": 32, "quantity": 250, "ts": 1756428384.139838, "side": "buy"}
{"type": "orderbook_delta", "seq": 4533, "price": 42, "quantity": -250, "ts": 1756428384.140055, "side": "buy"}
{"type": "orderbook_delta", "seq": 4534, "price": 44, "quantity": -250, "ts": 1756428384.15698, "side": "buy"}
{"type": "orderbook_delta", "seq": 4535, "price": 34, "quantity": 250, "ts": 1756428384.157057, "side": "buy"}
{"type": "orderbook_delta", "seq": 4536, "price": 42, "quantity": -200, "ts": 1756428384.175034, "side": "buy"}
{"type": "orderbook_delta", "seq": 4537, "price": 44, "quantity": -500, "ts": 1756428384.187287, "side": "buy"}
{"type": "orderbook_delta", "seq": 4538, "price": 41, "quantity": 200, "ts": 1756428384.21491, "side": "buy"}
{"type": "orderbook_delta", "seq": 4539, "price": 41, "quantity": 500, "ts": 1756428384.229438, "side": "buy"}
{"type": "trade", "seq": 55, "price": 50, "quantity": 3, "ts": 1756428384.44949, "side": "buy"}
{"type": "orderbook_delta", "seq": 4540, "price": 50, "quantity": 0, "ts": 1756428384.44949, "side": "sell"}
{"type": "orderbook_delta", "seq": 4541, "price": 42, "quantity": 250, "ts": 1756428384.566792, "side": "buy"}
{"type": "orderbook_delta", "seq": 4542, "price": 32, "quantity": -250, "ts": 1756428384.568686, "side": "buy"}
{"type": "orderbook_delta", "seq": 4543, "price": 41, "quantity": -500, "ts": 1756428384.602076, "side": "buy"}
{"type": "orderbook_delta", "seq": 4544, "price": 41, "quantity": -200, "ts": 1756428384.602488, "side": "buy"}
{"type": "orderbook_delta", "seq": 4545, "price": 42, "quantity": 200, "ts": 1756428384.657039, "side": "buy"}
{"type": "orderbook_delta", "seq": 4546, "price": 43, "quantity": 500, "ts": 1756428384.657325, "side": "buy"}
{"type": "orderbook_delta", "seq": 4547, "price": 55, "quantity": -1250, "ts": 1756428384.957496, "side": "sell"}
{"type": "orderbook_delta", "seq": 4548, "price": 53, "quantity": -200, "ts": 1756428384.957557, "side": "sell"}
{"type": "orderbook_delta", "seq": 4549, "price": 42, "quantity": -200, "ts": 1756428384.957611, "side": "buy"}
{"type": "orderbook_delta", "seq": 4550, "price": 40, "quantity": -1250, "ts": 1756428384.959084, "side": "buy"}
{"type": "orderbook_delta", "seq": 4551, "price": 50, "quantity": -500, "ts": 1756428384.960746, "side": "sell"}
{"type": "orderbook_delta", "seq": 4552, "price": 55, "quantity": -200, "ts": 1756428384.987594, "side": "sell"}
{"type": "orderbook_delta", "seq": 4553, "price": 56, "quantity": 200, "ts": 1756428384.987594, "side": "sell"}
{"type": "orderbook_delta", "seq": 4554, "price": 54, "quantity": 200, "ts": 1756428385.016301, "side": "sell"}
{"type": "orderbook_delta", "seq": 4555, "price": 51, "quantity": 500, "ts": 1756428385.017054, "side": "sell"}
{"type": "orderbook_delta", "seq": 4556, "price": 56, "quantity": 1250, "ts": 1756428385.017576, "side": "sell"}
{"type": "orderbook_delta", "seq": 4557, "price": 43, "quantity": 200, "ts": 1756428385.018032, "side": "buy"}
{"type": "orderbook_delta", "seq": 4558, "price": 41, "quantity": 1250, "ts": 1756428385.020349, "side": "buy"}
{"type": "orderbook_delta", "seq": 4559, "price": 56, "quantity": -200, "ts": 1756428385.050692, "side": "sell"}
{"type": "orderbook_delta", "seq": 4560, "price": 57, "quantity": 200, "ts": 1756428385.050692, "side": "sell"}
{"type": "orderbook_delta", "seq": 4561, "price": 44, "quantity": 250, "ts": 1756428385.131479, "side": "buy"}
{"type": "orderbook_delta", "seq": 4562, "price": 34, "quantity": -250, "ts": 1756428385.136271, "side": "buy"}
{"type": "orderbook_delta", "seq": 4563, "price": 43, "quantity": -500, "ts": 1756428385.189954, "side": "buy"}
{"type": "orderbook_delta", "seq": 4564, "price": 45, "quantity": 500, "ts": 1756428385.249463, "side": "buy"}
{"type": "orderbook_delta", "seq": 4565, "price": 52, "quantity": -100, "ts": 1756428385.387069, "side": "sell"}
{"type": "orderbook_delta", "seq": 4566, "price": 49, "quantity": -100, "ts": 1756428385.814968, "side": "buy"}
{"type": "orderbook_delta", "seq": 4567, "price": 50, "quantity": -847, "ts": 1756428386.133391, "side": "sell"}
{"type": "orderbook_delta", "seq": 4568, "price": 62, "quantity": 250, "ts": 1756428386.13366, "side": "sell"}
{"type": "orderbook_delta", "seq": 4569, "price": 57, "quantity": -200, "ts": 1756428386.157974, "side": "sell"}
{"type": "orderbook_delta", "seq": 4570, "price": 56, "quantity": 200, "ts": 1756428386.157974, "side": "sell"}
{"type": "orderbook_delta", "seq": 4571, "price": 52, "quantity": -250, "ts": 1756428386.165826, "side": "sell"}
{"type": "orderbook_delta", "seq": 4572, "price": 51, "quantity": 847, "ts": 1756428386.202789, "side": "sell"}
{"type": "orderbook_delta", "seq": 4573, "price": 56, "quantity": -200, "ts": 1756428386.21079, "side": "sell"}
{"type": "orderbook_delta", "seq": 4574, "price": 54, "quantity": 200, "ts": 1756428386.21079, "side": "sell"}
{"type": "orderbook_delta", "seq": 4575, "price": 51, "quantity": -500, "ts": 1756428386.298944, "side": "sell"}
{"type": "orderbook_delta", "seq": 4576, "price": 51, "quantity": 500, "ts": 1756428386.345842, "side": "sell"}
{"type": "orderbook_delta", "seq": 4577, "price": 79, "quantity": -8000, "ts": 1756428386.510772, "side": "sell"}
{"type": "orderbook_delta", "seq": 4578, "price": 80, "quantity": 8000, "ts": 1756428386.546338, "side": "sell"}
{"type": "orderbook_delta", "seq": 4579, "price": 62, "quantity": -250, "ts": 1756428387.103826, "side": "sell"}
{"type": "orderbook_delta", "seq": 4580, "price": 52, "quantity": 250, "ts": 1756428387.114783, "side": "sell"}
{"type": "orderbook_delta", "seq": 4581, "price": 54, "quantity": -200, "ts": 1756428387.491579, "side": "sell"}
{"type": "orderbook_delta", "seq": 4582, "price": 41, "quantity": -1250, "ts": 1756428387.491847, "side": "buy"}
{"type": "orderbook_delta", "seq": 4583, "price": 43, "quantity": -200, "ts": 1756428387.491971, "side": "buy"}
{"type": "orderbook_delta", "seq": 4584, "price": 80, "quantity": -8000, "ts": 1756428387.492093, "side": "sell"}
{"type": "orderbook_delta", "seq": 4585, "price": 56, "quantity": -1250, "ts": 1756428387.492896, "side": "sell"}
{"type": "orderbook_delta", "seq": 4586, "price": 79, "quantity": 8000, "ts": 1756428387.603451, "side": "sell"}
{"type": "orderbook_delta", "seq": 4587, "price": 55, "quantity": 1250, "ts": 1756428387.605831, "side": "sell"}
{"type": "orderbook_delta", "seq": 4588, "price": 42, "quantity": 200, "ts": 1756428387.60655, "side": "buy"}
{"type": "orderbook_delta", "seq": 4589, "price": 53, "quantity": 200, "ts": 1756428387.606994, "side": "sell"}
{"type": "orderbook_delta", "seq": 4590, "price": 40, "quantity": 1250, "ts": 1756428387.611649, "side": "buy"}
{"type": "orderbook_delta", "seq": 4591, "price": 53, "quantity": -200, "ts": 1756428387.760147, "side": "sell"}
{"type": "orderbook_delta", "seq": 4592, "price": 42, "quantity": -200, "ts": 1756428387.764022, "side": "buy"}
{"type": "orderbook_delta", "seq": 4593, "price": 40, "quantity": -1250, "ts": 1756428387.768865, "side": "buy"}
{"type": "orderbook_delta", "seq": 4594, "price": 41, "quantity": 1250, "ts": 1756428387.818094, "side": "buy"}
{"type": "orderbook_delta", "seq": 4595, "price": 43, "quantity": 200, "ts": 1756428387.825875, "side": "buy"}
{"type": "orderbook_delta", "seq": 4596, "price": 54, "quantity": 200, "ts": 1756428387.82637, "side": "sell"}
{"type": "orderbook_delta", "seq": 4597, "price": 45, "quantity": 0, "ts": 1756428388.193949, "side": "buy"}
{"type": "trade", "seq": 56, "price": 45, "quantity": 8, "ts": 1756428388.264655, "side": "sell"}
{"type": "orderbook_delta", "seq": 4598, "price": 55, "quantity": -1250, "ts": 1756428388.264655, "side": "sell"}
{"type": "orderbook_delta", "seq": 4599, "price": 56, "quantity": 1250, "ts": 1756428388.326167, "side": "sell"}
{"type": "orderbook_delta", "seq": 4600, "price": 79, "quantity": -8000, "ts": 1756428388.69069, "side": "sell"}
{"type": "orderbook_delta", "seq": 4601, "price": 80, "quantity": 8000, "ts": 1756428388.736438, "side": "sell"}
{"type": "orderbook_delta", "seq": 4602, "price": 54, "quantity": -200, "ts": 1756428388.98139, "side": "sell"}
{"type": "orderbook_delta", "seq": 4603, "price": 56, "quantity": 200, "ts": 1756428388.98139, "side": "sell"}
{"type": "orderbook_delta", "seq": 4604, "price": 62, "quantity": 250, "ts": 1756428389.140016, "side": "sell"}
{"type": "orderbook_delta", "seq": 4605, "price": 52, "quantity": -250, "ts": 1756428389.144252, "side": "sell"}
{"type": "orderbook_delta", "seq": 4606, "price": 51, "quantity": -500, "ts": 1756428389.359522, "side": "sell"}
{"type": "orderbook_delta", "seq": 4607, "price": 46, "quantity": 100, "ts": 1756428389.361455, "side": "buy"}
{"type": "orderbook_delta", "seq": 4608, "price": 53, "quantity": 500, "ts": 1756428389.412252, "side": "sell"}
{"type": "orderbook_delta", "seq": 4609, "price": 45, "quantity": -492, "ts": 1756428389.42801, "side": "buy"}
{"type": "orderbook_delta", "seq": 4610, "price": 43, "quantity": -200, "ts": 1756428389.435748, "side": "buy"}
{"type": "orderbook_delta", "seq": 4611, "price": 54, "quantity": -200, "ts": 1756428389.435813, "side": "sell"}
{"type": "orderbook_delta", "seq": 4612, "price": 41, "quantity": -1250, "ts": 1756428389.436659, "side": "buy"}
{"type": "orderbook_delta", "seq": 4613, "price": 56, "quantity": -1250, "ts": 1756428389.43727, "side": "sell"}
{"type": "orderbook_delta", "seq": 4614, "price": 80, "quantity": -8000, "ts": 1756428389.437339, "side": "sell"}
{"type": "orderbook_delta", "seq": 4615, "price": 47, "quantity": 500, "ts": 1756428389.466613, "side": "buy"}
{"type": "orderbook_delta", "seq": 4616, "price": 55, "quantity": 200, "ts": 1756428389.480677, "side": "sell"}
{"type": "orderbook_delta", "seq": 4617, "price": 42, "quantity": 1250, "ts": 1756428389.480992, "side": "buy"}
{"type": "orderbook_delta", "seq": 4618, "price": 57, "quantity": 1250, "ts": 1756428389.481234, "side": "sell"}
{"type": "orderbook_delta", "seq": 4619, "price": 44, "quantity": 200, "ts": 1756428389.483142, "side": "buy"}
{"type": "orderbook_delta", "seq": 4620, "price": 98, "quantity": 8000, "ts": 1756428389.485535, "side": "sell"}
{"type": "orderbook_delta", "seq": 4621, "price": 47, "quantity": -500, "ts": 1756428389.912197, "side": "buy"}
{"type": "orderbook_delta", "seq": 4622, "price": 46, "quantity": 500, "ts": 1756428390.006021, "side": "buy"}
{"type": "orderbook_delta", "seq": 4623, "price": 48, "quantity": 100, "ts": 1756428390.006903, "side": "buy"}
{"type": "orderbook_delta", "seq": 4624, "price": 51, "quantity": -847, "ts": 1756428390.038478, "side": "sell"}
{"type": "orderbook_delta", "seq": 4625, "price": 54, "quantity": 100, "ts": 1756428390.064233, "side": "sell"}
{"type": "orderbook_delta", "seq": 4626, "price": 52, "quantity": 847, "ts": 1756428390.084016, "side": "sell"}
{"type": "orderbook_delta", "seq": 4627, "price": 98, "quantity": -8000, "ts": 1756428390.106134, "side": "sell"}
{"type": "orderbook_delta", "seq": 4628, "price": 53, "quantity": -500, "ts": 1756428390.1111, "side": "sell"}
{"type": "orderbook_delta", "seq": 4629, "price": 46, "quantity": 250, "ts": 1756428390.116304, "side": "buy"}
{"type": "orderbook_delta", "seq": 4630, "price": 36, "quantity": -250, "ts": 1756428390.116564, "side": "buy"}
{"type": "orderbook_delta", "seq": 4631, "price": 48, "quantity": -100, "ts": 1756428390.138771, "side": "buy"}
{"type": "orderbook_delta", "seq": 4632, "price": 45, "quantity": 100, "ts": 1756428390.138771, "side": "buy"}
{"type": "orderbook_delta", "seq": 4633, "price": 52, "quantity": 500, "ts": 1756428390.170366, "side": "sell"}
{"type": "orderbook_delta", "seq": 4634, "price": 80, "quantity": 8000, "ts": 1756428390.194284, "side": "sell"}
{"type": "orderbook_delta", "seq": 4635, "price": 56, "quantity": -200, "ts": 1756428390.431217, "side": "sell"}
{"type": "orderbook_delta", "seq": 4636, "price": 54, "quantity": 200, "ts": 1756428390.431217, "side": "sell"}
{"type": "orderbook_delta", "seq": 4637, "price": 54, "quantity": -100, "ts": 1756428390.536798, "side": "sell"}
{"type": "orderbook_delta", "seq": 4638, "price": 51, "quantity": 100, "ts": 1756428390.536798, "side": "sell"}
{"type": "orderbook_delta", "seq": 4639, "price": 52, "quantity": -847, "ts": 1756428391.143855, "side": "sell"}
{"type": "orderbook_delta", "seq": 4640, "price": 46, "quantity": -250, "ts": 1756428391.156494, "side": "buy"}
{"type": "orderbook_delta", "seq": 4641, "price": 36, "quantity": 250, "ts": 1756428391.156579, "side": "buy"}
{"type": "orderbook_delta", "seq": 4642, "price": 52, "quantity": -500, "ts": 1756428391.175923, "side": "sell"}
{"type": "orderbook_delta", "seq": 4643, "price": 52, "quantity": 250, "ts": 1756428391.176585, "side": "sell"}
{"type": "orderbook_delta", "seq": 4644, "price": 62, "quantity": -250, "ts": 1756428391.196087, "side": "sell"}
{"type": "orderbook_delta", "seq": 4645, "price": 80, "quantity": -8000, "ts": 1756428391.200978, "side": "sell"}
{"type": "orderbook_delta", "seq": 4646, "price": 44, "quantity": -200, "ts": 1756428391.201712, "side": "buy"}
{"type": "orderbook_delta", "seq": 4647, "price": 42, "quantity": -1250, "ts": 1756428391.202447, "side": "buy"}
{"type": "orderbook_delta", "seq": 4648, "price": 57, "quantity": -1250, "ts": 1756428391.202894, "side": "sell"}
{"type": "orderbook_delta", "seq": 4649, "price": 55, "quantity": -200, "ts": 1756428391.20734, "side": "sell"}
{"type": "orderbook_delta", "seq": 4650, "price": 51, "quantity": 500, "ts": 1756428391.219202, "side": "sell"}
{"type": "orderbook_delta", "seq": 4651, "price": 46, "quantity": -500, "ts": 1756428391.224333, "side": "buy"}
{"type": "orderbook_delta", "seq": 4652, "price": 51, "quantity": 847, "ts": 1756428391.247324, "side": "sell"}
{"type": "orderbook_delta", "seq": 4653, "price": 45, "quantity": 500, "ts": 1756428391.283202, "side": "buy"}
{"type": "orderbook_delta", "seq": 4654, "price": 41, "quantity": 1250, "ts": 1756428391.284005, "side": "buy"}
{"type": "orderbook_delta", "seq": 4655, "price": 79, "quantity": 8000, "ts": 1756428391.284337, "side": "sell"}
{"type": "orderbook_delta", "seq": 4656, "price": 43, "quantity": 200, "ts": 1756428391.284685, "side": "buy"}
{"type": "orderbook_delta", "seq": 4657, "price": 56, "quantity": 1250, "ts": 1756428391.286669, "side": "sell"}
{"type": "orderbook_delta", "seq": 4658, "price": 54, "quantity": 200, "ts": 1756428391.312968, "side": "sell"}
{"type": "orderbook_delta", "seq": 4659, "price": 51, "quantity": -100, "ts": 1756428391.662643, "side": "sell"}
{"type": "orderbook_delta", "seq": 4660, "price": 52, "quantity": 100, "ts": 1756428391.662643, "side": "sell"}
{"type": "trade", "seq": 57, "price": 46, "quantity": 89, "ts": 1756428391.852988, "side": "sell"}
{"type": "orderbook_delta", "seq": 4661, "price": 46, "quantity": 0, "ts": 1756428391.852988, "side": "buy"}
{"type": "orderbook_delta", "seq": 4662, "price": 45, "quantity": -100, "ts": 1756428391.962188, "side": "buy"}
{"type": "orderbook_delta", "seq": 4663, "price": 46, "quantity": 100, "ts": 1756428391.962188, "side": "buy"}
{"type": "orderbook_delta", "seq": 4664, "price": 51, "quantity": -847, "ts": 1756428393.127111, "side": "sell"}
{"type": "orderbook_delta", "seq": 4665, "price": 50, "quantity": 847, "ts": 1756428393.170371, "side": "sell"}
{"type": "orderbook_delta", "seq": 4666, "price": 54, "quantity": -200, "ts": 1756428393.241869, "side": "sell"}
{"type": "orderbook_delta", "seq": 4667, "price": 43, "quantity": -200, "ts": 1756428393.241943, "side": "buy"}
{"type": "orderbook_delta", "seq": 4668, "price": 41, "quantity": -1250, "ts": 1756428393.24221, "side": "buy"}
{"type": "orderbook_delta", "seq": 4669, "price": 56, "quantity": -1250, "ts": 1756428393.244535, "side": "sell"}
{"type": "orderbook_delta", "seq": 4670, "price": 51, "quantity": -500, "ts": 1756428393.253136, "side": "sell"}
{"type": "orderbook_delta", "seq": 4671, "price": 45, "quantity": -500, "ts": 1756428393.253409, "side": "buy"}
{"type": "orderbook_delta", "seq": 4672, "price": 41, "quantity": 200, "ts": 1756428393.279867, "side": "buy"}
{"type": "orderbook_delta", "seq": 4673, "price": 52, "quantity": 200, "ts": 1756428393.28138, "side": "sell"}
{"type": "orderbook_delta", "seq": 4674, "price": 39, "quantity": 1250, "ts": 1756428393.282485, "side": "buy"}
{"type": "orderbook_delta", "seq": 4675, "price": 54, "quantity": 1250, "ts": 1756428393.284758, "side": "sell"}
{"type": "orderbook_delta", "seq": 4676, "price": 43, "quantity": 500, "ts": 1756428393.28567, "side": "buy"}
{"type": "orderbook_delta", "seq": 4677, "price": 50, "quantity": 500, "ts": 1756428393.288508, "side": "sell"}
{"type": "orderbook_delta", "seq": 4678, "price": 46, "quantity": -100, "ts": 1756428393.300864, "side": "buy"}
{"type": "orderbook_delta", "seq": 4679, "price": 45, "quantity": 100, "ts": 1756428393.300864, "side": "buy"}
{"type": "orderbook_delta", "seq": 4680, "price": 50, "quantity": -500, "ts": 1756428393.331561, "side": "sell"}
{"type": "orderbook_delta", "seq": 4681, "price": 45, "quantity": -100, "ts": 1756428393.34725, "side": "buy"}
{"type": "orderbook_delta", "seq": 4682, "price": 51, "quantity": 500, "ts": 1756428393.361466, "side": "sell"}
{"type": "orderbook_delta", "seq": 4683, "price": 52, "quantity": -100, "ts": 1756428393.393044, "side": "sell"}
{"type": "orderbook_delta", "seq": 4684, "price": 49, "quantity": 100, "ts": 1756428393.393044, "side": "sell"}
{"type": "orderbook_delta", "seq": 4685, "price": 51, "quantity": -500, "ts": 1756428393.39743, "side": "sell"}
{"type": "orderbook_delta", "seq": 4686, "price": 54, "quantity": -200, "ts": 1756428393.399308, "side": "sell"}
{"type": "orderbook_delta", "seq": 4687, "price": 52, "quantity": 200, "ts": 1756428393.399308, "side": "sell"}
{"type": "orderbook_delta", "seq": 4688, "price": 41, "quantity": -200, "ts": 1756428393.409236, "side": "buy"}
{"type": "orderbook_delta", "seq": 4689, "price": 52, "quantity": -200, "ts": 1756428393.411529, "side": "sell"}
{"type": "orderbook_delta", "seq": 4690, "price": 39, "quantity": -1250, "ts": 1756428393.411598, "side": "buy"}
{"type": "orderbook_delta", "seq": 4691, "price": 54, "quantity": -1250, "ts": 1756428393.411937, "side": "sell"}
{"type": "orderbook_delta", "seq": 4692, "price": 49, "quantity": 500, "ts": 1756428393.433592, "side": "sell"}
{"type": "orderbook_delta", "seq": 4693, "price": 40, "quantity": 200, "ts": 1756428393.464965, "side": "buy"}
{"type": "orderbook_delta", "seq": 4694, "price": 38, "quantity": 1250, "ts": 1756428393.468712, "side": "buy"}
{"type": "orderbook_delta", "seq": 4695, "price": 51, "quantity": 200, "ts": 1756428393.470483, "side": "sell"}
{"type": "orderbook_delta", "seq": 4696, "price": 53, "quantity": 1250, "ts": 1756428393.471859, "side": "sell"}
{"type": "orderbook_delta", "seq": 4697, "price": 49, "quantity": -100, "ts": 1756428393.637514, "side": "sell"}
{"type": "orderbook_delta", "seq": 4698, "price": 48, "quantity": 100, "ts": 1756428393.637514, "side": "sell"}
{"type": "orderbook_delta", "seq": 4699, "price": 53, "quantity": -1250, "ts": 1756428393.643397, "side": "sell"}
{"type": "orderbook_delta", "seq": 4700, "price": 49, "quantity": -500, "ts": 1756428393.643454, "side": "sell"}
{"type": "orderbook_delta", "seq": 4701, "price": 43, "quantity": -500, "ts": 1756428393.644651, "side": "buy"}
{"type": "orderbook_delta", "seq": 4702, "price": 48, "quantity": -100, "ts": 1756428393.687059, "side": "sell"}
{"type": "orderbook_delta", "seq": 4703, "price": 49, "quantity": 100, "ts": 1756428393.687059, "side": "sell"}
{"type": "orderbook_delta", "seq": 4704, "price": 42, "quantity": 500, "ts": 1756428393.687343, "side": "buy"}
{"type": "orderbook_delta", "seq": 4705, "price": 48, "quantity": 500, "ts": 1756428393.687778, "side": "sell"}
{"type": "orderbook_delta", "seq": 4706, "price": 34, "quantity": 250, "ts": 1756428393.688021, "side": "buy"}
{"type": "orderbook_delta", "seq": 4707, "price": 44, "quantity": -250, "ts": 1756428393.688209, "side": "buy"}
{"type": "orderbook_delta", "seq": 4708, "price": 52, "quantity": 1250, "ts": 1756428393.69703, "side": "sell"}
{"type": "orderbook_delta", "seq": 4709, "price": 44, "quantity": 250, "ts": 1756428393.774597, "side": "buy"}
{"type": "orderbook_delta", "seq": 4710, "price": 34, "quantity": -250, "ts": 1756428393.778328, "side": "buy"}
{"type": "orderbook_delta", "seq": 4711, "price": 50, "quantity": -847, "ts": 1756428394.13103, "side": "sell"}
{"type": "orderbook_delta", "seq": 4712, "price": 50, "quantity": 250, "ts": 1756428394.166783, "side": "sell"}
{"type": "orderbook_delta", "seq": 4713, "price": 60, "quantity": -250, "ts": 1756428394.186115, "side": "sell"}
{"type": "orderbook_delta", "seq": 4714, "price": 34, "quantity": 250, "ts": 1756428394.205556, "side": "buy"}
{"type": "orderbook_delta", "seq": 4715, "price": 44, "quantity": -250, "ts": 1756428394.206478, "side": "buy"}
{"type": "orderbook_delta", "seq": 4716, "price": 46, "quantity": -11, "ts": 1756428394.260163, "side": "buy"}
{"type": "orderbook_delta", "seq": 4717, "price": 48, "quantity": 847, "ts": 1756428394.272893, "side": "sell"}
{"type": "orderbook_delta", "seq": 4718, "price": 47, "quantity": 100, "ts": 1756428394.537334, "side": "buy"}
{"type": "orderbook_delta", "seq": 4719, "price": 40, "quantity": 100, "ts": 1756428394.86637, "side": "buy"}
{"type": "orderbook_delta", "seq": 4720, "price": 49, "quantity": -100, "ts": 1756428395.034817, "side": "sell"}
{"type": "orderbook_delta", "seq": 4721, "price": 48, "quantity": 100, "ts": 1756428395.034817, "side": "sell"}
{"type": "orderbook_delta", "seq": 4722, "price": 40, "quantity": -200, "ts": 1756428395.079543, "side": "buy"}
{"type": "orderbook_delta", "seq": 4723, "price": 38, "quantity": -1250, "ts": 1756428395.079607, "side": "buy"}
{"type": "orderbook_delta", "seq": 4724, "price": 51, "quantity": -200, "ts": 1756428395.080173, "side": "sell"}
{"type": "orderbook_delta", "seq": 4725, "price": 42, "quantity": -500, "ts": 1756428395.080249, "side": "buy"}
{"type": "orderbook_delta", "seq": 4726, "price": 52, "quantity": -1250, "ts": 1756428395.082991, "side": "sell"}
{"type": "orderbook_delta", "seq": 4727, "price": 52, "quantity": -200, "ts": 1756428395.106388, "side": "sell"}
{"type": "orderbook_delta", "seq": 4728, "price": 50, "quantity": 200, "ts": 1756428395.106388, "side": "sell"}
{"type": "orderbook_delta", "seq": 4729, "price": 40, "quantity": -100, "ts": 1756428395.119591, "side": "buy"}
{"type": "orderbook_delta", "seq": 4730, "price": 42, "quantity": 100, "ts": 1756428395.119591, "side": "buy"}
{"type": "orderbook_delta", "seq": 4731, "price": 50, "quantity": 200, "ts": 1756428395.12589, "side": "sell"}
{"type": "orderbook_delta", "seq": 4732, "price": 41, "quantity": 500, "ts": 1756428395.127846, "side": "buy"}
{"type": "orderbook_delta", "seq": 4733, "price": 51, "quantity": 1250, "ts": 1756428395.128107, "side": "sell"}
{"type": "orderbook_delta", "seq": 4734, "price": 39, "quantity": 200, "ts": 1756428395.130457, "side": "buy"}
{"type": "orderbook_delta", "seq": 4735, "price": 37, "quantity": 1250, "ts": 1756428395.131035, "side": "buy"}
{"type": "orderbook_delta", "seq": 4736, "price": 42, "quantity": -100, "ts": 1756428395.169141, "side": "buy"}
{"type": "orderbook_delta", "seq": 4737, "price": 41, "quantity": 100, "ts": 1756428395.169141, "side": "buy"}
{"type": "orderbook_delta", "seq": 4738, "price": 51, "quantity": -1250, "ts": 1756428395.194655, "side": "sell"}
{"type": "orderbook_delta", "seq": 4739, "price": 48, "quantity": -100, "ts": 1756428395.216826, "side": "sell"}
{"type": "orderbook_delta", "seq": 4740, "price": 50, "quantity": 100, "ts": 1756428395.216826, "side": "sell"}
{"type": "orderbook_delta", "seq": 4741, "price": 52, "quantity": 1250, "ts": 1756428395.234926, "side": "sell"}
{"type": "orderbook_delta", "seq": 4742, "price": 42, "quantity": -250, "ts": 1756428396.135267, "side": "buy"}
{"type": "orderbook_delta", "seq": 4743, "price": 32, "quantity": 250, "ts": 1756428396.136252, "side": "buy"}
{"type": "orderbook_delta", "seq": 4744, "price": 41, "quantity": -100, "ts": 1756428396.423952, "side": "buy"}
{"type": "orderbook_delta", "seq": 4745, "price": 40, "quantity": 100, "ts": 1756428396.423952, "side": "buy"}
{"type": "orderbook_delta", "seq": 4746, "price": 52, "quantity": -1250, "ts": 1756428396.458664, "side": "sell"}
{"type": "orderbook_delta", "seq": 4747, "price": 39, "quantity": -200, "ts": 1756428396.459242, "side": "buy"}
{"type": "orderbook_delta", "seq": 4748, "price": 37, "quantity": -1250, "ts": 1756428396.459296, "side": "buy"}
{"type": "orderbook_delta", "seq": 4749, "price": 50, "quantity": -200, "ts": 1756428396.459842, "side": "sell"}
{"type": "orderbook_delta", "seq": 4750, "price": 51, "quantity": 1250, "ts": 1756428396.504652, "side": "sell"}
{"type": "orderbook_delta", "seq": 4751, "price": 36, "quantity": 1250, "ts": 1756428396.504958, "side": "buy"}
{"type": "orderbook_delta", "seq": 4752, "price": 49, "quantity": 200, "ts": 1756428396.505215, "side": "sell"}
{"type": "orderbook_delta", "seq": 4753, "price": 38, "quantity": 200, "ts": 1756428396.505505, "side": "buy"}
{"type": "orderbook_delta", "seq": 4754, "price": 50, "quantity": -200, "ts": 1756428396.856531, "side": "sell"}
{"type": "orderbook_delta", "seq": 4755, "price": 49, "quantity": 200, "ts": 1756428396.856531, "side": "sell"}
{"type": "orderbook_delta", "seq": 4756, "price": 41, "quantity": -500, "ts": 1756428396.8981, "side": "buy"}
{"type": "orderbook_delta", "seq": 4757, "price": 40, "quantity": 500, "ts": 1756428396.931916, "side": "buy"}
{"type": "orderbook_delta", "seq": 4758, "price": 48, "quantity": 0, "ts": 1756428397.066615, "side": "sell"}
{"type": "trade", "seq": 58, "price": 48, "quantity": 3, "ts": 1756428397.16573, "side": "buy"}
{"type": "orderbook_delta", "seq": 4759, "price": 40, "quantity": -100, "ts": 1756428397.16573, "side": "buy"}
{"type": "orderbook_delta", "seq": 4760, "price": 41, "quantity": 100, "ts": 1756428397.16573, "side": "buy"}
{"type": "orderbook_delta", "seq": 4761, "price": 49, "quantity": -200, "ts": 1756428397.565674, "side": "sell"}
{"type": "orderbook_delta", "seq": 4762, "price": 50, "quantity": 200, "ts": 1756428397.565674, "side": "sell"}
{"type": "orderbook_delta", "seq": 4763, "price": 50, "quantity": -200, "ts": 1756428397.835622, "side": "sell"}
{"type": "orderbook_delta", "seq": 4764, "price": 51, "quantity": 200, "ts": 1756428397.835622, "side": "sell"}
{"type": "orderbook_delta", "seq": 4765, "price": 50, "quantity": -100, "ts": 1756428398.092638, "side": "sell"}
{"type": "orderbook_delta", "seq": 4766, "price": 51, "quantity": 100, "ts": 1756428398.092638, "side": "sell"}
{"type": "orderbook_delta", "seq": 4767, "price": 42, "quantity": 250, "ts": 1756428398.146051, "side": "buy"}
{"type": "orderbook_delta", "seq": 4768, "price": 32, "quantity": -250, "ts": 1756428398.146994, "side": "buy"}
{"type": "orderbook_delta", "seq": 4769, "price": 51, "quantity": -100, "ts": 1756428398.15487, "side": "sell"}
{"type": "orderbook_delta", "seq": 4770, "price": 52, "quantity": 100, "ts": 1756428398.15487, "side": "sell"}
{"type": "orderbook_delta", "seq": 4771, "price": 60, "quantity": 250, "ts": 1756428398.702969, "side": "sell"}
{"type": "orderbook_delta", "seq": 4772, "price": 48, "quantity": -847, "ts": 1756428398.703228, "side": "sell"}
{"type": "orderbook_delta", "seq": 4773, "price": 49, "quantity": -200, "ts": 1756428398.704304, "side": "sell"}
{"type": "orderbook_delta", "seq": 4774, "price": 48, "quantity": -497, "ts": 1756428398.704648, "side": "sell"}
{"type": "orderbook_delta", "seq": 4775, "price": 38, "quantity": -200, "ts": 1756428398.704944, "side": "buy"}
{"type": "orderbook_delta", "seq": 4776, "price": 40, "quantity": -500, "ts": 1756428398.705001, "side": "buy"}
{"type": "orderbook_delta", "seq": 4777, "price": 36, "quantity": -1250, "ts": 1756428398.705048, "side": "buy"}
{"type": "orderbook_delta", "seq": 4778, "price": 51, "quantity": -1250, "ts": 1756428398.705392, "side": "sell"}
{"type": "orderbook_delta", "seq": 4779, "price": 50, "quantity": -250, "ts": 1756428398.783909, "side": "sell"}
{"type": "orderbook_delta", "seq": 4780, "price": 49, "quantity": 500, "ts": 1756428398.784611, "side": "sell"}
{"type": "orderbook_delta", "seq": 4781, "price": 32, "quantity": 250, "ts": 1756428398.784898, "side": "buy"}
{"type": "orderbook_delta", "seq": 4782, "price": 42, "quantity": -250, "ts": 1756428398.785103, "side": "buy"}
{"type": "orderbook_delta", "seq": 4783, "price": 43, "quantity": 500, "ts": 1756428398.785309, "side": "buy"}
{"type": "orderbook_delta", "seq": 4784, "price": 39, "quantity": 1250, "ts": 1756428398.785788, "side": "buy"}
{"type": "orderbook_delta", "seq": 4785, "price": 41, "quantity": 200, "ts": 1756428398.786347, "side": "buy"}
{"type": "orderbook_delta", "seq": 4786, "price": 53, "quantity": 1250, "ts": 1756428398.786875, "side": "sell"}
{"type": "orderbook_delta", "seq": 4787, "price": 52, "quantity": 200, "ts": 1756428398.787114, "side": "sell"}
{"type": "orderbook_delta", "seq": 4788, "price": 49, "quantity": -500, "ts": 1756428398.815328, "side": "sell"}
{"type": "orderbook_delta", "seq": 4789, "price": 49, "quantity": 847, "ts": 1756428398.824783, "side": "sell"}
{"type": "orderbook_delta", "seq": 4790, "price": 43, "quantity": -500, "ts": 1756428398.835683, "side": "buy"}
{"type": "orderbook_delta", "seq": 4791, "price": 49, "quantity": 500, "ts": 1756428398.850757, "side": "sell"}
{"type": "orderbook_delta", "seq": 4792, "price": 42, "quantity": 250, "ts": 1756428398.857887, "side": "buy"}
{"type": "orderbook_delta", "seq": 4793, "price": 32, "quantity": -250, "ts": 1756428398.858779, "side": "buy"}
{"type": "orderbook_delta", "seq": 4794, "price": 42, "quantity": 500, "ts": 1756428398.8768, "side": "buy"}
{"type": "orderbook_delta", "seq": 4795, "price": 41, "quantity": -200, "ts": 1756428398.889539, "side": "buy"}
{"type": "orderbook_delta", "seq": 4796, "price": 39, "quantity": -1250, "ts": 1756428398.900097, "side": "buy"}
{"type": "orderbook_delta", "seq": 4797, "price": 41, "quantity": -100, "ts": 1756428398.908742, "side": "buy"}
{"type": "orderbook_delta", "seq": 4798, "price": 43, "quantity": 100, "ts": 1756428398.908742, "side": "buy"}
{"type": "orderbook_delta", "seq": 4799, "price": 42, "quantity": -500, "ts": 1756428398.926174, "side": "buy"}
{"type": "orderbook_delta", "seq": 4800, "price": 43, "quantity": 500, "ts": 1756428398.963008, "side": "buy"}
{"type": "orderbook_delta", "seq": 4801, "price": 52, "quantity": -200, "ts": 1756428398.983545, "side": "sell"}
{"type": "orderbook_delta", "seq": 4802, "price": 40, "quantity": 200, "ts": 1756428399.101925, "side": "buy"}
{"type": "orderbook_delta", "seq": 4803, "price": 38, "quantity": 1250, "ts": 1756428399.102334, "side": "buy"}
{"type": "orderbook_delta", "seq": 4804, "price": 51, "quantity": 200, "ts": 1756428399.102712, "side": "sell"}
{"type": "orderbook_delta", "seq": 4805, "price": 43, "quantity": -100, "ts": 1756428399.20928, "side": "buy"}
{"type": "orderbook_delta", "seq": 4806, "price": 44, "quantity": 100, "ts": 1756428399.20928, "side": "buy"}
{"type": "orderbook_delta", "seq": 4807, "price": 47, "quantity": -100, "ts": 1756428399.512634, "side": "buy"}
{"type": "orderbook_delta", "seq": 4808, "price": 52, "quantity": -100, "ts": 1756428399.617751, "side": "sell"}
{"type": "orderbook_delta", "seq": 4809, "price": 49, "quantity": 100, "ts": 1756428399.617751, "side": "sell"}
{"type": "orderbook_delta", "seq": 4810, "price": 49, "quantity": -100, "ts": 1756428399.770714, "side": "sell"}
{"type": "orderbook_delta", "seq": 4811, "price": 51, "quantity": 100, "ts": 1756428399.770714, "side": "sell"}
{"type": "orderbook_delta", "seq": 4812, "price": 44, "quantity": -100, "ts": 1756428400.006802, "side": "buy"}
{"type": "orderbook_delta", "seq": 4813, "price": 42, "quantity": 100, "ts": 1756428400.006802, "side": "buy"}
{"type": "orderbook_delta", "seq": 4814, "price": 43, "quantity": -500, "ts": 1756428400.007794, "side": "buy"}
{"type": "orderbook_delta", "seq": 4815, "price": 49, "quantity": -500, "ts": 1756428400.008695, "side": "sell"}
{"type": "orderbook_delta", "seq": 4816, "price": 42, "quantity": 500, "ts": 1756428400.090169, "side": "buy"}
{"type": "orderbook_delta", "seq": 4817, "price": 48, "quantity": 500, "ts": 1756428400.090942, "side": "sell"}
{"type": "orderbook_delta", "seq": 4818, "price": 60, "quantity": -250, "ts": 1756428400.110138, "side": "sell"}
{"type": "orderbook_delta", "seq": 4819, "price": 50, "quantity": 250, "ts": 1756428400.123132, "side": "sell"}
{"type": "orderbook_delta", "seq": 4820, "price": 51, "quantity": -200, "ts": 1756428400.751738, "side": "sell"}
{"type": "orderbook_delta", "seq": 4821, "price": 50, "quantity": 200, "ts": 1756428400.751738, "side": "sell"}
{"type": "orderbook_delta", "seq": 4822, "price": 50, "quantity": -200, "ts": 1756428400.901021, "side": "sell"}
{"type": "orderbook_delta", "seq": 4823, "price": 52, "quantity": 200, "ts": 1756428400.901021, "side": "sell"}
{"type": "orderbook_delta", "seq": 4824, "price": 51, "quantity": -100, "ts": 1756428400.998754, "side": "sell"}
{"type": "orderbook_delta", "seq": 4825, "price": 52, "quantity": 100, "ts": 1756428400.998754, "side": "sell"}
{"type": "orderbook_delta", "seq": 4826, "price": 53, "quantity": -1250, "ts": 1756428401.486988, "side": "sell"}
{"type": "orderbook_delta", "seq": 4827, "price": 42, "quantity": -500, "ts": 1756428401.487267, "side": "buy"}
{"type": "orderbook_delta", "seq": 4828, "price": 51, "quantity": -200, "ts": 1756428401.487352, "side": "sell"}
{"type": "orderbook_delta", "seq": 4829, "price": 48, "quantity": -500, "ts": 1756428401.487402, "side": "sell"}
{"type": "orderbook_delta", "seq": 4830, "price": 38, "quantity": -1250, "ts": 1756428401.487706, "side": "buy"}
{"type": "orderbook_delta", "seq": 4831, "price": 40, "quantity": -200, "ts": 1756428401.487757, "side": "buy"}
{"type": "orderbook_delta", "seq": 4832, "price": 42, "quantity": -100, "ts": 1756428401.487773, "side": "buy"}
{"type": "orderbook_delta", "seq": 4833, "price": 43, "quantity": 100, "ts": 1756428401.487773, "side": "buy"}
{"type": "orderbook_delta", "seq": 4834, "price": 60, "quantity": 250, "ts": 1756428401.48844, "side": "sell"}
{"type": "orderbook_delta", "seq": 4835, "price": 49, "quantity": -847, "ts": 1756428401.488648, "side": "sell"}
{"type": "orderbook_delta", "seq": 4836, "price": 79, "quantity": -8000, "ts": 1756428401.488765, "side": "sell"}
{"type": "orderbook_delta", "seq": 4837, "price": 52, "quantity": -250, "ts": 1756428401.508954, "side": "sell"}
{"type": "orderbook_delta", "seq": 4838, "price": 62, "quantity": 250, "ts": 1756428401.509199, "side": "sell"}
{"type": "orderbook_delta", "seq": 4839, "price": 52, "quantity": -200, "ts": 1756428401.516521, "side": "sell"}
{"type": "orderbook_delta", "seq": 4840, "price": 54, "quantity": 200, "ts": 1756428401.516521, "side": "sell"}
{"type": "orderbook_delta", "seq": 4841, "price": 50, "quantity": -250, "ts": 1756428401.526498, "side": "sell"}
{"type": "orderbook_delta", "seq": 4842, "price": 42, "quantity": -250, "ts": 1756428401.533441, "side": "buy"}
{"type": "orderbook_delta", "seq": 4843, "price": 56, "quantity": 200, "ts": 1756428401.533585, "side": "sell"}
{"type": "orderbook_delta", "seq": 4844, "price": 43, "quantity": 200, "ts": 1756428401.534966, "side": "buy"}
{"type": "orderbook_delta", "seq": 4845, "price": 43, "quantity": 500, "ts": 1756428401.535876, "side": "buy"}
{"type": "orderbook_delta", "seq": 4846, "price": 32, "quantity": 250, "ts": 1756428401.537943, "side": "buy"}
{"type": "orderbook_delta", "seq": 4847, "price": 98, "quantity": 8000, "ts": 1756428401.538641, "side": "sell"}
{"type": "orderbook_delta", "seq": 4848, "price": 58, "quantity": 1250, "ts": 1756428401.539487, "side": "sell"}
{"type": "orderbook_delta", "seq": 4849, "price": 43, "quantity": 1250, "ts": 1756428401.540199, "side": "buy"}
{"type": "orderbook_delta", "seq": 4850, "price": 53, "quantity": 500, "ts": 1756428401.541073, "side": "sell"}
{"type": "orderbook_delta", "seq": 4851, "price": 54, "quantity": -200, "ts": 1756428401.569578, "side": "sell"}
{"type": "orderbook_delta", "seq": 4852, "price": 55, "quantity": 200, "ts": 1756428401.569578, "side": "sell"}
{"type": "orderbook_delta", "seq": 4853, "price": 43, "quantity": -100, "ts": 1756428401.581123, "side": "buy"}
{"type": "orderbook_delta", "seq": 4854, "price": 41, "quantity": 100, "ts": 1756428401.581123, "side": "buy"}
{"type": "orderbook_delta", "seq": 4855, "price": 51, "quantity": 847, "ts": 1756428401.593102, "side": "sell"}
{"type": "orderbook_delta", "seq": 4856, "price": 52, "quantity": -100, "ts": 1756428401.620125, "side": "sell"}
{"type": "orderbook_delta", "seq": 4857, "price": 53, "quantity": 100, "ts": 1756428401.620125, "side": "sell"}
{"type": "orderbook_delta", "seq": 4858, "price": 42, "quantity": 250, "ts": 1756428401.631683, "side": "buy"}
{"type": "orderbook_delta", "seq": 4859, "price": 32, "quantity": -250, "ts": 1756428401.632167, "side": "buy"}
{"type": "orderbook_delta", "seq": 4860, "price": 53, "quantity": -100, "ts": 1756428401.678649, "side": "sell"}
{"type": "orderbook_delta", "seq": 4861, "price": 54, "quantity": 100, "ts": 1756428401.678649, "side": "sell"}
{"type": "orderbook_delta", "seq": 4862, "price": 51, "quantity": -847, "ts": 1756428401.693606, "side": "sell"}
{"type": "orderbook_delta", "seq": 4863, "price": 64, "quantity": 250, "ts": 1756428401.698881, "side": "sell"}
{"type": "orderbook_delta", "seq": 4864, "price": 43, "quantity": -200, "ts": 1756428401.700135, "side": "buy"}
{"type": "orderbook_delta", "seq": 4865, "price": 43, "quantity": -500, "ts": 1756428401.701458, "side": "buy"}
{"type": "orderbook_delta", "seq": 4866, "price": 43, "quantity": -1250, "ts": 1756428401.705731, "side": "buy"}
{"type": "orderbook_delta", "seq": 4867, "price": 56, "quantity": -200, "ts": 1756428401.712268, "side": "sell"}
{"type": "orderbook_delta", "seq": 4868, "price": 58, "quantity": -1250, "ts": 1756428401.712318, "side": "sell"}
{"type": "orderbook_delta", "seq": 4869, "price": 53, "quantity": -500, "ts": 1756428401.71287, "side": "sell"}
{"type": "orderbook_delta", "seq": 4870, "price": 54, "quantity": -250, "ts": 1756428401.712903, "side": "sell"}
{"type": "orderbook_delta", "seq": 4871, "price": 12, "quantity": -8000, "ts": 1756428401.71493, "side": "buy"}
{"type": "orderbook_delta", "seq": 4872, "price": 32, "quantity": 250, "ts": 1756428401.739114, "side": "buy"}
{"type": "orderbook_delta", "seq": 4873, "price": 54, "quantity": -100, "ts": 1756428401.739458, "side": "sell"}
{"type": "orderbook_delta", "seq": 4874, "price": 56, "quantity": 100, "ts": 1756428401.739458, "side": "sell"}
{"type": "orderbook_delta", "seq": 4875, "price": 42, "quantity": -250, "ts": 1756428401.740041, "side": "buy"}
{"type": "orderbook_delta", "seq": 4876, "price": 43, "quantity": 1250, "ts": 1756428401.749883, "side": "buy"}
{"type": "orderbook_delta", "seq": 4877, "price": 43, "quantity": 500, "ts": 1756428401.751332, "side": "buy"}
{"type": "orderbook_delta", "seq": 4878, "price": 43, "quantity": 200, "ts": 1756428401.752212, "side": "buy"}
{"type": "orderbook_delta", "seq": 4879, "price": 55, "quantity": 500, "ts": 1756428401.775383, "side": "sell"}
{"type": "orderbook_delta", "seq": 4880, "price": 21, "quantity": 8000, "ts": 1756428401.775702, "side": "buy"}
{"type": "orderbook_delta", "seq": 4881, "price": 60, "quantity": 1250, "ts": 1756428401.775967, "side": "sell"}
{"type": "orderbook_delta", "seq": 4882, "price": 52, "quantity": 847, "ts": 1756428401.779971, "side": "sell"}
{"type": "orderbook_delta", "seq": 4883, "price": 58, "quantity": 200, "ts": 1756428401.780512, "side": "sell"}
{"type": "orderbook_delta", "seq": 4884, "price": 56, "quantity": -100, "ts": 1756428401.78933, "side": "sell"}
{"type": "orderbook_delta", "seq": 4885, "price": 57, "quantity": 100, "ts": 1756428401.78933, "side": "sell"}
{"type": "orderbook_delta", "seq": 4886, "price": 43, "quantity": -500, "ts": 1756428401.797265, "side": "buy"}
{"type": "orderbook_delta", "seq": 4887, "price": 43, "quantity": -200, "ts": 1756428401.799219, "side": "buy"}
{"type": "orderbook_delta", "seq": 4888, "price": 55, "quantity": -200, "ts": 1756428401.799318, "side": "sell"}
{"type": "orderbook_delta", "seq": 4889, "price": 56, "quantity": 200, "ts": 1756428401.799318, "side": "sell"}
{"type": "orderbook_delta", "seq": 4890, "price": 43, "quantity": -1250, "ts": 1756428401.805568, "side": "buy"}
{"type": "orderbook_delta", "seq": 4891, "price": 42, "quantity": 250, "ts": 1756428401.834586, "side": "buy"}
{"type": "orderbook_delta", "seq": 4892, "price": 32, "quantity": -250, "ts": 1756428401.834826, "side": "buy"}
{"type": "orderbook_delta", "seq": 4893, "price": 41, "quantity": 200, "ts": 1756428401.846016, "side": "buy"}
{"type": "orderbook_delta", "seq": 4894, "price": 56, "quantity": -200, "ts": 1756428401.849153, "side": "sell"}
{"type": "orderbook_delta", "seq": 4895, "price": 59, "quantity": 200, "ts": 1756428401.849153, "side": "sell"}
{"type": "orderbook_delta", "seq": 4896, "price": 41, "quantity": 1250, "ts": 1756428401.853481, "side": "buy"}
{"type": "orderbook_delta", "seq": 4897, "price": 42, "quantity": 500, "ts": 1756428401.855043, "side": "buy"}
{"type": "orderbook_delta", "seq": 4898, "price": 42, "quantity": -250, "ts": 1756428401.871805, "side": "buy"}
{"type": "orderbook_delta", "seq": 4899, "price": 41, "quantity": -200, "ts": 1756428401.905486, "side": "buy"}
{"type": "orderbook_delta", "seq": 4900, "price": 41, "quantity": -1250, "ts": 1756428401.906245, "side": "buy"}
{"type": "orderbook_delta", "seq": 4901, "price": 42, "quantity": -500, "ts": 1756428401.90678, "side": "buy"}
{"type": "orderbook_delta", "seq": 4902, "price": 41, "quantity": 1250, "ts": 1756428401.966251, "side": "buy"}
{"type": "orderbook_delta", "seq": 4903, "price": 41, "quantity": 200, "ts": 1756428401.966851, "side": "buy"}
{"type": "orderbook_delta", "seq": 4904, "price": 42, "quantity": 500, "ts": 1756428401.968415, "side": "buy"}
{"type": "orderbook_delta", "seq": 4905, "price": 57, "quantity": -100, "ts": 1756428401.995762, "side": "sell"}
{"type": "orderbook_delta", "seq": 4906, "price": 58, "quantity": 100, "ts": 1756428401.995762, "side": "sell"}
{"type": "orderbook_delta", "seq": 4907, "price": 52, "quantity": -847, "ts": 1756428402.128595, "side": "sell"}
{"type": "orderbook_delta", "seq": 4908, "price": 44, "quantity": 250, "ts": 1756428402.13624, "side": "buy"}
{"type": "orderbook_delta", "seq": 4909, "price": 56, "quantity": -250, "ts": 1756428402.167883, "side": "sell"}
{"type": "orderbook_delta", "seq": 4910, "price": 42, "quantity": -500, "ts": 1756428402.176001, "side": "buy"}
{"type": "orderbook_delta", "seq": 4911, "price": 41, "quantity": -1250, "ts": 1756428402.179914, "side": "buy"}
{"type": "orderbook_delta", "seq": 4912, "price": 41, "quantity": -200, "ts": 1756428402.182761, "side": "buy"}
{"type": "orderbook_delta", "seq": 4913, "price": 55, "quantity": -500, "ts": 1756428402.206082, "side": "sell"}
{"type": "orderbook_delta", "seq": 4914, "price": 36, "quantity": -250, "ts": 1756428402.206206, "side": "buy"}
{"type": "orderbook_delta", "seq": 4915, "price": 66, "quantity": 250, "ts": 1756428402.206733, "side": "sell"}
{"type": "orderbook_delta", "seq": 4916, "price": 45, "quantity": 500, "ts": 1756428402.220883, "side": "buy"}
{"type": "orderbook_delta", "seq": 4917, "price": 45, "quantity": 1250, "ts": 1756428402.226234, "side": "buy"}
{"type": "orderbook_delta", "seq": 4918, "price": 42, "quantity": 250, "ts": 1756428402.226957, "side": "buy"}
{"type": "orderbook_delta", "seq": 4919, "price": 45, "quantity": 200, "ts": 1756428402.234354, "side": "buy"}
{"type": "orderbook_delta", "seq": 4920, "price": 57, "quantity": 500, "ts": 1756428402.250035, "side": "sell"}
{"type": "orderbook_delta", "seq": 4921, "price": 46, "quantity": 250, "ts": 1756428402.256361, "side": "buy"}
{"type": "orderbook_delta", "seq": 4922, "price": 34, "quantity": -250, "ts": 1756428402.256824, "side": "buy"}
{"type": "orderbook_delta", "seq": 4923, "price": 45, "quantity": -200, "ts": 1756428402.290972, "side": "buy"}
{"type": "orderbook_delta", "seq": 4924, "price": 45, "quantity": -500, "ts": 1756428402.292599, "side": "buy"}
{"type": "orderbook_delta", "seq": 4925, "price": 54, "quantity": 847, "ts": 1756428402.301068, "side": "sell"}
{"type": "orderbook_delta", "seq": 4926, "price": 47, "quantity": 200, "ts": 1756428402.333247, "side": "buy"}
{"type": "orderbook_delta", "seq": 4927, "price": 47, "quantity": 500, "ts": 1756428402.335416, "side": "buy"}
{"type": "orderbook_delta", "seq": 4928, "price": 45, "quantity": -1250, "ts": 1756428402.41595, "side": "buy"}
{"type": "orderbook_delta", "seq": 4929, "price": 21, "quantity": -8000, "ts": 1756428402.417232, "side": "buy"}
{"type": "orderbook_delta", "seq": 4930, "price": 57, "quantity": -500, "ts": 1756428402.418418, "side": "sell"}
{"type": "orderbook_delta", "seq": 4931, "price": 58, "quantity": -200, "ts": 1756428402.419494, "side": "sell"}
{"type": "orderbook_delta", "seq": 4932, "price": 60, "quantity": -1250, "ts": 1756428402.421214, "side": "sell"}
{"type": "orderbook_delta", "seq": 4933, "price": 58, "quantity": -100, "ts": 1756428402.432532, "side": "sell"}
{"type": "orderbook_delta", "seq": 4934, "price": 60, "quantity": 100, "ts": 1756428402.432532, "side": "sell"}
{"type": "orderbook_delta", "seq": 4935, "price": 57, "quantity": 500, "ts": 1756428402.457931, "side": "sell"}
{"type": "orderbook_delta", "seq": 4936, "price": 60, "quantity": 1250, "ts": 1756428402.459156, "side": "sell"}
{"type": "orderbook_delta", "seq": 4937, "price": 45, "quantity": 1250, "ts": 1756428402.460564, "side": "buy"}
{"type": "orderbook_delta", "seq": 4938, "price": 47, "quantity": -200, "ts": 1756428402.460875, "side": "buy"}
{"type": "orderbook_delta", "seq": 4939, "price": 58, "quantity": 200, "ts": 1756428402.4635, "side": "sell"}
{"type": "orderbook_delta", "seq": 4940, "price": 21, "quantity": 8000, "ts": 1756428402.464101, "side": "buy"}
{"type": "orderbook_delta", "seq": 4941, "price": 48, "quantity": 250, "ts": 1756428402.465619, "side": "buy"}
{"type": "orderbook_delta", "seq": 4942, "price": 54, "quantity": -847, "ts": 1756428402.465843, "side": "sell"}
{"type": "orderbook_delta", "seq": 4943, "price": 68, "quantity": 250, "ts": 1756428402.485914, "side": "sell"}
{"type": "orderbook_delta", "seq": 4944, "price": 58, "quantity": -250, "ts": 1756428402.486138, "side": "sell"}
{"type": "orderbook_delta", "seq": 4945, "price": 47, "quantity": 200, "ts": 1756428402.492234, "side": "buy"}
{"type": "orderbook_delta", "seq": 4946, "price": 38, "quantity": -250, "ts": 1756428402.50636, "side": "buy"}
{"type": "orderbook_delta", "seq": 4947, "price": 47, "quantity": -500, "ts": 1756428402.507376, "side": "buy"}
{"type": "orderbook_delta", "seq": 4948, "price": 57, "quantity": -500, "ts": 1756428402.527669, "side": "sell"}
{"type": "orderbook_delta", "seq": 4949, "price": 49, "quantity": 500, "ts": 1756428402.54945, "side": "buy"}
{"type": "orderbook_delta", "seq": 4950, "price": 58, "quantity": 500, "ts": 1756428402.572504, "side": "sell"}
{"type": "orderbook_delta", "seq": 4951, "price": 56, "quantity": 847, "ts": 1756428402.573952, "side": "sell"}
{"type": "orderbook_delta", "seq": 4952, "price": 41, "quantity": -100, "ts": 1756428402.581843, "side": "buy"}
{"type": "orderbook_delta", "seq": 4953, "price": 45, "quantity": 100, "ts": 1756428402.581843, "side": "buy"}
{"type": "orderbook_delta", "seq": 4954, "price": 48, "quantity": -250, "ts": 1756428402.605721, "side": "buy"}
{"type": "orderbook_delta", "seq": 4955, "price": 58, "quantity": -500, "ts": 1756428402.78595, "side": "sell"}
{"type": "orderbook_delta", "seq": 4956, "price": 49, "quantity": -500, "ts": 1756428402.793087, "side": "buy"}
{"type": "orderbook_delta", "seq": 4957, "price": 47, "quantity": 500, "ts": 1756428402.829685, "side": "buy"}
{"type": "orderbook_delta", "seq": 4958, "price": 56, "quantity": 500, "ts": 1756428402.830042, "side": "sell"}
{"type": "orderbook_delta", "seq": 4959, "price": 38, "quantity": 250, "ts": 1756428402.830405, "side": "buy"}
{"type": "orderbook_delta", "seq": 4960, "price": 45, "quantity": -100, "ts": 1756428402.935944, "side": "buy"}
{"type": "orderbook_delta", "seq": 4961, "price": 48, "quantity": 100, "ts": 1756428402.935944, "side": "buy"}
{"type": "orderbook_delta", "seq": 4962, "price": 56, "quantity": -500, "ts": 1756428402.97008, "side": "sell"}
{"type": "orderbook_delta", "seq": 4963, "price": 48, "quantity": 250, "ts": 1756428402.979456, "side": "buy"}
{"type": "orderbook_delta", "seq": 4964, "price": 38, "quantity": -250, "ts": 1756428402.980518, "side": "buy"}
{"type": "orderbook_delta", "seq": 4965, "price": 47, "quantity": -500, "ts": 1756428402.997444, "side": "buy"}
{"type": "orderbook_delta", "seq": 4966, "price": 55, "quantity": 500, "ts": 1756428403.009161, "side": "sell"}
{"type": "orderbook_delta", "seq": 4967, "price": 49, "quantity": 500, "ts": 1756428403.040896, "side": "buy"}
{"type": "orderbook_delta", "seq": 4968, "price": 50, "quantity": 250, "ts": 1756428403.120915, "side": "buy"}
{"type": "orderbook_delta", "seq": 4969, "price": 40, "quantity": -250, "ts": 1756428403.125843, "side": "buy"}
{"type": "orderbook_delta", "seq": 4970, "price": 48, "quantity": -100, "ts": 1756428403.183804, "side": "buy"}
{"type": "orderbook_delta", "seq": 4971, "price": 51, "quantity": 100, "ts": 1756428403.183804, "side": "buy"}
{"type": "orderbook_delta", "seq": 4972, "price": 51, "quantity": -100, "ts": 1756428403.390349, "side": "buy"}
{"type": "orderbook_delta", "seq": 4973, "price": 50, "quantity": 100, "ts": 1756428403.390349, "side": "buy"}
{"type": "orderbook_delta", "seq": 4974, "price": 60, "quantity": -100, "ts": 1756428403.438843, "side": "sell"}
{"type": "orderbook_delta", "seq": 4975, "price": 56, "quantity": 100, "ts": 1756428403.438843, "side": "sell"}
{"type": "orderbook_delta", "seq": 4976, "price": 49, "quantity": -500, "ts": 1756428403.513005, "side": "buy"}
{"type": "orderbook_delta", "seq": 4977, "price": 47, "quantity": -200, "ts": 1756428403.513966, "side": "buy"}
{"type": "orderbook_delta", "seq": 4978, "price": 45, "quantity": -1250, "ts": 1756428403.515407, "side": "buy"}
{"type": "orderbook_delta", "seq": 4979, "price": 21, "quantity": -8000, "ts": 1756428403.516898, "side": "buy"}
{"type": "orderbook_delta", "seq": 4980, "price": 60, "quantity": -1250, "ts": 1756428403.51838, "side": "sell"}
{"type": "orderbook_delta", "seq": 4981, "price": 58, "quantity": -200, "ts": 1756428403.546727, "side": "sell"}
{"type": "orderbook_delta", "seq": 4982, "price": 43, "quantity": 1250, "ts": 1756428403.561075, "side": "buy"}
{"type": "orderbook_delta", "seq": 4983, "price": 12, "quantity": 8000, "ts": 1756428403.562515, "side": "buy"}
{"type": "orderbook_delta", "seq": 4984, "price": 47, "quantity": 500, "ts": 1756428403.565217, "side": "buy"}
{"type": "orderbook_delta", "seq": 4985, "price": 45, "quantity": 200, "ts": 1756428403.565997, "side": "buy"}
{"type": "orderbook_delta", "seq": 4986, "price": 58, "quantity": 1250, "ts": 1756428403.566233, "side": "sell"}
{"type": "orderbook_delta", "seq": 4987, "price": 59, "quantity": -200, "ts": 1756428403.579526, "side": "sell"}
{"type": "orderbook_delta", "seq": 4988, "price": 56, "quantity": 200, "ts": 1756428403.579526, "side": "sell"}
{"type": "orderbook_delta", "seq": 4989, "price": 50, "quantity": -100, "ts": 1756428403.605813, "side": "buy"}
{"type": "orderbook_delta", "seq": 4990, "price": 49, "quantity": 100, "ts": 1756428403.605813, "side": "buy"}
{"type": "orderbook_delta", "seq": 4991, "price": 56, "quantity": 200, "ts": 1756428403.616601, "side": "sell"}
{"type": "orderbook_delta", "seq": 4992, "price": 58, "quantity": -1250, "ts": 1756428403.654878, "side": "sell"}
{"type": "orderbook_delta", "seq": 4993, "price": 56, "quantity": -200, "ts": 1756428403.660677, "side": "sell"}
{"type": "orderbook_delta", "seq": 4994, "price": 55, "quantity": 200, "ts": 1756428403.660677, "side": "sell"}
{"type": "orderbook_delta", "seq": 4995, "price": 55, "quantity": -500, "ts": 1756428403.727254, "side": "sell"}
{"type": "orderbook_delta", "seq": 4996, "price": 59, "quantity": 1250, "ts": 1756428403.746874, "side": "sell"}
{"type": "orderbook_delta", "seq": 4997, "price": 54, "quantity": 500, "ts": 1756428403.788878, "side": "sell"}
{"type": "orderbook_delta", "seq": 4998, "price": 50, "quantity": -250, "ts": 1756428403.845968, "side": "buy"}
{"type": "orderbook_delta", "seq": 4999, "price": 40, "quantity": 250, "ts": 1756428403.84601, "side": "buy"}
{"type": "orderbook_delta", "seq": 5000, "price": 68, "quantity": -250, "ts": 1756428404.103928, "side": "sell"}
{"type": "orderbook_delta", "seq": 5001, "price": 58, "quantity": 250, "ts": 1756428404.114916, "side": "sell"}
{"type": "orderbook_delta", "seq": 5002, "price": 59, "quantity": -1250, "ts": 1756428404.244123, "side": "sell"}
{"type": "orderbook_delta", "seq": 5003, "price": 56, "quantity": -200, "ts": 1756428404.276974, "side": "sell"}
{"type": "orderbook_delta", "seq": 5004, "price": 43, "quantity": -1250, "ts": 1756428404.27804, "side": "buy"}
{"type": "orderbook_delta", "seq": 5005, "price": 45, "quantity": -200, "ts": 1756428404.27901, "side": "buy"}
{"type": "orderbook_delta", "seq": 5006, "price": 55, "quantity": 200, "ts": 1756428404.344124, "side": "sell"}
{"type": "orderbook_delta", "seq": 5007, "price": 57, "quantity": 1250, "ts": 1756428404.344899, "side": "sell"}
{"type": "orderbook_delta", "seq": 5008, "price": 42, "quantity": 1250, "ts": 1756428404.346265, "side": "buy"}
{"type": "orderbook_delta", "seq": 5009, "price": 44, "quantity": 200, "ts": 1756428404.351091, "side": "buy"}
{"type": "orderbook_delta", "seq": 5010, "price": 55, "quantity": -200, "ts": 1756428404.522308, "side": "sell"}
{"type": "orderbook_delta", "seq": 5011, "price": 57, "quantity": 200, "ts": 1756428404.522308, "side": "sell"}
{"type": "orderbook_delta", "seq": 5012, "price": 54, "quantity": -500, "ts": 1756428404.577643, "side": "sell"}
{"type": "orderbook_delta", "seq": 5013, "price": 55, "quantity": 500, "ts": 1756428404.648256, "side": "sell"}
{"type": "orderbook_delta", "seq": 5014, "price": 56, "quantity": 250, "ts": 1756428405.136672, "side": "sell"}
{"type": "orderbook_delta", "seq": 5015, "price": 56, "quantity": -847, "ts": 1756428405.140915, "side": "sell"}
{"type": "orderbook_delta", "seq": 5016, "price": 50, "quantity": 100, "ts": 1756428405.210597, "side": "buy"}
{"type": "orderbook_delta", "seq": 5017, "price": 66, "quantity": -250, "ts": 1756428405.297876, "side": "sell"}
{"type": "orderbook_delta", "seq": 5018, "price": 53, "quantity": 847, "ts": 1756428405.361483, "side": "sell"}
{"type": "orderbook_delta", "seq": 5019, "price": 55, "quantity": -500, "ts": 1756428405.48245, "side": "sell"}
{"type": "orderbook_delta", "seq": 5020, "price": 53, "quantity": 500, "ts": 1756428405.524588, "side": "sell"}
{"type": "orderbook_delta", "seq": 5021, "price": 53, "quantity": -847, "ts": 1756428405.727326, "side": "sell"}
{"type": "orderbook_delta", "seq": 5022, "price": 66, "quantity": 250, "ts": 1756428405.729237, "side": "sell"}
{"type": "orderbook_delta", "seq": 5023, "price": 12, "quantity": -8000, "ts": 1756428405.74045, "side": "buy"}
{"type": "orderbook_delta", "seq": 5024, "price": 55, "quantity": -200, "ts": 1756428405.740957, "side": "sell"}
{"type": "orderbook_delta", "seq": 5025, "price": 44, "quantity": -200, "ts": 1756428405.741005, "side": "buy"}
{"type": "orderbook_delta", "seq": 5026, "price": 42, "quantity": -1250, "ts": 1756428405.741083, "side": "buy"}
{"type": "orderbook_delta", "seq": 5027, "price": 57, "quantity": -200, "ts": 1756428405.742236, "side": "sell"}
{"type": "orderbook_delta", "seq": 5028, "price": 58, "quantity": 200, "ts": 1756428405.742236, "side": "sell"}
{"type": "orderbook_delta", "seq": 5029, "price": 57, "quantity": -1250, "ts": 1756428405.742807, "side": "sell"}
{"type": "orderbook_delta", "seq": 5030, "price": 47, "quantity": -500, "ts": 1756428405.74477, "side": "buy"}
{"type": "orderbook_delta", "seq": 5031, "price": 53, "quantity": -500, "ts": 1756428405.745247, "side": "sell"}
{"type": "orderbook_delta", "seq": 5032, "price": 56, "quantity": -250, "ts": 1756428405.745759, "side": "sell"}
{"type": "orderbook_delta", "seq": 5033, "price": 59, "quantity": 1250, "ts": 1756428405.787843, "side": "sell"}
{"type": "orderbook_delta", "seq": 5034, "price": 38, "quantity": 250, "ts": 1756428405.78916, "side": "buy"}
{"type": "orderbook_delta", "seq": 5035, "price": 49, "quantity": 500, "ts": 1756428405.789412, "side": "buy"}
{"type": "orderbook_delta", "seq": 5036, "price": 46, "quantity": 200, "ts": 1756428405.789999, "side": "buy"}
{"type": "orderbook_delta", "seq": 5037, "price": 48, "quantity": -250, "ts": 1756428405.790278, "side": "buy"}
{"type": "orderbook_delta", "seq": 5038, "price": 20, "quantity": 8000, "ts": 1756428405.790532, "side": "buy"}
{"type": "orderbook_delta", "seq": 5039, "price": 44, "quantity": 1250, "ts": 1756428405.790769, "side": "buy"}
{"type": "orderbook_delta", "seq": 5040, "price": 57, "quantity": 200, "ts": 1756428405.791273, "side": "sell"}
{"type": "orderbook_delta", "seq": 5041, "price": 55, "quantity": 500, "ts": 1756428405.791793, "side": "sell"}
{"type": "orderbook_delta", "seq": 5042, "price": 55, "quantity": 847, "ts": 1756428405.794379, "side": "sell"}
{"type": "orderbook_delta", "seq": 5043, "price": 56, "quantity": -100, "ts": 1756428405.79884, "side": "sell"}
{"type": "orderbook_delta", "seq": 5044, "price": 57, "quantity": 100, "ts": 1756428405.79884, "side": "sell"}
{"type": "orderbook_delta", "seq": 5045, "price": 20, "quantity": -8000, "ts": 1756428405.826958, "side": "buy"}
{"type": "orderbook_delta", "seq": 5046, "price": 38, "quantity": -250, "ts": 1756428405.838147, "side": "buy"}
{"type": "orderbook_delta", "seq": 5047, "price": 44, "quantity": -1250, "ts": 1756428405.844704, "side": "buy"}
{"type": "orderbook_delta", "seq": 5048, "price": 21, "quantity": 8000, "ts": 1756428405.955796, "side": "buy"}
{"type": "orderbook_delta", "seq": 5049, "price": 45, "quantity": 1250, "ts": 1756428405.957065, "side": "buy"}
{"type": "orderbook_delta", "seq": 5050, "price": 57, "quantity": -100, "ts": 1756428405.967899, "side": "sell"}
{"type": "orderbook_delta", "seq": 5051, "price": 58, "quantity": 100, "ts": 1756428405.967899, "side": "sell"}
{"type": "orderbook_delta", "seq": 5052, "price": 57, "quantity": -200, "ts": 1756428406.017764, "side": "sell"}
{"type": "orderbook_delta", "seq": 5053, "price": 46, "quantity": -200, "ts": 1756428406.018334, "side": "buy"}
{"type": "orderbook_delta", "seq": 5054, "price": 55, "quantity": -500, "ts": 1756428406.018624, "side": "sell"}
{"type": "orderbook_delta", "seq": 5055, "price": 49, "quantity": -500, "ts": 1756428406.01962, "side": "buy"}
{"type": "orderbook_delta", "seq": 5056, "price": 59, "quantity": -1250, "ts": 1756428406.020224, "side": "sell"}
{"type": "orderbook_delta", "seq": 5057, "price": 49, "quantity": -100, "ts": 1756428406.073562, "side": "buy"}
{"type": "orderbook_delta", "seq": 5058, "price": 47, "quantity": 100, "ts": 1756428406.073562, "side": "buy"}
{"type": "orderbook_delta", "seq": 5059, "price": 50, "quantity": 500, "ts": 1756428406.09285, "side": "buy"}
{"type": "orderbook_delta", "seq": 5060, "price": 58, "quantity": 200, "ts": 1756428406.093125, "side": "sell"}
{"type": "orderbook_delta", "seq": 5061, "price": 60, "quantity": 1250, "ts": 1756428406.095526, "side": "sell"}
{"type": "orderbook_delta", "seq": 5062, "price": 57, "quantity": 500, "ts": 1756428406.095834, "side": "sell"}
{"type": "orderbook_delta", "seq": 5063, "price": 50, "quantity": -500, "ts": 1756428406.127764, "side": "buy"}
{"type": "orderbook_delta", "seq": 5064, "price": 57, "quantity": -500, "ts": 1756428406.132994, "side": "sell"}
{"type": "orderbook_delta", "seq": 5065, "price": 47, "quantity": 200, "ts": 1756428406.16516, "side": "buy"}
{"type": "orderbook_delta", "seq": 5066, "price": 48, "quantity": 500, "ts": 1756428406.166623, "side": "buy"}
{"type": "orderbook_delta", "seq": 5067, "price": 55, "quantity": 500, "ts": 1756428406.167846, "side": "sell"}
{"type": "orderbook_delta", "seq": 5068, "price": 58, "quantity": -200, "ts": 1756428406.434004, "side": "sell"}
{"type": "orderbook_delta", "seq": 5069, "price": 57, "quantity": 200, "ts": 1756428406.434004, "side": "sell"}
{"type": "orderbook_delta", "seq": 5070, "price": 21, "quantity": -8000, "ts": 1756428406.564433, "side": "buy"}
{"type": "orderbook_delta", "seq": 5071, "price": 55, "quantity": -500, "ts": 1756428406.564679, "side": "sell"}
{"type": "orderbook_delta", "seq": 5072, "price": 58, "quantity": -200, "ts": 1756428406.565307, "side": "sell"}
{"type": "orderbook_delta", "seq": 5073, "price": 60, "quantity": -1250, "ts": 1756428406.565968, "side": "sell"}
{"type": "orderbook_delta", "seq": 5074, "price": 47, "quantity": -200, "ts": 1756428406.566907, "side": "buy"}
{"type": "orderbook_delta", "seq": 5075, "price": 45, "quantity": -1250, "ts": 1756428406.571904, "side": "buy"}
{"type": "orderbook_delta", "seq": 5076, "price": 46, "quantity": 200, "ts": 1756428406.622578, "side": "buy"}
{"type": "orderbook_delta", "seq": 5077, "price": 59, "quantity": 1250, "ts": 1756428406.624294, "side": "sell"}
{"type": "orderbook_delta", "seq": 5078, "price": 44, "quantity": 1250, "ts": 1756428406.624859, "side": "buy"}
{"type": "orderbook_delta", "seq": 5079, "price": 20, "quantity": 8000, "ts": 1756428406.625175, "side": "buy"}
{"type": "orderbook_delta", "seq": 5080, "price": 54, "quantity": 500, "ts": 1756428406.62561, "side": "sell"}
{"type": "orderbook_delta", "seq": 5081, "price": 57, "quantity": 200, "ts": 1756428406.625839, "side": "sell"}
{"type": "orderbook_delta", "seq": 5082, "price": 40, "quantity": -250, "ts": 1756428406.677856, "side": "buy"}
{"type": "orderbook_delta", "seq": 5083, "price": 48, "quantity": 250, "ts": 1756428406.679262, "side": "buy"}
{"type": "orderbook_delta", "seq": 5084, "price": 50, "quantity": 250, "ts": 1756428406.698567, "side": "buy"}
{"type": "orderbook_delta", "seq": 5085, "price": 47, "quantity": -100, "ts": 1756428406.815564, "side": "buy"}
{"type": "orderbook_delta", "seq": 5086, "price": 49, "quantity": 100, "ts": 1756428406.815564, "side": "buy"}
{"type": "orderbook_delta", "seq": 5087, "price": 49, "quantity": -100, "ts": 1756428407.065941, "side": "buy"}
{"type": "orderbook_delta", "seq": 5088, "price": 51, "quantity": 100, "ts": 1756428407.065941, "side": "buy"}
{"type": "orderbook_delta", "seq": 5089, "price": 40, "quantity": 250, "ts": 1756428407.090893, "side": "buy"}
{"type": "orderbook_delta", "seq": 5090, "price": 50, "quantity": -250, "ts": 1756428407.093416, "side": "buy"}
{"type": "orderbook_delta", "seq": 5091, "price": 55, "quantity": -847, "ts": 1756428408.106381, "side": "sell"}
{"type": "orderbook_delta", "seq": 5092, "price": 66, "quantity": -250, "ts": 1756428408.126915, "side": "sell"}
{"type": "orderbook_delta", "seq": 5093, "price": 56, "quantity": 250, "ts": 1756428408.127466, "side": "sell"}
{"type": "orderbook_delta", "seq": 5094, "price": 54, "quantity": -500, "ts": 1756428408.146038, "side": "sell"}
{"type": "orderbook_delta", "seq": 5095, "price": 54, "quantity": 847, "ts": 1756428408.175481, "side": "sell"}
{"type": "orderbook_delta", "seq": 5096, "price": 55, "quantity": 500, "ts": 1756428408.200156, "side": "sell"}
{"type": "orderbook_delta", "seq": 5097, "price": 55, "quantity": -500, "ts": 1756428408.295079, "side": "sell"}
{"type": "orderbook_delta", "seq": 5098, "price": 54, "quantity": 500, "ts": 1756428408.332617, "side": "sell"}
{"type": "orderbook_delta", "seq": 5099, "price": 53, "quantity": 189, "ts": 1756428408.705679, "side": "sell"}
{"type": "orderbook_delta", "seq": 5100, "price": 66, "quantity": 250, "ts": 1756428408.819948, "side": "sell"}
{"type": "orderbook_delta", "seq": 5101, "price": 54, "quantity": -847, "ts": 1756428408.822681, "side": "sell"}
{"type": "orderbook_delta", "seq": 5102, "price": 48, "quantity": -500, "ts": 1756428408.831997, "side": "buy"}
{"type": "orderbook_delta", "seq": 5103, "price": 54, "quantity": -500, "ts": 1756428408.832169, "side": "sell"}
{"type": "orderbook_delta", "seq": 5104, "price": 57, "quantity": -200, "ts": 1756428408.832247, "side": "sell"}
{"type": "orderbook_delta", "seq": 5105, "price": 59, "quantity": -1250, "ts": 1756428408.832303, "side": "sell"}
{"type": "orderbook_delta", "seq": 5106, "price": 44, "quantity": -1250, "ts": 1756428408.833241, "side": "buy"}
{"type": "orderbook_delta", "seq": 5107, "price": 46, "quantity": -200, "ts": 1756428408.834374, "side": "buy"}
{"type": "orderbook_delta", "seq": 5108, "price": 20, "quantity": -8000, "ts": 1756428408.835431, "side": "buy"}
{"type": "orderbook_delta", "seq": 5109, "price": 56, "quantity": -250, "ts": 1756428408.836817, "side": "sell"}
{"type": "orderbook_delta", "seq": 5110, "price": 60, "quantity": 1250, "ts": 1756428408.870883, "side": "sell"}
{"type": "orderbook_delta", "seq": 5111, "price": 56, "quantity": 500, "ts": 1756428408.871692, "side": "sell"}
{"type": "orderbook_delta", "seq": 5112, "price": 58, "quantity": 200, "ts": 1756428408.871956, "side": "sell"}
{"type": "orderbook_delta", "seq": 5113, "price": 49, "quantity": 500, "ts": 1756428408.872195, "side": "buy"}
{"type": "orderbook_delta", "seq": 5114, "price": 45, "quantity": 1250, "ts": 1756428408.873606, "side": "buy"}
{"type": "orderbook_delta", "seq": 5115, "price": 21, "quantity": 8000, "ts": 1756428408.875551, "side": "buy"}
{"type": "orderbook_delta", "seq": 5116, "price": 47, "quantity": 200, "ts": 1756428408.876093, "side": "buy"}
{"type": "orderbook_delta", "seq": 5117, "price": 57, "quantity": -200, "ts": 1756428408.876397, "side": "sell"}
{"type": "orderbook_delta", "seq": 5118, "price": 58, "quantity": 200, "ts": 1756428408.876397, "side": "sell"}
{"type": "orderbook_delta", "seq": 5119, "price": 55, "quantity": 847, "ts": 1756428408.881715, "side": "sell"}
{"type": "orderbook_delta", "seq": 5120, "price": 56, "quantity": -500, "ts": 1756428408.917529, "side": "sell"}
{"type": "orderbook_delta", "seq": 5121, "price": 68, "quantity": 250, "ts": 1756428408.918821, "side": "sell"}
{"type": "orderbook_delta", "seq": 5122, "price": 58, "quantity": -250, "ts": 1756428408.920434, "side": "sell"}
{"type": "orderbook_delta", "seq": 5123, "price": 47, "quantity": -200, "ts": 1756428408.92731, "side": "buy"}
{"type": "orderbook_delta", "seq": 5124, "price": 49, "quantity": -500, "ts": 1756428408.928406, "side": "buy"}
{"type": "orderbook_delta", "seq": 5125, "price": 58, "quantity": -200, "ts": 1756428408.931038, "side": "sell"}
{"type": "orderbook_delta", "seq": 5126, "price": 45, "quantity": -1250, "ts": 1756428408.93173, "side": "buy"}
{"type": "orderbook_delta", "seq": 5127, "price": 60, "quantity": -1250, "ts": 1756428408.942336, "side": "sell"}
{"type": "orderbook_delta", "seq": 5128, "price": 57, "quantity": 500, "ts": 1756428409.043912, "side": "sell"}
{"type": "orderbook_delta", "seq": 5129, "price": 58, "quantity": -100, "ts": 1756428409.044791, "side": "sell"}
{"type": "orderbook_delta", "seq": 5130, "price": 59, "quantity": 100, "ts": 1756428409.044791, "side": "sell"}
{"type": "orderbook_delta", "seq": 5131, "price": 48, "quantity": 200, "ts": 1756428409.04501, "side": "buy"}
{"type": "orderbook_delta", "seq": 5132, "price": 50, "quantity": 500, "ts": 1756428409.045306, "side": "buy"}
{"type": "orderbook_delta", "seq": 5133, "price": 59, "quantity": 200, "ts": 1756428409.04574, "side": "sell"}
{"type": "orderbook_delta", "seq": 5134, "price": 61, "quantity": 1250, "ts": 1756428409.045971, "side": "sell"}
{"type": "orderbook_delta", "seq": 5135, "price": 46, "quantity": 1250, "ts": 1756428409.046241, "side": "buy"}
{"type": "orderbook_delta", "seq": 5136, "price": 55, "quantity": -847, "ts": 1756428409.048483, "side": "sell"}
{"type": "orderbook_delta", "seq": 5137, "price": 38, "quantity": 250, "ts": 1756428409.04855, "side": "buy"}
{"type": "orderbook_delta", "seq": 5138, "price": 58, "quantity": -200, "ts": 1756428409.050084, "side": "sell"}
{"type": "orderbook_delta", "seq": 5139, "price": 61, "quantity": 200, "ts": 1756428409.050084, "side": "sell"}
{"type": "orderbook_delta", "seq": 5140, "price": 20, "quantity": -200, "ts": 1756428409.050994, "side": "buy"}
{"type": "orderbook_delta", "seq": 5141, "price": 30, "quantity": 200, "ts": 1756428409.050994, "side": "buy"}
{"type": "orderbook_delta", "seq": 5142, "price": 70, "quantity": 250, "ts": 1756428409.079453, "side": "sell"}
{"type": "orderbook_delta", "seq": 5143, "price": 60, "quantity": -250, "ts": 1756428409.079907, "side": "sell"}
{"type": "orderbook_delta", "seq": 5144, "price": 80, "quantity": -200, "ts": 1756428409.080003, "side": "sell"}
{"type": "orderbook_delta", "seq": 5145, "price": 90, "quantity": 200, "ts": 1756428409.080003, "side": "sell"}
{"type": "orderbook_delta", "seq": 5146, "price": 57, "quantity": -500, "ts": 1756428409.086776, "side": "sell"}
{"type": "orderbook_delta", "seq": 5147, "price": 48, "quantity": -200, "ts": 1756428409.089369, "side": "buy"}
{"type": "orderbook_delta", "seq": 5148, "price": 51, "quantity": -100, "ts": 1756428409.090656, "side": "buy"}
{"type": "orderbook_delta", "seq": 5149, "price": 49, "quantity": 100, "ts": 1756428409.090656, "side": "buy"}
{"type": "orderbook_delta", "seq": 5150, "price": 48, "quantity": -250, "ts": 1756428409.096808, "side": "buy"}
{"type": "orderbook_delta", "seq": 5151, "price": 59, "quantity": -200, "ts": 1756428409.104798, "side": "sell"}
{"type": "orderbook_delta", "seq": 5152, "price": 21, "quantity": -8000, "ts": 1756428409.106003, "side": "buy"}
{"type": "orderbook_delta", "seq": 5153, "price": 61, "quantity": -1250, "ts": 1756428409.10691, "side": "sell"}
{"type": "orderbook_delta", "seq": 5154, "price": 61, "quantity": -200, "ts": 1756428409.116887, "side": "sell"}
{"type": "orderbook_delta", "seq": 5155, "price": 63, "quantity": 200, "ts": 1756428409.116887, "side": "sell"}
{"type": "orderbook_delta", "seq": 5156, "price": 98, "quantity": -8000, "ts": 1756428409.117122, "side": "sell"}
{"type": "orderbook_delta", "seq": 5157, "price": 50, "quantity": -500, "ts": 1756428409.11926, "side": "buy"}
{"type": "orderbook_delta", "seq": 5158, "price": 46, "quantity": -1250, "ts": 1756428409.121299, "side": "buy"}
{"type": "orderbook_delta", "seq": 5159, "price": 47, "quantity": 200, "ts": 1756428409.130983, "side": "buy"}
{"type": "orderbook_delta", "seq": 5160, "price": 59, "quantity": -100, "ts": 1756428409.132792, "side": "sell"}
{"type": "orderbook_delta", "seq": 5161, "price": 62, "quantity": 100, "ts": 1756428409.132792, "side": "sell"}
{"type": "orderbook_delta", "seq": 5162, "price": 60, "quantity": 500, "ts": 1756428409.133379, "side": "sell"}
{"type": "orderbook_delta", "seq": 5163, "price": 52, "quantity": 250, "ts": 1756428409.137975, "side": "buy"}
{"type": "orderbook_delta", "seq": 5164, "price": 42, "quantity": -250, "ts": 1756428409.138543, "side": "buy"}
{"type": "orderbook_delta", "seq": 5165, "price": 12, "quantity": 8000, "ts": 1756428409.145922, "side": "buy"}
{"type": "orderbook_delta", "seq": 5166, "price": 38, "quantity": -250, "ts": 1756428409.14622, "side": "buy"}
{"type": "orderbook_delta", "seq": 5167, "price": 59, "quantity": 847, "ts": 1756428409.160534, "side": "sell"}
{"type": "orderbook_delta", "seq": 5168, "price": 51, "quantity": 500, "ts": 1756428409.17064, "side": "buy"}
{"type": "orderbook_delta", "seq": 5169, "price": 62, "quantity": 200, "ts": 1756428409.172324, "side": "sell"}
{"type": "orderbook_delta", "seq": 5170, "price": 60, "quantity": -500, "ts": 1756428409.173514, "side": "sell"}
{"type": "orderbook_delta", "seq": 5171, "price": 47, "quantity": 1250, "ts": 1756428409.173657, "side": "buy"}
{"type": "orderbook_delta", "seq": 5172, "price": 64, "quantity": 1250, "ts": 1756428409.175451, "side": "sell"}
{"type": "orderbook_delta", "seq": 5173, "price": 89, "quantity": 8000, "ts": 1756428409.175954, "side": "sell"}
{"type": "orderbook_delta", "seq": 5174, "price": 50, "quantity": 250, "ts": 1756428409.195522, "side": "buy"}
{"type": "orderbook_delta", "seq": 5175, "price": 61, "quantity": 500, "ts": 1756428409.211065, "side": "sell"}
{"type": "orderbook_delta", "seq": 5176, "price": 51, "quantity": -500, "ts": 1756428409.23064, "side": "buy"}
{"type": "orderbook_delta", "seq": 5177, "price": 47, "quantity": -200, "ts": 1756428409.236285, "side": "buy"}
{"type": "orderbook_delta", "seq": 5178, "price": 52, "quantity": 500, "ts": 1756428409.278664, "side": "buy"}
{"type": "orderbook_delta", "seq": 5179, "price": 51, "quantity": 200, "ts": 1756428409.281377, "side": "buy"}
{"type": "orderbook_delta", "seq": 5180, "price": 40, "quantity": -250, "ts": 1756428409.296903, "side": "buy"}
{"type": "orderbook_delta", "seq": 5181, "price": 49, "quantity": -100, "ts": 1756428409.848504, "side": "buy"}
{"type": "orderbook_delta", "seq": 5182, "price": 51, "quantity": 100, "ts": 1756428409.848504, "side": "buy"}
{"type": "orderbook_delta", "seq": 5183, "price": 62, "quantity": -100, "ts": 1756428410.025483, "side": "sell"}
{"type": "orderbook_delta", "seq": 5184, "price": 63, "quantity": 100, "ts": 1756428410.025483, "side": "sell"}
{"type": "orderbook_delta", "seq": 5185, "price": 63, "quantity": -100, "ts": 1756428410.469519, "side": "sell"}
{"type": "orderbook_delta", "seq": 5186, "price": 64, "quantity": 100, "ts": 1756428410.469519, "side": "sell"}
{"type": "orderbook_delta", "seq": 5187, "price": 51, "quantity": -100, "ts": 1756428410.522689, "side": "buy"}
{"type": "orderbook_delta", "seq": 5188, "price": 52, "quantity": 100, "ts": 1756428410.522689, "side": "buy"}
{"type": "orderbook_delta", "seq": 5189, "price": 53, "quantity": 0, "ts": 1756428411.107329, "side": "sell"}
{"type": "trade", "seq": 59, "price": 53, "quantity": 189, "ts": 1756428411.110401, "side": "buy"}
{"type": "orderbook_delta", "seq": 5190, "price": 59, "quantity": -847, "ts": 1756428411.110401, "side": "sell"}
{"type": "orderbook_delta", "seq": 5191, "price": 44, "quantity": -250, "ts": 1756428411.224406, "side": "buy"}
{"type": "orderbook_delta", "seq": 5192, "price": 48, "quantity": 250, "ts": 1756428411.224425, "side": "buy"}
{"type": "orderbook_delta", "seq": 5193, "price": 60, "quantity": 847, "ts": 1756428411.225126, "side": "sell"}
{"type": "orderbook_delta", "seq": 5194, "price": 52, "quantity": -500, "ts": 1756428411.22537, "side": "buy"}
{"type": "orderbook_delta", "seq": 5195, "price": 52, "quantity": -100, "ts": 1756428411.231848, "side": "buy"}
{"type": "orderbook_delta", "seq": 5196, "price": 53, "quantity": 100, "ts": 1756428411.231848, "side": "buy"}
{"type": "orderbook_delta", "seq": 5197, "price": 54, "quantity": 250, "ts": 1756428411.236935, "side": "buy"}
{"type": "orderbook_delta", "seq": 5198, "price": 60, "quantity": 153, "ts": 1756428411.247649, "side": "sell"}
{"type": "orderbook_delta", "seq": 5199, "price": 47, "quantity": -1250, "ts": 1756428411.254963, "side": "buy"}
{"type": "orderbook_delta", "seq": 5200, "price": 61, "quantity": -500, "ts": 1756428411.268716, "side": "sell"}
{"type": "orderbook_delta", "seq": 5201, "price": 54, "quantity": 500, "ts": 1756428411.271961, "side": "buy"}
{"type": "orderbook_delta", "seq": 5202, "price": 44, "quantity": 250, "ts": 1756428411.273209, "side": "buy"}
{"type": "orderbook_delta", "seq": 5203, "price": 49, "quantity": 1250, "ts": 1756428411.290703, "side": "buy"}
{"type": "orderbook_delta", "seq": 5204, "price": 54, "quantity": -250, "ts": 1756428411.291811, "side": "buy"}
{"type": "orderbook_delta", "seq": 5205, "price": 60, "quantity": 500, "ts": 1756428411.310202, "side": "sell"}
{"type": "orderbook_delta", "seq": 5206, "price": 53, "quantity": -100, "ts": 1756428411.480394, "side": "buy"}
{"type": "orderbook_delta", "seq": 5207, "price": 55, "quantity": 100, "ts": 1756428411.480394, "side": "buy"}
{"type": "orderbook_delta", "seq": 5208, "price": 54, "quantity": -500, "ts": 1756428411.506474, "side": "buy"}
{"type": "orderbook_delta", "seq": 5209, "price": 53, "quantity": 500, "ts": 1756428411.550897, "side": "buy"}
{"type": "orderbook_delta", "seq": 5210, "price": 44, "quantity": -250, "ts": 1756428411.577151, "side": "buy"}
{"type": "orderbook_delta", "seq": 5211, "price": 54, "quantity": 250, "ts": 1756428411.579612, "side": "buy"}
{"type": "orderbook_delta", "seq": 5212, "price": 53, "quantity": -500, "ts": 1756428411.616924, "side": "buy"}
{"type": "orderbook_delta", "seq": 5213, "price": 54, "quantity": 500, "ts": 1756428411.678076, "side": "buy"}
{"type": "orderbook_delta", "seq": 5214, "price": 55, "quantity": -100, "ts": 1756428411.872676, "side": "buy"}
{"type": "orderbook_delta", "seq": 5215, "price": 53, "quantity": 100, "ts": 1756428411.872676, "side": "buy"}
{"type": "orderbook_delta", "seq": 5216, "price": 64, "quantity": -100, "ts": 1756428411.990204, "side": "sell"}
{"type": "orderbook_delta", "seq": 5217, "price": 59, "quantity": 100, "ts": 1756428411.990204, "side": "sell"}
{"type": "orderbook_delta", "seq": 5218, "price": 59, "quantity": -100, "ts": 1756428412.092025, "side": "sell"}
{"type": "orderbook_delta", "seq": 5219, "price": 60, "quantity": 100, "ts": 1756428412.092025, "side": "sell"}
{"type": "orderbook_delta", "seq": 5220, "price": 60, "quantity": -100, "ts": 1756428412.34644, "side": "sell"}
{"type": "orderbook_delta", "seq": 5221, "price": 62, "quantity": 100, "ts": 1756428412.34644, "side": "sell"}
{"type": "orderbook_delta", "seq": 5222, "price": 50, "quantity": -100, "ts": 1756428412.480213, "side": "buy"}
{"type": "orderbook_delta", "seq": 5223, "price": 54, "quantity": -500, "ts": 1756428412.608601, "side": "buy"}
{"type": "orderbook_delta", "seq": 5224, "price": 62, "quantity": -200, "ts": 1756428412.611144, "side": "sell"}
{"type": "orderbook_delta", "seq": 5225, "price": 64, "quantity": -1250, "ts": 1756428412.636006, "side": "sell"}
{"type": "orderbook_delta", "seq": 5226, "price": 49, "quantity": -1250, "ts": 1756428412.636379, "side": "buy"}
{"type": "orderbook_delta", "seq": 5227, "price": 60, "quantity": -500, "ts": 1756428412.63649, "side": "sell"}
{"type": "orderbook_delta", "seq": 5228, "price": 51, "quantity": -200, "ts": 1756428412.639067, "side": "buy"}
{"type": "orderbook_delta", "seq": 5229, "price": 53, "quantity": -100, "ts": 1756428412.639087, "side": "buy"}
{"type": "orderbook_delta", "seq": 5230, "price": 54, "quantity": 100, "ts": 1756428412.639087, "side": "buy"}
{"type": "orderbook_delta", "seq": 5231, "price": 59, "quantity": 500, "ts": 1756428412.674744, "side": "sell"}
{"type": "orderbook_delta", "seq": 5232, "price": 50, "quantity": 200, "ts": 1756428412.675956, "side": "buy"}
{"type": "orderbook_delta", "seq": 5233, "price": 48, "quantity": 1250, "ts": 1756428412.676228, "side": "buy"}
{"type": "orderbook_delta", "seq": 5234, "price": 63, "quantity": 1250, "ts": 1756428412.67828, "side": "sell"}
{"type": "orderbook_delta", "seq": 5235, "price": 53, "quantity": 500, "ts": 1756428412.679022, "side": "buy"}
{"type": "orderbook_delta", "seq": 5236, "price": 61, "quantity": 200, "ts": 1756428412.688748, "side": "sell"}
{"type": "orderbook_delta", "seq": 5237, "price": 44, "quantity": 250, "ts": 1756428413.13044, "side": "buy"}
{"type": "orderbook_delta", "seq": 5238, "price": 60, "quantity": -153, "ts": 1756428413.135096, "side": "sell"}
{"type": "orderbook_delta", "seq": 5239, "price": 60, "quantity": -847, "ts": 1756428413.158059, "side": "sell"}
{"type": "orderbook_delta", "seq": 5240, "price": 59, "quantity": -500, "ts": 1756428413.195165, "side": "sell"}
{"type": "orderbook_delta", "seq": 5241, "price": 54, "quantity": -250, "ts": 1756428413.217514, "side": "buy"}
{"type": "orderbook_delta", "seq": 5242, "price": 61, "quantity": 500, "ts": 1756428413.239348, "side": "sell"}
{"type": "orderbook_delta", "seq": 5243, "price": 59, "quantity": 1000, "ts": 1756428413.267983, "side": "sell"}
{"type": "orderbook_delta", "seq": 5244, "price": 61, "quantity": -500, "ts": 1756428413.305617, "side": "sell"}
{"type": "orderbook_delta", "seq": 5245, "price": 59, "quantity": 500, "ts": 1756428413.351337, "side": "sell"}
{"type": "orderbook_delta", "seq": 5246, "price": 54, "quantity": -100, "ts": 1756428413.442869, "side": "buy"}
{"type": "orderbook_delta", "seq": 5247, "price": 53, "quantity": 100, "ts": 1756428413.442869, "side": "buy"}
{"type": "orderbook_delta", "seq": 5248, "price": 63, "quantity": -200, "ts": 1756428413.489602, "side": "sell"}
{"type": "orderbook_delta", "seq": 5249, "price": 60, "quantity": 200, "ts": 1756428413.489602, "side": "sell"}
{"type": "orderbook_delta", "seq": 5250, "price": 50, "quantity": -200, "ts": 1756428413.777991, "side": "buy"}
{"type": "orderbook_delta", "seq": 5251, "price": 53, "quantity": -500, "ts": 1756428413.780289, "side": "buy"}
{"type": "orderbook_delta", "seq": 5252, "price": 59, "quantity": -500, "ts": 1756428413.780729, "side": "sell"}
{"type": "orderbook_delta", "seq": 5253, "price": 63, "quantity": -1250, "ts": 1756428413.781639, "side": "sell"}
{"type": "orderbook_delta", "seq": 5254, "price": 48, "quantity": -1250, "ts": 1756428413.783308, "side": "buy"}
{"type": "orderbook_delta", "seq": 5255, "price": 61, "quantity": -200, "ts": 1756428413.783564, "side": "sell"}
{"type": "orderbook_delta", "seq": 5256, "price": 46, "quantity": 1250, "ts": 1756428413.832761, "side": "buy"}
{"type": "orderbook_delta", "seq": 5257, "price": 58, "quantity": 500, "ts": 1756428413.833098, "side": "sell"}
{"type": "orderbook_delta", "seq": 5258, "price": 48, "quantity": 200, "ts": 1756428413.833394, "side": "buy"}
{"type": "orderbook_delta", "seq": 5259, "price": 51, "quantity": 500, "ts": 1756428413.833654, "side": "buy"}
{"type": "orderbook_delta", "seq": 5260, "price": 59, "quantity": 200, "ts": 1756428413.835526, "side": "sell"}
{"type": "orderbook_delta", "seq": 5261, "price": 61, "quantity": 1250, "ts": 1756428413.836097, "side": "sell"}
{"type": "orderbook_delta", "seq": 5262, "price": 53, "quantity": -100, "ts": 1756428414.072036, "side": "buy"}
{"type": "orderbook_delta", "seq": 5263, "price": 52, "quantity": 100, "ts": 1756428414.072036, "side": "buy"}
{"type": "orderbook_delta", "seq": 5264, "price": 59, "quantity": -1000, "ts": 1756428414.129576, "side": "sell"}
{"type": "orderbook_delta", "seq": 5265, "price": 60, "quantity": 250, "ts": 1756428414.146999, "side": "sell"}
{"type": "orderbook_delta", "seq": 5266, "price": 58, "quantity": -500, "ts": 1756428414.165767, "side": "sell"}
{"type": "orderbook_delta", "seq": 5267, "price": 52, "quantity": -250, "ts": 1756428414.166229, "side": "buy"}
{"type": "orderbook_delta", "seq": 5268, "price": 42, "quantity": 250, "ts": 1756428414.167246, "side": "buy"}
{"type": "orderbook_delta", "seq": 5269, "price": 62, "quantity": -100, "ts": 1756428414.260442, "side": "sell"}
{"type": "orderbook_delta", "seq": 5270, "price": 57, "quantity": 100, "ts": 1756428414.260442, "side": "sell"}
{"type": "orderbook_delta", "seq": 5271, "price": 59, "quantity": 500, "ts": 1756428414.261617, "side": "sell"}
{"type": "orderbook_delta", "seq": 5272, "price": 59, "quantity": -500, "ts": 1756428414.301734, "side": "sell"}
{"type": "orderbook_delta", "seq": 5273, "price": 57, "quantity": -100, "ts": 1756428414.310519, "side": "sell"}
{"type": "orderbook_delta", "seq": 5274, "price": 58, "quantity": 100, "ts": 1756428414.310519, "side": "sell"}
{"type": "orderbook_delta", "seq": 5275, "price": 57, "quantity": 500, "ts": 1756428414.349962, "side": "sell"}
{"type": "orderbook_delta", "seq": 5276, "price": 55, "quantity": 100, "ts": 1756428414.371743, "side": "buy"}
{"type": "orderbook_delta", "seq": 5277, "price": 70, "quantity": -250, "ts": 1756428414.405907, "side": "sell"}
{"type": "orderbook_delta", "seq": 5278, "price": 57, "quantity": 1000, "ts": 1756428414.452688, "side": "sell"}
{"type": "orderbook_delta", "seq": 5279, "price": 51, "quantity": -500, "ts": 1756428414.664824, "side": "buy"}
{"type": "orderbook_delta", "seq": 5280, "price": 46, "quantity": -1250, "ts": 1756428414.668256, "side": "buy"}
{"type": "orderbook_delta", "seq": 5281, "price": 48, "quantity": -200, "ts": 1756428414.669135, "side": "buy"}
{"type": "orderbook_delta", "seq": 5282, "price": 61, "quantity": -1250, "ts": 1756428414.669547, "side": "sell"}
{"type": "orderbook_delta", "seq": 5283, "price": 57, "quantity": -500, "ts": 1756428414.671006, "side": "sell"}
{"type": "orderbook_delta", "seq": 5284, "price": 60, "quantity": -200, "ts": 1756428414.68358, "side": "sell"}
{"type": "orderbook_delta", "seq": 5285, "price": 59, "quantity": 200, "ts": 1756428414.68358, "side": "sell"}
{"type": "orderbook_delta", "seq": 5286, "price": 47, "quantity": 200, "ts": 1756428414.710814, "side": "buy"}
{"type": "orderbook_delta", "seq": 5287, "price": 50, "quantity": 500, "ts": 1756428414.7116, "side": "buy"}
{"type": "orderbook_delta", "seq": 5288, "price": 45, "quantity": 1250, "ts": 1756428414.714173, "side": "buy"}
{"type": "orderbook_delta", "seq": 5289, "price": 56, "quantity": 500, "ts": 1756428414.714677, "side": "sell"}
{"type": "orderbook_delta", "seq": 5290, "price": 52, "quantity": -100, "ts": 1756428414.715127, "side": "buy"}
{"type": "orderbook_delta", "seq": 5291, "price": 51, "quantity": 100, "ts": 1756428414.715127, "side": "buy"}
{"type": "orderbook_delta", "seq": 5292, "price": 60, "quantity": 1250, "ts": 1756428414.71529, "side": "sell"}
{"type": "orderbook_delta", "seq": 5293, "price": 59, "quantity": -200, "ts": 1756428414.729195, "side": "sell"}
{"type": "orderbook_delta", "seq": 5294, "price": 58, "quantity": 200, "ts": 1756428414.762503, "side": "sell"}
{"type": "orderbook_delta", "seq": 5295, "price": 51, "quantity": -100, "ts": 1756428414.768483, "side": "buy"}
{"type": "orderbook_delta", "seq": 5296, "price": 48, "quantity": 100, "ts": 1756428414.768483, "side": "buy"}
{"type": "orderbook_delta", "seq": 5297, "price": 47, "quantity": -200, "ts": 1756428414.778815, "side": "buy"}
{"type": "orderbook_delta", "seq": 5298, "price": 50, "quantity": -500, "ts": 1756428414.779272, "side": "buy"}
{"type": "orderbook_delta", "seq": 5299, "price": 45, "quantity": -1250, "ts": 1756428414.780588, "side": "buy"}
{"type": "orderbook_delta", "seq": 5300, "price": 60, "quantity": -1250, "ts": 1756428414.781272, "side": "sell"}
{"type": "orderbook_delta", "seq": 5301, "price": 58, "quantity": -200, "ts": 1756428414.802679, "side": "sell"}
{"type": "orderbook_delta", "seq": 5302, "price": 59, "quantity": -200, "ts": 1756428414.819605, "side": "sell"}
{"type": "orderbook_delta", "seq": 5303, "price": 57, "quantity": 200, "ts": 1756428414.819605, "side": "sell"}
{"type": "orderbook_delta", "seq": 5304, "price": 48, "quantity": -100, "ts": 1756428414.820817, "side": "buy"}
{"type": "orderbook_delta", "seq": 5305, "price": 47, "quantity": 100, "ts": 1756428414.820817, "side": "buy"}
{"type": "orderbook_delta", "seq": 5306, "price": 59, "quantity": 1250, "ts": 1756428414.836646, "side": "sell"}
{"type": "orderbook_delta", "seq": 5307, "price": 44, "quantity": 1250, "ts": 1756428414.837585, "side": "buy"}
{"type": "orderbook_delta", "seq": 5308, "price": 46, "quantity": 200, "ts": 1756428414.838931, "side": "buy"}
{"type": "orderbook_delta", "seq": 5309, "price": 49, "quantity": 500, "ts": 1756428414.839822, "side": "buy"}
{"type": "orderbook_delta", "seq": 5310, "price": 57, "quantity": 200, "ts": 1756428414.840054, "side": "sell"}
{"type": "orderbook_delta", "seq": 5311, "price": 40, "quantity": 250, "ts": 1756428415.117768, "side": "buy"}
{"type": "orderbook_delta", "seq": 5312, "price": 57, "quantity": -1000, "ts": 1756428415.12027, "side": "sell"}
{"type": "orderbook_delta", "seq": 5313, "price": 55, "quantity": -100, "ts": 1756428415.134874, "side": "buy"}
{"type": "orderbook_delta", "seq": 5314, "price": 58, "quantity": 250, "ts": 1756428415.146855, "side": "sell"}
